{
  "version": 8,
  "blockIdVersion": 11,
  "anchorX": 0,
  "anchorY": 0,
  "anchorZ": 0,
  "blocks": [
    {
      "x": -6,
      "y": 0,
      "z": -8,
      "name": "Wood_Deadwood_Planks",
      "rotation": 1
    },
    {
      "x": -6,
      "y": 0,
      "z": -7,
      "name": "Wood_Deadwood_Planks",
      "rotation": 1
    },
    {
      "x": -6,
      "y": 0,
      "z": -6,
      "name": "Wood_Deadwood_Planks",
      "rotation": 1
    },
    {
      "x": -6,
      "y": 0,
      "z": -5,
      "name": "Wood_Deadwood_Planks",
      "rotation": 1
    },
    {
      "x": -6,
      "y": 0,
      "z": -4,
      "name": "Wood_Deadwood_Planks",
      "rotation": 1
    },
    {
      "x": -6,
      "y": 0,
      "z": -3,
      "name": "Wood_Deadwood_Planks",
      "rotation": 1
    },
    {
      "x": -6,
      "y": 0,
      "z": -2,
      "name": "Wood_Deadwood_Planks",
      "rotation": 1
    },
    {
      "x": -6,
      "y": 0,
      "z": -1,
      "name": "Wood_Deadwood_Planks",
      "rotation": 1
    },
    {
      "x": -6,
      "y": 0,
      "z": 0,
      "name": "Wood_Deadwood_Planks",
      "rotation": 1
    },
    {
      "x": -6,
      "y": 0,
      "z": 1,
      "name": "Wood_Deadwood_Planks",
      "rotation": 1
    },
    {
      "x": -6,
      "y": 0,
      "z": 2,
      "name": "Wood_Deadwood_Planks",
      "rotation": 1
    },
    {
      "x": -6,
      "y": 0,
      "z": 3,
      "name": "Wood_Deadwood_Planks",
      "rotation": 1
    },
    {
      "x": -6,
      "y": 0,
      "z": 4,
      "name": "Wood_Deadwood_Planks",
      "rotation": 1
    },
    {
      "x": -6,
      "y": 0,
      "z": 5,
      "name": "Wood_Deadwood_Planks",
      "rotation": 1
    },
    {
      "x": -6,
      "y": 0,
      "z": 6,
      "name": "Wood_Deadwood_Planks",
      "rotation": 1
    },
    {
      "x": -6,
      "y": 0,
      "z": 7,
      "name": "Wood_Deadwood_Planks",
      "rotation": 1
    },
    {
      "x": -6,
      "y": 0,
      "z": 8,
      "name": "Wood_Deadwood_Planks",
      "rotation": 1
    },
    {
      "x": -5,
      "y": 0,
      "z": -8,
      "name": "Wood_Deadwood_Planks",
      "rotation": 1
    },
    {
      "x": -5,
      "y": 0,
      "z": -7,
      "name": "Wood_Deadwood_Planks",
      "rotation": 1
    },
    {
      "x": -5,
      "y": 0,
      "z": -6,
      "name": "Wood_Deadwood_Planks",
      "rotation": 1
    },
    {
      "x": -5,
      "y": 0,
      "z": -5,
      "name": "Wood_Deadwood_Planks",
      "rotation": 1
    },
    {
      "x": -5,
      "y": 0,
      "z": -4,
      "name": "Wood_Deadwood_Planks",
      "rotation": 1
    },
    {
      "x": -5,
      "y": 0,
      "z": -3,
      "name": "Wood_Deadwood_Planks",
      "rotation": 1
    },
    {
      "x": -5,
      "y": 0,
      "z": -2,
      "name": "Wood_Deadwood_Planks",
      "rotation": 1
    },
    {
      "x": -5,
      "y": 0,
      "z": -1,
      "name": "Wood_Deadwood_Planks",
      "rotation": 1
    },
    {
      "x": -5,
      "y": 0,
      "z": 0,
      "name": "Wood_Deadwood_Planks",
      "rotation": 1
    },
    {
      "x": -5,
      "y": 1,
      "z": 0,
      "name": "Wood_Softwood_Beam",
      "rotation": 1
    },
    {
      "x": -5,
      "y": 2,
      "z": 0,
      "name": "Wood_Softwood_Beam",
      "rotation": 1
    },
    {
      "x": -5,
      "y": 3,
      "z": 0,
      "name": "Wood_Softwood_Beam",
      "rotation": 1
    },
    {
      "x": -5,
      "y": 4,
      "z": 0,
      "name": "Wood_Softwood_Beam",
      "rotation": 1
    },
    {
      "x": -5,
      "y": 5,
      "z": 0,
      "name": "Rock_Stone_Cobble_Roof",
      "rotation": 3
    },
    {
      "x": -5,
      "y": 11,
      "z": 0,
      "name": "Plant_Moss_Wall_Green",
      "support": 15,
      "rotation": 3
    },
    {
      "x": -5,
      "y": 12,
      "z": 0,
      "name": "Plant_Moss_Wall_Green_Dark",
      "support": 15,
      "rotation": 3
    },
    {
      "x": -5,
      "y": 0,
      "z": 1,
      "name": "Wood_Deadwood_Planks",
      "rotation": 1
    },
    {
      "x": -5,
      "y": 1,
      "z": 1,
      "name": "Furniture_Tavern_Planter",
      "rotation": 1
    },
    {
      "x": -5,
      "y": 2,
      "z": 1,
      "name": "Plant_Bramble_Moss_Twisted",
      "rotation": 1
    },
    {
      "x": -5,
      "y": 5,
      "z": 1,
      "name": "Rock_Stone_Cobble_Roof_Hollow",
      "rotation": 3
    },
    {
      "x": -5,
      "y": 13,
      "z": 1,
      "name": "Plant_Moss_Wall_Green",
      "support": 15,
      "rotation": 3
    },
    {
      "x": -5,
      "y": 14,
      "z": 1,
      "name": "Plant_Moss_Wall_Green_Dark",
      "support": 15,
      "rotation": 3
    },
    {
      "x": -5,
      "y": 0,
      "z": 2,
      "name": "Wood_Deadwood_Planks",
      "rotation": 1
    },
    {
      "x": -5,
      "y": 4,
      "z": 2,
      "name": "Plant_Moss_Wall_Green_Dark",
      "support": 15,
      "rotation": 3
    },
    {
      "x": -5,
      "y": 5,
      "z": 2,
      "name": "Rock_Stone_Cobble_Roof_Hollow",
      "rotation": 3
    },
    {
      "x": -5,
      "y": 11,
      "z": 2,
      "name": "Furniture_Kweebec_Shelf",
      "rotation": 3
    },
    {
      "x": -5,
      "y": 15,
      "z": 2,
      "name": "Plant_Moss_Wall_Green",
      "support": 15,
      "rotation": 3
    },
    {
      "x": -5,
      "y": 16,
      "z": 2,
      "name": "Plant_Moss_Wall_Green_Dark",
      "support": 15,
      "rotation": 3
    },
    {
      "x": -5,
      "y": 0,
      "z": 3,
      "name": "Wood_Deadwood_Planks",
      "rotation": 1
    },
    {
      "x": -5,
      "y": 1,
      "z": 3,
      "name": "Furniture_Tavern_Planter",
      "rotation": 1
    },
    {
      "x": -5,
      "y": 2,
      "z": 3,
      "name": "Plant_Bramble_Moss_Twisted",
      "rotation": 1
    },
    {
      "x": -5,
      "y": 3,
      "z": 3,
      "name": "Plant_Moss_Wall_Green",
      "support": 15,
      "rotation": 3
    },
    {
      "x": -5,
      "y": 4,
      "z": 3,
      "name": "Plant_Moss_Wall_Green_Dark",
      "support": 15,
      "rotation": 3
    },
    {
      "x": -5,
      "y": 5,
      "z": 3,
      "name": "Rock_Stone_Cobble_Roof_Hollow",
      "rotation": 3
    },
    {
      "x": -5,
      "y": 11,
      "z": 3,
      "name": "Furniture_Kweebec_Shelf",
      "rotation": 3
    },
    {
      "x": -5,
      "y": 15,
      "z": 3,
      "name": "Plant_Moss_Wall_Green",
      "support": 15,
      "rotation": 3
    },
    {
      "x": -5,
      "y": 16,
      "z": 3,
      "name": "Plant_Moss_Wall_Green_Dark",
      "support": 15,
      "rotation": 3
    },
    {
      "x": -5,
      "y": 0,
      "z": 4,
      "name": "Wood_Deadwood_Planks",
      "rotation": 1
    },
    {
      "x": -5,
      "y": 2,
      "z": 4,
      "name": "Plant_Moss_Wall_Green_Dark",
      "support": 15,
      "rotation": 3
    },
    {
      "x": -5,
      "y": 5,
      "z": 4,
      "name": "Rock_Stone_Cobble_Roof_Hollow",
      "rotation": 3
    },
    {
      "x": -5,
      "y": 12,
      "z": 4,
      "name": "Plant_Moss_Wall_Green",
      "support": 15,
      "rotation": 3
    },
    {
      "x": -5,
      "y": 13,
      "z": 4,
      "name": "Plant_Moss_Wall_Green_Dark",
      "support": 15,
      "rotation": 3
    },
    {
      "x": -5,
      "y": 14,
      "z": 4,
      "name": "Plant_Moss_Wall_Green",
      "support": 15,
      "rotation": 3
    },
    {
      "x": -5,
      "y": 0,
      "z": 5,
      "name": "Wood_Deadwood_Planks",
      "rotation": 1
    },
    {
      "x": -5,
      "y": 1,
      "z": 5,
      "name": "Wood_Softwood_Beam",
      "rotation": 1
    },
    {
      "x": -5,
      "y": 2,
      "z": 5,
      "name": "Wood_Softwood_Beam",
      "rotation": 1
    },
    {
      "x": -5,
      "y": 3,
      "z": 5,
      "name": "Wood_Softwood_Beam",
      "rotation": 1
    },
    {
      "x": -5,
      "y": 4,
      "z": 5,
      "name": "Wood_Softwood_Beam",
      "rotation": 1
    },
    {
      "x": -5,
      "y": 5,
      "z": 5,
      "name": "Rock_Stone_Cobble_Roof",
      "rotation": 3
    },
    {
      "x": -5,
      "y": 11,
      "z": 5,
      "name": "Plant_Moss_Wall_Green",
      "support": 15,
      "rotation": 3
    },
    {
      "x": -5,
      "y": 12,
      "z": 5,
      "name": "Plant_Moss_Wall_Green_Dark",
      "support": 15,
      "rotation": 3
    },
    {
      "x": -5,
      "y": 0,
      "z": 6,
      "name": "Wood_Deadwood_Planks",
      "rotation": 1
    },
    {
      "x": -5,
      "y": 0,
      "z": 7,
      "name": "Wood_Deadwood_Planks",
      "rotation": 1
    },
    {
      "x": -5,
      "y": 0,
      "z": 8,
      "name": "Wood_Deadwood_Planks",
      "rotation": 1
    },
    {
      "x": -4,
      "y": 0,
      "z": -8,
      "name": "Wood_Deadwood_Planks",
      "rotation": 1
    },
    {
      "x": -4,
      "y": 0,
      "z": -7,
      "name": "Wood_Deadwood_Planks",
      "rotation": 1
    },
    {
      "x": -4,
      "y": 0,
      "z": -6,
      "name": "Wood_Deadwood_Planks",
      "rotation": 1
    },
    {
      "x": -4,
      "y": 2,
      "z": -6,
      "name": "Plant_Moss_Wall_Green",
      "support": 15,
      "rotation": 3
    },
    {
      "x": -4,
      "y": 3,
      "z": -6,
      "name": "Plant_Moss_Wall_Green_Dark",
      "support": 15,
      "rotation": 3
    },
    {
      "x": -4,
      "y": 0,
      "z": -5,
      "name": "Wood_Deadwood_Planks",
      "rotation": 1
    },
    {
      "x": -4,
      "y": 1,
      "z": -5,
      "name": "Furniture_Kweebec_Shelf",
      "rotation": 3
    },
    {
      "x": -4,
      "y": 0,
      "z": -4,
      "name": "Wood_Deadwood_Planks",
      "rotation": 1
    },
    {
      "x": -4,
      "y": 4,
      "z": -4,
      "name": "Plant_Moss_Wall_Green_Dark",
      "support": 15,
      "rotation": 3
    },
    {
      "x": -4,
      "y": 0,
      "z": -3,
      "name": "Wood_Deadwood_Planks",
      "rotation": 1
    },
    {
      "x": -4,
      "y": 0,
      "z": -2,
      "name": "Wood_Deadwood_Planks",
      "rotation": 1
    },
    {
      "x": -4,
      "y": 5,
      "z": -2,
      "name": "Plant_Moss_Wall_Green",
      "support": 15,
      "rotation": 3
    },
    {
      "x": -4,
      "y": 0,
      "z": -1,
      "name": "Wood_Deadwood_Planks",
      "rotation": 1
    },
    {
      "x": -4,
      "y": 5,
      "z": -1,
      "name": "Plant_Moss_Wall_Green",
      "support": 15,
      "rotation": 3
    },
    {
      "x": -4,
      "y": 10,
      "z": -1,
      "name": "*Wood_Deadwood_Stairs_State_Definitions_Corner_Left",
      "rotation": 9
    },
    {
      "x": -4,
      "y": 11,
      "z": -1,
      "name": "Rock_Stone_Cobble_Roof_Steep",
      "rotation": 2
    },
    {
      "x": -4,
      "y": 12,
      "z": -1,
      "name": "Rock_Stone_Cobble_Roof_Steep",
      "filler": 1024,
      "rotation": 2
    },
    {
      "x": -4,
      "y": 0,
      "z": 0,
      "name": "Wood_Deadwood_Planks",
      "rotation": 1
    },
    {
      "x": -4,
      "y": 1,
      "z": 0,
      "name": "Wood_Deadwood_Planks",
      "rotation": 1
    },
    {
      "x": -4,
      "y": 2,
      "z": 0,
      "name": "Wood_Deadwood_Planks",
      "rotation": 1
    },
    {
      "x": -4,
      "y": 3,
      "z": 0,
      "name": "Wood_Deadwood_Planks",
      "rotation": 1
    },
    {
      "x": -4,
      "y": 4,
      "z": 0,
      "name": "Wood_Deadwood_Planks",
      "rotation": 1
    },
    {
      "x": -4,
      "y": 5,
      "z": 0,
      "name": "Wood_Deadwood_Planks",
      "rotation": 1
    },
    {
      "x": -4,
      "y": 6,
      "z": 0,
      "name": "Rock_Stone_Cobble_Roof",
      "rotation": 3
    },
    {
      "x": -4,
      "y": 8,
      "z": 0,
      "name": "Plant_Moss_Wall_Green",
      "support": 15,
      "rotation": 3
    },
    {
      "x": -4,
      "y": 9,
      "z": 0,
      "name": "Plant_Moss_Wall_Green_Dark",
      "support": 15,
      "rotation": 3
    },
    {
      "x": -4,
      "y": 10,
      "z": 0,
      "name": "Wood_Deadwood_Stairs",
      "rotation": 9
    },
    {
      "x": -4,
      "y": 11,
      "z": 0,
      "name": "Wood_Deadwood_Ornate",
      "rotation": 1
    },
    {
      "x": -4,
      "y": 12,
      "z": 0,
      "name": "Wood_Deadwood_Ornate",
      "rotation": 1
    },
    {
      "x": -4,
      "y": 13,
      "z": 0,
      "name": "Rock_Stone_Cobble_Roof_Steep",
      "rotation": 2
    },
    {
      "x": -4,
      "y": 14,
      "z": 0,
      "name": "Rock_Stone_Cobble_Roof_Steep",
      "filler": 1024,
      "rotation": 2
    },
    {
      "x": -4,
      "y": 0,
      "z": 1,
      "name": "Wood_Deadwood_Planks",
      "rotation": 1
    },
    {
      "x": -4,
      "y": 1,
      "z": 1,
      "name": "Wood_Deadwood_Planks",
      "rotation": 1
    },
    {
      "x": -4,
      "y": 2,
      "z": 1,
      "name": "Wood_Deadwood_Planks",
      "rotation": 1
    },
    {
      "x": -4,
      "y": 3,
      "z": 1,
      "name": "Wood_Deadwood_Planks",
      "rotation": 1
    },
    {
      "x": -4,
      "y": 4,
      "z": 1,
      "name": "Wood_Deadwood_Planks",
      "rotation": 1
    },
    {
      "x": -4,
      "y": 5,
      "z": 1,
      "name": "Wood_Deadwood_Planks",
      "rotation": 1
    },
    {
      "x": -4,
      "y": 6,
      "z": 1,
      "name": "Rock_Stone_Cobble_Roof",
      "rotation": 3
    },
    {
      "x": -4,
      "y": 7,
      "z": 1,
      "name": "Furniture_Crude_Ladder",
      "rotation": 3
    },
    {
      "x": -4,
      "y": 8,
      "z": 1,
      "name": "Furniture_Crude_Ladder",
      "rotation": 3
    },
    {
      "x": -4,
      "y": 9,
      "z": 1,
      "name": "Furniture_Crude_Ladder",
      "rotation": 3
    },
    {
      "x": -4,
      "y": 10,
      "z": 1,
      "name": "Wood_Deadwood_Stairs",
      "rotation": 9
    },
    {
      "x": -4,
      "y": 11,
      "z": 1,
      "name": "Wood_Deadwood_Ornate",
      "rotation": 1
    },
    {
      "x": -4,
      "y": 12,
      "z": 1,
      "name": "Wood_Deadwood_Ornate",
      "rotation": 1
    },
    {
      "x": -4,
      "y": 13,
      "z": 1,
      "name": "Wood_Deadwood_Ornate",
      "rotation": 1
    },
    {
      "x": -4,
      "y": 14,
      "z": 1,
      "name": "Wood_Deadwood_Ornate",
      "rotation": 1
    },
    {
      "x": -4,
      "y": 15,
      "z": 1,
      "name": "Rock_Stone_Cobble_Roof_Steep",
      "rotation": 2
    },
    {
      "x": -4,
      "y": 16,
      "z": 1,
      "name": "Rock_Stone_Cobble_Roof_Steep",
      "filler": 1024,
      "rotation": 2
    },
    {
      "x": -4,
      "y": 0,
      "z": 2,
      "name": "Wood_Deadwood_Planks",
      "rotation": 1
    },
    {
      "x": -4,
      "y": 1,
      "z": 2,
      "name": "Furniture_Human_Ruins_Door",
      "rotation": 1
    },
    {
      "x": -4,
      "y": 2,
      "z": 2,
      "name": "Furniture_Human_Ruins_Door",
      "filler": 1024,
      "rotation": 1
    },
    {
      "x": -4,
      "y": 3,
      "z": 2,
      "name": "Wood_Deadwood_Planks",
      "rotation": 1
    },
    {
      "x": -4,
      "y": 4,
      "z": 2,
      "name": "Wood_Deadwood_Planks",
      "rotation": 1
    },
    {
      "x": -4,
      "y": 5,
      "z": 2,
      "name": "Wood_Deadwood_Planks",
      "rotation": 1
    },
    {
      "x": -4,
      "y": 6,
      "z": 2,
      "name": "Rock_Stone_Cobble_Roof",
      "rotation": 3
    },
    {
      "x": -4,
      "y": 9,
      "z": 2,
      "name": "Plant_Moss_Wall_Green",
      "support": 15,
      "rotation": 3
    },
    {
      "x": -4,
      "y": 10,
      "z": 2,
      "name": "Wood_Deadwood_Stairs",
      "rotation": 9
    },
    {
      "x": -4,
      "y": 11,
      "z": 2,
      "name": "Wood_Deadwood_Ornate",
      "rotation": 1
    },
    {
      "x": -4,
      "y": 12,
      "z": 2,
      "name": "Furniture_Human_Ruins_Window",
      "rotation": 1
    },
    {
      "x": -4,
      "y": 13,
      "z": 2,
      "name": "Cloth_Roof_Hide_Flap",
      "rotation": 1
    },
    {
      "x": -4,
      "y": 14,
      "z": 2,
      "name": "Wood_Deadwood_Ornate",
      "rotation": 1
    },
    {
      "x": -4,
      "y": 15,
      "z": 2,
      "name": "Wood_Deadwood_Ornate",
      "rotation": 1
    },
    {
      "x": -4,
      "y": 16,
      "z": 2,
      "name": "Wood_Deadwood_Ornate",
      "rotation": 1
    },
    {
      "x": -4,
      "y": 17,
      "z": 2,
      "name": "Rock_Stone_Cobble_Roof_Steep",
      "rotation": 2
    },
    {
      "x": -4,
      "y": 18,
      "z": 2,
      "name": "Rock_Stone_Cobble_Roof_Steep",
      "filler": 1024,
      "rotation": 2
    },
    {
      "x": -4,
      "y": 0,
      "z": 3,
      "name": "Wood_Deadwood_Planks",
      "rotation": 1
    },
    {
      "x": -4,
      "y": 1,
      "z": 3,
      "name": "Wood_Deadwood_Planks",
      "rotation": 1
    },
    {
      "x": -4,
      "y": 2,
      "z": 3,
      "name": "Wood_Deadwood_Planks",
      "rotation": 1
    },
    {
      "x": -4,
      "y": 3,
      "z": 3,
      "name": "Wood_Deadwood_Planks",
      "rotation": 1
    },
    {
      "x": -4,
      "y": 4,
      "z": 3,
      "name": "Wood_Deadwood_Planks",
      "rotation": 1
    },
    {
      "x": -4,
      "y": 5,
      "z": 3,
      "name": "Wood_Deadwood_Planks",
      "rotation": 1
    },
    {
      "x": -4,
      "y": 6,
      "z": 3,
      "name": "Rock_Stone_Cobble_Roof",
      "rotation": 3
    },
    {
      "x": -4,
      "y": 8,
      "z": 3,
      "name": "Plant_Moss_Wall_Green_Dark",
      "support": 15,
      "rotation": 3
    },
    {
      "x": -4,
      "y": 10,
      "z": 3,
      "name": "Wood_Deadwood_Stairs",
      "rotation": 9
    },
    {
      "x": -4,
      "y": 11,
      "z": 3,
      "name": "Wood_Deadwood_Ornate",
      "rotation": 1
    },
    {
      "x": -4,
      "y": 12,
      "z": 3,
      "name": "Furniture_Human_Ruins_Window",
      "rotation": 1
    },
    {
      "x": -4,
      "y": 13,
      "z": 3,
      "name": "Cloth_Roof_Hide_Flap",
      "rotation": 1
    },
    {
      "x": -4,
      "y": 14,
      "z": 3,
      "name": "Wood_Deadwood_Ornate",
      "rotation": 1
    },
    {
      "x": -4,
      "y": 15,
      "z": 3,
      "name": "Wood_Deadwood_Ornate",
      "rotation": 1
    },
    {
      "x": -4,
      "y": 16,
      "z": 3,
      "name": "Wood_Deadwood_Ornate",
      "rotation": 1
    },
    {
      "x": -4,
      "y": 17,
      "z": 3,
      "name": "Rock_Stone_Cobble_Roof_Steep"
    },
    {
      "x": -4,
      "y": 18,
      "z": 3,
      "name": "Rock_Stone_Cobble_Roof_Steep",
      "filler": 1024
    },
    {
      "x": -4,
      "y": 0,
      "z": 4,
      "name": "Wood_Deadwood_Planks",
      "rotation": 1
    },
    {
      "x": -4,
      "y": 1,
      "z": 4,
      "name": "Wood_Deadwood_Planks",
      "rotation": 1
    },
    {
      "x": -4,
      "y": 2,
      "z": 4,
      "name": "Wood_Deadwood_Planks",
      "rotation": 1
    },
    {
      "x": -4,
      "y": 3,
      "z": 4,
      "name": "Wood_Deadwood_Planks",
      "rotation": 1
    },
    {
      "x": -4,
      "y": 4,
      "z": 4,
      "name": "Wood_Deadwood_Planks",
      "rotation": 1
    },
    {
      "x": -4,
      "y": 5,
      "z": 4,
      "name": "Wood_Deadwood_Planks",
      "rotation": 1
    },
    {
      "x": -4,
      "y": 6,
      "z": 4,
      "name": "Rock_Stone_Cobble_Roof",
      "rotation": 3
    },
    {
      "x": -4,
      "y": 7,
      "z": 4,
      "name": "Furniture_Crude_Ladder",
      "rotation": 3
    },
    {
      "x": -4,
      "y": 8,
      "z": 4,
      "name": "Furniture_Crude_Ladder",
      "rotation": 3
    },
    {
      "x": -4,
      "y": 9,
      "z": 4,
      "name": "Furniture_Crude_Ladder",
      "rotation": 3
    },
    {
      "x": -4,
      "y": 10,
      "z": 4,
      "name": "Wood_Deadwood_Stairs",
      "rotation": 9
    },
    {
      "x": -4,
      "y": 11,
      "z": 4,
      "name": "Wood_Deadwood_Ornate",
      "rotation": 1
    },
    {
      "x": -4,
      "y": 12,
      "z": 4,
      "name": "Wood_Deadwood_Ornate",
      "rotation": 1
    },
    {
      "x": -4,
      "y": 13,
      "z": 4,
      "name": "Wood_Deadwood_Ornate",
      "rotation": 1
    },
    {
      "x": -4,
      "y": 14,
      "z": 4,
      "name": "Wood_Deadwood_Ornate",
      "rotation": 1
    },
    {
      "x": -4,
      "y": 15,
      "z": 4,
      "name": "Rock_Stone_Cobble_Roof_Steep"
    },
    {
      "x": -4,
      "y": 16,
      "z": 4,
      "name": "Rock_Stone_Cobble_Roof_Steep",
      "filler": 1024
    },
    {
      "x": -4,
      "y": 0,
      "z": 5,
      "name": "Wood_Deadwood_Planks",
      "rotation": 1
    },
    {
      "x": -4,
      "y": 1,
      "z": 5,
      "name": "Wood_Deadwood_Planks",
      "rotation": 1
    },
    {
      "x": -4,
      "y": 2,
      "z": 5,
      "name": "Wood_Deadwood_Planks",
      "rotation": 1
    },
    {
      "x": -4,
      "y": 3,
      "z": 5,
      "name": "Wood_Deadwood_Planks",
      "rotation": 1
    },
    {
      "x": -4,
      "y": 4,
      "z": 5,
      "name": "Wood_Deadwood_Planks",
      "rotation": 1
    },
    {
      "x": -4,
      "y": 5,
      "z": 5,
      "name": "Wood_Deadwood_Planks",
      "rotation": 1
    },
    {
      "x": -4,
      "y": 6,
      "z": 5,
      "name": "Rock_Stone_Cobble_Roof",
      "rotation": 3
    },
    {
      "x": -4,
      "y": 8,
      "z": 5,
      "name": "Plant_Moss_Wall_Green",
      "support": 15,
      "rotation": 3
    },
    {
      "x": -4,
      "y": 9,
      "z": 5,
      "name": "Plant_Moss_Wall_Green_Dark",
      "support": 15,
      "rotation": 3
    },
    {
      "x": -4,
      "y": 10,
      "z": 5,
      "name": "Wood_Deadwood_Stairs",
      "rotation": 9
    },
    {
      "x": -4,
      "y": 11,
      "z": 5,
      "name": "Wood_Deadwood_Ornate",
      "rotation": 1
    },
    {
      "x": -4,
      "y": 12,
      "z": 5,
      "name": "Wood_Deadwood_Ornate",
      "rotation": 1
    },
    {
      "x": -4,
      "y": 13,
      "z": 5,
      "name": "Rock_Stone_Cobble_Roof_Steep"
    },
    {
      "x": -4,
      "y": 14,
      "z": 5,
      "name": "Rock_Stone_Cobble_Roof_Steep",
      "filler": 1024
    },
    {
      "x": -4,
      "y": 0,
      "z": 6,
      "name": "Wood_Deadwood_Planks",
      "rotation": 1
    },
    {
      "x": -4,
      "y": 2,
      "z": 6,
      "name": "Plant_Moss_Wall_Green_Dark",
      "support": 15,
      "rotation": 3
    },
    {
      "x": -4,
      "y": 3,
      "z": 6,
      "name": "Plant_Moss_Wall_Green_Dark",
      "support": 15
    },
    {
      "x": -4,
      "y": 5,
      "z": 6,
      "name": "Plant_Moss_Wall_Green",
      "support": 15
    },
    {
      "x": -4,
      "y": 10,
      "z": 6,
      "name": "*Wood_Deadwood_Stairs_State_Definitions_Corner_Left",
      "rotation": 10
    },
    {
      "x": -4,
      "y": 11,
      "z": 6,
      "name": "Rock_Stone_Cobble_Roof_Steep"
    },
    {
      "x": -4,
      "y": 12,
      "z": 6,
      "name": "Rock_Stone_Cobble_Roof_Steep",
      "filler": 1024
    },
    {
      "x": -4,
      "y": 0,
      "z": 7,
      "name": "Wood_Deadwood_Planks",
      "rotation": 1
    },
    {
      "x": -4,
      "y": 0,
      "z": 8,
      "name": "Wood_Deadwood_Planks",
      "rotation": 1
    },
    {
      "x": -3,
      "y": 0,
      "z": -8,
      "name": "Wood_Deadwood_Planks",
      "rotation": 1
    },
    {
      "x": -3,
      "y": 0,
      "z": -7,
      "name": "Wood_Deadwood_Planks",
      "rotation": 1
    },
    {
      "x": -3,
      "y": 2,
      "z": -7,
      "name": "Plant_Moss_Wall_Green",
      "support": 15,
      "rotation": 2
    },
    {
      "x": -3,
      "y": 3,
      "z": -7,
      "name": "Plant_Moss_Wall_Green_Dark",
      "support": 15,
      "rotation": 2
    },
    {
      "x": -3,
      "y": 0,
      "z": -6,
      "name": "Wood_Deadwood_Planks",
      "rotation": 1
    },
    {
      "x": -3,
      "y": 1,
      "z": -6,
      "name": "Wood_Deadwood_Ornate",
      "rotation": 1
    },
    {
      "x": -3,
      "y": 2,
      "z": -6,
      "name": "Wood_Deadwood_Ornate",
      "rotation": 1
    },
    {
      "x": -3,
      "y": 3,
      "z": -6,
      "name": "Wood_Deadwood_Ornate",
      "rotation": 1
    },
    {
      "x": -3,
      "y": 4,
      "z": -6,
      "name": "Rock_Stone_Cobble_Roof_Shallow",
      "rotation": 2
    },
    {
      "x": -3,
      "y": 0,
      "z": -5,
      "name": "Wood_Deadwood_Planks",
      "rotation": 1
    },
    {
      "x": -3,
      "y": 1,
      "z": -5,
      "name": "Wood_Deadwood_Ornate",
      "rotation": 1
    },
    {
      "x": -3,
      "y": 2,
      "z": -5,
      "name": "Furniture_Human_Ruins_Window",
      "rotation": 1
    },
    {
      "x": -3,
      "y": 3,
      "z": -5,
      "name": "Wood_Deadwood_Ornate",
      "rotation": 1
    },
    {
      "x": -3,
      "y": 4,
      "z": -5,
      "name": "Rock_Stone_Cobble_Roof_Shallow",
      "filler": 32,
      "rotation": 2
    },
    {
      "x": -3,
      "y": 0,
      "z": -4,
      "name": "Wood_Deadwood_Planks",
      "rotation": 1
    },
    {
      "x": -3,
      "y": 1,
      "z": -4,
      "name": "Wood_Deadwood_Ornate",
      "rotation": 1
    },
    {
      "x": -3,
      "y": 2,
      "z": -4,
      "name": "Wood_Deadwood_Ornate",
      "rotation": 1
    },
    {
      "x": -3,
      "y": 3,
      "z": -4,
      "name": "Wood_Deadwood_Ornate",
      "rotation": 1
    },
    {
      "x": -3,
      "y": 4,
      "z": -4,
      "name": "Wood_Deadwood_Ornate",
      "rotation": 1
    },
    {
      "x": -3,
      "y": 5,
      "z": -4,
      "name": "Rock_Stone_Cobble_Roof_Shallow",
      "rotation": 2
    },
    {
      "x": -3,
      "y": 0,
      "z": -3,
      "name": "Wood_Deadwood_Planks",
      "rotation": 1
    },
    {
      "x": -3,
      "y": 4,
      "z": -3,
      "name": "Wood_Deadwood_Ornate",
      "rotation": 1
    },
    {
      "x": -3,
      "y": 5,
      "z": -3,
      "name": "Rock_Stone_Cobble_Roof_Shallow",
      "filler": 32,
      "rotation": 2
    },
    {
      "x": -3,
      "y": 0,
      "z": -2,
      "name": "Wood_Deadwood_Planks",
      "rotation": 1
    },
    {
      "x": -3,
      "y": 4,
      "z": -2,
      "name": "Wood_Deadwood_Ornate",
      "rotation": 1
    },
    {
      "x": -3,
      "y": 5,
      "z": -2,
      "name": "Wood_Deadwood_Ornate",
      "rotation": 1
    },
    {
      "x": -3,
      "y": 6,
      "z": -2,
      "name": "Rock_Stone_Cobble_Roof_Shallow",
      "rotation": 2
    },
    {
      "x": -3,
      "y": 0,
      "z": -1,
      "name": "Wood_Deadwood_Planks",
      "rotation": 1
    },
    {
      "x": -3,
      "y": 1,
      "z": -1,
      "name": "Wood_Deadwood_Ornate",
      "rotation": 1
    },
    {
      "x": -3,
      "y": 2,
      "z": -1,
      "name": "Wood_Deadwood_Ornate",
      "rotation": 1
    },
    {
      "x": -3,
      "y": 3,
      "z": -1,
      "name": "Wood_Deadwood_Ornate",
      "rotation": 1
    },
    {
      "x": -3,
      "y": 4,
      "z": -1,
      "name": "Wood_Deadwood_Ornate",
      "rotation": 1
    },
    {
      "x": -3,
      "y": 5,
      "z": -1,
      "name": "Wood_Deadwood_Ornate",
      "rotation": 1
    },
    {
      "x": -3,
      "y": 6,
      "z": -1,
      "name": "Rock_Stone_Cobble_Roof_Shallow",
      "filler": 32,
      "rotation": 2
    },
    {
      "x": -3,
      "y": 10,
      "z": -1,
      "name": "Wood_Deadwood_Stairs",
      "rotation": 8
    },
    {
      "x": -3,
      "y": 11,
      "z": -1,
      "name": "Rock_Stone_Cobble_Roof_Steep",
      "rotation": 2
    },
    {
      "x": -3,
      "y": 12,
      "z": -1,
      "name": "Rock_Stone_Cobble_Roof_Steep",
      "filler": 1024,
      "rotation": 2
    },
    {
      "x": -3,
      "y": 0,
      "z": 0,
      "name": "Wood_Deadwood_Planks",
      "rotation": 1
    },
    {
      "x": -3,
      "y": 1,
      "z": 0,
      "name": "Wood_Deadwood_Planks",
      "rotation": 1
    },
    {
      "x": -3,
      "y": 2,
      "z": 0,
      "name": "Wood_Deadwood_Planks",
      "rotation": 1
    },
    {
      "x": -3,
      "y": 3,
      "z": 0,
      "name": "Wood_Deadwood_Planks",
      "rotation": 1
    },
    {
      "x": -3,
      "y": 4,
      "z": 0,
      "name": "Wood_Deadwood_Planks",
      "rotation": 1
    },
    {
      "x": -3,
      "y": 5,
      "z": 0,
      "name": "Wood_Deadwood_Planks",
      "rotation": 1
    },
    {
      "x": -3,
      "y": 6,
      "z": 0,
      "name": "Wood_Deadwood_Planks",
      "rotation": 1
    },
    {
      "x": -3,
      "y": 7,
      "z": 0,
      "name": "Wood_Deadwood_Decorative",
      "rotation": 1
    },
    {
      "x": -3,
      "y": 8,
      "z": 0,
      "name": "Wood_Deadwood_Decorative",
      "rotation": 1
    },
    {
      "x": -3,
      "y": 9,
      "z": 0,
      "name": "Wood_Deadwood_Decorative",
      "rotation": 1
    },
    {
      "x": -3,
      "y": 10,
      "z": 0,
      "name": "Wood_Deadwood_Decorative",
      "rotation": 1
    },
    {
      "x": -3,
      "y": 11,
      "z": 0,
      "name": "Wood_Deadwood_Ornate",
      "rotation": 1
    },
    {
      "x": -3,
      "y": 12,
      "z": 0,
      "name": "Wood_Deadwood_Ornate",
      "rotation": 1
    },
    {
      "x": -3,
      "y": 13,
      "z": 0,
      "name": "Rock_Stone_Cobble_Roof_Steep",
      "rotation": 2
    },
    {
      "x": -3,
      "y": 14,
      "z": 0,
      "name": "Rock_Stone_Cobble_Roof_Steep",
      "filler": 1024,
      "rotation": 2
    },
    {
      "x": -3,
      "y": 0,
      "z": 1,
      "name": "Wood_Deadwood_Planks",
      "rotation": 1
    },
    {
      "x": -3,
      "y": 1,
      "z": 1,
      "name": "Wood_Deadwood_Planks",
      "rotation": 1
    },
    {
      "x": -3,
      "y": 2,
      "z": 1,
      "name": "Wood_Deadwood_Planks",
      "rotation": 1
    },
    {
      "x": -3,
      "y": 3,
      "z": 1,
      "name": "Wood_Deadwood_Planks",
      "rotation": 1
    },
    {
      "x": -3,
      "y": 4,
      "z": 1,
      "name": "Wood_Deadwood_Planks",
      "rotation": 1
    },
    {
      "x": -3,
      "y": 5,
      "z": 1,
      "name": "Wood_Deadwood_Planks",
      "rotation": 1
    },
    {
      "x": -3,
      "y": 6,
      "z": 1,
      "name": "Wood_Deadwood_Planks",
      "rotation": 1
    },
    {
      "x": -3,
      "y": 7,
      "z": 1,
      "name": "Wood_Deadwood_Decorative",
      "rotation": 1
    },
    {
      "x": -3,
      "y": 8,
      "z": 1,
      "name": "Wood_Deadwood_Decorative",
      "rotation": 1
    },
    {
      "x": -3,
      "y": 9,
      "z": 1,
      "name": "Wood_Deadwood_Decorative",
      "rotation": 1
    },
    {
      "x": -3,
      "y": 10,
      "z": 1,
      "name": "Wood_Deadwood_Decorative",
      "rotation": 1
    },
    {
      "x": -3,
      "y": 15,
      "z": 1,
      "name": "Rock_Stone_Cobble_Roof_Steep",
      "rotation": 2
    },
    {
      "x": -3,
      "y": 16,
      "z": 1,
      "name": "Rock_Stone_Cobble_Roof_Steep",
      "filler": 1024,
      "rotation": 2
    },
    {
      "x": -3,
      "y": 0,
      "z": 2,
      "name": "Wood_Deadwood_Planks",
      "rotation": 1
    },
    {
      "x": -3,
      "y": 5,
      "z": 2,
      "name": "Furniture_Crude_Platform",
      "rotation": 2
    },
    {
      "x": -3,
      "y": 6,
      "z": 2,
      "name": "Wood_Deadwood_Planks",
      "rotation": 1
    },
    {
      "x": -3,
      "y": 7,
      "z": 2,
      "name": "Wood_Deadwood_Decorative",
      "rotation": 1
    },
    {
      "x": -3,
      "y": 8,
      "z": 2,
      "name": "Wood_Deadwood_Decorative",
      "rotation": 1
    },
    {
      "x": -3,
      "y": 9,
      "z": 2,
      "name": "Wood_Deadwood_Decorative",
      "rotation": 1
    },
    {
      "x": -3,
      "y": 10,
      "z": 2,
      "name": "Wood_Deadwood_Decorative",
      "rotation": 1
    },
    {
      "x": -3,
      "y": 17,
      "z": 2,
      "name": "Rock_Stone_Cobble_Roof_Steep",
      "rotation": 2
    },
    {
      "x": -3,
      "y": 18,
      "z": 2,
      "name": "Rock_Stone_Cobble_Roof_Steep",
      "filler": 1024,
      "rotation": 2
    },
    {
      "x": -3,
      "y": 0,
      "z": 3,
      "name": "Wood_Deadwood_Planks",
      "rotation": 1
    },
    {
      "x": -3,
      "y": 5,
      "z": 3,
      "name": "Furniture_Crude_Platform",
      "rotation": 2
    },
    {
      "x": -3,
      "y": 6,
      "z": 3,
      "name": "Wood_Deadwood_Planks",
      "rotation": 1
    },
    {
      "x": -3,
      "y": 7,
      "z": 3,
      "name": "Wood_Deadwood_Decorative",
      "rotation": 1
    },
    {
      "x": -3,
      "y": 8,
      "z": 3,
      "name": "Wood_Deadwood_Decorative",
      "rotation": 1
    },
    {
      "x": -3,
      "y": 9,
      "z": 3,
      "name": "Wood_Deadwood_Decorative",
      "rotation": 1
    },
    {
      "x": -3,
      "y": 10,
      "z": 3,
      "name": "Wood_Deadwood_Decorative",
      "rotation": 1
    },
    {
      "x": -3,
      "y": 17,
      "z": 3,
      "name": "Rock_Stone_Cobble_Roof_Steep"
    },
    {
      "x": -3,
      "y": 18,
      "z": 3,
      "name": "Rock_Stone_Cobble_Roof_Steep",
      "filler": 1024
    },
    {
      "x": -3,
      "y": 0,
      "z": 4,
      "name": "Wood_Deadwood_Planks",
      "rotation": 1
    },
    {
      "x": -3,
      "y": 5,
      "z": 4,
      "name": "Furniture_Crude_Platform",
      "rotation": 2
    },
    {
      "x": -3,
      "y": 6,
      "z": 4,
      "name": "Wood_Deadwood_Planks",
      "rotation": 1
    },
    {
      "x": -3,
      "y": 7,
      "z": 4,
      "name": "Wood_Deadwood_Decorative",
      "rotation": 1
    },
    {
      "x": -3,
      "y": 8,
      "z": 4,
      "name": "Wood_Deadwood_Decorative",
      "rotation": 1
    },
    {
      "x": -3,
      "y": 9,
      "z": 4,
      "name": "Wood_Deadwood_Decorative",
      "rotation": 1
    },
    {
      "x": -3,
      "y": 10,
      "z": 4,
      "name": "Wood_Deadwood_Decorative",
      "rotation": 1
    },
    {
      "x": -3,
      "y": 15,
      "z": 4,
      "name": "Rock_Stone_Cobble_Roof_Steep"
    },
    {
      "x": -3,
      "y": 16,
      "z": 4,
      "name": "Rock_Stone_Cobble_Roof_Steep",
      "filler": 1024
    },
    {
      "x": -3,
      "y": 0,
      "z": 5,
      "name": "Wood_Deadwood_Planks",
      "rotation": 1
    },
    {
      "x": -3,
      "y": 5,
      "z": 5,
      "name": "Furniture_Crude_Platform",
      "rotation": 2
    },
    {
      "x": -3,
      "y": 6,
      "z": 5,
      "name": "Wood_Deadwood_Planks",
      "rotation": 1
    },
    {
      "x": -3,
      "y": 7,
      "z": 5,
      "name": "Wood_Deadwood_Decorative",
      "rotation": 1
    },
    {
      "x": -3,
      "y": 8,
      "z": 5,
      "name": "Wood_Deadwood_Decorative",
      "rotation": 1
    },
    {
      "x": -3,
      "y": 9,
      "z": 5,
      "name": "Wood_Deadwood_Decorative",
      "rotation": 1
    },
    {
      "x": -3,
      "y": 10,
      "z": 5,
      "name": "Wood_Deadwood_Decorative",
      "rotation": 1
    },
    {
      "x": -3,
      "y": 11,
      "z": 5,
      "name": "Wood_Deadwood_Ornate",
      "rotation": 1
    },
    {
      "x": -3,
      "y": 12,
      "z": 5,
      "name": "Wood_Deadwood_Ornate",
      "rotation": 1
    },
    {
      "x": -3,
      "y": 13,
      "z": 5,
      "name": "Rock_Stone_Cobble_Roof_Steep"
    },
    {
      "x": -3,
      "y": 14,
      "z": 5,
      "name": "Rock_Stone_Cobble_Roof_Steep",
      "filler": 1024
    },
    {
      "x": -3,
      "y": 0,
      "z": 6,
      "name": "Wood_Deadwood_Planks",
      "rotation": 1
    },
    {
      "x": -3,
      "y": 1,
      "z": 6,
      "name": "Wood_Deadwood_Planks",
      "rotation": 1
    },
    {
      "x": -3,
      "y": 2,
      "z": 6,
      "name": "Wood_Deadwood_Planks",
      "rotation": 1
    },
    {
      "x": -3,
      "y": 3,
      "z": 6,
      "name": "Wood_Deadwood_Planks",
      "rotation": 1
    },
    {
      "x": -3,
      "y": 4,
      "z": 6,
      "name": "Wood_Deadwood_Planks",
      "rotation": 1
    },
    {
      "x": -3,
      "y": 5,
      "z": 6,
      "name": "Wood_Deadwood_Planks",
      "rotation": 1
    },
    {
      "x": -3,
      "y": 6,
      "z": 6,
      "name": "Rock_Stone_Cobble_Roof"
    },
    {
      "x": -3,
      "y": 8,
      "z": 6,
      "name": "Plant_Moss_Wall_Green",
      "support": 15
    },
    {
      "x": -3,
      "y": 9,
      "z": 6,
      "name": "Plant_Moss_Wall_Green_Dark",
      "support": 15
    },
    {
      "x": -3,
      "y": 10,
      "z": 6,
      "name": "Wood_Deadwood_Stairs",
      "rotation": 10
    },
    {
      "x": -3,
      "y": 11,
      "z": 6,
      "name": "Rock_Stone_Cobble_Roof_Steep"
    },
    {
      "x": -3,
      "y": 12,
      "z": 6,
      "name": "Rock_Stone_Cobble_Roof_Steep",
      "filler": 1024
    },
    {
      "x": -3,
      "y": 0,
      "z": 7,
      "name": "Wood_Deadwood_Planks",
      "rotation": 1
    },
    {
      "x": -3,
      "y": 1,
      "z": 7,
      "name": "Wood_Softwood_Beam",
      "rotation": 1
    },
    {
      "x": -3,
      "y": 2,
      "z": 7,
      "name": "Wood_Softwood_Beam",
      "rotation": 1
    },
    {
      "x": -3,
      "y": 3,
      "z": 7,
      "name": "Wood_Softwood_Beam",
      "rotation": 1
    },
    {
      "x": -3,
      "y": 4,
      "z": 7,
      "name": "Wood_Softwood_Beam",
      "rotation": 1
    },
    {
      "x": -3,
      "y": 5,
      "z": 7,
      "name": "Rock_Stone_Cobble_Roof"
    },
    {
      "x": -3,
      "y": 0,
      "z": 8,
      "name": "Wood_Deadwood_Planks",
      "rotation": 1
    },
    {
      "x": -2,
      "y": 0,
      "z": -8,
      "name": "Wood_Deadwood_Planks",
      "rotation": 1
    },
    {
      "x": -2,
      "y": 0,
      "z": -7,
      "name": "Wood_Deadwood_Planks",
      "rotation": 1
    },
    {
      "x": -2,
      "y": 0,
      "z": -6,
      "name": "Wood_Deadwood_Planks",
      "rotation": 1
    },
    {
      "x": -2,
      "y": 1,
      "z": -6,
      "name": "Wood_Deadwood_Fence",
      "rotation": 2
    },
    {
      "x": -2,
      "y": 4,
      "z": -6,
      "name": "Rock_Stone_Cobble_Roof_Shallow",
      "rotation": 2
    },
    {
      "x": -2,
      "y": 0,
      "z": -5,
      "name": "Wood_Deadwood_Planks",
      "rotation": 1
    },
    {
      "x": -2,
      "y": 1,
      "z": -5,
      "name": "Bench_Weapon",
      "components": {
        "Components": {
          "BenchBlock": {
            "TierLevel": 1,
            "UpgradeItems": []
          },
          "PlacedByInteraction": {
            "WhoPlacedUuid": {
              "$binary": "LX9SOyJtQGqmYXD75rCkcQ==",
              "$type": "04"
            }
          }
        }
      },
      "rotation": 1
    },
    {
      "x": -2,
      "y": 2,
      "z": -5,
      "name": "Bench_Weapon",
      "filler": 1024,
      "rotation": 1
    },
    {
      "x": -2,
      "y": 4,
      "z": -5,
      "name": "Rock_Stone_Cobble_Roof_Shallow",
      "filler": 32,
      "rotation": 2
    },
    {
      "x": -2,
      "y": 0,
      "z": -4,
      "name": "Wood_Deadwood_Planks",
      "rotation": 1
    },
    {
      "x": -2,
      "y": 1,
      "z": -4,
      "name": "Bench_Weapon",
      "filler": 32,
      "rotation": 1
    },
    {
      "x": -2,
      "y": 2,
      "z": -4,
      "name": "Bench_Weapon",
      "filler": 1056,
      "rotation": 1
    },
    {
      "x": -2,
      "y": 4,
      "z": -4,
      "name": "Rock_Stone_Cobble_Mossy",
      "rotation": 1
    },
    {
      "x": -2,
      "y": 5,
      "z": -4,
      "name": "Rock_Stone_Brick_Mossy",
      "rotation": 1
    },
    {
      "x": -2,
      "y": 6,
      "z": -4,
      "name": "Wood_Beech_Branch_Long",
      "support": 15,
      "rotation": 1
    },
    {
      "x": -2,
      "y": 7,
      "z": -4,
      "name": "Wood_Beech_Branch_Long",
      "support": 15,
      "rotation": 1
    },
    {
      "x": -2,
      "y": 8,
      "z": -4,
      "name": "*Rock_Stone_Cobble_Roof_Steep_State_Definitions_Corner_Right",
      "rotation": 3
    },
    {
      "x": -2,
      "y": 9,
      "z": -4,
      "name": "*Rock_Stone_Cobble_Roof_Steep_State_Definitions_Corner_Right",
      "filler": 1024,
      "rotation": 3
    },
    {
      "x": -2,
      "y": 0,
      "z": -3,
      "name": "Wood_Deadwood_Planks",
      "rotation": 1
    },
    {
      "x": -2,
      "y": 4,
      "z": -3,
      "name": "Rock_Stone_Brick_Mossy",
      "rotation": 1
    },
    {
      "x": -2,
      "y": 5,
      "z": -3,
      "name": "Rock_Stone_Cobble_Mossy",
      "rotation": 1
    },
    {
      "x": -2,
      "y": 6,
      "z": -3,
      "name": "Wood_Beech_Branch_Long",
      "support": 15,
      "rotation": 1
    },
    {
      "x": -2,
      "y": 7,
      "z": -3,
      "name": "Wood_Beech_Branch_Long",
      "support": 15,
      "rotation": 1
    },
    {
      "x": -2,
      "y": 8,
      "z": -3,
      "name": "*Rock_Stone_Cobble_Roof_Steep_State_Definitions_Corner_Left",
      "rotation": 3
    },
    {
      "x": -2,
      "y": 9,
      "z": -3,
      "name": "*Rock_Stone_Cobble_Roof_Steep_State_Definitions_Corner_Left",
      "filler": 1024,
      "rotation": 3
    },
    {
      "x": -2,
      "y": 0,
      "z": -2,
      "name": "Wood_Deadwood_Planks",
      "rotation": 1
    },
    {
      "x": -2,
      "y": 4,
      "z": -2,
      "name": "Rock_Stone_Brick_Mossy",
      "rotation": 1
    },
    {
      "x": -2,
      "y": 5,
      "z": -2,
      "name": "Rock_Stone_Brick_Mossy",
      "rotation": 1
    },
    {
      "x": -2,
      "y": 6,
      "z": -2,
      "name": "Rock_Stone_Cobble_Roof_Shallow",
      "rotation": 2
    },
    {
      "x": -2,
      "y": 0,
      "z": -1,
      "name": "Wood_Deadwood_Planks",
      "rotation": 1
    },
    {
      "x": -2,
      "y": 1,
      "z": -1,
      "name": "Wood_Deadwood_Planks",
      "rotation": 1
    },
    {
      "x": -2,
      "y": 2,
      "z": -1,
      "name": "Wood_Deadwood_Planks",
      "rotation": 1
    },
    {
      "x": -2,
      "y": 3,
      "z": -1,
      "name": "Wood_Deadwood_Planks",
      "rotation": 1
    },
    {
      "x": -2,
      "y": 4,
      "z": -1,
      "name": "Wood_Deadwood_Planks",
      "rotation": 1
    },
    {
      "x": -2,
      "y": 5,
      "z": -1,
      "name": "Wood_Deadwood_Planks",
      "rotation": 1
    },
    {
      "x": -2,
      "y": 6,
      "z": -1,
      "name": "Rock_Stone_Cobble_Roof_Shallow",
      "filler": 32,
      "rotation": 2
    },
    {
      "x": -2,
      "y": 7,
      "z": -1,
      "name": "*Furniture_Human_Ruins_Trapdoor_State_Definitions_OpenDoorOut",
      "rotation": 2
    },
    {
      "x": -2,
      "y": 8,
      "z": -1,
      "name": "*Furniture_Human_Ruins_Trapdoor_State_Definitions_OpenDoorOut",
      "rotation": 2
    },
    {
      "x": -2,
      "y": 9,
      "z": -1,
      "name": "*Furniture_Human_Ruins_Trapdoor_State_Definitions_OpenDoorOut",
      "rotation": 2
    },
    {
      "x": -2,
      "y": 10,
      "z": -1,
      "name": "Wood_Deadwood_Stairs",
      "rotation": 8
    },
    {
      "x": -2,
      "y": 11,
      "z": -1,
      "name": "Rock_Stone_Cobble_Roof_Steep",
      "rotation": 2
    },
    {
      "x": -2,
      "y": 12,
      "z": -1,
      "name": "Rock_Stone_Cobble_Roof_Steep",
      "filler": 1024,
      "rotation": 2
    },
    {
      "x": -2,
      "y": 0,
      "z": 0,
      "name": "Wood_Deadwood_Planks",
      "rotation": 1
    },
    {
      "x": -2,
      "y": 1,
      "z": 0,
      "name": "Wood_Deadwood_Planks",
      "rotation": 1
    },
    {
      "x": -2,
      "y": 2,
      "z": 0,
      "name": "Wood_Deadwood_Planks",
      "rotation": 1
    },
    {
      "x": -2,
      "y": 3,
      "z": 0,
      "name": "Wood_Deadwood_Planks",
      "rotation": 1
    },
    {
      "x": -2,
      "y": 4,
      "z": 0,
      "name": "Wood_Deadwood_Planks",
      "rotation": 1
    },
    {
      "x": -2,
      "y": 5,
      "z": 0,
      "name": "Wood_Deadwood_Planks",
      "rotation": 1
    },
    {
      "x": -2,
      "y": 6,
      "z": 0,
      "name": "Wood_Deadwood_Planks",
      "rotation": 1
    },
    {
      "x": -2,
      "y": 7,
      "z": 0,
      "name": "Wood_Deadwood_Decorative",
      "rotation": 1
    },
    {
      "x": -2,
      "y": 8,
      "z": 0,
      "name": "Wood_Deadwood_Decorative",
      "rotation": 1
    },
    {
      "x": -2,
      "y": 9,
      "z": 0,
      "name": "Wood_Deadwood_Decorative",
      "rotation": 1
    },
    {
      "x": -2,
      "y": 10,
      "z": 0,
      "name": "Wood_Deadwood_Decorative",
      "rotation": 1
    },
    {
      "x": -2,
      "y": 11,
      "z": 0,
      "name": "Wood_Deadwood_Ornate",
      "rotation": 1
    },
    {
      "x": -2,
      "y": 12,
      "z": 0,
      "name": "Wood_Deadwood_Ornate",
      "rotation": 1
    },
    {
      "x": -2,
      "y": 13,
      "z": 0,
      "name": "Rock_Stone_Cobble_Roof_Steep",
      "rotation": 2
    },
    {
      "x": -2,
      "y": 14,
      "z": 0,
      "name": "Rock_Stone_Cobble_Roof_Steep",
      "filler": 1024,
      "rotation": 2
    },
    {
      "x": -2,
      "y": 0,
      "z": 1,
      "name": "Wood_Deadwood_Planks",
      "rotation": 1
    },
    {
      "x": -2,
      "y": 1,
      "z": 1,
      "name": "Furniture_Tavern_Ladder"
    },
    {
      "x": -2,
      "y": 2,
      "z": 1,
      "name": "Furniture_Tavern_Ladder"
    },
    {
      "x": -2,
      "y": 3,
      "z": 1,
      "name": "Furniture_Tavern_Ladder"
    },
    {
      "x": -2,
      "y": 4,
      "z": 1,
      "name": "Furniture_Tavern_Ladder"
    },
    {
      "x": -2,
      "y": 5,
      "z": 1,
      "name": "Furniture_Tavern_Ladder"
    },
    {
      "x": -2,
      "y": 6,
      "z": 1,
      "name": "Furniture_Tavern_Ladder"
    },
    {
      "x": -2,
      "y": 7,
      "z": 1,
      "name": "Furniture_Tavern_Ladder"
    },
    {
      "x": -2,
      "y": 8,
      "z": 1,
      "name": "Furniture_Tavern_Ladder"
    },
    {
      "x": -2,
      "y": 9,
      "z": 1,
      "name": "Furniture_Tavern_Ladder"
    },
    {
      "x": -2,
      "y": 10,
      "z": 1,
      "name": "Furniture_Tavern_Ladder"
    },
    {
      "x": -2,
      "y": 11,
      "z": 1,
      "name": "Furniture_Tavern_Ladder"
    },
    {
      "x": -2,
      "y": 12,
      "z": 1,
      "name": "Furniture_Tavern_Ladder"
    },
    {
      "x": -2,
      "y": 13,
      "z": 1,
      "name": "Furniture_Tavern_Ladder"
    },
    {
      "x": -2,
      "y": 14,
      "z": 1,
      "name": "Furniture_Tavern_Ladder"
    },
    {
      "x": -2,
      "y": 15,
      "z": 1,
      "name": "Rock_Stone_Cobble_Roof_Steep",
      "rotation": 2
    },
    {
      "x": -2,
      "y": 16,
      "z": 1,
      "name": "Rock_Stone_Cobble_Roof_Steep",
      "filler": 1024,
      "rotation": 2
    },
    {
      "x": -2,
      "y": 0,
      "z": 2,
      "name": "Wood_Deadwood_Planks",
      "rotation": 1
    },
    {
      "x": -2,
      "y": 5,
      "z": 2,
      "name": "Furniture_Crude_Platform",
      "rotation": 2
    },
    {
      "x": -2,
      "y": 10,
      "z": 2,
      "name": "Furniture_Crude_Platform",
      "rotation": 1
    },
    {
      "x": -2,
      "y": 17,
      "z": 2,
      "name": "Rock_Stone_Cobble_Roof_Steep",
      "rotation": 2
    },
    {
      "x": -2,
      "y": 18,
      "z": 2,
      "name": "Rock_Stone_Cobble_Roof_Steep",
      "filler": 1024,
      "rotation": 2
    },
    {
      "x": -2,
      "y": 0,
      "z": 3,
      "name": "Wood_Deadwood_Planks",
      "rotation": 1
    },
    {
      "x": -2,
      "y": 5,
      "z": 3,
      "name": "Furniture_Crude_Platform",
      "rotation": 2
    },
    {
      "x": -2,
      "y": 10,
      "z": 3,
      "name": "Furniture_Crude_Platform",
      "rotation": 1
    },
    {
      "x": -2,
      "y": 17,
      "z": 3,
      "name": "Rock_Stone_Cobble_Roof_Steep"
    },
    {
      "x": -2,
      "y": 18,
      "z": 3,
      "name": "Rock_Stone_Cobble_Roof_Steep",
      "filler": 1024
    },
    {
      "x": -2,
      "y": 0,
      "z": 4,
      "name": "Wood_Deadwood_Planks",
      "rotation": 1
    },
    {
      "x": -2,
      "y": 5,
      "z": 4,
      "name": "Furniture_Crude_Platform",
      "rotation": 2
    },
    {
      "x": -2,
      "y": 10,
      "z": 4,
      "name": "Furniture_Crude_Platform",
      "rotation": 1
    },
    {
      "x": -2,
      "y": 15,
      "z": 4,
      "name": "Rock_Stone_Cobble_Roof_Steep"
    },
    {
      "x": -2,
      "y": 16,
      "z": 4,
      "name": "Rock_Stone_Cobble_Roof_Steep",
      "filler": 1024
    },
    {
      "x": -2,
      "y": 0,
      "z": 5,
      "name": "Wood_Deadwood_Planks",
      "rotation": 1
    },
    {
      "x": -2,
      "y": 5,
      "z": 5,
      "name": "Furniture_Crude_Platform",
      "rotation": 2
    },
    {
      "x": -2,
      "y": 6,
      "z": 5,
      "name": "Wood_Deadwood_Planks",
      "rotation": 1
    },
    {
      "x": -2,
      "y": 7,
      "z": 5,
      "name": "Wood_Deadwood_Decorative",
      "rotation": 1
    },
    {
      "x": -2,
      "y": 8,
      "z": 5,
      "name": "Furniture_Human_Ruins_Window",
      "rotation": 2
    },
    {
      "x": -2,
      "y": 9,
      "z": 5,
      "name": "Wood_Deadwood_Decorative",
      "rotation": 1
    },
    {
      "x": -2,
      "y": 10,
      "z": 5,
      "name": "Wood_Deadwood_Decorative",
      "rotation": 1
    },
    {
      "x": -2,
      "y": 11,
      "z": 5,
      "name": "Wood_Deadwood_Ornate",
      "rotation": 1
    },
    {
      "x": -2,
      "y": 12,
      "z": 5,
      "name": "Wood_Deadwood_Ornate",
      "rotation": 1
    },
    {
      "x": -2,
      "y": 13,
      "z": 5,
      "name": "Rock_Stone_Cobble_Roof_Steep"
    },
    {
      "x": -2,
      "y": 14,
      "z": 5,
      "name": "Rock_Stone_Cobble_Roof_Steep",
      "filler": 1024
    },
    {
      "x": -2,
      "y": 0,
      "z": 6,
      "name": "Wood_Deadwood_Planks",
      "rotation": 1
    },
    {
      "x": -2,
      "y": 1,
      "z": 6,
      "name": "Wood_Deadwood_Planks",
      "rotation": 1
    },
    {
      "x": -2,
      "y": 2,
      "z": 6,
      "name": "Wood_Deadwood_Planks",
      "rotation": 1
    },
    {
      "x": -2,
      "y": 3,
      "z": 6,
      "name": "Wood_Deadwood_Planks",
      "rotation": 1
    },
    {
      "x": -2,
      "y": 4,
      "z": 6,
      "name": "Wood_Deadwood_Planks",
      "rotation": 1
    },
    {
      "x": -2,
      "y": 5,
      "z": 6,
      "name": "Wood_Deadwood_Planks",
      "rotation": 1
    },
    {
      "x": -2,
      "y": 6,
      "z": 6,
      "name": "Rock_Stone_Cobble_Roof"
    },
    {
      "x": -2,
      "y": 7,
      "z": 6,
      "name": "Furniture_Kweebec_Shelf"
    },
    {
      "x": -2,
      "y": 9,
      "z": 6,
      "name": "Cloth_Roof_Hide_Flap"
    },
    {
      "x": -2,
      "y": 10,
      "z": 6,
      "name": "Wood_Deadwood_Stairs",
      "rotation": 10
    },
    {
      "x": -2,
      "y": 11,
      "z": 6,
      "name": "Rock_Stone_Cobble_Roof_Steep"
    },
    {
      "x": -2,
      "y": 12,
      "z": 6,
      "name": "Rock_Stone_Cobble_Roof_Steep",
      "filler": 1024
    },
    {
      "x": -2,
      "y": 0,
      "z": 7,
      "name": "Wood_Deadwood_Planks",
      "rotation": 1
    },
    {
      "x": -2,
      "y": 1,
      "z": 7,
      "name": "Furniture_Human_Ruins_Wardrobe",
      "filler": 31
    },
    {
      "x": -2,
      "y": 2,
      "z": 7,
      "name": "Furniture_Human_Ruins_Wardrobe",
      "filler": 1055
    },
    {
      "x": -2,
      "y": 4,
      "z": 7,
      "name": "Plant_Moss_Wall_Green_Dark",
      "support": 15
    },
    {
      "x": -2,
      "y": 5,
      "z": 7,
      "name": "Rock_Stone_Cobble_Roof_Hollow"
    },
    {
      "x": -2,
      "y": 0,
      "z": 8,
      "name": "Wood_Deadwood_Planks",
      "rotation": 1
    },
    {
      "x": -1,
      "y": 0,
      "z": -8,
      "name": "Wood_Deadwood_Planks",
      "rotation": 1
    },
    {
      "x": -1,
      "y": 0,
      "z": -7,
      "name": "Wood_Deadwood_Planks",
      "rotation": 1
    },
    {
      "x": -1,
      "y": 0,
      "z": -6,
      "name": "Wood_Deadwood_Planks",
      "rotation": 1
    },
    {
      "x": -1,
      "y": 4,
      "z": -6,
      "name": "Rock_Stone_Cobble_Roof_Shallow",
      "rotation": 2
    },
    {
      "x": -1,
      "y": 0,
      "z": -5,
      "name": "Wood_Deadwood_Planks",
      "rotation": 1
    },
    {
      "x": -1,
      "y": 4,
      "z": -5,
      "name": "Rock_Stone_Cobble_Roof_Shallow",
      "filler": 32,
      "rotation": 2
    },
    {
      "x": -1,
      "y": 0,
      "z": -4,
      "name": "Wood_Deadwood_Planks",
      "rotation": 1
    },
    {
      "x": -1,
      "y": 4,
      "z": -4,
      "name": "Rock_Stone_Brick_Mossy",
      "rotation": 1
    },
    {
      "x": -1,
      "y": 5,
      "z": -4,
      "name": "Bench_Furnace",
      "components": {
        "Components": {
          "BenchBlock": {
            "TierLevel": 1,
            "UpgradeItems": []
          },
          "ProcessingBenchBlock": {
            "InputContainer": {
              "Id": "Simple",
              "Capacity": 2,
              "Items": {}
            },
            "FuelContainer": {
              "Id": "Simple",
              "Capacity": 1,
              "Items": {}
            },
            "OutputContainer": {
              "Id": "Simple",
              "Capacity": 4,
              "Items": {}
            },
            "Progress": 0.0,
            "FuelTime": 0.0,
            "Active": false,
            "NextExtra": 2,
            "LastTickGameTime": "0001-01-13T12:00:00Z"
          },
          "PlacedByInteraction": {
            "WhoPlacedUuid": {
              "$binary": "LX9SOyJtQGqmYXD75rCkcQ==",
              "$type": "04"
            }
          }
        }
      },
      "rotation": 2
    },
    {
      "x": -1,
      "y": 6,
      "z": -4,
      "name": "Bench_Furnace",
      "filler": 1024,
      "rotation": 2
    },
    {
      "x": -1,
      "y": 7,
      "z": -4,
      "name": "Rock_Basalt_Cobble_Stairs",
      "rotation": 9
    },
    {
      "x": -1,
      "y": 8,
      "z": -4,
      "name": "Rock_Stone_Cobble_Roof_Steep",
      "rotation": 2
    },
    {
      "x": -1,
      "y": 9,
      "z": -4,
      "name": "Rock_Stone_Cobble_Roof_Steep",
      "filler": 1024,
      "rotation": 2
    },
    {
      "x": -1,
      "y": 0,
      "z": -3,
      "name": "Wood_Deadwood_Planks",
      "rotation": 1
    },
    {
      "x": -1,
      "y": 4,
      "z": -3,
      "name": "Rock_Stone_Brick_Mossy",
      "rotation": 1
    },
    {
      "x": -1,
      "y": 5,
      "z": -3,
      "name": "Bench_Furnace",
      "components": {
        "Components": {
          "BenchBlock": {
            "TierLevel": 1,
            "UpgradeItems": []
          },
          "ProcessingBenchBlock": {
            "InputContainer": {
              "Id": "Simple",
              "Capacity": 2,
              "Items": {}
            },
            "FuelContainer": {
              "Id": "Simple",
              "Capacity": 1,
              "Items": {}
            },
            "OutputContainer": {
              "Id": "Simple",
              "Capacity": 4,
              "Items": {}
            },
            "Progress": 0.0,
            "FuelTime": 0.0,
            "Active": false,
            "NextExtra": 2,
            "LastTickGameTime": "0001-01-13T12:00:00Z"
          },
          "PlacedByInteraction": {
            "WhoPlacedUuid": {
              "$binary": "LX9SOyJtQGqmYXD75rCkcQ==",
              "$type": "04"
            }
          }
        }
      },
      "rotation": 2
    },
    {
      "x": -1,
      "y": 6,
      "z": -3,
      "name": "Bench_Furnace",
      "filler": 1024,
      "rotation": 2
    },
    {
      "x": -1,
      "y": 7,
      "z": -3,
      "name": "Rock_Basalt_Cobble_Stairs",
      "rotation": 9
    },
    {
      "x": -1,
      "y": 8,
      "z": -3,
      "name": "Rock_Stone_Cobble_Roof_Steep"
    },
    {
      "x": -1,
      "y": 9,
      "z": -3,
      "name": "Rock_Stone_Cobble_Roof_Steep",
      "filler": 1024
    },
    {
      "x": -1,
      "y": 0,
      "z": -2,
      "name": "Wood_Deadwood_Planks",
      "rotation": 1
    },
    {
      "x": -1,
      "y": 4,
      "z": -2,
      "name": "Rock_Stone_Brick_Mossy",
      "rotation": 1
    },
    {
      "x": -1,
      "y": 5,
      "z": -2,
      "name": "Rock_Stone_Brick_Mossy",
      "rotation": 1
    },
    {
      "x": -1,
      "y": 6,
      "z": -2,
      "name": "Rock_Stone_Cobble_Roof_Shallow",
      "rotation": 2
    },
    {
      "x": -1,
      "y": 0,
      "z": -1,
      "name": "Wood_Deadwood_Planks",
      "rotation": 1
    },
    {
      "x": -1,
      "y": 1,
      "z": -1,
      "name": "*Furniture_Human_Ruins_Door_State_Definitions_CloseDoorOut"
    },
    {
      "x": -1,
      "y": 2,
      "z": -1,
      "name": "*Furniture_Human_Ruins_Door_State_Definitions_CloseDoorOut",
      "filler": 1024
    },
    {
      "x": -1,
      "y": 3,
      "z": -1,
      "name": "Wood_Deadwood_Planks",
      "rotation": 1
    },
    {
      "x": -1,
      "y": 4,
      "z": -1,
      "name": "Wood_Deadwood_Planks",
      "rotation": 1
    },
    {
      "x": -1,
      "y": 5,
      "z": -1,
      "name": "Wood_Deadwood_Planks",
      "rotation": 1
    },
    {
      "x": -1,
      "y": 6,
      "z": -1,
      "name": "Rock_Stone_Cobble_Roof_Shallow",
      "filler": 32,
      "rotation": 2
    },
    {
      "x": -1,
      "y": 10,
      "z": -1,
      "name": "Wood_Deadwood_Stairs",
      "rotation": 8
    },
    {
      "x": -1,
      "y": 11,
      "z": -1,
      "name": "Rock_Stone_Cobble_Roof_Steep",
      "rotation": 2
    },
    {
      "x": -1,
      "y": 12,
      "z": -1,
      "name": "Rock_Stone_Cobble_Roof_Steep",
      "filler": 1024,
      "rotation": 2
    },
    {
      "x": -1,
      "y": 0,
      "z": 0,
      "name": "Wood_Deadwood_Planks",
      "rotation": 1
    },
    {
      "x": -1,
      "y": 5,
      "z": 0,
      "name": "Wood_Deadwood_Planks",
      "rotation": 1
    },
    {
      "x": -1,
      "y": 6,
      "z": 0,
      "name": "Wood_Deadwood_Planks",
      "rotation": 1
    },
    {
      "x": -1,
      "y": 7,
      "z": 0,
      "name": "Wood_Deadwood_Decorative",
      "rotation": 1
    },
    {
      "x": -1,
      "y": 8,
      "z": 0,
      "name": "Wood_Deadwood_Decorative",
      "rotation": 1
    },
    {
      "x": -1,
      "y": 9,
      "z": 0,
      "name": "Wood_Deadwood_Decorative",
      "rotation": 1
    },
    {
      "x": -1,
      "y": 10,
      "z": 0,
      "name": "Wood_Deadwood_Decorative",
      "rotation": 1
    },
    {
      "x": -1,
      "y": 11,
      "z": 0,
      "name": "Wood_Deadwood_Ornate",
      "rotation": 1
    },
    {
      "x": -1,
      "y": 12,
      "z": 0,
      "name": "Wood_Deadwood_Ornate",
      "rotation": 1
    },
    {
      "x": -1,
      "y": 13,
      "z": 0,
      "name": "Rock_Stone_Cobble_Roof_Steep",
      "rotation": 2
    },
    {
      "x": -1,
      "y": 14,
      "z": 0,
      "name": "Rock_Stone_Cobble_Roof_Steep",
      "filler": 1024,
      "rotation": 2
    },
    {
      "x": -1,
      "y": 0,
      "z": 1,
      "name": "Wood_Deadwood_Planks",
      "rotation": 1
    },
    {
      "x": -1,
      "y": 5,
      "z": 1,
      "name": "Furniture_Crude_Platform",
      "rotation": 2
    },
    {
      "x": -1,
      "y": 10,
      "z": 1,
      "name": "Furniture_Crude_Platform",
      "rotation": 1
    },
    {
      "x": -1,
      "y": 15,
      "z": 1,
      "name": "Rock_Stone_Cobble_Roof_Steep",
      "rotation": 2
    },
    {
      "x": -1,
      "y": 16,
      "z": 1,
      "name": "Rock_Stone_Cobble_Roof_Steep",
      "filler": 1024,
      "rotation": 2
    },
    {
      "x": -1,
      "y": 0,
      "z": 2,
      "name": "Wood_Deadwood_Planks",
      "rotation": 1
    },
    {
      "x": -1,
      "y": 5,
      "z": 2,
      "name": "Furniture_Crude_Platform",
      "rotation": 2
    },
    {
      "x": -1,
      "y": 10,
      "z": 2,
      "name": "Furniture_Crude_Platform",
      "rotation": 1
    },
    {
      "x": -1,
      "y": 17,
      "z": 2,
      "name": "Rock_Stone_Cobble_Roof_Steep",
      "rotation": 2
    },
    {
      "x": -1,
      "y": 18,
      "z": 2,
      "name": "Rock_Stone_Cobble_Roof_Steep",
      "filler": 1024,
      "rotation": 2
    },
    {
      "x": -1,
      "y": 0,
      "z": 3,
      "name": "Wood_Deadwood_Planks",
      "rotation": 1
    },
    {
      "x": -1,
      "y": 5,
      "z": 3,
      "name": "Furniture_Crude_Platform",
      "rotation": 2
    },
    {
      "x": -1,
      "y": 10,
      "z": 3,
      "name": "Furniture_Crude_Platform",
      "rotation": 1
    },
    {
      "x": -1,
      "y": 17,
      "z": 3,
      "name": "Rock_Stone_Cobble_Roof_Steep"
    },
    {
      "x": -1,
      "y": 18,
      "z": 3,
      "name": "Rock_Stone_Cobble_Roof_Steep",
      "filler": 1024
    },
    {
      "x": -1,
      "y": 0,
      "z": 4,
      "name": "Wood_Deadwood_Planks",
      "rotation": 1
    },
    {
      "x": -1,
      "y": 5,
      "z": 4,
      "name": "Furniture_Crude_Platform",
      "rotation": 2
    },
    {
      "x": -1,
      "y": 10,
      "z": 4,
      "name": "Furniture_Crude_Platform",
      "rotation": 1
    },
    {
      "x": -1,
      "y": 15,
      "z": 4,
      "name": "Rock_Stone_Cobble_Roof_Steep"
    },
    {
      "x": -1,
      "y": 16,
      "z": 4,
      "name": "Rock_Stone_Cobble_Roof_Steep",
      "filler": 1024
    },
    {
      "x": -1,
      "y": 0,
      "z": 5,
      "name": "Wood_Deadwood_Planks",
      "rotation": 1
    },
    {
      "x": -1,
      "y": 5,
      "z": 5,
      "name": "Furniture_Crude_Platform",
      "rotation": 2
    },
    {
      "x": -1,
      "y": 6,
      "z": 5,
      "name": "Wood_Deadwood_Planks",
      "rotation": 1
    },
    {
      "x": -1,
      "y": 7,
      "z": 5,
      "name": "Wood_Deadwood_Decorative",
      "rotation": 1
    },
    {
      "x": -1,
      "y": 8,
      "z": 5,
      "name": "Wood_Deadwood_Decorative",
      "rotation": 1
    },
    {
      "x": -1,
      "y": 9,
      "z": 5,
      "name": "Wood_Deadwood_Decorative",
      "rotation": 1
    },
    {
      "x": -1,
      "y": 10,
      "z": 5,
      "name": "Wood_Deadwood_Decorative",
      "rotation": 1
    },
    {
      "x": -1,
      "y": 11,
      "z": 5,
      "name": "Wood_Deadwood_Ornate",
      "rotation": 1
    },
    {
      "x": -1,
      "y": 12,
      "z": 5,
      "name": "Wood_Deadwood_Ornate",
      "rotation": 1
    },
    {
      "x": -1,
      "y": 13,
      "z": 5,
      "name": "Rock_Stone_Cobble_Roof_Steep"
    },
    {
      "x": -1,
      "y": 14,
      "z": 5,
      "name": "Rock_Stone_Cobble_Roof_Steep",
      "filler": 1024
    },
    {
      "x": -1,
      "y": 0,
      "z": 6,
      "name": "Wood_Deadwood_Planks",
      "rotation": 1
    },
    {
      "x": -1,
      "y": 1,
      "z": 6,
      "name": "Wood_Deadwood_Planks",
      "rotation": 1
    },
    {
      "x": -1,
      "y": 2,
      "z": 6,
      "name": "Wood_Deadwood_Planks",
      "rotation": 1
    },
    {
      "x": -1,
      "y": 3,
      "z": 6,
      "name": "Wood_Deadwood_Planks",
      "rotation": 1
    },
    {
      "x": -1,
      "y": 4,
      "z": 6,
      "name": "Wood_Deadwood_Planks",
      "rotation": 1
    },
    {
      "x": -1,
      "y": 5,
      "z": 6,
      "name": "Wood_Deadwood_Planks",
      "rotation": 1
    },
    {
      "x": -1,
      "y": 6,
      "z": 6,
      "name": "Rock_Stone_Cobble_Roof"
    },
    {
      "x": -1,
      "y": 7,
      "z": 6,
      "name": "Furniture_Kweebec_Shelf"
    },
    {
      "x": -1,
      "y": 9,
      "z": 6,
      "name": "Plant_Moss_Wall_Green",
      "support": 15
    },
    {
      "x": -1,
      "y": 10,
      "z": 6,
      "name": "Wood_Deadwood_Stairs",
      "rotation": 10
    },
    {
      "x": -1,
      "y": 11,
      "z": 6,
      "name": "Rock_Stone_Cobble_Roof_Steep"
    },
    {
      "x": -1,
      "y": 12,
      "z": 6,
      "name": "Rock_Stone_Cobble_Roof_Steep",
      "filler": 1024
    },
    {
      "x": -1,
      "y": 0,
      "z": 7,
      "name": "Wood_Deadwood_Planks",
      "rotation": 1
    },
    {
      "x": -1,
      "y": 1,
      "z": 7,
      "name": "Furniture_Human_Ruins_Wardrobe"
    },
    {
      "x": -1,
      "y": 2,
      "z": 7,
      "name": "Furniture_Human_Ruins_Wardrobe",
      "filler": 1024
    },
    {
      "x": -1,
      "y": 3,
      "z": 7,
      "name": "Plant_Moss_Wall_Green_Dark",
      "support": 15
    },
    {
      "x": -1,
      "y": 4,
      "z": 7,
      "name": "Plant_Moss_Wall_Green_Dark",
      "support": 15
    },
    {
      "x": -1,
      "y": 5,
      "z": 7,
      "name": "Rock_Stone_Cobble_Roof_Hollow"
    },
    {
      "x": -1,
      "y": 0,
      "z": 8,
      "name": "Wood_Deadwood_Planks",
      "rotation": 1
    },
    {
      "x": 0,
      "y": 0,
      "z": -8,
      "name": "Wood_Deadwood_Planks",
      "rotation": 1
    },
    {
      "x": 0,
      "y": 0,
      "z": -7,
      "name": "Wood_Deadwood_Planks",
      "rotation": 1
    },
    {
      "x": 0,
      "y": 0,
      "z": -6,
      "name": "Wood_Deadwood_Planks",
      "rotation": 1
    },
    {
      "x": 0,
      "y": 4,
      "z": -6,
      "name": "Rock_Stone_Cobble_Roof_Shallow",
      "rotation": 2
    },
    {
      "x": 0,
      "y": 0,
      "z": -5,
      "name": "Wood_Deadwood_Planks",
      "rotation": 1
    },
    {
      "x": 0,
      "y": 4,
      "z": -5,
      "name": "Rock_Stone_Cobble_Roof_Shallow",
      "filler": 32,
      "rotation": 2
    },
    {
      "x": 0,
      "y": 0,
      "z": -4,
      "name": "Wood_Deadwood_Planks",
      "rotation": 1
    },
    {
      "x": 0,
      "y": 4,
      "z": -4,
      "name": "Rock_Stone_Brick_Mossy",
      "rotation": 1
    },
    {
      "x": 0,
      "y": 5,
      "z": -4,
      "name": "Bench_Furnace",
      "filler": 1,
      "rotation": 2
    },
    {
      "x": 0,
      "y": 6,
      "z": -4,
      "name": "Bench_Furnace",
      "filler": 1025,
      "rotation": 2
    },
    {
      "x": 0,
      "y": 7,
      "z": -4,
      "name": "Rock_Basalt_Cobble_Stairs",
      "rotation": 11
    },
    {
      "x": 0,
      "y": 8,
      "z": -4,
      "name": "Rock_Stone_Cobble_Roof_Steep",
      "rotation": 2
    },
    {
      "x": 0,
      "y": 9,
      "z": -4,
      "name": "Rock_Stone_Cobble_Roof_Steep",
      "filler": 1024,
      "rotation": 2
    },
    {
      "x": 0,
      "y": 0,
      "z": -3,
      "name": "Wood_Deadwood_Planks",
      "rotation": 1
    },
    {
      "x": 0,
      "y": 4,
      "z": -3,
      "name": "Rock_Stone_Brick_Mossy",
      "rotation": 1
    },
    {
      "x": 0,
      "y": 5,
      "z": -3,
      "name": "Bench_Furnace",
      "filler": 1,
      "rotation": 2
    },
    {
      "x": 0,
      "y": 6,
      "z": -3,
      "name": "Bench_Furnace",
      "filler": 1025,
      "rotation": 2
    },
    {
      "x": 0,
      "y": 7,
      "z": -3,
      "name": "Rock_Basalt_Cobble_Stairs",
      "rotation": 11
    },
    {
      "x": 0,
      "y": 8,
      "z": -3,
      "name": "Rock_Stone_Cobble_Roof_Steep"
    },
    {
      "x": 0,
      "y": 9,
      "z": -3,
      "name": "Rock_Stone_Cobble_Roof_Steep",
      "filler": 1024
    },
    {
      "x": 0,
      "y": 0,
      "z": -2,
      "name": "Wood_Deadwood_Planks",
      "rotation": 1
    },
    {
      "x": 0,
      "y": 4,
      "z": -2,
      "name": "Rock_Stone_Brick_Mossy",
      "rotation": 1
    },
    {
      "x": 0,
      "y": 5,
      "z": -2,
      "name": "Rock_Stone_Brick_Mossy",
      "rotation": 1
    },
    {
      "x": 0,
      "y": 6,
      "z": -2,
      "name": "Rock_Stone_Cobble_Roof_Shallow",
      "rotation": 2
    },
    {
      "x": 0,
      "y": 0,
      "z": -1,
      "name": "Wood_Deadwood_Planks",
      "rotation": 1
    },
    {
      "x": 0,
      "y": 1,
      "z": -1,
      "name": "*Furniture_Human_Ruins_Door_State_Definitions_CloseDoorIn",
      "rotation": 2
    },
    {
      "x": 0,
      "y": 2,
      "z": -1,
      "name": "*Furniture_Human_Ruins_Door_State_Definitions_CloseDoorIn",
      "filler": 1024,
      "rotation": 2
    },
    {
      "x": 0,
      "y": 3,
      "z": -1,
      "name": "Wood_Deadwood_Planks",
      "rotation": 1
    },
    {
      "x": 0,
      "y": 4,
      "z": -1,
      "name": "Wood_Deadwood_Planks",
      "rotation": 1
    },
    {
      "x": 0,
      "y": 5,
      "z": -1,
      "name": "Wood_Deadwood_Planks",
      "rotation": 1
    },
    {
      "x": 0,
      "y": 6,
      "z": -1,
      "name": "Rock_Stone_Cobble_Roof_Shallow",
      "filler": 32,
      "rotation": 2
    },
    {
      "x": 0,
      "y": 7,
      "z": -1,
      "name": "*Furniture_Human_Ruins_Trapdoor_State_Definitions_OpenDoorOut",
      "rotation": 2
    },
    {
      "x": 0,
      "y": 8,
      "z": -1,
      "name": "*Furniture_Human_Ruins_Trapdoor_State_Definitions_OpenDoorOut",
      "rotation": 2
    },
    {
      "x": 0,
      "y": 9,
      "z": -1,
      "name": "*Furniture_Human_Ruins_Trapdoor_State_Definitions_OpenDoorOut",
      "rotation": 2
    },
    {
      "x": 0,
      "y": 10,
      "z": -1,
      "name": "Wood_Deadwood_Stairs",
      "rotation": 8
    },
    {
      "x": 0,
      "y": 11,
      "z": -1,
      "name": "Rock_Stone_Cobble_Roof_Steep",
      "rotation": 2
    },
    {
      "x": 0,
      "y": 12,
      "z": -1,
      "name": "Rock_Stone_Cobble_Roof_Steep",
      "filler": 1024,
      "rotation": 2
    },
    {
      "x": 0,
      "y": 0,
      "z": 0,
      "name": "Wood_Deadwood_Planks",
      "rotation": 1
    },
    {
      "x": 0,
      "y": 5,
      "z": 0,
      "name": "Wood_Deadwood_Planks",
      "rotation": 1
    },
    {
      "x": 0,
      "y": 6,
      "z": 0,
      "name": "Wood_Deadwood_Planks",
      "rotation": 1
    },
    {
      "x": 0,
      "y": 7,
      "z": 0,
      "name": "Wood_Deadwood_Decorative",
      "rotation": 1
    },
    {
      "x": 0,
      "y": 8,
      "z": 0,
      "name": "Wood_Deadwood_Decorative",
      "rotation": 1
    },
    {
      "x": 0,
      "y": 9,
      "z": 0,
      "name": "Wood_Deadwood_Decorative",
      "rotation": 1
    },
    {
      "x": 0,
      "y": 10,
      "z": 0,
      "name": "Wood_Deadwood_Decorative",
      "rotation": 1
    },
    {
      "x": 0,
      "y": 11,
      "z": 0,
      "name": "Wood_Deadwood_Ornate",
      "rotation": 1
    },
    {
      "x": 0,
      "y": 12,
      "z": 0,
      "name": "Wood_Deadwood_Ornate",
      "rotation": 1
    },
    {
      "x": 0,
      "y": 13,
      "z": 0,
      "name": "Rock_Stone_Cobble_Roof_Steep",
      "rotation": 2
    },
    {
      "x": 0,
      "y": 14,
      "z": 0,
      "name": "Rock_Stone_Cobble_Roof_Steep",
      "filler": 1024,
      "rotation": 2
    },
    {
      "x": 0,
      "y": 0,
      "z": 1,
      "name": "Wood_Deadwood_Planks",
      "rotation": 1
    },
    {
      "x": 0,
      "y": 5,
      "z": 1,
      "name": "Furniture_Crude_Platform",
      "rotation": 2
    },
    {
      "x": 0,
      "y": 10,
      "z": 1,
      "name": "Furniture_Crude_Platform",
      "rotation": 1
    },
    {
      "x": 0,
      "y": 15,
      "z": 1,
      "name": "Rock_Stone_Cobble_Roof_Steep",
      "rotation": 2
    },
    {
      "x": 0,
      "y": 16,
      "z": 1,
      "name": "Rock_Stone_Cobble_Roof_Steep",
      "filler": 1024,
      "rotation": 2
    },
    {
      "x": 0,
      "y": 0,
      "z": 2,
      "name": "Wood_Deadwood_Planks",
      "rotation": 1
    },
    {
      "x": 0,
      "y": 5,
      "z": 2,
      "name": "Furniture_Crude_Platform",
      "rotation": 2
    },
    {
      "x": 0,
      "y": 10,
      "z": 2,
      "name": "Furniture_Crude_Platform",
      "rotation": 1
    },
    {
      "x": 0,
      "y": 17,
      "z": 2,
      "name": "Rock_Stone_Cobble_Roof_Steep",
      "rotation": 2
    },
    {
      "x": 0,
      "y": 18,
      "z": 2,
      "name": "Rock_Stone_Cobble_Roof_Steep",
      "filler": 1024,
      "rotation": 2
    },
    {
      "x": 0,
      "y": 0,
      "z": 3,
      "name": "Wood_Deadwood_Planks",
      "rotation": 1
    },
    {
      "x": 0,
      "y": 5,
      "z": 3,
      "name": "Furniture_Crude_Platform",
      "rotation": 2
    },
    {
      "x": 0,
      "y": 10,
      "z": 3,
      "name": "Furniture_Crude_Platform",
      "rotation": 1
    },
    {
      "x": 0,
      "y": 17,
      "z": 3,
      "name": "Rock_Stone_Cobble_Roof_Steep"
    },
    {
      "x": 0,
      "y": 18,
      "z": 3,
      "name": "Rock_Stone_Cobble_Roof_Steep",
      "filler": 1024
    },
    {
      "x": 0,
      "y": 0,
      "z": 4,
      "name": "Wood_Deadwood_Planks",
      "rotation": 1
    },
    {
      "x": 0,
      "y": 5,
      "z": 4,
      "name": "Furniture_Crude_Platform",
      "rotation": 2
    },
    {
      "x": 0,
      "y": 10,
      "z": 4,
      "name": "Furniture_Crude_Platform",
      "rotation": 1
    },
    {
      "x": 0,
      "y": 15,
      "z": 4,
      "name": "Rock_Stone_Cobble_Roof_Steep"
    },
    {
      "x": 0,
      "y": 16,
      "z": 4,
      "name": "Rock_Stone_Cobble_Roof_Steep",
      "filler": 1024
    },
    {
      "x": 0,
      "y": 0,
      "z": 5,
      "name": "Wood_Deadwood_Planks",
      "rotation": 1
    },
    {
      "x": 0,
      "y": 5,
      "z": 5,
      "name": "Furniture_Crude_Platform",
      "rotation": 2
    },
    {
      "x": 0,
      "y": 6,
      "z": 5,
      "name": "Wood_Deadwood_Planks",
      "rotation": 1
    },
    {
      "x": 0,
      "y": 7,
      "z": 5,
      "name": "Wood_Deadwood_Decorative",
      "rotation": 1
    },
    {
      "x": 0,
      "y": 8,
      "z": 5,
      "name": "Furniture_Human_Ruins_Window",
      "rotation": 2
    },
    {
      "x": 0,
      "y": 9,
      "z": 5,
      "name": "Wood_Deadwood_Decorative",
      "rotation": 1
    },
    {
      "x": 0,
      "y": 10,
      "z": 5,
      "name": "Wood_Deadwood_Decorative",
      "rotation": 1
    },
    {
      "x": 0,
      "y": 11,
      "z": 5,
      "name": "Wood_Deadwood_Ornate",
      "rotation": 1
    },
    {
      "x": 0,
      "y": 12,
      "z": 5,
      "name": "Wood_Deadwood_Ornate",
      "rotation": 1
    },
    {
      "x": 0,
      "y": 13,
      "z": 5,
      "name": "Rock_Stone_Cobble_Roof_Steep"
    },
    {
      "x": 0,
      "y": 14,
      "z": 5,
      "name": "Rock_Stone_Cobble_Roof_Steep",
      "filler": 1024
    },
    {
      "x": 0,
      "y": 0,
      "z": 6,
      "name": "Wood_Deadwood_Planks",
      "rotation": 1
    },
    {
      "x": 0,
      "y": 1,
      "z": 6,
      "name": "Wood_Deadwood_Planks",
      "rotation": 1
    },
    {
      "x": 0,
      "y": 2,
      "z": 6,
      "name": "Furniture_Human_Ruins_Window",
      "rotation": 2
    },
    {
      "x": 0,
      "y": 3,
      "z": 6,
      "name": "Furniture_Human_Ruins_Window",
      "rotation": 2
    },
    {
      "x": 0,
      "y": 4,
      "z": 6,
      "name": "Wood_Deadwood_Planks",
      "rotation": 1
    },
    {
      "x": 0,
      "y": 5,
      "z": 6,
      "name": "Wood_Deadwood_Planks",
      "rotation": 1
    },
    {
      "x": 0,
      "y": 6,
      "z": 6,
      "name": "Rock_Stone_Cobble_Roof"
    },
    {
      "x": 0,
      "y": 7,
      "z": 6,
      "name": "Furniture_Kweebec_Shelf"
    },
    {
      "x": 0,
      "y": 9,
      "z": 6,
      "name": "Cloth_Roof_Hide_Flap"
    },
    {
      "x": 0,
      "y": 10,
      "z": 6,
      "name": "Wood_Deadwood_Stairs",
      "rotation": 10
    },
    {
      "x": 0,
      "y": 11,
      "z": 6,
      "name": "Rock_Stone_Cobble_Roof_Steep"
    },
    {
      "x": 0,
      "y": 12,
      "z": 6,
      "name": "Rock_Stone_Cobble_Roof_Steep",
      "filler": 1024
    },
    {
      "x": 0,
      "y": 0,
      "z": 7,
      "name": "Wood_Deadwood_Planks",
      "rotation": 1
    },
    {
      "x": 0,
      "y": 1,
      "z": 7,
      "name": "Furniture_Kweebec_Shelf"
    },
    {
      "x": 0,
      "y": 3,
      "z": 7,
      "name": "Cloth_Roof_Hide_Flap"
    },
    {
      "x": 0,
      "y": 4,
      "z": 7,
      "name": "Cloth_Roof_Hide_Vertical"
    },
    {
      "x": 0,
      "y": 5,
      "z": 7,
      "name": "Rock_Stone_Cobble_Roof_Hollow"
    },
    {
      "x": 0,
      "y": 0,
      "z": 8,
      "name": "Wood_Deadwood_Planks",
      "rotation": 1
    },
    {
      "x": 1,
      "y": 0,
      "z": -8,
      "name": "Wood_Deadwood_Planks",
      "rotation": 1
    },
    {
      "x": 1,
      "y": 0,
      "z": -7,
      "name": "Wood_Deadwood_Planks",
      "rotation": 1
    },
    {
      "x": 1,
      "y": 0,
      "z": -6,
      "name": "Wood_Deadwood_Planks",
      "rotation": 1
    },
    {
      "x": 1,
      "y": 1,
      "z": -6,
      "name": "Wood_Deadwood_Fence",
      "rotation": 2
    },
    {
      "x": 1,
      "y": 4,
      "z": -6,
      "name": "Rock_Stone_Cobble_Roof_Shallow",
      "rotation": 2
    },
    {
      "x": 1,
      "y": 0,
      "z": -5,
      "name": "Wood_Deadwood_Planks",
      "rotation": 1
    },
    {
      "x": 1,
      "y": 1,
      "z": -5,
      "name": "Bench_Armour",
      "filler": 992,
      "rotation": 3
    },
    {
      "x": 1,
      "y": 2,
      "z": -5,
      "name": "Bench_Armour",
      "filler": 2016,
      "rotation": 3
    },
    {
      "x": 1,
      "y": 4,
      "z": -5,
      "name": "Rock_Stone_Cobble_Roof_Shallow",
      "filler": 32,
      "rotation": 2
    },
    {
      "x": 1,
      "y": 0,
      "z": -4,
      "name": "Wood_Deadwood_Planks",
      "rotation": 1
    },
    {
      "x": 1,
      "y": 1,
      "z": -4,
      "name": "Bench_Armour",
      "components": {
        "Components": {
          "BenchBlock": {
            "TierLevel": 1,
            "UpgradeItems": []
          },
          "PlacedByInteraction": {
            "WhoPlacedUuid": {
              "$binary": "LX9SOyJtQGqmYXD75rCkcQ==",
              "$type": "04"
            }
          }
        }
      },
      "rotation": 3
    },
    {
      "x": 1,
      "y": 2,
      "z": -4,
      "name": "Bench_Armour",
      "filler": 1024,
      "rotation": 3
    },
    {
      "x": 1,
      "y": 4,
      "z": -4,
      "name": "Rock_Stone_Cobble_Mossy",
      "rotation": 1
    },
    {
      "x": 1,
      "y": 5,
      "z": -4,
      "name": "Rock_Stone_Brick_Mossy",
      "rotation": 1
    },
    {
      "x": 1,
      "y": 6,
      "z": -4,
      "name": "Wood_Beech_Branch_Long",
      "support": 15,
      "rotation": 1
    },
    {
      "x": 1,
      "y": 7,
      "z": -4,
      "name": "Wood_Beech_Branch_Long",
      "support": 15,
      "rotation": 1
    },
    {
      "x": 1,
      "y": 8,
      "z": -4,
      "name": "*Rock_Stone_Cobble_Roof_Steep_State_Definitions_Corner_Right",
      "rotation": 2
    },
    {
      "x": 1,
      "y": 9,
      "z": -4,
      "name": "*Rock_Stone_Cobble_Roof_Steep_State_Definitions_Corner_Right",
      "filler": 1024,
      "rotation": 2
    },
    {
      "x": 1,
      "y": 0,
      "z": -3,
      "name": "Wood_Deadwood_Planks",
      "rotation": 1
    },
    {
      "x": 1,
      "y": 4,
      "z": -3,
      "name": "Rock_Stone_Cobble_Mossy",
      "rotation": 1
    },
    {
      "x": 1,
      "y": 5,
      "z": -3,
      "name": "Rock_Stone_Brick_Mossy",
      "rotation": 1
    },
    {
      "x": 1,
      "y": 6,
      "z": -3,
      "name": "Wood_Beech_Branch_Long",
      "support": 15,
      "rotation": 1
    },
    {
      "x": 1,
      "y": 7,
      "z": -3,
      "name": "Wood_Beech_Branch_Long",
      "support": 15,
      "rotation": 1
    },
    {
      "x": 1,
      "y": 8,
      "z": -3,
      "name": "*Rock_Stone_Cobble_Roof_Steep_State_Definitions_Corner_Right",
      "rotation": 1
    },
    {
      "x": 1,
      "y": 9,
      "z": -3,
      "name": "*Rock_Stone_Cobble_Roof_Steep_State_Definitions_Corner_Right",
      "filler": 1024,
      "rotation": 1
    },
    {
      "x": 1,
      "y": 0,
      "z": -2,
      "name": "Wood_Deadwood_Planks",
      "rotation": 1
    },
    {
      "x": 1,
      "y": 4,
      "z": -2,
      "name": "Rock_Stone_Brick_Mossy",
      "rotation": 1
    },
    {
      "x": 1,
      "y": 5,
      "z": -2,
      "name": "Wood_Deadwood_Planks",
      "rotation": 1
    },
    {
      "x": 1,
      "y": 6,
      "z": -2,
      "name": "Rock_Stone_Cobble_Roof_Shallow",
      "rotation": 2
    },
    {
      "x": 1,
      "y": 0,
      "z": -1,
      "name": "Wood_Deadwood_Planks",
      "rotation": 1
    },
    {
      "x": 1,
      "y": 1,
      "z": -1,
      "name": "Wood_Deadwood_Ornate",
      "rotation": 1
    },
    {
      "x": 1,
      "y": 2,
      "z": -1,
      "name": "Wood_Deadwood_Ornate",
      "rotation": 1
    },
    {
      "x": 1,
      "y": 3,
      "z": -1,
      "name": "Wood_Deadwood_Ornate",
      "rotation": 1
    },
    {
      "x": 1,
      "y": 4,
      "z": -1,
      "name": "Wood_Deadwood_Ornate",
      "rotation": 1
    },
    {
      "x": 1,
      "y": 5,
      "z": -1,
      "name": "Wood_Deadwood_Ornate",
      "rotation": 1
    },
    {
      "x": 1,
      "y": 6,
      "z": -1,
      "name": "Rock_Stone_Cobble_Roof_Shallow",
      "filler": 32,
      "rotation": 2
    },
    {
      "x": 1,
      "y": 10,
      "z": -1,
      "name": "Wood_Deadwood_Stairs",
      "rotation": 8
    },
    {
      "x": 1,
      "y": 11,
      "z": -1,
      "name": "Rock_Stone_Cobble_Roof_Steep",
      "rotation": 2
    },
    {
      "x": 1,
      "y": 12,
      "z": -1,
      "name": "Rock_Stone_Cobble_Roof_Steep",
      "filler": 1024,
      "rotation": 2
    },
    {
      "x": 1,
      "y": 0,
      "z": 0,
      "name": "Wood_Deadwood_Planks",
      "rotation": 1
    },
    {
      "x": 1,
      "y": 5,
      "z": 0,
      "name": "Wood_Deadwood_Planks",
      "rotation": 1
    },
    {
      "x": 1,
      "y": 6,
      "z": 0,
      "name": "Wood_Deadwood_Planks",
      "rotation": 1
    },
    {
      "x": 1,
      "y": 7,
      "z": 0,
      "name": "Wood_Deadwood_Decorative",
      "rotation": 1
    },
    {
      "x": 1,
      "y": 8,
      "z": 0,
      "name": "Wood_Deadwood_Decorative",
      "rotation": 1
    },
    {
      "x": 1,
      "y": 9,
      "z": 0,
      "name": "Wood_Deadwood_Decorative",
      "rotation": 1
    },
    {
      "x": 1,
      "y": 10,
      "z": 0,
      "name": "Wood_Deadwood_Decorative",
      "rotation": 1
    },
    {
      "x": 1,
      "y": 11,
      "z": 0,
      "name": "Wood_Deadwood_Ornate",
      "rotation": 1
    },
    {
      "x": 1,
      "y": 12,
      "z": 0,
      "name": "Wood_Deadwood_Ornate",
      "rotation": 1
    },
    {
      "x": 1,
      "y": 13,
      "z": 0,
      "name": "Rock_Stone_Cobble_Roof_Steep",
      "rotation": 2
    },
    {
      "x": 1,
      "y": 14,
      "z": 0,
      "name": "Rock_Stone_Cobble_Roof_Steep",
      "filler": 1024,
      "rotation": 2
    },
    {
      "x": 1,
      "y": 0,
      "z": 1,
      "name": "Wood_Deadwood_Planks",
      "rotation": 1
    },
    {
      "x": 1,
      "y": 5,
      "z": 1,
      "name": "Furniture_Crude_Platform",
      "rotation": 2
    },
    {
      "x": 1,
      "y": 6,
      "z": 1,
      "name": "Wood_Deadwood_Planks",
      "rotation": 1
    },
    {
      "x": 1,
      "y": 7,
      "z": 1,
      "name": "Wood_Deadwood_Decorative",
      "rotation": 1
    },
    {
      "x": 1,
      "y": 8,
      "z": 1,
      "name": "Furniture_Human_Ruins_Window",
      "rotation": 1
    },
    {
      "x": 1,
      "y": 9,
      "z": 1,
      "name": "Wood_Deadwood_Decorative",
      "rotation": 1
    },
    {
      "x": 1,
      "y": 10,
      "z": 1,
      "name": "Wood_Deadwood_Decorative",
      "rotation": 1
    },
    {
      "x": 1,
      "y": 15,
      "z": 1,
      "name": "Rock_Stone_Cobble_Roof_Steep",
      "rotation": 2
    },
    {
      "x": 1,
      "y": 16,
      "z": 1,
      "name": "Rock_Stone_Cobble_Roof_Steep",
      "filler": 1024,
      "rotation": 2
    },
    {
      "x": 1,
      "y": 0,
      "z": 2,
      "name": "Wood_Deadwood_Planks",
      "rotation": 1
    },
    {
      "x": 1,
      "y": 5,
      "z": 2,
      "name": "Furniture_Crude_Platform",
      "rotation": 2
    },
    {
      "x": 1,
      "y": 6,
      "z": 2,
      "name": "Wood_Deadwood_Planks",
      "rotation": 1
    },
    {
      "x": 1,
      "y": 7,
      "z": 2,
      "name": "Wood_Deadwood_Decorative",
      "rotation": 1
    },
    {
      "x": 1,
      "y": 8,
      "z": 2,
      "name": "Wood_Deadwood_Decorative",
      "rotation": 1
    },
    {
      "x": 1,
      "y": 9,
      "z": 2,
      "name": "Wood_Deadwood_Decorative",
      "rotation": 1
    },
    {
      "x": 1,
      "y": 10,
      "z": 2,
      "name": "Wood_Deadwood_Decorative",
      "rotation": 1
    },
    {
      "x": 1,
      "y": 17,
      "z": 2,
      "name": "Rock_Stone_Cobble_Roof_Steep",
      "rotation": 2
    },
    {
      "x": 1,
      "y": 18,
      "z": 2,
      "name": "Rock_Stone_Cobble_Roof_Steep",
      "filler": 1024,
      "rotation": 2
    },
    {
      "x": 1,
      "y": 0,
      "z": 3,
      "name": "Wood_Deadwood_Planks",
      "rotation": 1
    },
    {
      "x": 1,
      "y": 5,
      "z": 3,
      "name": "Furniture_Crude_Platform",
      "rotation": 2
    },
    {
      "x": 1,
      "y": 6,
      "z": 3,
      "name": "Wood_Deadwood_Planks",
      "rotation": 1
    },
    {
      "x": 1,
      "y": 7,
      "z": 3,
      "name": "Wood_Deadwood_Decorative",
      "rotation": 1
    },
    {
      "x": 1,
      "y": 8,
      "z": 3,
      "name": "Wood_Deadwood_Decorative",
      "rotation": 1
    },
    {
      "x": 1,
      "y": 9,
      "z": 3,
      "name": "Wood_Deadwood_Decorative",
      "rotation": 1
    },
    {
      "x": 1,
      "y": 10,
      "z": 3,
      "name": "Wood_Deadwood_Decorative",
      "rotation": 1
    },
    {
      "x": 1,
      "y": 17,
      "z": 3,
      "name": "Rock_Stone_Cobble_Roof_Steep"
    },
    {
      "x": 1,
      "y": 18,
      "z": 3,
      "name": "Rock_Stone_Cobble_Roof_Steep",
      "filler": 1024
    },
    {
      "x": 1,
      "y": 0,
      "z": 4,
      "name": "Wood_Deadwood_Planks",
      "rotation": 1
    },
    {
      "x": 1,
      "y": 5,
      "z": 4,
      "name": "Furniture_Crude_Platform",
      "rotation": 2
    },
    {
      "x": 1,
      "y": 6,
      "z": 4,
      "name": "Wood_Deadwood_Planks",
      "rotation": 1
    },
    {
      "x": 1,
      "y": 7,
      "z": 4,
      "name": "Furniture_Human_Ruins_Door",
      "rotation": 1
    },
    {
      "x": 1,
      "y": 8,
      "z": 4,
      "name": "Furniture_Human_Ruins_Door",
      "filler": 1024,
      "rotation": 1
    },
    {
      "x": 1,
      "y": 9,
      "z": 4,
      "name": "Wood_Deadwood_Decorative",
      "rotation": 1
    },
    {
      "x": 1,
      "y": 10,
      "z": 4,
      "name": "Wood_Deadwood_Decorative",
      "rotation": 1
    },
    {
      "x": 1,
      "y": 15,
      "z": 4,
      "name": "Rock_Stone_Cobble_Roof_Steep"
    },
    {
      "x": 1,
      "y": 16,
      "z": 4,
      "name": "Rock_Stone_Cobble_Roof_Steep",
      "filler": 1024
    },
    {
      "x": 1,
      "y": 0,
      "z": 5,
      "name": "Wood_Deadwood_Planks",
      "rotation": 1
    },
    {
      "x": 1,
      "y": 5,
      "z": 5,
      "name": "Furniture_Crude_Platform",
      "rotation": 2
    },
    {
      "x": 1,
      "y": 6,
      "z": 5,
      "name": "Wood_Deadwood_Planks",
      "rotation": 1
    },
    {
      "x": 1,
      "y": 7,
      "z": 5,
      "name": "Wood_Deadwood_Decorative",
      "rotation": 1
    },
    {
      "x": 1,
      "y": 8,
      "z": 5,
      "name": "Wood_Deadwood_Decorative",
      "rotation": 1
    },
    {
      "x": 1,
      "y": 9,
      "z": 5,
      "name": "Wood_Deadwood_Decorative",
      "rotation": 1
    },
    {
      "x": 1,
      "y": 10,
      "z": 5,
      "name": "Wood_Deadwood_Decorative",
      "rotation": 1
    },
    {
      "x": 1,
      "y": 11,
      "z": 5,
      "name": "Wood_Deadwood_Ornate",
      "rotation": 1
    },
    {
      "x": 1,
      "y": 12,
      "z": 5,
      "name": "Wood_Deadwood_Ornate",
      "rotation": 1
    },
    {
      "x": 1,
      "y": 13,
      "z": 5,
      "name": "Rock_Stone_Cobble_Roof_Steep"
    },
    {
      "x": 1,
      "y": 14,
      "z": 5,
      "name": "Rock_Stone_Cobble_Roof_Steep",
      "filler": 1024
    },
    {
      "x": 1,
      "y": 0,
      "z": 6,
      "name": "Wood_Deadwood_Planks",
      "rotation": 1
    },
    {
      "x": 1,
      "y": 1,
      "z": 6,
      "name": "Wood_Deadwood_Planks",
      "rotation": 1
    },
    {
      "x": 1,
      "y": 2,
      "z": 6,
      "name": "Furniture_Human_Ruins_Window",
      "rotation": 2
    },
    {
      "x": 1,
      "y": 3,
      "z": 6,
      "name": "Furniture_Human_Ruins_Window",
      "rotation": 2
    },
    {
      "x": 1,
      "y": 4,
      "z": 6,
      "name": "Wood_Deadwood_Planks",
      "rotation": 1
    },
    {
      "x": 1,
      "y": 5,
      "z": 6,
      "name": "Wood_Deadwood_Planks",
      "rotation": 1
    },
    {
      "x": 1,
      "y": 6,
      "z": 6,
      "name": "Rock_Stone_Cobble_Roof"
    },
    {
      "x": 1,
      "y": 8,
      "z": 6,
      "name": "Plant_Moss_Wall_Green",
      "support": 15
    },
    {
      "x": 1,
      "y": 9,
      "z": 6,
      "name": "Plant_Moss_Wall_Green_Dark",
      "support": 15
    },
    {
      "x": 1,
      "y": 10,
      "z": 6,
      "name": "Wood_Deadwood_Stairs",
      "rotation": 10
    },
    {
      "x": 1,
      "y": 11,
      "z": 6,
      "name": "Rock_Stone_Cobble_Roof_Steep"
    },
    {
      "x": 1,
      "y": 12,
      "z": 6,
      "name": "Rock_Stone_Cobble_Roof_Steep",
      "filler": 1024
    },
    {
      "x": 1,
      "y": 0,
      "z": 7,
      "name": "Wood_Deadwood_Planks",
      "rotation": 1
    },
    {
      "x": 1,
      "y": 1,
      "z": 7,
      "name": "Furniture_Kweebec_Shelf"
    },
    {
      "x": 1,
      "y": 3,
      "z": 7,
      "name": "Cloth_Roof_Hide_Flap"
    },
    {
      "x": 1,
      "y": 4,
      "z": 7,
      "name": "Cloth_Roof_Hide_Vertical"
    },
    {
      "x": 1,
      "y": 5,
      "z": 7,
      "name": "Rock_Stone_Cobble_Roof_Hollow"
    },
    {
      "x": 1,
      "y": 0,
      "z": 8,
      "name": "Wood_Deadwood_Planks",
      "rotation": 1
    },
    {
      "x": 2,
      "y": 0,
      "z": -8,
      "name": "Wood_Deadwood_Planks",
      "rotation": 1
    },
    {
      "x": 2,
      "y": 0,
      "z": -7,
      "name": "Wood_Deadwood_Planks",
      "rotation": 1
    },
    {
      "x": 2,
      "y": 2,
      "z": -7,
      "name": "Plant_Moss_Wall_Green",
      "support": 15,
      "rotation": 2
    },
    {
      "x": 2,
      "y": 3,
      "z": -7,
      "name": "Plant_Moss_Wall_Green_Dark",
      "support": 15,
      "rotation": 2
    },
    {
      "x": 2,
      "y": 0,
      "z": -6,
      "name": "Wood_Deadwood_Planks",
      "rotation": 1
    },
    {
      "x": 2,
      "y": 1,
      "z": -6,
      "name": "Wood_Deadwood_Ornate",
      "rotation": 1
    },
    {
      "x": 2,
      "y": 2,
      "z": -6,
      "name": "Wood_Deadwood_Ornate",
      "rotation": 1
    },
    {
      "x": 2,
      "y": 3,
      "z": -6,
      "name": "Wood_Deadwood_Ornate",
      "rotation": 1
    },
    {
      "x": 2,
      "y": 4,
      "z": -6,
      "name": "Rock_Stone_Cobble_Roof_Shallow",
      "rotation": 2
    },
    {
      "x": 2,
      "y": 0,
      "z": -5,
      "name": "Wood_Deadwood_Planks",
      "rotation": 1
    },
    {
      "x": 2,
      "y": 1,
      "z": -5,
      "name": "Wood_Deadwood_Ornate",
      "rotation": 1
    },
    {
      "x": 2,
      "y": 2,
      "z": -5,
      "name": "Furniture_Human_Ruins_Window",
      "rotation": 1
    },
    {
      "x": 2,
      "y": 3,
      "z": -5,
      "name": "Wood_Deadwood_Ornate",
      "rotation": 1
    },
    {
      "x": 2,
      "y": 4,
      "z": -5,
      "name": "Rock_Stone_Cobble_Roof_Shallow",
      "filler": 32,
      "rotation": 2
    },
    {
      "x": 2,
      "y": 0,
      "z": -4,
      "name": "Wood_Deadwood_Planks",
      "rotation": 1
    },
    {
      "x": 2,
      "y": 1,
      "z": -4,
      "name": "Wood_Deadwood_Ornate",
      "rotation": 1
    },
    {
      "x": 2,
      "y": 2,
      "z": -4,
      "name": "Wood_Deadwood_Ornate",
      "rotation": 1
    },
    {
      "x": 2,
      "y": 3,
      "z": -4,
      "name": "Wood_Deadwood_Ornate",
      "rotation": 1
    },
    {
      "x": 2,
      "y": 4,
      "z": -4,
      "name": "Wood_Deadwood_Ornate",
      "rotation": 1
    },
    {
      "x": 2,
      "y": 5,
      "z": -4,
      "name": "Rock_Stone_Cobble_Roof_Shallow",
      "rotation": 2
    },
    {
      "x": 2,
      "y": 0,
      "z": -3,
      "name": "Wood_Deadwood_Planks",
      "rotation": 1
    },
    {
      "x": 2,
      "y": 4,
      "z": -3,
      "name": "Wood_Deadwood_Ornate",
      "rotation": 1
    },
    {
      "x": 2,
      "y": 5,
      "z": -3,
      "name": "Rock_Stone_Cobble_Roof_Shallow",
      "filler": 32,
      "rotation": 2
    },
    {
      "x": 2,
      "y": 0,
      "z": -2,
      "name": "Wood_Deadwood_Planks",
      "rotation": 1
    },
    {
      "x": 2,
      "y": 4,
      "z": -2,
      "name": "Wood_Deadwood_Ornate",
      "rotation": 1
    },
    {
      "x": 2,
      "y": 5,
      "z": -2,
      "name": "Wood_Deadwood_Ornate",
      "rotation": 1
    },
    {
      "x": 2,
      "y": 6,
      "z": -2,
      "name": "Rock_Stone_Cobble_Roof_Shallow",
      "rotation": 2
    },
    {
      "x": 2,
      "y": 0,
      "z": -1,
      "name": "Wood_Deadwood_Planks",
      "rotation": 1
    },
    {
      "x": 2,
      "y": 1,
      "z": -1,
      "name": "Wood_Deadwood_Planks",
      "rotation": 1
    },
    {
      "x": 2,
      "y": 2,
      "z": -1,
      "name": "Wood_Deadwood_Planks",
      "rotation": 1
    },
    {
      "x": 2,
      "y": 3,
      "z": -1,
      "name": "Wood_Deadwood_Planks",
      "rotation": 1
    },
    {
      "x": 2,
      "y": 4,
      "z": -1,
      "name": "Wood_Deadwood_Planks",
      "rotation": 1
    },
    {
      "x": 2,
      "y": 5,
      "z": -1,
      "name": "Wood_Deadwood_Planks",
      "rotation": 1
    },
    {
      "x": 2,
      "y": 6,
      "z": -1,
      "name": "Rock_Stone_Cobble_Roof_Shallow",
      "filler": 32,
      "rotation": 2
    },
    {
      "x": 2,
      "y": 10,
      "z": -1,
      "name": "*Wood_Deadwood_Stairs_State_Definitions_Corner_Left",
      "rotation": 8
    },
    {
      "x": 2,
      "y": 11,
      "z": -1,
      "name": "Rock_Stone_Cobble_Roof_Steep",
      "rotation": 2
    },
    {
      "x": 2,
      "y": 12,
      "z": -1,
      "name": "Rock_Stone_Cobble_Roof_Steep",
      "filler": 1024,
      "rotation": 2
    },
    {
      "x": 2,
      "y": 0,
      "z": 0,
      "name": "Wood_Deadwood_Planks",
      "rotation": 1
    },
    {
      "x": 2,
      "y": 1,
      "z": 0,
      "name": "Wood_Deadwood_Planks",
      "rotation": 1
    },
    {
      "x": 2,
      "y": 2,
      "z": 0,
      "name": "Furniture_Human_Ruins_Window",
      "rotation": 1
    },
    {
      "x": 2,
      "y": 3,
      "z": 0,
      "name": "Furniture_Human_Ruins_Window",
      "rotation": 1
    },
    {
      "x": 2,
      "y": 4,
      "z": 0,
      "name": "Wood_Deadwood_Planks",
      "rotation": 1
    },
    {
      "x": 2,
      "y": 5,
      "z": 0,
      "name": "Wood_Deadwood_Planks",
      "rotation": 1
    },
    {
      "x": 2,
      "y": 6,
      "z": 0,
      "name": "Wood_Deadwood_Stairs",
      "rotation": 11
    },
    {
      "x": 2,
      "y": 7,
      "z": 0,
      "name": "Plant_Moss_Wall_Green",
      "support": 15,
      "rotation": 1
    },
    {
      "x": 2,
      "y": 8,
      "z": 0,
      "name": "Plant_Moss_Wall_Green_Dark",
      "support": 15,
      "rotation": 1
    },
    {
      "x": 2,
      "y": 10,
      "z": 0,
      "name": "Wood_Deadwood_Stairs",
      "rotation": 11
    },
    {
      "x": 2,
      "y": 11,
      "z": 0,
      "name": "Wood_Deadwood_Ornate",
      "rotation": 1
    },
    {
      "x": 2,
      "y": 12,
      "z": 0,
      "name": "Wood_Deadwood_Ornate",
      "rotation": 1
    },
    {
      "x": 2,
      "y": 13,
      "z": 0,
      "name": "Rock_Stone_Cobble_Roof_Steep",
      "rotation": 2
    },
    {
      "x": 2,
      "y": 14,
      "z": 0,
      "name": "Rock_Stone_Cobble_Roof_Steep",
      "filler": 1024,
      "rotation": 2
    },
    {
      "x": 2,
      "y": 0,
      "z": 1,
      "name": "Wood_Deadwood_Planks",
      "rotation": 1
    },
    {
      "x": 2,
      "y": 1,
      "z": 1,
      "name": "Wood_Deadwood_Planks",
      "rotation": 1
    },
    {
      "x": 2,
      "y": 2,
      "z": 1,
      "name": "Wood_Deadwood_Planks",
      "rotation": 1
    },
    {
      "x": 2,
      "y": 3,
      "z": 1,
      "name": "Wood_Deadwood_Planks",
      "rotation": 1
    },
    {
      "x": 2,
      "y": 4,
      "z": 1,
      "name": "Wood_Deadwood_Planks",
      "rotation": 1
    },
    {
      "x": 2,
      "y": 5,
      "z": 1,
      "name": "Wood_Deadwood_Planks",
      "rotation": 1
    },
    {
      "x": 2,
      "y": 6,
      "z": 1,
      "name": "Wood_Deadwood_Stairs",
      "rotation": 11
    },
    {
      "x": 2,
      "y": 7,
      "z": 1,
      "name": "Furniture_Kweebec_Shelf",
      "rotation": 1
    },
    {
      "x": 2,
      "y": 10,
      "z": 1,
      "name": "Wood_Deadwood_Stairs",
      "rotation": 11
    },
    {
      "x": 2,
      "y": 11,
      "z": 1,
      "name": "Wood_Deadwood_Ornate",
      "rotation": 1
    },
    {
      "x": 2,
      "y": 12,
      "z": 1,
      "name": "Wood_Deadwood_Ornate",
      "rotation": 1
    },
    {
      "x": 2,
      "y": 13,
      "z": 1,
      "name": "Wood_Deadwood_Ornate",
      "rotation": 1
    },
    {
      "x": 2,
      "y": 14,
      "z": 1,
      "name": "Wood_Deadwood_Ornate",
      "rotation": 1
    },
    {
      "x": 2,
      "y": 15,
      "z": 1,
      "name": "Rock_Stone_Cobble_Roof_Steep",
      "rotation": 2
    },
    {
      "x": 2,
      "y": 16,
      "z": 1,
      "name": "Rock_Stone_Cobble_Roof_Steep",
      "filler": 1024,
      "rotation": 2
    },
    {
      "x": 2,
      "y": 0,
      "z": 2,
      "name": "Wood_Deadwood_Planks",
      "rotation": 1
    },
    {
      "x": 2,
      "y": 5,
      "z": 2,
      "name": "Furniture_Crude_Platform",
      "rotation": 2
    },
    {
      "x": 2,
      "y": 6,
      "z": 2,
      "name": "*Wood_Deadwood_Stairs_State_Definitions_Inverted_Corner_Left",
      "rotation": 8
    },
    {
      "x": 2,
      "y": 7,
      "z": 2,
      "name": "Wood_Blackwood_Fence",
      "rotation": 2
    },
    {
      "x": 2,
      "y": 9,
      "z": 2,
      "name": "Plant_Moss_Wall_Green_Dark",
      "support": 15,
      "rotation": 1
    },
    {
      "x": 2,
      "y": 10,
      "z": 2,
      "name": "Wood_Deadwood_Stairs",
      "rotation": 11
    },
    {
      "x": 2,
      "y": 11,
      "z": 2,
      "name": "Wood_Deadwood_Ornate",
      "rotation": 1
    },
    {
      "x": 2,
      "y": 12,
      "z": 2,
      "name": "Furniture_Human_Ruins_Window",
      "rotation": 1
    },
    {
      "x": 2,
      "y": 13,
      "z": 2,
      "name": "Furniture_Human_Ruins_Window",
      "rotation": 1
    },
    {
      "x": 2,
      "y": 14,
      "z": 2,
      "name": "Wood_Deadwood_Ornate",
      "rotation": 1
    },
    {
      "x": 2,
      "y": 15,
      "z": 2,
      "name": "Wood_Deadwood_Ornate",
      "rotation": 1
    },
    {
      "x": 2,
      "y": 16,
      "z": 2,
      "name": "Wood_Deadwood_Ornate",
