{
  "version": 8,
  "blockIdVersion": 11,
  "anchorX": 0,
  "anchorY": 0,
  "anchorZ": 0,
  "blocks": [
    {
      "x": -6,
      "y": 0,
      "z": -10,
      "name": "Wood_Deadwood_Planks",
      "rotation": 1
    },
    {
      "x": -6,
      "y": 0,
      "z": -9,
      "name": "Wood_Deadwood_Planks",
      "rotation": 1
    },
    {
      "x": -6,
      "y": 0,
      "z": -8,
      "name": "Wood_Deadwood_Planks",
      "rotation": 1
    },
    {
      "x": -6,
      "y": 0,
      "z": -7,
      "name": "Wood_Deadwood_Planks",
      "rotation": 1
    },
    {
      "x": -6,
      "y": 0,
      "z": -6,
      "name": "Wood_Deadwood_Planks",
      "rotation": 1
    },
    {
      "x": -6,
      "y": 0,
      "z": -5,
      "name": "Wood_Deadwood_Planks",
      "rotation": 1
    },
    {
      "x": -6,
      "y": 0,
      "z": -4,
      "name": "Wood_Deadwood_Planks",
      "rotation": 1
    },
    {
      "x": -6,
      "y": 0,
      "z": -3,
      "name": "Wood_Deadwood_Planks",
      "rotation": 1
    },
    {
      "x": -6,
      "y": 0,
      "z": -2,
      "name": "Wood_Deadwood_Planks",
      "rotation": 1
    },
    {
      "x": -6,
      "y": 0,
      "z": -1,
      "name": "Wood_Deadwood_Planks",
      "rotation": 1
    },
    {
      "x": -6,
      "y": 0,
      "z": 0,
      "name": "Wood_Deadwood_Planks",
      "rotation": 1
    },
    {
      "x": -6,
      "y": 0,
      "z": 1,
      "name": "Wood_Deadwood_Planks",
      "rotation": 1
    },
    {
      "x": -6,
      "y": 0,
      "z": 2,
      "name": "Wood_Deadwood_Planks",
      "rotation": 1
    },
    {
      "x": -6,
      "y": 0,
      "z": 3,
      "name": "Wood_Deadwood_Planks",
      "rotation": 1
    },
    {
      "x": -6,
      "y": 0,
      "z": 4,
      "name": "Wood_Deadwood_Planks",
      "rotation": 1
    },
    {
      "x": -6,
      "y": 0,
      "z": 5,
      "name": "Wood_Deadwood_Planks",
      "rotation": 1
    },
    {
      "x": -6,
      "y": 0,
      "z": 6,
      "name": "Wood_Deadwood_Planks",
      "rotation": 1
    },
    {
      "x": -6,
      "y": 0,
      "z": 7,
      "name": "Wood_Deadwood_Planks",
      "rotation": 1
    },
    {
      "x": -6,
      "y": 0,
      "z": 8,
      "name": "Wood_Deadwood_Planks",
      "rotation": 1
    },
    {
      "x": -6,
      "y": 0,
      "z": 9,
      "name": "Wood_Deadwood_Planks",
      "rotation": 1
    },
    {
      "x": -6,
      "y": 0,
      "z": 10,
      "name": "Wood_Deadwood_Planks",
      "rotation": 1
    },
    {
      "x": -5,
      "y": 0,
      "z": -10,
      "name": "Wood_Deadwood_Planks",
      "rotation": 1
    },
    {
      "x": -5,
      "y": 0,
      "z": -9,
      "name": "Wood_Deadwood_Planks",
      "rotation": 1
    },
    {
      "x": -5,
      "y": 0,
      "z": -8,
      "name": "Wood_Deadwood_Planks",
      "rotation": 1
    },
    {
      "x": -5,
      "y": 1,
      "z": -8,
      "name": "Wood_Beech_Branch_Long",
      "support": 15,
      "rotation": 1
    },
    {
      "x": -5,
      "y": 2,
      "z": -8,
      "name": "Wood_Beech_Branch_Long",
      "support": 15,
      "rotation": 1
    },
    {
      "x": -5,
      "y": 3,
      "z": -8,
      "name": "Wood_Beech_Branch_Long",
      "support": 15,
      "rotation": 1
    },
    {
      "x": -5,
      "y": 4,
      "z": -8,
      "name": "Rock_Stone_Cobble_Roof",
      "rotation": 3
    },
    {
      "x": -5,
      "y": 0,
      "z": -7,
      "name": "Wood_Deadwood_Planks",
      "rotation": 1
    },
    {
      "x": -5,
      "y": 4,
      "z": -7,
      "name": "Rock_Stone_Cobble_Roof_Hollow",
      "rotation": 3
    },
    {
      "x": -5,
      "y": 0,
      "z": -6,
      "name": "Wood_Deadwood_Planks",
      "rotation": 1
    },
    {
      "x": -5,
      "y": 4,
      "z": -6,
      "name": "Rock_Stone_Cobble_Roof_Hollow",
      "rotation": 3
    },
    {
      "x": -5,
      "y": 0,
      "z": -5,
      "name": "Wood_Deadwood_Planks",
      "rotation": 1
    },
    {
      "x": -5,
      "y": 4,
      "z": -5,
      "name": "Rock_Stone_Cobble_Roof_Hollow",
      "rotation": 3
    },
    {
      "x": -5,
      "y": 0,
      "z": -4,
      "name": "Wood_Deadwood_Planks",
      "rotation": 1
    },
    {
      "x": -5,
      "y": 4,
      "z": -4,
      "name": "Rock_Stone_Cobble_Roof_Hollow",
      "rotation": 3
    },
    {
      "x": -5,
      "y": 0,
      "z": -3,
      "name": "Wood_Deadwood_Planks",
      "rotation": 1
    },
    {
      "x": -5,
      "y": 1,
      "z": -3,
      "name": "Wood_Beech_Branch_Long",
      "support": 15,
      "rotation": 1
    },
    {
      "x": -5,
      "y": 2,
      "z": -3,
      "name": "Wood_Beech_Branch_Long",
      "support": 15,
      "rotation": 1
    },
    {
      "x": -5,
      "y": 3,
      "z": -3,
      "name": "Wood_Beech_Branch_Long",
      "support": 15,
      "rotation": 1
    },
    {
      "x": -5,
      "y": 4,
      "z": -3,
      "name": "Rock_Stone_Cobble_Roof",
      "rotation": 3
    },
    {
      "x": -5,
      "y": 0,
      "z": -2,
      "name": "Wood_Deadwood_Planks",
      "rotation": 1
    },
    {
      "x": -5,
      "y": 4,
      "z": -2,
      "name": "Plant_Moss_Wall_Green",
      "support": 15,
      "rotation": 3
    },
    {
      "x": -5,
      "y": 0,
      "z": -1,
      "name": "Wood_Deadwood_Planks",
      "rotation": 1
    },
    {
      "x": -5,
      "y": 1,
      "z": -1,
      "name": "Wood_Softwood_Planks_Half",
      "rotation": 7
    },
    {
      "x": -5,
      "y": 2,
      "z": -1,
      "name": "Wood_Softwood_Planks_Half",
      "rotation": 7
    },
    {
      "x": -5,
      "y": 3,
      "z": -1,
      "name": "Wood_Softwood_Planks_Half",
      "rotation": 7
    },
    {
      "x": -5,
      "y": 4,
      "z": -1,
      "name": "Wood_Softwood_Planks_Half",
      "rotation": 7
    },
    {
      "x": -5,
      "y": 5,
      "z": -1,
      "name": "Wood_Softwood_Planks_Half",
      "rotation": 7
    },
    {
      "x": -5,
      "y": 6,
      "z": -1,
      "name": "Plant_Vine_Jungle",
      "support": 15,
      "rotation": 3
    },
    {
      "x": -5,
      "y": 0,
      "z": 0,
      "name": "Wood_Deadwood_Planks",
      "rotation": 1
    },
    {
      "x": -5,
      "y": 1,
      "z": 0,
      "name": "Wood_Softwood_Planks_Half",
      "rotation": 7
    },
    {
      "x": -5,
      "y": 2,
      "z": 0,
      "name": "Wood_Softwood_Planks_Half",
      "rotation": 7
    },
    {
      "x": -5,
      "y": 3,
      "z": 0,
      "name": "Wood_Softwood_Planks_Half",
      "rotation": 7
    },
    {
      "x": -5,
      "y": 4,
      "z": 0,
      "name": "Wood_Softwood_Planks_Half",
      "rotation": 7
    },
    {
      "x": -5,
      "y": 5,
      "z": 0,
      "name": "Wood_Softwood_Planks_Half",
      "rotation": 7
    },
    {
      "x": -5,
      "y": 6,
      "z": 0,
      "name": "Plant_Vine_Jungle",
      "support": 15,
      "rotation": 3
    },
    {
      "x": -5,
      "y": 0,
      "z": 1,
      "name": "Wood_Deadwood_Planks",
      "rotation": 1
    },
    {
      "x": -5,
      "y": 5,
      "z": 1,
      "name": "Plant_Moss_Wall_Green",
      "support": 15,
      "rotation": 3
    },
    {
      "x": -5,
      "y": 0,
      "z": 2,
      "name": "Wood_Deadwood_Planks",
      "rotation": 1
    },
    {
      "x": -5,
      "y": 1,
      "z": 2,
      "name": "Wood_Beech_Branch_Long",
      "support": 15,
      "rotation": 1
    },
    {
      "x": -5,
      "y": 2,
      "z": 2,
      "name": "Wood_Beech_Branch_Long",
      "support": 15,
      "rotation": 1
    },
    {
      "x": -5,
      "y": 3,
      "z": 2,
      "name": "Wood_Beech_Branch_Long",
      "support": 15,
      "rotation": 1
    },
    {
      "x": -5,
      "y": 4,
      "z": 2,
      "name": "Rock_Stone_Cobble_Roof",
      "rotation": 3
    },
    {
      "x": -5,
      "y": 0,
      "z": 3,
      "name": "Wood_Deadwood_Planks",
      "rotation": 1
    },
    {
      "x": -5,
      "y": 4,
      "z": 3,
      "name": "Rock_Stone_Cobble_Roof_Hollow",
      "rotation": 3
    },
    {
      "x": -5,
      "y": 0,
      "z": 4,
      "name": "Wood_Deadwood_Planks",
      "rotation": 1
    },
    {
      "x": -5,
      "y": 4,
      "z": 4,
      "name": "Rock_Stone_Cobble_Roof_Hollow",
      "rotation": 3
    },
    {
      "x": -5,
      "y": 0,
      "z": 5,
      "name": "Wood_Deadwood_Planks",
      "rotation": 1
    },
    {
      "x": -5,
      "y": 4,
      "z": 5,
      "name": "Rock_Stone_Cobble_Roof_Hollow",
      "rotation": 3
    },
    {
      "x": -5,
      "y": 0,
      "z": 6,
      "name": "Wood_Deadwood_Planks",
      "rotation": 1
    },
    {
      "x": -5,
      "y": 4,
      "z": 6,
      "name": "Rock_Stone_Cobble_Roof_Hollow",
      "rotation": 3
    },
    {
      "x": -5,
      "y": 0,
      "z": 7,
      "name": "Wood_Deadwood_Planks",
      "rotation": 1
    },
    {
      "x": -5,
      "y": 1,
      "z": 7,
      "name": "Wood_Beech_Branch_Long",
      "support": 15,
      "rotation": 1
    },
    {
      "x": -5,
      "y": 2,
      "z": 7,
      "name": "Wood_Beech_Branch_Long",
      "support": 15,
      "rotation": 1
    },
    {
      "x": -5,
      "y": 3,
      "z": 7,
      "name": "Wood_Beech_Branch_Long",
      "support": 15,
      "rotation": 1
    },
    {
      "x": -5,
      "y": 4,
      "z": 7,
      "name": "Rock_Stone_Cobble_Roof",
      "rotation": 3
    },
    {
      "x": -5,
      "y": 0,
      "z": 8,
      "name": "Wood_Deadwood_Planks",
      "rotation": 1
    },
    {
      "x": -5,
      "y": 0,
      "z": 9,
      "name": "Wood_Deadwood_Planks",
      "rotation": 1
    },
    {
      "x": -5,
      "y": 0,
      "z": 10,
      "name": "Wood_Deadwood_Planks",
      "rotation": 1
    },
    {
      "x": -4,
      "y": 0,
      "z": -10,
      "name": "Wood_Deadwood_Planks",
      "rotation": 1
    },
    {
      "x": -4,
      "y": 0,
      "z": -9,
      "name": "Wood_Deadwood_Planks",
      "rotation": 1
    },
    {
      "x": -4,
      "y": 0,
      "z": -8,
      "name": "Wood_Deadwood_Planks",
      "rotation": 1
    },
    {
      "x": -4,
      "y": 3,
      "z": -8,
      "name": "Plant_Moss_Wall_Green",
      "support": 15,
      "rotation": 3
    },
    {
      "x": -4,
      "y": 4,
      "z": -8,
      "name": "Wood_Beech_Branch_Long",
      "support": 15,
      "rotation": 5
    },
    {
      "x": -4,
      "y": 5,
      "z": -8,
      "name": "Rock_Stone_Cobble_Roof_Hollow",
      "rotation": 3
    },
    {
      "x": -4,
      "y": 9,
      "z": -8,
      "name": "Plant_Moss_Wall_Green_Dark",
      "support": 15,
      "rotation": 3
    },
    {
      "x": -4,
      "y": 0,
      "z": -7,
      "name": "Wood_Deadwood_Planks",
      "rotation": 1
    },
    {
      "x": -4,
      "y": 5,
      "z": -7,
      "name": "Rock_Stone_Cobble_Roof_Hollow",
      "rotation": 3
    },
    {
      "x": -4,
      "y": 9,
      "z": -7,
      "name": "Furniture_Temple_Dark_Shelf",
      "rotation": 3
    },
    {
      "x": -4,
      "y": 10,
      "z": -7,
      "name": "Cloth_Roof_Hide_Flap",
      "rotation": 3
    },
    {
      "x": -4,
      "y": 0,
      "z": -6,
      "name": "Wood_Deadwood_Planks",
      "rotation": 1
    },
    {
      "x": -4,
      "y": 1,
      "z": -6,
      "name": "Plant_Moss_Wall_Green",
      "support": 15,
      "rotation": 3
    },
    {
      "x": -4,
      "y": 5,
      "z": -6,
      "name": "Rock_Stone_Cobble_Roof_Hollow",
      "rotation": 3
    },
    {
      "x": -4,
      "y": 9,
      "z": -6,
      "name": "Furniture_Temple_Dark_Shelf",
      "rotation": 3
    },
    {
      "x": -4,
      "y": 10,
      "z": -6,
      "name": "Cloth_Roof_Hide_Flap",
      "rotation": 3
    },
    {
      "x": -4,
      "y": 0,
      "z": -5,
      "name": "Wood_Deadwood_Planks",
      "rotation": 1
    },
    {
      "x": -4,
      "y": 1,
      "z": -5,
      "name": "Plant_Moss_Wall_Green_Dark",
      "support": 15,
      "rotation": 3
    },
    {
      "x": -4,
      "y": 5,
      "z": -5,
      "name": "Rock_Stone_Cobble_Roof_Hollow",
      "rotation": 3
    },
    {
      "x": -4,
      "y": 9,
      "z": -5,
      "name": "Furniture_Temple_Dark_Shelf",
      "rotation": 3
    },
    {
      "x": -4,
      "y": 10,
      "z": -5,
      "name": "Cloth_Roof_Hide_Flap",
      "rotation": 3
    },
    {
      "x": -4,
      "y": 0,
      "z": -4,
      "name": "Wood_Deadwood_Planks",
      "rotation": 1
    },
    {
      "x": -4,
      "y": 5,
      "z": -4,
      "name": "Rock_Stone_Cobble_Roof_Hollow",
      "rotation": 3
    },
    {
      "x": -4,
      "y": 9,
      "z": -4,
      "name": "Furniture_Temple_Dark_Shelf",
      "rotation": 3
    },
    {
      "x": -4,
      "y": 10,
      "z": -4,
      "name": "Cloth_Roof_Hide_Flap",
      "rotation": 3
    },
    {
      "x": -4,
      "y": 0,
      "z": -3,
      "name": "Wood_Deadwood_Planks",
      "rotation": 1
    },
    {
      "x": -4,
      "y": 3,
      "z": -3,
      "name": "Plant_Moss_Wall_Green_Dark",
      "support": 15,
      "rotation": 3
    },
    {
      "x": -4,
      "y": 4,
      "z": -3,
      "name": "Wood_Beech_Branch_Long",
      "support": 15,
      "rotation": 5
    },
    {
      "x": -4,
      "y": 5,
      "z": -3,
      "name": "Rock_Stone_Cobble_Roof_Hollow",
      "rotation": 3
    },
    {
      "x": -4,
      "y": 9,
      "z": -3,
      "name": "Plant_Moss_Wall_Green_Dark",
      "support": 15,
      "rotation": 3
    },
    {
      "x": -4,
      "y": 0,
      "z": -2,
      "name": "Wood_Deadwood_Planks",
      "rotation": 1
    },
    {
      "x": -4,
      "y": 1,
      "z": -2,
      "name": "Wood_Deadwood_Ornate",
      "rotation": 1
    },
    {
      "x": -4,
      "y": 2,
      "z": -2,
      "name": "Wood_Deadwood_Ornate",
      "rotation": 1
    },
    {
      "x": -4,
      "y": 3,
      "z": -2,
      "name": "Wood_Deadwood_Ornate",
      "rotation": 1
    },
    {
      "x": -4,
      "y": 4,
      "z": -2,
      "name": "Wood_Deadwood_Ornate",
      "rotation": 3
    },
    {
      "x": -4,
      "y": 5,
      "z": -2,
      "name": "Wood_Deadwood_Ornate",
      "rotation": 3
    },
    {
      "x": -4,
      "y": 6,
      "z": -2,
      "name": "Rock_Stone_Cobble_Roof",
      "rotation": 2
    },
    {
      "x": -4,
      "y": 0,
      "z": -1,
      "name": "Wood_Deadwood_Planks",
      "rotation": 1
    },
    {
      "x": -4,
      "y": 1,
      "z": -1,
      "name": "Wood_Deadwood_Ornate",
      "rotation": 1
    },
    {
      "x": -4,
      "y": 2,
      "z": -1,
      "name": "Wood_Deadwood_Ornate",
      "rotation": 1
    },
    {
      "x": -4,
      "y": 3,
      "z": -1,
      "name": "Wood_Deadwood_Ornate",
      "rotation": 1
    },
    {
      "x": -4,
      "y": 4,
      "z": -1,
      "name": "Wood_Deadwood_Ornate",
      "rotation": 3
    },
    {
      "x": -4,
      "y": 5,
      "z": -1,
      "name": "Wood_Deadwood_Ornate",
      "rotation": 1
    },
    {
      "x": -4,
      "y": 6,
      "z": -1,
      "name": "Wood_Deadwood_Ornate",
      "rotation": 1
    },
    {
      "x": -4,
      "y": 7,
      "z": -1,
      "name": "Rock_Stone_Cobble_Roof_Steep",
      "rotation": 2
    },
    {
      "x": -4,
      "y": 8,
      "z": -1,
      "name": "Rock_Stone_Cobble_Roof_Steep",
      "filler": 1024,
      "rotation": 2
    },
    {
      "x": -4,
      "y": 0,
      "z": 0,
      "name": "Wood_Deadwood_Planks",
      "rotation": 1
    },
    {
      "x": -4,
      "y": 1,
      "z": 0,
      "name": "Wood_Deadwood_Ornate",
      "rotation": 1
    },
    {
      "x": -4,
      "y": 2,
      "z": 0,
      "name": "Wood_Deadwood_Ornate",
      "rotation": 1
    },
    {
      "x": -4,
      "y": 3,
      "z": 0,
      "name": "Wood_Deadwood_Ornate",
      "rotation": 1
    },
    {
      "x": -4,
      "y": 4,
      "z": 0,
      "name": "Wood_Deadwood_Ornate",
      "rotation": 3
    },
    {
      "x": -4,
      "y": 5,
      "z": 0,
      "name": "Wood_Deadwood_Ornate",
      "rotation": 1
    },
    {
      "x": -4,
      "y": 6,
      "z": 0,
      "name": "Wood_Deadwood_Ornate",
      "rotation": 1
    },
    {
      "x": -4,
      "y": 7,
      "z": 0,
      "name": "Rock_Stone_Cobble_Roof_Steep"
    },
    {
      "x": -4,
      "y": 8,
      "z": 0,
      "name": "Rock_Stone_Cobble_Roof_Steep",
      "filler": 1024
    },
    {
      "x": -4,
      "y": 0,
      "z": 1,
      "name": "Wood_Deadwood_Planks",
      "rotation": 1
    },
    {
      "x": -4,
      "y": 1,
      "z": 1,
      "name": "Wood_Deadwood_Ornate",
      "rotation": 1
    },
    {
      "x": -4,
      "y": 2,
      "z": 1,
      "name": "Wood_Deadwood_Ornate",
      "rotation": 1
    },
    {
      "x": -4,
      "y": 3,
      "z": 1,
      "name": "Wood_Deadwood_Ornate",
      "rotation": 1
    },
    {
      "x": -4,
      "y": 4,
      "z": 1,
      "name": "Wood_Deadwood_Ornate",
      "rotation": 3
    },
    {
      "x": -4,
      "y": 5,
      "z": 1,
      "name": "Wood_Deadwood_Ornate",
      "rotation": 3
    },
    {
      "x": -4,
      "y": 6,
      "z": 1,
      "name": "Rock_Stone_Cobble_Roof"
    },
    {
      "x": -4,
      "y": 0,
      "z": 2,
      "name": "Wood_Deadwood_Planks",
      "rotation": 1
    },
    {
      "x": -4,
      "y": 3,
      "z": 2,
      "name": "Plant_Moss_Wall_Green",
      "support": 15,
      "rotation": 3
    },
    {
      "x": -4,
      "y": 4,
      "z": 2,
      "name": "Wood_Beech_Branch_Long",
      "support": 15,
      "rotation": 5
    },
    {
      "x": -4,
      "y": 5,
      "z": 2,
      "name": "Rock_Stone_Cobble_Roof_Hollow",
      "rotation": 3
    },
    {
      "x": -4,
      "y": 9,
      "z": 2,
      "name": "Plant_Moss_Wall_Green_Dark",
      "support": 15,
      "rotation": 3
    },
    {
      "x": -4,
      "y": 0,
      "z": 3,
      "name": "Wood_Deadwood_Planks",
      "rotation": 1
    },
    {
      "x": -4,
      "y": 1,
      "z": 3,
      "name": "Plant_Moss_Wall_Green",
      "support": 15,
      "rotation": 3
    },
    {
      "x": -4,
      "y": 5,
      "z": 3,
      "name": "Rock_Stone_Cobble_Roof_Hollow",
      "rotation": 3
    },
    {
      "x": -4,
      "y": 9,
      "z": 3,
      "name": "Furniture_Temple_Dark_Shelf",
      "rotation": 3
    },
    {
      "x": -4,
      "y": 10,
      "z": 3,
      "name": "Cloth_Roof_Hide_Flap",
      "rotation": 3
    },
    {
      "x": -4,
      "y": 0,
      "z": 4,
      "name": "Wood_Deadwood_Planks",
      "rotation": 1
    },
    {
      "x": -4,
      "y": 5,
      "z": 4,
      "name": "Rock_Stone_Cobble_Roof_Hollow",
      "rotation": 3
    },
    {
      "x": -4,
      "y": 9,
      "z": 4,
      "name": "Furniture_Temple_Dark_Shelf",
      "rotation": 3
    },
    {
      "x": -4,
      "y": 10,
      "z": 4,
      "name": "Cloth_Roof_Hide_Flap",
      "rotation": 3
    },
    {
      "x": -4,
      "y": 0,
      "z": 5,
      "name": "Wood_Deadwood_Planks",
      "rotation": 1
    },
    {
      "x": -4,
      "y": 1,
      "z": 5,
      "name": "Plant_Vine_Jungle",
      "support": 15,
      "rotation": 3
    },
    {
      "x": -4,
      "y": 5,
      "z": 5,
      "name": "Rock_Stone_Cobble_Roof_Hollow",
      "rotation": 3
    },
    {
      "x": -4,
      "y": 9,
      "z": 5,
      "name": "Furniture_Temple_Dark_Shelf",
      "rotation": 3
    },
    {
      "x": -4,
      "y": 10,
      "z": 5,
      "name": "Cloth_Roof_Hide_Flap",
      "rotation": 3
    },
    {
      "x": -4,
      "y": 0,
      "z": 6,
      "name": "Wood_Deadwood_Planks",
      "rotation": 1
    },
    {
      "x": -4,
      "y": 1,
      "z": 6,
      "name": "Plant_Vine_Jungle",
      "support": 15,
      "rotation": 3
    },
    {
      "x": -4,
      "y": 5,
      "z": 6,
      "name": "Rock_Stone_Cobble_Roof_Hollow",
      "rotation": 3
    },
    {
      "x": -4,
      "y": 9,
      "z": 6,
      "name": "Furniture_Temple_Dark_Shelf",
      "rotation": 3
    },
    {
      "x": -4,
      "y": 10,
      "z": 6,
      "name": "Cloth_Roof_Hide_Flap",
      "rotation": 3
    },
    {
      "x": -4,
      "y": 0,
      "z": 7,
      "name": "Wood_Deadwood_Planks",
      "rotation": 1
    },
    {
      "x": -4,
      "y": 4,
      "z": 7,
      "name": "Wood_Beech_Branch_Long",
      "support": 15,
      "rotation": 5
    },
    {
      "x": -4,
      "y": 5,
      "z": 7,
      "name": "Rock_Stone_Cobble_Roof_Hollow",
      "rotation": 3
    },
    {
      "x": -4,
      "y": 9,
      "z": 7,
      "name": "Plant_Moss_Wall_Green",
      "support": 15,
      "rotation": 3
    },
    {
      "x": -4,
      "y": 0,
      "z": 8,
      "name": "Wood_Deadwood_Planks",
      "rotation": 1
    },
    {
      "x": -4,
      "y": 0,
      "z": 9,
      "name": "Wood_Deadwood_Planks",
      "rotation": 1
    },
    {
      "x": -4,
      "y": 0,
      "z": 10,
      "name": "Wood_Deadwood_Planks",
      "rotation": 1
    },
    {
      "x": -3,
      "y": 0,
      "z": -10,
      "name": "Wood_Deadwood_Planks",
      "rotation": 1
    },
    {
      "x": -3,
      "y": 0,
      "z": -9,
      "name": "Wood_Deadwood_Planks",
      "rotation": 1
    },
    {
      "x": -3,
      "y": 4,
      "z": -9,
      "name": "Plant_Vine_Jungle",
      "support": 15,
      "rotation": 2
    },
    {
      "x": -3,
      "y": 5,
      "z": -9,
      "name": "Plant_Moss_Wall_Green",
      "support": 15,
      "rotation": 2
    },
    {
      "x": -3,
      "y": 9,
      "z": -9,
      "name": "Plant_Moss_Wall_Green_Dark",
      "support": 15,
      "rotation": 2
    },
    {
      "x": -3,
      "y": 10,
      "z": -9,
      "name": "Rock_Stone_Cobble_Roof_Shallow",
      "rotation": 2
    },
    {
      "x": -3,
      "y": 0,
      "z": -8,
      "name": "Wood_Deadwood_Planks",
      "rotation": 1
    },
    {
      "x": -3,
      "y": 1,
      "z": -8,
      "name": "Wood_Deadwood_Ornate",
      "rotation": 1
    },
    {
      "x": -3,
      "y": 2,
      "z": -8,
      "name": "Wood_Deadwood_Ornate",
      "rotation": 1
    },
    {
      "x": -3,
      "y": 3,
      "z": -8,
      "name": "Wood_Deadwood_Ornate",
      "rotation": 1
    },
    {
      "x": -3,
      "y": 4,
      "z": -8,
      "name": "Wood_Deadwood_Ornate",
      "rotation": 1
    },
    {
      "x": -3,
      "y": 5,
      "z": -8,
      "name": "Wood_Deadwood_Ornate",
      "rotation": 1
    },
    {
      "x": -3,
      "y": 6,
      "z": -8,
      "name": "Wood_Beech_Branch_Long",
      "support": 15,
      "rotation": 1
    },
    {
      "x": -3,
      "y": 7,
      "z": -8,
      "name": "Wood_Beech_Branch_Long",
      "support": 15,
      "rotation": 1
    },
    {
      "x": -3,
      "y": 8,
      "z": -8,
      "name": "*Wood_Deadwood_Stairs_State_Definitions_Corner_Right",
      "rotation": 8
    },
    {
      "x": -3,
      "y": 9,
      "z": -8,
      "name": "Wood_Deadwood_Ornate",
      "rotation": 1
    },
    {
      "x": -3,
      "y": 10,
      "z": -8,
      "name": "Rock_Stone_Cobble_Roof_Shallow",
      "filler": 32,
      "rotation": 2
    },
    {
      "x": -3,
      "y": 0,
      "z": -7,
      "name": "Wood_Deadwood_Planks",
      "rotation": 1
    },
    {
      "x": -3,
      "y": 1,
      "z": -7,
      "name": "Wood_Deadwood_Ornate",
      "rotation": 1
    },
    {
      "x": -3,
      "y": 2,
      "z": -7,
      "name": "Wood_Deadwood_Ornate",
      "rotation": 1
    },
    {
      "x": -3,
      "y": 3,
      "z": -7,
      "name": "Wood_Deadwood_Ornate",
      "rotation": 1
    },
    {
      "x": -3,
      "y": 4,
      "z": -7,
      "name": "Wood_Deadwood_Ornate",
      "rotation": 1
    },
    {
      "x": -3,
      "y": 5,
      "z": -7,
      "name": "Wood_Deadwood_Ornate",
      "rotation": 1
    },
    {
      "x": -3,
      "y": 6,
      "z": -7,
      "name": "Wood_Deadwood_Planks_Half",
      "rotation": 7
    },
    {
      "x": -3,
      "y": 7,
      "z": -7,
      "name": "Wood_Deadwood_Planks_Half",
      "rotation": 7
    },
    {
      "x": -3,
      "y": 8,
      "z": -7,
      "name": "Wood_Deadwood_Stairs",
      "rotation": 9
    },
    {
      "x": -3,
      "y": 9,
      "z": -7,
      "name": "Wood_Deadwood_Ornate",
      "rotation": 1
    },
    {
      "x": -3,
      "y": 10,
      "z": -7,
      "name": "Furniture_Human_Ruins_Window",
      "rotation": 1
    },
    {
      "x": -3,
      "y": 11,
      "z": -7,
      "name": "Rock_Stone_Cobble_Roof_Shallow",
      "rotation": 2
    },
    {
      "x": -3,
      "y": 0,
      "z": -6,
      "name": "Wood_Deadwood_Planks",
      "rotation": 1
    },
    {
      "x": -3,
      "y": 1,
      "z": -6,
      "name": "Wood_Deadwood_Ornate",
      "rotation": 1
    },
    {
      "x": -3,
      "y": 2,
      "z": -6,
      "name": "Furniture_Human_Ruins_Window",
      "rotation": 1
    },
    {
      "x": -3,
      "y": 3,
      "z": -6,
      "name": "Furniture_Human_Ruins_Window",
      "rotation": 1
    },
    {
      "x": -3,
      "y": 4,
      "z": -6,
      "name": "Furniture_Human_Ruins_Window",
      "rotation": 1
    },
    {
      "x": -3,
      "y": 5,
      "z": -6,
      "name": "Wood_Deadwood_Ornate",
      "rotation": 1
    },
    {
      "x": -3,
      "y": 6,
      "z": -6,
      "name": "Wood_Deadwood_Planks_Half",
      "rotation": 7
    },
    {
      "x": -3,
      "y": 7,
      "z": -6,
      "name": "Wood_Deadwood_Planks_Half",
      "rotation": 7
    },
    {
      "x": -3,
      "y": 8,
      "z": -6,
      "name": "Wood_Deadwood_Stairs",
      "rotation": 9
    },
    {
      "x": -3,
      "y": 9,
      "z": -6,
      "name": "Wood_Deadwood_Ornate",
      "rotation": 1
    },
    {
      "x": -3,
      "y": 10,
      "z": -6,
      "name": "Furniture_Human_Ruins_Window",
      "rotation": 1
    },
    {
      "x": -3,
      "y": 11,
      "z": -6,
      "name": "Rock_Stone_Cobble_Roof_Shallow",
      "filler": 32,
      "rotation": 2
    },
    {
      "x": -3,
      "y": 0,
      "z": -5,
      "name": "Wood_Deadwood_Planks",
      "rotation": 1
    },
    {
      "x": -3,
      "y": 1,
      "z": -5,
      "name": "Wood_Deadwood_Ornate",
      "rotation": 1
    },
    {
      "x": -3,
      "y": 2,
      "z": -5,
      "name": "Furniture_Human_Ruins_Window",
      "rotation": 1
    },
    {
      "x": -3,
      "y": 3,
      "z": -5,
      "name": "Furniture_Human_Ruins_Window",
      "rotation": 1
    },
    {
      "x": -3,
      "y": 4,
      "z": -5,
      "name": "Furniture_Human_Ruins_Window",
      "rotation": 1
    },
    {
      "x": -3,
      "y": 5,
      "z": -5,
      "name": "Wood_Deadwood_Ornate",
      "rotation": 1
    },
    {
      "x": -3,
      "y": 6,
      "z": -5,
      "name": "Wood_Deadwood_Planks_Half",
      "rotation": 7
    },
    {
      "x": -3,
      "y": 7,
      "z": -5,
      "name": "Wood_Deadwood_Planks_Half",
      "rotation": 7
    },
    {
      "x": -3,
      "y": 8,
      "z": -5,
      "name": "Wood_Deadwood_Stairs",
      "rotation": 9
    },
    {
      "x": -3,
      "y": 9,
      "z": -5,
      "name": "Wood_Deadwood_Ornate",
      "rotation": 1
    },
    {
      "x": -3,
      "y": 10,
      "z": -5,
      "name": "Furniture_Human_Ruins_Window",
      "rotation": 1
    },
    {
      "x": -3,
      "y": 11,
      "z": -5,
      "name": "Rock_Stone_Cobble_Roof_Shallow",
      "filler": 992
    },
    {
      "x": -3,
      "y": 0,
      "z": -4,
      "name": "Wood_Deadwood_Planks",
      "rotation": 1
    },
    {
      "x": -3,
      "y": 1,
      "z": -4,
      "name": "Wood_Deadwood_Ornate",
      "rotation": 1
    },
    {
      "x": -3,
      "y": 2,
      "z": -4,
      "name": "Wood_Deadwood_Ornate",
      "rotation": 1
    },
    {
      "x": -3,
      "y": 3,
      "z": -4,
      "name": "Wood_Deadwood_Ornate",
      "rotation": 1
    },
    {
      "x": -3,
      "y": 4,
      "z": -4,
      "name": "Wood_Deadwood_Ornate",
      "rotation": 1
    },
    {
      "x": -3,
      "y": 5,
      "z": -4,
      "name": "Wood_Deadwood_Ornate",
      "rotation": 1
    },
    {
      "x": -3,
      "y": 6,
      "z": -4,
      "name": "Wood_Deadwood_Planks_Half",
      "rotation": 7
    },
    {
      "x": -3,
      "y": 7,
      "z": -4,
      "name": "Wood_Deadwood_Planks_Half",
      "rotation": 7
    },
    {
      "x": -3,
      "y": 8,
      "z": -4,
      "name": "Wood_Deadwood_Stairs",
      "rotation": 9
    },
    {
      "x": -3,
      "y": 9,
      "z": -4,
      "name": "Wood_Deadwood_Ornate",
      "rotation": 1
    },
    {
      "x": -3,
      "y": 10,
      "z": -4,
      "name": "Furniture_Human_Ruins_Window",
      "rotation": 1
    },
    {
      "x": -3,
      "y": 11,
      "z": -4,
      "name": "Rock_Stone_Cobble_Roof_Shallow"
    },
    {
      "x": -3,
      "y": 0,
      "z": -3,
      "name": "Wood_Deadwood_Planks",
      "rotation": 1
    },
    {
      "x": -3,
      "y": 1,
      "z": -3,
      "name": "Wood_Deadwood_Ornate",
      "rotation": 1
    },
    {
      "x": -3,
      "y": 2,
      "z": -3,
      "name": "Wood_Deadwood_Ornate",
      "rotation": 1
    },
    {
      "x": -3,
      "y": 3,
      "z": -3,
      "name": "Wood_Deadwood_Ornate",
      "rotation": 1
    },
    {
      "x": -3,
      "y": 4,
      "z": -3,
      "name": "Wood_Deadwood_Ornate",
      "rotation": 1
    },
    {
      "x": -3,
      "y": 5,
      "z": -3,
      "name": "Wood_Deadwood_Ornate",
      "rotation": 1
    },
    {
      "x": -3,
      "y": 6,
      "z": -3,
      "name": "Wood_Beech_Branch_Long",
      "support": 15,
      "rotation": 1
    },
    {
      "x": -3,
      "y": 7,
      "z": -3,
      "name": "Wood_Beech_Branch_Long",
      "support": 15,
      "rotation": 1
    },
    {
      "x": -3,
      "y": 8,
      "z": -3,
      "name": "*Wood_Deadwood_Stairs_State_Definitions_Corner_Right",
      "rotation": 9
    },
    {
      "x": -3,
      "y": 9,
      "z": -3,
      "name": "Wood_Deadwood_Ornate",
      "rotation": 1
    },
    {
      "x": -3,
      "y": 10,
      "z": -3,
      "name": "Rock_Stone_Cobble_Roof_Shallow",
      "filler": 992
    },
    {
      "x": -3,
      "y": 0,
      "z": -2,
      "name": "Wood_Deadwood_Planks",
      "rotation": 1
    },
    {
      "x": -3,
      "y": 6,
      "z": -2,
      "name": "Rock_Stone_Cobble_Roof_Hollow",
      "rotation": 2
    },
    {
      "x": -3,
      "y": 9,
      "z": -2,
      "name": "Plant_Moss_Wall_Green_Dark",
      "support": 15
    },
    {
      "x": -3,
      "y": 10,
      "z": -2,
      "name": "Rock_Stone_Cobble_Roof_Shallow"
    },
    {
      "x": -3,
      "y": 0,
      "z": -1,
      "name": "Wood_Deadwood_Planks",
      "rotation": 1
    },
    {
      "x": -3,
      "y": 7,
      "z": -1,
      "name": "Rock_Stone_Cobble_Roof_Steep",
      "rotation": 2
    },
    {
      "x": -3,
      "y": 8,
      "z": -1,
      "name": "Rock_Stone_Cobble_Roof_Steep",
      "filler": 1024,
      "rotation": 2
    },
    {
      "x": -3,
      "y": 0,
      "z": 0,
      "name": "Wood_Deadwood_Planks",
      "rotation": 1
    },
    {
      "x": -3,
      "y": 7,
      "z": 0,
      "name": "Rock_Stone_Cobble_Roof_Steep"
    },
    {
      "x": -3,
      "y": 8,
      "z": 0,
      "name": "Rock_Stone_Cobble_Roof_Steep",
      "filler": 1024
    },
    {
      "x": -3,
      "y": 0,
      "z": 1,
      "name": "Wood_Deadwood_Planks",
      "rotation": 1
    },
    {
      "x": -3,
      "y": 6,
      "z": 1,
      "name": "Rock_Stone_Cobble_Roof_Hollow"
    },
    {
      "x": -3,
      "y": 10,
      "z": 1,
      "name": "Rock_Stone_Cobble_Roof_Shallow",
      "rotation": 2
    },
    {
      "x": -3,
      "y": 0,
      "z": 2,
      "name": "Wood_Deadwood_Planks",
      "rotation": 1
    },
    {
      "x": -3,
      "y": 1,
      "z": 2,
      "name": "Wood_Deadwood_Ornate",
      "rotation": 1
    },
    {
      "x": -3,
      "y": 2,
      "z": 2,
      "name": "Wood_Deadwood_Ornate",
      "rotation": 1
    },
    {
      "x": -3,
      "y": 3,
      "z": 2,
      "name": "Wood_Deadwood_Ornate",
      "rotation": 1
    },
    {
      "x": -3,
      "y": 4,
      "z": 2,
      "name": "Wood_Deadwood_Ornate",
      "rotation": 1
    },
    {
      "x": -3,
      "y": 5,
      "z": 2,
      "name": "Wood_Deadwood_Ornate",
      "rotation": 1
    },
    {
      "x": -3,
      "y": 6,
      "z": 2,
      "name": "Wood_Beech_Branch_Long",
      "support": 15,
      "rotation": 1
    },
    {
      "x": -3,
      "y": 7,
      "z": 2,
      "name": "Wood_Beech_Branch_Long",
      "support": 15,
      "rotation": 1
    },
    {
      "x": -3,
      "y": 8,
      "z": 2,
      "name": "*Wood_Deadwood_Stairs_State_Definitions_Corner_Right",
      "rotation": 8
    },
    {
      "x": -3,
      "y": 9,
      "z": 2,
      "name": "Wood_Deadwood_Ornate",
      "rotation": 1
    },
    {
      "x": -3,
      "y": 10,
      "z": 2,
      "name": "Rock_Stone_Cobble_Roof_Shallow",
      "filler": 32,
      "rotation": 2
    },
    {
      "x": -3,
      "y": 0,
      "z": 3,
      "name": "Wood_Deadwood_Planks",
      "rotation": 1
    },
    {
      "x": -3,
      "y": 1,
      "z": 3,
      "name": "Wood_Deadwood_Ornate",
      "rotation": 1
    },
    {
      "x": -3,
      "y": 2,
      "z": 3,
      "name": "Wood_Deadwood_Ornate",
      "rotation": 1
    },
    {
      "x": -3,
      "y": 3,
      "z": 3,
      "name": "Wood_Deadwood_Ornate",
      "rotation": 1
    },
    {
      "x": -3,
      "y": 4,
      "z": 3,
      "name": "Wood_Deadwood_Ornate",
      "rotation": 1
    },
    {
      "x": -3,
      "y": 5,
      "z": 3,
      "name": "Wood_Deadwood_Ornate",
      "rotation": 1
    },
    {
      "x": -3,
      "y": 6,
      "z": 3,
      "name": "Wood_Deadwood_Planks_Half",
      "rotation": 7
    },
    {
      "x": -3,
      "y": 7,
      "z": 3,
      "name": "Wood_Deadwood_Planks_Half",
      "rotation": 7
    },
    {
      "x": -3,
      "y": 8,
      "z": 3,
      "name": "Wood_Deadwood_Stairs",
      "rotation": 9
    },
    {
      "x": -3,
      "y": 9,
      "z": 3,
      "name": "Wood_Deadwood_Ornate",
      "rotation": 1
    },
    {
      "x": -3,
      "y": 10,
      "z": 3,
      "name": "Furniture_Human_Ruins_Window",
      "rotation": 1
    },
    {
      "x": -3,
      "y": 11,
      "z": 3,
      "name": "Rock_Stone_Cobble_Roof_Shallow",
      "rotation": 2
    },
    {
      "x": -3,
      "y": 0,
      "z": 4,
      "name": "Wood_Deadwood_Planks",
      "rotation": 1
    },
    {
      "x": -3,
      "y": 1,
      "z": 4,
      "name": "Wood_Deadwood_Ornate",
      "rotation": 1
    },
    {
      "x": -3,
      "y": 2,
      "z": 4,
      "name": "Furniture_Human_Ruins_Window",
      "rotation": 1
    },
    {
      "x": -3,
      "y": 3,
      "z": 4,
      "name": "Furniture_Human_Ruins_Window",
      "rotation": 1
    },
    {
      "x": -3,
      "y": 4,
      "z": 4,
      "name": "Furniture_Human_Ruins_Window",
      "rotation": 1
    },
    {
      "x": -3,
      "y": 5,
      "z": 4,
      "name": "Wood_Deadwood_Ornate",
      "rotation": 1
    },
    {
      "x": -3,
      "y": 6,
      "z": 4,
      "name": "Wood_Deadwood_Planks_Half",
      "rotation": 7
    },
    {
      "x": -3,
      "y": 7,
      "z": 4,
      "name": "Wood_Deadwood_Planks_Half",
      "rotation": 7
    },
    {
      "x": -3,
      "y": 8,
      "z": 4,
      "name": "Wood_Deadwood_Stairs",
      "rotation": 9
    },
    {
      "x": -3,
      "y": 9,
      "z": 4,
      "name": "Wood_Deadwood_Ornate",
      "rotation": 1
    },
    {
      "x": -3,
      "y": 10,
      "z": 4,
      "name": "Furniture_Human_Ruins_Window",
      "rotation": 1
    },
    {
      "x": -3,
      "y": 11,
      "z": 4,
      "name": "Rock_Stone_Cobble_Roof_Shallow",
      "filler": 32,
      "rotation": 2
    },
    {
      "x": -3,
      "y": 0,
      "z": 5,
      "name": "Wood_Deadwood_Planks",
      "rotation": 1
    },
    {
      "x": -3,
      "y": 1,
      "z": 5,
      "name": "Wood_Deadwood_Ornate",
      "rotation": 1
    },
    {
      "x": -3,
      "y": 2,
      "z": 5,
      "name": "Furniture_Human_Ruins_Window",
      "rotation": 1
    },
    {
      "x": -3,
      "y": 3,
      "z": 5,
      "name": "Furniture_Human_Ruins_Window",
      "rotation": 1
    },
    {
      "x": -3,
      "y": 4,
      "z": 5,
      "name": "Furniture_Human_Ruins_Window",
      "rotation": 1
    },
    {
      "x": -3,
      "y": 5,
      "z": 5,
      "name": "Wood_Deadwood_Ornate",
      "rotation": 1
    },
    {
      "x": -3,
      "y": 6,
      "z": 5,
      "name": "Wood_Deadwood_Planks_Half",
      "rotation": 7
    },
    {
      "x": -3,
      "y": 7,
      "z": 5,
      "name": "Wood_Deadwood_Planks_Half",
      "rotation": 7
    },
    {
      "x": -3,
      "y": 8,
      "z": 5,
      "name": "Wood_Deadwood_Stairs",
      "rotation": 9
    },
    {
      "x": -3,
      "y": 9,
      "z": 5,
      "name": "Wood_Deadwood_Ornate",
      "rotation": 1
    },
    {
      "x": -3,
      "y": 10,
      "z": 5,
      "name": "Furniture_Human_Ruins_Window",
      "rotation": 1
    },
    {
      "x": -3,
      "y": 11,
      "z": 5,
      "name": "Rock_Stone_Cobble_Roof_Shallow",
      "filler": 992
    },
    {
      "x": -3,
      "y": 0,
      "z": 6,
      "name": "Wood_Deadwood_Planks",
      "rotation": 1
    },
    {
      "x": -3,
      "y": 1,
      "z": 6,
      "name": "Wood_Deadwood_Ornate",
      "rotation": 1
    },
    {
      "x": -3,
      "y": 2,
      "z": 6,
      "name": "Wood_Deadwood_Ornate",
      "rotation": 1
    },
    {
      "x": -3,
      "y": 3,
      "z": 6,
      "name": "Wood_Deadwood_Ornate",
      "rotation": 1
    },
    {
      "x": -3,
      "y": 4,
      "z": 6,
      "name": "Wood_Deadwood_Ornate",
      "rotation": 1
    },
    {
      "x": -3,
      "y": 5,
      "z": 6,
      "name": "Wood_Deadwood_Ornate",
      "rotation": 1
    },
    {
      "x": -3,
      "y": 6,
      "z": 6,
      "name": "Wood_Deadwood_Planks_Half",
      "rotation": 7
    },
    {
      "x": -3,
      "y": 7,
      "z": 6,
      "name": "Wood_Deadwood_Planks_Half",
      "rotation": 7
    },
    {
      "x": -3,
      "y": 8,
      "z": 6,
      "name": "Wood_Deadwood_Stairs",
      "rotation": 9
    },
    {
      "x": -3,
      "y": 9,
      "z": 6,
      "name": "Wood_Deadwood_Ornate",
      "rotation": 1
    },
    {
      "x": -3,
      "y": 10,
      "z": 6,
      "name": "Furniture_Human_Ruins_Window",
      "rotation": 1
    },
    {
      "x": -3,
      "y": 11,
      "z": 6,
      "name": "Rock_Stone_Cobble_Roof_Shallow"
    },
    {
      "x": -3,
      "y": 0,
      "z": 7,
      "name": "Wood_Deadwood_Planks",
      "rotation": 1
    },
    {
      "x": -3,
      "y": 1,
      "z": 7,
      "name": "Wood_Deadwood_Ornate",
      "rotation": 1
    },
    {
      "x": -3,
      "y": 2,
      "z": 7,
      "name": "Wood_Deadwood_Ornate",
      "rotation": 1
    },
    {
      "x": -3,
      "y": 3,
      "z": 7,
      "name": "Wood_Deadwood_Ornate",
      "rotation": 1
    },
    {
      "x": -3,
      "y": 4,
      "z": 7,
      "name": "Wood_Deadwood_Ornate",
      "rotation": 1
    },
    {
      "x": -3,
      "y": 5,
      "z": 7,
      "name": "Wood_Deadwood_Ornate",
      "rotation": 1
    },
    {
      "x": -3,
      "y": 6,
      "z": 7,
      "name": "Wood_Beech_Branch_Long",
      "support": 15,
      "rotation": 1
    },
    {
      "x": -3,
      "y": 7,
      "z": 7,
      "name": "Wood_Beech_Branch_Long",
      "support": 15,
      "rotation": 1
    },
    {
      "x": -3,
      "y": 8,
      "z": 7,
      "name": "*Wood_Deadwood_Stairs_State_Definitions_Corner_Right",
      "rotation": 9
    },
    {
      "x": -3,
      "y": 9,
      "z": 7,
      "name": "Wood_Deadwood_Ornate",
      "rotation": 1
    },
    {
      "x": -3,
      "y": 10,
      "z": 7,
      "name": "Rock_Stone_Cobble_Roof_Shallow",
      "filler": 992
    },
    {
      "x": -3,
      "y": 0,
      "z": 8,
      "name": "Wood_Deadwood_Planks",
      "rotation": 1
    },
    {
      "x": -3,
      "y": 2,
      "z": 8,
      "name": "Plant_Moss_Wall_Green",
      "support": 15
    },
    {
      "x": -3,
      "y": 5,
      "z": 8,
      "name": "Plant_Vine_Jungle",
      "support": 15
    },
    {
      "x": -3,
      "y": 9,
      "z": 8,
      "name": "Plant_Moss_Wall_Green",
      "support": 15
    },
    {
      "x": -3,
      "y": 10,
      "z": 8,
      "name": "Rock_Stone_Cobble_Roof_Shallow"
    },
    {
      "x": -3,
      "y": 0,
      "z": 9,
      "name": "Wood_Deadwood_Planks",
      "rotation": 1
    },
    {
      "x": -3,
      "y": 0,
      "z": 10,
      "name": "Wood_Deadwood_Planks",
      "rotation": 1
    },
    {
      "x": -2,
      "y": 0,
      "z": -10,
      "name": "Wood_Deadwood_Planks",
      "rotation": 1
    },
    {
      "x": -2,
      "y": 0,
      "z": -9,
      "name": "Wood_Deadwood_Planks",
      "rotation": 1
    },
    {
      "x": -2,
      "y": 2,
      "z": -9,
      "name": "Plant_Moss_Wall_Green",
      "support": 15,
      "rotation": 2
    },
    {
      "x": -2,
      "y": 3,
      "z": -9,
      "name": "Plant_Vine_Jungle",
      "support": 15,
      "rotation": 2
    },
    {
      "x": -2,
      "y": 5,
      "z": -9,
      "name": "Plant_Moss_Wall_Green_Dark",
      "support": 15,
      "rotation": 2
    },
    {
      "x": -2,
      "y": 9,
      "z": -9,
      "name": "Plant_Moss_Wall_Green_Dark",
      "support": 15,
      "rotation": 2
    },
    {
      "x": -2,
      "y": 10,
      "z": -9,
      "name": "Rock_Stone_Cobble_Roof_Shallow",
      "rotation": 2
    },
    {
      "x": -2,
      "y": 0,
      "z": -8,
      "name": "Wood_Deadwood_Planks",
      "rotation": 1
    },
    {
      "x": -2,
      "y": 1,
      "z": -8,
      "name": "Wood_Deadwood_Ornate",
      "rotation": 1
    },
    {
      "x": -2,
      "y": 2,
      "z": -8,
      "name": "Wood_Deadwood_Ornate",
      "rotation": 1
    },
    {
      "x": -2,
      "y": 3,
      "z": -8,
      "name": "Wood_Deadwood_Ornate",
      "rotation": 1
    },
    {
      "x": -2,
      "y": 4,
      "z": -8,
      "name": "Wood_Deadwood_Ornate",
      "rotation": 1
    },
    {
      "x": -2,
      "y": 5,
      "z": -8,
      "name": "Wood_Deadwood_Ornate",
      "rotation": 1
    },
    {
      "x": -2,
      "y": 6,
      "z": -8,
      "name": "Wood_Deadwood_Planks_Half",
      "rotation": 6
    },
    {
      "x": -2,
      "y": 7,
      "z": -8,
      "name": "Wood_Deadwood_Planks_Half",
      "rotation": 6
    },
    {
      "x": -2,
      "y": 8,
      "z": -8,
      "name": "Wood_Deadwood_Stairs",
      "rotation": 8
    },
    {
      "x": -2,
      "y": 9,
      "z": -8,
      "name": "Wood_Deadwood_Ornate",
      "rotation": 1
    },
    {
      "x": -2,
      "y": 10,
      "z": -8,
      "name": "Rock_Stone_Cobble_Roof_Shallow",
      "filler": 32,
      "rotation": 2
    },
    {
      "x": -2,
      "y": 0,
      "z": -7,
      "name": "Wood_Deadwood_Planks",
      "rotation": 1
    },
    {
      "x": -2,
      "y": 1,
      "z": -7,
      "name": "Furniture_Crude_Ladder",
      "rotation": 1
    },
    {
      "x": -2,
      "y": 2,
      "z": -7,
      "name": "Furniture_Crude_Ladder",
      "rotation": 1
    },
    {
      "x": -2,
      "y": 3,
      "z": -7,
      "name": "Furniture_Crude_Ladder",
      "rotation": 1
    },
    {
      "x": -2,
      "y": 4,
      "z": -7,
      "name": "Furniture_Crude_Ladder",
      "rotation": 1
    },
    {
      "x": -2,
      "y": 5,
      "z": -7,
      "name": "Furniture_Crude_Ladder",
      "rotation": 1
    },
    {
      "x": -2,
      "y": 6,
      "z": -7,
      "name": "Furniture_Crude_Ladder",
      "rotation": 1
    },
    {
      "x": -2,
      "y": 7,
      "z": -7,
      "name": "Furniture_Crude_Ladder",
      "rotation": 1
    },
    {
      "x": -2,
      "y": 11,
      "z": -7,
      "name": "Rock_Stone_Cobble_Roof_Shallow",
      "rotation": 2
    },
    {
      "x": -2,
      "y": 0,
      "z": -6,
      "name": "Wood_Deadwood_Planks",
      "rotation": 1
    },
    {
      "x": -2,
      "y": 5,
      "z": -6,
      "name": "Furniture_Crude_Platform",
      "rotation": 2
    },
    {
      "x": -2,
      "y": 11,
      "z": -6,
      "name": "Rock_Stone_Cobble_Roof_Shallow",
      "filler": 32,
      "rotation": 2
    },
    {
      "x": -2,
      "y": 0,
      "z": -5,
      "name": "Wood_Deadwood_Planks",
      "rotation": 1
    },
    {
      "x": -2,
      "y": 5,
      "z": -5,
      "name": "Furniture_Crude_Platform",
      "rotation": 2
    },
    {
      "x": -2,
      "y": 11,
      "z": -5,
      "name": "Rock_Stone_Cobble_Roof_Shallow",
      "filler": 992
    },
    {
      "x": -2,
      "y": 0,
      "z": -4,
      "name": "Wood_Deadwood_Planks",
      "rotation": 1
    },
    {
      "x": -2,
      "y": 5,
      "z": -4,
      "name": "Furniture_Crude_Platform",
      "rotation": 2
    },
    {
      "x": -2,
      "y": 11,
      "z": -4,
      "name": "Rock_Stone_Cobble_Roof_Shallow"
    },
    {
      "x": -2,
      "y": 0,
      "z": -3,
      "name": "Wood_Deadwood_Planks",
      "rotation": 1
    },
    {
      "x": -2,
      "y": 1,
      "z": -3,
      "name": "Wood_Deadwood_Ornate",
      "rotation": 1
    },
    {
      "x": -2,
      "y": 2,
      "z": -3,
      "name": "Wood_Deadwood_Ornate",
      "rotation": 1
    },
    {
      "x": -2,
      "y": 3,
      "z": -3,
      "name": "Wood_Deadwood_Ornate",
      "rotation": 1
    },
    {
      "x": -2,
      "y": 4,
      "z": -3,
      "name": "Wood_Deadwood_Ornate",
      "rotation": 1
    },
    {
      "x": -2,
      "y": 5,
      "z": -3,
      "name": "Wood_Deadwood_Ornate",
      "rotation": 1
    },
    {
      "x": -2,
      "y": 6,
      "z": -3,
      "name": "Wood_Deadwood_Planks_Half",
      "rotation": 4
    },
    {
      "x": -2,
      "y": 7,
      "z": -3,
      "name": "Wood_Deadwood_Planks_Half",
      "rotation": 4
    },
    {
      "x": -2,
      "y": 8,
      "z": -3,
      "name": "Wood_Deadwood_Stairs",
      "rotation": 10
    },
    {
      "x": -2,
      "y": 9,
      "z": -3,
      "name": "Wood_Deadwood_Ornate",
      "rotation": 1
    },
    {
      "x": -2,
      "y": 10,
      "z": -3,
      "name": "Rock_Stone_Cobble_Roof_Shallow",
      "filler": 992
    },
    {
      "x": -2,
      "y": 0,
      "z": -2,
      "name": "Wood_Deadwood_Planks",
      "rotation": 1
    },
    {
      "x": -2,
      "y": 6,
      "z": -2,
      "name": "Rock_Stone_Cobble_Roof_Hollow",
      "rotation": 2
    },
    {
      "x": -2,
      "y": 10,
      "z": -2,
      "name": "Rock_Stone_Cobble_Roof_Shallow"
    },
    {
      "x": -2,
      "y": 0,
      "z": -1,
      "name": "Wood_Deadwood_Planks",
      "rotation": 1
    },
    {
      "x": -2,
      "y": 7,
      "z": -1,
      "name": "Rock_Stone_Cobble_Roof_Steep",
      "rotation": 2
    },
    {
      "x": -2,
      "y": 8,
      "z": -1,
      "name": "Rock_Stone_Cobble_Roof_Steep",
      "filler": 1024,
      "rotation": 2
    },
    {
      "x": -2,
      "y": 0,
      "z": 0,
      "name": "Wood_Deadwood_Planks",
      "rotation": 1
    },
    {
      "x": -2,
      "y": 7,
      "z": 0,
      "name": "Rock_Stone_Cobble_Roof_Steep"
    },
    {
      "x": -2,
      "y": 8,
      "z": 0,
      "name": "Rock_Stone_Cobble_Roof_Steep",
      "filler": 1024
    },
    {
      "x": -2,
      "y": 0,
      "z": 1,
      "name": "Wood_Deadwood_Planks",
      "rotation": 1
    },
    {
      "x": -2,
      "y": 6,
      "z": 1,
      "name": "Rock_Stone_Cobble_Roof_Hollow"
    },
    {
      "x": -2,
      "y": 9,
      "z": 1,
      "name": "Plant_Moss_Wall_Green_Dark",
      "support": 15,
      "rotation": 2
    },
    {
      "x": -2,
      "y": 10,
      "z": 1,
      "name": "Rock_Stone_Cobble_Roof_Shallow",
      "rotation": 2
    },
    {
      "x": -2,
      "y": 0,
      "z": 2,
      "name": "Wood_Deadwood_Planks",
      "rotation": 1
    },
    {
      "x": -2,
      "y": 1,
      "z": 2,
      "name": "Wood_Deadwood_Ornate",
      "rotation": 1
    },
    {
      "x": -2,
      "y": 2,
      "z": 2,
      "name": "Wood_Deadwood_Ornate",
      "rotation": 1
    },
    {
      "x": -2,
      "y": 3,
      "z": 2,
      "name": "Wood_Deadwood_Ornate",
      "rotation": 1
    },
    {
      "x": -2,
      "y": 4,
      "z": 2,
      "name": "Wood_Deadwood_Ornate",
      "rotation": 1
    },
    {
      "x": -2,
      "y": 5,
      "z": 2,
      "name": "Wood_Deadwood_Ornate",
      "rotation": 1
    },
    {
      "x": -2,
      "y": 6,
      "z": 2,
      "name": "Wood_Deadwood_Planks_Half",
      "rotation": 6
    },
    {
      "x": -2,
      "y": 7,
      "z": 2,
      "name": "Wood_Deadwood_Planks_Half",
      "rotation": 6
    },
    {
      "x": -2,
      "y": 8,
      "z": 2,
      "name": "Wood_Deadwood_Stairs",
      "rotation": 8
    },
    {
      "x": -2,
      "y": 9,
      "z": 2,
      "name": "Wood_Deadwood_Ornate",
      "rotation": 1
    },
    {
      "x": -2,
      "y": 10,
      "z": 2,
      "name": "Rock_Stone_Cobble_Roof_Shallow",
      "filler": 32,
      "rotation": 2
    },
    {
      "x": -2,
      "y": 0,
      "z": 3,
      "name": "Wood_Deadwood_Planks",
      "rotation": 1
    },
    {
      "x": -2,
      "y": 1,
      "z": 3,
      "name": "Furniture_Crude_Ladder",
      "rotation": 1
    },
    {
      "x": -2,
      "y": 2,
      "z": 3,
      "name": "Furniture_Crude_Ladder",
      "rotation": 1
    },
    {
      "x": -2,
      "y": 3,
      "z": 3,
      "name": "Furniture_Crude_Ladder",
      "rotation": 1
    },
    {
      "x": -2,
      "y": 4,
      "z": 3,
      "name": "Furniture_Crude_Ladder",
      "rotation": 1
    },
    {
      "x": -2,
      "y": 5,
      "z": 3,
      "name": "Furniture_Crude_Ladder",
      "rotation": 1
    },
    {
      "x": -2,
      "y": 6,
      "z": 3,
      "name": "Furniture_Crude_Ladder",
      "rotation": 1
    },
    {
      "x": -2,
      "y": 7,
      "z": 3,
      "name": "Furniture_Crude_Ladder",
      "rotation": 1
    },
    {
      "x": -2,
      "y": 11,
      "z": 3,
      "name": "Rock_Stone_Cobble_Roof_Shallow",
      "rotation": 2
    },
    {
      "x": -2,
      "y": 0,
      "z": 4,
      "name": "Wood_Deadwood_Planks",
      "rotation": 1
    },
    {
      "x": -2,
      "y": 5,
      "z": 4,
      "name": "Furniture_Crude_Platform",
      "rotation": 2
    },
    {
      "x": -2,
      "y": 11,
      "z": 4,
      "name": "Rock_Stone_Cobble_Roof_Shallow",
      "filler": 32,
      "rotation": 2
    },
    {
      "x": -2,
      "y": 0,
      "z": 5,
      "name": "Wood_Deadwood_Planks",
      "rotation": 1
    },
    {
      "x": -2,
      "y": 5,
      "z": 5,
      "name": "Furniture_Crude_Platform",
      "rotation": 2
    },
    {
      "x": -2,
      "y": 11,
      "z": 5,
      "name": "Rock_Stone_Cobble_Roof_Shallow",
      "filler": 992
    },
    {
      "x": -2,
      "y": 0,
      "z": 6,
      "name": "Wood_Deadwood_Planks",
      "rotation": 1
    },
    {
      "x": -2,
      "y": 5,
      "z": 6,
      "name": "Furniture_Crude_Platform",
      "rotation": 2
    },
    {
      "x": -2,
      "y": 11,
      "z": 6,
      "name": "Rock_Stone_Cobble_Roof_Shallow"
    },
    {
      "x": -2,
      "y": 0,
      "z": 7,
      "name": "Wood_Deadwood_Planks",
      "rotation": 1
    },
    {
      "x": -2,
      "y": 1,
      "z": 7,
      "name": "Wood_Deadwood_Ornate",
      "rotation": 1
    },
    {
      "x": -2,
      "y": 2,
      "z": 7,
      "name": "Wood_Deadwood_Ornate",
      "rotation": 1
    },
    {
      "x": -2,
      "y": 3,
      "z": 7,
      "name": "Wood_Deadwood_Ornate",
      "rotation": 1
    },
    {
      "x": -2,
      "y": 4,
      "z": 7,
      "name": "Wood_Deadwood_Ornate",
      "rotation": 1
    },
    {
      "x": -2,
      "y": 5,
      "z": 7,
      "name": "Wood_Deadwood_Ornate",
      "rotation": 1
    },
    {
      "x": -2,
      "y": 6,
      "z": 7,
      "name": "Wood_Deadwood_Planks_Half",
      "rotation": 4
    },
    {
      "x": -2,
      "y": 7,
      "z": 7,
      "name": "Wood_Deadwood_Planks_Half",
      "rotation": 4
    },
    {
      "x": -2,
      "y": 8,
      "z": 7,
      "name": "Wood_Deadwood_Stairs",
      "rotation": 10
    },
    {
      "x": -2,
      "y": 9,
      "z": 7,
      "name": "Wood_Deadwood_Ornate",
      "rotation": 1
    },
    {
      "x": -2,
      "y": 10,
      "z": 7,
      "name": "Rock_Stone_Cobble_Roof_Shallow",
      "filler": 992
    },
    {
      "x": -2,
      "y": 0,
      "z": 8,
      "name": "Wood_Deadwood_Planks",
      "rotation": 1
    },
    {
      "x": -2,
      "y": 1,
      "z": 8,
      "name": "Wood_Beech_Branch_Long",
      "support": 15,
      "rotation": 1
    },
    {
      "x": -2,
      "y": 2,
      "z": 8,
      "name": "Wood_Beech_Branch_Long",
      "support": 15,
      "rotation": 1
    },
    {
      "x": -2,
      "y": 3,
      "z": 8,
      "name": "Wood_Beech_Branch_Long",
      "support": 15,
      "rotation": 1
    },
    {
      "x": -2,
      "y": 4,
      "z": 8,
      "name": "Wood_Beech_Branch_Long",
      "support": 15,
      "rotation": 1
    },
    {
      "x": -2,
      "y": 5,
      "z": 8,
      "name": "Rock_Stone_Cobble_Roof",
      "rotation": 3
    },
    {
      "x": -2,
      "y": 10,
      "z": 8,
      "name": "Rock_Stone_Cobble_Roof_Shallow"
    },
    {
      "x": -2,
      "y": 0,
      "z": 9,
      "name": "Wood_Deadwood_Planks",
      "rotation": 1
    },
    {
      "x": -2,
      "y": 5,
      "z": 9,
      "name": "*Rock_Stone_Cobble_Roof_Hollow_State_Definitions_Corner_Right"
    },
    {
      "x": -2,
      "y": 0,
      "z": 10,
      "name": "Wood_Deadwood_Planks",
      "rotation": 1
    },
    {
      "x": -1,
      "y": 0,
      "z": -10,
      "name": "Wood_Deadwood_Planks",
      "rotation": 1
    },
    {
      "x": -1,
      "y": 7,
      "z": -10,
      "name": "Wood_Beech_Branch_Long",
      "support": 15,
      "rotation": 6
    },
    {
      "x": -1,
      "y": 0,
      "z": -9,
      "name": "Wood_Deadwood_Planks",
      "rotation": 1
    },
    {
      "x": -1,
      "y": 1,
      "z": -9,
      "name": "Furniture_Crude_Ladder",
      "rotation": 2
    },
    {
      "x": -1,
      "y": 2,
      "z": -9,
      "name": "Furniture_Crude_Ladder",
      "rotation": 2
    },
    {
      "x": -1,
      "y": 3,
      "z": -9,
      "name": "Furniture_Crude_Ladder",
      "rotation": 2
    },
    {
      "x": -1,
      "y": 4,
      "z": -9,
      "name": "Furniture_Crude_Ladder",
      "rotation": 2
    },
    {
      "x": -1,
      "y": 7,
      "z": -9,
      "name": "Wood_Beech_Branch_Long",
      "support": 15,
      "rotation": 6
    },
    {
      "x": -1,
      "y": 10,
      "z": -9,
      "name": "Rock_Stone_Cobble_Roof_Shallow",
      "rotation": 2
    },
    {
      "x": -1,
      "y": 0,
      "z": -8,
      "name": "Wood_Deadwood_Planks",
      "rotation": 1
    },
    {
      "x": -1,
      "y": 1,
      "z": -8,
      "name": "Wood_Deadwood_Ornate",
      "rotation": 1
    },
    {
      "x": -1,
      "y": 2,
      "z": -8,
      "name": "Wood_Deadwood_Ornate",
      "rotation": 1
    },
    {
      "x": -1,
      "y": 3,
      "z": -8,
      "name": "Wood_Deadwood_Ornate",
      "rotation": 1
    },
    {
      "x": -1,
      "y": 4,
      "z": -8,
      "name": "Wood_Deadwood_Ornate",
      "rotation": 1
    },
    {
      "x": -1,
      "y": 5,
      "z": -8,
      "name": "Wood_Deadwood_Ornate",
      "rotation": 1
    },
    {
      "x": -1,
      "y": 6,
      "z": -8,
      "name": "Wood_Deadwood_Planks_Half",
      "rotation": 6
    },
    {
      "x": -1,
      "y": 7,
      "z": -8,
      "name": "Wood_Deadwood_Planks_Half",
      "rotation": 6
    },
    {
      "x": -1,
      "y": 8,
      "z": -8,
      "name": "Wood_Deadwood_Stairs",
      "rotation": 8
    },
    {
      "x": -1,
      "y": 9,
      "z": -8,
      "name": "Wood_Deadwood_Ornate",
      "rotation": 1
    },
    {
      "x": -1,
      "y": 10,
      "z": -8,
      "name": "Rock_Stone_Cobble_Roof_Shallow",
      "filler": 32,
      "rotation": 2
    },
    {
      "x": -1,
      "y": 0,
      "z": -7,
      "name": "Wood_Deadwood_Planks",
      "rotation": 1
    },
    {
      "x": -1,
      "y": 5,
      "z": -7,
      "name": "Furniture_Crude_Platform",
      "rotation": 2
    },
    {
      "x": -1,
      "y": 11,
      "z": -7,
      "name": "Rock_Stone_Cobble_Roof_Shallow",
      "rotation": 2
    },
    {
      "x": -1,
      "y": 0,
      "z": -6,
      "name": "Wood_Deadwood_Planks",
      "rotation": 1
    },
    {
      "x": -1,
      "y": 5,
      "z": -6,
      "name": "Furniture_Crude_Platform",
      "rotation": 2
    },
    {
      "x": -1,
      "y": 11,
      "z": -6,
      "name": "Rock_Stone_Cobble_Roof_Shallow",
      "filler": 32,
      "rotation": 2
    },
    {
      "x": -1,
      "y": 0,
      "z": -5,
      "name": "Wood_Deadwood_Planks",
      "rotation": 1
    },
    {
      "x": -1,
      "y": 5,
      "z": -5,
      "name": "Furniture_Crude_Platform",
      "rotation": 2
    },
    {
      "x": -1,
      "y": 11,
      "z": -5,
      "name": "Rock_Stone_Cobble_Roof_Shallow",
      "filler": 992
    },
    {
      "x": -1,
      "y": 0,
      "z": -4,
      "name": "Wood_Deadwood_Planks",
      "rotation": 1
    },
    {
      "x": -1,
      "y": 5,
      "z": -4,
      "name": "Furniture_Crude_Platform",
      "rotation": 2
    },
    {
      "x": -1,
      "y": 11,
      "z": -4,
      "name": "Rock_Stone_Cobble_Roof_Shallow"
    },
    {
      "x": -1,
      "y": 0,
      "z": -3,
      "name": "Wood_Deadwood_Planks",
      "rotation": 1
    },
    {
      "x": -1,
      "y": 4,
      "z": -3,
      "name": "Wood_Softwood_Beam",
      "rotation": 5
    },
    {
      "x": -1,
      "y": 5,
      "z": -3,
      "name": "Wood_Deadwood_Ornate",
      "rotation": 1
    },
    {
      "x": -1,
      "y": 6,
      "z": -3,
      "name": "Wood_Deadwood_Planks_Half",
      "rotation": 4
    },
    {
      "x": -1,
      "y": 7,
      "z": -3,
      "name": "Wood_Deadwood_Planks_Half",
      "rotation": 4
    },
    {
      "x": -1,
      "y": 8,
      "z": -3,
      "name": "Wood_Deadwood_Stairs",
      "rotation": 10
    },
    {
      "x": -1,
      "y": 9,
      "z": -3,
      "name": "Wood_Deadwood_Ornate",
      "rotation": 1
    },
    {
      "x": -1,
      "y": 10,
      "z": -3,
      "name": "Rock_Stone_Cobble_Roof_Shallow",
      "filler": 992
    },
    {
      "x": -1,
      "y": 0,
      "z": -2,
      "name": "Wood_Deadwood_Planks",
      "rotation": 1
    },
    {
      "x": -1,
      "y": 6,
      "z": -2,
      "name": "Rock_Stone_Cobble_Roof_Hollow",
      "rotation": 2
    },
    {
      "x": -1,
      "y": 9,
      "z": -2,
      "name": "Plant_Vine_Jungle",
      "support": 15
    },
    {
      "x": -1,
      "y": 10,
      "z": -2,
      "name": "Rock_Stone_Cobble_Roof_Shallow"
    },
    {
      "x": -1,
      "y": 0,
      "z": -1,
      "name": "Wood_Deadwood_Planks",
      "rotation": 1
    },
    {
      "x": -1,
      "y": 7,
      "z": -1,
      "name": "Rock_Stone_Cobble_Roof_Steep",
      "rotation": 2
    },
    {
      "x": -1,
      "y": 8,
      "z": -1,
      "name": "Rock_Stone_Cobble_Roof_Steep",
      "filler": 1024,
      "rotation": 2
    },
    {
      "x": -1,
      "y": 0,
      "z": 0,
      "name": "Wood_Deadwood_Planks",
      "rotation": 1
    },
    {
      "x": -1,
      "y": 7,
      "z": 0,
      "name": "Rock_Stone_Cobble_Roof_Steep"
    },
    {
      "x": -1,
      "y": 8,
      "z": 0,
      "name": "Rock_Stone_Cobble_Roof_Steep",
      "filler": 1024
    },
    {
      "x": -1,
      "y": 0,
      "z": 1,
      "name": "Wood_Deadwood_Planks",
      "rotation": 1
    },
    {
      "x": -1,
      "y": 6,
      "z": 1,
      "name": "Rock_Stone_Cobble_Roof_Hollow"
    },
    {
      "x": -1,
      "y": 10,
      "z": 1,
      "name": "Rock_Stone_Cobble_Roof_Shallow",
      "rotation": 2
    },
    {
      "x": -1,
      "y": 0,
      "z": 2,
      "name": "Wood_Deadwood_Planks",
      "rotation": 1
    },
    {
      "x": -1,
      "y": 4,
      "z": 2,
      "name": "Wood_Softwood_Beam",
      "rotation": 5
    },
    {
      "x": -1,
      "y": 5,
      "z": 2,
      "name": "Wood_Deadwood_Ornate",
      "rotation": 1
    },
    {
      "x": -1,
      "y": 6,
      "z": 2,
      "name": "Wood_Deadwood_Planks_Half",
      "rotation": 6
    },
    {
      "x": -1,
      "y": 7,
      "z": 2,
      "name": "Wood_Deadwood_Planks_Half",
      "rotation": 6
    },
    {
      "x": -1,
      "y": 8,
      "z": 2,
      "name": "Wood_Deadwood_Stairs",
      "rotation": 8
    },
    {
      "x": -1,
      "y": 9,
      "z": 2,
      "name": "Wood_Deadwood_Ornate",
      "rotation": 1
    },
    {
      "x": -1,
      "y": 10,
      "z": 2,
      "name": "Rock_Stone_Cobble_Roof_Shallow",
      "filler": 32,
      "rotation": 2
    },
    {
      "x": -1,
      "y": 0,
      "z": 3,
      "name": "Wood_Deadwood_Planks",
      "rotation": 1
    },
    {
      "x": -1,
      "y": 5,
      "z": 3,
      "name": "Furniture_Crude_Platform",
      "rotation": 2
    },
    {
      "x": -1,
      "y": 11,
      "z": 3,
      "name": "Rock_Stone_Cobble_Roof_Shallow",
      "rotation": 2
    },
    {
      "x": -1,
      "y": 0,
      "z": 4,
      "name": "Wood_Deadwood_Planks",
      "rotation": 1
    },
    {
      "x": -1,
      "y": 5,
      "z": 4,
      "name": "Furniture_Crude_Platform",
      "rotation": 2
    },
    {
      "x": -1,
      "y": 11,
      "z": 4,
      "name": "Rock_Stone_Cobble_Roof_Shallow",
      "filler": 32,
      "rotation": 2
    },
    {
      "x": -1,
      "y": 0,
      "z": 5,
      "name": "Wood_Deadwood_Planks",
      "rotation": 1
    },
    {
      "x": -1,
      "y": 5,
      "z": 5,
      "name": "Furniture_Crude_Platform",
      "rotation": 2
    },
    {
      "x": -1,
      "y": 11,
      "z": 5,
      "name": "Rock_Stone_Cobble_Roof_Shallow",
      "filler": 992
    },
    {
      "x": -1,
      "y": 0,
      "z": 6,
      "name": "Wood_Deadwood_Planks",
      "rotation": 1
    },
    {
      "x": -1,
      "y": 3,
      "z": 6,
      "name": "Furniture_Crude_Platform",
      "rotation": 2
    },
    {
      "x": -1,
      "y": 5,
      "z": 6,
      "name": "Furniture_Crude_Platform",
      "rotation": 2
    },
    {
      "x": -1,
      "y": 6,
      "z": 6,
      "name": "Wood_Deadwood_Planks_Half",
      "rotation": 6
    },
    {
      "x": -1,
      "y": 7,
      "z": 6,
      "name": "Wood_Deadwood_Planks_Half",
      "rotation": 6
    },
    {
      "x": -1,
      "y": 11,
      "z": 6,
      "name": "Rock_Stone_Cobble_Roof_Shallow"
    },
    {
      "x": -1,
      "y": 0,
      "z": 7,
      "name": "Wood_Deadwood_Planks",
      "rotation": 1
    },
    {
      "x": -1,
      "y": 1,
      "z": 7,
      "name": "Wood_Deadwood_Ornate",
      "rotation": 1
    },
    {
      "x": -1,
      "y": 2,
      "z": 7,
      "name": "Furniture_Human_Ruins_Window",
      "rotation": 2
    },
    {
      "x": -1,
      "y": 3,
      "z": 7,
      "name": "Wood_Deadwood_Ornate",
      "rotation": 1
    },
    {
      "x": -1,
      "y": 5,
      "z": 7,
      "name": "Furniture_Crude_Platform",
      "rotation": 2
    },
    {
      "x": -1,
      "y": 6,
      "z": 7,
      "name": "Rock_Stone_Cobble_Roof",
      "rotation": 3
    },
    {
      "x": -1,
      "y": 7,
      "z": 7,
      "name": "Wood_Deadwood_Planks_Half",
      "rotation": 4
    },
    {
      "x": -1,
      "y": 8,
      "z": 7,
      "name": "Wood_Deadwood_Stairs",
      "rotation": 10
    },
    {
      "x": -1,
      "y": 9,
      "z": 7,
      "name": "Wood_Deadwood_Ornate",
      "rotation": 1
    },
    {
      "x": -1,
      "y": 10,
      "z": 7,
      "name": "Rock_Stone_Cobble_Roof_Shallow",
      "filler": 992
    },
    {
      "x": -1,
      "y": 0,
      "z": 8,
      "name": "Wood_Deadwood_Planks",
      "rotation": 1
    },
    {
      "x": -1,
      "y": 1,
      "z": 8,
      "name": "Plant_Moss_Wall_Green",
      "support": 15
    },
    {
      "x": -1,
      "y": 3,
      "z": 8,
      "name": "*Wood_Deadwood_Stairs_State_Definitions_Corner_Right",
      "rotation": 9
    },
    {
      "x": -1,
      "y": 4,
      "z": 8,
      "name": "Wood_Deadwood_Ornate",
      "rotation": 1
    },
    {
      "x": -1,
      "y": 5,
      "z": 8,
      "name": "Wood_Deadwood_Ornate",
      "rotation": 1
    },
    {
      "x": -1,
      "y": 6,
      "z": 8,
      "name": "*Rock_Stone_Cobble_Roof_State_Definitions_Corner_Left",
      "rotation": 3
    },
    {
      "x": -1,
      "y": 9,
      "z": 8,
      "name": "Plant_Vine_Jungle",
      "support": 15
    },
    {
      "x": -1,
      "y": 10,
      "z": 8,
      "name": "Rock_Stone_Cobble_Roof_Shallow"
    },
    {
      "x": -1,
      "y": 0,
      "z": 9,
      "name": "Wood_Deadwood_Planks",
      "rotation": 1
    },
    {
      "x": -1,
      "y": 5,
      "z": 9,
      "name": "Rock_Stone_Cobble_Roof_Hollow"
    },
    {
      "x": -1,
      "y": 0,
      "z": 10,
      "name": "Wood_Deadwood_Planks",
      "rotation": 1
    },
    {
      "x": 0,
      "y": 0,
      "z": -10,
      "name": "Wood_Deadwood_Planks",
      "rotation": 1
    },
    {
      "x": 0,
      "y": 0,
      "z": -9,
      "name": "Wood_Deadwood_Planks",
      "rotation": 1
    },
    {
      "x": 0,
      "y": 9,
      "z": -9,
      "name": "Plant_Vine_Jungle",
      "support": 15,
      "rotation": 2
    },
    {
      "x": 0,
      "y": 10,
      "z": -9,
      "name": "Rock_Stone_Cobble_Roof_Shallow",
      "rotation": 2
    },
    {
      "x": 0,
      "y": 0,
      "z": -8,
      "name": "Wood_Deadwood_Planks",
      "rotation": 1
    },
    {
      "x": 0,
      "y": 1,
      "z": -8,
      "name": "Wood_Deadwood_Ornate",
      "rotation": 1
    },
    {
      "x": 0,
      "y": 2,
      "z": -8,
      "name": "Furniture_Human_Ruins_Window",
      "rotation": 2
    },
    {
      "x": 0,
      "y": 3,
      "z": -8,
      "name": "Furniture_Human_Ruins_Window",
      "rotation": 2
    },
    {
      "x": 0,
      "y": 4,
      "z": -8,
      "name": "Furniture_Human_Ruins_Window",
      "rotation": 2
    },
    {
      "x": 0,
      "y": 5,
      "z": -8,
      "name": "Wood_Deadwood_Ornate",
      "rotation": 1
    },
    {
      "x": 0,
      "y": 6,
      "z": -8,
      "name": "Wood_Deadwood_Planks_Half",
      "rotation": 6
    },
    {
      "x": 0,
      "y": 7,
      "z": -8,
      "name": "Wood_Deadwood_Planks_Half",
      "rotation": 6
    },
    {
      "x": 0,
      "y": 8,
      "z": -8,
      "name": "Wood_Deadwood_Stairs",
      "rotation": 8
    },
    {
      "x": 0,
      "y": 9,
      "z": -8,
      "name": "Wood_Deadwood_Ornate",
      "rotation": 1
    },
    {
      "x": 0,
      "y": 10,
      "z": -8,
      "name": "Rock_Stone_Cobble_Roof_Shallow",
      "filler": 32,
      "rotation": 2
    },
    {
      "x": 0,
      "y": 0,
      "z": -7,
      "name": "Wood_Deadwood_Planks",
      "rotation": 1
    },
    {
      "x": 0,
      "y": 5,
      "z": -7,
      "name": "Furniture_Crude_Platform",
      "rotation": 2
    },
    {
      "x": 0,
      "y": 11,
      "z": -7,
      "name": "Rock_Stone_Cobble_Roof_Shallow",
      "rotation": 2
    },
    {
      "x": 0,
      "y": 0,
      "z": -6,
      "name": "Wood_Deadwood_Planks",
      "rotation": 1
    },
    {
      "x": 0,
      "y": 5,
      "z": -6,
      "name": "Furniture_Crude_Platform",
      "rotation": 2
    },
    {
      "x": 0,
      "y": 11,
      "z": -6,
      "name": "Rock_Stone_Cobble_Roof_Shallow",
      "filler": 32,
      "rotation": 2
    },
    {
      "x": 0,
      "y": 0,
      "z": -5,
      "name": "Wood_Deadwood_Planks",
      "rotation": 1
    },
    {
      "x": 0,
      "y": 5,
      "z": -5,
      "name": "Furniture_Crude_Platform",
      "rotation": 2
    },
    {
      "x": 0,
      "y": 11,
      "z": -5,
      "name": "Rock_Stone_Cobble_Roof_Shallow",
      "filler": 992
    },
    {
      "x": 0,
      "y": 0,
      "z": -4,
      "name": "Wood_Deadwood_Planks",
      "rotation": 1
    },
    {
      "x": 0,
      "y": 5,
      "z": -4,
      "name": "Furniture_Crude_Platform",
      "rotation": 2
    },
    {
      "x": 0,
      "y": 11,
      "z": -4,
      "name": "Rock_Stone_Cobble_Roof_Shallow"
    },
    {
      "x": 0,
      "y": 0,
      "z": -3,
      "name": "Wood_Deadwood_Planks",
      "rotation": 1
    },
    {
      "x": 0,
      "y": 4,
      "z": -3,
      "name": "Wood_Softwood_Beam",
      "rotation": 5
    },
    {
      "x": 0,
      "y": 5,
      "z": -3,
      "name": "Wood_Deadwood_Ornate",
      "rotation": 1
    },
    {
      "x": 0,
      "y": 6,
      "z": -3,
      "name": "Wood_Deadwood_Planks_Half",
      "rotation": 4
    },
    {
      "x": 0,
      "y": 7,
      "z": -3,
      "name": "Wood_Deadwood_Planks_Half",
      "rotation": 4
    },
    {
      "x": 0,
      "y": 8,
      "z": -3,
      "name": "Wood_Deadwood_Stairs",
      "rotation": 10
    },
    {
      "x": 0,
      "y": 9,
      "z": -3,
      "name": "Wood_Deadwood_Ornate",
      "rotation": 1
    },
    {
      "x": 0,
      "y": 10,
      "z": -3,
      "name": "Rock_Stone_Cobble_Roof_Shallow",
      "filler": 992
    },
    {
      "x": 0,
      "y": 0,
      "z": -2,
      "name": "Wood_Deadwood_Planks",
      "rotation": 1
    },
    {
      "x": 0,
      "y": 6,
      "z": -2,
      "name": "Rock_Stone_Cobble_Roof_Hollow",
      "rotation": 2
    },
    {
      "x": 0,
      "y": 9,
      "z": -2,
      "name": "Plant_Moss_Wall_Green",
      "support": 15
    },
    {
      "x": 0,
      "y": 10,
      "z": -2,
      "name": "Rock_Stone_Cobble_Roof_Shallow"
    },
    {
      "x": 0,
      "y": 0,
      "z": -1,
      "name": "Wood_Deadwood_Planks",
      "rotation": 1
    },
    {
      "x": 0,
      "y": 7,
      "z": -1,
      "name": "Rock_Stone_Cobble_Roof_Steep",
      "rotation": 2
    },
    {
      "x": 0,
      "y": 8,
      "z": -1,
      "name": "Rock_Stone_Cobble_Roof_Steep",
      "filler": 1024,
      "rotation": 2
    },
    {
      "x": 0,
      "y": 0,
      "z": 0,
      "name": "Wood_Deadwood_Planks",
      "rotation": 1
    },
    {
      "x": 0,
      "y": 7,
      "z": 0,
      "name": "Rock_Stone_Cobble_Roof_Steep"
    },
    {
      "x": 0,
      "y": 8,
      "z": 0,
      "name": "Rock_Stone_Cobble_Roof_Steep",
      "filler": 1024
    },
    {
      "x": 0,
      "y": 0,
      "z": 1,
      "name": "Wood_Deadwood_Planks",
      "rotation": 1
    },
    {
      "x": 0,
      "y": 6,
      "z": 1,
      "name": "Rock_Stone_Cobble_Roof_Hollow"
    },
    {
      "x": 0,
      "y": 9,
      "z": 1,
      "name": "Plant_Moss_Wall_Green",
      "support": 15,
      "rotation": 2
    },
    {
      "x": 0,
      "y": 10,
      "z": 1,
      "name": "Rock_Stone_Cobble_Roof_Shallow",
      "rotation": 2
    },
    {
      "x": 0,
      "y": 0,
      "z": 2,
      "name": "Wood_Deadwood_Planks",
      "rotation": 1
    },
    {
      "x": 0,
      "y": 4,
      "z": 2,
      "name": "Wood_Softwood_Beam",
      "rotation": 5
    },
    {
      "x": 0,
      "y": 5,
      "z": 2,
      "name": "Wood_Deadwood_Ornate",
      "rotation": 1
    },
    {
      "x": 0,
      "y": 6,
      "z": 2,
      "name": "Wood_Deadwood_Planks_Half",
      "rotation": 6
    },
    {
      "x": 0,
      "y": 7,
      "z": 2,
      "name": "Wood_Deadwood_Planks_Half",
      "rotation": 6
    },
    {
      "x": 0,
      "y": 8,
      "z": 2,
      "name": "Wood_Deadwood_Stairs",
      "rotation": 8
    },
    {
      "x": 0,
      "y": 9,
      "z": 2,
      "name": "Wood_Deadwood_Ornate",
      "rotation": 1
    },
    {
      "x": 0,
      "y": 10,
      "z": 2,
      "name": "Rock_Stone_Cobble_Roof_Shallow",
      "filler": 32,
      "rotation": 2
    },
    {
      "x": 0,
      "y": 0,
      "z": 3,
      "name": "Wood_Deadwood_Planks",
      "rotation": 1
    },
    {
      "x": 0,
      "y": 5,
      "z": 3,
      "name": "Furniture_Crude_Platform",
      "rotation": 2
    },
    {
      "x": 0,
      "y": 11,
      "z": 3,
      "name": "Rock_Stone_Cobble_Roof_Shallow",
      "rotation": 2
    },
    {
      "x": 0,
      "y": 0,
      "z": 4,
      "name": "Wood_Deadwood_Planks",
      "rotation": 1
    },
    {
      "x": 0,
      "y": 5,
      "z": 4,
      "name": "Furniture_Crude_Platform",
      "rotation": 2
    },
    {
      "x": 0,
      "y": 11,
      "z": 4,
      "name": "Rock_Stone_Cobble_Roof_Shallow",
      "filler": 32,
      "rotation": 2
    },
    {
      "x": 0,
      "y": 0,
      "z": 5,
      "name": "Wood_Deadwood_Planks",
      "rotation": 1
    },
    {
      "x": 0,
      "y": 5,
      "z": 5,
      "name": "Furniture_Crude_Platform",
      "rotation": 2
    },
    {
      "x": 0,
      "y": 11,
      "z": 5,
      "name": "Rock_Stone_Cobble_Roof_Shallow",
      "filler": 992
    },
    {
      "x": 0,
      "y": 0,
      "z": 6,
      "name": "Wood_Deadwood_Planks",
      "rotation": 1
    },
    {
      "x": 0,
      "y": 3,
      "z": 6,
      "name": "Furniture_Crude_Platform",
      "rotation": 2
    },
    {
      "x": 0,
      "y": 5,
      "z": 6,
      "name": "Furniture_Crude_Platform",
      "rotation": 2
    },
    {
      "x": 0,
      "y": 6,
      "z": 6,
      "name": "Wood_Deadwood_Planks_Half",
      "rotation": 6
    },
    {
      "x": 0,
      "y": 7,
      "z": 6,
      "name": "Wood_Deadwood_Planks_Half",
      "rotation": 6
    },
    {
      "x": 0,
      "y": 11,
      "z": 6,
      "name": "Rock_Stone_Cobble_Roof_Shallow"
    },
    {
      "x": 0,
      "y": 0,
      "z": 7,
      "name": "Wood_Deadwood_Planks",
      "rotation": 1
    },
    {
      "x": 0,
      "y": 1,
      "z": 7,
      "name": "Wood_Deadwood_Ornate",
      "rotation": 1
    },
    {
      "x": 0,
      "y": 2,
      "z": 7,
      "name": "Furniture_Human_Ruins_Window",
      "rotation": 2
    },
    {
      "x": 0,
      "y": 3,
      "z": 7,
      "name": "Wood_Deadwood_Ornate",
      "rotation": 1
    },
    {
      "x": 0,
      "y": 5,
      "z": 7,
      "name": "Furniture_Crude_Platform",
      "rotation": 2
    },
    {
      "x": 0,
      "y": 7,
      "z": 7,
      "name": "Rock_Stone_Cobble_Roof_Flat",
      "rotation": 3
    },
    {
      "x": 0,
      "y": 8,
      "z": 7,
      "name": "Wood_Deadwood_Stairs",
      "rotation": 10
    },
    {
      "x": 0,
      "y": 9,
      "z": 7,
      "name": "Wood_Deadwood_Ornate",
      "rotation": 1
    },
    {
      "x": 0,
      "y": 10,
      "z": 7,
      "name": "Rock_Stone_Cobble_Roof_Shallow",
      "filler": 992
    },
    {
      "x": 0,
      "y": 0,
      "z": 8,
      "name": "Wood_Deadwood_Planks",
      "rotation": 1
    },
    {
      "x": 0,
      "y": 1,
      "z": 8,
      "name": "Plant_Vine_Jungle",
      "support": 15
    },
    {
      "x": 0,
      "y": 3,
      "z": 8,
      "name": "Wood_Deadwood_Stairs",
      "rotation": 10
    },
    {
      "x": 0,
      "y": 4,
      "z": 8,
      "name": "Furniture_Human_Ruins_Window",
      "rotation": 2
    },
    {
      "x": 0,
      "y": 5,
      "z": 8,
      "name": "Furniture_Human_Ruins_Window",
      "rotation": 2
    },
    {
      "x": 0,
      "y": 6,
      "z": 8,
      "name": "Rock_Stone_Cobble_Roof"
    },
    {
      "x": 0,
      "y": 9,
      "z": 8,
      "name": "Plant_Moss_Wall_Green",
      "support": 15
    },
    {
      "x": 0,
      "y": 10,
      "z": 8,
      "name": "Rock_Stone_Cobble_Roof_Shallow"
    },
    {
      "x": 0,
      "y": 0,
      "z": 9,
      "name": "Wood_Deadwood_Planks",
      "rotation": 1
    },
    {
      "x": 0,
      "y": 5,
      "z": 9,
      "name": "Rock_Stone_Cobble_Roof_Hollow"
    },
    {
      "x": 0,
      "y": 0,
      "z": 10,
      "name": "Wood_Deadwood_Planks",
      "rotation": 1
    },
    {
      "x": 1,
      "y": 0,
      "z": -10,
      "name": "Wood_Deadwood_Planks",
      "rotation": 1
    },
    {
      "x": 1,
      "y": 7,
      "z": -10,
      "name": "Wood_Beech_Branch_Long",
      "support": 15,
      "rotation": 6
    },
    {
      "x": 1,
      "y": 0,
      "z": -9,
      "name": "Wood_Deadwood_Planks",
      "rotation": 1
    },
    {
      "x": 1,
      "y": 1,
      "z": -9,
      "name": "Furniture_Crude_Ladder",
      "rotation": 2
    },
    {
      "x": 1,
      "y": 2,
      "z": -9,
      "name": "Furniture_Crude_Ladder",
      "rotation": 2
    },
    {
      "x": 1,
      "y": 3,
      "z": -9,
      "name": "Furniture_Crude_Ladder",
      "rotation": 2
    },
    {
      "x": 1,
      "y": 4,
      "z": -9,
      "name": "Furniture_Crude_Ladder",
      "rotation": 2
    },
    {
      "x": 1,
      "y": 7,
      "z": -9,
      "name": "Wood_Beech_Branch_Long",
      "support": 15,
      "rotation": 6
    },
    {
      "x": 1,
      "y": 9,
      "z": -9,
      "name": "Plant_Moss_Wall_Green_Dark",
      "support": 15,
      "rotation": 2
    },
    {
      "x": 1,
      "y": 10,
      "z": -9,
      "name": "Rock_Stone_Cobble_Roof_Shallow",
      "rotation": 2
    },
    {
      "x": 1,
      "y": 0,
      "z": -8,
      "name": "Wood_Deadwood_Planks",
      "rotation": 1
    },
    {
      "x": 1,
      "y": 1,
      "z": -8,
      "name": "Wood_Deadwood_Ornate",
      "rotation": 1
    },
    {
      "x": 1,
      "y": 2,
      "z": -8,
      "name": "Wood_Deadwood_Ornate",
      "rotation": 1
    },
    {
      "x": 1,
      "y": 3,
      "z": -8,
      "name": "Wood_Deadwood_Ornate",
      "rotation": 1
    },
    {
      "x": 1,
      "y": 4,
      "z": -8,
      "name": "Wood_Deadwood_Ornate",
      "rotation": 1
    },
    {
      "x": 1,
      "y": 5,
      "z": -8,
      "name": "Wood_Deadwood_Ornate",
      "rotation": 1
    },
    {
      "x": 1,
      "y": 6,
      "z": -8,
      "name": "Wood_Deadwood_Planks_Half",
      "rotation": 6
    },
    {
      "x": 1,
      "y": 7,
      "z": -8,
      "name": "Wood_Deadwood_Planks_Half",
      "rotation": 6
    },
    {
      "x": 1,
      "y": 8,
      "z": -8,
      "name": "Wood_Deadwood_Stairs",
      "rotation": 8
    },
    {
      "x": 1,
      "y": 9,
      "z": -8,
      "name": "Wood_Deadwood_Ornate",
      "rotation": 1
    },
    {
      "x": 1,
      "y": 10,
      "z": -8,
      "name": "Rock_Stone_Cobble_Roof_Shallow",
      "filler": 32,
      "rotation": 2
    },
    {
      "x": 1,
      "y": 0,
      "z": -7,
      "name": "Wood_Deadwood_Planks",
      "rotation": 1
    },
    {
      "x": 1,
      "y": 5,
      "z": -7,
      "name": "Furniture_Crude_Platform",
      "rotation": 2
    },
    {
      "x": 1,
      "y": 11,
      "z": -7,
      "name": "Rock_Stone_Cobble_Roof_Shallow",
      "rotation": 2
    },
    {
      "x": 1,
      "y": 0,
      "z": -6,
      "name": "Wood_Deadwood_Planks",
      "rotation": 1
    },
    {
      "x": 1,
      "y": 5,
      "z": -6,
      "name": "Furniture_Crude_Platform",
      "rotation": 2
    },
    {
      "x": 1,
      "y": 11,
      "z": -6,
      "name": "Rock_Stone_Cobble_Roof_Shallow",
      "filler": 32,
      "rotation": 2
    },
    {
      "x": 1,
      "y": 0,
      "z": -5,
      "name": "Wood_Deadwood_Planks",
      "rotation": 1
    },
    {
      "x": 1,
      "y": 5,
      "z": -5,
      "name": "Furniture_Crude_Platform",
      "rotation": 2
    },
    {
      "x": 1,
      "y": 11,
      "z": -5,
      "name": "Rock_Stone_Cobble_Roof_Shallow",
      "filler": 992
    },
    {
      "x": 1,
      "y": 0,
      "z": -4,
      "name": "Wood_Deadwood_Planks",
      "rotation": 1
    },
    {
      "x": 1,
      "y": 5,
      "z": -4,
      "name": "Furniture_Crude_Platform",
      "rotation": 2
    },
    {
      "x": 1,
      "y": 11,
      "z": -4,
      "name": "Rock_Stone_Cobble_Roof_Shallow"
    },
    {
      "x": 1,
      "y": 0,
      "z": -3,
      "name": "Wood_Deadwood_Planks",
      "rotation": 1
    },
    {
      "x": 1,
      "y": 4,
      "z": -3,
      "name": "Wood_Softwood_Beam",
      "rotation": 5
    },
    {
      "x": 1,
      "y": 5,
      "z": -3,
      "name": "Wood_Deadwood_Ornate",
      "rotation": 1
    },
    {
      "x": 1,
      "y": 6,
      "z": -3,
      "name": "Wood_Deadwood_Planks_Half",
      "rotation": 4
    },
    {
      "x": 1,
      "y": 7,
      "z": -3,
      "name": "Wood_Deadwood_Planks_Half",
      "rotation": 4
    },
    {
      "x": 1,
      "y": 8,
      "z": -3,
      "name": "Wood_Deadwood_Stairs",
      "rotation": 10
    },
    {
      "x": 1,
      "y": 9,
      "z": -3,
      "name": "Wood_Deadwood_Ornate",
      "rotation": 1
    },
    {
      "x": 1,
      "y": 10,
      "z": -3,
      "name": "Rock_Stone_Cobble_Roof_Shallow",
      "filler": 992
    },
    {
      "x": 1,
      "y": 0,
      "z": -2,
      "name": "Wood_Deadwood_Planks",
      "rotation": 1
    },
    {
      "x": 1,
      "y": 6,
      "z": -2,
      "name": "Rock_Stone_Cobble_Roof_Hollow",
      "rotation": 2
    },
    {
      "x": 1,
      "y": 10,
      "z": -2,
      "name": "Rock_Stone_Cobble_Roof_Shallow"
    },
    {
      "x": 1,
      "y": 0,
      "z": -1,
      "name": "Wood_Deadwood_Planks",
      "rotation": 1
    },
    {
      "x": 1,
      "y": 7,
      "z": -1,
      "name": "Rock_Stone_Cobble_Roof_Steep",
      "rotation": 2
    },
    {
      "x": 1,
      "y": 8,
      "z": -1,
      "name": "Rock_Stone_Cobble_Roof_Steep",
      "filler": 1024,
      "rotation": 2
    },
    {
      "x": 1,
      "y": 0,
      "z": 0,
      "name": "Wood_Deadwood_Planks",
      "rotation": 1
    },
    {
      "x": 1,
      "y": 7,
      "z": 0,
      "name": "Rock_Stone_Cobble_Roof_Steep"
    },
    {
      "x": 1,
      "y": 8,
      "z": 0,
      "name": "Rock_Stone_Cobble_Roof_Steep",
      "filler": 1024
    },
    {
      "x": 1,
      "y": 0,
      "z": 1,
      "name": "Wood_Deadwood_Planks",
      "rotation": 1
    },
    {
      "x": 1,
      "y": 6,
      "z": 1,
      "name": "Rock_Stone_Cobble_Roof_Hollow"
    },
    {
      "x": 1,
      "y": 9,
      "z": 1,
      "name": "Plant_Vine_Jungle",
      "support": 15,
      "rotation": 2
    },
    {
      "x": 1,
      "y": 10,
      "z": 1,
      "name": "Rock_Stone_Cobble_Roof_Shallow",
      "rotation": 2
    },
    {
      "x": 1,
      "y": 0,
      "z": 2,
      "name": "Wood_Deadwood_Planks",
      "rotation": 1
    },
    {
      "x": 1,
      "y": 4,
      "z": 2,
      "name": "Wood_Softwood_Beam",
      "rotation": 5
    },
    {
      "x": 1,
      "y": 5,
      "z": 2,
      "name": "Wood_Deadwood_Ornate",
      "rotation": 1
    },
    {
      "x": 1,
      "y": 6,
      "z": 2,
      "name": "Wood_Deadwood_Planks_Half",
      "rotation": 6
    },
    {
      "x": 1,
      "y": 7,
      "z": 2,
      "name": "Wood_Deadwood_Planks_Half",
      "rotation": 6
    },
    {
      "x": 1,
      "y": 8,
      "z": 2,
      "name": "Wood_Deadwood_Stairs",
      "rotation": 8
    },
    {
      "x": 1,
      "y": 9,
      "z": 2,
      "name": "Wood_Deadwood_Ornate",
      "rotation": 1
    },
    {
      "x": 1,
      "y": 10,
      "z": 2,
      "name": "Rock_Stone_Cobble_Roof_Shallow",
      "filler": 32,
      "rotation": 2
    },
    {
      "x": 1,
      "y": 0,
      "z": 3,
      "name": "Wood_Deadwood_Planks",
      "rotation": 1
    },
    {
      "x": 1,
      "y": 5,
      "z": 3,
      "name": "Furniture_Crude_Platform",
      "rotation": 2
    },
    {
      "x": 1,
      "y": 11,
      "z": 3,
      "name": "Rock_Stone_Cobble_Roof_Shallow",
      "rotation": 2
    },
    {
      "x": 1,
      "y": 0,
      "z": 4,
      "name": "Wood_Deadwood_Planks",
      "rotation": 1
    },
    {
      "x": 1,
      "y": 5,
      "z": 4,
      "name": "Furniture_Crude_Platform",
      "rotation": 2
    },
    {
      "x": 1,
      "y": 11,
      "z": 4,
      "name": "Rock_Stone_Cobble_Roof_Shallow",
      "filler": 32,
      "rotation": 2
    },
    {
      "x": 1,
      "y": 0,
      "z": 5,
      "name": "Wood_Deadwood_Planks",
      "rotation": 1
    },
    {
      "x": 1,
      "y": 5,
      "z": 5,
      "name": "Furniture_Crude_Platform",
      "rotation": 2
    },
    {
      "x": 1,
      "y": 11,
      "z": 5,
      "name": "Rock_Stone_Cobble_Roof_Shallow",
      "filler": 992
    },
    {
      "x": 1,
      "y": 0,
      "z": 6,
      "name": "Wood_Deadwood_Planks",
      "rotation": 1
    },
    {
      "x": 1,
      "y": 3,
      "z": 6,
      "name": "Furniture_Crude_Platform",
      "rotation": 2
    },
    {
      "x": 1,
      "y": 5,
      "z": 6,
      "name": "Furniture_Crude_Platform",
      "rotation": 2
    },
    {
      "x": 1,
      "y": 6,
      "z": 6,
      "name": "Wood_Deadwood_Planks_Half",
      "rotation": 6
    },
    {
      "x": 1,
      "y": 7,
      "z": 6,
      "name": "Wood_Deadwood_Planks_Half",
      "rotation": 6
    },
    {
      "x": 1,
      "y": 11,
      "z": 6,
      "name": "Rock_Stone_Cobble_Roof_Shallow"
    },
    {
      "x": 1,
      "y": 0,
      "z": 7,
      "name": "Wood_Deadwood_Planks",
      "rotation": 1
    },
    {
      "x": 1,
      "y": 1,
      "z": 7,
      "name": "Wood_Deadwood_Ornate",
      "rotation": 1
    },
    {
      "x": 1,
      "y": 2,
      "z": 7,
      "name": "Furniture_Human_Ruins_Window",
      "rotation": 2
    },
    {
      "x": 1,
      "y": 3,
      "z": 7,
      "name": "Wood_Deadwood_Ornate",
      "rotation": 1
    },
    {
      "x": 1,
      "y": 5,
      "z": 7,
      "name": "Furniture_Crude_Platform",
      "rotation": 2
    },
    {
      "x": 1,
      "y": 6,
      "z": 7,
      "name": "Rock_Stone_Cobble_Roof",
      "rotation": 1
    },
    {
      "x": 1,
      "y": 7,
      "z": 7,
      "name": "Wood_Deadwood_Planks_Half",
      "rotation": 4
    },
    {
      "x": 1,
      "y": 8,
      "z": 7,
      "name": "Wood_Deadwood_Stairs",
      "rotation": 10
    },
    {
      "x": 1,
      "y": 9,
      "z": 7,
      "name": "Wood_Deadwood_Ornate",
      "rotation": 1
    },
    {
      "x": 1,
      "y": 10,
      "z": 7,
      "name": "Rock_Stone_Cobble_Roof_Shallow",
      "filler": 992
    },
    {
      "x": 1,
      "y": 0,
      "z": 8,
      "name": "Wood_Deadwood_Planks",
      "rotation": 1
    },
    {
      "x": 1,
      "y": 3,
      "z": 8,
      "name": "*Wood_Deadwood_Stairs_State_Definitions_Corner_Left",
      "rotation": 11
    },
    {
      "x": 1,
      "y": 4,
      "z": 8,
      "name": "Wood_Deadwood_Ornate",
      "rotation": 1
    },
    {
      "x": 1,
      "y": 5,
      "z": 8,
      "name": "Wood_Deadwood_Ornate",
      "rotation": 1
    },
    {
      "x": 1,
      "y": 6,
      "z": 8,
      "name": "*Rock_Stone_Cobble_Roof_State_Definitions_Corner_Left"
    },
    {
      "x": 1,
      "y": 10,
      "z": 8,
      "name": "Rock_Stone_Cobble_Roof_Shallow"
    },
    {
      "x": 1,
      "y": 0,
      "z": 9,
      "name": "Wood_Deadwood_Planks",
      "rotation": 1
    },
    {
      "x": 1,
      "y": 5,
      "z": 9,
      "name": "Rock_Stone_Cobble_Roof_Hollow"
    },
    {
      "x": 1,
      "y": 0,
      "z": 10,
      "name": "Wood_Deadwood_Planks",
      "rotation": 1
    },
    {
      "x": 2,
      "y": 0,
      "z": -10,
      "name": "Wood_Deadwood_Planks",
      "rotation": 1
    },
    {
      "x": 2,
      "y": 0,
      "z": -9,
      "name": "Wood_Deadwood_Planks",
      "rotation": 1
    },
    {
      "x": 2,
      "y": 4,
      "z": -9,
      "name": "Plant_Moss_Wall_Green",
      "support": 15,
      "rotation": 2
    },
    {
      "x": 2,
      "y": 5,
      "z": -9,
      "name": "Plant_Moss_Wall_Green",
      "support": 15,
      "rotation": 2
    },
    {
      "x": 2,
      "y": 9,
      "z": -9,
      "name": "Plant_Vine_Jungle",
      "support": 15,
      "rotation": 2
    },
    {
      "x": 2,
      "y": 10,
      "z": -9,
      "name": "Rock_Stone_Cobble_Roof_Shallow",
      "rotation": 2
    },
    {
      "x": 2,
      "y": 0,
      "z": -8,
      "name": "Wood_Deadwood_Planks",
      "rotation": 1
    },
    {
      "x": 2,
      "y": 1,
      "z": -8,
      "name": "Wood_Deadwood_Ornate",
      "rotation": 1
    },
    {
      "x": 2,
      "y": 2,
      "z": -8,
      "name": "Wood_Deadwood_Ornate",
      "rotation": 1
    },
    {
      "x": 2,
      "y": 3,
      "z": -8,
      "name": "Wood_Deadwood_Ornate",
      "rotation": 1
    },
    {
      "x": 2,
      "y": 4,
      "z": -8,
      "name": "Wood_Deadwood_Ornate",
      "rotation": 1
    },
    {
      "x": 2,
      "y": 5,
      "z": -8,
      "name": "Wood_Deadwood_Ornate",
      "rotation": 1
    },
    {
      "x": 2,
      "y": 6,
      "z": -8,
      "name": "Wood_Deadwood_Planks_Half",
      "rotation": 6
    },
    {
      "x": 2,
      "y": 7,
      "z": -8,
      "name": "Wood_Deadwood_Planks_Half",
      "rotation": 6
    },
    {
      "x": 2,
      "y": 8,
      "z": -8,
      "name": "Wood_Deadwood_Stairs",
      "rotation": 8
    },
    {
      "x": 2,
      "y": 9,
      "z": -8,
      "name": "Wood_Deadwood_Ornate",
      "rotation": 1
    },
    {
      "x": 2,
      "y": 10,
      "z": -8,
      "name": "Rock_Stone_Cobble_Roof_Shallow",
      "filler": 32,
      "rotation": 2
    },
    {
      "x": 2,
      "y": 0,
      "z": -7,
      "name": "Wood_Deadwood_Planks",
      "rotation": 1
    },
    {
      "x": 2,
      "y": 5,
      "z": -7,
      "name": "Furniture_Crude_Platform",
      "rotation": 2
    },
    {
      "x": 2,
      "y": 11,
      "z": -7,
      "name": "Rock_Stone_Cobble_Roof_Shallow",
      "rotation": 2
    },
    {
      "x": 2,
      "y": 0,
      "z": -6,
      "name": "Wood_Deadwood_Planks",
      "rotation": 1
    },
    {
      "x": 2,
      "y": 5,
      "z": -6,
      "name": "Furniture_Crude_Platform",
      "rotation": 2
    },
    {
      "x": 2,
      "y": 11,
      "z": -6,
      "name": "Rock_Stone_Cobble_Roof_Shallow",
      "filler": 32,
      "rotation": 2
    },
    {
      "x": 2,
      "y": 0,
      "z": -5,
      "name": "Wood_Deadwood_Planks",
      "rotation": 1
    },
    {
      "x": 2,
      "y": 5,
      "z": -5,
      "name": "Furniture_Crude_Platform",
      "rotation": 2
    },
    {
      "x": 2,
      "y": 11,
      "z": -5,
      "name": "Rock_Stone_Cobble_Roof_Shallow",
      "filler": 992
    },
    {
      "x": 2,
      "y": 0,
      "z": -4,
      "name": "Wood_Deadwood_Planks",
      "rotation": 1
    },
    {
      "x": 2,
      "y": 5,
      "z": -4,
      "name": "Furniture_Crude_Platform",
      "rotation": 2
    },
    {
      "x": 2,
      "y": 11,
      "z": -4,
      "name": "Rock_Stone_Cobble_Roof_Shallow"
    },
    {
      "x": 2,
      "y": 0,
      "z": -3,
      "name": "Wood_Deadwood_Planks",
      "rotation": 1
    },
    {
      "x": 2,
      "y": 1,
      "z": -3,
      "name": "Wood_Deadwood_Ornate",
      "rotation": 1
    },
    {
      "x": 2,
      "y": 2,
      "z": -3,
      "name": "Wood_Deadwood_Ornate",
      "rotation": 1
    },
    {
      "x": 2,
      "y": 3,
      "z": -3,
      "name": "Wood_Deadwood_Ornate",
      "rotation": 1
    },
    {
      "x": 2,
      "y": 4,
      "z": -3,
      "name": "Wood_Deadwood_Ornate",
      "rotation": 1
    },
    {
      "x": 2,
      "y": 5,
      "z": -3,
      "name": "Wood_Deadwood_Ornate",
      "rotation": 1
    },
    {
      "x": 2,
      "y": 6,
      "z": -3,
      "name": "Wood_Deadwood_Planks_Half",
      "rotation": 4
    },
    {
      "x": 2,
      "y": 7,
      "z": -3,
      "name": "Wood_Deadwood_Planks_Half",
      "rotation": 4
    },
    {
      "x": 2,
      "y": 8,
      "z": -3,
      "name": "Wood_Deadwood_Stairs",
      "rotation": 10
    },
    {
      "x": 2,
      "y": 9,
      "z": -3,
      "name": "Wood_Deadwood_Ornate",
      "rotation": 1
    },
    {
      "x": 2,
      "y": 10,
      "z": -3,
      "name": "Rock_Stone_Cobble_Roof_Shallow",
      "filler": 992
    },
    {
      "x": 2,
      "y": 0,
      "z": -2,
      "name": "Wood_Deadwood_Planks",
      "rotation": 1
    },
    {
      "x": 2,
      "y": 6,
      "z": -2,
      "name": "Rock_Stone_Cobble_Roof_Hollow",
      "rotation": 2
    },
    {
      "x": 2,
      "y": 10,
      "z": -2,
      "name": "Rock_Stone_Cobble_Roof_Shallow"
    },
    {
      "x": 2,
      "y": 0,
      "z": -1,
      "name": "Wood_Deadwood_Planks",
      "rotation": 1
    },
    {
      "x": 2,
      "y": 7,
      "z": -1,
      "name": "Rock_Stone_Cobble_Roof_Steep",
      "rotation": 2
    },
    {
      "x": 2,
      "y": 8,
      "z": -1,
      "name": "Rock_Stone_Cobble_Roof_Steep",
      "filler": 1024,
      "rotation": 2
    },
    {
      "x": 2,
      "y": 0,
      "z": 0,
      "name": "Wood_Deadwood_Planks",
      "rotation": 1
    },
    {
      "x": 2,
      "y": 7,
      "z": 0,
      "name": "Rock_Stone_Cobble_Roof_Steep"
    },
    {
      "x": 2,
      "y": 8,
      "z": 0,
      "name": "Rock_Stone_Cobble_Roof_Steep",
      "filler": 1024
    },
    {
      "x": 2,
      "y": 0,
      "z": 1,
      "name": "Wood_Deadwood_Planks",
      "rotation": 1
    },
    {
      "x": 2,
      "y": 6,
      "z": 1,
      "name": "Rock_Stone_Cobble_Roof_Hollow"
    },
    {
      "x": 2,
      "y": 10,
      "z": 1,
      "name": "Rock_Stone_Cobble_Roof_Shallow",
      "rotation": 2
    },
    {
      "x": 2,
      "y": 0,
      "z": 2,
      "name": "Wood_Deadwood_Planks",
      "rotation": 1
    },
    {
      "x": 2,
      "y": 1,
      "z": 2,
      "name": "Wood_Deadwood_Ornate",
      "rotation": 1
    },
    {
      "x": 2,
      "y": 2,
      "z": 2,
      "name": "Wood_Deadwood_Ornate",
      "rotation": 1
    },
    {
      "x": 2,
      "y": 3,
      "z": 2,
      "name": "Wood_Deadwood_Ornate",
      "rotation": 1
    },
    {
      "x": 2,
      "y": 4,
      "z": 2,
      "name": "Wood_Deadwood_Ornate",
      "rotation": 1
    },
    {
      "x": 2,
      "y": 5,
      "z": 2,
      "name": "Wood_Deadwood_Ornate",
      "rotation": 1
    },
    {
      "x": 2,
      "y": 6,
      "z": 2,
      "name": "Wood_Deadwood_Planks_Half",
      "rotation": 6
    },
    {
      "x": 2,
      "y": 7,
      "z": 2,
      "name": "Wood_Deadwood_Planks_Half",
      "rotation": 6
    },
    {
      "x": 2,
      "y": 8,
      "z": 2,
      "name": "Wood_Deadwood_Stairs",
      "rotation": 8
    },
    {
      "x": 2,
      "y": 9,
      "z": 2,
      "name": "Wood_Deadwood_Ornate",
      "rotation": 1
    },
    {
      "x": 2,
      "y": 10,
      "z": 2,
      "name": "Rock_Stone_Cobble_Roof_Shallow",
      "filler": 32,
      "rotation": 2
    },
    {
      "x": 2,
      "y": 0,
      "z": 3,
      "name": "Wood_Deadwood_Planks",
      "rotation": 1
    },
    {
      "x": 2,
      "y": 5,
      "z": 3,
      "name": "Furniture_Crude_Platform",
      "rotation": 2
    },
    {
      "x": 2,
      "y": 11,
      "z": 3,
      "name": "Rock_Stone_Cobble_Roof_Shallow",
      "rotation": 2
    },
    {
      "x": 2,
      "y": 0,
      "z": 4,
      "name": "Wood_Deadwood_Planks",
      "rotation": 1
    },
    {
      "x": 2,
      "y": 5,
      "z": 4,
      "name": "Furniture_Crude_Platform",
      "rotation": 2
    },
    {
      "x": 2,
      "y": 11,
      "z": 4,
      "name": "Rock_Stone_Cobble_Roof_Shallow",
      "filler": 32,
      "rotation": 2
    },
    {
      "x": 2,
      "y": 0,
      "z": 5,
      "name": "Wood_Deadwood_Planks",
      "rotation": 1
    },
    {
      "x": 2,
      "y": 1,
      "z": 5,
      "name": "*Furniture_Human_Ruins_Door_State_Definitions_OpenDoorOut",
      "filler": 31,
      "rotation": 1
    },
    {
      "x": 2,
      "y": 2,
      "z": 5,
      "name": "*Furniture_Human_Ruins_Door_State_Definitions_OpenDoorOut",
      "filler": 1055,
      "rotation": 1
    },
    {
      "x": 2,
      "y": 5,
      "z": 5,
      "name": "Furniture_Crude_Platform",
      "rotation": 2
    },
    {
      "x": 2,
      "y": 11,
      "z": 5,
      "name": "Rock_Stone_Cobble_Roof_Shallow",
      "filler": 992
    },
    {
      "x": 2,
      "y": 0,
      "z": 6,
      "name": "Wood_Deadwood_Planks",
      "rotation": 1
    },
    {
      "x": 2,
      "y": 5,
      "z": 6,
      "name": "Furniture_Crude_Platform",
      "rotation": 2
    },
    {
      "x": 2,
      "y": 11,
      "z": 6,
      "name": "Rock_Stone_Cobble_Roof_Shallow"
    },
    {
      "x": 2,
      "y": 0,
      "z": 7,
      "name": "Wood_Deadwood_Planks",
      "rotation": 1
    },
    {
      "x": 2,
      "y": 1,
      "z": 7,
      "name": "Wood_Deadwood_Ornate",
      "rotation": 1
    },
    {
      "x": 2,
      "y": 2,
      "z": 7,
      "name": "Wood_Deadwood_Ornate",
      "rotation": 1
    },
    {
      "x": 2,
      "y": 3,
      "z": 7,
      "name": "Wood_Deadwood_Ornate",
      "rotation": 1
    },
    {
      "x": 2,
      "y": 4,
      "z": 7,
      "name": "Wood_Deadwood_Ornate",
      "rotation": 1
    },
    {
      "x": 2,
      "y": 5,
      "z": 7,
      "name": "Wood_Deadwood_Ornate",
      "rotation": 1
    },
    {
      "x": 2,
      "y": 6,
      "z": 7,
      "name": "Wood_Deadwood_Planks_Half",
      "rotation": 4
    },
    {
      "x": 2,
      "y": 7,
      "z": 7,
      "name": "Wood_Deadwood_Planks_Half",
      "rotation": 4
    },
    {
      "x": 2,
      "y": 8,
      "z": 7,
      "name": "Wood_Deadwood_Stairs",
      "rotation": 10
    },
    {
      "x": 2,
      "y": 9,
      "z": 7,
      "name": "Wood_Deadwood_Ornate",
      "rotation": 1
    },
    {
      "x": 2,
      "y": 10,
      "z": 7,
      "name": "Rock_Stone_Cobble_Roof_Shallow",
      "filler": 992
    },
    {
      "x": 2,
      "y": 0,
      "z": 8,
      "name": "Wood_Deadwood_Planks",
      "rotation": 1
    },
    {
      "x": 2,
      "y": 1,
      "z": 8,
      "name": "Wood_Beech_Branch_Long",
      "support": 15,
      "rotation": 1
    },
    {
      "x": 2,
      "y": 2,
      "z": 8,
      "name": "Wood_Beech_Branch_Long",
      "support": 15,
      "rotation": 1
    },
    {
      "x": 2,
      "y": 3,
      "z": 8,
      "name": "Wood_Beech_Branch_Long",
      "support": 15,
      "rotation": 1
    },
    {
      "x": 2,
      "y": 4,
      "z": 8,
      "name": "Wood_Beech_Branch_Long",
      "support": 15,
      "rotation": 1
    },
    {
      "x": 2,
      "y": 5,
      "z": 8,
      "name": "Rock_Stone_Cobble_Roof",
      "rotation": 1
    },
    {
      "x": 2,
      "y": 10,
      "z": 8,
      "name": "Rock_Stone_Cobble_Roof_Shallow"
    },
    {
      "x": 2,
      "y": 0,
      "z": 9,
      "name": "Wood_Deadwood_Planks",
      "rotation": 1
    },
    {
      "x": 2,
      "y": 5,
      "z": 9,
      "name": "*Rock_Stone_Cobble_Roof_Hollow_State_Definitions_Corner_Left"
    },
    {
      "x": 2,
      "y": 0,
      "z": 10,
      "name": "Wood_Deadwood_Planks",
      "rotation": 1
    },
    {
      "x": 3,
      "y": 0,
      "z": -10,
      "name": "Wood_Deadwood_Planks",
      "rotation": 1
    },
    {
      "x": 3,
      "y": 0,
      "z": -9,
      "name": "Wood_Deadwood_Planks",
      "rotation": 1
    },
    {
      "x": 3,
      "y": 3,
      "z": -9,
      "name": "Plant_Moss_Wall_Green",
      "support": 15,
      "rotation": 2
    },
    {
      "x": 3,
      "y": 4,
      "z": -9,
      "name": "Plant_Moss_Wall_Green_Dark",
      "support": 15,
      "rotation": 2
    },
    {
      "x": 3,
      "y": 9,
      "z": -9,
      "name": "Plant_Vine_Jungle",
      "support": 15,
      "rotation": 2
    },
    {
      "x": 3,
      "y": 10,
      "z": -9,
      "name": "Rock_Stone_Cobble_Roof_Shallow",
      "rotation": 2
