{
  "version": 8,
  "blockIdVersion": 11,
  "anchorX": 0,
  "anchorY": 0,
  "anchorZ": 0,
  "blocks": [
    {
      "x": -10,
      "y": 0,
      "z": -14,
      "name": "Soil_Mud_Dry"
    },
    {
      "x": -10,
      "y": 1,
      "z": -14,
      "name": "Soil_Mud_Dry"
    },
    {
      "x": -10,
      "y": 0,
      "z": -13,
      "name": "Soil_Mud_Dry"
    },
    {
      "x": -10,
      "y": 1,
      "z": -13,
      "name": "Soil_Mud_Dry"
    },
    {
      "x": -10,
      "y": 0,
      "z": -12,
      "name": "Soil_Mud_Dry"
    },
    {
      "x": -10,
      "y": 1,
      "z": -12,
      "name": "Soil_Mud_Dry"
    },
    {
      "x": -10,
      "y": 0,
      "z": -11,
      "name": "Soil_Mud_Dry"
    },
    {
      "x": -10,
      "y": 1,
      "z": -11,
      "name": "Soil_Mud_Dry"
    },
    {
      "x": -10,
      "y": 0,
      "z": -10,
      "name": "Soil_Mud_Dry"
    },
    {
      "x": -10,
      "y": 1,
      "z": -10,
      "name": "Soil_Mud_Dry"
    },
    {
      "x": -10,
      "y": 0,
      "z": -9,
      "name": "Soil_Mud_Dry"
    },
    {
      "x": -10,
      "y": 1,
      "z": -9,
      "name": "Soil_Mud_Dry"
    },
    {
      "x": -10,
      "y": 0,
      "z": -8,
      "name": "Soil_Dirt"
    },
    {
      "x": -10,
      "y": 1,
      "z": -8,
      "name": "Soil_Leaves"
    },
    {
      "x": -10,
      "y": 0,
      "z": -7,
      "name": "Soil_Dirt"
    },
    {
      "x": -10,
      "y": 1,
      "z": -7,
      "name": "Soil_Dirt"
    },
    {
      "x": -10,
      "y": 2,
      "z": -7,
      "name": "Soil_Grass"
    },
    {
      "x": -10,
      "y": 0,
      "z": -6,
      "name": "Soil_Dirt"
    },
    {
      "x": -10,
      "y": 1,
      "z": -6,
      "name": "Soil_Dirt"
    },
    {
      "x": -10,
      "y": 2,
      "z": -6,
      "name": "Soil_Grass"
    },
    {
      "x": -10,
      "y": 0,
      "z": -5,
      "name": "Soil_Dirt"
    },
    {
      "x": -10,
      "y": 1,
      "z": -5,
      "name": "Soil_Dirt"
    },
    {
      "x": -10,
      "y": 2,
      "z": -5,
      "name": "Soil_Grass"
    },
    {
      "x": -10,
      "y": 0,
      "z": -4,
      "name": "Soil_Dirt"
    },
    {
      "x": -10,
      "y": 1,
      "z": -4,
      "name": "Soil_Dirt"
    },
    {
      "x": -10,
      "y": 2,
      "z": -4,
      "name": "Soil_Grass"
    },
    {
      "x": -10,
      "y": 0,
      "z": -3,
      "name": "Soil_Dirt"
    },
    {
      "x": -10,
      "y": 1,
      "z": -3,
      "name": "Soil_Dirt"
    },
    {
      "x": -10,
      "y": 2,
      "z": -3,
      "name": "Soil_Grass"
    },
    {
      "x": -10,
      "y": 0,
      "z": -2,
      "name": "Soil_Dirt"
    },
    {
      "x": -10,
      "y": 1,
      "z": -2,
      "name": "Soil_Dirt"
    },
    {
      "x": -10,
      "y": 2,
      "z": -2,
      "name": "Soil_Leaves"
    },
    {
      "x": -10,
      "y": 0,
      "z": -1,
      "name": "Soil_Dirt"
    },
    {
      "x": -10,
      "y": 1,
      "z": -1,
      "name": "Soil_Dirt"
    },
    {
      "x": -10,
      "y": 2,
      "z": -1,
      "name": "Soil_Grass"
    },
    {
      "x": -10,
      "y": 0,
      "z": 0,
      "name": "Soil_Dirt"
    },
    {
      "x": -10,
      "y": 1,
      "z": 0,
      "name": "Soil_Dirt"
    },
    {
      "x": -10,
      "y": 2,
      "z": 0,
      "name": "Soil_Grass"
    },
    {
      "x": -10,
      "y": 0,
      "z": 1,
      "name": "Soil_Dirt"
    },
    {
      "x": -10,
      "y": 1,
      "z": 1,
      "name": "Soil_Dirt"
    },
    {
      "x": -10,
      "y": 2,
      "z": 1,
      "name": "Soil_Grass"
    },
    {
      "x": -10,
      "y": 0,
      "z": 2,
      "name": "Soil_Dirt"
    },
    {
      "x": -10,
      "y": 1,
      "z": 2,
      "name": "Soil_Dirt"
    },
    {
      "x": -10,
      "y": 2,
      "z": 2,
      "name": "Soil_Grass"
    },
    {
      "x": -10,
      "y": 0,
      "z": 3,
      "name": "Soil_Dirt"
    },
    {
      "x": -10,
      "y": 1,
      "z": 3,
      "name": "Soil_Dirt"
    },
    {
      "x": -10,
      "y": 2,
      "z": 3,
      "name": "Soil_Grass"
    },
    {
      "x": -10,
      "y": 0,
      "z": 4,
      "name": "Soil_Dirt"
    },
    {
      "x": -10,
      "y": 1,
      "z": 4,
      "name": "Soil_Dirt"
    },
    {
      "x": -10,
      "y": 2,
      "z": 4,
      "name": "Soil_Grass"
    },
    {
      "x": -10,
      "y": 0,
      "z": 5,
      "name": "Soil_Dirt"
    },
    {
      "x": -10,
      "y": 1,
      "z": 5,
      "name": "Soil_Dirt"
    },
    {
      "x": -10,
      "y": 2,
      "z": 5,
      "name": "Soil_Grass"
    },
    {
      "x": -10,
      "y": 0,
      "z": 6,
      "name": "Soil_Dirt"
    },
    {
      "x": -10,
      "y": 1,
      "z": 6,
      "name": "Soil_Dirt"
    },
    {
      "x": -10,
      "y": 2,
      "z": 6,
      "name": "Soil_Grass"
    },
    {
      "x": -10,
      "y": 0,
      "z": 7,
      "name": "Soil_Dirt"
    },
    {
      "x": -10,
      "y": 1,
      "z": 7,
      "name": "Soil_Dirt"
    },
    {
      "x": -10,
      "y": 2,
      "z": 7,
      "name": "Soil_Leaves"
    },
    {
      "x": -10,
      "y": 0,
      "z": 8,
      "name": "Soil_Dirt"
    },
    {
      "x": -10,
      "y": 1,
      "z": 8,
      "name": "Soil_Dirt"
    },
    {
      "x": -10,
      "y": 2,
      "z": 8,
      "name": "Soil_Grass"
    },
    {
      "x": -10,
      "y": 0,
      "z": 9,
      "name": "Soil_Dirt"
    },
    {
      "x": -10,
      "y": 1,
      "z": 9,
      "name": "Soil_Dirt"
    },
    {
      "x": -10,
      "y": 2,
      "z": 9,
      "name": "Soil_Grass"
    },
    {
      "x": -10,
      "y": 0,
      "z": 10,
      "name": "Soil_Dirt"
    },
    {
      "x": -10,
      "y": 1,
      "z": 10,
      "name": "Soil_Dirt"
    },
    {
      "x": -10,
      "y": 2,
      "z": 10,
      "name": "Soil_Grass"
    },
    {
      "x": -10,
      "y": 0,
      "z": 11,
      "name": "Soil_Dirt"
    },
    {
      "x": -10,
      "y": 1,
      "z": 11,
      "name": "Soil_Dirt"
    },
    {
      "x": -10,
      "y": 2,
      "z": 11,
      "name": "Soil_Grass"
    },
    {
      "x": -10,
      "y": 0,
      "z": 12,
      "name": "Soil_Dirt"
    },
    {
      "x": -10,
      "y": 1,
      "z": 12,
      "name": "Soil_Dirt"
    },
    {
      "x": -10,
      "y": 2,
      "z": 12,
      "name": "Soil_Grass"
    },
    {
      "x": -10,
      "y": 0,
      "z": 13,
      "name": "Soil_Dirt"
    },
    {
      "x": -10,
      "y": 1,
      "z": 13,
      "name": "Soil_Dirt"
    },
    {
      "x": -10,
      "y": 2,
      "z": 13,
      "name": "Soil_Grass"
    },
    {
      "x": -10,
      "y": 3,
      "z": 13,
      "name": "Plant_Grass_Lush_Short"
    },
    {
      "x": -10,
      "y": 0,
      "z": 14,
      "name": "Soil_Dirt"
    },
    {
      "x": -10,
      "y": 1,
      "z": 14,
      "name": "Soil_Dirt"
    },
    {
      "x": -10,
      "y": 2,
      "z": 14,
      "name": "Soil_Grass"
    },
    {
      "x": -10,
      "y": 0,
      "z": 15,
      "name": "Wood_Ash_Trunk",
      "rotation": 1
    },
    {
      "x": -10,
      "y": 1,
      "z": 15,
      "name": "Wood_Ash_Trunk",
      "rotation": 1
    },
    {
      "x": -10,
      "y": 2,
      "z": 15,
      "name": "Soil_Grass"
    },
    {
      "x": -9,
      "y": 0,
      "z": -14,
      "name": "Soil_Leaves"
    },
    {
      "x": -9,
      "y": 1,
      "z": -14,
      "name": "Plant_Moss_Rug_Green"
    },
    {
      "x": -9,
      "y": 0,
      "z": -13,
      "name": "Soil_Mud_Dry"
    },
    {
      "x": -9,
      "y": 1,
      "z": -13,
      "name": "Soil_Mud_Dry"
    },
    {
      "x": -9,
      "y": 0,
      "z": -12,
      "name": "Soil_Mud_Dry"
    },
    {
      "x": -9,
      "y": 1,
      "z": -12,
      "name": "Soil_Mud_Dry"
    },
    {
      "x": -9,
      "y": 0,
      "z": -11,
      "name": "Soil_Mud_Dry"
    },
    {
      "x": -9,
      "y": 1,
      "z": -11,
      "name": "Soil_Mud_Dry"
    },
    {
      "x": -9,
      "y": 0,
      "z": -10,
      "name": "Soil_Mud_Dry"
    },
    {
      "x": -9,
      "y": 1,
      "z": -10,
      "name": "Soil_Mud_Dry"
    },
    {
      "x": -9,
      "y": 0,
      "z": -9,
      "name": "Soil_Mud_Dry"
    },
    {
      "x": -9,
      "y": 1,
      "z": -9,
      "name": "Soil_Ash"
    },
    {
      "x": -9,
      "y": 0,
      "z": -8,
      "name": "Soil_Mud_Dry"
    },
    {
      "x": -9,
      "y": 1,
      "z": -8,
      "name": "Soil_Ash"
    },
    {
      "x": -9,
      "y": 0,
      "z": -7,
      "name": "Soil_Dirt"
    },
    {
      "x": -9,
      "y": 1,
      "z": -7,
      "name": "Soil_Dirt"
    },
    {
      "x": -9,
      "y": 2,
      "z": -7,
      "name": "Soil_Grass"
    },
    {
      "x": -9,
      "y": 0,
      "z": -6,
      "name": "Soil_Dirt"
    },
    {
      "x": -9,
      "y": 1,
      "z": -6,
      "name": "Soil_Dirt"
    },
    {
      "x": -9,
      "y": 2,
      "z": -6,
      "name": "Soil_Grass"
    },
    {
      "x": -9,
      "y": 3,
      "z": -6,
      "name": "Plant_Grass_Lush_Short"
    },
    {
      "x": -9,
      "y": 0,
      "z": -5,
      "name": "Soil_Dirt"
    },
    {
      "x": -9,
      "y": 1,
      "z": -5,
      "name": "Soil_Dirt"
    },
    {
      "x": -9,
      "y": 2,
      "z": -5,
      "name": "Soil_Grass"
    },
    {
      "x": -9,
      "y": 3,
      "z": -5,
      "name": "Plant_Grass_Lush_Short"
    },
    {
      "x": -9,
      "y": 0,
      "z": -4,
      "name": "Soil_Dirt"
    },
    {
      "x": -9,
      "y": 1,
      "z": -4,
      "name": "Soil_Dirt"
    },
    {
      "x": -9,
      "y": 2,
      "z": -4,
      "name": "Soil_Grass"
    },
    {
      "x": -9,
      "y": 0,
      "z": -3,
      "name": "Soil_Dirt"
    },
    {
      "x": -9,
      "y": 1,
      "z": -3,
      "name": "Soil_Dirt"
    },
    {
      "x": -9,
      "y": 2,
      "z": -3,
      "name": "Soil_Grass"
    },
    {
      "x": -9,
      "y": 0,
      "z": -2,
      "name": "Soil_Dirt"
    },
    {
      "x": -9,
      "y": 1,
      "z": -2,
      "name": "Soil_Dirt"
    },
    {
      "x": -9,
      "y": 2,
      "z": -2,
      "name": "Soil_Leaves"
    },
    {
      "x": -9,
      "y": 3,
      "z": -2,
      "name": "Plant_Leaves_Banyan",
      "support": 15
    },
    {
      "x": -9,
      "y": 0,
      "z": -1,
      "name": "Soil_Dirt"
    },
    {
      "x": -9,
      "y": 1,
      "z": -1,
      "name": "Soil_Dirt"
    },
    {
      "x": -9,
      "y": 2,
      "z": -1,
      "name": "Soil_Leaves"
    },
    {
      "x": -9,
      "y": 3,
      "z": -1,
      "name": "Plant_Seaweed_Dead_Ghostly",
      "support": 15
    },
    {
      "x": -9,
      "y": 4,
      "z": -1,
      "name": "Plant_Seaweed_Dead_Ghostly",
      "filler": 1024
    },
    {
      "x": -9,
      "y": 0,
      "z": 0,
      "name": "Soil_Dirt"
    },
    {
      "x": -9,
      "y": 1,
      "z": 0,
      "name": "Soil_Dirt"
    },
    {
      "x": -9,
      "y": 2,
      "z": 0,
      "name": "Soil_Leaves"
    },
    {
      "x": -9,
      "y": 3,
      "z": 0,
      "name": "Plant_Flower_Tall_Cyan"
    },
    {
      "x": -9,
      "y": 0,
      "z": 1,
      "name": "Soil_Dirt"
    },
    {
      "x": -9,
      "y": 1,
      "z": 1,
      "name": "Soil_Dirt"
    },
    {
      "x": -9,
      "y": 2,
      "z": 1,
      "name": "Soil_Grass"
    },
    {
      "x": -9,
      "y": 3,
      "z": 1,
      "name": "Plant_Seaweed_Winter_Aurora",
      "support": 15
    },
    {
      "x": -9,
      "y": 4,
      "z": 1,
      "name": "Plant_Seaweed_Winter_Aurora",
      "filler": 1024
    },
    {
      "x": -9,
      "y": 0,
      "z": 2,
      "name": "Soil_Dirt"
    },
    {
      "x": -9,
      "y": 1,
      "z": 2,
      "name": "Soil_Dirt"
    },
    {
      "x": -9,
      "y": 2,
      "z": 2,
      "name": "Soil_Grass"
    },
    {
      "x": -9,
      "y": 3,
      "z": 2,
      "name": "Plant_Seaweed_Dead_Eerie",
      "support": 15
    },
    {
      "x": -9,
      "y": 4,
      "z": 2,
      "name": "Plant_Seaweed_Dead_Eerie",
      "filler": 1024
    },
    {
      "x": -9,
      "y": 0,
      "z": 3,
      "name": "Soil_Dirt"
    },
    {
      "x": -9,
      "y": 1,
      "z": 3,
      "name": "Soil_Dirt"
    },
    {
      "x": -9,
      "y": 2,
      "z": 3,
      "name": "Soil_Grass"
    },
    {
      "x": -9,
      "y": 3,
      "z": 3,
      "name": "Plant_Coral_Bush_Poisoned"
    },
    {
      "x": -9,
      "y": 0,
      "z": 4,
      "name": "Soil_Dirt"
    },
    {
      "x": -9,
      "y": 1,
      "z": 4,
      "name": "Soil_Dirt"
    },
    {
      "x": -9,
      "y": 2,
      "z": 4,
      "name": "Soil_Leaves"
    },
    {
      "x": -9,
      "y": 3,
      "z": 4,
      "name": "Wood_Blackwood_Stairs",
      "rotation": 3
    },
    {
      "x": -9,
      "y": 0,
      "z": 5,
      "name": "Soil_Dirt"
    },
    {
      "x": -9,
      "y": 1,
      "z": 5,
      "name": "Soil_Dirt"
    },
    {
      "x": -9,
      "y": 2,
      "z": 5,
      "name": "Soil_Leaves"
    },
    {
      "x": -9,
      "y": 3,
      "z": 5,
      "name": "Plant_Coral_Bush_Poisoned"
    },
    {
      "x": -9,
      "y": 0,
      "z": 6,
      "name": "Soil_Dirt"
    },
    {
      "x": -9,
      "y": 1,
      "z": 6,
      "name": "Soil_Dirt"
    },
    {
      "x": -9,
      "y": 2,
      "z": 6,
      "name": "Soil_Grass"
    },
    {
      "x": -9,
      "y": 3,
      "z": 6,
      "name": "Plant_Leaves_Fig_Blue",
      "support": 15
    },
    {
      "x": -9,
      "y": 0,
      "z": 7,
      "name": "Soil_Dirt"
    },
    {
      "x": -9,
      "y": 1,
      "z": 7,
      "name": "Soil_Dirt"
    },
    {
      "x": -9,
      "y": 2,
      "z": 7,
      "name": "Soil_Leaves"
    },
    {
      "x": -9,
      "y": 3,
      "z": 7,
      "name": "Plant_Seaweed_Winter_Blue",
      "support": 15
    },
    {
      "x": -9,
      "y": 4,
      "z": 7,
      "name": "Plant_Seaweed_Winter_Blue",
      "filler": 1024
    },
    {
      "x": -9,
      "y": 0,
      "z": 8,
      "name": "Soil_Dirt"
    },
    {
      "x": -9,
      "y": 1,
      "z": 8,
      "name": "Soil_Dirt"
    },
    {
      "x": -9,
      "y": 2,
      "z": 8,
      "name": "Soil_Grass"
    },
    {
      "x": -9,
      "y": 3,
      "z": 8,
      "name": "Plant_Flower_Tall_Cyan"
    },
    {
      "x": -9,
      "y": 0,
      "z": 9,
      "name": "Soil_Dirt"
    },
    {
      "x": -9,
      "y": 1,
      "z": 9,
      "name": "Soil_Dirt"
    },
    {
      "x": -9,
      "y": 2,
      "z": 9,
      "name": "Soil_Grass"
    },
    {
      "x": -9,
      "y": 3,
      "z": 9,
      "name": "Plant_Leaves_Poisoned",
      "support": 15
    },
    {
      "x": -9,
      "y": 0,
      "z": 10,
      "name": "Soil_Dirt"
    },
    {
      "x": -9,
      "y": 1,
      "z": 10,
      "name": "Soil_Dirt"
    },
    {
      "x": -9,
      "y": 2,
      "z": 10,
      "name": "Soil_Grass"
    },
    {
      "x": -9,
      "y": 3,
      "z": 10,
      "name": "Plant_Seaweed_Dead_Ghostly",
      "support": 15
    },
    {
      "x": -9,
      "y": 4,
      "z": 10,
      "name": "Plant_Seaweed_Dead_Ghostly",
      "filler": 1024
    },
    {
      "x": -9,
      "y": 0,
      "z": 11,
      "name": "Wood_Ash_Trunk"
    },
    {
      "x": -9,
      "y": 1,
      "z": 11,
      "name": "Wood_Ash_Trunk_Full"
    },
    {
      "x": -9,
      "y": 2,
      "z": 11,
      "name": "Soil_Grass"
    },
    {
      "x": -9,
      "y": 3,
      "z": 11,
      "name": "Plant_Grass_Lush_Short"
    },
    {
      "x": -9,
      "y": 0,
      "z": 12,
      "name": "Soil_Dirt"
    },
    {
      "x": -9,
      "y": 1,
      "z": 12,
      "name": "Wood_Ash_Trunk_Full"
    },
    {
      "x": -9,
      "y": 2,
      "z": 12,
      "name": "Soil_Grass"
    },
    {
      "x": -9,
      "y": 0,
      "z": 13,
      "name": "Soil_Dirt"
    },
    {
      "x": -9,
      "y": 1,
      "z": 13,
      "name": "Soil_Dirt"
    },
    {
      "x": -9,
      "y": 2,
      "z": 13,
      "name": "Soil_Grass"
    },
    {
      "x": -9,
      "y": 0,
      "z": 14,
      "name": "Soil_Dirt"
    },
    {
      "x": -9,
      "y": 1,
      "z": 14,
      "name": "Soil_Dirt"
    },
    {
      "x": -9,
      "y": 2,
      "z": 14,
      "name": "Soil_Grass"
    },
    {
      "x": -9,
      "y": 0,
      "z": 15,
      "name": "Soil_Dirt"
    },
    {
      "x": -9,
      "y": 1,
      "z": 15,
      "name": "Soil_Dirt"
    },
    {
      "x": -9,
      "y": 2,
      "z": 15,
      "name": "Soil_Grass"
    },
    {
      "x": -8,
      "y": 0,
      "z": -14,
      "name": "Soil_Mud_Dry"
    },
    {
      "x": -8,
      "y": 1,
      "z": -14,
      "name": "Plant_Moss_Rug_Green"
    },
    {
      "x": -8,
      "y": 0,
      "z": -13,
      "name": "Soil_Mud_Dry"
    },
    {
      "x": -8,
      "y": 1,
      "z": -13,
      "name": "Soil_Mud_Dry"
    },
    {
      "x": -8,
      "y": 0,
      "z": -12,
      "name": "Soil_Mud_Dry"
    },
    {
      "x": -8,
      "y": 1,
      "z": -12,
      "name": "Soil_Mud_Dry"
    },
    {
      "x": -8,
      "y": 0,
      "z": -11,
      "name": "Soil_Mud_Dry"
    },
    {
      "x": -8,
      "y": 1,
      "z": -11,
      "name": "Soil_Mud_Dry"
    },
    {
      "x": -8,
      "y": 0,
      "z": -10,
      "name": "Soil_Mud_Dry"
    },
    {
      "x": -8,
      "y": 1,
      "z": -10,
      "name": "Soil_Ash"
    },
    {
      "x": -8,
      "y": 0,
      "z": -9,
      "name": "Soil_Mud_Dry"
    },
    {
      "x": -8,
      "y": 1,
      "z": -9,
      "name": "Soil_Ash"
    },
    {
      "x": -8,
      "y": 0,
      "z": -8,
      "name": "Soil_Mud_Dry"
    },
    {
      "x": -8,
      "y": 1,
      "z": -8,
      "name": "Rock_Slate_Cobble"
    },
    {
      "x": -8,
      "y": 0,
      "z": -7,
      "name": "Soil_Mud_Dry"
    },
    {
      "x": -8,
      "y": 1,
      "z": -7,
      "name": "Rock_Slate_Cobble"
    },
    {
      "x": -8,
      "y": 0,
      "z": -6,
      "name": "Soil_Dirt"
    },
    {
      "x": -8,
      "y": 1,
      "z": -6,
      "name": "Soil_Mud_Dry"
    },
    {
      "x": -8,
      "y": 2,
      "z": -6,
      "name": "Soil_Mud_Dry"
    },
    {
      "x": -8,
      "y": 0,
      "z": -5,
      "name": "Soil_Dirt"
    },
    {
      "x": -8,
      "y": 1,
      "z": -5,
      "name": "Soil_Mud_Dry"
    },
    {
      "x": -8,
      "y": 2,
      "z": -5,
      "name": "Soil_Mud_Dry"
    },
    {
      "x": -8,
      "y": 0,
      "z": -4,
      "name": "Soil_Dirt"
    },
    {
      "x": -8,
      "y": 1,
      "z": -4,
      "name": "Soil_Dirt"
    },
    {
      "x": -8,
      "y": 2,
      "z": -4,
      "name": "Soil_Grass"
    },
    {
      "x": -8,
      "y": 0,
      "z": -3,
      "name": "Soil_Dirt"
    },
    {
      "x": -8,
      "y": 1,
      "z": -3,
      "name": "Soil_Dirt"
    },
    {
      "x": -8,
      "y": 2,
      "z": -3,
      "name": "Soil_Grass"
    },
    {
      "x": -8,
      "y": 0,
      "z": -2,
      "name": "Soil_Dirt"
    },
    {
      "x": -8,
      "y": 1,
      "z": -2,
      "name": "Soil_Dirt"
    },
    {
      "x": -8,
      "y": 2,
      "z": -2,
      "name": "Soil_Leaves"
    },
    {
      "x": -8,
      "y": 3,
      "z": -2,
      "name": "Plant_Coral_Bush_Red"
    },
    {
      "x": -8,
      "y": 0,
      "z": -1,
      "name": "Soil_Dirt"
    },
    {
      "x": -8,
      "y": 1,
      "z": -1,
      "name": "Soil_Dirt"
    },
    {
      "x": -8,
      "y": 2,
      "z": -1,
      "name": "Soil_Leaves"
    },
    {
      "x": -8,
      "y": 3,
      "z": -1,
      "name": "Wood_Blackwood_Beam"
    },
    {
      "x": -8,
      "y": 4,
      "z": -1,
      "name": "Wood_Blackwood_Roof_Shallow",
      "rotation": 3
    },
    {
      "x": -8,
      "y": 0,
      "z": 0,
      "name": "Soil_Dirt"
    },
    {
      "x": -8,
      "y": 1,
      "z": 0,
      "name": "Soil_Dirt"
    },
    {
      "x": -8,
      "y": 2,
      "z": 0,
      "name": "Soil_Leaves"
    },
    {
      "x": -8,
      "y": 3,
      "z": 0,
      "name": "Plant_Leaves_Fig_Blue",
      "support": 15
    },
    {
      "x": -8,
      "y": 4,
      "z": 0,
      "name": "Wood_Blackwood_Roof_Shallow",
      "rotation": 3
    },
    {
      "x": -8,
      "y": 0,
      "z": 1,
      "name": "Soil_Dirt"
    },
    {
      "x": -8,
      "y": 1,
      "z": 1,
      "name": "Soil_Dirt"
    },
    {
      "x": -8,
      "y": 2,
      "z": 1,
      "name": "Soil_Leaves"
    },
    {
      "x": -8,
      "y": 3,
      "z": 1,
      "name": "Wood_Blackwood_Beam"
    },
    {
      "x": -8,
      "y": 4,
      "z": 1,
      "name": "Wood_Blackwood_Roof_Shallow",
      "rotation": 3
    },
    {
      "x": -8,
      "y": 0,
      "z": 2,
      "name": "Soil_Dirt"
    },
    {
      "x": -8,
      "y": 1,
      "z": 2,
      "name": "Soil_Dirt"
    },
    {
      "x": -8,
      "y": 2,
      "z": 2,
      "name": "Soil_Leaves"
    },
    {
      "x": -8,
      "y": 3,
      "z": 2,
      "name": "Plant_Coral_Bush_Poisoned"
    },
    {
      "x": -8,
      "y": 4,
      "z": 2,
      "name": "Wood_Blackwood_Roof_Shallow",
      "rotation": 3
    },
    {
      "x": -8,
      "y": 0,
      "z": 3,
      "name": "Soil_Dirt"
    },
    {
      "x": -8,
      "y": 1,
      "z": 3,
      "name": "Soil_Dirt"
    },
    {
      "x": -8,
      "y": 2,
      "z": 3,
      "name": "Soil_Leaves"
    },
    {
      "x": -8,
      "y": 3,
      "z": 3,
      "name": "Wood_Blackwood_Beam"
    },
    {
      "x": -8,
      "y": 4,
      "z": 3,
      "name": "Wood_Blackwood_Roof_Shallow",
      "rotation": 3
    },
    {
      "x": -8,
      "y": 0,
      "z": 4,
      "name": "Soil_Dirt"
    },
    {
      "x": -8,
      "y": 1,
      "z": 4,
      "name": "Soil_Dirt"
    },
    {
      "x": -8,
      "y": 2,
      "z": 4,
      "name": "Soil_Leaves"
    },
    {
      "x": -8,
      "y": 3,
      "z": 4,
      "name": "Wood_Blackwood_Planks"
    },
    {
      "x": -8,
      "y": 4,
      "z": 4,
      "name": "Wood_Blackwood_Stairs",
      "rotation": 3
    },
    {
      "x": -8,
      "y": 5,
      "z": 4,
      "name": "Furniture_Ancient_Ladder",
      "rotation": 3
    },
    {
      "x": -8,
      "y": 6,
      "z": 4,
      "name": "Furniture_Ancient_Ladder",
      "rotation": 3
    },
    {
      "x": -8,
      "y": 7,
      "z": 4,
      "name": "Furniture_Ancient_Ladder",
      "rotation": 3
    },
    {
      "x": -8,
      "y": 8,
      "z": 4,
      "name": "Furniture_Ancient_Ladder",
      "rotation": 3
    },
    {
      "x": -8,
      "y": 9,
      "z": 4,
      "name": "Furniture_Ancient_Ladder",
      "rotation": 3
    },
    {
      "x": -8,
      "y": 10,
      "z": 4,
      "name": "Furniture_Ancient_Ladder",
      "rotation": 3
    },
    {
      "x": -8,
      "y": 0,
      "z": 5,
      "name": "Soil_Dirt"
    },
    {
      "x": -8,
      "y": 1,
      "z": 5,
      "name": "Soil_Dirt"
    },
    {
      "x": -8,
      "y": 2,
      "z": 5,
      "name": "Soil_Grass"
    },
    {
      "x": -8,
      "y": 3,
      "z": 5,
      "name": "Wood_Blackwood_Beam"
    },
    {
      "x": -8,
      "y": 4,
      "z": 5,
      "name": "Wood_Blackwood_Roof_Shallow",
      "rotation": 3
    },
    {
      "x": -8,
      "y": 0,
      "z": 6,
      "name": "Soil_Dirt"
    },
    {
      "x": -8,
      "y": 1,
      "z": 6,
      "name": "Soil_Dirt"
    },
    {
      "x": -8,
      "y": 2,
      "z": 6,
      "name": "Soil_Grass"
    },
    {
      "x": -8,
      "y": 3,
      "z": 6,
      "name": "Plant_Coral_Bush_Poisoned"
    },
    {
      "x": -8,
      "y": 4,
      "z": 6,
      "name": "Wood_Blackwood_Roof_Shallow",
      "rotation": 3
    },
    {
      "x": -8,
      "y": 0,
      "z": 7,
      "name": "Soil_Dirt"
    },
    {
      "x": -8,
      "y": 1,
      "z": 7,
      "name": "Soil_Dirt"
    },
    {
      "x": -8,
      "y": 2,
      "z": 7,
      "name": "Soil_Grass"
    },
    {
      "x": -8,
      "y": 3,
      "z": 7,
      "name": "Wood_Blackwood_Beam"
    },
    {
      "x": -8,
      "y": 4,
      "z": 7,
      "name": "Wood_Blackwood_Roof_Shallow",
      "rotation": 3
    },
    {
      "x": -8,
      "y": 0,
      "z": 8,
      "name": "Soil_Dirt"
    },
    {
      "x": -8,
      "y": 1,
      "z": 8,
      "name": "Soil_Dirt"
    },
    {
      "x": -8,
      "y": 2,
      "z": 8,
      "name": "Soil_Grass"
    },
    {
      "x": -8,
      "y": 3,
      "z": 8,
      "name": "Plant_Leaves_Crystal",
      "support": 15
    },
    {
      "x": -8,
      "y": 4,
      "z": 8,
      "name": "Wood_Blackwood_Roof_Shallow",
      "rotation": 3
    },
    {
      "x": -8,
      "y": 0,
      "z": 9,
      "name": "Soil_Dirt"
    },
    {
      "x": -8,
      "y": 1,
      "z": 9,
      "name": "Soil_Dirt"
    },
    {
      "x": -8,
      "y": 2,
      "z": 9,
      "name": "Soil_Grass"
    },
    {
      "x": -8,
      "y": 3,
      "z": 9,
      "name": "Wood_Blackwood_Beam"
    },
    {
      "x": -8,
      "y": 4,
      "z": 9,
      "name": "Wood_Blackwood_Roof_Shallow",
      "rotation": 3
    },
    {
      "x": -8,
      "y": 0,
      "z": 10,
      "name": "Soil_Dirt"
    },
    {
      "x": -8,
      "y": 1,
      "z": 10,
      "name": "Soil_Dirt"
    },
    {
      "x": -8,
      "y": 2,
      "z": 10,
      "name": "Soil_Grass"
    },
    {
      "x": -8,
      "y": 3,
      "z": 10,
      "name": "Furniture_Tavern_Barrel"
    },
    {
      "x": -8,
      "y": 0,
      "z": 11,
      "name": "Soil_Dirt"
    },
    {
      "x": -8,
      "y": 1,
      "z": 11,
      "name": "Soil_Dirt"
    },
    {
      "x": -8,
      "y": 2,
      "z": 11,
      "name": "Soil_Grass"
    },
    {
      "x": -8,
      "y": 3,
      "z": 11,
      "name": "Deco_Pot_Clay_Broken"
    },
    {
      "x": -8,
      "y": 0,
      "z": 12,
      "name": "Soil_Dirt"
    },
    {
      "x": -8,
      "y": 1,
      "z": 12,
      "name": "Soil_Dirt"
    },
    {
      "x": -8,
      "y": 2,
      "z": 12,
      "name": "Soil_Grass"
    },
    {
      "x": -8,
      "y": 3,
      "z": 12,
      "name": "Plant_Grass_Lush_Tall"
    },
    {
      "x": -8,
      "y": 0,
      "z": 13,
      "name": "Soil_Dirt"
    },
    {
      "x": -8,
      "y": 1,
      "z": 13,
      "name": "Soil_Dirt"
    },
    {
      "x": -8,
      "y": 2,
      "z": 13,
      "name": "Soil_Grass"
    },
    {
      "x": -8,
      "y": 3,
      "z": 13,
      "name": "Plant_Grass_Lush"
    },
    {
      "x": -8,
      "y": 0,
      "z": 14,
      "name": "Soil_Dirt"
    },
    {
      "x": -8,
      "y": 1,
      "z": 14,
      "name": "Soil_Dirt"
    },
    {
      "x": -8,
      "y": 2,
      "z": 14,
      "name": "Soil_Grass"
    },
    {
      "x": -8,
      "y": 0,
      "z": 15,
      "name": "Soil_Dirt"
    },
    {
      "x": -8,
      "y": 1,
      "z": 15,
      "name": "Soil_Dirt"
    },
    {
      "x": -8,
      "y": 2,
      "z": 15,
      "name": "Soil_Grass"
    },
    {
      "x": -7,
      "y": 0,
      "z": -14,
      "name": "Soil_Mud_Dry"
    },
    {
      "x": -7,
      "y": 1,
      "z": -14,
      "name": "Plant_Moss_Rug_Green"
    },
    {
      "x": -7,
      "y": 0,
      "z": -13,
      "name": "Soil_Mud_Dry"
    },
    {
      "x": -7,
      "y": 1,
      "z": -13,
      "name": "Plant_Moss_Rug_Green"
    },
    {
      "x": -7,
      "y": 0,
      "z": -12,
      "name": "Soil_Mud_Dry"
    },
    {
      "x": -7,
      "y": 1,
      "z": -12,
      "name": "Soil_Ash"
    },
    {
      "x": -7,
      "y": 0,
      "z": -11,
      "name": "Soil_Mud_Dry"
    },
    {
      "x": -7,
      "y": 1,
      "z": -11,
      "name": "Rock_Slate_Cobble"
    },
    {
      "x": -7,
      "y": 0,
      "z": -10,
      "name": "Soil_Mud_Dry"
    },
    {
      "x": -7,
      "y": 1,
      "z": -10,
      "name": "Soil_Ash"
    },
    {
      "x": -7,
      "y": 0,
      "z": -9,
      "name": "Soil_Mud_Dry"
    },
    {
      "x": -7,
      "y": 1,
      "z": -9,
      "name": "Rock_Slate_Cobble"
    },
    {
      "x": -7,
      "y": 0,
      "z": -8,
      "name": "Soil_Mud_Dry"
    },
    {
      "x": -7,
      "y": 1,
      "z": -8,
      "name": "Rock_Slate_Cobble"
    },
    {
      "x": -7,
      "y": 0,
      "z": -7,
      "name": "Soil_Mud_Dry"
    },
    {
      "x": -7,
      "y": 1,
      "z": -7,
      "name": "Rock_Slate_Cobble"
    },
    {
      "x": -7,
      "y": 0,
      "z": -6,
      "name": "Soil_Dirt"
    },
    {
      "x": -7,
      "y": 1,
      "z": -6,
      "name": "Soil_Dirt"
    },
    {
      "x": -7,
      "y": 2,
      "z": -6,
      "name": "Soil_Grass"
    },
    {
      "x": -7,
      "y": 3,
      "z": -6,
      "name": "Plant_Grass_Lush_Short"
    },
    {
      "x": -7,
      "y": 0,
      "z": -5,
      "name": "Soil_Dirt"
    },
    {
      "x": -7,
      "y": 1,
      "z": -5,
      "name": "Soil_Mud_Dry"
    },
    {
      "x": -7,
      "y": 2,
      "z": -5,
      "name": "Soil_Mud_Dry"
    },
    {
      "x": -7,
      "y": 0,
      "z": -4,
      "name": "Soil_Dirt"
    },
    {
      "x": -7,
      "y": 1,
      "z": -4,
      "name": "Soil_Mud_Dry"
    },
    {
      "x": -7,
      "y": 2,
      "z": -4,
      "name": "Soil_Mud_Dry"
    },
    {
      "x": -7,
      "y": 0,
      "z": -3,
      "name": "Soil_Dirt"
    },
    {
      "x": -7,
      "y": 1,
      "z": -3,
      "name": "Soil_Dirt"
    },
    {
      "x": -7,
      "y": 2,
      "z": -3,
      "name": "Soil_Leaves"
    },
    {
      "x": -7,
      "y": 3,
      "z": -3,
      "name": "Plant_Crop_Health3",
      "rotation": 1
    },
    {
      "x": -7,
      "y": 4,
      "z": -3,
      "name": "Plant_Crop_Health3",
      "filler": 1024,
      "rotation": 1
    },
    {
      "x": -7,
      "y": 0,
      "z": -2,
      "name": "Soil_Dirt"
    },
    {
      "x": -7,
      "y": 1,
      "z": -2,
      "name": "Soil_Dirt"
    },
    {
      "x": -7,
      "y": 2,
      "z": -2,
      "name": "Soil_Leaves"
    },
    {
      "x": -7,
      "y": 3,
      "z": -2,
      "name": "Plant_Seaweed_Arid_Red",
      "support": 15
    },
    {
      "x": -7,
      "y": 4,
      "z": -2,
      "name": "Plant_Seaweed_Arid_Red",
      "filler": 1024
    },
    {
      "x": -7,
      "y": 0,
      "z": -1,
      "name": "Soil_Dirt"
    },
    {
      "x": -7,
      "y": 1,
      "z": -1,
      "name": "Soil_Dirt"
    },
    {
      "x": -7,
      "y": 2,
      "z": -1,
      "name": "Soil_Leaves"
    },
    {
      "x": -7,
      "y": 3,
      "z": -1,
      "name": "Wood_Blackwood_Planks",
      "rotation": 2
    },
    {
      "x": -7,
      "y": 4,
      "z": -1,
      "name": "Wood_Blackwood_Roof_Shallow",
      "filler": 1,
      "rotation": 3
    },
    {
      "x": -7,
      "y": 0,
      "z": 0,
      "name": "Soil_Dirt"
    },
    {
      "x": -7,
      "y": 1,
      "z": 0,
      "name": "Soil_Dirt"
    },
    {
      "x": -7,
      "y": 2,
      "z": 0,
      "name": "Soil_Leaves"
    },
    {
      "x": -7,
      "y": 3,
      "z": 0,
      "name": "Wood_Blackwood_Planks",
      "rotation": 2
    },
    {
      "x": -7,
      "y": 4,
      "z": 0,
      "name": "Wood_Blackwood_Roof_Shallow",
      "filler": 1,
      "rotation": 3
    },
    {
      "x": -7,
      "y": 5,
      "z": 0,
      "name": "Plant_Crop_Mushroom_Shelve_Green"
    },
    {
      "x": -7,
      "y": 0,
      "z": 1,
      "name": "Soil_Dirt"
    },
    {
      "x": -7,
      "y": 1,
      "z": 1,
      "name": "Soil_Dirt"
    },
    {
      "x": -7,
      "y": 2,
      "z": 1,
      "name": "Soil_Leaves"
    },
    {
      "x": -7,
      "y": 3,
      "z": 1,
      "name": "Wood_Blackwood_Planks",
      "rotation": 2
    },
    {
      "x": -7,
      "y": 4,
      "z": 1,
      "name": "Wood_Blackwood_Roof_Shallow",
      "filler": 1,
      "rotation": 3
    },
    {
      "x": -7,
      "y": 5,
      "z": 1,
      "name": "Furniture_Temple_Dark_Shelf",
      "rotation": 3
    },
    {
      "x": -7,
      "y": 6,
      "z": 1,
      "name": "WinterHoliday_Garland",
      "rotation": 3
    },
    {
      "x": -7,
      "y": 0,
      "z": 2,
      "name": "Soil_Dirt"
    },
    {
      "x": -7,
      "y": 1,
      "z": 2,
      "name": "Soil_Dirt"
    },
    {
      "x": -7,
      "y": 2,
      "z": 2,
      "name": "Soil_Leaves"
    },
    {
      "x": -7,
      "y": 3,
      "z": 2,
      "name": "Wood_Blackwood_Planks",
      "rotation": 2
    },
    {
      "x": -7,
      "y": 4,
      "z": 2,
      "name": "Wood_Blackwood_Roof_Shallow",
      "filler": 1,
      "rotation": 3
    },
    {
      "x": -7,
      "y": 5,
      "z": 2,
      "name": "Furniture_Temple_Dark_Shelf",
      "rotation": 3
    },
    {
      "x": -7,
      "y": 6,
      "z": 2,
      "name": "WinterHoliday_Garland",
      "rotation": 3
    },
    {
      "x": -7,
      "y": 10,
      "z": 2,
      "name": "Wood_Blackwood_Stairs",
      "rotation": 8
    },
    {
      "x": -7,
      "y": 11,
      "z": 2,
      "name": "*Wood_Blackwood_Fence_State_Definitions_Corner",
      "rotation": 1
    },
    {
      "x": -7,
      "y": 0,
      "z": 3,
      "name": "Soil_Dirt"
    },
    {
      "x": -7,
      "y": 1,
      "z": 3,
      "name": "Soil_Dirt"
    },
    {
      "x": -7,
      "y": 2,
      "z": 3,
      "name": "Soil_Leaves"
    },
    {
      "x": -7,
      "y": 3,
      "z": 3,
      "name": "Wood_Blackwood_Planks",
      "rotation": 2
    },
    {
      "x": -7,
      "y": 4,
      "z": 3,
      "name": "Wood_Blackwood_Roof_Shallow",
      "filler": 1,
      "rotation": 3
    },
    {
      "x": -7,
      "y": 5,
      "z": 3,
      "name": "Wood_Blackwood_Beam"
    },
    {
      "x": -7,
      "y": 6,
      "z": 3,
      "name": "Wood_Blackwood_Beam"
    },
    {
      "x": -7,
      "y": 7,
      "z": 3,
      "name": "Wood_Blackwood_Beam"
    },
    {
      "x": -7,
      "y": 8,
      "z": 3,
      "name": "Wood_Blackwood_Beam"
    },
    {
      "x": -7,
      "y": 9,
      "z": 3,
      "name": "Wood_Blackwood_Beam"
    },
    {
      "x": -7,
      "y": 10,
      "z": 3,
      "name": "Wood_Blackwood_Decorative"
    },
    {
      "x": -7,
      "y": 11,
      "z": 3,
      "name": "Wood_Blackwood_Fence",
      "rotation": 1
    },
    {
      "x": -7,
      "y": 0,
      "z": 4,
      "name": "Soil_Dirt"
    },
    {
      "x": -7,
      "y": 1,
      "z": 4,
      "name": "Soil_Dirt"
    },
    {
      "x": -7,
      "y": 2,
      "z": 4,
      "name": "Soil_Leaves"
    },
    {
      "x": -7,
      "y": 3,
      "z": 4,
      "name": "Wood_Blackwood_Planks",
      "rotation": 2
    },
    {
      "x": -7,
      "y": 4,
      "z": 4,
      "name": "Wood_Blackwood_Planks"
    },
    {
      "x": -7,
      "y": 5,
      "z": 4,
      "name": "Wood_Blackwood_Beam"
    },
    {
      "x": -7,
      "y": 6,
      "z": 4,
      "name": "Wood_Blackwood_Beam"
    },
    {
      "x": -7,
      "y": 7,
      "z": 4,
      "name": "Wood_Blackwood_Beam"
    },
    {
      "x": -7,
      "y": 8,
      "z": 4,
      "name": "Wood_Blackwood_Beam"
    },
    {
      "x": -7,
      "y": 9,
      "z": 4,
      "name": "Wood_Blackwood_Beam"
    },
    {
      "x": -7,
      "y": 10,
      "z": 4,
      "name": "Wood_Blackwood_Decorative"
    },
    {
      "x": -7,
      "y": 0,
      "z": 5,
      "name": "Soil_Dirt"
    },
    {
      "x": -7,
      "y": 1,
      "z": 5,
      "name": "Soil_Dirt"
    },
    {
      "x": -7,
      "y": 2,
      "z": 5,
      "name": "Soil_Grass"
    },
    {
      "x": -7,
      "y": 3,
      "z": 5,
      "name": "Wood_Blackwood_Planks",
      "rotation": 2
    },
    {
      "x": -7,
      "y": 4,
      "z": 5,
      "name": "Wood_Blackwood_Roof_Shallow",
      "filler": 1,
      "rotation": 3
    },
    {
      "x": -7,
      "y": 5,
      "z": 5,
      "name": "Wood_Blackwood_Beam"
    },
    {
      "x": -7,
      "y": 6,
      "z": 5,
      "name": "Wood_Blackwood_Beam"
    },
    {
      "x": -7,
      "y": 7,
      "z": 5,
      "name": "Wood_Blackwood_Beam"
    },
    {
      "x": -7,
      "y": 8,
      "z": 5,
      "name": "Wood_Blackwood_Beam"
    },
    {
      "x": -7,
      "y": 9,
      "z": 5,
      "name": "Wood_Blackwood_Beam"
    },
    {
      "x": -7,
      "y": 10,
      "z": 5,
      "name": "Wood_Blackwood_Decorative"
    },
    {
      "x": -7,
      "y": 11,
      "z": 5,
      "name": "Wood_Blackwood_Fence",
      "rotation": 3
    },
    {
      "x": -7,
      "y": 0,
      "z": 6,
      "name": "Soil_Dirt"
    },
    {
      "x": -7,
      "y": 1,
      "z": 6,
      "name": "Soil_Dirt"
    },
    {
      "x": -7,
      "y": 2,
      "z": 6,
      "name": "Soil_Grass"
    },
    {
      "x": -7,
      "y": 3,
      "z": 6,
      "name": "Wood_Blackwood_Planks",
      "rotation": 2
    },
    {
      "x": -7,
      "y": 4,
      "z": 6,
      "name": "Wood_Blackwood_Roof_Shallow",
      "filler": 1,
      "rotation": 3
    },
    {
      "x": -7,
      "y": 5,
      "z": 6,
      "name": "Furniture_Temple_Dark_Shelf",
      "rotation": 3
    },
    {
      "x": -7,
      "y": 6,
      "z": 6,
      "name": "WinterHoliday_Garland",
      "rotation": 3
    },
    {
      "x": -7,
      "y": 10,
      "z": 6,
      "name": "Wood_Blackwood_Stairs",
      "rotation": 10
    },
    {
      "x": -7,
      "y": 11,
      "z": 6,
      "name": "*Wood_Blackwood_Fence_State_Definitions_Corner",
      "rotation": 2
    },
    {
      "x": -7,
      "y": 0,
      "z": 7,
      "name": "Soil_Dirt"
    },
    {
      "x": -7,
      "y": 1,
      "z": 7,
      "name": "Soil_Dirt"
    },
    {
      "x": -7,
      "y": 2,
      "z": 7,
      "name": "Soil_Grass"
    },
    {
      "x": -7,
      "y": 3,
      "z": 7,
      "name": "Wood_Blackwood_Planks",
      "rotation": 2
    },
    {
      "x": -7,
      "y": 4,
      "z": 7,
      "name": "Wood_Blackwood_Roof_Shallow",
      "filler": 1,
      "rotation": 3
    },
    {
      "x": -7,
      "y": 5,
      "z": 7,
      "name": "Furniture_Temple_Dark_Shelf",
      "rotation": 3
    },
    {
      "x": -7,
      "y": 6,
      "z": 7,
      "name": "WinterHoliday_Garland",
      "rotation": 3
    },
    {
      "x": -7,
      "y": 0,
      "z": 8,
      "name": "Soil_Dirt"
    },
    {
      "x": -7,
      "y": 1,
      "z": 8,
      "name": "Soil_Dirt"
    },
    {
      "x": -7,
      "y": 2,
      "z": 8,
      "name": "Soil_Grass"
    },
    {
      "x": -7,
      "y": 3,
      "z": 8,
      "name": "Wood_Blackwood_Planks",
      "rotation": 2
    },
    {
      "x": -7,
      "y": 4,
      "z": 8,
      "name": "Wood_Blackwood_Roof_Shallow",
      "filler": 1,
      "rotation": 3
    },
    {
      "x": -7,
      "y": 5,
      "z": 8,
      "name": "Plant_Crop_Mushroom_Shelve_Yellow"
    },
    {
      "x": -7,
      "y": 0,
      "z": 9,
      "name": "Soil_Dirt"
    },
    {
      "x": -7,
      "y": 1,
      "z": 9,
      "name": "Soil_Dirt"
    },
    {
      "x": -7,
      "y": 2,
      "z": 9,
      "name": "Soil_Grass"
    },
    {
      "x": -7,
      "y": 3,
      "z": 9,
      "name": "Wood_Blackwood_Planks",
      "rotation": 2
    },
    {
      "x": -7,
      "y": 4,
      "z": 9,
      "name": "Wood_Blackwood_Roof_Shallow",
      "filler": 1,
      "rotation": 3
    },
    {
      "x": -7,
      "y": 0,
      "z": 10,
      "name": "Soil_Dirt"
    },
    {
      "x": -7,
      "y": 1,
      "z": 10,
      "name": "Soil_Dirt"
    },
    {
      "x": -7,
      "y": 2,
      "z": 10,
      "name": "Soil_Grass"
    },
    {
      "x": -7,
      "y": 3,
      "z": 10,
      "name": "Furniture_Village_Crate"
    },
    {
      "x": -7,
      "y": 4,
      "z": 10,
      "name": "Furniture_Tavern_Barrel"
    },
    {
      "x": -7,
      "y": 5,
      "z": 10,
      "name": "Plant_Leaves_Banyan",
      "support": 15
    },
    {
      "x": -7,
      "y": 0,
      "z": 11,
      "name": "Soil_Dirt"
    },
    {
      "x": -7,
      "y": 1,
      "z": 11,
      "name": "Soil_Dirt"
    },
    {
      "x": -7,
      "y": 2,
      "z": 11,
      "name": "Soil_Grass"
    },
    {
      "x": -7,
      "y": 3,
      "z": 11,
      "name": "Furniture_Temple_Wind_Pot"
    },
    {
      "x": -7,
      "y": 4,
      "z": 11,
      "name": "Furniture_Temple_Wind_Pot",
      "filler": 1024
    },
    {
      "x": -7,
      "y": 0,
      "z": 12,
      "name": "Soil_Dirt"
    },
    {
      "x": -7,
      "y": 1,
      "z": 12,
      "name": "Soil_Dirt"
    },
    {
      "x": -7,
      "y": 2,
      "z": 12,
      "name": "Soil_Grass"
    },
    {
      "x": -7,
      "y": 3,
      "z": 12,
      "name": "Plant_Grass_Lush"
    },
    {
      "x": -7,
      "y": 0,
      "z": 13,
      "name": "Soil_Dirt"
    },
    {
      "x": -7,
      "y": 1,
      "z": 13,
      "name": "Soil_Dirt"
    },
    {
      "x": -7,
      "y": 2,
      "z": 13,
      "name": "Soil_Grass"
    },
    {
      "x": -7,
      "y": 3,
      "z": 13,
      "name": "Plant_Grass_Lush_Short"
    },
    {
      "x": -7,
      "y": 0,
      "z": 14,
      "name": "Soil_Dirt"
    },
    {
      "x": -7,
      "y": 1,
      "z": 14,
      "name": "Soil_Dirt"
    },
    {
      "x": -7,
      "y": 2,
      "z": 14,
      "name": "Soil_Grass"
    },
    {
      "x": -7,
      "y": 0,
      "z": 15,
      "name": "Soil_Dirt"
    },
    {
      "x": -7,
      "y": 1,
      "z": 15,
      "name": "Soil_Dirt"
    },
    {
      "x": -7,
      "y": 2,
      "z": 15,
      "name": "Soil_Grass"
    },
    {
      "x": -6,
      "y": 0,
      "z": -14,
      "name": "Soil_Mud_Dry"
    },
    {
      "x": -6,
      "y": 1,
      "z": -14,
      "name": "Plant_Moss_Rug_Green"
    },
    {
      "x": -6,
      "y": 0,
      "z": -13,
      "name": "Soil_Mud_Dry"
    },
    {
      "x": -6,
      "y": 1,
      "z": -13,
      "name": "Plant_Moss_Rug_Green"
    },
    {
      "x": -6,
      "y": 0,
      "z": -12,
      "name": "Soil_Mud_Dry"
    },
    {
      "x": -6,
      "y": 1,
      "z": -12,
      "name": "Rock_Slate_Cobble"
    },
    {
      "x": -6,
      "y": 0,
      "z": -11,
      "name": "Soil_Mud_Dry"
    },
    {
      "x": -6,
      "y": 1,
      "z": -11,
      "name": "Rock_Slate_Cobble"
    },
    {
      "x": -6,
      "y": 0,
      "z": -10,
      "name": "Soil_Mud_Dry"
    },
    {
      "x": -6,
      "y": 1,
      "z": -10,
      "name": "Rock_Slate_Cobble"
    },
    {
      "x": -6,
      "y": 0,
      "z": -9,
      "name": "Soil_Mud_Dry"
    },
    {
      "x": -6,
      "y": 1,
      "z": -9,
      "name": "Rock_Slate_Cobble"
    },
    {
      "x": -6,
      "y": 0,
      "z": -8,
      "name": "Soil_Mud_Dry"
    },
    {
      "x": -6,
      "y": 1,
      "z": -8,
      "name": "Rock_Basalt_Cobble"
    },
    {
      "x": -6,
      "y": 0,
      "z": -7,
      "name": "Soil_Mud_Dry"
    },
    {
      "x": -6,
      "y": 1,
      "z": -7,
      "name": "Soil_Mud_Dry"
    },
    {
      "x": -6,
      "y": 2,
      "z": -7,
      "name": "Rock_Basalt_Cobble_Half"
    },
    {
      "x": -6,
      "y": 0,
      "z": -6,
      "name": "Soil_Dirt"
    },
    {
      "x": -6,
      "y": 1,
      "z": -6,
      "name": "Soil_Mud_Dry"
    },
    {
      "x": -6,
      "y": 2,
      "z": -6,
      "name": "Soil_Mud_Dry"
    },
    {
      "x": -6,
      "y": 3,
      "z": -6,
      "name": "Plant_Crop_Mushroom_Flatcap_Green"
    },
    {
      "x": -6,
      "y": 0,
      "z": -5,
      "name": "Soil_Dirt"
    },
    {
      "x": -6,
      "y": 1,
      "z": -5,
      "name": "Soil_Mud_Dry"
    },
    {
      "x": -6,
      "y": 2,
      "z": -5,
      "name": "Soil_Mud_Dry"
    },
    {
      "x": -6,
      "y": 0,
      "z": -4,
      "name": "Soil_Dirt"
    },
    {
      "x": -6,
      "y": 1,
      "z": -4,
      "name": "Soil_Mud_Dry"
    },
    {
      "x": -6,
      "y": 2,
      "z": -4,
      "name": "Soil_Mud_Dry"
    },
    {
      "x": -6,
      "y": 3,
      "z": -4,
      "name": "Plant_Crop_Health2"
    },
    {
      "x": -6,
      "y": 0,
      "z": -3,
      "name": "Soil_Dirt"
    },
    {
      "x": -6,
      "y": 1,
      "z": -3,
      "name": "Soil_Dirt"
    },
    {
      "x": -6,
      "y": 2,
      "z": -3,
      "name": "Soil_Leaves"
    },
    {
      "x": -6,
      "y": 3,
      "z": -3,
      "name": "Plant_Seaweed_Arid_Red",
      "support": 15
    },
    {
      "x": -6,
      "y": 4,
      "z": -3,
      "name": "Plant_Seaweed_Arid_Red",
      "filler": 1024
    },
    {
      "x": -6,
      "y": 0,
      "z": -2,
      "name": "Soil_Dirt"
    },
    {
      "x": -6,
      "y": 1,
      "z": -2,
      "name": "Soil_Dirt"
    },
    {
      "x": -6,
      "y": 2,
      "z": -2,
      "name": "Soil_Leaves"
    },
    {
      "x": -6,
      "y": 3,
      "z": -2,
      "name": "Plant_Leaves_Banyan",
      "support": 15
    },
    {
      "x": -6,
      "y": 4,
      "z": -2,
      "name": "Plant_Leaves_Banyan",
      "support": 15
    },
    {
      "x": -6,
      "y": 0,
      "z": -1,
      "name": "Soil_Dirt"
    },
    {
      "x": -6,
      "y": 1,
      "z": -1,
      "name": "Soil_Dirt"
    },
    {
      "x": -6,
      "y": 2,
      "z": -1,
      "name": "Soil_Leaves"
    },
    {
      "x": -6,
      "y": 3,
      "z": -1,
      "name": "Wood_Blackwood_Planks",
      "rotation": 2
    },
    {
      "x": -6,
      "y": 4,
      "z": -1,
      "name": "Wood_Blackwood_Planks",
      "rotation": 2
    },
    {
      "x": -6,
      "y": 5,
      "z": -1,
      "name": "Wood_Blackwood_Roof_Shallow",
      "rotation": 3
    },
    {
      "x": -6,
      "y": 6,
      "z": -1,
      "name": "Plant_Leaves_Banyan",
      "support": 15
    },
    {
      "x": -6,
      "y": 0,
      "z": 0,
      "name": "Soil_Dirt"
    },
    {
      "x": -6,
      "y": 1,
      "z": 0,
      "name": "Soil_Dirt"
    },
    {
      "x": -6,
      "y": 2,
      "z": 0,
      "name": "Soil_Ash"
    },
    {
      "x": -6,
      "y": 4,
      "z": 0,
      "name": "Plant_Leaves_Crystal",
      "support": 15
    },
    {
      "x": -6,
      "y": 5,
      "z": 0,
      "name": "Wood_Blackwood_Planks"
    },
    {
      "x": -6,
      "y": 6,
      "z": 0,
      "name": "Wood_Blackwood_Roof_Steep",
      "rotation": 2
    },
    {
      "x": -6,
      "y": 7,
      "z": 0,
      "name": "Wood_Blackwood_Roof_Steep",
      "filler": 1024,
      "rotation": 2
    },
    {
      "x": -6,
      "y": 0,
      "z": 1,
      "name": "Soil_Dirt"
    },
    {
      "x": -6,
      "y": 1,
      "z": 1,
      "name": "Soil_Dirt"
    },
    {
      "x": -6,
      "y": 2,
      "z": 1,
      "name": "Soil_Ash"
    },
    {
      "x": -6,
      "y": 4,
      "z": 1,
      "name": "Plant_Fruit_Poison",
      "rotation": 5
    },
    {
      "x": -6,
      "y": 5,
      "z": 1,
      "name": "Wood_Blackwood_Planks"
    },
    {
      "x": -6,
      "y": 6,
      "z": 1,
      "name": "Furniture_Tavern_Window",
      "rotation": 1
    },
    {
      "x": -6,
      "y": 7,
      "z": 1,
      "name": "Furniture_Tavern_Window",
      "rotation": 1
    },
    {
      "x": -6,
      "y": 8,
      "z": 1,
      "name": "Wood_Blackwood_Roof",
      "rotation": 2
    },
    {
      "x": -6,
      "y": 0,
      "z": 2,
      "name": "Soil_Dirt"
    },
    {
      "x": -6,
      "y": 1,
      "z": 2,
      "name": "Soil_Dirt"
    },
    {
      "x": -6,
      "y": 2,
      "z": 2,
      "name": "Soil_Ash"
    },
    {
      "x": -6,
      "y": 3,
      "z": 2,
      "name": "Plant_Leaves_Fig_Blue",
      "support": 15
    },
    {
      "x": -6,
      "y": 4,
      "z": 2,
      "name": "Plant_Leaves_Poisoned",
      "support": 15
    },
    {
      "x": -6,
      "y": 5,
      "z": 2,
      "name": "Wood_Blackwood_Planks"
    },
    {
      "x": -6,
      "y": 6,
      "z": 2,
      "name": "Furniture_Tavern_Window",
      "rotation": 1
    },
    {
      "x": -6,
      "y": 7,
      "z": 2,
      "name": "Furniture_Tavern_Window",
      "rotation": 1
    },
    {
      "x": -6,
      "y": 8,
      "z": 2,
      "name": "Wood_Blackwood_Roof"
    },
    {
      "x": -6,
      "y": 10,
      "z": 2,
      "name": "Wood_Blackwood_Planks_Half",
      "rotation": 8
    },
    {
      "x": -6,
      "y": 11,
      "z": 2,
      "name": "Wood_Blackwood_Fence",
      "rotation": 2
    },
    {
      "x": -6,
      "y": 12,
      "z": 2,
      "name": "Wood_Blackwood_Beam"
    },
    {
      "x": -6,
      "y": 13,
      "z": 2,
      "name": "Wood_Blackwood_Beam"
    },
    {
      "x": -6,
      "y": 14,
      "z": 2,
      "name": "*Wood_Blackwood_Roof_State_Definitions_Corner_Right",
      "rotation": 3
    },
    {
      "x": -6,
      "y": 0,
      "z": 3,
      "name": "Soil_Dirt"
    },
    {
      "x": -6,
      "y": 1,
      "z": 3,
      "name": "Soil_Dirt"
    },
    {
      "x": -6,
      "y": 2,
      "z": 3,
      "name": "Soil_Ash"
    },
    {
      "x": -6,
      "y": 3,
      "z": 3,
      "name": "Plant_Flower_Bushy_Orange"
    },
    {
      "x": -6,
      "y": 4,
      "z": 3,
      "name": "Plant_Fruit_Spiral",
      "rotation": 8
    },
    {
      "x": -6,
      "y": 5,
      "z": 3,
      "name": "Wood_Blackwood_Planks"
    },
    {
      "x": -6,
      "y": 6,
      "z": 3,
      "name": "Wood_Blackwood_Roof_Steep"
    },
    {
      "x": -6,
      "y": 7,
      "z": 3,
      "name": "Wood_Blackwood_Roof_Steep",
      "filler": 1024
    },
    {
      "x": -6,
      "y": 10,
      "z": 3,
      "name": "Wood_Blackwood_Planks_Half",
      "rotation": 8
    },
    {
      "x": -6,
      "y": 14,
      "z": 3,
      "name": "Wood_Blackwood_Roof_Hollow",
      "rotation": 3
    },
    {
      "x": -6,
      "y": 0,
      "z": 4,
      "name": "Soil_Dirt"
    },
    {
      "x": -6,
      "y": 1,
      "z": 4,
      "name": "Soil_Dirt"
    },
    {
      "x": -6,
      "y": 2,
      "z": 4,
      "name": "Soil_Ash"
    },
    {
      "x": -6,
      "y": 3,
      "z": 4,
      "name": "Plant_Flower_Tall_Red"
    },
    {
      "x": -6,
      "y": 5,
      "z": 4,
      "name": "Wood_Blackwood_Roof_Shallow",
      "rotation": 3
    },
    {
      "x": -6,
      "y": 10,
      "z": 4,
      "name": "Wood_Blackwood_Planks_Half",
      "rotation": 8
    },
    {
      "x": -6,
      "y": 11,
      "z": 4,
      "name": "Plant_Moss_Rug_Red",
      "support": 15
    },
    {
      "x": -6,
      "y": 14,
      "z": 4,
      "name": "Wood_Blackwood_Roof_Hollow",
      "rotation": 3
    },
    {
      "x": -6,
      "y": 0,
      "z": 5,
      "name": "Soil_Dirt"
    },
    {
      "x": -6,
      "y": 1,
      "z": 5,
      "name": "Soil_Dirt"
    },
    {
      "x": -6,
      "y": 2,
      "z": 5,
      "name": "Soil_Ash"
    },
    {
      "x": -6,
      "y": 3,
      "z": 5,
      "name": "Plant_Flower_Bushy_Orange"
    },
    {
      "x": -6,
      "y": 4,
      "z": 5,
      "name": "Plant_Fruit_Spiral",
      "rotation": 8
    },
    {
      "x": -6,
      "y": 5,
      "z": 5,
      "name": "Wood_Blackwood_Planks"
    },
    {
      "x": -6,
      "y": 6,
      "z": 5,
      "name": "Wood_Blackwood_Roof_Steep",
      "rotation": 2
    },
    {
      "x": -6,
      "y": 7,
      "z": 5,
      "name": "Wood_Blackwood_Roof_Steep",
      "filler": 1024,
      "rotation": 2
    },
    {
      "x": -6,
      "y": 10,
      "z": 5,
      "name": "Wood_Blackwood_Planks_Half",
      "rotation": 8
    },
    {
      "x": -6,
      "y": 14,
      "z": 5,
      "name": "Wood_Blackwood_Roof_Hollow",
      "rotation": 3
    },
    {
      "x": -6,
      "y": 0,
      "z": 6,
      "name": "Soil_Dirt"
    },
    {
      "x": -6,
      "y": 1,
      "z": 6,
      "name": "Soil_Dirt"
    },
    {
      "x": -6,
      "y": 2,
      "z": 6,
      "name": "Soil_Ash"
    },
    {
      "x": -6,
      "y": 3,
      "z": 6,
      "name": "Plant_Leaves_Fig_Blue",
      "support": 15
    },
    {
      "x": -6,
      "y": 4,
      "z": 6,
      "name": "Plant_Leaves_Poisoned",
      "support": 15
    },
    {
      "x": -6,
      "y": 5,
      "z": 6,
      "name": "Wood_Blackwood_Planks"
    },
    {
      "x": -6,
      "y": 6,
      "z": 6,
      "name": "Furniture_Tavern_Window",
      "rotation": 1
    },
    {
      "x": -6,
      "y": 7,
      "z": 6,
      "name": "Furniture_Tavern_Window",
      "rotation": 1
    },
    {
      "x": -6,
      "y": 8,
      "z": 6,
      "name": "Wood_Blackwood_Roof",
      "rotation": 2
    },
    {
      "x": -6,
      "y": 10,
      "z": 6,
      "name": "Wood_Blackwood_Planks_Half",
      "rotation": 8
    },
    {
      "x": -6,
      "y": 11,
      "z": 6,
      "name": "Wood_Blackwood_Fence"
    },
    {
      "x": -6,
      "y": 12,
      "z": 6,
      "name": "Wood_Blackwood_Beam"
    },
    {
      "x": -6,
      "y": 13,
      "z": 6,
      "name": "Wood_Blackwood_Beam"
    },
    {
      "x": -6,
      "y": 14,
      "z": 6,
      "name": "*Wood_Blackwood_Roof_State_Definitions_Corner_Right"
    },
    {
      "x": -6,
      "y": 0,
      "z": 7,
      "name": "Soil_Dirt"
    },
    {
      "x": -6,
      "y": 1,
      "z": 7,
      "name": "Soil_Dirt"
    },
    {
      "x": -6,
      "y": 2,
      "z": 7,
      "name": "Soil_Ash"
    },
    {
      "x": -6,
      "y": 4,
      "z": 7,
      "name": "Plant_Fruit_Poison",
      "rotation": 5
    },
    {
      "x": -6,
      "y": 5,
      "z": 7,
      "name": "Wood_Blackwood_Planks"
    },
    {
      "x": -6,
      "y": 6,
      "z": 7,
      "name": "Furniture_Tavern_Window",
      "rotation": 1
    },
    {
      "x": -6,
      "y": 7,
      "z": 7,
      "name": "Furniture_Tavern_Window",
      "rotation": 1
    },
    {
      "x": -6,
      "y": 8,
      "z": 7,
      "name": "Wood_Blackwood_Roof"
    },
    {
      "x": -6,
      "y": 0,
      "z": 8,
      "name": "Soil_Dirt"
    },
    {
      "x": -6,
      "y": 1,
      "z": 8,
      "name": "Soil_Dirt"
    },
    {
      "x": -6,
      "y": 2,
      "z": 8,
      "name": "Soil_Ash"
    },
    {
      "x": -6,
      "y": 4,
      "z": 8,
      "name": "Plant_Leaves_Crystal",
      "support": 15
    },
    {
      "x": -6,
      "y": 5,
      "z": 8,
      "name": "Wood_Blackwood_Planks"
    },
    {
      "x": -6,
      "y": 6,
      "z": 8,
      "name": "Wood_Blackwood_Roof_Steep"
    },
    {
      "x": -6,
      "y": 7,
      "z": 8,
      "name": "Wood_Blackwood_Roof_Steep",
      "filler": 1024
    },
    {
      "x": -6,
      "y": 0,
      "z": 9,
      "name": "Soil_Dirt"
    },
    {
      "x": -6,
      "y": 1,
      "z": 9,
      "name": "Soil_Dirt"
    },
    {
      "x": -6,
      "y": 2,
      "z": 9,
      "name": "Soil_Grass"
    },
    {
      "x": -6,
      "y": 3,
      "z": 9,
      "name": "Wood_Blackwood_Planks",
      "rotation": 2
    },
    {
      "x": -6,
      "y": 4,
      "z": 9,
      "name": "Wood_Blackwood_Planks",
      "rotation": 2
    },
    {
      "x": -6,
      "y": 5,
      "z": 9,
      "name": "Wood_Blackwood_Roof_Shallow",
      "rotation": 3
    },
    {
      "x": -6,
      "y": 6,
      "z": 9,
      "name": "Plant_Leaves_Banyan",
      "support": 15
    },
    {
      "x": -6,
      "y": 0,
      "z": 10,
      "name": "Soil_Dirt"
    },
    {
      "x": -6,
      "y": 1,
      "z": 10,
      "name": "Soil_Dirt"
    },
    {
      "x": -6,
      "y": 2,
      "z": 10,
      "name": "Soil_Grass"
    },
    {
      "x": -6,
      "y": 3,
      "z": 10,
      "name": "Plant_Leaves_Banyan",
      "support": 15
    },
    {
      "x": -6,
      "y": 4,
      "z": 10,
      "name": "Furniture_Village_Crate"
    },
    {
      "x": -6,
      "y": 5,
      "z": 10,
      "name": "Tinkering_Target_Dummy"
    },
    {
      "x": -6,
      "y": 6,
      "z": 10,
      "name": "Tinkering_Target_Dummy",
      "filler": 1024
    },
    {
      "x": -6,
      "y": 0,
      "z": 11,
      "name": "Soil_Dirt"
    },
    {
      "x": -6,
      "y": 1,
      "z": 11,
      "name": "Soil_Dirt"
    },
    {
      "x": -6,
      "y": 2,
      "z": 11,
      "name": "Soil_Grass"
    },
    {
      "x": -6,
      "y": 3,
      "z": 11,
      "name": "Furniture_Village_Crate"
    },
    {
      "x": -6,
      "y": 0,
      "z": 12,
      "name": "Soil_Dirt"
    },
    {
      "x": -6,
      "y": 1,
      "z": 12,
      "name": "Soil_Dirt"
    },
    {
      "x": -6,
      "y": 2,
      "z": 12,
      "name": "Soil_Grass"
    },
    {
      "x": -6,
      "y": 3,
      "z": 12,
      "name": "Plant_Flower_Orchid_Cyan"
    },
    {
      "x": -6,
      "y": 0,
      "z": 13,
      "name": "Soil_Dirt"
    },
    {
      "x": -6,
      "y": 1,
      "z": 13,
      "name": "Soil_Dirt"
    },
    {
      "x": -6,
      "y": 2,
      "z": 13,
      "name": "Soil_Grass"
    },
    {
      "x": -6,
      "y": 0,
      "z": 14,
      "name": "Soil_Dirt"
    },
    {
      "x": -6,
      "y": 1,
      "z": 14,
      "name": "Soil_Dirt"
    },
    {
      "x": -6,
      "y": 2,
      "z": 14,
      "name": "Soil_Grass"
    },
    {
      "x": -6,
      "y": 3,
      "z": 14,
      "name": "Plant_Grass_Lush_Tall"
    },
    {
      "x": -6,
      "y": 0,
      "z": 15,
      "name": "Soil_Dirt"
    },
    {
      "x": -6,
      "y": 1,
      "z": 15,
      "name": "Soil_Dirt"
    },
    {
      "x": -6,
      "y": 2,
      "z": 15,
      "name": "Soil_Grass"
    },
    {
      "x": -6,
      "y": 3,
      "z": 15,
      "name": "Plant_Grass_Lush_Short"
    },
    {
      "x": -5,
      "y": 0,
      "z": -14,
      "name": "Soil_Mud_Dry"
    },
    {
      "x": -5,
      "y": 1,
      "z": -14,
      "name": "Plant_Moss_Rug_Green"
    },
    {
      "x": -5,
      "y": 0,
      "z": -13,
      "name": "Soil_Ash"
    },
    {
      "x": -5,
      "y": 0,
      "z": -12,
      "name": "Rock_Slate_Cobble"
    },
    {
      "x": -5,
      "y": 0,
      "z": -11,
      "name": "Soil_Mud_Dry"
    },
    {
      "x": -5,
      "y": 1,
      "z": -11,
      "name": "Rock_Slate_Cobble"
    },
    {
      "x": -5,
      "y": 0,
      "z": -10,
      "name": "Soil_Mud_Dry"
    },
    {
      "x": -5,
      "y": 1,
      "z": -10,
      "name": "Rock_Slate_Cobble"
    },
    {
      "x": -5,
      "y": 0,
      "z": -9,
      "name": "Soil_Mud_Dry"
    },
    {
      "x": -5,
      "y": 1,
      "z": -9,
      "name": "Rock_Basalt_Cobble"
    },
    {
      "x": -5,
      "y": 0,
      "z": -8,
      "name": "Soil_Mud_Dry"
    },
    {
      "x": -5,
      "y": 1,
      "z": -8,
      "name": "Soil_Mud_Dry"
    },
    {
      "x": -5,
      "y": 2,
      "z": -8,
      "name": "Rock_Basalt_Cobble_Half"
    },
    {
      "x": -5,
      "y": 0,
      "z": -7,
      "name": "Soil_Mud_Dry"
    },
    {
      "x": -5,
      "y": 1,
      "z": -7,
      "name": "Soil_Mud_Dry"
    },
    {
      "x": -5,
      "y": 2,
      "z": -7,
      "name": "Rock_Basalt_Cobble_Half"
    },
    {
      "x": -5,
      "y": 0,
      "z": -6,
      "name": "Soil_Dirt"
    },
    {
      "x": -5,
      "y": 1,
      "z": -6,
      "name": "Soil_Mud_Dry"
    },
    {
      "x": -5,
      "y": 2,
      "z": -6,
      "name": "Wood_Blackwood_Planks"
    },
    {
      "x": -5,
      "y": 0,
      "z": -5,
      "name": "Soil_Dirt"
    },
    {
      "x": -5,
      "y": 1,
      "z": -5,
      "name": "Soil_Mud_Dry"
    },
    {
      "x": -5,
      "y": 2,
      "z": -5,
      "name": "Soil_Mud_Dry"
    },
    {
      "x": -5,
      "y": 0,
      "z": -4,
      "name": "Soil_Dirt"
    },
    {
      "x": -5,
      "y": 1,
      "z": -4,
      "name": "Soil_Mud_Dry"
    },
    {
      "x": -5,
      "y": 2,
      "z": -4,
      "name": "Soil_Mud_Dry"
    },
    {
      "x": -5,
      "y": 0,
      "z": -3,
      "name": "Soil_Dirt"
    },
    {
      "x": -5,
      "y": 1,
      "z": -3,
      "name": "Soil_Mud_Dry"
    },
    {
      "x": -5,
      "y": 2,
      "z": -3,
      "name": "Soil_Mud_Dry"
    },
    {
      "x": -5,
      "y": 3,
      "z": -3,
      "name": "Plant_Flower_Tall_Red"
    },
    {
      "x": -5,
      "y": 0,
      "z": -2,
      "name": "Soil_Dirt"
    },
    {
      "x": -5,
      "y": 1,
      "z": -2,
      "name": "Soil_Dirt"
    },
    {
      "x": -5,
      "y": 2,
      "z": -2,
      "name": "Soil_Leaves"
    },
    {
      "x": -5,
      "y": 3,
      "z": -2,
      "name": "Plant_Crop_Mushroom_Flatcap_Green"
    },
    {
      "x": -5,
      "y": 4,
      "z": -2,
      "name": "Plant_Leaves_Banyan",
      "support": 15
    },
    {
      "x": -5,
      "y": 5,
      "z": -2,
      "name": "Plant_Leaves_Banyan",
      "support": 15
    },
    {
      "x": -5,
      "y": 0,
      "z": -1,
      "name": "Soil_Dirt"
    },
    {
      "x": -5,
      "y": 1,
      "z": -1,
      "name": "Soil_Mud_Dry"
    },
    {
      "x": -5,
      "y": 2,
      "z": -1,
      "name": "Soil_Mud_Dry"
    },
    {
      "x": -5,
      "y": 3,
      "z": -1,
      "name": "Wood_Blackwood_Planks",
      "rotation": 2
    },
    {
      "x": -5,
      "y": 4,
      "z": -1,
      "name": "Wood_Blackwood_Planks",
      "rotation": 2
    },
    {
      "x": -5,
      "y": 5,
      "z": -1,
      "name": "Wood_Blackwood_Roof_Shallow",
      "filler": 1,
      "rotation": 3
    },
    {
      "x": -5,
      "y": 6,
      "z": -1,
      "name": "Plant_Leaves_Banyan",
      "support": 15
    },
    {
      "x": -5,
      "y": 7,
      "z": -1,
      "name": "Plant_Leaves_Banyan",
      "support": 15
    },
    {
      "x": -5,
      "y": 0,
      "z": 0,
      "name": "Soil_Dirt"
    },
    {
      "x": -5,
      "y": 1,
      "z": 0,
      "name": "Soil_Dirt"
    },
    {
      "x": -5,
      "y": 2,
      "z": 0,
      "name": "Soil_Ash"
    },
    {
      "x": -5,
      "y": 3,
      "z": 0,
      "name": "Plant_Leaves_Fig_Blue",
      "support": 15
    },
    {
      "x": -5,
      "y": 4,
      "z": 0,
      "name": "Plant_Leaves_Windwillow",
      "support": 15
    },
    {
      "x": -5,
      "y": 5,
      "z": 0,
      "name": "Wood_Blackwood_Planks",
      "rotation": 2
    },
    {
      "x": -5,
      "y": 6,
      "z": 0,
      "name": "Wood_Blackwood_Roof_Steep",
      "rotation": 2
    },
    {
      "x": -5,
      "y": 7,
      "z": 0,
      "name": "Wood_Blackwood_Roof_Steep",
      "filler": 1024,
      "rotation": 2
    },
    {
      "x": -5,
      "y": 0,
      "z": 1,
      "name": "Soil_Dirt"
    },
    {
      "x": -5,
      "y": 1,
      "z": 1,
      "name": "Soil_Dirt"
    },
    {
      "x": -5,
      "y": 2,
      "z": 1,
      "name": "Soil_Ash"
    },
    {
      "x": -5,
      "y": 3,
      "z": 1,
      "name": "Furniture_Royal_Magic_Wardrobe",
      "rotation": 1
    },
    {
      "x": -5,
      "y": 4,
      "z": 1,
      "name": "Furniture_Royal_Magic_Wardrobe",
      "filler": 1024,
      "rotation": 1
    },
    {
      "x": -5,
      "y": 8,
      "z": 1,
      "name": "Wood_Blackwood_Roof_Hollow",
      "rotation": 2
    },
    {
      "x": -5,
      "y": 0,
      "z": 2,
      "name": "Soil_Dirt"
    },
    {
      "x": -5,
      "y": 1,
      "z": 2,
      "name": "Soil_Dirt"
    },
    {
      "x": -5,
      "y": 2,
      "z": 2,
      "name": "Soil_Ash"
    },
    {
      "x": -5,
      "y": 3,
      "z": 2,
      "name": "Furniture_Royal_Magic_Wardrobe",
      "filler": 32,
      "rotation": 1
    },
    {
      "x": -5,
      "y": 4,
      "z": 2,
      "name": "Furniture_Royal_Magic_Wardrobe",
      "filler": 1056,
      "rotation": 1
    },
    {
      "x": -5,
      "y": 8,
      "z": 2,
      "name": "Wood_Blackwood_Roof_Hollow"
    },
    {
      "x": -5,
      "y": 10,
      "z": 2,
      "name": "Wood_Blackwood_Planks_Half",
      "rotation": 8
    },
    {
      "x": -5,
      "y": 11,
      "z": 2,
      "name": "Wood_Blackwood_Fence",
      "rotation": 2
    },
    {
      "x": -5,
      "y": 14,
      "z": 2,
      "name": "Wood_Blackwood_Roof_Hollow",
      "rotation": 2
    },
    {
      "x": -5,
      "y": 0,
      "z": 3,
      "name": "Soil_Dirt"
    },
    {
      "x": -5,
      "y": 1,
      "z": 3,
      "name": "Soil_Dirt"
    },
    {
      "x": -5,
      "y": 2,
      "z": 3,
      "name": "Soil_Ash"
    },
    {
      "x": -5,
      "y": 3,
      "z": 3,
      "name": "Plant_Crop_Mana3"
    },
    {
      "x": -5,
      "y": 4,
      "z": 3,
      "name": "Plant_Crop_Mana3",
      "filler": 1024
    },
    {
      "x": -5,
      "y": 5,
      "z": 3,
      "name": "Wood_Blackwood_Planks",
      "rotation": 2
    },
    {
      "x": -5,
      "y": 6,
      "z": 3,
      "name": "Wood_Blackwood_Roof_Steep"
    },
    {
      "x": -5,
      "y": 7,
      "z": 3,
      "name": "Wood_Blackwood_Roof_Steep",
      "filler": 1024
    },
    {
      "x": -5,
      "y": 10,
      "z": 3,
      "name": "Wood_Blackwood_Planks_Half",
      "rotation": 8
    },
    {
      "x": -5,
      "y": 15,
      "z": 3,
      "name": "*Wood_Blackwood_Roof_Steep_State_Definitions_Corner_Left",
      "rotation": 2
    },
    {
      "x": -5,
      "y": 16,
      "z": 3,
      "name": "*Wood_Blackwood_Roof_Steep_State_Definitions_Corner_Left",
      "filler": 1024,
      "rotation": 2
    },
    {
      "x": -5,
      "y": 0,
      "z": 4,
      "name": "Soil_Dirt"
    },
    {
      "x": -5,
      "y": 1,
      "z": 4,
      "name": "Soil_Dirt"
    },
    {
      "x": -5,
      "y": 2,
      "z": 4,
      "name": "Soil_Ash"
    },
    {
      "x": -5,
      "y": 3,
      "z": 4,
      "name": "Plant_Moss_Rug_Red",
      "support": 15
    },
    {
      "x": -5,
      "y": 5,
      "z": 4,
      "name": "Wood_Blackwood_Roof_Shallow",
      "filler": 1,
      "rotation": 3
    },
    {
      "x": -5,
      "y": 7,
      "z": 4,
      "name": "Plant_Leaves_Banyan",
      "support": 15
    },
    {
      "x": -5,
      "y": 10,
      "z": 4,
      "name": "Wood_Blackwood_Planks_Half",
      "rotation": 8
    },
    {
      "x": -5,
      "y": 15,
      "z": 4,
      "name": "Wood_Blackwood_Roof_Steep",
      "rotation": 3
    },
    {
      "x": -5,
      "y": 16,
      "z": 4,
      "name": "Wood_Blackwood_Roof_Steep",
      "filler": 1024,
      "rotation": 3
    },
    {
      "x": -5,
      "y": 0,
      "z": 5,
      "name": "Soil_Dirt"
    },
    {
      "x": -5,
      "y": 1,
      "z": 5,
      "name": "Soil_Dirt"
    },
    {
      "x": -5,
      "y": 2,
      "z": 5,
      "name": "Soil_Ash"
    },
    {
      "x": -5,
      "y": 3,
      "z": 5,
      "name": "Plant_Crop_Mushroom_Glowing_Orange"
    },
    {
      "x": -5,
      "y": 5,
      "z": 5,
      "name": "Wood_Blackwood_Planks"
    },
    {
      "x": -5,
      "y": 6,
      "z": 5,
      "name": "Wood_Blackwood_Roof_Steep",
      "rotation": 2
    },
    {
      "x": -5,
      "y": 7,
      "z": 5,
      "name": "Wood_Blackwood_Roof_Steep",
      "filler": 1024,
      "rotation": 2
    },
    {
      "x": -5,
      "y": 10,
      "z": 5,
      "name": "Wood_Blackwood_Planks_Half",
      "rotation": 8
    },
    {
      "x": -5,
      "y": 11,
      "z": 5,
      "name": "Plant_Moss_Rug_Red",
      "support": 15
    },
    {
      "x": -5,
      "y": 15,
      "z": 5,
      "name": "*Wood_Blackwood_Roof_Steep_State_Definitions_Corner_Left",
      "rotation": 3
    },
    {
      "x": -5,
      "y": 16,
      "z": 5,
      "name": "*Wood_Blackwood_Roof_Steep_State_Definitions_Corner_Left",
      "filler": 1024,
      "rotation": 3
    },
    {
      "x": -5,
      "y": 0,
      "z": 6,
      "name": "Soil_Dirt"
    },
    {
      "x": -5,
      "y": 1,
      "z": 6,
      "name": "Soil_Dirt"
    },
    {
      "x": -5,
      "y": 2,
      "z": 6,
      "name": "Soil_Ash"
    },
    {
      "x": -5,
      "y": 3,
      "z": 6,
      "name": "Furniture_Royal_Magic_Wardrobe",
      "rotation": 1
    },
    {
      "x": -5,
      "y": 4,
      "z": 6,
      "name": "Furniture_Royal_Magic_Wardrobe",
      "filler": 1024,
      "rotation": 1
    },
    {
      "x": -5,
      "y": 8,
      "z": 6,
      "name": "Wood_Blackwood_Roof_Hollow",
      "rotation": 2
    },
    {
      "x": -5,
      "y": 10,
      "z": 6,
      "name": "Wood_Blackwood_Planks_Half",
      "rotation": 8
    },
    {
      "x": -5,
      "y": 11,
      "z": 6,
      "name": "Wood_Blackwood_Fence"
    },
    {
      "x": -5,
      "y": 14,
      "z": 6,
      "name": "Wood_Blackwood_Roof_Hollow"
    },
    {
      "x": -5,
      "y": 0,
      "z": 7,
      "name": "Soil_Dirt"
    },
    {
      "x": -5,
      "y": 1,
      "z": 7,
      "name": "Soil_Mud_Dry"
    },
    {
      "x": -5,
      "y": 2,
      "z": 7,
      "name": "Soil_Ash"
    },
    {
      "x": -5,
      "y": 3,
      "z": 7,
      "name": "Furniture_Royal_Magic_Wardrobe",
      "filler": 32,
      "rotation": 1
    },
    {
      "x": -5,
      "y": 4,
      "z": 7,
      "name": "Furniture_Royal_Magic_Wardrobe",
      "filler": 1056,
      "rotation": 1
    },
    {
      "x": -5,
      "y": 8,
      "z": 7,
      "name": "Wood_Blackwood_Roof_Hollow"
    },
    {
      "x": -5,
      "y": 0,
      "z": 8,
      "name": "Soil_Dirt"
    },
    {
      "x": -5,
      "y": 1,
      "z": 8,
      "name": "Soil_Mud_Dry"
    },
    {
      "x": -5,
      "y": 2,
      "z": 8,
      "name": "Soil_Ash"
    },
    {
      "x": -5,
      "y": 3,
      "z": 8,
      "name": "Plant_Leaves_Fig_Blue",
      "support": 15
    },
    {
      "x": -5,
      "y": 4,
      "z": 8,
      "name": "Plant_Leaves_Windwillow",
      "support": 15
    },
    {
      "x": -5,
      "y": 5,
      "z": 8,
      "name": "Wood_Blackwood_Planks",
      "rotation": 2
    },
    {
      "x": -5,
      "y": 6,
      "z": 8,
      "name": "Wood_Blackwood_Roof_Steep"
    },
    {
      "x": -5,
      "y": 7,
      "z": 8,
      "name": "Wood_Blackwood_Roof_Steep",
      "filler": 1024
    },
    {
      "x": -5,
      "y": 0,
      "z": 9,
      "name": "Soil_Dirt"
    },
    {
      "x": -5,
      "y": 1,
      "z": 9,
      "name": "Soil_Dirt"
    },
    {
      "x": -5,
      "y": 2,
      "z": 9,
      "name": "Soil_Grass"
    },
    {
      "x": -5,
      "y": 3,
      "z": 9,
      "name": "Wood_Blackwood_Planks",
      "rotation": 2
    },
    {
      "x": -5,
      "y": 4,
      "z": 9,
      "name": "Wood_Blackwood_Planks",
      "rotation": 2
    },
    {
      "x": -5,
      "y": 5,
      "z": 9,
      "name": "Wood_Blackwood_Roof_Shallow",
      "filler": 1,
      "rotation": 3
    },
    {
      "x": -5,
      "y": 6,
      "z": 9,
      "name": "Plant_Leaves_Banyan",
      "support": 15
    },
    {
      "x": -5,
      "y": 7,
      "z": 9,
      "name": "Plant_Leaves_Banyan",
      "support": 15
    },
    {
      "x": -5,
      "y": 0,
      "z": 10,
      "name": "Soil_Dirt"
    },
    {
      "x": -5,
      "y": 1,
      "z": 10,
      "name": "Soil_Dirt"
    },
    {
      "x": -5,
      "y": 2,
      "z": 10,
      "name": "Soil_Grass"
    },
    {
      "x": -5,
      "y": 3,
      "z": 10,
      "name": "Plant_Leaves_Banyan",
      "support": 15
    },
    {
      "x": -5,
      "y": 4,
      "z": 10,
      "name": "Plant_Leaves_Banyan",
      "support": 15
    },
    {
      "x": -5,
      "y": 0,
      "z": 11,
      "name": "Soil_Dirt"
    },
    {
      "x": -5,
      "y": 1,
      "z": 11,
      "name": "Soil_Dirt"
    },
    {
      "x": -5,
      "y": 2,
      "z": 11,
      "name": "Soil_Grass"
    },
    {
      "x": -5,
      "y": 3,
      "z": 11,
      "name": "Plant_Fruit_Poison"
    },
    {
      "x": -5,
      "y": 0,
      "z": 12,
      "name": "Soil_Dirt"
    },
    {
      "x": -5,
      "y": 1,
      "z": 12,
      "name": "Soil_Dirt"
    },
    {
      "x": -5,
      "y": 2,
      "z": 12,
      "name": "Soil_Grass"
    },
    {
      "x": -5,
      "y": 3,
      "z": 12,
      "name": "Plant_Flower_Tall_Red"
    },
    {
      "x": -5,
      "y": 0,
      "z": 13,
      "name": "Wood_Ash_Trunk_Full"
    },
    {
      "x": -5,
      "y": 1,
      "z": 13,
      "name": "Wood_Ash_Trunk"
    },
    {
      "x": -5,
      "y": 2,
      "z": 13,
      "name": "Soil_Grass"
    },
    {
      "x": -5,
      "y": 0,
      "z": 14,
      "name": "Soil_Dirt"
    },
    {
      "x": -5,
      "y": 1,
      "z": 14,
      "name": "Soil_Dirt"
    },
    {
      "x": -5,
      "y": 2,
      "z": 14,
      "name": "Soil_Grass"
    },
    {
      "x": -5,
      "y": 0,
      "z": 15,
      "name": "Soil_Dirt"
    },
    {
      "x": -5,
      "y": 1,
      "z": 15,
      "name": "Soil_Dirt"
    },
    {
      "x": -5,
      "y": 2,
      "z": 15,
      "name": "Soil_Grass"
    },
    {
      "x": -4,
      "y": 0,
      "z": -14,
      "name": "Soil_Mud_Dry"
    },
    {
      "x": -4,
      "y": 1,
      "z": -14,
      "name": "Plant_Moss_Rug_Green"
    },
    {
      "x": -4,
      "y": 0,
      "z": -13,
      "name": "Soil_Ash"
    },
    {
      "x": -4,
      "y": 0,
      "z": -12,
      "name": "Soil_Grass"
    },
    {
      "x": -4,
      "y": 1,
      "z": -12,
      "name": "Rock_Basalt_Cobble_Half"
    },
    {
      "x": -4,
      "y": 0,
      "z": -11,
      "name": "Soil_Mud_Dry"
    },
    {
      "x": -4,
      "y": 1,
      "z": -11,
      "name": "Rock_Slate_Cobble"
    },
    {
      "x": -4,
      "y": 0,
      "z": -10,
      "name": "Soil_Mud_Dry"
    },
    {
      "x": -4,
      "y": 1,
      "z": -10,
      "name": "Rock_Basalt_Cobble"
    },
    {
      "x": -4,
      "y": 0,
      "z": -9,
      "name": "Soil_Mud_Dry"
    },
    {
      "x": -4,
      "y": 1,
      "z": -9,
      "name": "Rock_Basalt_Cobble"
    },
    {
      "x": -4,
      "y": 0,
      "z": -8,
      "name": "Soil_Mud_Dry"
    },
    {
      "x": -4,
      "y": 1,
      "z": -8,
      "name": "Soil_Mud_Dry"
    },
    {
      "x": -4,
      "y": 2,
      "z": -8,
      "name": "Rock_Basalt_Cobble_Half"
    },
    {
      "x": -4,
      "y": 0,
      "z": -7,
      "name": "Soil_Mud_Dry"
    },
    {
      "x": -4,
      "y": 1,
      "z": -7,
      "name": "Soil_Mud_Dry"
    },
    {
      "x": -4,
      "y": 2,
      "z": -7,
      "name": "Rock_Basalt_Cobble_Half"
    },
    {
      "x": -4,
      "y": 0,
      "z": -6,
      "name": "Soil_Dirt"
    },
    {
      "x": -4,
      "y": 1,
      "z": -6,
      "name": "Soil_Mud_Dry"
    },
    {
      "x": -4,
      "y": 2,
      "z": -6,
      "name": "Wood_Blackwood_Planks"
    },
    {
      "x": -4,
      "y": 0,
      "z": -5,
      "name": "Soil_Dirt"
    },
    {
      "x": -4,
      "y": 1,
      "z": -5,
      "name": "Soil_Mud_Dry"
    },
    {
      "x": -4,
      "y": 2,
      "z": -5,
      "name": "Wood_Blackwood_Planks"
    },
    {
      "x": -4,
      "y": 3,
      "z": -5,
      "name": "Wood_Blackwood_Planks_Half"
    },
    {
      "x": -4,
      "y": 0,
      "z": -4,
      "name": "Soil_Dirt"
    },
    {
      "x": -4,
      "y": 1,
      "z": -4,
      "name": "Soil_Dirt"
    },
    {
      "x": -4,
      "y": 2,
      "z": -4,
      "name": "Soil_Grass"
    },
    {
      "x": -4,
      "y": 3,
      "z": -4,
      "name": "Wood_Blackwood_Decorative"
    },
    {
      "x": -4,
      "y": 0,
      "z": -3,
      "name": "Soil_Dirt"
    },
    {
      "x": -4,
      "y": 1,
      "z": -3,
      "name": "Soil_Dirt"
    },
    {
      "x": -4,
      "y": 2,
      "z": -3,
      "name": "Soil_Grass"
    },
    {
      "x": -4,
      "y": 3,
      "z": -3,
      "name": "Wood_Blackwood_Decorative"
    },
    {
      "x": -4,
      "y": 4,
      "z": -3,
      "name": "Wood_Blackwood_Roof",
      "rotation": 3
    },
    {
      "x": -4,
      "y": 0,
      "z": -2,
      "name": "Soil_Dirt"
    },
    {
      "x": -4,
      "y": 1,
      "z": -2,
      "name": "Soil_Dirt"
    },
    {
      "x": -4,
      "y": 2,
      "z": -2,
      "name": "Soil_Leaves"
    },
    {
      "x": -4,
      "y": 3,
      "z": -2,
      "name": "Wood_Blackwood_Planks"
    },
    {
      "x": -4,
      "y": 4,
      "z": -2,
      "name": "Wood_Blackwood_Roof",
      "rotation": 3
    },
    {
      "x": -4,
      "y": 0,
      "z": -1,
      "name": "Soil_Dirt"
    },
    {
      "x": -4,
      "y": 1,
      "z": -1,
      "name": "Soil_Mud_Dry"
    },
    {
      "x": -4,
      "y": 2,
      "z": -1,
      "name": "Soil_Mud_Dry"
    },
    {
      "x": -4,
      "y": 3,
      "z": -1,
      "name": "Wood_Blackwood_Planks"
    },
    {
      "x": -4,
      "y": 4,
      "z": -1,
      "name": "Wood_Blackwood_Planks"
    },
    {
      "x": -4,
      "y": 5,
      "z": -1,
      "name": "Wood_Blackwood_Decorative"
    },
    {
      "x": -4,
      "y": 6,
      "z": -1,
      "name": "Wood_Blackwood_Roof_Steep",
      "rotation": 3
    },
    {
      "x": -4,
      "y": 7,
      "z": -1,
      "name": "Wood_Blackwood_Roof_Steep",
      "filler": 1024,
      "rotation": 3
    },
    {
      "x": -4,
      "y": 8,
      "z": -1,
      "name": "Plant_Leaves_Banyan",
      "support": 15
    },
    {
      "x": -4,
      "y": 0,
      "z": 0,
      "name": "Soil_Dirt"
    },
    {
      "x": -4,
      "y": 1,
      "z": 0,
      "name": "Soil_Mud_Dry"
    },
    {
      "x": -4,
      "y": 2,
      "z": 0,
      "name": "Soil_Ash"
    },
    {
      "x": -4,
      "y": 3,
      "z": 0,
      "name": "Plant_Flower_Tall_Cyan"
    },
    {
      "x": -4,
      "y": 5,
      "z": 0,
      "name": "Wood_Blackwood_Stairs",
      "rotation": 11
    },
    {
      "x": -4,
      "y": 6,
      "z": 0,
      "name": "*Wood_Blackwood_Roof_Steep_State_Definitions_Inverted_Corner_Left",
      "rotation": 2
    },
    {
      "x": -4,
      "y": 7,
      "z": 0,
      "name": "*Wood_Blackwood_Roof_Steep_State_Definitions_Inverted_Corner_Left",
      "filler": 1024,
      "rotation": 2
    },
    {
      "x": -4,
      "y": 8,
      "z": 0,
      "name": "Plant_Leaves_Banyan",
      "support": 15
    },
    {
      "x": -4,
      "y": 0,
      "z": 1,
      "name": "Soil_Dirt"
    },
    {
      "x": -4,
      "y": 1,
      "z": 1,
      "name": "Soil_Mud_Dry"
    },
    {
      "x": -4,
      "y": 2,
      "z": 1,
      "name": "Soil_Ash"
    },
    {
      "x": -4,
      "y": 3,
      "z": 1,
      "name": "Plant_Moss_Rug_Pink",
      "support": 15
    },
    {
      "x": -4,
      "y": 6,
      "z": 1,
      "name": "Wood_Blackwood_Beam",
      "rotation": 4
    },
    {
      "x": -4,
      "y": 7,
      "z": 1,
      "name": "Wood_Blackwood_Beam",
      "rotation": 4
    },
    {
      "x": -4,
      "y": 8,
      "z": 1,
      "name": "Wood_Blackwood_Roof_Hollow",
      "rotation": 2
    },
    {
      "x": -4,
      "y": 0,
      "z": 2,
      "name": "Soil_Dirt"
    },
    {
      "x": -4,
      "y": 1,
      "z": 2,
      "name": "Soil_Mud_Dry"
    },
    {
      "x": -4,
      "y": 2,
      "z": 2,
      "name": "Wood_Blackwood_Planks"
    },
    {
      "x": -4,
      "y": 3,
      "z": 2,
      "name": "Plant_Crop_Mushroom_Flatcap_Green"
    },
    {
      "x": -4,
      "y": 6,
      "z": 2,
      "name": "Wood_Blackwood_Beam",
      "rotation": 4
    },
    {
      "x": -4,
      "y": 7,
      "z": 2,
      "name": "Wood_Blackwood_Beam",
      "rotation": 4
    },
    {
      "x": -4,
      "y": 8,
      "z": 2,
      "name": "Wood_Blackwood_Roof_Hollow"
    },
    {
      "x": -4,
      "y": 10,
      "z": 2,
      "name": "Wood_Blackwood_Planks_Half",
      "rotation": 8
    },
    {
      "x": -4,
      "y": 11,
      "z": 2,
      "name": "Wood_Blackwood_Fence",
      "rotation": 2
    },
    {
      "x": -4,
      "y": 14,
      "z": 2,
      "name": "Wood_Blackwood_Roof_Hollow",
      "rotation": 2
    },
    {
      "x": -4,
      "y": 0,
      "z": 3,
      "name": "Soil_Dirt"
    },
    {
      "x": -4,
      "y": 1,
      "z": 3,
      "name": "Soil_Mud_Dry"
    },
    {
      "x": -4,
      "y": 2,
      "z": 3,
      "name": "Wood_Blackwood_Planks"
    },
    {
      "x": -4,
      "y": 3,
      "z": 3,
      "name": "Plant_Moss_Rug_Red",
      "support": 15
    },
    {
      "x": -4,
      "y": 5,
      "z": 3,
      "name": "Plant_Crop_Mushroom_Block_Blue_Mycelium"
    },
    {
      "x": -4,
      "y": 6,
      "z": 3,
      "name": "*Wood_Blackwood_Roof_Steep_State_Definitions_Inverted_Corner_Left",
      "rotation": 3
    },
    {
      "x": -4,
      "y": 7,
      "z": 3,
      "name": "*Wood_Blackwood_Roof_Steep_State_Definitions_Inverted_Corner_Left",
      "filler": 1024,
      "rotation": 3
    },
    {
      "x": -4,
      "y": 8,
      "z": 3,
      "name": "Plant_Leaves_Banyan",
      "support": 15
    },
    {
      "x": -4,
      "y": 10,
      "z": 3,
      "name": "Wood_Blackwood_Planks_Half",
      "rotation": 8
    },
    {
      "x": -4,
      "y": 11,
      "z": 3,
      "name": "Plant_Moss_Rug_Red",
      "support": 15
    },
    {
      "x": -4,
      "y": 15,
      "z": 3,
      "name": "Wood_Blackwood_Roof_Steep",
      "rotation": 2
    },
    {
      "x": -4,
      "y": 16,
      "z": 3,
      "name": "Wood_Blackwood_Roof_Steep",
      "filler": 1024,
      "rotation": 2
    },
    {
      "x": -4,
      "y": 0,
      "z": 4,
      "name": "Soil_Dirt"
    },
    {
      "x": -4,
      "y": 1,
      "z": 4,
      "name": "Soil_Mud_Dry"
    },
    {
      "x": -4,
      "y": 2,
      "z": 4,
      "name": "Wood_Blackwood_Planks"
    },
    {
      "x": -4,
      "y": 6,
      "z": 4,
      "name": "Wood_Blackwood_Roof_Steep",
      "rotation": 3
    },
    {
      "x": -4,
      "y": 7,
      "z": 4,
      "name": "Wood_Blackwood_Roof_Steep",
      "filler": 1024,
      "rotation": 3
    },
    {
      "x": -4,
      "y": 8,
      "z": 4,
      "name": "Plant_Leaves_Banyan",
      "support": 15
    },
    {
      "x": -4,
      "y": 10,
      "z": 4,
      "name": "Wood_Blackwood_Planks_Half",
      "rotation": 8
    },
    {
      "x": -4,
      "y": 16,
      "z": 4,
      "name": "Wood_Blackwood_Decorative"
    },
    {
      "x": -4,
      "y": 17,
      "z": 4,
      "name": "Rock_Slate_Stalactite_Small"
    },
    {
      "x": -4,
      "y": 0,
      "z": 5,
      "name": "Soil_Dirt"
    },
    {
      "x": -4,
      "y": 1,
      "z": 5,
      "name": "Soil_Dirt"
    },
    {
      "x": -4,
      "y": 2,
      "z": 5,
      "name": "Wood_Blackwood_Planks"
    },
    {
      "x": -4,
      "y": 3,
      "z": 5,
      "name": "Plant_Moss_Rug_Red",
      "support": 15
    },
    {
      "x": -4,
      "y": 5,
      "z": 5,
      "name": "Plant_Crop_Mushroom_Block_Blue_Mycelium"
    },
    {
      "x": -4,
      "y": 6,
      "z": 5,
      "name": "*Wood_Blackwood_Roof_Steep_State_Definitions_Inverted_Corner_Right",
      "rotation": 3
    },
    {
      "x": -4,
      "y": 7,
      "z": 5,
      "name": "*Wood_Blackwood_Roof_Steep_State_Definitions_Inverted_Corner_Right",
      "filler": 1024,
      "rotation": 3
    },
    {
      "x": -4,
      "y": 8,
      "z": 5,
      "name": "Plant_Leaves_Banyan",
      "support": 15
    },
    {
      "x": -4,
      "y": 10,
      "z": 5,
      "name": "Wood_Blackwood_Planks_Half",
      "rotation": 8
    },
    {
      "x": -4,
      "y": 15,
      "z": 5,
      "name": "Wood_Blackwood_Roof_Steep"
    },
    {
      "x": -4,
      "y": 16,
      "z": 5,
      "name": "Wood_Blackwood_Roof_Steep",
      "filler": 1024
    },
    {
      "x": -4,
      "y": 0,
      "z": 6,
      "name": "Soil_Dirt"
    },
    {
      "x": -4,
      "y": 1,
      "z": 6,
      "name": "Soil_Mud_Dry"
    },
    {
      "x": -4,
      "y": 2,
      "z": 6,
      "name": "Wood_Blackwood_Planks"
    },
    {
      "x": -4,
      "y": 3,
      "z": 6,
      "name": "Plant_Crop_Mushroom_Glowing_Violet"
    },
    {
      "x": -4,
      "y": 6,
      "z": 6,
      "name": "Wood_Blackwood_Beam",
      "rotation": 4
    },
    {
      "x": -4,
      "y": 7,
      "z": 6,
      "name": "Wood_Blackwood_Beam",
      "rotation": 4
    },
    {
      "x": -4,
      "y": 8,
      "z": 6,
      "name": "Wood_Blackwood_Roof_Hollow",
      "rotation": 2
    },
    {
      "x": -4,
      "y": 10,
      "z": 6,
      "name": "Wood_Blackwood_Planks_Half",
      "rotation": 8
    },
    {
      "x": -4,
      "y": 11,
      "z": 6,
      "name": "Wood_Blackwood_Fence"
    },
    {
      "x": -4,
      "y": 14,
      "z": 6,
      "name": "Wood_Blackwood_Roof_Hollow"
    },
    {
      "x": -4,
      "y": 0,
      "z": 7,
      "name": "Soil_Dirt"
    },
    {
      "x": -4,
      "y": 1,
      "z": 7,
      "name": "Soil_Mud_Dry"
    },
    {
      "x": -4,
      "y": 2,
      "z": 7,
      "name": "Soil_Ash"
    },
    {
      "x": -4,
      "y": 3,
      "z": 7,
      "name": "Plant_Moss_Rug_Pink",
      "support": 15
    },
    {
      "x": -4,
      "y": 6,
      "z": 7,
      "name": "Wood_Blackwood_Beam",
      "rotation": 4
    },
    {
      "x": -4,
      "y": 7,
      "z": 7,
      "name": "Wood_Blackwood_Beam",
      "rotation": 4
    },
    {
      "x": -4,
      "y": 8,
      "z": 7,
      "name": "Wood_Blackwood_Roof_Hollow"
    },
    {
      "x": -4,
      "y": 0,
      "z": 8,
      "name": "Soil_Dirt"
    },
    {
      "x": -4,
      "y": 1,
      "z": 8,
      "name": "Soil_Mud_Dry"
    },
    {
      "x": -4,
      "y": 2,
      "z": 8,
      "name": "Soil_Ash"
    },
    {
      "x": -4,
      "y": 3,
      "z": 8,
      "name": "Plant_Flower_Tall_Cyan"
    },
    {
      "x": -4,
      "y": 5,
      "z": 8,
      "name": "Wood_Blackwood_Stairs",
      "rotation": 11
    },
    {
      "x": -4,
      "y": 6,
      "z": 8,
      "name": "*Wood_Blackwood_Roof_Steep_State_Definitions_Inverted_Corner_Right"
    },
    {
      "x": -4,
      "y": 7,
      "z": 8,
      "name": "*Wood_Blackwood_Roof_Steep_State_Definitions_Inverted_Corner_Right",
      "filler": 1024
    },
    {
      "x": -4,
      "y": 8,
      "z": 8,
      "name": "Plant_Leaves_Banyan",
      "support": 15
    },
    {
      "x": -4,
      "y": 0,
      "z": 9,
      "name": "Soil_Dirt"
    },
    {
      "x": -4,
      "y": 1,
      "z": 9,
      "name": "Soil_Mud_Dry"
    },
    {
      "x": -4,
      "y": 2,
      "z": 9,
      "name": "Soil_Mud_Dry"
    },
    {
      "x": -4,
      "y": 3,
      "z": 9,
      "name": "Wood_Blackwood_Planks",
      "rotation": 2
    },
    {
      "x": -4,
      "y": 4,
      "z": 9,
      "name": "Wood_Blackwood_Planks",
      "rotation": 2
    },
    {
      "x": -4,
      "y": 5,
      "z": 9,
      "name": "Wood_Blackwood_Planks",
      "rotation": 2
    },
    {
      "x": -4,
      "y": 6,
      "z": 9,
      "name": "Wood_Blackwood_Roof_Steep",
      "rotation": 3
    },
    {
      "x": -4,
      "y": 7,
      "z": 9,
      "name": "Wood_Blackwood_Roof_Steep",
      "filler": 1024,
      "rotation": 3
    },
    {
      "x": -4,
      "y": 0,
      "z": 10,
      "name": "Soil_Dirt"
    },
    {
      "x": -4,
      "y": 1,
      "z": 10,
      "name": "Soil_Dirt"
    },
    {
      "x": -4,
      "y": 2,
      "z": 10,
      "name": "Soil_Grass"
    },
    {
      "x": -4,
      "y": 3,
      "z": 10,
      "name": "Wood_Blackwood_Planks",
      "rotation": 2
    },
    {
      "x": -4,
      "y": 4,
      "z": 10,
      "name": "Wood_Blackwood_Roof",
      "rotation": 3
    },
    {
      "x": -4,
      "y": 5,
      "z": 10,
      "name": "Plant_Leaves_Banyan",
      "support": 15
    },
    {
      "x": -4,
      "y": 0,
      "z": 11,
      "name": "Soil_Dirt"
    },
    {
      "x": -4,
      "y": 1,
      "z": 11,
      "name": "Soil_Dirt"
    },
    {
      "x": -4,
      "y": 2,
      "z": 11,
      "name": "Soil_Grass"
    },
    {
      "x": -4,
      "y": 3,
      "z": 11,
      "name": "Wood_Blackwood_Fence",
      "rotation": 3
    },
    {
      "x": -4,
      "y": 4,
      "z": 11,
      "name": "Wood_Blackwood_Roof",
      "rotation": 3
    },
    {
      "x": -4,
      "y": 0,
      "z": 12,
      "name": "Soil_Dirt"
    },
    {
      "x": -4,
      "y": 1,
      "z": 12,
      "name": "Soil_Dirt"
    },
    {
      "x": -4,
      "y": 2,
      "z": 12,
      "name": "Soil_Grass"
    },
    {
      "x": -4,
      "y": 3,
      "z": 12,
      "name": "Wood_Blackwood_Fence",
      "rotation": 3
    },
    {
      "x": -4,
      "y": 0,
      "z": 13,
      "name": "Soil_Dirt"
    },
    {
      "x": -4,
      "y": 1,
      "z": 13,
      "name": "Soil_Dirt"
    },
    {
      "x": -4,
      "y": 2,
      "z": 13,
      "name": "Soil_Grass"
    },
    {
      "x": -4,
      "y": 3,
      "z": 13,
      "name": "*Wood_Blackwood_Fence_State_Definitions_Corner",
      "rotation": 2
    },
    {
      "x": -4,
      "y": 0,
      "z": 14,
      "name": "Soil_Dirt"
    },
    {
      "x": -4,
      "y": 1,
      "z": 14,
      "name": "Soil_Dirt"
    },
    {
      "x": -4,
      "y": 2,
      "z": 14,
      "name": "Soil_Grass"
    },
    {
      "x": -4,
      "y": 0,
      "z": 15,
      "name": "Soil_Dirt"
    },
    {
      "x": -4,
      "y": 1,
      "z": 15,
      "name": "Soil_Dirt"
    },
    {
      "x": -4,
      "y": 2,
      "z": 15,
      "name": "Soil_Grass"
    },
    {
      "x": -4,
      "y": 3,
      "z": 15,
      "name": "Plant_Grass_Lush_Tall"
    },
    {
      "x": -3,
      "y": 0,
      "z": -14,
      "name": "Soil_Grass"
    },
    {
      "x": -3,
      "y": 1,
      "z": -14,
      "name": "Plant_Moss_Rug_Green"
    },
    {
      "x": -3,
      "y": 0,
      "z": -13,
      "name": "Rock_Slate_Cobble"
    },
    {
      "x": -3,
      "y": 0,
      "z": -12,
      "name": "Soil_Grass"
    },
    {
      "x": -3,
      "y": 1,
      "z": -12,
      "name": "Rock_Basalt_Cobble_Half"
    },
    {
      "x": -3,
      "y": 0,
      "z": -11,
      "name": "Soil_Dirt"
    },
    {
      "x": -3,
      "y": 1,
      "z": -11,
      "name": "Soil_Grass"
    },
    {
      "x": -3,
      "y": 0,
      "z": -10,
      "name": "Soil_Dirt"
    },
    {
      "x": -3,
      "y": 1,
      "z": -10,
      "name": "Rock_Basalt_Cobble"
    },
    {
      "x": -3,
      "y": 0,
      "z": -9,
      "name": "Soil_Mud_Dry"
    },
    {
      "x": -3,
      "y": 1,
      "z": -9,
      "name": "Soil_Mud_Dry"
    },
    {
      "x": -3,
      "y": 2,
      "z": -9,
      "name": "Rock_Basalt_Cobble_Half"
    },
    {
      "x": -3,
      "y": 0,
      "z": -8,
      "name": "Soil_Mud_Dry"
    },
    {
      "x": -3,
      "y": 1,
      "z": -8,
      "name": "Soil_Mud_Dry"
    },
    {
      "x": -3,
      "y": 2,
      "z": -8,
      "name": "Rock_Basalt_Cobble_Half"
    },
    {
      "x": -3,
      "y": 0,
      "z": -7,
      "name": "Soil_Mud_Dry"
    },
    {
      "x": -3,
      "y": 1,
      "z": -7,
      "name": "Soil_Mud_Dry"
    },
    {
      "x": -3,
      "y": 2,
      "z": -7,
      "name": "Rock_Basalt_Cobble_Half",
      "rotation": 8
    },
    {
      "x": -3,
      "y": 0,
      "z": -6,
      "name": "Soil_Dirt"
    },
    {
      "x": -3,
      "y": 1,
      "z": -6,
      "name": "Soil_Mud_Dry"
    },
    {
      "x": -3,
      "y": 2,
      "z": -6,
      "name": "Wood_Blackwood_Planks"
    },
    {
      "x": -3,
      "y": 3,
      "z": -6,
      "name": "Wood_Blackwood_Planks_Half"
    },
    {
      "x": -3,
      "y": 0,
      "z": -5,
      "name": "Soil_Dirt"
    },
    {
      "x": -3,
      "y": 1,
      "z": -5,
      "name": "Soil_Dirt"
    },
    {
      "x": -3,
      "y": 2,
      "z": -5,
      "name": "Soil_Grass"
    },
    {
      "x": -3,
      "y": 3,
      "z": -5,
      "name": "Wood_Blackwood_Planks"
    },
    {
      "x": -3,
      "y": 0,
      "z": -4,
      "name": "Soil_Dirt"
    },
    {
      "x": -3,
      "y": 1,
      "z": -4,
      "name": "Soil_Dirt"
    },
    {
      "x": -3,
      "y": 2,
      "z": -4,
      "name": "Soil_Grass"
    },
    {
      "x": -3,
      "y": 3,
      "z": -4,
      "name": "Wood_Blackwood_Planks"
    },
    {
      "x": -3,
      "y": 0,
      "z": -3,
      "name": "Soil_Dirt"
    },
    {
      "x": -3,
      "y": 1,
      "z": -3,
      "name": "Soil_Dirt"
    },
    {
      "x": -3,
      "y": 2,
      "z": -3,
      "name": "Soil_Grass"
    },
    {
      "x": -3,
      "y": 3,
      "z": -3,
      "name": "Wood_Blackwood_Planks"
    },
    {
      "x": -3,
      "y": 4,
      "z": -3,
      "name": "Deco_Lantern"
    },
    {
      "x": -3,
      "y": 5,
      "z": -3,
      "name": "Wood_Blackwood_Roof_Hollow",
      "rotation": 3
    },
    {
      "x": -3,
      "y": 0,
      "z": -2,
      "name": "Soil_Dirt"
    },
    {
      "x": -3,
      "y": 1,
      "z": -2,
      "name": "Soil_Dirt"
    },
    {
      "x": -3,
      "y": 2,
      "z": -2,
      "name": "Soil_Leaves"
    },
    {
      "x": -3,
      "y": 3,
      "z": -2,
      "name": "Wood_Blackwood_Decorative"
    },
    {
      "x": -3,
      "y": 4,
      "z": -2,
      "name": "Wood_Blackwood_Planks"
    },
    {
      "x": -3,
      "y": 5,
      "z": -2,
      "name": "Wood_Blackwood_Roof",
      "rotation": 3
    },
    {
      "x": -3,
      "y": 6,
      "z": -2,
      "name": "Furniture_Temple_Dark_Shelf",
      "rotation": 2
    },
    {
      "x": -3,
      "y": 7,
      "z": -2,
      "name": "Furniture_Tavern_Planter"
    },
    {
      "x": -3,
      "y": 8,
      "z": -2,
      "name": "Plant_Leaves_Windwillow",
      "support": 15
    },
    {
      "x": -3,
      "y": 0,
      "z": -1,
      "name": "Soil_Dirt"
    },
    {
      "x": -3,
      "y": 1,
      "z": -1,
      "name": "Soil_Mud_Dry"
    },
    {
      "x": -3,
      "y": 2,
      "z": -1,
      "name": "Soil_Ash"
    },
    {
      "x": -3,
      "y": 3,
      "z": -1,
      "name": "Wood_Blackwood_Planks"
    },
    {
      "x": -3,
      "y": 4,
      "z": -1,
      "name": "Wood_Blackwood_Planks"
    },
    {
      "x": -3,
      "y": 5,
      "z": -1,
      "name": "Wood_Blackwood_Planks"
    },
    {
      "x": -3,
      "y": 6,
      "z": -1,
      "name": "Wood_Blackwood_Planks"
    },
    {
      "x": -3,
      "y": 7,
      "z": -1,
      "name": "Wood_Blackwood_Decorative"
    },
    {
      "x": -3,
      "y": 8,
      "z": -1,
      "name": "Wood_Blackwood_Roof",
      "rotation": 3
    },
    {
      "x": -3,
      "y": 0,
      "z": 0,
      "name": "Soil_Dirt"
    },
    {
      "x": -3,
      "y": 1,
      "z": 0,
      "name": "Soil_Dirt"
    },
    {
      "x": -3,
      "y": 2,
      "z": 0,
      "name": "Soil_Ash"
    },
    {
      "x": -3,
      "y": 3,
      "z": 0,
      "name": "Plant_Moss_Rug_Pink",
      "support": 15
    },
    {
      "x": -3,
      "y": 6,
      "z": 0,
      "name": "Plant_Leaves_Camphor",
      "support": 15
    },
    {
      "x": -3,
      "y": 7,
      "z": 0,
      "name": "Plant_Coral_Bush_Poisoned"
    },
    {
      "x": -3,
      "y": 8,
      "z": 0,
      "name": "Wood_Blackwood_Roof_Hollow",
      "rotation": 3
    },
    {
      "x": -3,
      "y": 0,
      "z": 1,
      "name": "Soil_Dirt"
    },
    {
      "x": -3,
      "y": 1,
      "z": 1,
      "name": "Soil_Dirt"
    },
    {
      "x": -3,
      "y": 2,
      "z": 1,
      "name": "Wood_Blackwood_Planks"
    },
    {
      "x": -3,
      "y": 3,
      "z": 1,
      "name": "Plant_Moss_Rug_Red",
      "support": 15
    },
    {
      "x": -3,
      "y": 8,
      "z": 1,
      "name": "*Wood_Blackwood_Roof_Hollow_State_Definitions_Inverted_Corner_Right",
      "rotation": 3
    },
    {
      "x": -3,
      "y": 9,
      "z": 1,
      "name": "Plant_Leaves_Banyan",
      "support": 15
    },
    {
      "x": -3,
      "y": 0,
      "z": 2,
      "name": "Soil_Dirt"
    },
    {
      "x": -3,
      "y": 1,
      "z": 2,
      "name": "Soil_Dirt"
    },
    {
      "x": -3,
      "y": 2,
      "z": 2,
      "name": "Wood_Blackwood_Planks"
    },
    {
      "x": -3,
      "y": 8,
      "z": 2,
      "name": "*Wood_Blackwood_Roof_Hollow_State_Definitions_Inverted_Corner_Right"
    },
    {
      "x": -3,
      "y": 9,
      "z": 2,
      "name": "Plant_Leaves_Banyan",
      "support": 15
    },
    {
      "x": -3,
      "y": 10,
      "z": 2,
      "name": "Wood_Blackwood_Planks_Half",
      "rotation": 8
    },
    {
      "x": -3,
      "y": 11,
      "z": 2,
      "name": "Wood_Blackwood_Fence",
      "rotation": 2
    },
    {
      "x": -3,
      "y": 14,
      "z": 2,
      "name": "Wood_Blackwood_Roof_Hollow",
      "rotation": 2
    },
    {
      "x": -3,
      "y": 0,
      "z": 3,
      "name": "Soil_Dirt"
    },
    {
      "x": -3,
      "y": 1,
      "z": 3,
      "name": "Soil_Dirt"
    },
    {
      "x": -3,
      "y": 2,
      "z": 3,
      "name": "Wood_Blackwood_Decorative"
    },
    {
      "x": -3,
      "y": 3,
      "z": 3,
      "name": "Furniture_Temple_Scarak_Pot"
    },
    {
      "x": -3,
      "y": 8,
      "z": 3,
      "name": "Wood_Blackwood_Roof_Hollow",
      "rotation": 3
    },
    {
      "x": -3,
      "y": 10,
      "z": 3,
      "name": "Wood_Blackwood_Planks_Half",
      "rotation": 8
    },
    {
      "x": -3,
      "y": 15,
      "z": 3,
      "name": "*Wood_Blackwood_Roof_Steep_State_Definitions_Corner_Right",
      "rotation": 2
    },
    {
      "x": -3,
      "y": 16,
      "z": 3,
      "name": "*Wood_Blackwood_Roof_Steep_State_Definitions_Corner_Right",
      "filler": 1024,
      "rotation": 2
    },
    {
      "x": -3,
      "y": 0,
      "z": 4,
      "name": "Soil_Dirt"
    },
    {
      "x": -3,
      "y": 1,
      "z": 4,
      "name": "Soil_Mud_Dry"
    },
    {
      "x": -3,
      "y": 2,
      "z": 4,
      "name": "Wood_Blackwood_Decorative"
    },
    {
      "x": -3,
      "y": 6,
      "z": 4,
      "name": "Furniture_Temple_Dark_Shelf",
      "rotation": 1
    },
    {
      "x": -3,
      "y": 7,
      "z": 4,
      "name": "WinterHoliday_Garland",
      "rotation": 1
    },
    {
      "x": -3,
      "y": 8,
      "z": 4,
      "name": "Wood_Blackwood_Roof_Hollow",
      "rotation": 3
    },
    {
      "x": -3,
      "y": 9,
      "z": 4,
      "name": "Plant_Leaves_Banyan",
      "support": 15
    },
    {
      "x": -3,
      "y": 10,
      "z": 4,
      "name": "Wood_Blackwood_Planks_Half",
      "rotation": 8
    },
    {
      "x": -3,
      "y": 11,
      "z": 4,
      "name": "Plant_Moss_Rug_Red",
      "support": 15
    },
    {
      "x": -3,
      "y": 15,
      "z": 4,
      "name": "Wood_Blackwood_Roof_Steep",
      "rotation": 1
    },
    {
      "x": -3,
      "y": 16,
      "z": 4,
      "name": "Wood_Blackwood_Roof_Steep",
      "filler": 1024,
      "rotation": 1
    },
    {
      "x": -3,
      "y": 0,
      "z": 5,
      "name": "Soil_Dirt"
    },
    {
      "x": -3,
      "y": 1,
      "z": 5,
      "name": "Soil_Mud_Dry"
    },
    {
      "x": -3,
      "y": 2,
      "z": 5,
      "name": "Wood_Blackwood_Decorative"
    },
    {
      "x": -3,
      "y": 8,
      "z": 5,
      "name": "Wood_Blackwood_Roof_Hollow",
      "rotation": 3
    },
    {
      "x": -3,
      "y": 10,
      "z": 5,
      "name": "Wood_Blackwood_Planks_Half",
      "rotation": 8
    },
    {
      "x": -3,
      "y": 15,
      "z": 5,
      "name": "*Wood_Blackwood_Roof_Steep_State_Definitions_Corner_Left"
    },
    {
      "x": -3,
      "y": 16,
      "z": 5,
      "name": "*Wood_Blackwood_Roof_Steep_State_Definitions_Corner_Left",
      "filler": 1024
    },
    {
      "x": -3,
      "y": 0,
      "z": 6,
      "name": "Soil_Dirt"
    },
    {
      "x": -3,
      "y": 1,
      "z": 6,
      "name": "Soil_Mud_Dry"
    },
    {
      "x": -3,
      "y": 2,
      "z": 6,
      "name": "Wood_Blackwood_Planks"
    },
    {
      "x": -3,
      "y": 3,
      "z": 6,
      "name": "Plant_Moss_Rug_Red",
      "support": 15
    },
    {
      "x": -3,
      "y": 8,
      "z": 6,
      "name": "*Wood_Blackwood_Roof_Hollow_State_Definitions_Inverted_Corner_Left",
      "rotation": 2
    },
    {
      "x": -3,
      "y": 9,
      "z": 6,
      "name": "Plant_Leaves_Banyan",
      "support": 15
    },
    {
      "x": -3,
      "y": 10,
      "z": 6,
