{
  "version": 8,
  "blockIdVersion": 10,
  "anchorX": 0,
  "anchorY": 0,
  "anchorZ": 0,
  "blocks": [
    {
      "x": -12,
      "y": 0,
      "z": -10,
      "name": "Soil_Clay_Smooth_Lime"
    },
    {
      "x": -12,
      "y": 0,
      "z": -9,
      "name": "Soil_Clay_Smooth_Lime"
    },
    {
      "x": -12,
      "y": 0,
      "z": -8,
      "name": "Soil_Clay_Smooth_Lime"
    },
    {
      "x": -12,
      "y": 0,
      "z": -7,
      "name": "Soil_Clay_Smooth_Lime"
    },
    {
      "x": -12,
      "y": 12,
      "z": -7,
      "name": "Wood_Oak_Branch_Short",
      "rotation": 3
    },
    {
      "x": -12,
      "y": 0,
      "z": -6,
      "name": "Soil_Clay_Smooth_Lime"
    },
    {
      "x": -12,
      "y": 0,
      "z": -5,
      "name": "Soil_Clay_Smooth_Lime"
    },
    {
      "x": -12,
      "y": 12,
      "z": -5,
      "name": "Wood_Oak_Branch_Short",
      "rotation": 3
    },
    {
      "x": -12,
      "y": 0,
      "z": -4,
      "name": "Soil_Clay_Smooth_Lime"
    },
    {
      "x": -12,
      "y": 0,
      "z": -3,
      "name": "Soil_Clay_Smooth_Lime"
    },
    {
      "x": -12,
      "y": 0,
      "z": -2,
      "name": "Soil_Clay_Smooth_Lime"
    },
    {
      "x": -12,
      "y": 0,
      "z": -1,
      "name": "Soil_Clay_Smooth_Lime"
    },
    {
      "x": -12,
      "y": 0,
      "z": 0,
      "name": "Soil_Clay_Smooth_Lime"
    },
    {
      "x": -12,
      "y": 12,
      "z": 0,
      "name": "Wood_Oak_Branch_Short",
      "rotation": 3
    },
    {
      "x": -12,
      "y": 0,
      "z": 1,
      "name": "Soil_Clay_Smooth_Lime"
    },
    {
      "x": -12,
      "y": 0,
      "z": 2,
      "name": "Soil_Clay_Smooth_Lime"
    },
    {
      "x": -12,
      "y": 0,
      "z": 3,
      "name": "Soil_Clay_Smooth_Lime"
    },
    {
      "x": -12,
      "y": 0,
      "z": 4,
      "name": "Soil_Clay_Smooth_Lime"
    },
    {
      "x": -12,
      "y": 0,
      "z": 5,
      "name": "Soil_Clay_Smooth_Lime"
    },
    {
      "x": -12,
      "y": 0,
      "z": 6,
      "name": "Soil_Clay_Smooth_Lime"
    },
    {
      "x": -12,
      "y": 0,
      "z": 7,
      "name": "Soil_Clay_Smooth_Lime"
    },
    {
      "x": -12,
      "y": 12,
      "z": 7,
      "name": "Wood_Oak_Branch_Short",
      "rotation": 3
    },
    {
      "x": -12,
      "y": 0,
      "z": 8,
      "name": "Soil_Clay_Smooth_Lime"
    },
    {
      "x": -12,
      "y": 0,
      "z": 9,
      "name": "Soil_Clay_Smooth_Lime"
    },
    {
      "x": -12,
      "y": 0,
      "z": 10,
      "name": "Soil_Clay_Smooth_Lime"
    },
    {
      "x": -11,
      "y": 0,
      "z": -10,
      "name": "Soil_Clay_Smooth_Lime"
    },
    {
      "x": -11,
      "y": 0,
      "z": -9,
      "name": "Soil_Clay_Smooth_Lime"
    },
    {
      "x": -11,
      "y": 12,
      "z": -9,
      "name": "Wood_Softwood_Roof_Hollow",
      "rotation": 2
    },
    {
      "x": -11,
      "y": 0,
      "z": -8,
      "name": "Soil_Clay_Smooth_Lime"
    },
    {
      "x": -11,
      "y": 13,
      "z": -8,
      "name": "Wood_Softwood_Roof_Hollow",
      "rotation": 2
    },
    {
      "x": -11,
      "y": 0,
      "z": -7,
      "name": "Soil_Clay_Smooth_Lime"
    },
    {
      "x": -11,
      "y": 6,
      "z": -7,
      "name": "Wood_Oak_Branch_Short",
      "rotation": 3
    },
    {
      "x": -11,
      "y": 12,
      "z": -7,
      "name": "Wood_Oak_Trunk",
      "rotation": 5
    },
    {
      "x": -11,
      "y": 14,
      "z": -7,
      "name": "Wood_Softwood_Roof_Hollow",
      "rotation": 2
    },
    {
      "x": -11,
      "y": 0,
      "z": -6,
      "name": "Soil_Clay_Smooth_Lime"
    },
    {
      "x": -11,
      "y": 12,
      "z": -6,
      "name": "Wood_Softwood_Beam",
      "rotation": 4
    },
    {
      "x": -11,
      "y": 15,
      "z": -6,
      "name": "Wood_Softwood_Roof_Hollow",
      "rotation": 2
    },
    {
      "x": -11,
      "y": 0,
      "z": -5,
      "name": "Soil_Clay_Smooth_Lime"
    },
    {
      "x": -11,
      "y": 6,
      "z": -5,
      "name": "Wood_Oak_Branch_Short",
      "rotation": 3
    },
    {
      "x": -11,
      "y": 12,
      "z": -5,
      "name": "Wood_Oak_Trunk",
      "rotation": 5
    },
    {
      "x": -11,
      "y": 16,
      "z": -5,
      "name": "Wood_Softwood_Roof_Hollow",
      "rotation": 2
    },
    {
      "x": -11,
      "y": 0,
      "z": -4,
      "name": "Soil_Clay_Smooth_Lime"
    },
    {
      "x": -11,
      "y": 12,
      "z": -4,
      "name": "Wood_Softwood_Beam",
      "rotation": 4
    },
    {
      "x": -11,
      "y": 17,
      "z": -4,
      "name": "Wood_Softwood_Roof_Hollow",
      "rotation": 2
    },
    {
      "x": -11,
      "y": 0,
      "z": -3,
      "name": "Soil_Clay_Smooth_Lime"
    },
    {
      "x": -11,
      "y": 12,
      "z": -3,
      "name": "Wood_Softwood_Beam",
      "rotation": 4
    },
    {
      "x": -11,
      "y": 18,
      "z": -3,
      "name": "Wood_Softwood_Roof_Hollow",
      "rotation": 2
    },
    {
      "x": -11,
      "y": 0,
      "z": -2,
      "name": "Soil_Clay_Smooth_Lime"
    },
    {
      "x": -11,
      "y": 12,
      "z": -2,
      "name": "Wood_Softwood_Beam",
      "rotation": 4
    },
    {
      "x": -11,
      "y": 16,
      "z": -2,
      "name": "*Furniture_Tavern_Trapdoor_State_Definitions_OpenDoorOut",
      "rotation": 3
    },
    {
      "x": -11,
      "y": 18,
      "z": -2,
      "name": "Wood_Oak_Trunk_Stairs",
      "rotation": 9
    },
    {
      "x": -11,
      "y": 19,
      "z": -2,
      "name": "Wood_Softwood_Roof_Flat",
      "rotation": 3
    },
    {
      "x": -11,
      "y": 0,
      "z": -1,
      "name": "Soil_Clay_Smooth_Lime"
    },
    {
      "x": -11,
      "y": 12,
      "z": -1,
      "name": "Wood_Softwood_Beam",
      "rotation": 4
    },
    {
      "x": -11,
      "y": 19,
      "z": -1,
      "name": "Wood_Softwood_Roof_Flat",
      "rotation": 3
    },
    {
      "x": -11,
      "y": 0,
      "z": 0,
      "name": "Soil_Clay_Smooth_Lime"
    },
    {
      "x": -11,
      "y": 6,
      "z": 0,
      "name": "Wood_Oak_Branch_Short",
      "rotation": 3
    },
    {
      "x": -11,
      "y": 12,
      "z": 0,
      "name": "Wood_Oak_Trunk",
      "rotation": 5
    },
    {
      "x": -11,
      "y": 19,
      "z": 0,
      "name": "Wood_Softwood_Roof_Flat",
      "rotation": 3
    },
    {
      "x": -11,
      "y": 0,
      "z": 1,
      "name": "Soil_Clay_Smooth_Lime"
    },
    {
      "x": -11,
      "y": 12,
      "z": 1,
      "name": "Wood_Softwood_Beam",
      "rotation": 4
    },
    {
      "x": -11,
      "y": 16,
      "z": 1,
      "name": "*Furniture_Tavern_Trapdoor_State_Definitions_OpenDoorOut",
      "rotation": 3
    },
    {
      "x": -11,
      "y": 18,
      "z": 1,
      "name": "Wood_Oak_Trunk_Stairs",
      "rotation": 9
    },
    {
      "x": -11,
      "y": 19,
      "z": 1,
      "name": "Wood_Softwood_Roof_Flat",
      "rotation": 3
    },
    {
      "x": -11,
      "y": 0,
      "z": 2,
      "name": "Soil_Clay_Smooth_Lime"
    },
    {
      "x": -11,
      "y": 12,
      "z": 2,
      "name": "Wood_Softwood_Beam",
      "rotation": 4
    },
    {
      "x": -11,
      "y": 18,
      "z": 2,
      "name": "Wood_Softwood_Roof_Hollow"
    },
    {
      "x": -11,
      "y": 0,
      "z": 3,
      "name": "Soil_Clay_Smooth_Lime"
    },
    {
      "x": -11,
      "y": 12,
      "z": 3,
      "name": "Wood_Softwood_Beam",
      "rotation": 4
    },
    {
      "x": -11,
      "y": 17,
      "z": 3,
      "name": "Wood_Softwood_Roof_Hollow"
    },
    {
      "x": -11,
      "y": 0,
      "z": 4,
      "name": "Soil_Clay_Smooth_Lime"
    },
    {
      "x": -11,
      "y": 12,
      "z": 4,
      "name": "Wood_Softwood_Beam",
      "rotation": 4
    },
    {
      "x": -11,
      "y": 16,
      "z": 4,
      "name": "Wood_Softwood_Roof_Hollow"
    },
    {
      "x": -11,
      "y": 0,
      "z": 5,
      "name": "Soil_Clay_Smooth_Lime"
    },
    {
      "x": -11,
      "y": 12,
      "z": 5,
      "name": "Wood_Softwood_Beam",
      "rotation": 4
    },
    {
      "x": -11,
      "y": 15,
      "z": 5,
      "name": "Wood_Softwood_Roof_Hollow"
    },
    {
      "x": -11,
      "y": 0,
      "z": 6,
      "name": "Soil_Clay_Smooth_Lime"
    },
    {
      "x": -11,
      "y": 12,
      "z": 6,
      "name": "Wood_Softwood_Beam",
      "rotation": 4
    },
    {
      "x": -11,
      "y": 14,
      "z": 6,
      "name": "Wood_Softwood_Roof_Hollow"
    },
    {
      "x": -11,
      "y": 0,
      "z": 7,
      "name": "Soil_Clay_Smooth_Lime"
    },
    {
      "x": -11,
      "y": 6,
      "z": 7,
      "name": "Wood_Oak_Branch_Short",
      "rotation": 3
    },
    {
      "x": -11,
      "y": 12,
      "z": 7,
      "name": "Wood_Oak_Trunk",
      "rotation": 5
    },
    {
      "x": -11,
      "y": 13,
      "z": 7,
      "name": "Wood_Softwood_Roof"
    },
    {
      "x": -11,
      "y": 0,
      "z": 8,
      "name": "Soil_Clay_Smooth_Lime"
    },
    {
      "x": -11,
      "y": 12,
      "z": 8,
      "name": "Wood_Softwood_Roof_Hollow"
    },
    {
      "x": -11,
      "y": 0,
      "z": 9,
      "name": "Soil_Clay_Smooth_Lime"
    },
    {
      "x": -11,
      "y": 0,
      "z": 10,
      "name": "Soil_Clay_Smooth_Lime"
    },
    {
      "x": -10,
      "y": 0,
      "z": -10,
      "name": "Soil_Clay_Smooth_Lime"
    },
    {
      "x": -10,
      "y": 0,
      "z": -9,
      "name": "Soil_Clay_Smooth_Lime"
    },
    {
      "x": -10,
      "y": 12,
      "z": -9,
      "name": "Wood_Softwood_Roof_Hollow",
      "rotation": 2
    },
    {
      "x": -10,
      "y": 0,
      "z": -8,
      "name": "Soil_Clay_Smooth_Lime"
    },
    {
      "x": -10,
      "y": 12,
      "z": -8,
      "name": "Wood_Hardwood_Planks_Half",
      "rotation": 8
    },
    {
      "x": -10,
      "y": 13,
      "z": -8,
      "name": "Wood_Softwood_Roof",
      "rotation": 2
    },
    {
      "x": -10,
      "y": 0,
      "z": -7,
      "name": "Soil_Clay_Smooth_Lime"
    },
    {
      "x": -10,
      "y": 6,
      "z": -7,
      "name": "Wood_Oak_Trunk",
      "rotation": 5
    },
    {
      "x": -10,
      "y": 10,
      "z": -7,
      "name": "*Furniture_Tavern_Trapdoor_State_Definitions_OpenDoorOut",
      "rotation": 3
    },
    {
      "x": -10,
      "y": 11,
      "z": -7,
      "name": "Wood_Oak_Trunk_Stairs",
      "rotation": 9
    },
    {
      "x": -10,
      "y": 12,
      "z": -7,
      "name": "Wood_Oak_Trunk",
      "rotation": 5
    },
    {
      "x": -10,
      "y": 13,
      "z": -7,
      "name": "Wood_Softwood_Planks"
    },
    {
      "x": -10,
      "y": 14,
      "z": -7,
      "name": "Wood_Softwood_Roof",
      "rotation": 2
    },
    {
      "x": -10,
      "y": 0,
      "z": -6,
      "name": "Soil_Clay_Smooth_Lime"
    },
    {
      "x": -10,
      "y": 12,
      "z": -6,
      "name": "Wood_Hardwood_Planks_Half",
      "rotation": 8
    },
    {
      "x": -10,
      "y": 13,
      "z": -6,
      "name": "Wood_Softwood_Planks"
    },
    {
      "x": -10,
      "y": 14,
      "z": -6,
      "name": "Wood_Softwood_Planks"
    },
    {
      "x": -10,
      "y": 15,
      "z": -6,
      "name": "Wood_Softwood_Roof",
      "rotation": 2
    },
    {
      "x": -10,
      "y": 0,
      "z": -5,
      "name": "Soil_Clay_Smooth_Lime"
    },
    {
      "x": -10,
      "y": 6,
      "z": -5,
      "name": "Wood_Oak_Trunk",
      "rotation": 5
    },
    {
      "x": -10,
      "y": 7,
      "z": -5,
      "name": "Wood_Hardwood_Fence",
      "rotation": 3
    },
    {
      "x": -10,
      "y": 10,
      "z": -5,
      "name": "*Furniture_Tavern_Trapdoor_State_Definitions_OpenDoorOut",
      "rotation": 3
    },
    {
      "x": -10,
      "y": 11,
      "z": -5,
      "name": "Wood_Oak_Trunk_Stairs",
      "rotation": 9
    },
    {
      "x": -10,
      "y": 12,
      "z": -5,
      "name": "Wood_Oak_Trunk",
      "rotation": 5
    },
    {
      "x": -10,
      "y": 13,
      "z": -5,
      "name": "Wood_Oak_Trunk"
    },
    {
      "x": -10,
      "y": 14,
      "z": -5,
      "name": "Wood_Oak_Trunk"
    },
    {
      "x": -10,
      "y": 15,
      "z": -5,
      "name": "Wood_Oak_Trunk"
    },
    {
      "x": -10,
      "y": 16,
      "z": -5,
      "name": "Wood_Softwood_Roof",
      "rotation": 2
    },
    {
      "x": -10,
      "y": 0,
      "z": -4,
      "name": "Soil_Clay_Smooth_Lime"
    },
    {
      "x": -10,
      "y": 6,
      "z": -4,
      "name": "Wood_Oak_Trunk_Stairs",
      "rotation": 9
    },
    {
      "x": -10,
      "y": 7,
      "z": -4,
      "name": "Wood_Hardwood_Fence",
      "rotation": 3
    },
    {
      "x": -10,
      "y": 12,
      "z": -4,
      "name": "Wood_Hardwood_Planks_Half",
      "rotation": 8
    },
    {
      "x": -10,
      "y": 13,
      "z": -4,
      "name": "Wood_Softwood_Planks_Half",
      "rotation": 7
    },
    {
      "x": -10,
      "y": 14,
      "z": -4,
      "name": "Wood_Softwood_Planks_Half",
      "rotation": 7
    },
    {
      "x": -10,
      "y": 15,
      "z": -4,
      "name": "Wood_Softwood_Planks_Half",
      "rotation": 7
    },
    {
      "x": -10,
      "y": 16,
      "z": -4,
      "name": "Wood_Oak_Trunk",
      "rotation": 4
    },
    {
      "x": -10,
      "y": 17,
      "z": -4,
      "name": "Wood_Softwood_Roof",
      "rotation": 2
    },
    {
      "x": -10,
      "y": 0,
      "z": -3,
      "name": "Soil_Clay_Smooth_Lime"
    },
    {
      "x": -10,
      "y": 6,
      "z": -3,
      "name": "Wood_Oak_Trunk_Stairs",
      "rotation": 9
    },
    {
      "x": -10,
      "y": 7,
      "z": -3,
      "name": "Wood_Hardwood_Fence",
      "rotation": 3
    },
    {
      "x": -10,
      "y": 12,
      "z": -3,
      "name": "Wood_Hardwood_Planks_Half",
      "rotation": 8
    },
    {
      "x": -10,
      "y": 13,
      "z": -3,
      "name": "Wood_Softwood_Planks_Half",
      "rotation": 7
    },
    {
      "x": -10,
      "y": 14,
      "z": -3,
      "name": "Wood_Softwood_Planks_Half",
      "rotation": 7
    },
    {
      "x": -10,
      "y": 15,
      "z": -3,
      "name": "Wood_Softwood_Planks_Half",
      "rotation": 7
    },
    {
      "x": -10,
      "y": 16,
      "z": -3,
      "name": "Wood_Oak_Trunk",
      "rotation": 4
    },
    {
      "x": -10,
      "y": 17,
      "z": -3,
      "name": "Wood_Softwood_Planks"
    },
    {
      "x": -10,
      "y": 18,
      "z": -3,
      "name": "Wood_Softwood_Roof",
      "rotation": 2
    },
    {
      "x": -10,
      "y": 0,
      "z": -2,
      "name": "Soil_Clay_Smooth_Lime"
    },
    {
      "x": -10,
      "y": 6,
      "z": -2,
      "name": "Wood_Oak_Trunk_Stairs",
      "rotation": 9
    },
    {
      "x": -10,
      "y": 7,
      "z": -2,
      "name": "Wood_Hardwood_Fence",
      "rotation": 3
    },
    {
      "x": -10,
      "y": 12,
      "z": -2,
      "name": "Wood_Hardwood_Planks_Half",
      "rotation": 8
    },
    {
      "x": -10,
      "y": 13,
      "z": -2,
      "name": "Wood_Oak_Trunk"
    },
    {
      "x": -10,
      "y": 14,
      "z": -2,
      "name": "Wood_Oak_Trunk"
    },
    {
      "x": -10,
      "y": 15,
      "z": -2,
      "name": "Wood_Oak_Trunk"
    },
    {
      "x": -10,
      "y": 16,
      "z": -2,
      "name": "Wood_Oak_Trunk"
    },
    {
      "x": -10,
      "y": 17,
      "z": -2,
      "name": "Wood_Oak_Trunk"
    },
    {
      "x": -10,
      "y": 18,
      "z": -2,
      "name": "Wood_Oak_Trunk"
    },
    {
      "x": -10,
      "y": 19,
      "z": -2,
      "name": "Wood_Softwood_Roof_Flat",
      "rotation": 3
    },
    {
      "x": -10,
      "y": 0,
      "z": -1,
      "name": "Soil_Clay_Smooth_Lime"
    },
    {
      "x": -10,
      "y": 6,
      "z": -1,
      "name": "Wood_Oak_Trunk_Stairs",
      "rotation": 9
    },
    {
      "x": -10,
      "y": 7,
      "z": -1,
      "name": "Wood_Hardwood_Fence",
      "rotation": 3
    },
    {
      "x": -10,
      "y": 12,
      "z": -1,
      "name": "Wood_Hardwood_Planks_Half",
      "rotation": 8
    },
    {
      "x": -10,
      "y": 13,
      "z": -1,
      "name": "Wood_Softwood_Planks_Half",
      "rotation": 7
    },
    {
      "x": -10,
      "y": 14,
      "z": -1,
      "name": "Wood_Softwood_Planks_Half",
      "rotation": 7
    },
    {
      "x": -10,
      "y": 15,
      "z": -1,
      "name": "Wood_Softwood_Planks_Half",
      "rotation": 7
    },
    {
      "x": -10,
      "y": 16,
      "z": -1,
      "name": "Wood_Oak_Trunk",
      "rotation": 4
    },
    {
      "x": -10,
      "y": 17,
      "z": -1,
      "name": "Furniture_Village_Window",
      "rotation": 1
    },
    {
      "x": -10,
      "y": 18,
      "z": -1,
      "name": "Wood_Oak_Trunk",
      "rotation": 4
    },
    {
      "x": -10,
      "y": 19,
      "z": -1,
      "name": "Wood_Softwood_Roof_Flat",
      "rotation": 3
    },
    {
      "x": -10,
      "y": 0,
      "z": 0,
      "name": "Soil_Clay_Smooth_Lime"
    },
    {
      "x": -10,
      "y": 6,
      "z": 0,
      "name": "Wood_Oak_Trunk",
      "rotation": 5
    },
    {
      "x": -10,
      "y": 7,
      "z": 0,
      "name": "Wood_Hardwood_Fence",
      "rotation": 3
    },
    {
      "x": -10,
      "y": 10,
      "z": 0,
      "name": "*Furniture_Tavern_Trapdoor_State_Definitions_OpenDoorOut",
      "rotation": 3
    },
    {
      "x": -10,
      "y": 11,
      "z": 0,
      "name": "Wood_Oak_Trunk_Stairs",
      "rotation": 9
    },
    {
      "x": -10,
      "y": 12,
      "z": 0,
      "name": "Wood_Oak_Trunk",
      "rotation": 5
    },
    {
      "x": -10,
      "y": 13,
      "z": 0,
      "name": "Wood_Softwood_Planks_Half",
      "rotation": 7
    },
    {
      "x": -10,
      "y": 14,
      "z": 0,
      "name": "Wood_Softwood_Planks_Half",
      "rotation": 7
    },
    {
      "x": -10,
      "y": 15,
      "z": 0,
      "name": "Wood_Softwood_Planks_Half",
      "rotation": 7
    },
    {
      "x": -10,
      "y": 16,
      "z": 0,
      "name": "Wood_Oak_Trunk",
      "rotation": 4
    },
    {
      "x": -10,
      "y": 17,
      "z": 0,
      "name": "Furniture_Village_Window",
      "rotation": 1
    },
    {
      "x": -10,
      "y": 18,
      "z": 0,
      "name": "Wood_Oak_Trunk",
      "rotation": 4
    },
    {
      "x": -10,
      "y": 19,
      "z": 0,
      "name": "Wood_Softwood_Roof_Flat",
      "rotation": 3
    },
    {
      "x": -10,
      "y": 0,
      "z": 1,
      "name": "Soil_Clay_Smooth_Lime"
    },
    {
      "x": -10,
      "y": 12,
      "z": 1,
      "name": "Wood_Hardwood_Planks_Half",
      "rotation": 8
    },
    {
      "x": -10,
      "y": 13,
      "z": 1,
      "name": "Wood_Oak_Trunk"
    },
    {
      "x": -10,
      "y": 14,
      "z": 1,
      "name": "Wood_Oak_Trunk"
    },
    {
      "x": -10,
      "y": 15,
      "z": 1,
      "name": "Wood_Oak_Trunk"
    },
    {
      "x": -10,
      "y": 16,
      "z": 1,
      "name": "Wood_Oak_Trunk"
    },
    {
      "x": -10,
      "y": 17,
      "z": 1,
      "name": "Wood_Oak_Trunk"
    },
    {
      "x": -10,
      "y": 18,
      "z": 1,
      "name": "Wood_Oak_Trunk"
    },
    {
      "x": -10,
      "y": 19,
      "z": 1,
      "name": "Wood_Softwood_Roof_Flat",
      "rotation": 3
    },
    {
      "x": -10,
      "y": 0,
      "z": 2,
      "name": "Soil_Clay_Smooth_Lime"
    },
    {
      "x": -10,
      "y": 12,
      "z": 2,
      "name": "Wood_Hardwood_Planks_Half",
      "rotation": 8
    },
    {
      "x": -10,
      "y": 13,
      "z": 2,
      "name": "Wood_Softwood_Planks_Half",
      "rotation": 7
    },
    {
      "x": -10,
      "y": 14,
      "z": 2,
      "name": "Wood_Softwood_Planks_Half",
      "rotation": 7
    },
    {
      "x": -10,
      "y": 15,
      "z": 2,
      "name": "Wood_Softwood_Planks_Half",
      "rotation": 7
    },
    {
      "x": -10,
      "y": 16,
      "z": 2,
      "name": "Wood_Oak_Trunk",
      "rotation": 4
    },
    {
      "x": -10,
      "y": 17,
      "z": 2,
      "name": "Wood_Softwood_Planks"
    },
    {
      "x": -10,
      "y": 18,
      "z": 2,
      "name": "Wood_Softwood_Roof"
    },
    {
      "x": -10,
      "y": 0,
      "z": 3,
      "name": "Soil_Clay_Smooth_Lime"
    },
    {
      "x": -10,
      "y": 12,
      "z": 3,
      "name": "Wood_Hardwood_Planks_Half",
      "rotation": 8
    },
    {
      "x": -10,
      "y": 13,
      "z": 3,
      "name": "Wood_Softwood_Planks_Half",
      "rotation": 7
    },
    {
      "x": -10,
      "y": 14,
      "z": 3,
      "name": "Wood_Softwood_Planks_Half",
      "rotation": 7
    },
    {
      "x": -10,
      "y": 15,
      "z": 3,
      "name": "Wood_Softwood_Planks_Half",
      "rotation": 7
    },
    {
      "x": -10,
      "y": 16,
      "z": 3,
      "name": "Wood_Oak_Trunk",
      "rotation": 4
    },
    {
      "x": -10,
      "y": 17,
      "z": 3,
      "name": "Wood_Softwood_Roof"
    },
    {
      "x": -10,
      "y": 0,
      "z": 4,
      "name": "Soil_Clay_Smooth_Lime"
    },
    {
      "x": -10,
      "y": 12,
      "z": 4,
      "name": "Wood_Hardwood_Planks_Half",
      "rotation": 8
    },
    {
      "x": -10,
      "y": 13,
      "z": 4,
      "name": "Wood_Oak_Trunk"
    },
    {
      "x": -10,
      "y": 14,
      "z": 4,
      "name": "Wood_Oak_Trunk"
    },
    {
      "x": -10,
      "y": 15,
      "z": 4,
      "name": "Wood_Oak_Trunk"
    },
    {
      "x": -10,
      "y": 16,
      "z": 4,
      "name": "Wood_Softwood_Roof"
    },
    {
      "x": -10,
      "y": 0,
      "z": 5,
      "name": "Soil_Clay_Smooth_Lime"
    },
    {
      "x": -10,
      "y": 12,
      "z": 5,
      "name": "Wood_Hardwood_Planks_Half",
      "rotation": 8
    },
    {
      "x": -10,
      "y": 13,
      "z": 5,
      "name": "Wood_Softwood_Planks"
    },
    {
      "x": -10,
      "y": 14,
      "z": 5,
      "name": "Wood_Softwood_Planks"
    },
    {
      "x": -10,
      "y": 15,
      "z": 5,
      "name": "Wood_Softwood_Roof"
    },
    {
      "x": -10,
      "y": 0,
      "z": 6,
      "name": "Soil_Clay_Smooth_Lime"
    },
    {
      "x": -10,
      "y": 12,
      "z": 6,
      "name": "Wood_Hardwood_Planks_Half",
      "rotation": 8
    },
    {
      "x": -10,
      "y": 13,
      "z": 6,
      "name": "Wood_Softwood_Planks"
    },
    {
      "x": -10,
      "y": 14,
      "z": 6,
      "name": "Wood_Softwood_Roof"
    },
    {
      "x": -10,
      "y": 0,
      "z": 7,
      "name": "Soil_Clay_Smooth_Lime"
    },
    {
      "x": -10,
      "y": 6,
      "z": 7,
      "name": "Wood_Oak_Trunk",
      "rotation": 5
    },
    {
      "x": -10,
      "y": 10,
      "z": 7,
      "name": "*Furniture_Tavern_Trapdoor_State_Definitions_OpenDoorOut",
      "rotation": 3
    },
    {
      "x": -10,
      "y": 11,
      "z": 7,
      "name": "Wood_Oak_Trunk_Stairs",
      "rotation": 9
    },
    {
      "x": -10,
      "y": 12,
      "z": 7,
      "name": "Wood_Oak_Trunk",
      "rotation": 5
    },
    {
      "x": -10,
      "y": 13,
      "z": 7,
      "name": "Wood_Softwood_Roof"
    },
    {
      "x": -10,
      "y": 0,
      "z": 8,
      "name": "Soil_Clay_Smooth_Lime"
    },
    {
      "x": -10,
      "y": 12,
      "z": 8,
      "name": "*Wood_Softwood_Roof_Hollow_State_Definitions_Inverted_Corner_Left",
      "rotation": 3
    },
    {
      "x": -10,
      "y": 0,
      "z": 9,
      "name": "Soil_Clay_Smooth_Lime"
    },
    {
      "x": -10,
      "y": 12,
      "z": 9,
      "name": "Wood_Softwood_Roof_Hollow",
      "rotation": 3
    },
    {
      "x": -10,
      "y": 0,
      "z": 10,
      "name": "Soil_Clay_Smooth_Lime"
    },
    {
      "x": -9,
      "y": 0,
      "z": -10,
      "name": "Soil_Clay_Smooth_Lime"
    },
    {
      "x": -9,
      "y": 12,
      "z": -10,
      "name": "Wood_Oak_Branch_Short",
      "rotation": 2
    },
    {
      "x": -9,
      "y": 0,
      "z": -9,
      "name": "Soil_Clay_Smooth_Lime"
    },
    {
      "x": -9,
      "y": 6,
      "z": -9,
      "name": "Wood_Oak_Branch_Short",
      "rotation": 2
    },
    {
      "x": -9,
      "y": 12,
      "z": -9,
      "name": "Wood_Oak_Trunk",
      "rotation": 4
    },
    {
      "x": -9,
      "y": 0,
      "z": -8,
      "name": "Soil_Clay_Smooth_Lime"
    },
    {
      "x": -9,
      "y": 6,
      "z": -8,
      "name": "Wood_Oak_Trunk",
      "rotation": 4
    },
    {
      "x": -9,
      "y": 10,
      "z": -8,
      "name": "*Furniture_Tavern_Trapdoor_State_Definitions_OpenDoorOut",
      "rotation": 2
    },
    {
      "x": -9,
      "y": 11,
      "z": -8,
      "name": "Wood_Oak_Trunk_Stairs",
      "rotation": 8
    },
    {
      "x": -9,
      "y": 12,
      "z": -8,
      "name": "Wood_Oak_Trunk",
      "rotation": 4
    },
    {
      "x": -9,
      "y": 13,
      "z": -8,
      "name": "Wood_Softwood_Roof",
      "rotation": 2
    },
    {
      "x": -9,
      "y": 0,
      "z": -7,
      "name": "Soil_Clay_Smooth_Lime"
    },
    {
      "x": -9,
      "y": 6,
      "z": -7,
      "name": "Wood_Oak_Trunk",
      "rotation": 5
    },
    {
      "x": -9,
      "y": 7,
      "z": -7,
      "name": "Wood_Oak_Trunk"
    },
    {
      "x": -9,
      "y": 8,
      "z": -7,
      "name": "Wood_Oak_Trunk"
    },
    {
      "x": -9,
      "y": 9,
      "z": -7,
      "name": "Wood_Oak_Trunk"
    },
    {
      "x": -9,
      "y": 10,
      "z": -7,
      "name": "Wood_Oak_Trunk"
    },
    {
      "x": -9,
      "y": 11,
      "z": -7,
      "name": "Wood_Oak_Trunk"
    },
    {
      "x": -9,
      "y": 12,
      "z": -7,
      "name": "Wood_Oak_Trunk"
    },
    {
      "x": -9,
      "y": 14,
      "z": -7,
      "name": "Wood_Softwood_Roof_Hollow",
      "rotation": 2
    },
    {
      "x": -9,
      "y": 0,
      "z": -6,
      "name": "Soil_Clay_Smooth_Lime"
    },
    {
      "x": -9,
      "y": 1,
      "z": -6,
      "name": "Wood_Oak_Trunk_Stairs",
      "rotation": 3
    },
    {
      "x": -9,
      "y": 4,
      "z": -6,
      "name": "*Furniture_Tavern_Trapdoor_State_Definitions_OpenDoorOut",
      "rotation": 3
    },
    {
      "x": -9,
      "y": 5,
      "z": -6,
      "name": "Wood_Oak_Trunk_Stairs",
      "rotation": 9
    },
    {
      "x": -9,
      "y": 6,
      "z": -6,
      "name": "Wood_Oak_Trunk",
      "rotation": 4
    },
    {
      "x": -9,
      "y": 7,
      "z": -6,
      "name": "Soil_Clay_Brick_Half",
      "rotation": 7
    },
    {
      "x": -9,
      "y": 8,
      "z": -6,
      "name": "Soil_Clay_Brick_Half",
      "rotation": 7
    },
    {
      "x": -9,
      "y": 9,
      "z": -6,
      "name": "Soil_Clay_Brick_Half",
      "rotation": 7
    },
    {
      "x": -9,
      "y": 10,
      "z": -6,
      "name": "Soil_Clay_Brick_Half",
      "rotation": 7
    },
    {
      "x": -9,
      "y": 11,
      "z": -6,
      "name": "Soil_Clay_Brick_Half",
      "rotation": 7
    },
    {
      "x": -9,
      "y": 12,
      "z": -6,
      "name": "Wood_Oak_Trunk",
      "rotation": 4
    },
    {
      "x": -9,
      "y": 15,
      "z": -6,
      "name": "Wood_Softwood_Roof_Hollow",
      "rotation": 2
    },
    {
      "x": -9,
      "y": 0,
      "z": -5,
      "name": "Soil_Clay_Smooth_Lime"
    },
    {
      "x": -9,
      "y": 6,
      "z": -5,
      "name": "Wood_Oak_Trunk",
      "rotation": 4
    },
    {
      "x": -9,
      "y": 7,
      "z": -5,
      "name": "Wood_Oak_Trunk"
    },
    {
      "x": -9,
      "y": 8,
      "z": -5,
      "name": "Wood_Oak_Trunk"
    },
    {
      "x": -9,
      "y": 9,
      "z": -5,
      "name": "Wood_Oak_Trunk"
    },
    {
      "x": -9,
      "y": 10,
      "z": -5,
      "name": "Wood_Oak_Trunk"
    },
    {
      "x": -9,
      "y": 11,
      "z": -5,
      "name": "Wood_Oak_Trunk"
    },
    {
      "x": -9,
      "y": 12,
      "z": -5,
      "name": "Wood_Oak_Trunk",
      "rotation": 4
    },
    {
      "x": -9,
      "y": 16,
      "z": -5,
      "name": "Wood_Softwood_Roof_Hollow",
      "rotation": 2
    },
    {
      "x": -9,
      "y": 0,
      "z": -4,
      "name": "Soil_Clay_Smooth_Lime"
    },
    {
      "x": -9,
      "y": 6,
      "z": -4,
      "name": "Wood_Oak_Trunk",
      "rotation": 4
    },
    {
      "x": -9,
      "y": 7,
      "z": -4,
      "name": "Rock_Chalk_Brick_Half",
      "rotation": 7
    },
    {
      "x": -9,
      "y": 8,
      "z": -4,
      "name": "Rock_Chalk_Brick_Half",
      "rotation": 7
    },
    {
      "x": -9,
      "y": 9,
      "z": -4,
      "name": "Rock_Chalk_Brick_Half",
      "rotation": 7
    },
    {
      "x": -9,
      "y": 10,
      "z": -4,
      "name": "Wood_Oak_Trunk",
      "rotation": 4
    },
    {
      "x": -9,
      "y": 11,
      "z": -4,
      "name": "Rock_Chalk_Brick_Half",
      "rotation": 7
    },
    {
      "x": -9,
      "y": 12,
      "z": -4,
      "name": "Wood_Oak_Trunk",
      "rotation": 4
    },
    {
      "x": -9,
      "y": 17,
      "z": -4,
      "name": "Wood_Softwood_Roof_Hollow",
      "rotation": 2
    },
    {
      "x": -9,
      "y": 0,
      "z": -3,
      "name": "Soil_Clay_Smooth_Lime"
    },
    {
      "x": -9,
      "y": 6,
      "z": -3,
      "name": "Wood_Oak_Trunk",
      "rotation": 4
    },
    {
      "x": -9,
      "y": 7,
      "z": -3,
      "name": "*Furniture_Village_Door_State_Definitions_CloseDoorOut",
      "rotation": 3
    },
    {
      "x": -9,
      "y": 8,
      "z": -3,
      "name": "*Furniture_Village_Door_State_Definitions_CloseDoorOut",
      "filler": 1024,
      "rotation": 3
    },
    {
      "x": -9,
      "y": 9,
      "z": -3,
      "name": "Rock_Chalk_Brick_Half",
      "rotation": 7
    },
    {
      "x": -9,
      "y": 10,
      "z": -3,
      "name": "Wood_Oak_Trunk",
      "rotation": 4
    },
    {
      "x": -9,
      "y": 11,
      "z": -3,
      "name": "Furniture_Human_Ruins_Window",
      "rotation": 1
    },
    {
      "x": -9,
      "y": 12,
      "z": -3,
      "name": "Wood_Oak_Trunk",
      "rotation": 4
    },
    {
      "x": -9,
      "y": 18,
      "z": -3,
      "name": "Wood_Softwood_Roof_Hollow",
      "rotation": 2
    },
    {
      "x": -9,
      "y": 0,
      "z": -2,
      "name": "Soil_Clay_Smooth_Lime"
    },
    {
      "x": -9,
      "y": 6,
      "z": -2,
      "name": "Wood_Oak_Trunk",
      "rotation": 4
    },
    {
      "x": -9,
      "y": 7,
      "z": -2,
      "name": "*Furniture_Village_Door_State_Definitions_CloseDoorIn",
      "rotation": 1
    },
    {
      "x": -9,
      "y": 8,
      "z": -2,
      "name": "*Furniture_Village_Door_State_Definitions_CloseDoorIn",
      "filler": 1024,
      "rotation": 1
    },
    {
      "x": -9,
      "y": 9,
      "z": -2,
      "name": "Rock_Chalk_Brick_Half",
      "rotation": 7
    },
    {
      "x": -9,
      "y": 10,
      "z": -2,
      "name": "Wood_Oak_Trunk",
      "rotation": 4
    },
    {
      "x": -9,
      "y": 11,
      "z": -2,
      "name": "Furniture_Human_Ruins_Window",
      "rotation": 1
    },
    {
      "x": -9,
      "y": 12,
      "z": -2,
      "name": "Wood_Oak_Trunk",
      "rotation": 4
    },
    {
      "x": -9,
      "y": 19,
      "z": -2,
      "name": "Wood_Softwood_Roof_Flat",
      "rotation": 3
    },
    {
      "x": -9,
      "y": 0,
      "z": -1,
      "name": "Soil_Clay_Smooth_Lime"
    },
    {
      "x": -9,
      "y": 6,
      "z": -1,
      "name": "Wood_Oak_Trunk",
      "rotation": 4
    },
    {
      "x": -9,
      "y": 7,
      "z": -1,
      "name": "Rock_Chalk_Brick_Half",
      "rotation": 7
    },
    {
      "x": -9,
      "y": 8,
      "z": -1,
      "name": "Rock_Chalk_Brick_Half",
      "rotation": 7
    },
    {
      "x": -9,
      "y": 9,
      "z": -1,
      "name": "Rock_Chalk_Brick_Half",
      "rotation": 7
    },
    {
      "x": -9,
      "y": 10,
      "z": -1,
      "name": "Wood_Oak_Trunk",
      "rotation": 4
    },
    {
      "x": -9,
      "y": 11,
      "z": -1,
      "name": "Rock_Chalk_Brick_Half",
      "rotation": 7
    },
    {
      "x": -9,
      "y": 12,
      "z": -1,
      "name": "Wood_Oak_Trunk",
      "rotation": 4
    },
    {
      "x": -9,
      "y": 19,
      "z": -1,
      "name": "Wood_Softwood_Roof_Flat",
      "rotation": 3
    },
    {
      "x": -9,
      "y": 0,
      "z": 0,
      "name": "Soil_Clay_Smooth_Lime"
    },
    {
      "x": -9,
      "y": 1,
      "z": 0,
      "name": "Wood_Oak_Trunk_Stairs",
      "rotation": 3
    },
    {
      "x": -9,
      "y": 4,
      "z": 0,
      "name": "*Furniture_Tavern_Trapdoor_State_Definitions_OpenDoorOut",
      "rotation": 3
    },
    {
      "x": -9,
      "y": 5,
      "z": 0,
      "name": "Wood_Oak_Trunk_Stairs",
      "rotation": 9
    },
    {
      "x": -9,
      "y": 6,
      "z": 0,
      "name": "Wood_Oak_Trunk",
      "rotation": 4
    },
    {
      "x": -9,
      "y": 7,
      "z": 0,
      "name": "Wood_Oak_Trunk"
    },
    {
      "x": -9,
      "y": 8,
      "z": 0,
      "name": "Wood_Oak_Trunk"
    },
    {
      "x": -9,
      "y": 9,
      "z": 0,
      "name": "Wood_Oak_Trunk"
    },
    {
      "x": -9,
      "y": 10,
      "z": 0,
      "name": "Wood_Oak_Trunk"
    },
    {
      "x": -9,
      "y": 11,
      "z": 0,
      "name": "Wood_Oak_Trunk"
    },
    {
      "x": -9,
      "y": 12,
      "z": 0,
      "name": "Wood_Oak_Trunk"
    },
    {
      "x": -9,
      "y": 19,
      "z": 0,
      "name": "Wood_Softwood_Roof_Flat",
      "rotation": 3
    },
    {
      "x": -9,
      "y": 0,
      "z": 1,
      "name": "Soil_Clay_Smooth_Lime"
    },
    {
      "x": -9,
      "y": 6,
      "z": 1,
      "name": "Wood_Oak_Trunk",
      "rotation": 4
    },
    {
      "x": -9,
      "y": 7,
      "z": 1,
      "name": "Rock_Chalk_Brick_Half",
      "rotation": 7
    },
    {
      "x": -9,
      "y": 8,
      "z": 1,
      "name": "Rock_Chalk_Brick_Half",
      "rotation": 7
    },
    {
      "x": -9,
      "y": 9,
      "z": 1,
      "name": "Rock_Chalk_Brick_Half",
      "rotation": 7
    },
    {
      "x": -9,
      "y": 10,
      "z": 1,
      "name": "Rock_Chalk_Brick_Half",
      "rotation": 7
    },
    {
      "x": -9,
      "y": 11,
      "z": 1,
      "name": "Rock_Chalk_Brick_Half",
      "rotation": 7
    },
    {
      "x": -9,
      "y": 12,
      "z": 1,
      "name": "Wood_Oak_Trunk",
      "rotation": 4
    },
    {
      "x": -9,
      "y": 19,
      "z": 1,
      "name": "Wood_Softwood_Roof_Flat",
      "rotation": 3
    },
    {
      "x": -9,
      "y": 0,
      "z": 2,
      "name": "Soil_Clay_Smooth_Lime"
    },
    {
      "x": -9,
      "y": 6,
      "z": 2,
      "name": "Wood_Oak_Trunk",
      "rotation": 4
    },
    {
      "x": -9,
      "y": 7,
      "z": 2,
      "name": "*Wood_Village_Wall_White_Full_State_Definitions_Bottom"
    },
    {
      "x": -9,
      "y": 8,
      "z": 2,
      "name": "*Wood_Village_Wall_White_Full_State_Definitions_Middle"
    },
    {
      "x": -9,
      "y": 9,
      "z": 2,
      "name": "*Wood_Village_Wall_White_Full_State_Definitions_Middle"
    },
    {
      "x": -9,
      "y": 10,
      "z": 2,
      "name": "*Wood_Village_Wall_White_Full_State_Definitions_Middle"
    },
    {
      "x": -9,
      "y": 11,
      "z": 2,
      "name": "*Wood_Village_Wall_White_Full_State_Definitions_Top"
    },
    {
      "x": -9,
      "y": 12,
      "z": 2,
      "name": "Wood_Oak_Trunk",
      "rotation": 4
    },
    {
      "x": -9,
      "y": 18,
      "z": 2,
      "name": "Wood_Softwood_Roof_Hollow"
    },
    {
      "x": -9,
      "y": 0,
      "z": 3,
      "name": "Soil_Clay_Smooth_Lime"
    },
    {
      "x": -9,
      "y": 6,
      "z": 3,
      "name": "Wood_Oak_Trunk",
      "rotation": 4
    },
    {
      "x": -9,
      "y": 7,
      "z": 3,
      "name": "Wood_Village_Wall_White_Full"
    },
    {
      "x": -9,
      "y": 8,
      "z": 3,
      "name": "Furniture_Human_Ruins_Window",
      "rotation": 1
    },
    {
      "x": -9,
      "y": 9,
      "z": 3,
      "name": "Furniture_Human_Ruins_Window",
      "rotation": 1
    },
    {
      "x": -9,
      "y": 10,
      "z": 3,
      "name": "Furniture_Human_Ruins_Window",
      "rotation": 1
    },
    {
      "x": -9,
      "y": 11,
      "z": 3,
      "name": "Wood_Village_Wall_White_Full"
    },
    {
      "x": -9,
      "y": 12,
      "z": 3,
      "name": "Wood_Oak_Trunk",
      "rotation": 4
    },
    {
      "x": -9,
      "y": 17,
      "z": 3,
      "name": "Wood_Softwood_Roof_Hollow"
    },
    {
      "x": -9,
      "y": 0,
      "z": 4,
      "name": "Soil_Clay_Smooth_Lime"
    },
    {
      "x": -9,
      "y": 6,
      "z": 4,
      "name": "Wood_Oak_Trunk",
      "rotation": 4
    },
    {
      "x": -9,
      "y": 7,
      "z": 4,
      "name": "*Wood_Village_Wall_White_Full_State_Definitions_Bottom"
    },
    {
      "x": -9,
      "y": 8,
      "z": 4,
      "name": "*Wood_Village_Wall_White_Full_State_Definitions_Middle"
    },
    {
      "x": -9,
      "y": 9,
      "z": 4,
      "name": "*Wood_Village_Wall_White_Full_State_Definitions_Middle"
    },
    {
      "x": -9,
      "y": 10,
      "z": 4,
      "name": "*Wood_Village_Wall_White_Full_State_Definitions_Middle"
    },
    {
      "x": -9,
      "y": 11,
      "z": 4,
      "name": "*Wood_Village_Wall_White_Full_State_Definitions_Top"
    },
    {
      "x": -9,
      "y": 12,
      "z": 4,
      "name": "Wood_Oak_Trunk",
      "rotation": 4
    },
    {
      "x": -9,
      "y": 16,
      "z": 4,
      "name": "Wood_Softwood_Roof_Hollow"
    },
    {
      "x": -9,
      "y": 0,
      "z": 5,
      "name": "Soil_Clay_Smooth_Lime"
    },
    {
      "x": -9,
      "y": 6,
      "z": 5,
      "name": "Wood_Oak_Trunk",
      "rotation": 4
    },
    {
      "x": -9,
      "y": 7,
      "z": 5,
      "name": "Rock_Chalk_Brick_Half",
      "rotation": 7
    },
    {
      "x": -9,
      "y": 8,
      "z": 5,
      "name": "Rock_Chalk_Brick_Half",
      "rotation": 7
    },
    {
      "x": -9,
      "y": 9,
      "z": 5,
      "name": "Rock_Chalk_Brick_Half",
      "rotation": 7
    },
    {
      "x": -9,
      "y": 10,
      "z": 5,
      "name": "Rock_Chalk_Brick_Half",
      "rotation": 7
    },
    {
      "x": -9,
      "y": 11,
      "z": 5,
      "name": "Rock_Chalk_Brick_Half",
      "rotation": 7
    },
    {
      "x": -9,
      "y": 12,
      "z": 5,
      "name": "Wood_Oak_Trunk",
      "rotation": 4
    },
    {
      "x": -9,
      "y": 15,
      "z": 5,
      "name": "Wood_Softwood_Roof_Hollow"
    },
    {
      "x": -9,
      "y": 0,
      "z": 6,
      "name": "Soil_Clay_Smooth_Lime"
    },
    {
      "x": -9,
      "y": 1,
      "z": 6,
      "name": "Wood_Oak_Trunk_Stairs",
      "rotation": 3
    },
    {
      "x": -9,
      "y": 4,
      "z": 6,
      "name": "*Furniture_Tavern_Trapdoor_State_Definitions_OpenDoorOut",
      "rotation": 3
    },
    {
      "x": -9,
      "y": 5,
      "z": 6,
      "name": "Wood_Oak_Trunk_Stairs",
      "rotation": 9
    },
    {
      "x": -9,
      "y": 6,
      "z": 6,
      "name": "Wood_Oak_Trunk",
      "rotation": 4
    },
    {
      "x": -9,
      "y": 7,
      "z": 6,
      "name": "Rock_Chalk_Brick_Half",
      "rotation": 7
    },
    {
      "x": -9,
      "y": 8,
      "z": 6,
      "name": "Rock_Chalk_Brick_Half",
      "rotation": 7
    },
    {
      "x": -9,
      "y": 9,
      "z": 6,
      "name": "Rock_Chalk_Brick_Half",
      "rotation": 7
    },
    {
      "x": -9,
      "y": 10,
      "z": 6,
      "name": "Rock_Chalk_Brick_Half",
      "rotation": 7
    },
    {
      "x": -9,
      "y": 11,
      "z": 6,
      "name": "Rock_Chalk_Brick_Half",
      "rotation": 7
    },
    {
      "x": -9,
      "y": 12,
      "z": 6,
      "name": "Wood_Oak_Trunk",
      "rotation": 4
    },
    {
      "x": -9,
      "y": 14,
      "z": 6,
      "name": "Wood_Softwood_Roof_Hollow"
    },
    {
      "x": -9,
      "y": 0,
      "z": 7,
      "name": "Soil_Clay_Smooth_Lime"
    },
    {
      "x": -9,
      "y": 6,
      "z": 7,
      "name": "Wood_Oak_Trunk",
      "rotation": 4
    },
    {
      "x": -9,
      "y": 7,
      "z": 7,
      "name": "Wood_Oak_Trunk"
    },
    {
      "x": -9,
      "y": 8,
      "z": 7,
      "name": "Wood_Oak_Trunk"
    },
    {
      "x": -9,
      "y": 9,
      "z": 7,
      "name": "Wood_Oak_Trunk"
    },
    {
      "x": -9,
      "y": 10,
      "z": 7,
      "name": "Wood_Oak_Trunk"
    },
    {
      "x": -9,
      "y": 11,
      "z": 7,
      "name": "Wood_Oak_Trunk"
    },
    {
      "x": -9,
      "y": 12,
      "z": 7,
      "name": "Wood_Oak_Trunk"
    },
    {
      "x": -9,
      "y": 13,
      "z": 7,
      "name": "*Wood_Softwood_Roof_State_Definitions_Inverted_Corner_Left",
      "rotation": 3
    },
    {
      "x": -9,
      "y": 0,
      "z": 8,
      "name": "Soil_Clay_Smooth_Lime"
    },
    {
      "x": -9,
      "y": 6,
      "z": 8,
      "name": "Wood_Oak_Trunk",
      "rotation": 4
    },
    {
      "x": -9,
      "y": 10,
      "z": 8,
      "name": "*Furniture_Tavern_Trapdoor_State_Definitions_OpenDoorOut"
    },
    {
      "x": -9,
      "y": 11,
      "z": 8,
      "name": "Wood_Oak_Trunk_Stairs",
      "rotation": 10
    },
    {
      "x": -9,
      "y": 12,
      "z": 8,
      "name": "Wood_Oak_Trunk",
      "rotation": 4
    },
    {
      "x": -9,
      "y": 13,
      "z": 8,
      "name": "Wood_Softwood_Roof",
      "rotation": 3
    },
    {
      "x": -9,
      "y": 0,
      "z": 9,
      "name": "Soil_Clay_Smooth_Lime"
    },
    {
      "x": -9,
      "y": 6,
      "z": 9,
      "name": "Wood_Oak_Branch_Short"
    },
    {
      "x": -9,
      "y": 12,
      "z": 9,
      "name": "Wood_Oak_Trunk",
      "rotation": 4
    },
    {
      "x": -9,
      "y": 13,
      "z": 9,
      "name": "Wood_Softwood_Roof",
      "rotation": 3
    },
    {
      "x": -9,
      "y": 0,
      "z": 10,
      "name": "Soil_Clay_Smooth_Lime"
    },
    {
      "x": -9,
      "y": 12,
      "z": 10,
      "name": "Wood_Oak_Branch_Short"
    },
    {
      "x": -8,
      "y": 0,
      "z": -10,
      "name": "Soil_Clay_Smooth_Lime"
    },
    {
      "x": -8,
      "y": 0,
      "z": -9,
      "name": "Soil_Clay_Smooth_Lime"
    },
    {
      "x": -8,
      "y": 12,
      "z": -9,
      "name": "Wood_Softwood_Roof_Hollow",
      "rotation": 2
    },
    {
      "x": -8,
      "y": 0,
      "z": -8,
      "name": "Soil_Clay_Smooth_Lime"
    },
    {
      "x": -8,
      "y": 12,
      "z": -8,
      "name": "Wood_Hardwood_Planks_Half",
      "rotation": 8
    },
    {
      "x": -8,
      "y": 13,
      "z": -8,
      "name": "Wood_Softwood_Roof",
      "rotation": 2
    },
    {
      "x": -8,
      "y": 0,
      "z": -7,
      "name": "Soil_Clay_Smooth_Lime"
    },
    {
      "x": -8,
      "y": 1,
      "z": -7,
      "name": "Wood_Oak_Trunk_Stairs",
      "rotation": 2
    },
    {
      "x": -8,
      "y": 4,
      "z": -7,
      "name": "*Furniture_Tavern_Trapdoor_State_Definitions_OpenDoorOut",
      "rotation": 2
    },
    {
      "x": -8,
      "y": 5,
      "z": -7,
      "name": "Wood_Oak_Trunk_Stairs",
      "rotation": 8
    },
    {
      "x": -8,
      "y": 6,
      "z": -7,
      "name": "Wood_Oak_Trunk",
      "rotation": 5
    },
    {
      "x": -8,
      "y": 7,
      "z": -7,
      "name": "Soil_Clay_Brick_Half",
      "rotation": 6
    },
    {
      "x": -8,
      "y": 8,
      "z": -7,
      "name": "Soil_Clay_Brick_Half",
      "rotation": 6
    },
    {
      "x": -8,
      "y": 9,
      "z": -7,
      "name": "Soil_Clay_Brick_Half",
      "rotation": 6
    },
    {
      "x": -8,
      "y": 10,
      "z": -7,
      "name": "Soil_Clay_Brick_Half",
      "rotation": 6
    },
    {
      "x": -8,
      "y": 11,
      "z": -7,
      "name": "Soil_Clay_Brick_Half",
      "rotation": 6
    },
    {
      "x": -8,
      "y": 12,
      "z": -7,
      "name": "Wood_Oak_Trunk",
      "rotation": 5
    },
    {
      "x": -8,
      "y": 14,
      "z": -7,
      "name": "Wood_Softwood_Roof_Hollow",
      "rotation": 2
    },
    {
      "x": -8,
      "y": 0,
      "z": -6,
      "name": "Soil_Clay_Smooth_Lime"
    },
    {
      "x": -8,
      "y": 1,
      "z": -6,
      "name": "Wood_Oak_Trunk",
      "support": 15
    },
    {
      "x": -8,
      "y": 2,
      "z": -6,
      "name": "Wood_Oak_Trunk"
    },
    {
      "x": -8,
      "y": 3,
      "z": -6,
      "name": "Wood_Oak_Trunk"
    },
    {
      "x": -8,
      "y": 4,
      "z": -6,
      "name": "Wood_Oak_Trunk"
    },
    {
      "x": -8,
      "y": 5,
      "z": -6,
      "name": "Wood_Oak_Trunk"
    },
    {
      "x": -8,
      "y": 6,
      "z": -6,
      "name": "Wood_Hardwood_Planks"
    },
    {
      "x": -8,
      "y": 12,
      "z": -6,
      "name": "Wood_Hardwood_Planks"
    },
    {
      "x": -8,
      "y": 15,
      "z": -6,
      "name": "Wood_Softwood_Roof_Hollow",
      "rotation": 2
    },
    {
      "x": -8,
      "y": 0,
      "z": -5,
      "name": "Soil_Clay_Smooth_Lime"
    },
    {
      "x": -8,
      "y": 1,
      "z": -5,
      "name": "Wood_Oak_Trunk_Stairs"
    },
    {
      "x": -8,
      "y": 4,
      "z": -5,
      "name": "*Furniture_Tavern_Trapdoor_State_Definitions_OpenDoorOut"
    },
    {
      "x": -8,
      "y": 5,
      "z": -5,
      "name": "Wood_Oak_Trunk_Stairs",
      "rotation": 10
    },
    {
      "x": -8,
      "y": 6,
      "z": -5,
      "name": "Wood_Hardwood_Planks"
    },
    {
      "x": -8,
      "y": 12,
      "z": -5,
      "name": "Wood_Hardwood_Planks"
    },
    {
      "x": -8,
      "y": 16,
      "z": -5,
      "name": "Wood_Softwood_Roof_Hollow",
      "rotation": 2
    },
    {
      "x": -8,
      "y": 0,
      "z": -4,
      "name": "Soil_Clay_Smooth_Lime"
    },
    {
      "x": -8,
      "y": 5,
      "z": -4,
      "name": "Furniture_Tavern_Trapdoor",
      "rotation": 1
    },
    {
      "x": -8,
      "y": 6,
      "z": -4,
      "name": "Wood_Hardwood_Planks"
    },
    {
      "x": -8,
      "y": 12,
      "z": -4,
      "name": "Wood_Hardwood_Planks"
    },
    {
      "x": -8,
      "y": 17,
      "z": -4,
      "name": "Wood_Softwood_Roof_Hollow",
      "rotation": 2
    },
    {
      "x": -8,
      "y": 0,
      "z": -3,
      "name": "Soil_Clay_Smooth_Lime"
    },
    {
      "x": -8,
      "y": 5,
      "z": -3,
      "name": "Furniture_Tavern_Trapdoor",
      "rotation": 1
    },
    {
      "x": -8,
      "y": 6,
      "z": -3,
      "name": "Wood_Hardwood_Planks"
    },
    {
      "x": -8,
      "y": 12,
      "z": -3,
      "name": "Wood_Hardwood_Planks"
    },
    {
      "x": -8,
      "y": 18,
      "z": -3,
      "name": "Wood_Softwood_Roof_Hollow",
      "rotation": 2
    },
    {
      "x": -8,
      "y": 0,
      "z": -2,
      "name": "Soil_Clay_Smooth_Lime"
    },
    {
      "x": -8,
      "y": 5,
      "z": -2,
      "name": "Furniture_Tavern_Trapdoor",
      "rotation": 1
    },
    {
      "x": -8,
      "y": 6,
      "z": -2,
      "name": "Wood_Hardwood_Planks"
    },
    {
      "x": -8,
      "y": 12,
      "z": -2,
      "name": "Wood_Hardwood_Planks"
    },
    {
      "x": -8,
      "y": 19,
      "z": -2,
      "name": "Wood_Softwood_Roof_Flat",
      "rotation": 3
    },
    {
      "x": -8,
      "y": 0,
      "z": -1,
      "name": "Soil_Clay_Smooth_Lime"
    },
    {
      "x": -8,
      "y": 1,
      "z": -1,
      "name": "Wood_Oak_Trunk_Stairs",
      "rotation": 2
    },
    {
      "x": -8,
      "y": 4,
      "z": -1,
      "name": "*Furniture_Tavern_Trapdoor_State_Definitions_OpenDoorOut",
      "rotation": 2
    },
    {
      "x": -8,
      "y": 5,
      "z": -1,
      "name": "Wood_Oak_Trunk_Stairs",
      "rotation": 8
    },
    {
      "x": -8,
      "y": 6,
      "z": -1,
      "name": "Wood_Hardwood_Planks"
    },
    {
      "x": -8,
      "y": 12,
      "z": -1,
      "name": "Wood_Hardwood_Planks"
    },
    {
      "x": -8,
      "y": 19,
      "z": -1,
      "name": "Wood_Softwood_Roof_Flat",
      "rotation": 3
    },
    {
      "x": -8,
      "y": 0,
      "z": 0,
      "name": "Soil_Clay_Smooth_Lime"
    },
    {
      "x": -8,
      "y": 1,
      "z": 0,
      "name": "Wood_Oak_Trunk",
      "support": 15
    },
    {
      "x": -8,
      "y": 2,
      "z": 0,
      "name": "Wood_Oak_Trunk"
    },
    {
      "x": -8,
      "y": 3,
      "z": 0,
      "name": "Wood_Oak_Trunk"
    },
    {
      "x": -8,
      "y": 4,
      "z": 0,
      "name": "Wood_Oak_Trunk"
    },
    {
      "x": -8,
      "y": 5,
      "z": 0,
      "name": "Wood_Oak_Trunk"
    },
    {
      "x": -8,
      "y": 6,
      "z": 0,
      "name": "Wood_Hardwood_Planks"
    },
    {
      "x": -8,
      "y": 12,
      "z": 0,
      "name": "Wood_Hardwood_Planks"
    },
    {
      "x": -8,
      "y": 19,
      "z": 0,
      "name": "Wood_Softwood_Roof_Flat",
      "rotation": 3
    },
    {
      "x": -8,
      "y": 0,
      "z": 1,
      "name": "Soil_Clay_Smooth_Lime"
    },
    {
      "x": -8,
      "y": 1,
      "z": 1,
      "name": "Wood_Oak_Trunk_Stairs"
    },
    {
      "x": -8,
      "y": 4,
      "z": 1,
      "name": "*Furniture_Tavern_Trapdoor_State_Definitions_OpenDoorOut"
    },
    {
      "x": -8,
      "y": 5,
      "z": 1,
      "name": "Wood_Oak_Trunk_Stairs",
      "rotation": 10
    },
    {
      "x": -8,
      "y": 6,
      "z": 1,
      "name": "Wood_Hardwood_Planks"
    },
    {
      "x": -8,
      "y": 12,
      "z": 1,
      "name": "Wood_Hardwood_Planks"
    },
    {
      "x": -8,
      "y": 19,
      "z": 1,
      "name": "Wood_Softwood_Roof_Flat",
      "rotation": 3
    },
    {
      "x": -8,
      "y": 0,
      "z": 2,
      "name": "Soil_Clay_Smooth_Lime"
    },
    {
      "x": -8,
      "y": 5,
      "z": 2,
      "name": "Furniture_Tavern_Trapdoor",
      "rotation": 1
    },
    {
      "x": -8,
      "y": 6,
      "z": 2,
      "name": "Wood_Hardwood_Planks"
    },
    {
      "x": -8,
      "y": 12,
      "z": 2,
      "name": "Wood_Hardwood_Planks"
    },
    {
      "x": -8,
      "y": 18,
      "z": 2,
      "name": "Wood_Softwood_Roof_Hollow"
    },
    {
      "x": -8,
      "y": 0,
      "z": 3,
      "name": "Soil_Clay_Smooth_Lime"
    },
    {
      "x": -8,
      "y": 5,
      "z": 3,
      "name": "Furniture_Tavern_Trapdoor",
      "rotation": 1
    },
    {
      "x": -8,
      "y": 6,
      "z": 3,
      "name": "Wood_Hardwood_Planks"
    },
    {
      "x": -8,
      "y": 12,
      "z": 3,
      "name": "Wood_Hardwood_Planks"
    },
    {
      "x": -8,
      "y": 17,
      "z": 3,
      "name": "Wood_Softwood_Roof_Hollow"
    },
    {
      "x": -8,
      "y": 0,
      "z": 4,
      "name": "Soil_Clay_Smooth_Lime"
    },
    {
      "x": -8,
      "y": 5,
      "z": 4,
      "name": "Furniture_Tavern_Trapdoor",
      "rotation": 1
    },
    {
      "x": -8,
      "y": 6,
      "z": 4,
      "name": "Wood_Hardwood_Planks"
    },
    {
      "x": -8,
      "y": 12,
      "z": 4,
      "name": "Wood_Hardwood_Planks"
    },
    {
      "x": -8,
      "y": 16,
      "z": 4,
      "name": "Wood_Softwood_Roof_Hollow"
    },
    {
      "x": -8,
      "y": 0,
      "z": 5,
      "name": "Soil_Clay_Smooth_Lime"
    },
    {
      "x": -8,
      "y": 1,
      "z": 5,
      "name": "Wood_Oak_Trunk_Stairs",
      "rotation": 2
    },
    {
      "x": -8,
      "y": 4,
      "z": 5,
      "name": "*Furniture_Tavern_Trapdoor_State_Definitions_OpenDoorOut",
      "rotation": 2
    },
    {
      "x": -8,
      "y": 5,
      "z": 5,
      "name": "Wood_Oak_Trunk_Stairs",
      "rotation": 8
    },
    {
      "x": -8,
      "y": 6,
      "z": 5,
      "name": "Wood_Hardwood_Planks"
    },
    {
      "x": -8,
      "y": 12,
      "z": 5,
      "name": "Wood_Hardwood_Planks"
    },
    {
      "x": -8,
      "y": 15,
      "z": 5,
      "name": "Wood_Softwood_Roof_Hollow"
    },
    {
      "x": -8,
      "y": 0,
      "z": 6,
      "name": "Soil_Clay_Smooth_Lime"
    },
    {
      "x": -8,
      "y": 1,
      "z": 6,
      "name": "Wood_Oak_Trunk",
      "support": 15
    },
    {
      "x": -8,
      "y": 2,
      "z": 6,
      "name": "Wood_Oak_Trunk"
    },
    {
      "x": -8,
      "y": 3,
      "z": 6,
      "name": "Wood_Oak_Trunk"
    },
    {
      "x": -8,
      "y": 4,
      "z": 6,
      "name": "Wood_Oak_Trunk"
    },
    {
      "x": -8,
      "y": 5,
      "z": 6,
      "name": "Wood_Oak_Trunk"
    },
    {
      "x": -8,
      "y": 6,
      "z": 6,
      "name": "Wood_Hardwood_Planks"
    },
    {
      "x": -8,
      "y": 12,
      "z": 6,
      "name": "Wood_Hardwood_Planks"
    },
    {
      "x": -8,
      "y": 14,
      "z": 6,
      "name": "*Wood_Softwood_Roof_Hollow_State_Definitions_Inverted_Corner_Left",
      "rotation": 3
    },
    {
      "x": -8,
      "y": 0,
      "z": 7,
      "name": "Soil_Clay_Smooth_Lime"
    },
    {
      "x": -8,
      "y": 1,
      "z": 7,
      "name": "Wood_Oak_Trunk_Stairs"
    },
    {
      "x": -8,
      "y": 4,
      "z": 7,
      "name": "*Furniture_Tavern_Trapdoor_State_Definitions_OpenDoorOut"
    },
    {
      "x": -8,
      "y": 5,
      "z": 7,
      "name": "Wood_Oak_Trunk_Stairs",
      "rotation": 10
    },
    {
      "x": -8,
      "y": 6,
      "z": 7,
      "name": "Wood_Oak_Trunk",
      "rotation": 5
    },
    {
      "x": -8,
      "y": 7,
      "z": 7,
      "name": "Rock_Chalk_Brick_Half",
      "rotation": 4
    },
    {
      "x": -8,
      "y": 8,
      "z": 7,
      "name": "Rock_Chalk_Brick_Half",
      "rotation": 4
    },
    {
      "x": -8,
      "y": 9,
      "z": 7,
      "name": "Rock_Chalk_Brick_Half",
      "rotation": 4
    },
    {
      "x": -8,
      "y": 10,
      "z": 7,
      "name": "Rock_Chalk_Brick_Half",
      "rotation": 4
    },
    {
      "x": -8,
      "y": 11,
      "z": 7,
      "name": "Rock_Chalk_Brick_Half",
      "rotation": 4
    },
    {
      "x": -8,
      "y": 12,
      "z": 7,
      "name": "Wood_Oak_Trunk",
      "rotation": 5
    },
    {
      "x": -8,
      "y": 14,
      "z": 7,
      "name": "Wood_Softwood_Roof_Hollow",
      "rotation": 3
    },
    {
      "x": -8,
      "y": 0,
      "z": 8,
      "name": "Soil_Clay_Smooth_Lime"
    },
    {
      "x": -8,
      "y": 12,
      "z": 8,
      "name": "Wood_Hardwood_Planks_Half",
      "rotation": 8
    },
    {
      "x": -8,
      "y": 13,
      "z": 8,
      "name": "Wood_Softwood_Planks"
    },
    {
      "x": -8,
      "y": 14,
      "z": 8,
      "name": "Wood_Softwood_Roof",
      "rotation": 3
    },
    {
      "x": -8,
      "y": 0,
      "z": 9,
      "name": "Soil_Clay_Smooth_Lime"
    },
    {
      "x": -8,
      "y": 14,
      "z": 9,
      "name": "Wood_Softwood_Roof_Hollow",
      "rotation": 3
    },
    {
      "x": -8,
      "y": 0,
      "z": 10,
      "name": "Soil_Clay_Smooth_Lime"
    },
    {
      "x": -7,
      "y": 0,
      "z": -10,
      "name": "Soil_Clay_Smooth_Lime"
    },
    {
      "x": -7,
      "y": 0,
      "z": -9,
      "name": "Soil_Clay_Smooth_Lime"
    },
    {
      "x": -7,
      "y": 12,
      "z": -9,
      "name": "Wood_Softwood_Roof_Hollow",
      "rotation": 2
    },
    {
      "x": -7,
      "y": 0,
      "z": -8,
      "name": "Soil_Clay_Smooth_Lime"
    },
    {
      "x": -7,
      "y": 12,
      "z": -8,
      "name": "Wood_Hardwood_Planks_Half",
      "rotation": 8
    },
    {
      "x": -7,
      "y": 13,
      "z": -8,
      "name": "Wood_Softwood_Roof",
      "rotation": 2
    },
    {
      "x": -7,
      "y": 0,
      "z": -7,
      "name": "Soil_Clay_Smooth_Lime"
    },
    {
      "x": -7,
      "y": 6,
      "z": -7,
      "name": "Wood_Oak_Trunk",
      "rotation": 5
    },
    {
      "x": -7,
      "y": 7,
      "z": -7,
      "name": "*Wood_Village_Wall_White_Full_State_Definitions_Bottom"
    },
    {
      "x": -7,
      "y": 8,
      "z": -7,
      "name": "*Wood_Village_Wall_White_Full_State_Definitions_Middle"
    },
    {
      "x": -7,
      "y": 9,
      "z": -7,
      "name": "*Wood_Village_Wall_White_Full_State_Definitions_Middle"
    },
    {
      "x": -7,
      "y": 10,
      "z": -7,
      "name": "*Wood_Village_Wall_White_Full_State_Definitions_Middle"
    },
    {
      "x": -7,
      "y": 11,
      "z": -7,
      "name": "*Wood_Village_Wall_White_Full_State_Definitions_Top"
    },
    {
      "x": -7,
      "y": 12,
      "z": -7,
      "name": "Wood_Oak_Trunk",
      "rotation": 5
    },
    {
      "x": -7,
      "y": 14,
      "z": -7,
      "name": "Wood_Softwood_Roof_Hollow",
      "rotation": 2
    },
    {
      "x": -7,
      "y": 0,
      "z": -6,
      "name": "Soil_Clay_Smooth_Lime"
    },
    {
      "x": -7,
      "y": 1,
      "z": -6,
      "name": "Wood_Oak_Trunk_Stairs",
      "rotation": 1
    },
    {
      "x": -7,
      "y": 4,
      "z": -6,
      "name": "*Furniture_Tavern_Trapdoor_State_Definitions_OpenDoorOut",
      "rotation": 1
    },
    {
      "x": -7,
      "y": 5,
      "z": -6,
      "name": "Wood_Oak_Trunk_Stairs",
      "rotation": 11
    },
    {
      "x": -7,
      "y": 6,
      "z": -6,
      "name": "Wood_Hardwood_Planks"
    },
    {
      "x": -7,
      "y": 12,
      "z": -6,
      "name": "Wood_Hardwood_Planks"
    },
    {
      "x": -7,
      "y": 15,
      "z": -6,
      "name": "Wood_Softwood_Roof_Hollow",
      "rotation": 2
    },
    {
      "x": -7,
      "y": 0,
      "z": -5,
      "name": "Soil_Clay_Smooth_Lime"
    },
    {
      "x": -7,
      "y": 1,
      "z": -5,
      "name": "Rock_Stone_Brick"
    },
    {
      "x": -7,
      "y": 2,
      "z": -5,
      "name": "Rock_Stone_Brick"
    },
    {
      "x": -7,
      "y": 3,
      "z": -5,
      "name": "Rock_Stone_Brick"
    },
    {
      "x": -7,
      "y": 4,
      "z": -5,
      "name": "Rock_Stone_Brick"
    },
    {
      "x": -7,
      "y": 5,
      "z": -5,
      "name": "Rock_Stone_Brick"
    },
    {
      "x": -7,
      "y": 6,
      "z": -5,
      "name": "Wood_Hardwood_Planks"
    },
    {
      "x": -7,
      "y": 12,
      "z": -5,
      "name": "Wood_Hardwood_Planks"
    },
    {
      "x": -7,
      "y": 16,
      "z": -5,
      "name": "Wood_Softwood_Roof_Hollow",
      "rotation": 2
    },
    {
      "x": -7,
      "y": 0,
      "z": -4,
      "name": "Soil_Clay_Smooth_Lime"
    },
    {
      "x": -7,
      "y": 1,
      "z": -4,
      "name": "Rock_Stone_Brick"
    },
    {
      "x": -7,
      "y": 2,
      "z": -4,
      "name": "Rock_Stone_Brick"
    },
    {
      "x": -7,
      "y": 3,
      "z": -4,
      "name": "Rock_Stone_Brick"
    },
    {
      "x": -7,
      "y": 4,
      "z": -4,
      "name": "Rock_Stone_Brick"
    },
    {
      "x": -7,
      "y": 5,
      "z": -4,
      "name": "Rock_Stone_Brick"
    },
    {
      "x": -7,
      "y": 6,
      "z": -4,
      "name": "Wood_Hardwood_Planks"
    },
    {
      "x": -7,
      "y": 12,
      "z": -4,
      "name": "Wood_Hardwood_Planks"
    },
    {
      "x": -7,
      "y": 17,
      "z": -4,
      "name": "Wood_Softwood_Roof_Hollow",
      "rotation": 2
    },
    {
      "x": -7,
      "y": 0,
      "z": -3,
      "name": "Soil_Clay_Smooth_Lime"
    },
    {
      "x": -7,
      "y": 1,
      "z": -3,
      "name": "Rock_Stone_Brick"
    },
    {
      "x": -7,
      "y": 2,
      "z": -3,
      "name": "Rock_Stone_Brick"
    },
    {
      "x": -7,
      "y": 3,
      "z": -3,
      "name": "Rock_Stone_Brick"
    },
    {
      "x": -7,
      "y": 4,
      "z": -3,
      "name": "Rock_Stone_Brick"
    },
    {
      "x": -7,
      "y": 5,
      "z": -3,
      "name": "Rock_Stone_Brick"
    },
    {
      "x": -7,
      "y": 6,
      "z": -3,
      "name": "Wood_Hardwood_Planks"
    },
    {
      "x": -7,
      "y": 12,
      "z": -3,
      "name": "Wood_Hardwood_Planks"
    },
    {
      "x": -7,
      "y": 18,
      "z": -3,
      "name": "Wood_Softwood_Roof_Hollow",
      "rotation": 2
    },
    {
      "x": -7,
      "y": 0,
      "z": -2,
      "name": "Soil_Clay_Smooth_Lime"
    },
    {
      "x": -7,
      "y": 1,
      "z": -2,
      "name": "Rock_Stone_Brick"
    },
    {
      "x": -7,
      "y": 2,
      "z": -2,
      "name": "Rock_Stone_Brick"
    },
    {
      "x": -7,
      "y": 3,
      "z": -2,
      "name": "Rock_Stone_Brick"
    },
    {
      "x": -7,
      "y": 4,
      "z": -2,
      "name": "Rock_Stone_Brick"
    },
    {
      "x": -7,
      "y": 5,
      "z": -2,
      "name": "Rock_Stone_Brick"
    },
    {
      "x": -7,
      "y": 6,
      "z": -2,
      "name": "Wood_Hardwood_Planks"
    },
    {
      "x": -7,
      "y": 12,
      "z": -2,
      "name": "Wood_Hardwood_Planks"
    },
    {
      "x": -7,
      "y": 19,
      "z": -2,
      "name": "Wood_Softwood_Roof_Flat",
      "rotation": 3
    },
    {
      "x": -7,
      "y": 0,
      "z": -1,
      "name": "Soil_Clay_Smooth_Lime"
    },
    {
      "x": -7,
      "y": 1,
      "z": -1,
      "name": "Rock_Stone_Brick"
    },
    {
      "x": -7,
      "y": 2,
      "z": -1,
      "name": "Rock_Stone_Brick"
    },
    {
      "x": -7,
      "y": 3,
      "z": -1,
      "name": "Rock_Stone_Brick"
    },
    {
      "x": -7,
      "y": 4,
      "z": -1,
      "name": "Rock_Stone_Brick"
    },
    {
      "x": -7,
      "y": 5,
      "z": -1,
      "name": "Rock_Stone_Brick"
    },
    {
      "x": -7,
      "y": 6,
      "z": -1,
      "name": "Wood_Hardwood_Planks"
    },
    {
      "x": -7,
      "y": 12,
      "z": -1,
      "name": "Wood_Hardwood_Planks"
    },
    {
      "x": -7,
      "y": 19,
      "z": -1,
      "name": "Wood_Softwood_Roof_Flat",
      "rotation": 3
    },
    {
      "x": -7,
      "y": 0,
      "z": 0,
      "name": "Wood_Softwood_Planks"
    },
    {
      "x": -7,
      "y": 6,
      "z": 0,
      "name": "Wood_Hardwood_Planks"
    },
    {
      "x": -7,
      "y": 12,
      "z": 0,
      "name": "Wood_Hardwood_Planks"
    },
    {
      "x": -7,
      "y": 19,
      "z": 0,
      "name": "Wood_Softwood_Roof_Flat",
      "rotation": 3
    },
    {
      "x": -7,
      "y": 0,
      "z": 1,
      "name": "Soil_Clay_Smooth_Lime"
    },
    {
      "x": -7,
      "y": 1,
      "z": 1,
      "name": "Rock_Stone_Brick"
    },
    {
      "x": -7,
      "y": 2,
      "z": 1,
      "name": "Rock_Stone_Brick"
    },
    {
      "x": -7,
      "y": 3,
      "z": 1,
      "name": "Rock_Stone_Brick"
    },
    {
      "x": -7,
      "y": 4,
      "z": 1,
      "name": "Rock_Stone_Brick"
    },
    {
      "x": -7,
      "y": 5,
      "z": 1,
      "name": "Rock_Stone_Brick"
    },
    {
      "x": -7,
      "y": 6,
      "z": 1,
      "name": "Wood_Hardwood_Planks"
    },
    {
      "x": -7,
      "y": 12,
      "z": 1,
      "name": "Wood_Hardwood_Planks"
    },
    {
      "x": -7,
      "y": 19,
      "z": 1,
      "name": "Wood_Softwood_Roof_Flat",
      "rotation": 3
    },
    {
      "x": -7,
      "y": 0,
      "z": 2,
      "name": "Soil_Clay_Smooth_Lime"
    },
    {
      "x": -7,
      "y": 1,
      "z": 2,
      "name": "Rock_Stone_Brick"
    },
    {
      "x": -7,
      "y": 2,
      "z": 2,
      "name": "Rock_Stone_Brick"
    },
    {
      "x": -7,
      "y": 3,
      "z": 2,
      "name": "Rock_Stone_Brick"
    },
    {
      "x": -7,
      "y": 4,
      "z": 2,
      "name": "Rock_Stone_Brick"
    },
    {
      "x": -7,
      "y": 5,
      "z": 2,
      "name": "Rock_Stone_Brick"
    },
    {
      "x": -7,
      "y": 6,
      "z": 2,
      "name": "Wood_Hardwood_Planks"
    },
    {
      "x": -7,
      "y": 12,
      "z": 2,
      "name": "Wood_Hardwood_Planks"
    },
    {
      "x": -7,
      "y": 18,
      "z": 2,
      "name": "Wood_Softwood_Roof_Hollow"
    },
    {
      "x": -7,
      "y": 0,
      "z": 3,
      "name": "Soil_Clay_Smooth_Lime"
    },
    {
      "x": -7,
      "y": 1,
      "z": 3,
      "name": "Rock_Stone_Brick"
    },
    {
      "x": -7,
      "y": 2,
      "z": 3,
      "name": "Rock_Stone_Brick"
    },
    {
      "x": -7,
      "y": 3,
      "z": 3,
      "name": "Rock_Stone_Brick"
    },
    {
      "x": -7,
      "y": 4,
      "z": 3,
      "name": "Rock_Stone_Brick"
    },
    {
      "x": -7,
      "y": 5,
      "z": 3,
      "name": "Rock_Stone_Brick"
    },
    {
      "x": -7,
      "y": 6,
      "z": 3,
      "name": "Wood_Hardwood_Planks"
    },
    {
      "x": -7,
      "y": 12,
      "z": 3,
      "name": "Wood_Hardwood_Planks"
    },
    {
      "x": -7,
      "y": 17,
      "z": 3,
      "name": "Wood_Softwood_Roof_Hollow"
    },
    {
      "x": -7,
      "y": 0,
      "z": 4,
      "name": "Soil_Clay_Smooth_Lime"
    },
    {
      "x": -7,
      "y": 1,
      "z": 4,
      "name": "Rock_Stone_Brick"
    },
    {
      "x": -7,
      "y": 2,
      "z": 4,
      "name": "Rock_Stone_Brick"
    },
    {
      "x": -7,
      "y": 3,
      "z": 4,
      "name": "Rock_Stone_Brick"
    },
    {
      "x": -7,
      "y": 4,
      "z": 4,
      "name": "Rock_Stone_Brick"
    },
    {
      "x": -7,
      "y": 5,
      "z": 4,
      "name": "Rock_Stone_Brick"
    },
    {
      "x": -7,
      "y": 6,
      "z": 4,
      "name": "Wood_Hardwood_Planks"
    },
    {
      "x": -7,
      "y": 12,
      "z": 4,
      "name": "Wood_Hardwood_Planks"
    },
    {
      "x": -7,
      "y": 16,
      "z": 4,
      "name": "Wood_Softwood_Roof_Hollow"
    },
    {
      "x": -7,
      "y": 0,
      "z": 5,
      "name": "Soil_Clay_Smooth_Lime"
    },
    {
      "x": -7,
      "y": 1,
      "z": 5,
      "name": "Rock_Stone_Brick"
    },
    {
      "x": -7,
      "y": 2,
      "z": 5,
      "name": "Rock_Stone_Brick"
    },
    {
      "x": -7,
      "y": 3,
      "z": 5,
      "name": "Rock_Stone_Brick"
    },
    {
      "x": -7,
      "y": 4,
      "z": 5,
      "name": "Rock_Stone_Brick"
    },
    {
      "x": -7,
      "y": 5,
      "z": 5,
      "name": "Rock_Stone_Brick"
    },
    {
      "x": -7,
      "y": 6,
      "z": 5,
      "name": "Wood_Hardwood_Planks"
    },
    {
      "x": -7,
      "y": 12,
      "z": 5,
      "name": "Wood_Hardwood_Planks"
    },
    {
      "x": -7,
      "y": 15,
      "z": 5,
      "name": "*Wood_Softwood_Roof_Hollow_State_Definitions_Inverted_Corner_Left",
      "rotation": 3
    },
    {
      "x": -7,
      "y": 0,
      "z": 6,
      "name": "Soil_Clay_Smooth_Lime"
    },
    {
      "x": -7,
      "y": 1,
      "z": 6,
      "name": "Wood_Oak_Trunk_Stairs",
      "rotation": 1
    },
    {
      "x": -7,
      "y": 4,
      "z": 6,
      "name": "*Furniture_Tavern_Trapdoor_State_Definitions_OpenDoorOut",
      "rotation": 1
    },
    {
      "x": -7,
      "y": 5,
      "z": 6,
      "name": "Wood_Oak_Trunk_Stairs",
      "rotation": 11
    },
    {
      "x": -7,
      "y": 6,
      "z": 6,
      "name": "Wood_Hardwood_Planks"
    },
    {
      "x": -7,
      "y": 12,
      "z": 6,
      "name": "Wood_Hardwood_Planks"
    },
    {
      "x": -7,
      "y": 15,
      "z": 6,
      "name": "Wood_Softwood_Roof_Hollow",
      "rotation": 3
    },
    {
      "x": -7,
      "y": 0,
      "z": 7,
      "name": "Soil_Clay_Smooth_Lime"
    },
    {
      "x": -7,
      "y": 6,
      "z": 7,
      "name": "Wood_Oak_Trunk",
      "rotation": 5
    },
    {
      "x": -7,
      "y": 7,
      "z": 7,
      "name": "Rock_Chalk_Brick_Half",
      "rotation": 4
    },
    {
      "x": -7,
      "y": 8,
      "z": 7,
      "name": "Rock_Chalk_Brick_Half",
      "rotation": 4
    },
    {
      "x": -7,
      "y": 9,
      "z": 7,
      "name": "Rock_Chalk_Brick_Half",
      "rotation": 4
    },
    {
      "x": -7,
      "y": 10,
      "z": 7,
      "name": "Rock_Chalk_Brick_Half",
      "rotation": 4
    },
    {
      "x": -7,
      "y": 11,
      "z": 7,
      "name": "Rock_Chalk_Brick_Half",
      "rotation": 4
    },
    {
      "x": -7,
      "y": 12,
      "z": 7,
      "name": "Wood_Oak_Trunk",
      "rotation": 5
    },
    {
      "x": -7,
      "y": 15,
      "z": 7,
      "name": "Wood_Softwood_Roof_Hollow",
      "rotation": 3
    },
    {
      "x": -7,
      "y": 0,
      "z": 8,
      "name": "Soil_Clay_Smooth_Lime"
    },
    {
      "x": -7,
      "y": 12,
      "z": 8,
      "name": "Wood_Hardwood_Planks_Half",
      "rotation": 8
    },
    {
      "x": -7,
      "y": 13,
      "z": 8,
      "name": "Wood_Softwood_Planks"
    },
    {
      "x": -7,
      "y": 14,
      "z": 8,
      "name": "Wood_Softwood_Planks"
    },
    {
      "x": -7,
      "y": 15,
      "z": 8,
      "name": "Wood_Softwood_Roof",
      "rotation": 3
    },
    {
      "x": -7,
      "y": 0,
      "z": 9,
      "name": "Soil_Clay_Smooth_Lime"
    },
    {
      "x": -7,
      "y": 15,
      "z": 9,
      "name": "Wood_Softwood_Roof_Hollow",
      "rotation": 3
    },
    {
      "x": -7,
      "y": 0,
      "z": 10,
      "name": "Soil_Clay_Smooth_Lime"
    },
    {
      "x": -6,
      "y": 0,
      "z": -10,
      "name": "Soil_Clay_Smooth_Lime"
    },
    {
      "x": -6,
      "y": 0,
      "z": -9,
      "name": "Soil_Clay_Smooth_Lime"
    },
    {
      "x": -6,
      "y": 12,
      "z": -9,
      "name": "Wood_Softwood_Roof_Hollow",
      "rotation": 2
    },
    {
      "x": -6,
      "y": 0,
      "z": -8,
      "name": "Soil_Clay_Smooth_Lime"
    },
    {
      "x": -6,
      "y": 12,
      "z": -8,
      "name": "Wood_Hardwood_Planks_Half",
      "rotation": 8
    },
    {
      "x": -6,
      "y": 13,
      "z": -8,
      "name": "Wood_Softwood_Roof",
      "rotation": 2
    },
    {
      "x": -6,
      "y": 0,
      "z": -7,
      "name": "Soil_Clay_Smooth_Lime"
    },
    {
      "x": -6,
      "y": 6,
      "z": -7,
      "name": "Wood_Oak_Trunk",
      "rotation": 5
    },
    {
      "x": -6,
      "y": 7,
      "z": -7,
      "name": "Wood_Village_Wall_White_Full"
    },
    {
      "x": -6,
      "y": 8,
      "z": -7,
      "name": "Furniture_Human_Ruins_Window"
    },
    {
      "x": -6,
      "y": 9,
      "z": -7,
      "name": "Furniture_Human_Ruins_Window"
    },
    {
      "x": -6,
      "y": 10,
      "z": -7,
      "name": "Furniture_Human_Ruins_Window"
    },
    {
      "x": -6,
      "y": 11,
      "z": -7,
      "name": "Wood_Village_Wall_White_Full"
    },
    {
      "x": -6,
      "y": 12,
      "z": -7,
      "name": "Wood_Oak_Trunk",
      "rotation": 5
    },
    {
      "x": -6,
      "y": 14,
      "z": -7,
      "name": "Wood_Softwood_Roof_Hollow",
      "rotation": 2
    },
    {
      "x": -6,
      "y": 0,
      "z": -6,
      "name": "Soil_Clay_Smooth_Lime"
    },
    {
      "x": -6,
      "y": 5,
      "z": -6,
      "name": "Furniture_Tavern_Trapdoor"
    },
    {
      "x": -6,
      "y": 6,
      "z": -6,
      "name": "Wood_Hardwood_Planks"
    },
    {
      "x": -6,
      "y": 12,
      "z": -6,
      "name": "Wood_Hardwood_Planks"
    },
    {
      "x": -6,
      "y": 15,
      "z": -6,
      "name": "Wood_Softwood_Roof_Hollow",
      "rotation": 2
    },
    {
      "x": -6,
      "y": 0,
      "z": -5,
      "name": "Soil_Clay_Smooth_Lime"
    },
    {
      "x": -6,
      "y": 1,
      "z": -5,
      "name": "Rock_Stone_Brick"
    },
    {
      "x": -6,
      "y": 2,
      "z": -5,
      "name": "Rock_Stone_Brick"
    },
    {
      "x": -6,
      "y": 3,
      "z": -5,
      "name": "Rock_Stone_Brick"
    },
    {
      "x": -6,
      "y": 4,
      "z": -5,
      "name": "Rock_Stone_Brick"
    },
    {
      "x": -6,
      "y": 5,
      "z": -5,
      "name": "Rock_Stone_Brick"
    },
    {
      "x": -6,
      "y": 6,
      "z": -5,
      "name": "Wood_Hardwood_Planks"
    },
    {
      "x": -6,
      "y": 12,
      "z": -5,
      "name": "Wood_Hardwood_Planks"
    },
    {
      "x": -6,
      "y": 16,
      "z": -5,
      "name": "Wood_Softwood_Roof_Hollow",
      "rotation": 2
    },
    {
      "x": -6,
      "y": 0,
      "z": -4,
      "name": "Wood_Softwood_Planks"
    },
    {
      "x": -6,
      "y": 6,
      "z": -4,
      "name": "Wood_Hardwood_Planks"
    },
    {
      "x": -6,
      "y": 12,
      "z": -4,
      "name": "Wood_Hardwood_Planks"
    },
    {
      "x": -6,
      "y": 17,
      "z": -4,
      "name": "Wood_Softwood_Roof_Hollow",
      "rotation": 2
    },
    {
      "x": -6,
      "y": 0,
      "z": -3,
      "name": "Wood_Softwood_Planks"
    },
    {
      "x": -6,
      "y": 6,
      "z": -3,
      "name": "Wood_Hardwood_Planks"
    },
    {
      "x": -6,
      "y": 12,
      "z": -3,
      "name": "Wood_Hardwood_Planks"
    },
    {
      "x": -6,
      "y": 18,
      "z": -3,
      "name": "Wood_Softwood_Roof_Hollow",
      "rotation": 2
    },
    {
      "x": -6,
      "y": 0,
      "z": -2,
      "name": "Wood_Softwood_Planks"
    },
    {
      "x": -6,
      "y": 6,
      "z": -2,
      "name": "Wood_Hardwood_Planks"
    },
    {
      "x": -6,
      "y": 12,
      "z": -2,
      "name": "Wood_Hardwood_Planks"
    },
    {
      "x": -6,
      "y": 19,
      "z": -2,
      "name": "Wood_Softwood_Roof_Flat",
      "rotation": 3
    },
    {
      "x": -6,
      "y": 0,
      "z": -1,
      "name": "Wood_Softwood_Planks"
    },
    {
      "x": -6,
      "y": 6,
      "z": -1,
      "name": "Wood_Hardwood_Planks"
    },
    {
      "x": -6,
      "y": 12,
      "z": -1,
      "name": "Wood_Hardwood_Planks"
    },
    {
      "x": -6,
      "y": 19,
      "z": -1,
      "name": "Wood_Softwood_Roof_Flat",
      "rotation": 3
    },
    {
      "x": -6,
      "y": 0,
      "z": 0,
      "name": "Wood_Softwood_Planks"
    },
    {
      "x": -6,
      "y": 6,
      "z": 0,
      "name": "Wood_Hardwood_Planks"
    },
    {
      "x": -6,
      "y": 12,
      "z": 0,
      "name": "Wood_Hardwood_Planks"
    },
    {
      "x": -6,
      "y": 19,
      "z": 0,
      "name": "Wood_Softwood_Roof_Flat",
      "rotation": 3
    },
    {
      "x": -6,
      "y": 0,
      "z": 1,
      "name": "Wood_Softwood_Planks"
    },
    {
      "x": -6,
      "y": 6,
      "z": 1,
      "name": "Wood_Hardwood_Planks"
    },
    {
      "x": -6,
      "y": 12,
      "z": 1,
      "name": "Wood_Hardwood_Planks"
    },
    {
      "x": -6,
      "y": 19,
      "z": 1,
      "name": "Wood_Softwood_Roof_Flat",
      "rotation": 3
    },
    {
      "x": -6,
      "y": 0,
      "z": 2,
      "name": "Wood_Softwood_Planks"
    },
    {
      "x": -6,
      "y": 6,
      "z": 2,
      "name": "Wood_Hardwood_Planks"
    },
    {
      "x": -6,
      "y": 12,
      "z": 2,
      "name": "Wood_Hardwood_Planks"
    },
    {
      "x": -6,
      "y": 18,
      "z": 2,
      "name": "Wood_Softwood_Roof_Hollow"
    },
    {
      "x": -6,
      "y": 0,
      "z": 3,
      "name": "Wood_Softwood_Planks"
    },
    {
      "x": -6,
      "y": 6,
      "z": 3,
      "name": "Wood_Hardwood_Planks"
    },
    {
      "x": -6,
      "y": 12,
      "z": 3,
      "name": "Wood_Hardwood_Planks"
    },
    {
      "x": -6,
      "y": 17,
      "z": 3,
      "name": "Wood_Softwood_Roof_Hollow"
    },
    {
      "x": -6,
      "y": 0,
      "z": 4,
      "name": "Wood_Softwood_Planks"
    },
    {
      "x": -6,
      "y": 6,
      "z": 4,
      "name": "Wood_Hardwood_Planks"
    },
    {
      "x": -6,
      "y": 12,
      "z": 4,
      "name": "Wood_Hardwood_Planks"
    },
    {
      "x": -6,
      "y": 16,
      "z": 4,
      "name": "*Wood_Softwood_Roof_Hollow_State_Definitions_Inverted_Corner_Left",
      "rotation": 3
    },
    {
      "x": -6,
      "y": 0,
      "z": 5,
      "name": "Soil_Clay_Smooth_Lime"
    },
    {
      "x": -6,
      "y": 1,
      "z": 5,
      "name": "Rock_Stone_Brick"
    },
    {
      "x": -6,
      "y": 2,
      "z": 5,
      "name": "Rock_Stone_Brick"
    },
    {
      "x": -6,
      "y": 3,
      "z": 5,
      "name": "Rock_Stone_Brick"
    },
    {
      "x": -6,
      "y": 4,
      "z": 5,
      "name": "Rock_Stone_Brick"
    },
    {
      "x": -6,
      "y": 5,
      "z": 5,
      "name": "Rock_Stone_Brick"
    },
    {
      "x": -6,
      "y": 6,
      "z": 5,
      "name": "Wood_Hardwood_Planks"
    },
    {
      "x": -6,
      "y": 12,
      "z": 5,
      "name": "Wood_Hardwood_Planks"
    },
    {
      "x": -6,
      "y": 16,
      "z": 5,
      "name": "Wood_Softwood_Roof_Hollow",
      "rotation": 3
    },
    {
      "x": -6,
      "y": 0,
      "z": 6,
      "name": "Soil_Clay_Smooth_Lime"
    },
    {
      "x": -6,
      "y": 5,
      "z": 6,
      "name": "Furniture_Tavern_Trapdoor",
      "rotation": 2
    },
    {
      "x": -6,
      "y": 6,
      "z": 6,
      "name": "Wood_Hardwood_Planks"
    },
    {
      "x": -6,
      "y": 12,
      "z": 6,
      "name": "Wood_Hardwood_Planks"
    },
    {
      "x": -6,
      "y": 16,
      "z": 6,
      "name": "Wood_Softwood_Roof_Hollow",
      "rotation": 3
    },
    {
      "x": -6,
      "y": 0,
      "z": 7,
      "name": "Soil_Clay_Smooth_Lime"
    },
    {
      "x": -6,
      "y": 6,
      "z": 7,
      "name": "Wood_Oak_Trunk",
      "rotation": 5
    },
    {
      "x": -6,
      "y": 7,
      "z": 7,
      "name": "*Wood_Village_Wall_White_Full_State_Definitions_Bottom"
    },
    {
      "x": -6,
      "y": 8,
      "z": 7,
      "name": "*Wood_Village_Wall_White_Full_State_Definitions_Middle"
    },
    {
      "x": -6,
      "y": 9,
      "z": 7,
      "name": "*Wood_Village_Wall_White_Full_State_Definitions_Middle"
    },
    {
      "x": -6,
      "y": 10,
      "z": 7,
      "name": "*Wood_Village_Wall_White_Full_State_Definitions_Middle"
    },
    {
      "x": -6,
      "y": 11,
      "z": 7,
      "name": "*Wood_Village_Wall_White_Full_State_Definitions_Top"
    },
    {
      "x": -6,
      "y": 12,
      "z": 7,
      "name": "Wood_Oak_Trunk",
      "rotation": 5
    },
    {
      "x": -6,
      "y": 16,
      "z": 7,
      "name": "Wood_Softwood_Roof_Hollow",
      "rotation": 3
    },
    {
      "x": -6,
      "y": 0,
      "z": 8,
      "name": "Soil_Clay_Smooth_Lime"
    },
    {
      "x": -6,
      "y": 12,
      "z": 8,
      "name": "Wood_Hardwood_Planks_Half",
      "rotation": 8
    },
    {
      "x": -6,
      "y": 13,
      "z": 8,
      "name": "Wood_Oak_Trunk"
    },
    {
      "x": -6,
      "y": 14,
      "z": 8,
      "name": "Wood_Oak_Trunk"
    },
    {
      "x": -6,
      "y": 15,
      "z": 8,
      "name": "Wood_Oak_Trunk"
    },
    {
      "x": -6,
      "y": 16,
      "z": 8,
      "name": "Wood_Softwood_Roof",
      "rotation": 3
    },
    {
      "x": -6,
      "y": 0,
      "z": 9,
      "name": "Soil_Clay_Smooth_Lime"
    },
    {
      "x": -6,
      "y": 13,
      "z": 9,
      "name": "*Furniture_Village_Trapdoor_State_Definitions_OpenDoorOut"
    },
    {
      "x": -6,
      "y": 16,
      "z": 9,
      "name": "Wood_Softwood_Roof_Hollow",
      "rotation": 3
    },
    {
      "x": -6,
      "y": 0,
      "z": 10,
      "name": "Soil_Clay_Smooth_Lime"
    },
    {
      "x": -5,
      "y": 0,
      "z": -10,
      "name": "Soil_Clay_Smooth_Lime"
    },
    {
      "x": -5,
      "y": 0,
      "z": -9,
      "name": "Soil_Clay_Smooth_Lime"
    },
    {
      "x": -5,
      "y": 12,
      "z": -9,
      "name": "Wood_Softwood_Roof_Hollow",
      "rotation": 2
    },
    {
      "x": -5,
      "y": 0,
      "z": -8,
      "name": "Soil_Clay_Smooth_Lime"
    },
    {
      "x": -5,
      "y": 12,
      "z": -8,
      "name": "Wood_Hardwood_Planks_Half",
      "rotation": 8
    },
    {
      "x": -5,
      "y": 13,
      "z": -8,
      "name": "Wood_Softwood_Roof",
      "rotation": 2
    },
    {
      "x": -5,
      "y": 0,
      "z": -7,
      "name": "Soil_Clay_Smooth_Lime"
    },
    {
      "x": -5,
      "y": 6,
      "z": -7,
      "name": "Wood_Oak_Trunk",
      "rotation": 5
    },
    {
      "x": -5,
      "y": 7,
      "z": -7,
      "name": "*Wood_Village_Wall_White_Full_State_Definitions_Bottom"
    },
    {
      "x": -5,
      "y": 8,
      "z": -7,
      "name": "*Wood_Village_Wall_White_Full_State_Definitions_Middle"
    },
    {
      "x": -5,
      "y": 9,
      "z": -7,
      "name": "*Wood_Village_Wall_White_Full_State_Definitions_Middle"
    },
    {
      "x": -5,
      "y": 10,
      "z": -7,
      "name": "*Wood_Village_Wall_White_Full_State_Definitions_Middle"
    },
    {
      "x": -5,
      "y": 11,
      "z": -7,
      "name": "*Wood_Village_Wall_White_Full_State_Definitions_Top"
    },
    {
      "x": -5,
      "y": 12,
      "z": -7,
      "name": "Wood_Oak_Trunk",
      "rotation": 5
    },
    {
      "x": -5,
      "y": 14,
      "z": -7,
      "name": "Wood_Softwood_Roof_Hollow",
      "rotation": 2
    },
    {
      "x": -5,
      "y": 0,
      "z": -6,
      "name": "Soil_Clay_Smooth_Lime"
    },
    {
      "x": -5,
      "y": 5,
      "z": -6,
      "name": "Furniture_Tavern_Trapdoor"
    },
    {
      "x": -5,
      "y": 6,
      "z": -6,
      "name": "Wood_Hardwood_Planks"
    },
    {
      "x": -5,
      "y": 12,
      "z": -6,
      "name": "Wood_Hardwood_Planks"
    },
    {
      "x": -5,
      "y": 15,
      "z": -6,
      "name": "Wood_Softwood_Roof_Hollow",
      "rotation": 2
    },
    {
      "x": -5,
      "y": 0,
      "z": -5,
      "name": "Soil_Clay_Smooth_Lime"
    },
    {
      "x": -5,
      "y": 1,
      "z": -5,
      "name": "Rock_Stone_Brick"
    },
    {
      "x": -5,
      "y": 2,
      "z": -5,
      "name": "Rock_Stone_Brick"
    },
    {
      "x": -5,
      "y": 3,
      "z": -5,
      "name": "Rock_Stone_Brick"
    },
    {
      "x": -5,
      "y": 4,
      "z": -5,
      "name": "Rock_Stone_Brick"
    },
    {
      "x": -5,
      "y": 5,
      "z": -5,
      "name": "Rock_Stone_Brick"
    },
    {
      "x": -5,
      "y": 6,
      "z": -5,
      "name": "Wood_Hardwood_Planks"
    },
    {
      "x": -5,
      "y": 12,
      "z": -5,
      "name": "Wood_Hardwood_Planks"
    },
    {
      "x": -5,
      "y": 16,
      "z": -5,
      "name": "Wood_Softwood_Roof_Hollow",
      "rotation": 2
    },
    {
      "x": -5,
      "y": 0,
      "z": -4,
      "name": "Wood_Softwood_Planks"
    },
    {
      "x": -5,
      "y": 6,
      "z": -4,
      "name": "Wood_Hardwood_Planks"
    },
    {
      "x": -5,
      "y": 12,
      "z": -4,
      "name": "Wood_Hardwood_Planks"
    },
    {
      "x": -5,
      "y": 17,
      "z": -4,
      "name": "Wood_Softwood_Roof_Hollow",
      "rotation": 2
    },
    {
      "x": -5,
      "y": 0,
      "z": -3,
      "name": "Wood_Softwood_Planks"
    },
    {
      "x": -5,
      "y": 6,
      "z": -3,
      "name": "Wood_Hardwood_Planks"
    },
    {
      "x": -5,
      "y": 12,
      "z": -3,
      "name": "Wood_Hardwood_Planks"
    },
    {
      "x": -5,
      "y": 18,
      "z": -3,
      "name": "Wood_Softwood_Roof_Hollow",
      "rotation": 2
    },
    {
      "x": -5,
      "y": 0,
      "z": -2,
      "name": "Wood_Softwood_Planks"
    },
    {
      "x": -5,
      "y": 6,
      "z": -2,
      "name": "Wood_Hardwood_Planks"
    },
    {
      "x": -5,
      "y": 12,
      "z": -2,
      "name": "Wood_Hardwood_Planks"
    },
    {
      "x": -5,
      "y": 19,
      "z": -2,
      "name": "Wood_Softwood_Roof_Flat",
      "rotation": 3
    },
    {
      "x": -5,
      "y": 0,
      "z": -1,
      "name": "Wood_Softwood_Planks"
    },
    {
      "x": -5,
      "y": 6,
      "z": -1,
      "name": "Wood_Hardwood_Planks"
    },
    {
      "x": -5,
      "y": 12,
      "z": -1,
      "name": "Wood_Hardwood_Planks"
    },
    {
      "x": -5,
      "y": 19,
      "z": -1,
      "name": "Wood_Softwood_Roof_Flat",
      "rotation": 3
    },
    {
      "x": -5,
      "y": 0,
      "z": 0,
      "name": "Wood_Softwood_Planks"
    },
    {
      "x": -5,
      "y": 6,
      "z": 0,
      "name": "Wood_Hardwood_Planks"
    },
    {
      "x": -5,
      "y": 12,
      "z": 0,
      "name": "Wood_Hardwood_Planks"
    },
    {
      "x": -5,
      "y": 19,
      "z": 0,
      "name": "Wood_Softwood_Roof_Flat",
      "rotation": 3
    },
    {
      "x": -5,
      "y": 0,
      "z": 1,
      "name": "Wood_Softwood_Planks"
    },
    {
      "x": -5,
      "y": 6,
      "z": 1,
      "name": "Wood_Hardwood_Planks"
    },
    {
      "x": -5,
      "y": 12,
      "z": 1,
      "name": "Wood_Hardwood_Planks"
    },
    {
      "x": -5,
      "y": 19,
      "z": 1,
      "name": "Wood_Softwood_Roof_Flat",
      "rotation": 3
    },
    {
      "x": -5,
      "y": 0,
      "z": 2,
      "name": "Wood_Softwood_Planks"
    },
    {
      "x": -5,
      "y": 6,
      "z": 2,
      "name": "Wood_Hardwood_Planks"
    },
    {
      "x": -5,
      "y": 12,
      "z": 2,
      "name": "Wood_Hardwood_Planks"
    },
    {
      "x": -5,
      "y": 18,
      "z": 2,
      "name": "Wood_Softwood_Roof_Hollow"
    },
    {
      "x": -5,
      "y": 0,
      "z": 3,
      "name": "Wood_Softwood_Planks"
    },
    {
      "x": -5,
      "y": 6,
      "z": 3,
      "name": "Wood_Hardwood_Planks"
    },
    {
      "x": -5,
      "y": 12,
      "z": 3,
      "name": "Wood_Hardwood_Planks"
    },
    {
      "x": -5,
      "y": 17,
      "z": 3,
      "name": "*Wood_Softwood_Roof_Hollow_State_Definitions_Inverted_Corner_Left",
      "rotation": 3
    },
    {
      "x": -5,
      "y": 0,
      "z": 4,
      "name": "Wood_Softwood_Planks"
    },
    {
      "x": -5,
      "y": 6,
      "z": 4,
      "name": "Wood_Hardwood_Planks"
    },
    {
      "x": -5,
      "y": 12,
      "z": 4,
      "name": "Wood_Hardwood_Planks"
    },
    {
      "x": -5,
      "y": 17,
      "z": 4,
      "name": "Wood_Softwood_Roof_Hollow",
      "rotation": 3
    },
    {
      "x": -5,
      "y": 0,
      "z": 5,
      "name": "Soil_Clay_Smooth_Lime"
    },
    {
      "x": -5,
      "y": 1,
      "z": 5,
      "name": "Rock_Stone_Brick"
    },
    {
      "x": -5,
      "y": 2,
      "z": 5,
      "name": "Rock_Stone_Brick"
    },
    {
      "x": -5,
      "y": 3,
      "z": 5,
      "name": "Rock_Stone_Brick"
    },
    {
      "x": -5,
      "y": 4,
      "z": 5,
      "name": "Rock_Stone_Brick"
    },
    {
      "x": -5,
      "y": 5,
      "z": 5,
      "name": "Rock_Stone_Brick"
    },
    {
      "x": -5,
      "y": 6,
      "z": 5,
      "name": "Wood_Hardwood_Planks"
    },
    {
      "x": -5,
      "y": 12,
      "z": 5,
      "name": "Wood_Hardwood_Planks"
    },
    {
      "x": -5,
      "y": 17,
      "z": 5,
      "name": "Wood_Softwood_Roof_Hollow",
      "rotation": 3
    },
    {
      "x": -5,
      "y": 0,
      "z": 6,
      "name": "Soil_Clay_Smooth_Lime"
    },
    {
      "x": -5,
      "y": 5,
      "z": 6,
      "name": "Furniture_Tavern_Trapdoor",
      "rotation": 2
    },
    {
      "x": -5,
      "y": 6,
      "z": 6,
      "name": "Wood_Hardwood_Planks"
    },
    {
      "x": -5,
      "y": 12,
      "z": 6,
      "name": "Wood_Hardwood_Planks"
    },
    {
      "x": -5,
      "y": 17,
      "z": 6,
      "name": "Wood_Softwood_Roof_Hollow",
      "rotation": 3
    },
    {
      "x": -5,
      "y": 0,
      "z": 7,
      "name": "Soil_Clay_Smooth_Lime"
    },
    {
      "x": -5,
      "y": 6,
      "z": 7,
      "name": "Wood_Oak_Trunk",
      "rotation": 5
    },
    {
      "x": -5,
      "y": 7,
      "z": 7,
      "name": "Wood_Village_Wall_White_Full"
    },
    {
      "x": -5,
      "y": 8,
      "z": 7,
      "name": "Furniture_Human_Ruins_Window"
    },
    {
      "x": -5,
      "y": 9,
      "z": 7,
      "name": "Furniture_Human_Ruins_Window"
    },
    {
      "x": -5,
      "y": 10,
      "z": 7,
      "name": "Furniture_Human_Ruins_Window"
    },
    {
      "x": -5,
      "y": 11,
      "z": 7,
      "name": "Wood_Village_Wall_White_Full"
    },
    {
      "x": -5,
      "y": 12,
      "z": 7,
      "name": "Wood_Oak_Trunk",
      "rotation": 5
    },
    {
      "x": -5,
      "y": 17,
      "z": 7,
      "name": "Wood_Softwood_Roof_Hollow",
      "rotation": 3
    },
    {
      "x": -5,
      "y": 0,
      "z": 8,
      "name": "Soil_Clay_Smooth_Lime"
    },
    {
      "x": -5,
      "y": 12,
      "z": 8,
      "name": "Wood_Hardwood_Planks_Half",
      "rotation": 8
    },
    {
      "x": -5,
      "y": 13,
      "z": 8,
      "name": "Wood_Hardwood_Ornate"
    },
    {
      "x": -5,
      "y": 14,
      "z": 8,
      "name": "Furniture_Village_Window"
    },
    {
      "x": -5,
      "y": 15,
      "z": 8,
      "name": "Furniture_Village_Window"
    },
    {
      "x": -5,
      "y": 16,
      "z": 8,
      "name": "Wood_Oak_Trunk",
      "rotation": 5
    },
    {
      "x": -5,
      "y": 17,
      "z": 8,
      "name": "Wood_Softwood_Roof",
      "rotation": 3
    },
    {
      "x": -5,
      "y": 0,
      "z": 9,
      "name": "Soil_Clay_Smooth_Lime"
    },
    {
      "x": -5,
      "y": 13,
      "z": 9,
      "name": "*Furniture_Village_Trapdoor_State_Definitions_OpenDoorOut"
    },
    {
      "x": -5,
      "y": 17,
      "z": 9,
      "name": "Wood_Softwood_Roof_Hollow",
      "rotation": 3
    },
    {
      "x": -5,
      "y": 0,
      "z": 10,
      "name": "Soil_Clay_Smooth_Lime"
    },
    {
      "x": -4,
      "y": 0,
      "z": -10,
      "name": "Soil_Clay_Smooth_Lime"
    },
    {
      "x": -4,
      "y": 0,
      "z": -9,
      "name": "Soil_Clay_Smooth_Lime"
    },
    {
      "x": -4,
      "y": 12,
      "z": -9,
      "name": "Wood_Softwood_Roof_Hollow",
      "rotation": 2
    },
    {
      "x": -4,
      "y": 0,
      "z": -8,
      "name": "Soil_Clay_Smooth_Lime"
    },
    {
      "x": -4,
      "y": 12,
      "z": -8,
      "name": "Wood_Hardwood_Planks_Half",
      "rotation": 8
    },
    {
      "x": -4,
      "y": 13,
      "z": -8,
      "name": "Wood_Softwood_Roof",
      "rotation": 2
    },
    {
      "x": -4,
      "y": 0,
      "z": -7,
      "name": "Soil_Clay_Smooth_Lime"
    },
    {
      "x": -4,
      "y": 6,
      "z": -7,
      "name": "Wood_Oak_Trunk",
      "rotation": 5
    },
    {
      "x": -4,
      "y": 7,
      "z": -7,
      "name": "Rock_Chalk_Brick_Half",
      "rotation": 6
    },
    {
      "x": -4,
      "y": 8,
      "z": -7,
      "name": "Rock_Chalk_Brick_Half",
      "rotation": 6
    },
    {
      "x": -4,
      "y": 9,
      "z": -7,
      "name": "Rock_Chalk_Brick_Half",
      "rotation": 6
    },
    {
      "x": -4,
      "y": 10,
      "z": -7,
      "name": "Rock_Chalk_Brick_Half",
      "rotation": 6
    },
    {
      "x": -4,
      "y": 11,
      "z": -7,
      "name": "Rock_Chalk_Brick_Half",
      "rotation": 6
    },
    {
      "x": -4,
      "y": 12,
      "z": -7,
      "name": "Wood_Oak_Trunk",
      "rotation": 5
    },
    {
      "x": -4,
      "y": 14,
      "z": -7,
      "name": "Wood_Softwood_Roof_Hollow",
      "rotation": 2
    },
    {
      "x": -4,
      "y": 0,
      "z": -6,
      "name": "Soil_Clay_Smooth_Lime"
    },
    {
      "x": -4,
      "y": 5,
      "z": -6,
      "name": "Furniture_Tavern_Trapdoor"
    },
    {
      "x": -4,
      "y": 6,
      "z": -6,
      "name": "Wood_Hardwood_Planks"
    },
    {
      "x": -4,
      "y": 12,
      "z": -6,
      "name": "Wood_Hardwood_Planks"
    },
    {
      "x": -4,
      "y": 15,
      "z": -6,
      "name": "Wood_Softwood_Roof_Hollow",
      "rotation": 2
    },
    {
      "x": -4,
      "y": 0,
      "z": -5,
      "name": "Soil_Clay_Smooth_Lime"
    },
    {
      "x": -4,
      "y": 1,
      "z": -5,
      "name": "Rock_Stone_Brick"
    },
    {
      "x": -4,
      "y": 2,
      "z": -5,
      "name": "Rock_Stone_Brick"
    },
    {
      "x": -4,
      "y": 3,
      "z": -5,
      "name": "Rock_Stone_Brick"
    },
    {
      "x": -4,
      "y": 4,
      "z": -5,
      "name": "Rock_Stone_Brick"
    },
    {
      "x": -4,
      "y": 5,
      "z": -5,
      "name": "Rock_Stone_Brick"
    },
    {
      "x": -4,
      "y": 6,
      "z": -5,
      "name": "Wood_Hardwood_Planks"
    },
    {
      "x": -4,
      "y": 12,
      "z": -5,
      "name": "Wood_Hardwood_Planks"
    },
    {
      "x": -4,
      "y": 16,
      "z": -5,
      "name": "Wood_Softwood_Roof_Hollow",
      "rotation": 2
    },
    {
      "x": -4,
      "y": 0,
      "z": -4,
      "name": "Wood_Softwood_Planks"
    },
    {
      "x": -4,
      "y": 6,
      "z": -4,
      "name": "Wood_Hardwood_Planks"
    },
    {
      "x": -4,
      "y": 12,
      "z": -4,
      "name": "Wood_Hardwood_Planks"
    },
    {
      "x": -4,
      "y": 17,
      "z": -4,
      "name": "Wood_Softwood_Roof_Hollow",
      "rotation": 2
    },
    {
      "x": -4,
      "y": 0,
      "z": -3,
      "name": "Wood_Softwood_Planks"
    },
    {
      "x": -4,
      "y": 6,
      "z": -3,
      "name": "Wood_Hardwood_Planks"
    },
    {
      "x": -4,
      "y": 12,
      "z": -3,
      "name": "Wood_Hardwood_Planks"
    },
    {
      "x": -4,
      "y": 18,
      "z": -3,
      "name": "Wood_Softwood_Roof_Hollow",
      "rotation": 2
    },
    {
      "x": -4,
      "y": 0,
      "z": -2,
      "name": "Wood_Softwood_Planks"
    },
    {
      "x": -4,
      "y": 6,
      "z": -2,
      "name": "Wood_Hardwood_Planks"
    },
    {
      "x": -4,
      "y": 12,
      "z": -2,
      "name": "Wood_Hardwood_Planks"
    },
    {
      "x": -4,
      "y": 19,
      "z": -2,
      "name": "Wood_Softwood_Roof_Flat",
      "rotation": 3
    },
    {
      "x": -4,
      "y": 0,
      "z": -1,
      "name": "Wood_Softwood_Planks"
    },
    {
      "x": -4,
      "y": 6,
      "z": -1,
      "name": "Wood_Hardwood_Planks"
    },
    {
      "x": -4,
      "y": 12,
      "z": -1,
      "name": "Wood_Hardwood_Planks"
    },
    {
      "x": -4,
      "y": 19,
      "z": -1,
      "name": "Wood_Softwood_Roof_Flat",
      "rotation": 3
    },
    {
      "x": -4,
      "y": 0,
      "z": 0,
      "name": "Wood_Softwood_Planks"
    },
    {
      "x": -4,
      "y": 6,
      "z": 0,
      "name": "Wood_Hardwood_Planks"
    },
    {
      "x": -4,
      "y": 12,
      "z": 0,
      "name": "Wood_Hardwood_Planks"
    },
    {
      "x": -4,
      "y": 19,
      "z": 0,
      "name": "Wood_Softwood_Roof_Flat",
      "rotation": 3
    },
    {
      "x": -4,
      "y": 0,
      "z": 1,
      "name": "Wood_Softwood_Planks"
    },
    {
      "x": -4,
      "y": 6,
      "z": 1,
      "name": "Wood_Hardwood_Planks"
    },
    {
      "x": -4,
      "y": 12,
      "z": 1,
      "name": "Wood_Hardwood_Planks"
    },
    {
      "x": -4,
      "y": 19,
      "z": 1,
      "name": "Wood_Softwood_Roof_Flat",
      "rotation": 3
    },
    {
      "x": -4,
      "y": 0,
      "z": 2,
      "name": "Wood_Softwood_Planks"
    },
    {
      "x": -4,
      "y": 6,
      "z": 2,
      "name": "Wood_Hardwood_Planks"
    },
    {
      "x": -4,
      "y": 12,
      "z": 2,
      "name": "Wood_Hardwood_Planks"
    },
    {
      "x": -4,
      "y": 18,
      "z": 2,
      "name": "Wood_Softwood_Roof_Hollow"
    },
    {
      "x": -4,
      "y": 0,
      "z": 3,
      "name": "Wood_Softwood_Planks"
    },
    {
      "x": -4,
      "y": 6,
      "z": 3,
      "name": "Wood_Hardwood_Planks"
    },
    {
      "x": -4,
      "y": 12,
      "z": 3,
      "name": "Wood_Hardwood_Planks"
    },
    {
      "x": -4,
      "y": 17,
      "z": 3,
      "name": "*Wood_Softwood_Roof_Hollow_State_Definitions_Inverted_Corner_Left"
    },
    {
      "x": -4,
      "y": 0,
      "z": 4,
      "name": "Wood_Softwood_Planks"
    },
    {
      "x": -4,
      "y": 6,
      "z": 4,
      "name": "Wood_Hardwood_Planks"
    },
    {
      "x": -4,
      "y": 12,
      "z": 4,
      "name": "Wood_Hardwood_Planks"
    },
    {
      "x": -4,
      "y": 17,
      "z": 4,
      "name": "Wood_Softwood_Roof_Hollow",
      "rotation": 1
    },
    {
      "x": -4,
      "y": 0,
      "z": 5,
      "name": "Soil_Clay_Smooth_Lime"
    },
    {
      "x": -4,
      "y": 1,
      "z": 5,
      "name": "Rock_Stone_Brick"
    },
    {
      "x": -4,
      "y": 2,
      "z": 5,
      "name": "Rock_Stone_Brick"
    },
    {
      "x": -4,
      "y": 3,
      "z": 5,
      "name": "Rock_Stone_Brick"
    },
    {
      "x": -4,
      "y": 4,
      "z": 5,
      "name": "Rock_Stone_Brick"
    },
    {
      "x": -4,
      "y": 5,
      "z": 5,
      "name": "Rock_Stone_Brick"
    },
    {
      "x": -4,
      "y": 6,
      "z": 5,
      "name": "Wood_Hardwood_Planks"
    },
    {
      "x": -4,
      "y": 12,
      "z": 5,
      "name": "Wood_Hardwood_Planks"
    },
    {
      "x": -4,
      "y": 17,
      "z": 5,
      "name": "Wood_Softwood_Roof_Hollow",
      "rotation": 1
    },
    {
      "x": -4,
      "y": 0,
      "z": 6,
      "name": "Soil_Clay_Smooth_Lime"
    },
    {
      "x": -4,
      "y": 5,
      "z": 6,
      "name": "Furniture_Tavern_Trapdoor",
      "rotation": 2
    },
    {
      "x": -4,
      "y": 6,
      "z": 6,
      "name": "Wood_Hardwood_Planks"
    },
    {
      "x": -4,
      "y": 12,
      "z": 6,
      "name": "Wood_Hardwood_Planks"
    },
    {
      "x": -4,
      "y": 17,
      "z": 6,
      "name": "Wood_Softwood_Roof_Hollow",
      "rotation": 1
    },
    {
      "x": -4,
      "y": 0,
      "z": 7,
      "name": "Soil_Clay_Smooth_Lime"
    },
    {
      "x": -4,
      "y": 6,
      "z": 7,
      "name": "Wood_Oak_Trunk",
      "rotation": 5
    },
    {
      "x": -4,
      "y": 7,
      "z": 7,
      "name": "*Wood_Village_Wall_White_Full_State_Definitions_Bottom"
    },
    {
      "x": -4,
      "y": 8,
      "z": 7,
      "name": "*Wood_Village_Wall_White_Full_State_Definitions_Middle"
    },
    {
      "x": -4,
      "y": 9,
      "z": 7,
      "name": "*Wood_Village_Wall_White_Full_State_Definitions_Middle"
    },
    {
      "x": -4,
      "y": 10,
      "z": 7,
      "name": "*Wood_Village_Wall_White_Full_State_Definitions_Middle"
    },
    {
      "x": -4,
      "y": 11,
      "z": 7,
      "name": "*Wood_Village_Wall_White_Full_State_Definitions_Top"
    },
    {
      "x": -4,
      "y": 12,
      "z": 7,
      "name": "Wood_Oak_Trunk",
      "rotation": 5
    },
    {
      "x": -4,
      "y": 17,
      "z": 7,
      "name": "Wood_Softwood_Roof_Hollow",
      "rotation": 1
    },
    {
      "x": -4,
      "y": 0,
      "z": 8,
      "name": "Soil_Clay_Smooth_Lime"
    },
    {
      "x": -4,
      "y": 12,
      "z": 8,
      "name": "Wood_Hardwood_Planks_Half",
      "rotation": 8
    },
    {
      "x": -4,
      "y": 13,
      "z": 8,
      "name": "Wood_Hardwood_Ornate"
    },
    {
      "x": -4,
      "y": 14,
      "z": 8,
      "name": "Furniture_Village_Window"
    },
    {
      "x": -4,
      "y": 15,
      "z": 8,
      "name": "Furniture_Village_Window"
    },
    {
      "x": -4,
      "y": 16,
      "z": 8,
      "name": "Wood_Oak_Trunk",
      "rotation": 5
    },
    {
      "x": -4,
      "y": 17,
      "z": 8,
      "name": "Wood_Softwood_Roof",
      "rotation": 1
    },
    {
      "x": -4,
      "y": 0,
      "z": 9,
      "name": "Soil_Clay_Smooth_Lime"
    },
    {
      "x": -4,
      "y": 13,
      "z": 9,
      "name": "*Furniture_Village_Trapdoor_State_Definitions_OpenDoorOut"
    },
    {
      "x": -4,
      "y": 17,
      "z": 9,
      "name": "Wood_Softwood_Roof_Hollow",
      "rotation": 1
    },
    {
      "x": -4,
      "y": 0,
      "z": 10,
      "name": "Soil_Clay_Smooth_Lime"
    },
    {
      "x": -3,
      "y": 0,
      "z": -10,
      "name": "Soil_Clay_Smooth_Lime"
    },
    {
      "x": -3,
      "y": 0,
      "z": -9,
      "name": "Soil_Clay_Smooth_Lime"
    },
    {
      "x": -3,
      "y": 12,
      "z": -9,
      "name": "Wood_Softwood_Roof_Hollow",
      "rotation": 2
    },
    {
      "x": -3,
      "y": 0,
      "z": -8,
      "name": "Soil_Clay_Smooth_Lime"
    },
    {
      "x": -3,
      "y": 12,
      "z": -8,
      "name": "Wood_Hardwood_Planks_Half",
      "rotation": 8
    },
    {
      "x": -3,
      "y": 13,
      "z": -8,
      "name": "Wood_Softwood_Roof",
      "rotation": 2
    },
    {
