{
  "version": 8,
  "blockIdVersion": 11,
  "anchorX": 0,
  "anchorY": 0,
  "anchorZ": 0,
  "blocks": [
    {
      "x": -26,
      "y": 19,
      "z": -2,
      "name": "Wood_Hardwood_Stairs",
      "rotation": 9
    },
    {
      "x": -25,
      "y": 18,
      "z": -2,
      "name": "Wood_Hardwood_Stairs",
      "rotation": 9
    },
    {
      "x": -25,
      "y": 19,
      "z": -2,
      "name": "Wood_Hardwood_Stairs",
      "rotation": 9
    },
    {
      "x": -24,
      "y": 10,
      "z": -9,
      "name": "Furniture_Crude_Trapdoor",
      "rotation": 2
    },
    {
      "x": -24,
      "y": 9,
      "z": -8,
      "name": "Deco_Lantern_Ceiling"
    },
    {
      "x": -24,
      "y": 10,
      "z": -8,
      "name": "Deco_Iron_Chain_Small"
    },
    {
      "x": -24,
      "y": 11,
      "z": -8,
      "name": "Wood_Hardwood_Planks_Half"
    },
    {
      "x": -24,
      "y": 11,
      "z": -7,
      "name": "Wood_Hardwood_Planks_Half",
      "rotation": 8
    },
    {
      "x": -24,
      "y": 12,
      "z": -6,
      "name": "Wood_Hardwood_Planks"
    },
    {
      "x": -24,
      "y": 13,
      "z": -5,
      "name": "Wood_Hardwood_Planks"
    },
    {
      "x": -24,
      "y": 14,
      "z": -4,
      "name": "Wood_Hardwood_Planks"
    },
    {
      "x": -24,
      "y": 15,
      "z": -4,
      "name": "Wood_Hardwood_Planks"
    },
    {
      "x": -24,
      "y": 16,
      "z": -3,
      "name": "Wood_Hardwood_Planks"
    },
    {
      "x": -24,
      "y": 17,
      "z": -3,
      "name": "Wood_Hardwood_Planks"
    },
    {
      "x": -24,
      "y": 18,
      "z": -2,
      "name": "Wood_Hardwood_Planks"
    },
    {
      "x": -24,
      "y": 19,
      "z": -2,
      "name": "Wood_Hardwood_Planks"
    },
    {
      "x": -24,
      "y": 16,
      "z": -1,
      "name": "Wood_Hardwood_Planks"
    },
    {
      "x": -24,
      "y": 17,
      "z": -1,
      "name": "Wood_Hardwood_Planks"
    },
    {
      "x": -24,
      "y": 14,
      "z": 0,
      "name": "Wood_Hardwood_Planks"
    },
    {
      "x": -24,
      "y": 15,
      "z": 0,
      "name": "Wood_Hardwood_Planks"
    },
    {
      "x": -24,
      "y": 13,
      "z": 1,
      "name": "Wood_Hardwood_Planks"
    },
    {
      "x": -24,
      "y": 12,
      "z": 2,
      "name": "Wood_Hardwood_Planks"
    },
    {
      "x": -24,
      "y": 11,
      "z": 3,
      "name": "Wood_Hardwood_Planks_Half",
      "rotation": 8
    },
    {
      "x": -24,
      "y": 9,
      "z": 4,
      "name": "Deco_Lantern_Ceiling"
    },
    {
      "x": -24,
      "y": 10,
      "z": 4,
      "name": "Deco_Iron_Chain_Small"
    },
    {
      "x": -24,
      "y": 11,
      "z": 4,
      "name": "Wood_Hardwood_Planks_Half"
    },
    {
      "x": -24,
      "y": 10,
      "z": 5,
      "name": "Furniture_Village_Trapdoor",
      "rotation": 2
    },
    {
      "x": -23,
      "y": 23,
      "z": -11,
      "name": "*Rock_Stone_Brick_Stairs_State_Definitions_Corner_Right",
      "rotation": 8
    },
    {
      "x": -23,
      "y": 24,
      "z": -11,
      "name": "*Wood_Hardwood_Fence_State_Definitions_Corner",
      "rotation": 1
    },
    {
      "x": -23,
      "y": 25,
      "z": -11,
      "name": "Wood_Hardwood_Beam"
    },
    {
      "x": -23,
      "y": 26,
      "z": -11,
      "name": "Wood_Hardwood_Beam"
    },
    {
      "x": -23,
      "y": 27,
      "z": -11,
      "name": "Wood_Hardwood_Stairs",
      "rotation": 3
    },
    {
      "x": -23,
      "y": 23,
      "z": -10,
      "name": "Rock_Stone_Brick_Stairs",
      "rotation": 9
    },
    {
      "x": -23,
      "y": 24,
      "z": -10,
      "name": "Wood_Hardwood_Fence",
      "rotation": 3
    },
    {
      "x": -23,
      "y": 27,
      "z": -10,
      "name": "Wood_Hardwood_Stairs",
      "rotation": 9
    },
    {
      "x": -23,
      "y": 10,
      "z": -9,
      "name": "Furniture_Crude_Trapdoor",
      "rotation": 2
    },
    {
      "x": -23,
      "y": 23,
      "z": -9,
      "name": "Rock_Stone_Brick_Stairs",
      "rotation": 9
    },
    {
      "x": -23,
      "y": 24,
      "z": -9,
      "name": "Wood_Hardwood_Fence",
      "rotation": 3
    },
    {
      "x": -23,
      "y": 27,
      "z": -9,
      "name": "Wood_Hardwood_Stairs",
      "rotation": 3
    },
    {
      "x": -23,
      "y": 10,
      "z": -8,
      "name": "Wood_Hardwood_Stairs",
      "rotation": 8
    },
    {
      "x": -23,
      "y": 11,
      "z": -8,
      "name": "Wood_Hardwood_Planks_Half"
    },
    {
      "x": -23,
      "y": 23,
      "z": -8,
      "name": "Rock_Stone_Brick_Stairs",
      "rotation": 9
    },
    {
      "x": -23,
      "y": 24,
      "z": -8,
      "name": "Wood_Hardwood_Fence",
      "rotation": 3
    },
    {
      "x": -23,
      "y": 27,
      "z": -8,
      "name": "Wood_Hardwood_Stairs",
      "rotation": 9
    },
    {
      "x": -23,
      "y": 9,
      "z": -7,
      "name": "Wood_Hardwood_Stairs",
      "rotation": 8
    },
    {
      "x": -23,
      "y": 10,
      "z": -7,
      "name": "Wood_Softwood_Fence_Gate",
      "rotation": 1
    },
    {
      "x": -23,
      "y": 11,
      "z": -7,
      "name": "Rock_Shale_Cobble_Half",
      "rotation": 8
    },
    {
      "x": -23,
      "y": 12,
      "z": -7,
      "name": "Rock_Shale_Cobble_Roof_Flat",
      "rotation": 2
    },
    {
      "x": -23,
      "y": 23,
      "z": -7,
      "name": "*Rock_Stone_Brick_Stairs_State_Definitions_Corner_Left",
      "rotation": 10
    },
    {
      "x": -23,
      "y": 24,
      "z": -7,
      "name": "*Wood_Hardwood_Fence_State_Definitions_Corner",
      "rotation": 2
    },
    {
      "x": -23,
      "y": 25,
      "z": -7,
      "name": "Wood_Hardwood_Beam"
    },
    {
      "x": -23,
      "y": 26,
      "z": -7,
      "name": "Wood_Hardwood_Beam"
    },
    {
      "x": -23,
      "y": 27,
      "z": -7,
      "name": "Wood_Hardwood_Stairs",
      "rotation": 3
    },
    {
      "x": -23,
      "y": 4,
      "z": -6,
      "name": "Rock_Stone_Cobble"
    },
    {
      "x": -23,
      "y": 5,
      "z": -6,
      "name": "Wood_Oak_Trunk",
      "support": 15
    },
    {
      "x": -23,
      "y": 6,
      "z": -6,
      "name": "Wood_Oak_Trunk",
      "support": 15
    },
    {
      "x": -23,
      "y": 7,
      "z": -6,
      "name": "Wood_Oak_Trunk",
      "support": 15
    },
    {
      "x": -23,
      "y": 8,
      "z": -6,
      "name": "Wood_Oak_Trunk",
      "support": 15
    },
    {
      "x": -23,
      "y": 9,
      "z": -6,
      "name": "Wood_Oak_Trunk",
      "support": 15
    },
    {
      "x": -23,
      "y": 10,
      "z": -6,
      "name": "Wood_Oak_Trunk",
      "support": 15
    },
    {
      "x": -23,
      "y": 11,
      "z": -6,
      "name": "Wood_Oak_Trunk",
      "support": 15
    },
    {
      "x": -23,
      "y": 12,
      "z": -6,
      "name": "Rock_Shale_Cobble_Roof",
      "rotation": 2
    },
    {
      "x": -23,
      "y": 4,
      "z": -5,
      "name": "Rock_Stone_Cobble"
    },
    {
      "x": -23,
      "y": 5,
      "z": -5,
      "name": "Wood_Beech_Trunk",
      "support": 15
    },
    {
      "x": -23,
      "y": 6,
      "z": -5,
      "name": "Wood_Beech_Trunk",
      "support": 15
    },
    {
      "x": -23,
      "y": 7,
      "z": -5,
      "name": "Wood_Beech_Trunk",
      "support": 15
    },
    {
      "x": -23,
      "y": 8,
      "z": -5,
      "name": "Wood_Beech_Trunk",
      "support": 15
    },
    {
      "x": -23,
      "y": 9,
      "z": -5,
      "name": "Wood_Beech_Trunk",
      "support": 15
    },
    {
      "x": -23,
      "y": 10,
      "z": -5,
      "name": "Wood_Beech_Trunk",
      "support": 15
    },
    {
      "x": -23,
      "y": 11,
      "z": -5,
      "name": "Wood_Oak_Trunk",
      "support": 15,
      "rotation": 4
    },
    {
      "x": -23,
      "y": 12,
      "z": -5,
      "name": "Wood_Beech_Trunk",
      "support": 15
    },
    {
      "x": -23,
      "y": 13,
      "z": -5,
      "name": "Rock_Shale_Cobble_Roof",
      "rotation": 2
    },
    {
      "x": -23,
      "y": 4,
      "z": -4,
      "name": "Rock_Stone_Cobble"
    },
    {
      "x": -23,
      "y": 5,
      "z": -4,
      "name": "Wood_Beech_Trunk",
      "support": 15
    },
    {
      "x": -23,
      "y": 6,
      "z": -4,
      "name": "Wood_Beech_Trunk",
      "support": 15
    },
    {
      "x": -23,
      "y": 7,
      "z": -4,
      "name": "Wood_Beech_Trunk",
      "support": 15
    },
    {
      "x": -23,
      "y": 8,
      "z": -4,
      "name": "Wood_Beech_Trunk",
      "support": 15
    },
    {
      "x": -23,
      "y": 9,
      "z": -4,
      "name": "Wood_Beech_Trunk",
      "support": 15
    },
    {
      "x": -23,
      "y": 10,
      "z": -4,
      "name": "Wood_Beech_Trunk",
      "support": 15
    },
    {
      "x": -23,
      "y": 11,
      "z": -4,
      "name": "Wood_Oak_Trunk",
      "support": 15,
      "rotation": 4
    },
    {
      "x": -23,
      "y": 12,
      "z": -4,
      "name": "Wood_Beech_Trunk",
      "support": 15
    },
    {
      "x": -23,
      "y": 13,
      "z": -4,
      "name": "Wood_Beech_Trunk",
      "support": 15
    },
    {
      "x": -23,
      "y": 14,
      "z": -4,
      "name": "Rock_Shale_Cobble_Roof_Steep",
      "rotation": 2
    },
    {
      "x": -23,
      "y": 15,
      "z": -4,
      "name": "Rock_Shale_Cobble_Roof_Steep",
      "filler": 1024,
      "rotation": 2
    },
    {
      "x": -23,
      "y": 4,
      "z": -3,
      "name": "Rock_Stone_Cobble"
    },
    {
      "x": -23,
      "y": 5,
      "z": -3,
      "name": "Wood_Beech_Trunk",
      "support": 15
    },
    {
      "x": -23,
      "y": 6,
      "z": -3,
      "name": "Wood_Beech_Trunk",
      "support": 15
    },
    {
      "x": -23,
      "y": 7,
      "z": -3,
      "name": "Wood_Beech_Trunk",
      "support": 15
    },
    {
      "x": -23,
      "y": 8,
      "z": -3,
      "name": "Wood_Beech_Trunk",
      "support": 15
    },
    {
      "x": -23,
      "y": 9,
      "z": -3,
      "name": "Wood_Beech_Trunk",
      "support": 15
    },
    {
      "x": -23,
      "y": 10,
      "z": -3,
      "name": "Wood_Beech_Trunk",
      "support": 15
    },
    {
      "x": -23,
      "y": 11,
      "z": -3,
      "name": "Wood_Oak_Trunk",
      "support": 15,
      "rotation": 4
    },
    {
      "x": -23,
      "y": 12,
      "z": -3,
      "name": "Wood_Beech_Trunk",
      "support": 15
    },
    {
      "x": -23,
      "y": 13,
      "z": -3,
      "name": "Wood_Beech_Trunk",
      "support": 15
    },
    {
      "x": -23,
      "y": 14,
      "z": -3,
      "name": "Wood_Beech_Trunk",
      "support": 15
    },
    {
      "x": -23,
      "y": 15,
      "z": -3,
      "name": "Wood_Beech_Trunk",
      "support": 15
    },
    {
      "x": -23,
      "y": 16,
      "z": -3,
      "name": "Rock_Shale_Cobble_Roof_Steep",
      "rotation": 2
    },
    {
      "x": -23,
      "y": 17,
      "z": -3,
      "name": "Rock_Shale_Cobble_Roof_Steep",
      "filler": 1024,
      "rotation": 2
    },
    {
      "x": -23,
      "y": 4,
      "z": -2,
      "name": "Rock_Stone_Cobble"
    },
    {
      "x": -23,
      "y": 5,
      "z": -2,
      "name": "Wood_Beech_Trunk",
      "support": 15
    },
    {
      "x": -23,
      "y": 6,
      "z": -2,
      "name": "Wood_Beech_Trunk",
      "support": 15
    },
    {
      "x": -23,
      "y": 7,
      "z": -2,
      "name": "Wood_Beech_Trunk",
      "support": 15
    },
    {
      "x": -23,
      "y": 8,
      "z": -2,
      "name": "Wood_Beech_Trunk",
      "support": 15
    },
    {
      "x": -23,
      "y": 9,
      "z": -2,
      "name": "Wood_Beech_Trunk",
      "support": 15
    },
    {
      "x": -23,
      "y": 10,
      "z": -2,
      "name": "Wood_Beech_Trunk",
      "support": 15
    },
    {
      "x": -23,
      "y": 11,
      "z": -2,
      "name": "Wood_Oak_Trunk",
      "support": 15,
      "rotation": 4
    },
    {
      "x": -23,
      "y": 12,
      "z": -2,
      "name": "Wood_Oak_Trunk",
      "support": 15
    },
    {
      "x": -23,
      "y": 13,
      "z": -2,
      "name": "Wood_Oak_Trunk",
      "support": 15
    },
    {
      "x": -23,
      "y": 14,
      "z": -2,
      "name": "Wood_Oak_Trunk",
      "support": 15
    },
    {
      "x": -23,
      "y": 15,
      "z": -2,
      "name": "Wood_Oak_Trunk",
      "support": 15
    },
    {
      "x": -23,
      "y": 16,
      "z": -2,
      "name": "Wood_Oak_Trunk",
      "support": 15
    },
    {
      "x": -23,
      "y": 17,
      "z": -2,
      "name": "Wood_Oak_Trunk",
      "support": 15
    },
    {
      "x": -23,
      "y": 18,
      "z": -2,
      "name": "Rock_Shale_Brick"
    },
    {
      "x": -23,
      "y": 19,
      "z": -2,
      "name": "Rock_Shale_Cobble"
    },
    {
      "x": -23,
      "y": 20,
      "z": -2,
      "name": "Rock_Shale_Cobble_Roof_Flat"
    },
    {
      "x": -23,
      "y": 4,
      "z": -1,
      "name": "Rock_Stone_Cobble"
    },
    {
      "x": -23,
      "y": 5,
      "z": -1,
      "name": "Wood_Beech_Trunk",
      "support": 15
    },
    {
      "x": -23,
      "y": 6,
      "z": -1,
      "name": "Wood_Beech_Trunk",
      "support": 15
    },
    {
      "x": -23,
      "y": 7,
      "z": -1,
      "name": "Wood_Beech_Trunk",
      "support": 15
    },
    {
      "x": -23,
      "y": 8,
      "z": -1,
      "name": "Wood_Beech_Trunk",
      "support": 15
    },
    {
      "x": -23,
      "y": 9,
      "z": -1,
      "name": "Wood_Beech_Trunk",
      "support": 15
    },
    {
      "x": -23,
      "y": 10,
      "z": -1,
      "name": "Wood_Beech_Trunk",
      "support": 15
    },
    {
      "x": -23,
      "y": 11,
      "z": -1,
      "name": "Wood_Oak_Trunk",
      "support": 15,
      "rotation": 4
    },
    {
      "x": -23,
      "y": 12,
      "z": -1,
      "name": "Wood_Beech_Trunk",
      "support": 15
    },
    {
      "x": -23,
      "y": 13,
      "z": -1,
      "name": "Wood_Beech_Trunk",
      "support": 15
    },
    {
      "x": -23,
      "y": 14,
      "z": -1,
      "name": "Wood_Beech_Trunk",
      "support": 15
    },
    {
      "x": -23,
      "y": 15,
      "z": -1,
      "name": "Wood_Beech_Trunk",
      "support": 15
    },
    {
      "x": -23,
      "y": 16,
      "z": -1,
      "name": "Rock_Shale_Cobble_Roof_Steep"
    },
    {
      "x": -23,
      "y": 17,
      "z": -1,
      "name": "Rock_Shale_Cobble_Roof_Steep",
      "filler": 1024
    },
    {
      "x": -23,
      "y": 4,
      "z": 0,
      "name": "Rock_Stone_Cobble"
    },
    {
      "x": -23,
      "y": 5,
      "z": 0,
      "name": "Wood_Beech_Trunk",
      "support": 15
    },
    {
      "x": -23,
      "y": 6,
      "z": 0,
      "name": "Wood_Beech_Trunk",
      "support": 15
    },
    {
      "x": -23,
      "y": 7,
      "z": 0,
      "name": "Wood_Beech_Trunk",
      "support": 15
    },
    {
      "x": -23,
      "y": 8,
      "z": 0,
      "name": "Wood_Beech_Trunk",
      "support": 15
    },
    {
      "x": -23,
      "y": 9,
      "z": 0,
      "name": "Wood_Beech_Trunk",
      "support": 15
    },
    {
      "x": -23,
      "y": 10,
      "z": 0,
      "name": "Wood_Beech_Trunk",
      "support": 15
    },
    {
      "x": -23,
      "y": 11,
      "z": 0,
      "name": "Wood_Oak_Trunk",
      "support": 15,
      "rotation": 4
    },
    {
      "x": -23,
      "y": 12,
      "z": 0,
      "name": "Wood_Beech_Trunk",
      "support": 15
    },
    {
      "x": -23,
      "y": 13,
      "z": 0,
      "name": "Wood_Beech_Trunk",
      "support": 15
    },
    {
      "x": -23,
      "y": 14,
      "z": 0,
      "name": "Rock_Shale_Brick_Roof_Steep"
    },
    {
      "x": -23,
      "y": 15,
      "z": 0,
      "name": "Rock_Shale_Brick_Roof_Steep",
      "filler": 1024
    },
    {
      "x": -23,
      "y": 4,
      "z": 1,
      "name": "Rock_Stone_Cobble"
    },
    {
      "x": -23,
      "y": 5,
      "z": 1,
      "name": "Wood_Beech_Trunk",
      "support": 15
    },
    {
      "x": -23,
      "y": 6,
      "z": 1,
      "name": "Wood_Beech_Trunk",
      "support": 15
    },
    {
      "x": -23,
      "y": 7,
      "z": 1,
      "name": "Wood_Beech_Trunk",
      "support": 15
    },
    {
      "x": -23,
      "y": 8,
      "z": 1,
      "name": "Wood_Beech_Trunk",
      "support": 15
    },
    {
      "x": -23,
      "y": 9,
      "z": 1,
      "name": "Wood_Beech_Trunk",
      "support": 15
    },
    {
      "x": -23,
      "y": 10,
      "z": 1,
      "name": "Wood_Beech_Trunk",
      "support": 15
    },
    {
      "x": -23,
      "y": 11,
      "z": 1,
      "name": "Wood_Oak_Trunk",
      "support": 15,
      "rotation": 4
    },
    {
      "x": -23,
      "y": 12,
      "z": 1,
      "name": "Wood_Beech_Trunk",
      "support": 15
    },
    {
      "x": -23,
      "y": 13,
      "z": 1,
      "name": "Rock_Shale_Cobble_Roof"
    },
    {
      "x": -23,
      "y": 4,
      "z": 2,
      "name": "Rock_Stone_Cobble"
    },
    {
      "x": -23,
      "y": 5,
      "z": 2,
      "name": "Wood_Oak_Trunk",
      "support": 15
    },
    {
      "x": -23,
      "y": 6,
      "z": 2,
      "name": "Wood_Oak_Trunk",
      "support": 15
    },
    {
      "x": -23,
      "y": 7,
      "z": 2,
      "name": "Wood_Oak_Trunk",
      "support": 15
    },
    {
      "x": -23,
      "y": 8,
      "z": 2,
      "name": "Wood_Oak_Trunk",
      "support": 15
    },
    {
      "x": -23,
      "y": 9,
      "z": 2,
      "name": "Wood_Oak_Trunk",
      "support": 15
    },
    {
      "x": -23,
      "y": 10,
      "z": 2,
      "name": "Wood_Oak_Trunk",
      "support": 15
    },
    {
      "x": -23,
      "y": 11,
      "z": 2,
      "name": "Wood_Oak_Trunk",
      "support": 15
    },
    {
      "x": -23,
      "y": 12,
      "z": 2,
      "name": "Rock_Shale_Brick_Roof"
    },
    {
      "x": -23,
      "y": 9,
      "z": 3,
      "name": "Wood_Hardwood_Stairs",
      "rotation": 10
    },
    {
      "x": -23,
      "y": 10,
      "z": 3,
      "name": "Wood_Softwood_Fence_Gate",
      "rotation": 3
    },
    {
      "x": -23,
      "y": 11,
      "z": 3,
      "name": "Rock_Shale_Cobble_Half",
      "rotation": 8
    },
    {
      "x": -23,
      "y": 12,
      "z": 3,
      "name": "Rock_Shale_Brick_Roof_Flat",
      "rotation": 1
    },
    {
      "x": -23,
      "y": 10,
      "z": 4,
      "name": "Wood_Hardwood_Stairs",
      "rotation": 10
    },
    {
      "x": -23,
      "y": 11,
      "z": 4,
      "name": "Wood_Hardwood_Planks_Half"
    },
    {
      "x": -23,
      "y": 10,
      "z": 5,
      "name": "Furniture_Village_Trapdoor",
      "rotation": 2
    },
    {
      "x": -22,
      "y": 23,
      "z": -12,
      "name": "*Rock_Stone_Brick_Stairs_State_Definitions_Corner_Left",
      "rotation": 9
    },
    {
      "x": -22,
      "y": 24,
      "z": -12,
      "name": "*Wood_Hardwood_Fence_State_Definitions_Corner",
      "rotation": 1
    },
    {
      "x": -22,
      "y": 25,
      "z": -12,
      "name": "Wood_Hardwood_Beam"
    },
    {
      "x": -22,
      "y": 26,
      "z": -12,
      "name": "Wood_Hardwood_Beam"
    },
    {
      "x": -22,
      "y": 27,
      "z": -12,
      "name": "Wood_Hardwood_Stairs",
      "rotation": 2
    },
    {
      "x": -22,
      "y": 5,
      "z": -11,
      "name": "Rock_Stone_Cobble_Beam"
    },
    {
      "x": -22,
      "y": 6,
      "z": -11,
      "name": "Rock_Stone_Cobble_Beam"
    },
    {
      "x": -22,
      "y": 7,
      "z": -11,
      "name": "Rock_Stone_Cobble_Beam"
    },
    {
      "x": -22,
      "y": 8,
      "z": -11,
      "name": "Rock_Stone_Cobble_Beam"
    },
    {
      "x": -22,
      "y": 9,
      "z": -11,
      "name": "Rock_Stone_Cobble_Beam"
    },
    {
      "x": -22,
      "y": 10,
      "z": -11,
      "name": "Rock_Stone_Cobble_Beam"
    },
    {
      "x": -22,
      "y": 11,
      "z": -11,
      "name": "Rock_Stone_Cobble_Beam"
    },
    {
      "x": -22,
      "y": 12,
      "z": -11,
      "name": "Rock_Stone_Cobble_Beam"
    },
    {
      "x": -22,
      "y": 13,
      "z": -11,
      "name": "Rock_Stone_Cobble_Beam"
    },
    {
      "x": -22,
      "y": 14,
      "z": -11,
      "name": "Rock_Stone_Cobble_Beam"
    },
    {
      "x": -22,
      "y": 15,
      "z": -11,
      "name": "Rock_Stone_Cobble_Beam"
    },
    {
      "x": -22,
      "y": 16,
      "z": -11,
      "name": "Rock_Stone_Cobble_Beam"
    },
    {
      "x": -22,
      "y": 17,
      "z": -11,
      "name": "Rock_Stone_Cobble_Beam"
    },
    {
      "x": -22,
      "y": 18,
      "z": -11,
      "name": "Rock_Stone_Cobble_Beam"
    },
    {
      "x": -22,
      "y": 19,
      "z": -11,
      "name": "Rock_Stone_Cobble_Beam"
    },
    {
      "x": -22,
      "y": 20,
      "z": -11,
      "name": "Rock_Stone_Cobble_Beam"
    },
    {
      "x": -22,
      "y": 21,
      "z": -11,
      "name": "Rock_Stone_Cobble_Beam"
    },
    {
      "x": -22,
      "y": 22,
      "z": -11,
      "name": "Rock_Stone_Cobble_Beam"
    },
    {
      "x": -22,
      "y": 23,
      "z": -11,
      "name": "Rock_Stone_Brick_Stairs",
      "rotation": 9
    },
    {
      "x": -22,
      "y": 24,
      "z": -11,
      "name": "*Wood_Hardwood_Fence_State_Definitions_Corner",
      "rotation": 3
    },
    {
      "x": -22,
      "y": 27,
      "z": -11,
      "name": "Rock_Shale_Cobble_Half",
      "rotation": 8
    },
    {
      "x": -22,
      "y": 28,
      "z": -11,
      "name": "Rock_Shale_Brick_Beam"
    },
    {
      "x": -22,
      "y": 5,
      "z": -10,
      "name": "Rock_Stone_Brick"
    },
    {
      "x": -22,
      "y": 6,
      "z": -10,
      "name": "Rock_Stone_Brick"
    },
    {
      "x": -22,
      "y": 7,
      "z": -10,
      "name": "Rock_Stone_Brick"
    },
    {
      "x": -22,
      "y": 8,
      "z": -10,
      "name": "Rock_Stone_Brick_Mossy"
    },
    {
      "x": -22,
      "y": 9,
      "z": -10,
      "name": "Rock_Stone_Brick"
    },
    {
      "x": -22,
      "y": 10,
      "z": -10,
      "name": "Rock_Stone_Brick"
    },
    {
      "x": -22,
      "y": 11,
      "z": -10,
      "name": "Rock_Stone_Brick"
    },
    {
      "x": -22,
      "y": 12,
      "z": -10,
      "name": "Rock_Stone_Brick"
    },
    {
      "x": -22,
      "y": 13,
      "z": -10,
      "name": "Rock_Stone_Brick_Mossy"
    },
    {
      "x": -22,
      "y": 14,
      "z": -10,
      "name": "Rock_Stone_Brick"
    },
    {
      "x": -22,
      "y": 15,
      "z": -10,
      "name": "Rock_Stone_Brick_Mossy"
    },
    {
      "x": -22,
      "y": 16,
      "z": -10,
      "name": "Rock_Stone_Brick"
    },
    {
      "x": -22,
      "y": 17,
      "z": -10,
      "name": "Rock_Stone_Brick"
    },
    {
      "x": -22,
      "y": 18,
      "z": -10,
      "name": "Rock_Stone_Brick"
    },
    {
      "x": -22,
      "y": 19,
      "z": -10,
      "name": "Rock_Stone_Brick"
    },
    {
      "x": -22,
      "y": 20,
      "z": -10,
      "name": "Rock_Stone_Brick"
    },
    {
      "x": -22,
      "y": 21,
      "z": -10,
      "name": "Rock_Stone_Brick"
    },
    {
      "x": -22,
      "y": 22,
      "z": -10,
      "name": "Rock_Stone_Brick"
    },
    {
      "x": -22,
      "y": 23,
      "z": -10,
      "name": "Rock_Stone_Brick"
    },
    {
      "x": -22,
      "y": 27,
      "z": -10,
      "name": "Rock_Shale_Cobble_Half",
      "rotation": 8
    },
    {
      "x": -22,
      "y": 28,
      "z": -10,
      "name": "*Rock_Shale_Cobble_Roof_State_Definitions_Corner_Left",
      "rotation": 2
    },
    {
      "x": -22,
      "y": 5,
      "z": -9,
      "name": "Rock_Stone_Brick_Mossy"
    },
    {
      "x": -22,
      "y": 6,
      "z": -9,
      "name": "Rock_Stone_Brick"
    },
    {
      "x": -22,
      "y": 7,
      "z": -9,
      "name": "Rock_Stone_Brick"
    },
    {
      "x": -22,
      "y": 8,
      "z": -9,
      "name": "Rock_Stone_Brick_Mossy"
    },
    {
      "x": -22,
      "y": 9,
      "z": -9,
      "name": "Rock_Stone_Brick"
    },
    {
      "x": -22,
      "y": 10,
      "z": -9,
      "name": "Rock_Stone_Brick"
    },
    {
      "x": -22,
      "y": 11,
      "z": -9,
      "name": "Rock_Stone_Brick"
    },
    {
      "x": -22,
      "y": 12,
      "z": -9,
      "name": "Rock_Stone_Brick"
    },
    {
      "x": -22,
      "y": 13,
      "z": -9,
      "name": "Rock_Stone_Brick"
    },
    {
      "x": -22,
      "y": 14,
      "z": -9,
      "name": "Rock_Stone_Brick"
    },
    {
      "x": -22,
      "y": 15,
      "z": -9,
      "name": "Rock_Stone_Brick"
    },
    {
      "x": -22,
      "y": 16,
      "z": -9,
      "name": "Rock_Stone_Brick"
    },
    {
      "x": -22,
      "y": 17,
      "z": -9,
      "name": "Rock_Stone_Brick"
    },
    {
      "x": -22,
      "y": 18,
      "z": -9,
      "name": "Rock_Stone_Brick"
    },
    {
      "x": -22,
      "y": 19,
      "z": -9,
      "name": "Rock_Stone_Brick_Mossy"
    },
    {
      "x": -22,
      "y": 20,
      "z": -9,
      "name": "Rock_Stone_Brick_Mossy"
    },
    {
      "x": -22,
      "y": 21,
      "z": -9,
      "name": "Rock_Stone_Brick"
    },
    {
      "x": -22,
      "y": 22,
      "z": -9,
      "name": "Rock_Stone_Brick"
    },
    {
      "x": -22,
      "y": 23,
      "z": -9,
      "name": "Rock_Stone_Brick"
    },
    {
      "x": -22,
      "y": 27,
      "z": -9,
      "name": "Rock_Shale_Cobble_Half",
      "rotation": 8
    },
    {
      "x": -22,
      "y": 28,
      "z": -9,
      "name": "Rock_Shale_Brick_Roof",
      "rotation": 3
    },
    {
      "x": -22,
      "y": 5,
      "z": -8,
      "name": "Rock_Stone_Brick"
    },
    {
      "x": -22,
      "y": 6,
      "z": -8,
      "name": "Rock_Stone_Brick"
    },
    {
      "x": -22,
      "y": 7,
      "z": -8,
      "name": "Rock_Stone_Brick_Mossy"
    },
    {
      "x": -22,
      "y": 8,
      "z": -8,
      "name": "Rock_Stone_Brick"
    },
    {
      "x": -22,
      "y": 9,
      "z": -8,
      "name": "Rock_Stone_Brick"
    },
    {
      "x": -22,
      "y": 10,
      "z": -8,
      "name": "Rock_Stone_Brick"
    },
    {
      "x": -22,
      "y": 11,
      "z": -8,
      "name": "Rock_Stone_Brick"
    },
    {
      "x": -22,
      "y": 12,
      "z": -8,
      "name": "Rock_Stone_Brick"
    },
    {
      "x": -22,
      "y": 13,
      "z": -8,
      "name": "Rock_Stone_Brick"
    },
    {
      "x": -22,
      "y": 14,
      "z": -8,
      "name": "Rock_Stone_Brick"
    },
    {
      "x": -22,
      "y": 15,
      "z": -8,
      "name": "Rock_Stone_Brick_Mossy"
    },
    {
      "x": -22,
      "y": 16,
      "z": -8,
      "name": "Rock_Stone_Brick"
    },
    {
      "x": -22,
      "y": 17,
      "z": -8,
      "name": "Rock_Stone_Brick"
    },
    {
      "x": -22,
      "y": 18,
      "z": -8,
      "name": "Rock_Stone_Brick"
    },
    {
      "x": -22,
      "y": 19,
      "z": -8,
      "name": "Rock_Stone_Brick"
    },
    {
      "x": -22,
      "y": 20,
      "z": -8,
      "name": "Rock_Stone_Brick"
    },
    {
      "x": -22,
      "y": 21,
      "z": -8,
      "name": "Rock_Stone_Brick"
    },
    {
      "x": -22,
      "y": 22,
      "z": -8,
      "name": "Rock_Stone_Brick"
    },
    {
      "x": -22,
      "y": 23,
      "z": -8,
      "name": "Rock_Stone_Brick"
    },
    {
      "x": -22,
      "y": 27,
      "z": -8,
      "name": "Rock_Shale_Cobble_Half",
      "rotation": 8
    },
    {
      "x": -22,
      "y": 28,
      "z": -8,
      "name": "*Rock_Shale_Cobble_Roof_State_Definitions_Corner_Right"
    },
    {
      "x": -22,
      "y": 5,
      "z": -7,
      "name": "Rock_Stone_Cobble_Beam"
    },
    {
      "x": -22,
      "y": 6,
      "z": -7,
      "name": "Rock_Stone_Cobble_Beam"
    },
    {
      "x": -22,
      "y": 7,
      "z": -7,
      "name": "Rock_Stone_Cobble_Beam"
    },
    {
      "x": -22,
      "y": 8,
      "z": -7,
      "name": "Rock_Stone_Cobble_Beam"
    },
    {
      "x": -22,
      "y": 9,
      "z": -7,
      "name": "Rock_Stone_Cobble_Beam"
    },
    {
      "x": -22,
      "y": 10,
      "z": -7,
      "name": "Rock_Stone_Cobble_Beam"
    },
    {
      "x": -22,
      "y": 11,
      "z": -7,
      "name": "Rock_Stone_Cobble_Beam"
    },
    {
      "x": -22,
      "y": 12,
      "z": -7,
      "name": "Rock_Stone_Cobble_Beam"
    },
    {
      "x": -22,
      "y": 13,
      "z": -7,
      "name": "Rock_Stone_Cobble_Beam"
    },
    {
      "x": -22,
      "y": 14,
      "z": -7,
      "name": "Rock_Stone_Cobble_Beam"
    },
    {
      "x": -22,
      "y": 15,
      "z": -7,
      "name": "Rock_Stone_Cobble_Beam"
    },
    {
      "x": -22,
      "y": 16,
      "z": -7,
      "name": "Rock_Stone_Cobble_Beam"
    },
    {
      "x": -22,
      "y": 17,
      "z": -7,
      "name": "Rock_Stone_Cobble_Beam"
    },
    {
      "x": -22,
      "y": 18,
      "z": -7,
      "name": "Rock_Stone_Cobble_Beam"
    },
    {
      "x": -22,
      "y": 19,
      "z": -7,
      "name": "Rock_Stone_Cobble_Beam"
    },
    {
      "x": -22,
      "y": 20,
      "z": -7,
      "name": "Rock_Stone_Cobble_Beam"
    },
    {
      "x": -22,
      "y": 21,
      "z": -7,
      "name": "Rock_Stone_Cobble_Beam"
    },
    {
      "x": -22,
      "y": 22,
      "z": -7,
      "name": "Rock_Stone_Cobble_Beam"
    },
    {
      "x": -22,
      "y": 23,
      "z": -7,
      "name": "Rock_Stone_Brick_Stairs",
      "rotation": 10
    },
    {
      "x": -22,
      "y": 24,
      "z": -7,
      "name": "*Wood_Hardwood_Fence_State_Definitions_Corner"
    },
    {
      "x": -22,
      "y": 27,
      "z": -7,
      "name": "Rock_Shale_Cobble_Half",
      "rotation": 8
    },
    {
      "x": -22,
      "y": 28,
      "z": -7,
      "name": "Rock_Shale_Brick_Beam"
    },
    {
      "x": -22,
      "y": 4,
      "z": -6,
      "name": "Rock_Stone_Cobble"
    },
    {
      "x": -22,
      "y": 5,
      "z": -6,
      "name": "Wood_Beech_Trunk",
      "support": 15
    },
    {
      "x": -22,
      "y": 6,
      "z": -6,
      "name": "Wood_Beech_Trunk",
      "support": 15
    },
    {
      "x": -22,
      "y": 7,
      "z": -6,
      "name": "Wood_Beech_Trunk",
      "support": 15
    },
    {
      "x": -22,
      "y": 8,
      "z": -6,
      "name": "Wood_Beech_Trunk",
      "support": 15
    },
    {
      "x": -22,
      "y": 9,
      "z": -6,
      "name": "Wood_Beech_Trunk",
      "support": 15
    },
    {
      "x": -22,
      "y": 10,
      "z": -6,
      "name": "Wood_Beech_Trunk",
      "support": 15
    },
    {
      "x": -22,
      "y": 11,
      "z": -6,
      "name": "Wood_Beech_Trunk",
      "support": 15
    },
    {
      "x": -22,
      "y": 12,
      "z": -6,
      "name": "Rock_Shale_Brick_Roof",
      "rotation": 2
    },
    {
      "x": -22,
      "y": 23,
      "z": -6,
      "name": "*Rock_Stone_Brick_Stairs_State_Definitions_Corner_Right",
      "rotation": 9
    },
    {
      "x": -22,
      "y": 24,
      "z": -6,
      "name": "*Wood_Hardwood_Fence_State_Definitions_Corner",
      "rotation": 2
    },
    {
      "x": -22,
      "y": 25,
      "z": -6,
      "name": "Wood_Hardwood_Beam"
    },
    {
      "x": -22,
      "y": 26,
      "z": -6,
      "name": "Wood_Hardwood_Beam"
    },
    {
      "x": -22,
      "y": 27,
      "z": -6,
      "name": "Wood_Hardwood_Stairs"
    },
    {
      "x": -22,
      "y": 5,
      "z": -5,
      "name": "Wood_Hardwood_Planks"
    },
    {
      "x": -22,
      "y": 12,
      "z": -5,
      "name": "Wood_Hardwood_Planks"
    },
    {
      "x": -22,
      "y": 13,
      "z": -5,
      "name": "Rock_Shale_Cobble_Roof",
      "rotation": 2
    },
    {
      "x": -22,
      "y": 5,
      "z": -4,
      "name": "Wood_Hardwood_Planks"
    },
    {
      "x": -22,
      "y": 12,
      "z": -4,
      "name": "Wood_Hardwood_Planks"
    },
    {
      "x": -22,
      "y": 13,
      "z": -4,
      "name": "Wood_Hardwood_Stairs",
      "rotation": 10
    },
    {
      "x": -22,
      "y": 14,
      "z": -4,
      "name": "Rock_Shale_Cobble_Roof_Steep",
      "rotation": 2
    },
    {
      "x": -22,
      "y": 15,
      "z": -4,
      "name": "Rock_Shale_Cobble_Roof_Steep",
      "filler": 1024,
      "rotation": 2
    },
    {
      "x": -22,
      "y": 5,
      "z": -3,
      "name": "Wood_Hardwood_Planks"
    },
    {
      "x": -22,
      "y": 12,
      "z": -3,
      "name": "Wood_Hardwood_Planks"
    },
    {
      "x": -22,
      "y": 16,
      "z": -3,
      "name": "Rock_Shale_Cobble_Roof_Steep",
      "rotation": 2
    },
    {
      "x": -22,
      "y": 17,
      "z": -3,
      "name": "Rock_Shale_Cobble_Roof_Steep",
      "filler": 1024,
      "rotation": 2
    },
    {
      "x": -22,
      "y": 5,
      "z": -2,
      "name": "Wood_Hardwood_Planks"
    },
    {
      "x": -22,
      "y": 12,
      "z": -2,
      "name": "Wood_Hardwood_Planks"
    },
    {
      "x": -22,
      "y": 18,
      "z": -2,
      "name": "Rock_Shale_Cobble"
    },
    {
      "x": -22,
      "y": 19,
      "z": -2,
      "name": "Rock_Shale_Brick"
    },
    {
      "x": -22,
      "y": 20,
      "z": -2,
      "name": "Rock_Shale_Cobble_Roof_Flat"
    },
    {
      "x": -22,
      "y": 5,
      "z": -1,
      "name": "Wood_Hardwood_Planks"
    },
    {
      "x": -22,
      "y": 12,
      "z": -1,
      "name": "Wood_Hardwood_Planks"
    },
    {
      "x": -22,
      "y": 16,
      "z": -1,
      "name": "Rock_Shale_Brick_Roof_Steep"
    },
    {
      "x": -22,
      "y": 17,
      "z": -1,
      "name": "Rock_Shale_Brick_Roof_Steep",
      "filler": 1024
    },
    {
      "x": -22,
      "y": 5,
      "z": 0,
      "name": "Wood_Hardwood_Planks"
    },
    {
      "x": -22,
      "y": 12,
      "z": 0,
      "name": "Wood_Hardwood_Planks"
    },
    {
      "x": -22,
      "y": 13,
      "z": 0,
      "name": "Wood_Hardwood_Stairs",
      "rotation": 8
    },
    {
      "x": -22,
      "y": 14,
      "z": 0,
      "name": "Rock_Shale_Cobble_Roof_Steep"
    },
    {
      "x": -22,
      "y": 15,
      "z": 0,
      "name": "Rock_Shale_Cobble_Roof_Steep",
      "filler": 1024
    },
    {
      "x": -22,
      "y": 16,
      "z": 0,
      "name": "Furniture_Village_Trapdoor",
      "rotation": 1
    },
    {
      "x": -22,
      "y": 5,
      "z": 1,
      "name": "Wood_Hardwood_Planks"
    },
    {
      "x": -22,
      "y": 12,
      "z": 1,
      "name": "Wood_Hardwood_Planks"
    },
    {
      "x": -22,
      "y": 13,
      "z": 1,
      "name": "Rock_Shale_Brick_Roof"
    },
    {
      "x": -22,
      "y": 16,
      "z": 1,
      "name": "Furniture_Village_Trapdoor",
      "rotation": 1
    },
    {
      "x": -22,
      "y": 4,
      "z": 2,
      "name": "Rock_Stone_Cobble"
    },
    {
      "x": -22,
      "y": 5,
      "z": 2,
      "name": "Wood_Beech_Trunk",
      "support": 15
    },
    {
      "x": -22,
      "y": 6,
      "z": 2,
      "name": "Wood_Beech_Trunk",
      "support": 15
    },
    {
      "x": -22,
      "y": 7,
      "z": 2,
      "name": "Wood_Beech_Trunk",
      "support": 15
    },
    {
      "x": -22,
      "y": 8,
      "z": 2,
      "name": "Wood_Beech_Trunk",
      "support": 15
    },
    {
      "x": -22,
      "y": 9,
      "z": 2,
      "name": "Wood_Beech_Trunk",
      "support": 15
    },
    {
      "x": -22,
      "y": 10,
      "z": 2,
      "name": "Wood_Beech_Trunk",
      "support": 15
    },
    {
      "x": -22,
      "y": 11,
      "z": 2,
      "name": "Wood_Beech_Trunk",
      "support": 15
    },
    {
      "x": -22,
      "y": 12,
      "z": 2,
      "name": "Rock_Shale_Brick_Roof"
    },
    {
      "x": -22,
      "y": 16,
      "z": 2,
      "name": "Furniture_Village_Trapdoor",
      "rotation": 2
    },
    {
      "x": -22,
      "y": 5,
      "z": 3,
      "name": "Plant_Bush_Lush",
      "support": 15
    },
    {
      "x": -22,
      "y": 7,
      "z": 3,
      "name": "*Furniture_Temple_Dark_Trapdoor_State_Definitions_OpenDoorOut"
    },
    {
      "x": -22,
      "y": 8,
      "z": 3,
      "name": "*Furniture_Temple_Dark_Trapdoor_State_Definitions_OpenDoorOut"
    },
    {
      "x": -22,
      "y": 9,
      "z": 3,
      "name": "*Furniture_Temple_Dark_Trapdoor_State_Definitions_OpenDoorOut"
    },
    {
      "x": -22,
      "y": 10,
      "z": 3,
      "name": "*Furniture_Temple_Dark_Trapdoor_State_Definitions_OpenDoorOut"
    },
    {
      "x": -22,
      "y": 11,
      "z": 3,
      "name": "Rock_Shale_Cobble_Half",
      "rotation": 8
    },
    {
      "x": -22,
      "y": 12,
      "z": 3,
      "name": "Rock_Shale_Cobble_Roof_Flat"
    },
    {
      "x": -22,
      "y": 11,
      "z": 4,
      "name": "Wood_Hardwood_Planks_Half"
    },
    {
      "x": -22,
      "y": 10,
      "z": 5,
      "name": "Furniture_Village_Trapdoor",
      "rotation": 2
    },
    {
      "x": -21,
      "y": 23,
      "z": -12,
      "name": "Rock_Stone_Brick_Stairs",
      "rotation": 8
    },
    {
      "x": -21,
      "y": 24,
      "z": -12,
      "name": "Wood_Hardwood_Fence",
      "rotation": 2
    },
    {
      "x": -21,
      "y": 27,
      "z": -12,
      "name": "Wood_Hardwood_Stairs",
      "rotation": 8
    },
    {
      "x": -21,
      "y": 5,
      "z": -11,
      "name": "Rock_Stone_Brick"
    },
    {
      "x": -21,
      "y": 6,
      "z": -11,
      "name": "Rock_Stone_Brick"
    },
    {
      "x": -21,
      "y": 7,
      "z": -11,
      "name": "Rock_Stone_Brick"
    },
    {
      "x": -21,
      "y": 8,
      "z": -11,
      "name": "Rock_Stone_Brick"
    },
    {
      "x": -21,
      "y": 9,
      "z": -11,
      "name": "Rock_Stone_Brick"
    },
    {
      "x": -21,
      "y": 10,
      "z": -11,
      "name": "Rock_Stone_Brick"
    },
    {
      "x": -21,
      "y": 11,
      "z": -11,
      "name": "Rock_Stone_Brick"
    },
    {
      "x": -21,
      "y": 12,
      "z": -11,
      "name": "Rock_Stone_Brick_Mossy"
    },
    {
      "x": -21,
      "y": 13,
      "z": -11,
      "name": "Rock_Stone_Brick"
    },
    {
      "x": -21,
      "y": 14,
      "z": -11,
      "name": "Rock_Stone_Brick"
    },
    {
      "x": -21,
      "y": 15,
      "z": -11,
      "name": "Rock_Stone_Brick"
    },
    {
      "x": -21,
      "y": 16,
      "z": -11,
      "name": "Rock_Stone_Brick"
    },
    {
      "x": -21,
      "y": 17,
      "z": -11,
      "name": "Rock_Stone_Brick"
    },
    {
      "x": -21,
      "y": 18,
      "z": -11,
      "name": "Rock_Stone_Brick"
    },
    {
      "x": -21,
      "y": 19,
      "z": -11,
      "name": "Rock_Stone_Brick"
    },
    {
      "x": -21,
      "y": 20,
      "z": -11,
      "name": "Rock_Stone_Brick"
    },
    {
      "x": -21,
      "y": 21,
      "z": -11,
      "name": "Rock_Stone_Brick"
    },
    {
      "x": -21,
      "y": 22,
      "z": -11,
      "name": "Rock_Stone_Brick"
    },
    {
      "x": -21,
      "y": 23,
      "z": -11,
      "name": "Rock_Stone_Brick"
    },
    {
      "x": -21,
      "y": 27,
      "z": -11,
      "name": "Rock_Shale_Cobble_Half",
      "rotation": 8
    },
    {
      "x": -21,
      "y": 28,
      "z": -11,
      "name": "*Rock_Shale_Cobble_Roof_State_Definitions_Corner_Right",
      "rotation": 3
    },
    {
      "x": -21,
      "y": 5,
      "z": -10,
      "name": "Wood_Hardwood_Planks"
    },
    {
      "x": -21,
      "y": 11,
      "z": -10,
      "name": "Wood_Hardwood_Planks"
    },
    {
      "x": -21,
      "y": 17,
      "z": -10,
      "name": "Wood_Hardwood_Planks"
    },
    {
      "x": -21,
      "y": 23,
      "z": -10,
      "name": "Rock_Stone_Brick"
    },
    {
      "x": -21,
      "y": 27,
      "z": -10,
      "name": "Rock_Shale_Cobble_Half",
      "rotation": 8
    },
    {
      "x": -21,
      "y": 28,
      "z": -10,
      "name": "Rock_Shale_Cobble"
    },
    {
      "x": -21,
      "y": 29,
      "z": -10,
      "name": "Rock_Shale_Cobble"
    },
    {
      "x": -21,
      "y": 30,
      "z": -10,
      "name": "Rock_Shale_Brick_Beam"
    },
    {
      "x": -21,
      "y": 5,
      "z": -9,
      "name": "Wood_Hardwood_Planks"
    },
    {
      "x": -21,
      "y": 11,
      "z": -9,
      "name": "Wood_Hardwood_Planks"
    },
    {
      "x": -21,
      "y": 17,
      "z": -9,
      "name": "Wood_Hardwood_Planks"
    },
    {
      "x": -21,
      "y": 23,
      "z": -9,
      "name": "Rock_Stone_Brick"
    },
    {
      "x": -21,
      "y": 27,
      "z": -9,
      "name": "Rock_Shale_Cobble_Half",
      "rotation": 8
    },
    {
      "x": -21,
      "y": 28,
      "z": -9,
      "name": "Rock_Shale_Cobble"
    },
    {
      "x": -21,
      "y": 29,
      "z": -9,
      "name": "Rock_Shale_Cobble_Roof_Steep",
      "rotation": 3
    },
    {
      "x": -21,
      "y": 30,
      "z": -9,
      "name": "Rock_Shale_Cobble_Roof_Steep",
      "filler": 1024,
      "rotation": 3
    },
    {
      "x": -21,
      "y": 5,
      "z": -8,
      "name": "Wood_Hardwood_Planks"
    },
    {
      "x": -21,
      "y": 11,
      "z": -8,
      "name": "Wood_Hardwood_Planks"
    },
    {
      "x": -21,
      "y": 17,
      "z": -8,
      "name": "Wood_Hardwood_Planks"
    },
    {
      "x": -21,
      "y": 23,
      "z": -8,
      "name": "Rock_Stone_Brick"
    },
    {
      "x": -21,
      "y": 27,
      "z": -8,
      "name": "Rock_Shale_Cobble_Half",
      "rotation": 8
    },
    {
      "x": -21,
      "y": 28,
      "z": -8,
      "name": "Rock_Shale_Cobble"
    },
    {
      "x": -21,
      "y": 29,
      "z": -8,
      "name": "Rock_Shale_Cobble"
    },
    {
      "x": -21,
      "y": 30,
      "z": -8,
      "name": "Rock_Shale_Brick_Beam"
    },
    {
      "x": -21,
      "y": 5,
      "z": -7,
      "name": "Rock_Stone_Brick"
    },
    {
      "x": -21,
      "y": 6,
      "z": -7,
      "name": "Rock_Stone_Brick"
    },
    {
      "x": -21,
      "y": 7,
      "z": -7,
      "name": "Rock_Stone_Brick"
    },
    {
      "x": -21,
      "y": 8,
      "z": -7,
      "name": "Rock_Stone_Brick"
    },
    {
      "x": -21,
      "y": 9,
      "z": -7,
      "name": "Rock_Stone_Brick"
    },
    {
      "x": -21,
      "y": 10,
      "z": -7,
      "name": "Rock_Stone_Brick"
    },
    {
      "x": -21,
      "y": 11,
      "z": -7,
      "name": "Rock_Stone_Brick"
    },
    {
      "x": -21,
      "y": 12,
      "z": -7,
      "name": "Rock_Stone_Brick"
    },
    {
      "x": -21,
      "y": 13,
      "z": -7,
      "name": "Rock_Stone_Brick"
    },
    {
      "x": -21,
      "y": 14,
      "z": -7,
      "name": "Rock_Stone_Brick"
    },
    {
      "x": -21,
      "y": 15,
      "z": -7,
      "name": "Rock_Stone_Brick"
    },
    {
      "x": -21,
      "y": 16,
      "z": -7,
      "name": "Rock_Stone_Brick"
    },
    {
      "x": -21,
      "y": 17,
      "z": -7,
      "name": "Rock_Stone_Brick"
    },
    {
      "x": -21,
      "y": 18,
      "z": -7,
      "name": "Rock_Stone_Brick"
    },
    {
      "x": -21,
      "y": 19,
      "z": -7,
      "name": "Rock_Stone_Brick_Mossy"
    },
    {
      "x": -21,
      "y": 20,
      "z": -7,
      "name": "Rock_Stone_Brick"
    },
    {
      "x": -21,
      "y": 21,
      "z": -7,
      "name": "Rock_Stone_Brick"
    },
    {
      "x": -21,
      "y": 22,
      "z": -7,
      "name": "Rock_Stone_Brick"
    },
    {
      "x": -21,
      "y": 23,
      "z": -7,
      "name": "Rock_Stone_Brick"
    },
    {
      "x": -21,
      "y": 27,
      "z": -7,
      "name": "Rock_Shale_Cobble_Half",
      "rotation": 8
    },
    {
      "x": -21,
      "y": 28,
      "z": -7,
      "name": "*Rock_Shale_Cobble_Roof_State_Definitions_Corner_Left",
      "rotation": 3
    },
    {
      "x": -21,
      "y": 4,
      "z": -6,
      "name": "Rock_Stone_Cobble"
    },
    {
      "x": -21,
      "y": 5,
      "z": -6,
      "name": "Wood_Hardwood_Planks"
    },
    {
      "x": -21,
      "y": 6,
      "z": -6,
      "name": "Rock_Stone_Brick_Half",
      "rotation": 5
    },
    {
      "x": -21,
      "y": 7,
      "z": -6,
      "name": "Rock_Stone_Brick_Half",
      "rotation": 5
    },
    {
      "x": -21,
      "y": 8,
      "z": -6,
      "name": "Rock_Stone_Brick_Stairs",
      "rotation": 11
    },
    {
      "x": -21,
      "y": 9,
      "z": -6,
      "name": "Wood_Beech_Trunk",
      "support": 15
    },
    {
      "x": -21,
      "y": 10,
      "z": -6,
      "name": "Wood_Beech_Trunk",
      "support": 15
    },
    {
      "x": -21,
      "y": 11,
      "z": -6,
      "name": "Wood_Beech_Trunk",
      "support": 15
    },
    {
      "x": -21,
      "y": 12,
      "z": -6,
      "name": "Rock_Shale_Cobble_Roof",
      "rotation": 2
    },
    {
      "x": -21,
      "y": 23,
      "z": -6,
      "name": "Rock_Stone_Brick_Stairs",
      "rotation": 10
    },
    {
      "x": -21,
      "y": 24,
      "z": -6,
      "name": "Wood_Hardwood_Fence"
    },
    {
      "x": -21,
      "y": 27,
      "z": -6,
      "name": "Wood_Hardwood_Stairs",
      "rotation": 10
    },
    {
      "x": -21,
      "y": 5,
      "z": -5,
      "name": "Wood_Hardwood_Planks"
    },
    {
      "x": -21,
      "y": 12,
      "z": -5,
      "name": "Wood_Hardwood_Planks"
    },
    {
      "x": -21,
      "y": 13,
      "z": -5,
      "name": "Rock_Shale_Cobble_Roof",
      "rotation": 2
    },
    {
      "x": -21,
      "y": 5,
      "z": -4,
      "name": "Wood_Hardwood_Planks"
    },
    {
      "x": -21,
      "y": 12,
      "z": -4,
      "name": "Wood_Hardwood_Planks"
    },
    {
      "x": -21,
      "y": 13,
      "z": -4,
      "name": "Wood_Hardwood_Stairs",
      "rotation": 10
    },
    {
      "x": -21,
      "y": 14,
      "z": -4,
      "name": "Rock_Shale_Cobble_Roof_Steep",
      "rotation": 2
    },
    {
      "x": -21,
      "y": 15,
      "z": -4,
      "name": "Rock_Shale_Cobble_Roof_Steep",
      "filler": 1024,
      "rotation": 2
    },
    {
      "x": -21,
      "y": 5,
      "z": -3,
      "name": "Wood_Hardwood_Planks"
    },
    {
      "x": -21,
      "y": 12,
      "z": -3,
      "name": "Wood_Hardwood_Planks"
    },
    {
      "x": -21,
      "y": 16,
      "z": -3,
      "name": "Rock_Shale_Brick_Roof_Steep",
      "rotation": 2
    },
    {
      "x": -21,
      "y": 17,
      "z": -3,
      "name": "Rock_Shale_Brick_Roof_Steep",
      "filler": 1024,
      "rotation": 2
    },
    {
      "x": -21,
      "y": 5,
      "z": -2,
      "name": "Wood_Hardwood_Planks"
    },
    {
      "x": -21,
      "y": 12,
      "z": -2,
      "name": "Wood_Hardwood_Planks"
    },
    {
      "x": -21,
      "y": 17,
      "z": -2,
      "name": "Deco_Lantern_Ceiling"
    },
    {
      "x": -21,
      "y": 18,
      "z": -2,
      "name": "Rock_Shale_Brick"
    },
    {
      "x": -21,
      "y": 19,
      "z": -2,
      "name": "Rock_Shale_Cobble"
    },
    {
      "x": -21,
      "y": 20,
      "z": -2,
      "name": "Rock_Shale_Cobble_Roof_Flat"
    },
    {
      "x": -21,
      "y": 5,
      "z": -1,
      "name": "Wood_Hardwood_Planks"
    },
    {
      "x": -21,
      "y": 12,
      "z": -1,
      "name": "Wood_Hardwood_Planks"
    },
    {
      "x": -21,
      "y": 17,
      "z": -1,
      "name": "Rock_Shale_Brick_Roof_Hollow"
    },
    {
      "x": -21,
      "y": 5,
      "z": 0,
      "name": "Wood_Hardwood_Planks"
    },
    {
      "x": -21,
      "y": 12,
      "z": 0,
      "name": "Wood_Hardwood_Planks"
    },
    {
      "x": -21,
      "y": 13,
      "z": 0,
      "name": "Wood_Hardwood_Stairs",
      "rotation": 8
    },
    {
      "x": -21,
      "y": 14,
      "z": 0,
      "name": "Wood_Oak_Trunk",
      "support": 15
    },
    {
      "x": -21,
      "y": 15,
      "z": 0,
      "name": "Wood_Oak_Trunk",
      "support": 15
    },
    {
      "x": -21,
      "y": 16,
      "z": 0,
      "name": "Wood_Oak_Trunk",
      "support": 15
    },
    {
      "x": -21,
      "y": 17,
      "z": 0,
      "name": "Wood_Hardwood_Planks_Half"
    },
    {
      "x": -21,
      "y": 5,
      "z": 1,
      "name": "Wood_Hardwood_Planks"
    },
    {
      "x": -21,
      "y": 12,
      "z": 1,
      "name": "Wood_Hardwood_Planks"
    },
    {
      "x": -21,
      "y": 13,
      "z": 1,
      "name": "Rock_Shale_Brick_Roof"
    },
    {
      "x": -21,
      "y": 17,
      "z": 1,
      "name": "Wood_Hardwood_Planks_Half"
    },
    {
      "x": -21,
      "y": 4,
      "z": 2,
      "name": "Rock_Stone_Cobble"
    },
    {
      "x": -21,
      "y": 5,
      "z": 2,
      "name": "Wood_Beech_Trunk",
      "support": 15
    },
    {
      "x": -21,
      "y": 6,
      "z": 2,
      "name": "Wood_Beech_Trunk",
      "support": 15
    },
    {
      "x": -21,
      "y": 7,
      "z": 2,
      "name": "Furniture_Village_Window"
    },
    {
      "x": -21,
      "y": 8,
      "z": 2,
      "name": "Furniture_Village_Window"
    },
    {
      "x": -21,
      "y": 9,
      "z": 2,
      "name": "Furniture_Village_Window"
    },
    {
      "x": -21,
      "y": 10,
      "z": 2,
      "name": "Furniture_Village_Window"
    },
    {
      "x": -21,
      "y": 11,
      "z": 2,
      "name": "Wood_Beech_Trunk",
      "support": 15
    },
    {
      "x": -21,
      "y": 12,
      "z": 2,
      "name": "Rock_Shale_Cobble_Roof"
    },
    {
      "x": -21,
      "y": 16,
      "z": 2,
      "name": "Furniture_Village_Trapdoor",
      "rotation": 2
    },
    {
      "x": -21,
      "y": 11,
      "z": 3,
      "name": "Rock_Shale_Cobble_Half",
      "rotation": 8
    },
    {
      "x": -21,
      "y": 12,
      "z": 3,
      "name": "Rock_Shale_Cobble_Roof_Flat"
    },
    {
      "x": -21,
      "y": 5,
      "z": 4,
      "name": "Plant_Flower_Bushy_Green"
    },
    {
      "x": -21,
      "y": 11,
      "z": 4,
      "name": "Wood_Hardwood_Planks_Half"
    },
    {
      "x": -21,
      "y": 5,
      "z": 5,
      "name": "Plant_Grass_Sharp_Overgrown",
      "support": 15
    },
    {
      "x": -21,
      "y": 6,
      "z": 5,
      "name": "Plant_Grass_Sharp_Overgrown",
      "filler": 1024
    },
    {
      "x": -21,
      "y": 10,
      "z": 5,
      "name": "Furniture_Village_Trapdoor",
      "rotation": 2
    },
    {
      "x": -20,
      "y": 23,
      "z": -12,
      "name": "Rock_Stone_Brick_Stairs",
      "rotation": 8
    },
    {
      "x": -20,
      "y": 24,
      "z": -12,
      "name": "Wood_Hardwood_Fence",
      "rotation": 2
    },
    {
      "x": -20,
      "y": 27,
      "z": -12,
      "name": "Wood_Hardwood_Stairs",
      "rotation": 2
    },
    {
      "x": -20,
      "y": 5,
      "z": -11,
      "name": "Rock_Stone_Brick"
    },
    {
      "x": -20,
      "y": 6,
      "z": -11,
      "name": "Rock_Stone_Brick"
    },
    {
      "x": -20,
      "y": 7,
      "z": -11,
      "name": "Rock_Stone_Brick"
    },
    {
      "x": -20,
      "y": 8,
      "z": -11,
      "name": "Rock_Stone_Brick_Mossy"
    },
    {
      "x": -20,
      "y": 9,
      "z": -11,
      "name": "Rock_Stone_Brick_Mossy"
    },
    {
      "x": -20,
      "y": 10,
      "z": -11,
      "name": "Rock_Stone_Brick"
    },
    {
      "x": -20,
      "y": 11,
      "z": -11,
      "name": "Rock_Stone_Brick"
    },
    {
      "x": -20,
      "y": 12,
      "z": -11,
      "name": "Rock_Stone_Brick"
    },
    {
      "x": -20,
      "y": 13,
      "z": -11,
      "name": "Rock_Stone_Brick"
    },
    {
      "x": -20,
      "y": 14,
      "z": -11,
      "name": "Rock_Stone_Brick"
    },
    {
      "x": -20,
      "y": 15,
      "z": -11,
      "name": "Rock_Stone_Brick"
    },
    {
      "x": -20,
      "y": 16,
      "z": -11,
      "name": "Rock_Stone_Brick_Mossy"
    },
    {
      "x": -20,
      "y": 17,
      "z": -11,
      "name": "Rock_Stone_Brick"
    },
    {
      "x": -20,
      "y": 18,
      "z": -11,
      "name": "Rock_Stone_Brick"
    },
    {
      "x": -20,
      "y": 19,
      "z": -11,
      "name": "Rock_Stone_Brick"
    },
    {
      "x": -20,
      "y": 20,
      "z": -11,
      "name": "Rock_Stone_Brick"
    },
    {
      "x": -20,
      "y": 21,
      "z": -11,
      "name": "Rock_Stone_Brick"
    },
    {
      "x": -20,
      "y": 22,
      "z": -11,
      "name": "Rock_Stone_Brick"
    },
    {
      "x": -20,
      "y": 23,
      "z": -11,
      "name": "Rock_Stone_Brick"
    },
    {
      "x": -20,
      "y": 27,
      "z": -11,
      "name": "Rock_Shale_Cobble_Half",
      "rotation": 8
    },
    {
      "x": -20,
      "y": 28,
      "z": -11,
      "name": "Rock_Shale_Brick_Roof",
      "rotation": 2
    },
    {
      "x": -20,
      "y": 5,
      "z": -10,
      "name": "Wood_Hardwood_Planks"
    },
    {
      "x": -20,
      "y": 6,
      "z": -10,
      "name": "Furniture_Lumberjack_Ladder"
    },
    {
      "x": -20,
      "y": 7,
      "z": -10,
      "name": "Furniture_Lumberjack_Ladder"
    },
    {
      "x": -20,
      "y": 8,
      "z": -10,
      "name": "Furniture_Lumberjack_Ladder"
    },
    {
      "x": -20,
      "y": 9,
      "z": -10,
      "name": "Furniture_Lumberjack_Ladder"
    },
    {
      "x": -20,
      "y": 10,
      "z": -10,
      "name": "Furniture_Lumberjack_Ladder"
    },
    {
      "x": -20,
      "y": 11,
      "z": -10,
      "name": "Furniture_Lumberjack_Ladder"
    },
    {
      "x": -20,
      "y": 12,
      "z": -10,
      "name": "Furniture_Lumberjack_Ladder"
    },
    {
      "x": -20,
      "y": 13,
      "z": -10,
      "name": "Furniture_Lumberjack_Ladder"
    },
    {
      "x": -20,
      "y": 14,
      "z": -10,
      "name": "Furniture_Lumberjack_Ladder"
    },
    {
      "x": -20,
      "y": 15,
      "z": -10,
      "name": "Furniture_Lumberjack_Ladder"
    },
    {
      "x": -20,
      "y": 16,
      "z": -10,
      "name": "Furniture_Lumberjack_Ladder"
    },
    {
      "x": -20,
      "y": 17,
      "z": -10,
      "name": "Furniture_Lumberjack_Ladder"
    },
    {
      "x": -20,
      "y": 18,
      "z": -10,
      "name": "Furniture_Lumberjack_Ladder"
    },
    {
      "x": -20,
      "y": 19,
      "z": -10,
      "name": "Furniture_Lumberjack_Ladder"
    },
    {
      "x": -20,
      "y": 20,
      "z": -10,
      "name": "Furniture_Lumberjack_Ladder"
    },
    {
      "x": -20,
      "y": 21,
      "z": -10,
      "name": "Furniture_Lumberjack_Ladder"
    },
    {
      "x": -20,
      "y": 22,
      "z": -10,
      "name": "Furniture_Lumberjack_Ladder"
    },
    {
      "x": -20,
      "y": 23,
      "z": -10,
      "name": "Furniture_Lumberjack_Ladder"
    },
    {
      "x": -20,
      "y": 27,
      "z": -10,
      "name": "Rock_Shale_Cobble_Half",
      "rotation": 8
    },
    {
      "x": -20,
      "y": 28,
      "z": -10,
      "name": "Rock_Shale_Cobble"
    },
    {
      "x": -20,
      "y": 29,
      "z": -10,
      "name": "Rock_Shale_Cobble_Roof_Steep",
      "rotation": 2
    },
    {
      "x": -20,
      "y": 30,
      "z": -10,
      "name": "Rock_Shale_Cobble_Roof_Steep",
      "filler": 1024,
      "rotation": 2
    },
    {
      "x": -20,
      "y": 5,
      "z": -9,
      "name": "Wood_Hardwood_Planks"
    },
    {
      "x": -20,
      "y": 11,
      "z": -9,
      "name": "Wood_Hardwood_Planks"
    },
    {
      "x": -20,
      "y": 17,
      "z": -9,
      "name": "Wood_Hardwood_Planks"
    },
    {
      "x": -20,
      "y": 23,
      "z": -9,
      "name": "Rock_Stone_Brick"
    },
    {
      "x": -20,
      "y": 27,
      "z": -9,
      "name": "Rock_Shale_Cobble_Half",
      "rotation": 8
    },
    {
      "x": -20,
      "y": 28,
      "z": -9,
      "name": "Rock_Shale_Cobble"
    },
    {
      "x": -20,
      "y": 29,
      "z": -9,
      "name": "Rock_Shale_Cobble"
    },
    {
      "x": -20,
      "y": 30,
      "z": -9,
      "name": "Rock_Shale_Cobble"
    },
    {
      "x": -20,
      "y": 31,
      "z": -9,
      "name": "Rock_Shale_Brick_Pillar_Base"
    },
    {
      "x": -20,
      "y": 32,
      "z": -9,
      "name": "Rock_Shale_Brick_Beam"
    },
    {
      "x": -20,
      "y": 33,
      "z": -9,
      "name": "Wood_Hardwood_Beam"
    },
    {
      "x": -20,
      "y": 5,
      "z": -8,
      "name": "Wood_Hardwood_Planks"
    },
    {
      "x": -20,
      "y": 11,
      "z": -8,
      "name": "Wood_Hardwood_Planks"
    },
    {
      "x": -20,
      "y": 17,
      "z": -8,
      "name": "Wood_Hardwood_Planks"
    },
    {
      "x": -20,
      "y": 23,
      "z": -8,
      "name": "Rock_Stone_Brick"
    },
    {
      "x": -20,
      "y": 27,
      "z": -8,
      "name": "Rock_Shale_Cobble_Half",
      "rotation": 8
    },
    {
      "x": -20,
      "y": 28,
      "z": -8,
      "name": "Rock_Shale_Cobble"
    },
    {
      "x": -20,
      "y": 29,
      "z": -8,
      "name": "Rock_Shale_Cobble_Roof_Steep"
    },
    {
      "x": -20,
      "y": 30,
      "z": -8,
      "name": "Rock_Shale_Cobble_Roof_Steep",
      "filler": 1024
    },
    {
      "x": -20,
      "y": 5,
      "z": -7,
      "name": "Wood_Hardwood_Planks"
    },
    {
      "x": -20,
      "y": 8,
      "z": -7,
      "name": "Rock_Stone_Brick"
    },
    {
      "x": -20,
      "y": 9,
      "z": -7,
      "name": "Rock_Stone_Brick"
    },
    {
      "x": -20,
      "y": 10,
      "z": -7,
      "name": "Rock_Stone_Brick"
    },
    {
      "x": -20,
      "y": 11,
      "z": -7,
      "name": "Rock_Stone_Brick"
    },
    {
      "x": -20,
      "y": 12,
      "z": -7,
      "name": "Rock_Stone_Brick"
    },
    {
      "x": -20,
      "y": 13,
      "z": -7,
      "name": "Rock_Stone_Brick_Mossy"
    },
    {
      "x": -20,
      "y": 14,
      "z": -7,
      "name": "Rock_Stone_Brick"
    },
    {
      "x": -20,
      "y": 15,
      "z": -7,
      "name": "Rock_Stone_Brick"
    },
    {
      "x": -20,
      "y": 16,
      "z": -7,
      "name": "Rock_Stone_Brick_Mossy"
    },
    {
      "x": -20,
      "y": 17,
      "z": -7,
      "name": "Rock_Stone_Brick"
    },
    {
      "x": -20,
      "y": 18,
      "z": -7,
      "name": "Rock_Stone_Brick"
    },
    {
      "x": -20,
      "y": 19,
      "z": -7,
      "name": "Deco_Iron_Bars"
    },
    {
      "x": -20,
      "y": 20,
      "z": -7,
      "name": "Deco_Iron_Bars"
    },
    {
      "x": -20,
      "y": 21,
      "z": -7,
      "name": "Deco_Iron_Bars"
    },
    {
      "x": -20,
      "y": 22,
      "z": -7,
      "name": "Rock_Stone_Brick_Mossy"
    },
    {
      "x": -20,
      "y": 23,
      "z": -7,
      "name": "Rock_Stone_Brick"
    },
    {
      "x": -20,
      "y": 27,
      "z": -7,
      "name": "Rock_Shale_Cobble_Half",
      "rotation": 8
    },
    {
      "x": -20,
      "y": 28,
      "z": -7,
      "name": "Rock_Shale_Cobble_Roof"
    },
    {
      "x": -20,
      "y": 4,
      "z": -6,
      "name": "Rock_Stone_Cobble"
    },
    {
      "x": -20,
      "y": 5,
      "z": -6,
      "name": "Wood_Hardwood_Planks"
    },
    {
      "x": -20,
      "y": 8,
      "z": -6,
      "name": "Rock_Stone_Brick_Half",
      "rotation": 8
    },
    {
      "x": -20,
      "y": 9,
      "z": -6,
      "name": "Wood_Beech_Trunk",
      "support": 15
    },
    {
      "x": -20,
      "y": 10,
      "z": -6,
      "name": "Wood_Beech_Trunk",
      "support": 15
    },
    {
      "x": -20,
      "y": 11,
      "z": -6,
      "name": "Wood_Beech_Trunk",
      "support": 15
    },
    {
      "x": -20,
      "y": 12,
      "z": -6,
      "name": "Rock_Shale_Cobble_Roof",
      "rotation": 2
    },
    {
      "x": -20,
      "y": 23,
      "z": -6,
      "name": "Rock_Stone_Brick_Stairs",
      "rotation": 10
    },
    {
      "x": -20,
      "y": 24,
      "z": -6,
      "name": "Wood_Hardwood_Fence"
    },
    {
      "x": -20,
      "y": 27,
      "z": -6,
      "name": "Wood_Hardwood_Stairs"
    },
    {
      "x": -20,
      "y": 5,
      "z": -5,
      "name": "Wood_Hardwood_Planks"
    },
    {
      "x": -20,
      "y": 12,
      "z": -5,
      "name": "Wood_Hardwood_Planks"
    },
    {
      "x": -20,
      "y": 13,
      "z": -5,
      "name": "Rock_Shale_Cobble_Roof",
      "rotation": 2
    },
    {
      "x": -20,
      "y": 5,
      "z": -4,
      "name": "Wood_Hardwood_Planks"
    },
    {
      "x": -20,
      "y": 12,
      "z": -4,
      "name": "Wood_Hardwood_Planks"
    },
    {
      "x": -20,
      "y": 13,
      "z": -4,
      "name": "Wood_Hardwood_Stairs",
      "rotation": 10
    },
    {
      "x": -20,
      "y": 14,
      "z": -4,
      "name": "Rock_Shale_Brick_Roof_Steep",
      "rotation": 2
    },
    {
      "x": -20,
      "y": 15,
      "z": -4,
      "name": "Rock_Shale_Brick_Roof_Steep",
      "filler": 1024,
      "rotation": 2
    },
    {
      "x": -20,
      "y": 5,
      "z": -3,
      "name": "Wood_Hardwood_Planks"
    },
    {
      "x": -20,
      "y": 12,
      "z": -3,
      "name": "Wood_Hardwood_Planks"
    },
    {
      "x": -20,
      "y": 16,
      "z": -3,
      "name": "Rock_Shale_Brick_Roof_Steep",
      "rotation": 2
    },
    {
      "x": -20,
      "y": 17,
      "z": -3,
      "name": "Rock_Shale_Brick_Roof_Steep",
      "filler": 1024,
      "rotation": 2
    },
    {
      "x": -20,
      "y": 5,
      "z": -2,
      "name": "Wood_Hardwood_Planks"
    },
    {
      "x": -20,
      "y": 12,
      "z": -2,
      "name": "Wood_Hardwood_Planks"
    },
    {
      "x": -20,
      "y": 18,
      "z": -2,
      "name": "Rock_Shale_Brick"
    },
    {
      "x": -20,
      "y": 19,
      "z": -2,
      "name": "Rock_Shale_Cobble"
    },
    {
      "x": -20,
      "y": 20,
      "z": -2,
      "name": "Rock_Shale_Cobble_Roof_Flat"
    },
    {
      "x": -20,
      "y": 5,
      "z": -1,
      "name": "Wood_Hardwood_Planks"
    },
    {
      "x": -20,
      "y": 12,
      "z": -1,
      "name": "Wood_Hardwood_Planks"
    },
    {
      "x": -20,
      "y": 17,
      "z": -1,
      "name": "Rock_Shale_Brick_Roof_Hollow"
    },
    {
      "x": -20,
      "y": 5,
      "z": 0,
      "name": "Wood_Hardwood_Planks"
    },
    {
      "x": -20,
      "y": 12,
      "z": 0,
      "name": "Wood_Hardwood_Planks"
    },
    {
      "x": -20,
      "y": 13,
      "z": 0,
      "name": "Wood_Hardwood_Stairs",
      "rotation": 8
    },
    {
      "x": -20,
      "y": 14,
      "z": 0,
      "name": "Furniture_Village_Window"
    },
    {
      "x": -20,
      "y": 15,
      "z": 0,
      "name": "Furniture_Village_Window"
    },
    {
      "x": -20,
      "y": 16,
      "z": 0,
      "name": "Furniture_Village_Window"
    },
    {
      "x": -20,
      "y": 17,
      "z": 0,
      "name": "Wood_Hardwood_Planks"
    },
    {
      "x": -20,
      "y": 18,
      "z": 0,
      "name": "Rock_Shale_Cobble_Roof_Flat"
    },
    {
      "x": -20,
      "y": 5,
      "z": 1,
      "name": "Wood_Hardwood_Planks"
    },
    {
      "x": -20,
      "y": 12,
      "z": 1,
      "name": "Wood_Hardwood_Planks"
    },
    {
      "x": -20,
      "y": 13,
      "z": 1,
      "name": "Rock_Shale_Cobble_Roof"
    },
    {
      "x": -20,
      "y": 17,
      "z": 1,
      "name": "Wood_Hardwood_Planks_Half"
    },
    {
      "x": -20,
      "y": 4,
      "z": 2,
      "name": "Rock_Stone_Cobble"
    },
    {
      "x": -20,
      "y": 5,
      "z": 2,
      "name": "Wood_Beech_Trunk",
      "support": 15
    },
    {
      "x": -20,
      "y": 6,
      "z": 2,
      "name": "Wood_Beech_Trunk",
      "support": 15
    },
    {
      "x": -20,
      "y": 7,
      "z": 2,
      "name": "Furniture_Village_Window"
    },
    {
      "x": -20,
      "y": 8,
      "z": 2,
      "name": "Furniture_Village_Window"
    },
    {
      "x": -20,
      "y": 9,
      "z": 2,
      "name": "Furniture_Village_Window"
    },
    {
      "x": -20,
      "y": 10,
      "z": 2,
      "name": "Furniture_Village_Window"
    },
    {
      "x": -20,
      "y": 11,
      "z": 2,
      "name": "Wood_Beech_Trunk",
      "support": 15
    },
    {
      "x": -20,
      "y": 12,
      "z": 2,
      "name": "Rock_Shale_Cobble_Roof"
    },
    {
      "x": -20,
      "y": 16,
      "z": 2,
      "name": "Furniture_Village_Trapdoor",
      "rotation": 2
    },
    {
      "x": -20,
      "y": 5,
      "z": 3,
      "name": "Plant_Flower_Bushy_Green"
    },
    {
      "x": -20,
      "y": 11,
      "z": 3,
      "name": "Rock_Shale_Cobble_Half",
      "rotation": 8
    },
    {
      "x": -20,
      "y": 12,
      "z": 3,
      "name": "Rock_Shale_Brick_Roof_Flat",
      "rotation": 1
    },
    {
      "x": -20,
      "y": 11,
      "z": 4,
      "name": "Wood_Hardwood_Planks_Half"
    },
    {
      "x": -20,
      "y": 10,
      "z": 5,
      "name": "Furniture_Village_Trapdoor",
      "rotation": 2
    },
    {
      "x": -19,
      "y": 23,
      "z": -12,
      "name": "Rock_Stone_Brick_Stairs",
      "rotation": 8
    },
    {
      "x": -19,
      "y": 24,
      "z": -12,
      "name": "Wood_Hardwood_Fence",
      "rotation": 2
    },
    {
      "x": -19,
      "y": 27,
      "z": -12,
      "name": "Wood_Hardwood_Stairs",
      "rotation": 8
    },
    {
      "x": -19,
      "y": 5,
      "z": -11,
      "name": "Rock_Stone_Brick"
    },
    {
      "x": -19,
      "y": 6,
      "z": -11,
      "name": "Rock_Stone_Brick"
    },
    {
      "x": -19,
      "y": 7,
      "z": -11,
      "name": "Rock_Stone_Brick"
    },
    {
      "x": -19,
      "y": 8,
      "z": -11,
      "name": "Rock_Stone_Brick_Mossy"
    },
    {
      "x": -19,
      "y": 9,
      "z": -11,
      "name": "Rock_Stone_Brick_Mossy"
    },
    {
      "x": -19,
      "y": 10,
      "z": -11,
      "name": "Rock_Stone_Brick"
    },
    {
      "x": -19,
      "y": 11,
      "z": -11,
      "name": "Rock_Stone_Brick"
    },
    {
      "x": -19,
      "y": 12,
      "z": -11,
      "name": "Rock_Stone_Brick"
    },
    {
      "x": -19,
      "y": 13,
      "z": -11,
      "name": "Rock_Stone_Brick"
    },
    {
      "x": -19,
      "y": 14,
      "z": -11,
      "name": "Rock_Stone_Brick_Mossy"
    },
    {
      "x": -19,
      "y": 15,
      "z": -11,
      "name": "Rock_Stone_Brick"
    },
    {
      "x": -19,
      "y": 16,
      "z": -11,
      "name": "Rock_Stone_Brick"
    },
    {
      "x": -19,
      "y": 17,
      "z": -11,
      "name": "Rock_Stone_Brick"
    },
    {
      "x": -19,
      "y": 18,
      "z": -11,
      "name": "Rock_Stone_Brick"
    },
    {
      "x": -19,
      "y": 19,
      "z": -11,
      "name": "Rock_Stone_Brick"
    },
    {
      "x": -19,
      "y": 20,
      "z": -11,
      "name": "Rock_Stone_Brick_Mossy"
    },
    {
      "x": -19,
      "y": 21,
      "z": -11,
      "name": "Rock_Stone_Brick_Mossy"
    },
    {
      "x": -19,
      "y": 22,
      "z": -11,
      "name": "Rock_Stone_Brick"
    },
    {
      "x": -19,
      "y": 23,
      "z": -11,
      "name": "Rock_Stone_Brick"
    },
    {
      "x": -19,
      "y": 27,
      "z": -11,
      "name": "Rock_Shale_Cobble_Half",
      "rotation": 8
    },
    {
      "x": -19,
      "y": 28,
      "z": -11,
      "name": "*Rock_Shale_Cobble_Roof_State_Definitions_Corner_Left",
      "rotation": 1
    },
    {
      "x": -19,
      "y": 5,
      "z": -10,
      "name": "Wood_Hardwood_Planks"
    },
    {
      "x": -19,
      "y": 11,
      "z": -10,
      "name": "Wood_Hardwood_Planks"
    },
    {
      "x": -19,
      "y": 17,
      "z": -10,
      "name": "Wood_Hardwood_Planks"
    },
    {
      "x": -19,
      "y": 23,
      "z": -10,
      "name": "Rock_Stone_Brick"
    },
    {
      "x": -19,
      "y": 27,
      "z": -10,
      "name": "Rock_Shale_Cobble_Half",
      "rotation": 8
    },
    {
      "x": -19,
      "y": 28,
      "z": -10,
      "name": "Rock_Shale_Cobble"
    },
    {
      "x": -19,
      "y": 29,
      "z": -10,
      "name": "Rock_Shale_Cobble"
    },
    {
      "x": -19,
      "y": 30,
      "z": -10,
      "name": "Rock_Shale_Brick_Beam"
    },
    {
      "x": -19,
      "y": 5,
      "z": -9,
      "name": "Wood_Hardwood_Planks"
    },
    {
      "x": -19,
      "y": 11,
      "z": -9,
      "name": "Wood_Hardwood_Planks"
    },
    {
      "x": -19,
      "y": 17,
      "z": -9,
      "name": "Wood_Hardwood_Planks"
    },
    {
      "x": -19,
      "y": 23,
      "z": -9,
      "name": "Rock_Stone_Brick"
    },
    {
      "x": -19,
      "y": 27,
      "z": -9,
      "name": "Rock_Shale_Cobble_Half",
      "rotation": 8
    },
    {
      "x": -19,
      "y": 28,
      "z": -9,
      "name": "Rock_Shale_Cobble"
    },
    {
      "x": -19,
      "y": 29,
      "z": -9,
      "name": "Rock_Shale_Brick_Roof_Steep",
      "rotation": 1
    },
    {
      "x": -19,
      "y": 30,
      "z": -9,
      "name": "Rock_Shale_Brick_Roof_Steep",
      "filler": 1024,
      "rotation": 1
    },
    {
      "x": -19,
      "y": 5,
      "z": -8,
      "name": "Wood_Hardwood_Planks"
    },
    {
      "x": -19,
      "y": 11,
      "z": -8,
      "name": "Wood_Hardwood_Planks"
    },
    {
      "x": -19,
      "y": 17,
      "z": -8,
      "name": "Wood_Hardwood_Planks"
    },
    {
      "x": -19,
      "y": 23,
      "z": -8,
      "name": "Rock_Stone_Brick"
    },
    {
      "x": -19,
      "y": 27,
      "z": -8,
      "name": "Rock_Shale_Cobble_Half",
      "rotation": 8
    },
    {
      "x": -19,
      "y": 28,
      "z": -8,
      "name": "Rock_Shale_Cobble"
    },
    {
      "x": -19,
      "y": 29,
      "z": -8,
      "name": "Rock_Shale_Cobble"
    },
    {
      "x": -19,
      "y": 30,
      "z": -8,
      "name": "Rock_Shale_Brick_Beam"
    },
    {
      "x": -19,
      "y": 5,
      "z": -7,
      "name": "Rock_Stone_Brick"
    },
    {
      "x": -19,
      "y": 6,
      "z": -7,
      "name": "Rock_Stone_Brick"
    },
    {
      "x": -19,
      "y": 7,
      "z": -7,
      "name": "Rock_Stone_Brick"
    },
    {
      "x": -19,
      "y": 8,
      "z": -7,
      "name": "Rock_Stone_Brick"
    },
    {
      "x": -19,
      "y": 9,
      "z": -7,
      "name": "Rock_Stone_Brick"
    },
    {
      "x": -19,
      "y": 10,
      "z": -7,
      "name": "Rock_Stone_Brick"
    },
    {
      "x": -19,
      "y": 11,
      "z": -7,
      "name": "Rock_Stone_Brick"
    },
    {
      "x": -19,
      "y": 12,
      "z": -7,
      "name": "Rock_Stone_Brick"
    },
    {
      "x": -19,
      "y": 13,
      "z": -7,
      "name": "Rock_Stone_Brick_Mossy"
    },
    {
      "x": -19,
      "y": 14,
      "z": -7,
      "name": "Rock_Stone_Brick"
    },
    {
      "x": -19,
      "y": 15,
      "z": -7,
      "name": "Rock_Stone_Brick"
    },
    {
      "x": -19,
      "y": 16,
      "z": -7,
      "name": "Rock_Stone_Brick"
    },
    {
      "x": -19,
      "y": 17,
      "z": -7,
      "name": "Rock_Stone_Brick"
    },
    {
      "x": -19,
      "y": 18,
      "z": -7,
      "name": "Rock_Stone_Brick"
    },
    {
      "x": -19,
      "y": 19,
      "z": -7,
      "name": "Rock_Stone_Brick"
    },
    {
      "x": -19,
      "y": 20,
      "z": -7,
      "name": "Rock_Stone_Brick"
    },
    {
      "x": -19,
      "y": 21,
      "z": -7,
      "name": "Rock_Stone_Brick"
    },
    {
      "x": -19,
      "y": 22,
      "z": -7,
      "name": "Rock_Stone_Brick_Mossy"
    },
    {
      "x": -19,
      "y": 23,
      "z": -7,
      "name": "Rock_Stone_Brick"
    },
    {
      "x": -19,
      "y": 27,
      "z": -7,
      "name": "Rock_Shale_Cobble_Half",
      "rotation": 8
    },
    {
      "x": -19,
      "y": 28,
      "z": -7,
      "name": "*Rock_Shale_Cobble_Roof_State_Definitions_Corner_Right",
      "rotation": 1
    },
    {
      "x": -19,
      "y": 4,
      "z": -6,
      "name": "Rock_Stone_Cobble"
    },
    {
      "x": -19,
      "y": 5,
      "z": -6,
      "name": "Wood_Hardwood_Planks"
    },
    {
      "x": -19,
      "y": 6,
      "z": -6,
      "name": "Rock_Stone_Brick_Half",
      "rotation": 7
    },
    {
      "x": -19,
      "y": 7,
      "z": -6,
      "name": "Rock_Stone_Brick_Half",
      "rotation": 7
    },
    {
      "x": -19,
      "y": 8,
      "z": -6,
      "name": "Rock_Stone_Brick_Stairs",
      "rotation": 9
    },
    {
      "x": -19,
      "y": 9,
      "z": -6,
      "name": "Wood_Beech_Trunk",
      "support": 15
    },
    {
      "x": -19,
      "y": 10,
      "z": -6,
      "name": "Wood_Beech_Trunk",
      "support": 15
    },
    {
      "x": -19,
      "y": 11,
      "z": -6,
      "name": "Wood_Beech_Trunk",
      "support": 15
    },
    {
      "x": -19,
      "y": 12,
      "z": -6,
      "name": "Rock_Shale_Brick_Roof",
      "rotation": 2
    },
    {
      "x": -19,
      "y": 23,
      "z": -6,
      "name": "Rock_Stone_Brick_Stairs",
      "rotation": 10
    },
    {
      "x": -19,
      "y": 24,
      "z": -6,
      "name": "Wood_Hardwood_Fence"
    },
    {
      "x": -19,
      "y": 27,
      "z": -6,
      "name": "Wood_Hardwood_Stairs",
      "rotation": 10
    },
    {
      "x": -19,
      "y": 5,
      "z": -5,
      "name": "Wood_Hardwood_Planks"
    },
    {
      "x": -19,
      "y": 12,
      "z": -5,
      "name": "Wood_Hardwood_Planks"
    },
    {
      "x": -19,
      "y": 13,
      "z": -5,
      "name": "Rock_Shale_Cobble_Roof",
      "rotation": 2
    },
    {
      "x": -19,
      "y": 5,
      "z": -4,
      "name": "Wood_Hardwood_Planks"
    },
    {
      "x": -19,
      "y": 12,
      "z": -4,
      "name": "Wood_Hardwood_Planks"
    },
    {
      "x": -19,
      "y": 13,
      "z": -4,
      "name": "Wood_Hardwood_Stairs",
      "rotation": 10
    },
    {
      "x": -19,
      "y": 14,
      "z": -4,
      "name": "Rock_Shale_Cobble_Roof_Steep",
      "rotation": 2
    },
    {
      "x": -19,
      "y": 15,
      "z": -4,
      "name": "Rock_Shale_Cobble_Roof_Steep",
      "filler": 1024,
      "rotation": 2
    },
    {
      "x": -19,
      "y": 5,
      "z": -3,
      "name": "Wood_Hardwood_Planks"
    },
    {
      "x": -19,
      "y": 12,
      "z": -3,
      "name": "Wood_Hardwood_Planks"
    },
    {
      "x": -19,
      "y": 16,
      "z": -3,
      "name": "Rock_Shale_Brick_Roof_Steep",
      "rotation": 2
    },
    {
      "x": -19,
      "y": 17,
      "z": -3,
      "name": "Rock_Shale_Brick_Roof_Steep",
      "filler": 1024,
      "rotation": 2
    },
    {
      "x": -19,
      "y": 5,
      "z": -2,
      "name": "Wood_Hardwood_Planks"
    },
    {
      "x": -19,
      "y": 11,
      "z": -2,
      "name": "Deco_Lantern_Ceiling"
    },
    {
      "x": -19,
      "y": 12,
      "z": -2,
      "name": "Wood_Hardwood_Planks"
    },
    {
      "x": -19,
      "y": 18,
      "z": -2,
      "name": "Rock_Shale_Cobble"
    },
    {
      "x": -19,
      "y": 19,
      "z": -2,
      "name": "Rock_Shale_Brick"
    },
    {
      "x": -19,
      "y": 20,
      "z": -2,
      "name": "Rock_Shale_Cobble_Roof_Flat"
    },
    {
      "x": -19,
      "y": 5,
      "z": -1,
      "name": "Wood_Hardwood_Planks"
    },
    {
      "x": -19,
      "y": 12,
      "z": -1,
      "name": "Wood_Hardwood_Planks"
    },
    {
      "x": -19,
      "y": 17,
      "z": -1,
      "name": "Rock_Shale_Cobble_Roof_Hollow"
    },
    {
      "x": -19,
      "y": 5,
      "z": 0,
      "name": "Wood_Hardwood_Planks"
    },
    {
      "x": -19,
      "y": 12,
      "z": 0,
      "name": "Wood_Hardwood_Planks"
    },
    {
      "x": -19,
      "y": 13,
      "z": 0,
      "name": "Wood_Hardwood_Stairs",
      "rotation": 8
    },
    {
      "x": -19,
      "y": 14,
      "z": 0,
      "name": "Furniture_Village_Window"
    },
    {
      "x": -19,
      "y": 15,
      "z": 0,
      "name": "Furniture_Village_Window"
    },
    {
      "x": -19,
      "y": 16,
      "z": 0,
      "name": "Furniture_Village_Window"
    },
    {
      "x": -19,
      "y": 17,
      "z": 0,
      "name": "Wood_Hardwood_Planks"
    },
    {
      "x": -19,
      "y": 18,
      "z": 0,
      "name": "Rock_Shale_Cobble_Roof_Flat"
    },
    {
      "x": -19,
      "y": 5,
      "z": 1,
      "name": "Wood_Hardwood_Planks"
    },
    {
      "x": -19,
      "y": 12,
      "z": 1,
      "name": "Wood_Hardwood_Planks"
    },
    {
      "x": -19,
      "y": 13,
      "z": 1,
      "name": "Rock_Shale_Cobble_Roof"
    },
    {
      "x": -19,
      "y": 17,
      "z": 1,
      "name": "Wood_Hardwood_Planks_Half"
    },
    {
      "x": -19,
      "y": 4,
      "z": 2,
      "name": "Rock_Stone_Cobble"
    },
    {
      "x": -19,
      "y": 5,
      "z": 2,
      "name": "Wood_Beech_Trunk",
      "support": 15
    },
    {
      "x": -19,
      "y": 6,
      "z": 2,
      "name": "Wood_Beech_Trunk",
      "support": 15
    },
    {
      "x": -19,
      "y": 7,
      "z": 2,
      "name": "Furniture_Village_Window"
    },
    {
      "x": -19,
      "y": 8,
      "z": 2,
      "name": "Furniture_Village_Window"
    },
    {
      "x": -19,
      "y": 9,
      "z": 2,
      "name": "Furniture_Village_Window"
    },
    {
      "x": -19,
      "y": 10,
      "z": 2,
      "name": "Furniture_Village_Window"
    },
    {
      "x": -19,
      "y": 11,
      "z": 2,
      "name": "Wood_Beech_Trunk",
      "support": 15
    },
    {
      "x": -19,
      "y": 12,
      "z": 2,
      "name": "Rock_Shale_Brick_Roof"
    },
    {
      "x": -19,
      "y": 16,
      "z": 2,
      "name": "Furniture_Village_Trapdoor",
      "rotation": 2
    },
    {
      "x": -19,
      "y": 5,
      "z": 3,
      "name": "Plant_Grass_Sharp_Tall",
      "support": 15
    },
    {
      "x": -19,
      "y": 6,
      "z": 3,
      "name": "Plant_Grass_Sharp_Tall",
      "filler": 1024
    },
    {
      "x": -19,
      "y": 11,
      "z": 3,
      "name": "Rock_Shale_Cobble_Half",
      "rotation": 8
    },
    {
      "x": -19,
      "y": 12,
      "z": 3,
      "name": "Rock_Shale_Cobble_Roof_Flat"
    },
    {
      "x": -19,
      "y": 5,
      "z": 4,
      "name": "Plant_Grass_Sharp_Tall",
      "support": 15
    },
    {
      "x": -19,
      "y": 6,
      "z": 4,
      "name": "Plant_Grass_Sharp_Tall",
      "filler": 1024
    },
    {
      "x": -19,
      "y": 11,
      "z": 4,
      "name": "Wood_Hardwood_Planks_Half"
    },
    {
      "x": -19,
      "y": 5,
      "z": 5,
      "name": "Plant_Grass_Sharp_Tall",
      "support": 15
    },
    {
      "x": -19,
      "y": 6,
      "z": 5,
      "name": "Plant_Grass_Sharp_Tall",
      "filler": 1024
    },
    {
      "x": -19,
      "y": 10,
      "z": 5,
      "name": "Furniture_Village_Trapdoor",
      "rotation": 2
    },
    {
      "x": -18,
      "y": 23,
      "z": -12,
      "name": "*Rock_Stone_Brick_Stairs_State_Definitions_Corner_Right",
      "rotation": 11
    },
    {
      "x": -18,
      "y": 24,
      "z": -12,
      "name": "*Wood_Hardwood_Fence_State_Definitions_Corner"
    },
    {
      "x": -18,
      "y": 25,
      "z": -12,
      "name": "Wood_Hardwood_Beam"
    },
    {
      "x": -18,
      "y": 26,
      "z": -12,
      "name": "Wood_Hardwood_Beam"
    },
    {
      "x": -18,
      "y": 27,
      "z": -12,
      "name": "Wood_Hardwood_Stairs",
      "rotation": 2
    },
    {
      "x": -18,
      "y": 5,
      "z": -11,
      "name": "Rock_Stone_Cobble_Beam"
    },
    {
      "x": -18,
      "y": 6,
      "z": -11,
      "name": "Rock_Stone_Cobble_Beam"
    },
    {
      "x": -18,
      "y": 7,
      "z": -11,
      "name": "Rock_Stone_Cobble_Beam"
    },
    {
      "x": -18,
      "y": 8,
      "z": -11,
      "name": "Rock_Stone_Cobble_Beam"
    },
    {
      "x": -18,
      "y": 9,
      "z": -11,
      "name": "Rock_Stone_Cobble_Beam"
    },
    {
      "x": -18,
      "y": 10,
      "z": -11,
      "name": "Rock_Stone_Cobble_Beam"
    },
    {
      "x": -18,
      "y": 11,
      "z": -11,
      "name": "Rock_Stone_Cobble_Beam"
    },
    {
      "x": -18,
      "y": 12,
      "z": -11,
      "name": "Rock_Stone_Cobble_Beam"
    },
    {
      "x": -18,
      "y": 13,
      "z": -11,
      "name": "Rock_Stone_Cobble_Beam"
    },
    {
      "x": -18,
      "y": 14,
      "z": -11,
      "name": "Rock_Stone_Cobble_Beam"
    },
    {
      "x": -18,
      "y": 15,
      "z": -11,
      "name": "Rock_Stone_Cobble_Beam"
    },
    {
      "x": -18,
      "y": 16,
      "z": -11,
      "name": "Rock_Stone_Cobble_Beam"
    },
    {
      "x": -18,
      "y": 17,
      "z": -11,
      "name": "Rock_Stone_Cobble_Beam"
    },
    {
      "x": -18,
      "y": 18,
      "z": -11,
      "name": "Rock_Stone_Cobble_Beam"
    },
    {
      "x": -18,
      "y": 19,
      "z": -11,
      "name": "Rock_Stone_Cobble_Beam"
    },
    {
      "x": -18,
      "y": 20,
      "z": -11,
      "name": "Rock_Stone_Cobble_Beam"
    },
    {
      "x": -18,
      "y": 21,
      "z": -11,
      "name": "Rock_Stone_Cobble_Beam"
    },
    {
      "x": -18,
      "y": 22,
      "z": -11,
      "name": "Rock_Stone_Cobble_Beam"
    },
    {
      "x": -18,
      "y": 23,
      "z": -11,
      "name": "Rock_Stone_Brick_Stairs",
      "rotation": 8
    },
    {
      "x": -18,
      "y": 24,
      "z": -11,
      "name": "*Wood_Hardwood_Fence_State_Definitions_Corner",
      "rotation": 2
    },
    {
      "x": -18,
      "y": 27,
      "z": -11,
      "name": "Rock_Shale_Cobble_Half",
      "rotation": 8
    },
    {
      "x": -18,
      "y": 28,
      "z": -11,
      "name": "Rock_Shale_Brick_Beam"
    },
    {
      "x": -18,
      "y": 5,
      "z": -10,
      "name": "Rock_Stone_Brick"
    },
    {
      "x": -18,
      "y": 6,
      "z": -10,
      "name": "Rock_Stone_Brick"
    },
    {
      "x": -18,
      "y": 7,
      "z": -10,
      "name": "Rock_Stone_Brick"
    },
    {
      "x": -18,
      "y": 8,
      "z": -10,
      "name": "Rock_Stone_Brick"
    },
    {
      "x": -18,
      "y": 9,
      "z": -10,
      "name": "Rock_Stone_Brick"
    },
    {
      "x": -18,
      "y": 10,
      "z": -10,
      "name": "Rock_Stone_Brick_Mossy"
    },
    {
      "x": -18,
      "y": 11,
      "z": -10,
      "name": "Rock_Stone_Brick"
    },
    {
      "x": -18,
      "y": 12,
      "z": -10,
      "name": "Rock_Stone_Brick"
    },
    {
      "x": -18,
      "y": 13,
      "z": -10,
      "name": "Rock_Stone_Brick"
    },
    {
      "x": -18,
      "y": 14,
      "z": -10,
      "name": "Rock_Stone_Brick"
    },
    {
      "x": -18,
      "y": 15,
      "z": -10,
      "name": "Rock_Stone_Brick"
    },
    {
      "x": -18,
      "y": 16,
      "z": -10,
      "name": "Rock_Stone_Brick"
    },
    {
      "x": -18,
      "y": 17,
      "z": -10,
      "name": "Rock_Stone_Brick_Mossy"
    },
    {
      "x": -18,
      "y": 18,
      "z": -10,
      "name": "Rock_Stone_Brick"
    },
    {
      "x": -18,
      "y": 19,
      "z": -10,
      "name": "Rock_Stone_Brick"
    },
    {
      "x": -18,
      "y": 20,
      "z": -10,
      "name": "Rock_Stone_Brick"
    },
    {
      "x": -18,
      "y": 21,
      "z": -10,
      "name": "Rock_Stone_Brick"
    },
    {
      "x": -18,
      "y": 22,
      "z": -10,
      "name": "Rock_Stone_Brick"
    },
    {
      "x": -18,
      "y": 23,
      "z": -10,
      "name": "Rock_Stone_Brick"
    },
    {
      "x": -18,
      "y": 27,
      "z": -10,
      "name": "Rock_Shale_Cobble_Half",
      "rotation": 8
    },
    {
      "x": -18,
      "y": 28,
      "z": -10,
      "name": "*Rock_Shale_Cobble_Roof_State_Definitions_Corner_Right",
      "rotation": 2
    },
    {
      "x": -18,
      "y": 5,
      "z": -9,
      "name": "Rock_Stone_Brick"
    },
    {
      "x": -18,
      "y": 6,
      "z": -9,
      "name": "Rock_Stone_Brick"
    },
    {
      "x": -18,
      "y": 7,
      "z": -9,
      "name": "Rock_Stone_Brick"
    },
    {
      "x": -18,
      "y": 8,
      "z": -9,
      "name": "Rock_Stone_Brick"
    },
    {
      "x": -18,
      "y": 9,
      "z": -9,
      "name": "Rock_Stone_Brick"
    },
    {
      "x": -18,
      "y": 10,
      "z": -9,
      "name": "Rock_Stone_Brick"
    },
    {
      "x": -18,
      "y": 11,
      "z": -9,
      "name": "Rock_Stone_Brick"
    },
    {
      "x": -18,
      "y": 12,
      "z": -9,
      "name": "Rock_Stone_Brick"
    },
    {
      "x": -18,
      "y": 13,
      "z": -9,
      "name": "Rock_Stone_Brick"
    },
    {
      "x": -18,
      "y": 14,
      "z": -9,
      "name": "Rock_Stone_Brick"
    },
    {
      "x": -18,
      "y": 15,
      "z": -9,
      "name": "Rock_Stone_Brick"
    },
    {
      "x": -18,
      "y": 16,
      "z": -9,
      "name": "Rock_Stone_Brick"
    },
    {
      "x": -18,
      "y": 17,
      "z": -9,
      "name": "Rock_Stone_Brick"
    },
    {
      "x": -18,
      "y": 18,
      "z": -9,
      "name": "Rock_Stone_Brick_Mossy"
    },
    {
      "x": -18,
      "y": 19,
      "z": -9,
      "name": "Rock_Stone_Brick"
    },
    {
      "x": -18,
      "y": 20,
      "z": -9,
      "name": "Rock_Stone_Brick"
    },
    {
      "x": -18,
      "y": 21,
      "z": -9,
      "name": "Rock_Stone_Brick"
    },
    {
      "x": -18,
      "y": 22,
      "z": -9,
      "name": "Rock_Stone_Brick"
    },
    {
      "x": -18,
      "y": 23,
      "z": -9,
      "name": "Rock_Stone_Brick"
    },
    {
      "x": -18,
      "y": 27,
      "z": -9,
      "name": "Rock_Shale_Cobble_Half",
      "rotation": 8
    },
    {
      "x": -18,
      "y": 28,
      "z": -9,
      "name": "Rock_Shale_Brick_Roof",
      "rotation": 1
    },
    {
      "x": -18,
      "y": 5,
      "z": -8,
      "name": "Rock_Stone_Brick"
    },
    {
      "x": -18,
      "y": 6,
      "z": -8,
      "name": "Rock_Stone_Brick"
    },
    {
      "x": -18,
      "y": 7,
      "z": -8,
      "name": "Rock_Stone_Brick_Mossy"
    },
    {
      "x": -18,
      "y": 8,
      "z": -8,
      "name": "Rock_Stone_Brick"
    },
    {
      "x": -18,
      "y": 9,
      "z": -8,
      "name": "Rock_Stone_Brick"
    },
    {
      "x": -18,
      "y": 10,
      "z": -8,
      "name": "Rock_Stone_Brick"
    },
    {
      "x": -18,
      "y": 11,
      "z": -8,
      "name": "Rock_Stone_Brick"
    },
    {
      "x": -18,
      "y": 12,
      "z": -8,
      "name": "Rock_Stone_Brick"
    },
    {
      "x": -18,
      "y": 13,
      "z": -8,
      "name": "Rock_Stone_Brick"
    },
    {
      "x": -18,
      "y": 14,
      "z": -8,
      "name": "Rock_Stone_Brick"
    },
    {
      "x": -18,
      "y": 15,
      "z": -8,
      "name": "Rock_Stone_Brick"
    },
    {
      "x": -18,
      "y": 16,
      "z": -8,
      "name": "Rock_Stone_Brick"
    },
    {
      "x": -18,
      "y": 17,
      "z": -8,
      "name": "Rock_Stone_Brick"
    },
    {
      "x": -18,
      "y": 18,
      "z": -8,
      "name": "Rock_Stone_Brick"
    },
    {
      "x": -18,
      "y": 19,
      "z": -8,
      "name": "Rock_Stone_Brick"
    },
    {
      "x": -18,
      "y": 20,
      "z": -8,
      "name": "Rock_Stone_Brick_Mossy"
    },
    {
      "x": -18,
      "y": 21,
      "z": -8,
      "name": "Rock_Stone_Brick"
    },
    {
      "x": -18,
      "y": 22,
      "z": -8,
      "name": "Rock_Stone_Brick"
    },
    {
      "x": -18,
      "y": 23,
      "z": -8,
      "name": "Rock_Stone_Brick"
    },
    {
      "x": -18,
      "y": 27,
      "z": -8,
      "name": "Rock_Shale_Cobble_Half",
      "rotation": 8
    },
    {
      "x": -18,
      "y": 28,
      "z": -8,
      "name": "*Rock_Shale_Cobble_Roof_State_Definitions_Corner_Left"
    },
    {
      "x": -18,
      "y": 5,
      "z": -7,
      "name": "Rock_Stone_Cobble_Beam"
    },
    {
      "x": -18,
      "y": 6,
      "z": -7,
      "name": "Rock_Stone_Cobble_Beam"
    },
    {
      "x": -18,
      "y": 7,
      "z": -7,
      "name": "Rock_Stone_Cobble_Beam"
    },
    {
      "x": -18,
      "y": 8,
      "z": -7,
      "name": "Rock_Stone_Cobble_Beam"
    },
    {
      "x": -18,
      "y": 9,
      "z": -7,
      "name": "Rock_Stone_Cobble_Beam"
    },
    {
      "x": -18,
      "y": 10,
      "z": -7,
      "name": "Rock_Stone_Cobble_Beam"
    },
    {
      "x": -18,
      "y": 11,
      "z": -7,
      "name": "Rock_Stone_Cobble_Beam"
    },
    {
      "x": -18,
      "y": 12,
      "z": -7,
      "name": "Rock_Stone_Cobble_Beam"
    },
    {
      "x": -18,
      "y": 13,
      "z": -7,
      "name": "Rock_Stone_Cobble_Beam"
    },
    {
      "x": -18,
      "y": 14,
      "z": -7,
      "name": "Rock_Stone_Cobble_Beam"
    },
    {
      "x": -18,
      "y": 15,
      "z": -7,
      "name": "Rock_Stone_Cobble_Beam"
    },
    {
      "x": -18,
      "y": 16,
      "z": -7,
      "name": "Rock_Stone_Cobble_Beam"
    },
    {
      "x": -18,
      "y": 17,
      "z": -7,
      "name": "Rock_Stone_Cobble_Beam"
    },
    {
      "x": -18,
      "y": 18,
      "z": -7,
      "name": "Rock_Stone_Cobble_Beam"
    },
    {
      "x": -18,
      "y": 19,
      "z": -7,
      "name": "Rock_Stone_Cobble_Beam"
    },
    {
      "x": -18,
      "y": 20,
      "z": -7,
      "name": "Rock_Stone_Cobble_Beam"
    },
    {
      "x": -18,
      "y": 21,
      "z": -7,
      "name": "Rock_Stone_Cobble_Beam"
    },
    {
      "x": -18,
      "y": 22,
      "z": -7,
      "name": "Rock_Stone_Cobble_Beam"
    },
    {
      "x": -18,
      "y": 23,
      "z": -7,
      "name": "Rock_Stone_Brick_Stairs",
      "rotation": 11
    },
    {
      "x": -18,
      "y": 24,
      "z": -7,
      "name": "*Wood_Hardwood_Fence_State_Definitions_Corner",
      "rotation": 1
    },
    {
      "x": -18,
      "y": 27,
      "z": -7,
      "name": "Rock_Shale_Cobble_Half",
      "rotation": 8
    },
    {
      "x": -18,
      "y": 28,
      "z": -7,
      "name": "Rock_Shale_Brick_Beam"
    },
    {
      "x": -18,
      "y": 4,
      "z": -6,
      "name": "Rock_Stone_Cobble"
    },
    {
      "x": -18,
      "y": 5,
      "z": -6,
      "name": "Wood_Beech_Trunk",
      "support": 15
    },
    {
      "x": -18,
      "y": 6,
      "z": -6,
      "name": "Wood_Beech_Trunk",
      "support": 15
    },
    {
      "x": -18,
      "y": 7,
      "z": -6,
      "name": "Wood_Beech_Trunk",
      "support": 15
    },
    {
      "x": -18,
      "y": 8,
      "z": -6,
      "name": "Wood_Beech_Trunk",
      "support": 15
    },
    {
      "x": -18,
      "y": 9,
      "z": -6,
      "name": "Wood_Beech_Trunk",
      "support": 15
    },
    {
      "x": -18,
      "y": 10,
      "z": -6,
      "name": "Wood_Beech_Trunk",
      "support": 15
    },
    {
      "x": -18,
      "y": 11,
      "z": -6,
      "name": "Wood_Beech_Trunk",
      "support": 15
    },
    {
      "x": -18,
      "y": 12,
      "z": -6,
      "name": "Rock_Shale_Cobble_Roof",
      "rotation": 2
    },
    {
      "x": -18,
      "y": 23,
      "z": -6,
      "name": "*Rock_Stone_Brick_Stairs_State_Definitions_Corner_Left",
      "rotation": 11
    },
    {
      "x": -18,
      "y": 24,
      "z": -6,
      "name": "*Wood_Hardwood_Fence_State_Definitions_Corner",
      "rotation": 3
    },
    {
      "x": -18,
      "y": 25,
      "z": -6,
      "name": "Wood_Hardwood_Beam"
    },
    {
      "x": -18,
      "y": 26,
      "z": -6,
      "name": "Wood_Hardwood_Beam"
    },
    {
      "x": -18,
      "y": 27,
      "z": -6,
      "name": "Wood_Hardwood_Stairs"
    },
    {
      "x": -18,
      "y": 5,
      "z": -5,
      "name": "Wood_Hardwood_Planks"
    },
    {
      "x": -18,
      "y": 12,
      "z": -5,
      "name": "Wood_Hardwood_Planks"
    },
    {
      "x": -18,
      "y": 13,
      "z": -5,
      "name": "Rock_Shale_Brick_Roof",
      "rotation": 2
    },
    {
      "x": -18,
      "y": 5,
      "z": -4,
      "name": "Wood_Hardwood_Planks"
    },
    {
      "x": -18,
      "y": 12,
      "z": -4,
      "name": "Wood_Hardwood_Planks"
    },
    {
      "x": -18,
      "y": 13,
      "z": -4,
      "name": "Wood_Hardwood_Stairs",
      "rotation": 10
    },
    {
      "x": -18,
      "y": 14,
      "z": -4,
      "name": "Rock_Shale_Cobble_Roof_Steep",
      "rotation": 2
    },
    {
      "x": -18,
      "y": 15,
      "z": -4,
      "name": "Rock_Shale_Cobble_Roof_Steep",
      "filler": 1024,
      "rotation": 2
    },
    {
      "x": -18,
      "y": 5,
      "z": -3,
      "name": "Wood_Hardwood_Planks"
    },
    {
      "x": -18,
      "y": 12,
      "z": -3,
      "name": "Wood_Hardwood_Planks"
    },
    {
      "x": -18,
      "y": 16,
      "z": -3,
      "name": "Rock_Shale_Brick_Roof_Steep",
      "rotation": 2
    },
    {
      "x": -18,
      "y": 17,
      "z": -3,
      "name": "Rock_Shale_Brick_Roof_Steep",
      "filler": 1024,
      "rotation": 2
    },
    {
      "x": -18,
      "y": 5,
      "z": -2,
      "name": "Wood_Hardwood_Planks"
    },
    {
      "x": -18,
      "y": 12,
      "z": -2,
      "name": "Wood_Hardwood_Planks"
    },
    {
      "x": -18,
      "y": 18,
      "z": -2,
      "name": "Rock_Shale_Cobble"
    },
    {
      "x": -18,
      "y": 19,
      "z": -2,
      "name": "Rock_Shale_Brick"
    },
    {
      "x": -18,
      "y": 20,
      "z": -2,
      "name": "Rock_Shale_Cobble_Roof_Flat"
    },
    {
      "x": -18,
      "y": 5,
      "z": -1,
      "name": "Wood_Hardwood_Planks"
    },
    {
      "x": -18,
      "y": 12,
      "z": -1,
      "name": "Wood_Hardwood_Planks"
    },
    {
      "x": -18,
      "y": 17,
      "z": -1,
      "name": "Rock_Shale_Cobble_Roof_Hollow"
    },
    {
      "x": -18,
      "y": 5,
      "z": 0,
      "name": "Wood_Hardwood_Planks"
    },
    {
      "x": -18,
      "y": 12,
      "z": 0,
      "name": "Wood_Hardwood_Planks"
    },
    {
      "x": -18,
      "y": 13,
      "z": 0,
      "name": "Wood_Hardwood_Stairs",
      "rotation": 8
    },
    {
      "x": -18,
      "y": 14,
      "z": 0,
      "name": "Wood_Oak_Trunk",
      "support": 15
    },
    {
      "x": -18,
      "y": 15,
      "z": 0,
      "name": "Wood_Oak_Trunk",
      "support": 15
    },
    {
      "x": -18,
      "y": 16,
      "z": 0,
      "name": "Wood_Oak_Trunk",
      "support": 15
    },
    {
      "x": -18,
      "y": 17,
      "z": 0,
      "name": "Wood_Hardwood_Planks"
    },
    {
      "x": -18,
      "y": 18,
      "z": 0,
      "name": "Rock_Shale_Cobble_Roof_Flat"
    },
    {
      "x": -18,
      "y": 5,
      "z": 1,
      "name": "Wood_Hardwood_Planks"
    },
    {
      "x": -18,
      "y": 12,
      "z": 1,
      "name": "Wood_Hardwood_Planks"
    },
    {
      "x": -18,
      "y": 13,
      "z": 1,
      "name": "Rock_Shale_Brick_Roof"
    },
    {
      "x": -18,
      "y": 17,
      "z": 1,
      "name": "Wood_Hardwood_Planks_Half"
    },
    {
      "x": -18,
      "y": 4,
      "z": 2,
      "name": "Rock_Stone_Cobble"
    },
    {
      "x": -18,
      "y": 5,
      "z": 2,
      "name": "Wood_Beech_Trunk",
      "support": 15
    },
    {
      "x": -18,
      "y": 6,
      "z": 2,
      "name": "Wood_Beech_Trunk",
      "support": 15
    },
    {
      "x": -18,
      "y": 7,
      "z": 2,
      "name": "Wood_Beech_Trunk",
      "support": 15
    },
    {
      "x": -18,
      "y": 8,
      "z": 2,
      "name": "Wood_Beech_Trunk",
      "support": 15
    },
    {
      "x": -18,
      "y": 9,
      "z": 2,
      "name": "Wood_Beech_Trunk",
      "support": 15
    },
    {
      "x": -18,
      "y": 10,
      "z": 2,
      "name": "Wood_Beech_Trunk",
      "support": 15
    },
    {
      "x": -18,
      "y": 11,
      "z": 2,
      "name": "Wood_Beech_Trunk",
      "support": 15
    },
    {
      "x": -18,
      "y": 12,
      "z": 2,
      "name": "Rock_Shale_Cobble_Roof"
    },
    {
      "x": -18,
      "y": 16,
      "z": 2,
      "name": "Furniture_Village_Trapdoor",
      "rotation": 2
    },
    {
      "x": -18,
      "y": 7,
      "z": 3,
      "name": "*Furniture_Temple_Dark_Trapdoor_State_Definitions_OpenDoorOut"
    },
    {
      "x": -18,
      "y": 8,
      "z": 3,
      "name": "*Furniture_Temple_Dark_Trapdoor_State_Definitions_OpenDoorOut"
    },
    {
      "x": -18,
      "y": 9,
      "z": 3,
      "name": "*Furniture_Temple_Dark_Trapdoor_State_Definitions_OpenDoorOut"
    },
    {
      "x": -18,
      "y": 10,
      "z": 3,
      "name": "*Furniture_Temple_Dark_Trapdoor_State_Definitions_OpenDoorOut"
    },
    {
      "x": -18,
      "y": 11,
      "z": 3,
      "name": "Rock_Shale_Cobble_Half",
      "rotation": 8
    },
    {
      "x": -18,
      "y": 12,
      "z": 3,
      "name": "Rock_Shale_Cobble_Roof_Flat"
    },
    {
      "x": -18,
      "y": 11,
      "z": 4,
      "name": "Wood_Hardwood_Planks_Half"
    },
    {
      "x": -18,
      "y": 5,
      "z": 5,
      "name": "Plant_Grass_Sharp_Overgrown",
      "support": 15
    },
    {
      "x": -18,
      "y": 6,
      "z": 5,
      "name": "Plant_Grass_Sharp_Overgrown",
      "filler": 1024
    },
    {
      "x": -18,
      "y": 10,
      "z": 5,
      "name": "Furniture_Village_Trapdoor",
      "rotation": 2
    },
    {
      "x": -17,
      "y": 23,
      "z": -11,
      "name": "*Rock_Stone_Brick_Stairs_State_Definitions_Corner_Left",
      "rotation": 8
    },
    {
      "x": -17,
      "y": 24,
      "z": -11,
      "name": "*Wood_Hardwood_Fence_State_Definitions_Corner"
    },
    {
      "x": -17,
      "y": 25,
      "z": -11,
      "name": "Wood_Hardwood_Beam"
    },
    {
      "x": -17,
      "y": 26,
      "z": -11,
      "name": "Wood_Hardwood_Beam"
    },
    {
      "x": -17,
      "y": 27,
      "z": -11,
      "name": "Wood_Hardwood_Stairs",
      "rotation": 1
    },
    {
      "x": -17,
      "y": 23,
      "z": -10,
      "name": "Rock_Stone_Brick_Stairs",
      "rotation": 11
    },
    {
      "x": -17,
      "y": 24,
      "z": -10,
      "name": "Wood_Hardwood_Fence",
      "rotation": 1
    },
    {
      "x": -17,
      "y": 27,
      "z": -10,
      "name": "Wood_Hardwood_Stairs",
      "rotation": 11
    },
    {
      "x": -17,
      "y": 5,
      "z": -9,
      "name": "Plant_Bush_Lush",
      "support": 15
    },
    {
      "x": -17,
      "y": 10,
      "z": -9,
      "name": "Furniture_Crude_Trapdoor",
      "rotation": 2
    },
    {
      "x": -17,
      "y": 23,
      "z": -9,
      "name": "Rock_Stone_Brick_Stairs",
      "rotation": 11
    },
    {
      "x": -17,
      "y": 24,
      "z": -9,
      "name": "Wood_Hardwood_Fence",
      "rotation": 1
    },
    {
      "x": -17,
      "y": 27,
      "z": -9,
      "name": "Wood_Hardwood_Stairs",
      "rotation": 1
    },
    {
      "x": -17,
      "y": 11,
      "z": -8,
      "name": "Wood_Hardwood_Planks_Half"
    },
    {
      "x": -17,
      "y": 23,
      "z": -8,
      "name": "Rock_Stone_Brick_Stairs",
      "rotation": 11
    },
    {
      "x": -17,
      "y": 24,
      "z": -8,
      "name": "Wood_Hardwood_Fence",
      "rotation": 1
    },
    {
      "x": -17,
      "y": 27,
      "z": -8,
      "name": "Wood_Hardwood_Stairs",
      "rotation": 11
    },
    {
      "x": -17,
      "y": 5,
      "z": -7,
      "name": "Plant_Bush_Hanging",
      "support": 15
    },
    {
      "x": -17,
      "y": 11,
      "z": -7,
      "name": "Rock_Shale_Cobble_Half",
      "rotation": 8
    },
    {
      "x": -17,
      "y": 23,
      "z": -7,
      "name": "*Rock_Stone_Brick_Stairs_State_Definitions_Corner_Right",
      "rotation": 10
    },
    {
      "x": -17,
      "y": 24,
      "z": -7,
      "name": "*Wood_Hardwood_Fence_State_Definitions_Corner",
      "rotation": 3
    },
    {
      "x": -17,
      "y": 25,
      "z": -7,
      "name": "Wood_Hardwood_Beam"
    },
    {
      "x": -17,
      "y": 26,
      "z": -7,
      "name": "Wood_Hardwood_Beam"
    },
    {
      "x": -17,
      "y": 27,
      "z": -7,
      "name": "Wood_Hardwood_Stairs",
      "rotation": 1
    },
    {
      "x": -17,
      "y": 4,
      "z": -6,
      "name": "Rock_Stone_Cobble"
    },
    {
      "x": -17,
      "y": 5,
      "z": -6,
      "name": "Wood_Beech_Trunk",
      "support": 15
    },
    {
      "x": -17,
      "y": 6,
      "z": -6,
