{
  "version": 8,
  "blockIdVersion": 11,
  "anchorX": 0,
  "anchorY": 0,
  "anchorZ": 0,
  "blocks": [
    {
      "x": -27,
      "y": 0,
      "z": -20,
      "name": "Soil_Grass"
    },
    {
      "x": -27,
      "y": 0,
      "z": -19,
      "name": "Soil_Grass"
    },
    {
      "x": -27,
      "y": 0,
      "z": -18,
      "name": "Soil_Grass"
    },
    {
      "x": -27,
      "y": 0,
      "z": -17,
      "name": "Soil_Grass"
    },
    {
      "x": -27,
      "y": 0,
      "z": -16,
      "name": "Soil_Grass"
    },
    {
      "x": -27,
      "y": 0,
      "z": -15,
      "name": "Soil_Grass"
    },
    {
      "x": -27,
      "y": 0,
      "z": -14,
      "name": "Soil_Grass"
    },
    {
      "x": -27,
      "y": 0,
      "z": -13,
      "name": "Soil_Grass"
    },
    {
      "x": -27,
      "y": 0,
      "z": -12,
      "name": "Soil_Grass"
    },
    {
      "x": -27,
      "y": 0,
      "z": -11,
      "name": "Soil_Grass"
    },
    {
      "x": -27,
      "y": 0,
      "z": -10,
      "name": "Soil_Grass"
    },
    {
      "x": -27,
      "y": 0,
      "z": -9,
      "name": "Soil_Grass"
    },
    {
      "x": -27,
      "y": 0,
      "z": -8,
      "name": "Soil_Grass"
    },
    {
      "x": -27,
      "y": 0,
      "z": -7,
      "name": "Soil_Grass"
    },
    {
      "x": -27,
      "y": 0,
      "z": -6,
      "name": "Soil_Grass"
    },
    {
      "x": -27,
      "y": 0,
      "z": -5,
      "name": "Soil_Grass"
    },
    {
      "x": -27,
      "y": 0,
      "z": -4,
      "name": "Soil_Grass"
    },
    {
      "x": -27,
      "y": 0,
      "z": -3,
      "name": "Soil_Grass"
    },
    {
      "x": -27,
      "y": 0,
      "z": -2,
      "name": "Soil_Grass"
    },
    {
      "x": -27,
      "y": 0,
      "z": -1,
      "name": "Soil_Dirt"
    },
    {
      "x": -27,
      "y": 1,
      "z": -1,
      "name": "Soil_Grass"
    },
    {
      "x": -27,
      "y": 0,
      "z": 0,
      "name": "Soil_Dirt"
    },
    {
      "x": -27,
      "y": 1,
      "z": 0,
      "name": "Soil_Grass"
    },
    {
      "x": -27,
      "y": 0,
      "z": 1,
      "name": "Soil_Dirt"
    },
    {
      "x": -27,
      "y": 1,
      "z": 1,
      "name": "Soil_Grass"
    },
    {
      "x": -27,
      "y": 0,
      "z": 2,
      "name": "Soil_Dirt"
    },
    {
      "x": -27,
      "y": 1,
      "z": 2,
      "name": "Soil_Grass"
    },
    {
      "x": -27,
      "y": 2,
      "z": 2,
      "name": "Plant_Grass_Sharp",
      "support": 15
    },
    {
      "x": -27,
      "y": 0,
      "z": 3,
      "name": "Soil_Dirt"
    },
    {
      "x": -27,
      "y": 1,
      "z": 3,
      "name": "Soil_Grass"
    },
    {
      "x": -27,
      "y": 0,
      "z": 4,
      "name": "Soil_Grass"
    },
    {
      "x": -27,
      "y": 0,
      "z": 5,
      "name": "Soil_Grass"
    },
    {
      "x": -27,
      "y": 0,
      "z": 6,
      "name": "Soil_Grass"
    },
    {
      "x": -27,
      "y": 0,
      "z": 7,
      "name": "Soil_Grass"
    },
    {
      "x": -27,
      "y": 0,
      "z": 8,
      "name": "Soil_Grass"
    },
    {
      "x": -27,
      "y": 0,
      "z": 9,
      "name": "Soil_Grass"
    },
    {
      "x": -27,
      "y": 0,
      "z": 10,
      "name": "Soil_Grass"
    },
    {
      "x": -27,
      "y": 0,
      "z": 11,
      "name": "Soil_Grass"
    },
    {
      "x": -27,
      "y": 0,
      "z": 12,
      "name": "Soil_Grass"
    },
    {
      "x": -27,
      "y": 0,
      "z": 13,
      "name": "Soil_Grass"
    },
    {
      "x": -27,
      "y": 0,
      "z": 14,
      "name": "Soil_Grass"
    },
    {
      "x": -27,
      "y": 0,
      "z": 15,
      "name": "Soil_Grass"
    },
    {
      "x": -27,
      "y": 0,
      "z": 16,
      "name": "Soil_Grass"
    },
    {
      "x": -27,
      "y": 0,
      "z": 17,
      "name": "Soil_Grass"
    },
    {
      "x": -27,
      "y": 0,
      "z": 18,
      "name": "Soil_Grass"
    },
    {
      "x": -27,
      "y": 0,
      "z": 19,
      "name": "Soil_Grass"
    },
    {
      "x": -27,
      "y": 0,
      "z": 20,
      "name": "Soil_Grass"
    },
    {
      "x": -26,
      "y": 0,
      "z": -20,
      "name": "Soil_Grass"
    },
    {
      "x": -26,
      "y": 0,
      "z": -19,
      "name": "Soil_Grass"
    },
    {
      "x": -26,
      "y": 0,
      "z": -18,
      "name": "Soil_Grass"
    },
    {
      "x": -26,
      "y": 0,
      "z": -17,
      "name": "Soil_Grass"
    },
    {
      "x": -26,
      "y": 0,
      "z": -16,
      "name": "Soil_Grass"
    },
    {
      "x": -26,
      "y": 0,
      "z": -15,
      "name": "Soil_Grass"
    },
    {
      "x": -26,
      "y": 0,
      "z": -14,
      "name": "Soil_Grass"
    },
    {
      "x": -26,
      "y": 0,
      "z": -13,
      "name": "Soil_Grass"
    },
    {
      "x": -26,
      "y": 0,
      "z": -12,
      "name": "Soil_Grass"
    },
    {
      "x": -26,
      "y": 0,
      "z": -11,
      "name": "Soil_Grass"
    },
    {
      "x": -26,
      "y": 0,
      "z": -10,
      "name": "Soil_Grass"
    },
    {
      "x": -26,
      "y": 0,
      "z": -9,
      "name": "Soil_Grass"
    },
    {
      "x": -26,
      "y": 0,
      "z": -8,
      "name": "Soil_Grass"
    },
    {
      "x": -26,
      "y": 0,
      "z": -7,
      "name": "Soil_Grass"
    },
    {
      "x": -26,
      "y": 0,
      "z": -6,
      "name": "Soil_Grass"
    },
    {
      "x": -26,
      "y": 1,
      "z": -6,
      "name": "Plant_Grass_Sharp",
      "support": 15
    },
    {
      "x": -26,
      "y": 0,
      "z": -5,
      "name": "Soil_Dirt"
    },
    {
      "x": -26,
      "y": 1,
      "z": -5,
      "name": "Soil_Grass"
    },
    {
      "x": -26,
      "y": 0,
      "z": -4,
      "name": "Soil_Dirt"
    },
    {
      "x": -26,
      "y": 1,
      "z": -4,
      "name": "Soil_Grass"
    },
    {
      "x": -26,
      "y": 0,
      "z": -3,
      "name": "Soil_Dirt"
    },
    {
      "x": -26,
      "y": 1,
      "z": -3,
      "name": "Soil_Grass"
    },
    {
      "x": -26,
      "y": 0,
      "z": -2,
      "name": "Soil_Dirt"
    },
    {
      "x": -26,
      "y": 1,
      "z": -2,
      "name": "Soil_Grass"
    },
    {
      "x": -26,
      "y": 0,
      "z": -1,
      "name": "Soil_Dirt"
    },
    {
      "x": -26,
      "y": 1,
      "z": -1,
      "name": "Soil_Grass"
    },
    {
      "x": -26,
      "y": 0,
      "z": 0,
      "name": "Soil_Dirt"
    },
    {
      "x": -26,
      "y": 1,
      "z": 0,
      "name": "Soil_Grass"
    },
    {
      "x": -26,
      "y": 0,
      "z": 1,
      "name": "Soil_Dirt"
    },
    {
      "x": -26,
      "y": 1,
      "z": 1,
      "name": "Soil_Grass"
    },
    {
      "x": -26,
      "y": 0,
      "z": 2,
      "name": "Soil_Dirt"
    },
    {
      "x": -26,
      "y": 1,
      "z": 2,
      "name": "Soil_Grass"
    },
    {
      "x": -26,
      "y": 0,
      "z": 3,
      "name": "Soil_Dirt"
    },
    {
      "x": -26,
      "y": 1,
      "z": 3,
      "name": "Soil_Grass"
    },
    {
      "x": -26,
      "y": 2,
      "z": 3,
      "name": "Plant_Grass_Sharp",
      "support": 15
    },
    {
      "x": -26,
      "y": 0,
      "z": 4,
      "name": "Soil_Dirt"
    },
    {
      "x": -26,
      "y": 1,
      "z": 4,
      "name": "Soil_Grass"
    },
    {
      "x": -26,
      "y": 0,
      "z": 5,
      "name": "Soil_Grass"
    },
    {
      "x": -26,
      "y": 0,
      "z": 6,
      "name": "Soil_Grass"
    },
    {
      "x": -26,
      "y": 0,
      "z": 7,
      "name": "Soil_Grass"
    },
    {
      "x": -26,
      "y": 0,
      "z": 8,
      "name": "Soil_Grass"
    },
    {
      "x": -26,
      "y": 0,
      "z": 9,
      "name": "Soil_Grass"
    },
    {
      "x": -26,
      "y": 0,
      "z": 10,
      "name": "Soil_Grass"
    },
    {
      "x": -26,
      "y": 0,
      "z": 11,
      "name": "Soil_Grass"
    },
    {
      "x": -26,
      "y": 0,
      "z": 12,
      "name": "Soil_Grass"
    },
    {
      "x": -26,
      "y": 0,
      "z": 13,
      "name": "Soil_Grass"
    },
    {
      "x": -26,
      "y": 0,
      "z": 14,
      "name": "Soil_Grass"
    },
    {
      "x": -26,
      "y": 0,
      "z": 15,
      "name": "Soil_Grass"
    },
    {
      "x": -26,
      "y": 0,
      "z": 16,
      "name": "Soil_Grass"
    },
    {
      "x": -26,
      "y": 0,
      "z": 17,
      "name": "Soil_Grass"
    },
    {
      "x": -26,
      "y": 0,
      "z": 18,
      "name": "Soil_Grass"
    },
    {
      "x": -26,
      "y": 0,
      "z": 19,
      "name": "Soil_Grass"
    },
    {
      "x": -26,
      "y": 0,
      "z": 20,
      "name": "Soil_Grass"
    },
    {
      "x": -25,
      "y": 0,
      "z": -20,
      "name": "Soil_Grass"
    },
    {
      "x": -25,
      "y": 0,
      "z": -19,
      "name": "Soil_Grass"
    },
    {
      "x": -25,
      "y": 0,
      "z": -18,
      "name": "Soil_Grass"
    },
    {
      "x": -25,
      "y": 0,
      "z": -17,
      "name": "Soil_Grass"
    },
    {
      "x": -25,
      "y": 0,
      "z": -16,
      "name": "Soil_Dirt"
    },
    {
      "x": -25,
      "y": 1,
      "z": -16,
      "name": "Soil_Grass"
    },
    {
      "x": -25,
      "y": 0,
      "z": -15,
      "name": "Soil_Dirt"
    },
    {
      "x": -25,
      "y": 1,
      "z": -15,
      "name": "Soil_Grass"
    },
    {
      "x": -25,
      "y": 0,
      "z": -14,
      "name": "Soil_Dirt"
    },
    {
      "x": -25,
      "y": 1,
      "z": -14,
      "name": "Soil_Grass"
    },
    {
      "x": -25,
      "y": 0,
      "z": -13,
      "name": "Soil_Dirt"
    },
    {
      "x": -25,
      "y": 1,
      "z": -13,
      "name": "Soil_Grass"
    },
    {
      "x": -25,
      "y": 2,
      "z": -13,
      "name": "Plant_Grass_Sharp",
      "support": 15
    },
    {
      "x": -25,
      "y": 0,
      "z": -12,
      "name": "Soil_Dirt"
    },
    {
      "x": -25,
      "y": 1,
      "z": -12,
      "name": "Soil_Grass"
    },
    {
      "x": -25,
      "y": 0,
      "z": -11,
      "name": "Soil_Dirt"
    },
    {
      "x": -25,
      "y": 1,
      "z": -11,
      "name": "Soil_Grass"
    },
    {
      "x": -25,
      "y": 0,
      "z": -10,
      "name": "Soil_Dirt"
    },
    {
      "x": -25,
      "y": 1,
      "z": -10,
      "name": "Soil_Grass"
    },
    {
      "x": -25,
      "y": 0,
      "z": -9,
      "name": "Soil_Dirt"
    },
    {
      "x": -25,
      "y": 1,
      "z": -9,
      "name": "Soil_Grass"
    },
    {
      "x": -25,
      "y": 0,
      "z": -8,
      "name": "Soil_Dirt"
    },
    {
      "x": -25,
      "y": 1,
      "z": -8,
      "name": "Soil_Grass"
    },
    {
      "x": -25,
      "y": 0,
      "z": -7,
      "name": "Soil_Dirt"
    },
    {
      "x": -25,
      "y": 1,
      "z": -7,
      "name": "Soil_Grass"
    },
    {
      "x": -25,
      "y": 0,
      "z": -6,
      "name": "Soil_Dirt"
    },
    {
      "x": -25,
      "y": 1,
      "z": -6,
      "name": "Soil_Grass"
    },
    {
      "x": -25,
      "y": 0,
      "z": -5,
      "name": "Soil_Dirt"
    },
    {
      "x": -25,
      "y": 1,
      "z": -5,
      "name": "Soil_Grass"
    },
    {
      "x": -25,
      "y": 0,
      "z": -4,
      "name": "Soil_Dirt"
    },
    {
      "x": -25,
      "y": 1,
      "z": -4,
      "name": "Soil_Grass"
    },
    {
      "x": -25,
      "y": 0,
      "z": -3,
      "name": "Soil_Dirt"
    },
    {
      "x": -25,
      "y": 1,
      "z": -3,
      "name": "Soil_Grass"
    },
    {
      "x": -25,
      "y": 0,
      "z": -2,
      "name": "Soil_Dirt"
    },
    {
      "x": -25,
      "y": 1,
      "z": -2,
      "name": "Soil_Dirt"
    },
    {
      "x": -25,
      "y": 2,
      "z": -2,
      "name": "Soil_Grass"
    },
    {
      "x": -25,
      "y": 0,
      "z": -1,
      "name": "Soil_Dirt"
    },
    {
      "x": -25,
      "y": 1,
      "z": -1,
      "name": "Soil_Dirt"
    },
    {
      "x": -25,
      "y": 2,
      "z": -1,
      "name": "Soil_Grass"
    },
    {
      "x": -25,
      "y": 0,
      "z": 0,
      "name": "Soil_Dirt"
    },
    {
      "x": -25,
      "y": 1,
      "z": 0,
      "name": "Soil_Dirt"
    },
    {
      "x": -25,
      "y": 2,
      "z": 0,
      "name": "Soil_Grass"
    },
    {
      "x": -25,
      "y": 3,
      "z": 0,
      "name": "Plant_Grass_Sharp",
      "support": 15
    },
    {
      "x": -25,
      "y": 0,
      "z": 1,
      "name": "Soil_Dirt"
    },
    {
      "x": -25,
      "y": 1,
      "z": 1,
      "name": "Soil_Dirt"
    },
    {
      "x": -25,
      "y": 2,
      "z": 1,
      "name": "Soil_Grass"
    },
    {
      "x": -25,
      "y": 0,
      "z": 2,
      "name": "Soil_Dirt"
    },
    {
      "x": -25,
      "y": 1,
      "z": 2,
      "name": "Soil_Dirt"
    },
    {
      "x": -25,
      "y": 2,
      "z": 2,
      "name": "Soil_Grass"
    },
    {
      "x": -25,
      "y": 0,
      "z": 3,
      "name": "Soil_Dirt"
    },
    {
      "x": -25,
      "y": 1,
      "z": 3,
      "name": "Soil_Grass"
    },
    {
      "x": -25,
      "y": 0,
      "z": 4,
      "name": "Soil_Dirt"
    },
    {
      "x": -25,
      "y": 1,
      "z": 4,
      "name": "Soil_Grass"
    },
    {
      "x": -25,
      "y": 0,
      "z": 5,
      "name": "Soil_Dirt"
    },
    {
      "x": -25,
      "y": 1,
      "z": 5,
      "name": "Soil_Grass"
    },
    {
      "x": -25,
      "y": 0,
      "z": 6,
      "name": "Soil_Grass"
    },
    {
      "x": -25,
      "y": 0,
      "z": 7,
      "name": "Soil_Grass"
    },
    {
      "x": -25,
      "y": 0,
      "z": 8,
      "name": "Soil_Grass"
    },
    {
      "x": -25,
      "y": 0,
      "z": 9,
      "name": "Soil_Grass"
    },
    {
      "x": -25,
      "y": 0,
      "z": 10,
      "name": "Soil_Grass"
    },
    {
      "x": -25,
      "y": 0,
      "z": 11,
      "name": "Soil_Grass"
    },
    {
      "x": -25,
      "y": 0,
      "z": 12,
      "name": "Soil_Grass"
    },
    {
      "x": -25,
      "y": 0,
      "z": 13,
      "name": "Soil_Grass"
    },
    {
      "x": -25,
      "y": 0,
      "z": 14,
      "name": "Soil_Grass"
    },
    {
      "x": -25,
      "y": 0,
      "z": 15,
      "name": "Soil_Grass"
    },
    {
      "x": -25,
      "y": 0,
      "z": 16,
      "name": "Soil_Grass"
    },
    {
      "x": -25,
      "y": 0,
      "z": 17,
      "name": "Soil_Grass"
    },
    {
      "x": -25,
      "y": 0,
      "z": 18,
      "name": "Soil_Grass"
    },
    {
      "x": -25,
      "y": 0,
      "z": 19,
      "name": "Soil_Grass"
    },
    {
      "x": -25,
      "y": 0,
      "z": 20,
      "name": "Soil_Grass"
    },
    {
      "x": -24,
      "y": 0,
      "z": -20,
      "name": "Soil_Grass"
    },
    {
      "x": -24,
      "y": 0,
      "z": -19,
      "name": "Soil_Grass"
    },
    {
      "x": -24,
      "y": 0,
      "z": -18,
      "name": "Soil_Grass"
    },
    {
      "x": -24,
      "y": 0,
      "z": -17,
      "name": "Soil_Dirt"
    },
    {
      "x": -24,
      "y": 1,
      "z": -17,
      "name": "Soil_Grass"
    },
    {
      "x": -24,
      "y": 0,
      "z": -16,
      "name": "Soil_Dirt"
    },
    {
      "x": -24,
      "y": 1,
      "z": -16,
      "name": "Soil_Grass"
    },
    {
      "x": -24,
      "y": 2,
      "z": -16,
      "name": "Plant_Grass_Dry_Tall",
      "support": 15
    },
    {
      "x": -24,
      "y": 3,
      "z": -16,
      "name": "Plant_Grass_Dry_Tall",
      "filler": 1024
    },
    {
      "x": -24,
      "y": 0,
      "z": -15,
      "name": "Soil_Dirt"
    },
    {
      "x": -24,
      "y": 1,
      "z": -15,
      "name": "Soil_Grass"
    },
    {
      "x": -24,
      "y": 0,
      "z": -14,
      "name": "Soil_Dirt"
    },
    {
      "x": -24,
      "y": 1,
      "z": -14,
      "name": "Soil_Grass"
    },
    {
      "x": -24,
      "y": 0,
      "z": -13,
      "name": "Soil_Dirt"
    },
    {
      "x": -24,
      "y": 1,
      "z": -13,
      "name": "Soil_Grass"
    },
    {
      "x": -24,
      "y": 0,
      "z": -12,
      "name": "Soil_Dirt"
    },
    {
      "x": -24,
      "y": 1,
      "z": -12,
      "name": "Soil_Dirt"
    },
    {
      "x": -24,
      "y": 2,
      "z": -12,
      "name": "Soil_Grass"
    },
    {
      "x": -24,
      "y": 0,
      "z": -11,
      "name": "Soil_Dirt"
    },
    {
      "x": -24,
      "y": 1,
      "z": -11,
      "name": "Soil_Dirt"
    },
    {
      "x": -24,
      "y": 2,
      "z": -11,
      "name": "Soil_Grass"
    },
    {
      "x": -24,
      "y": 0,
      "z": -10,
      "name": "Soil_Dirt"
    },
    {
      "x": -24,
      "y": 1,
      "z": -10,
      "name": "Soil_Grass"
    },
    {
      "x": -24,
      "y": 0,
      "z": -9,
      "name": "Soil_Dirt"
    },
    {
      "x": -24,
      "y": 1,
      "z": -9,
      "name": "Soil_Grass"
    },
    {
      "x": -24,
      "y": 2,
      "z": -9,
      "name": "Plant_Grass_Sharp",
      "support": 15
    },
    {
      "x": -24,
      "y": 0,
      "z": -8,
      "name": "Soil_Dirt"
    },
    {
      "x": -24,
      "y": 1,
      "z": -8,
      "name": "Soil_Dirt"
    },
    {
      "x": -24,
      "y": 2,
      "z": -8,
      "name": "Soil_Grass"
    },
    {
      "x": -24,
      "y": 0,
      "z": -7,
      "name": "Soil_Dirt"
    },
    {
      "x": -24,
      "y": 1,
      "z": -7,
      "name": "Soil_Dirt"
    },
    {
      "x": -24,
      "y": 2,
      "z": -7,
      "name": "Soil_Grass"
    },
    {
      "x": -24,
      "y": 3,
      "z": -7,
      "name": "Plant_Grass_Sharp",
      "support": 15
    },
    {
      "x": -24,
      "y": 0,
      "z": -6,
      "name": "Soil_Dirt"
    },
    {
      "x": -24,
      "y": 1,
      "z": -6,
      "name": "Soil_Dirt"
    },
    {
      "x": -24,
      "y": 2,
      "z": -6,
      "name": "Soil_Grass"
    },
    {
      "x": -24,
      "y": 0,
      "z": -5,
      "name": "Soil_Dirt"
    },
    {
      "x": -24,
      "y": 1,
      "z": -5,
      "name": "Soil_Grass"
    },
    {
      "x": -24,
      "y": 0,
      "z": -4,
      "name": "Soil_Dirt"
    },
    {
      "x": -24,
      "y": 1,
      "z": -4,
      "name": "Soil_Grass"
    },
    {
      "x": -24,
      "y": 0,
      "z": -3,
      "name": "Soil_Dirt"
    },
    {
      "x": -24,
      "y": 1,
      "z": -3,
      "name": "Soil_Dirt"
    },
    {
      "x": -24,
      "y": 2,
      "z": -3,
      "name": "Soil_Grass"
    },
    {
      "x": -24,
      "y": 3,
      "z": -3,
      "name": "Plant_Grass_Sharp",
      "support": 15
    },
    {
      "x": -24,
      "y": 0,
      "z": -2,
      "name": "Soil_Dirt"
    },
    {
      "x": -24,
      "y": 1,
      "z": -2,
      "name": "Soil_Dirt"
    },
    {
      "x": -24,
      "y": 2,
      "z": -2,
      "name": "Soil_Grass"
    },
    {
      "x": -24,
      "y": 0,
      "z": -1,
      "name": "Soil_Dirt"
    },
    {
      "x": -24,
      "y": 1,
      "z": -1,
      "name": "Soil_Dirt"
    },
    {
      "x": -24,
      "y": 2,
      "z": -1,
      "name": "Soil_Grass"
    },
    {
      "x": -24,
      "y": 3,
      "z": -1,
      "name": "Plant_Grass_Sharp",
      "support": 15
    },
    {
      "x": -24,
      "y": 0,
      "z": 0,
      "name": "Soil_Dirt"
    },
    {
      "x": -24,
      "y": 1,
      "z": 0,
      "name": "Soil_Dirt"
    },
    {
      "x": -24,
      "y": 2,
      "z": 0,
      "name": "Soil_Grass"
    },
    {
      "x": -24,
      "y": 0,
      "z": 1,
      "name": "Soil_Dirt"
    },
    {
      "x": -24,
      "y": 1,
      "z": 1,
      "name": "Soil_Dirt"
    },
    {
      "x": -24,
      "y": 2,
      "z": 1,
      "name": "Soil_Grass"
    },
    {
      "x": -24,
      "y": 0,
      "z": 2,
      "name": "Soil_Dirt"
    },
    {
      "x": -24,
      "y": 1,
      "z": 2,
      "name": "Soil_Dirt"
    },
    {
      "x": -24,
      "y": 2,
      "z": 2,
      "name": "Soil_Grass"
    },
    {
      "x": -24,
      "y": 0,
      "z": 3,
      "name": "Soil_Dirt"
    },
    {
      "x": -24,
      "y": 1,
      "z": 3,
      "name": "Soil_Dirt"
    },
    {
      "x": -24,
      "y": 2,
      "z": 3,
      "name": "Soil_Grass"
    },
    {
      "x": -24,
      "y": 3,
      "z": 3,
      "name": "Plant_Bush",
      "support": 15
    },
    {
      "x": -24,
      "y": 0,
      "z": 4,
      "name": "Soil_Dirt"
    },
    {
      "x": -24,
      "y": 1,
      "z": 4,
      "name": "Soil_Dirt"
    },
    {
      "x": -24,
      "y": 2,
      "z": 4,
      "name": "Soil_Grass"
    },
    {
      "x": -24,
      "y": 0,
      "z": 5,
      "name": "Soil_Dirt"
    },
    {
      "x": -24,
      "y": 1,
      "z": 5,
      "name": "Soil_Dirt"
    },
    {
      "x": -24,
      "y": 2,
      "z": 5,
      "name": "Soil_Grass"
    },
    {
      "x": -24,
      "y": 3,
      "z": 5,
      "name": "Plant_Grass_Sharp",
      "support": 15
    },
    {
      "x": -24,
      "y": 0,
      "z": 6,
      "name": "Soil_Dirt"
    },
    {
      "x": -24,
      "y": 1,
      "z": 6,
      "name": "Soil_Grass"
    },
    {
      "x": -24,
      "y": 0,
      "z": 7,
      "name": "Soil_Grass"
    },
    {
      "x": -24,
      "y": 0,
      "z": 8,
      "name": "Soil_Grass"
    },
    {
      "x": -24,
      "y": 0,
      "z": 9,
      "name": "Soil_Grass"
    },
    {
      "x": -24,
      "y": 0,
      "z": 10,
      "name": "Soil_Grass"
    },
    {
      "x": -24,
      "y": 0,
      "z": 11,
      "name": "Soil_Grass"
    },
    {
      "x": -24,
      "y": 0,
      "z": 12,
      "name": "Soil_Grass"
    },
    {
      "x": -24,
      "y": 0,
      "z": 13,
      "name": "Soil_Grass"
    },
    {
      "x": -24,
      "y": 0,
      "z": 14,
      "name": "Soil_Grass"
    },
    {
      "x": -24,
      "y": 0,
      "z": 15,
      "name": "Soil_Grass"
    },
    {
      "x": -24,
      "y": 0,
      "z": 16,
      "name": "Soil_Grass"
    },
    {
      "x": -24,
      "y": 0,
      "z": 17,
      "name": "Soil_Grass"
    },
    {
      "x": -24,
      "y": 0,
      "z": 18,
      "name": "Soil_Grass"
    },
    {
      "x": -24,
      "y": 0,
      "z": 19,
      "name": "Soil_Grass"
    },
    {
      "x": -24,
      "y": 0,
      "z": 20,
      "name": "Soil_Grass"
    },
    {
      "x": -23,
      "y": 0,
      "z": -20,
      "name": "Soil_Grass"
    },
    {
      "x": -23,
      "y": 0,
      "z": -19,
      "name": "Soil_Grass"
    },
    {
      "x": -23,
      "y": 0,
      "z": -18,
      "name": "Soil_Dirt"
    },
    {
      "x": -23,
      "y": 1,
      "z": -18,
      "name": "Soil_Grass"
    },
    {
      "x": -23,
      "y": 0,
      "z": -17,
      "name": "Soil_Dirt"
    },
    {
      "x": -23,
      "y": 1,
      "z": -17,
      "name": "Soil_Grass"
    },
    {
      "x": -23,
      "y": 0,
      "z": -16,
      "name": "Soil_Dirt"
    },
    {
      "x": -23,
      "y": 1,
      "z": -16,
      "name": "Soil_Grass"
    },
    {
      "x": -23,
      "y": 2,
      "z": -16,
      "name": "Plant_Grass_Dry_Tall",
      "support": 15
    },
    {
      "x": -23,
      "y": 3,
      "z": -16,
      "name": "Plant_Grass_Dry_Tall",
      "filler": 1024
    },
    {
      "x": -23,
      "y": 0,
      "z": -15,
      "name": "Soil_Dirt"
    },
    {
      "x": -23,
      "y": 1,
      "z": -15,
      "name": "Soil_Dirt"
    },
    {
      "x": -23,
      "y": 2,
      "z": -15,
      "name": "Soil_Grass"
    },
    {
      "x": -23,
      "y": 0,
      "z": -14,
      "name": "Soil_Dirt"
    },
    {
      "x": -23,
      "y": 1,
      "z": -14,
      "name": "Soil_Dirt"
    },
    {
      "x": -23,
      "y": 2,
      "z": -14,
      "name": "Soil_Grass"
    },
    {
      "x": -23,
      "y": 0,
      "z": -13,
      "name": "Soil_Dirt"
    },
    {
      "x": -23,
      "y": 1,
      "z": -13,
      "name": "Soil_Dirt"
    },
    {
      "x": -23,
      "y": 2,
      "z": -13,
      "name": "Soil_Grass"
    },
    {
      "x": -23,
      "y": 3,
      "z": -13,
      "name": "Plant_Flower_Common_White2"
    },
    {
      "x": -23,
      "y": 0,
      "z": -12,
      "name": "Soil_Dirt"
    },
    {
      "x": -23,
      "y": 1,
      "z": -12,
      "name": "Soil_Dirt"
    },
    {
      "x": -23,
      "y": 2,
      "z": -12,
      "name": "Soil_Grass"
    },
    {
      "x": -23,
      "y": 3,
      "z": -12,
      "name": "Plant_Grass_Sharp",
      "support": 15
    },
    {
      "x": -23,
      "y": 0,
      "z": -11,
      "name": "Soil_Dirt"
    },
    {
      "x": -23,
      "y": 1,
      "z": -11,
      "name": "Soil_Dirt"
    },
    {
      "x": -23,
      "y": 2,
      "z": -11,
      "name": "Soil_Grass"
    },
    {
      "x": -23,
      "y": 0,
      "z": -10,
      "name": "Soil_Dirt"
    },
    {
      "x": -23,
      "y": 1,
      "z": -10,
      "name": "Soil_Dirt"
    },
    {
      "x": -23,
      "y": 2,
      "z": -10,
      "name": "Soil_Grass"
    },
    {
      "x": -23,
      "y": 0,
      "z": -9,
      "name": "Soil_Dirt"
    },
    {
      "x": -23,
      "y": 1,
      "z": -9,
      "name": "Soil_Dirt"
    },
    {
      "x": -23,
      "y": 2,
      "z": -9,
      "name": "Soil_Grass"
    },
    {
      "x": -23,
      "y": 0,
      "z": -8,
      "name": "Soil_Dirt"
    },
    {
      "x": -23,
      "y": 1,
      "z": -8,
      "name": "Soil_Dirt"
    },
    {
      "x": -23,
      "y": 2,
      "z": -8,
      "name": "Soil_Grass"
    },
    {
      "x": -23,
      "y": 0,
      "z": -7,
      "name": "Soil_Dirt"
    },
    {
      "x": -23,
      "y": 1,
      "z": -7,
      "name": "Soil_Dirt"
    },
    {
      "x": -23,
      "y": 2,
      "z": -7,
      "name": "Soil_Grass"
    },
    {
      "x": -23,
      "y": 3,
      "z": -7,
      "name": "Plant_Grass_Sharp",
      "support": 15
    },
    {
      "x": -23,
      "y": 0,
      "z": -6,
      "name": "Soil_Dirt"
    },
    {
      "x": -23,
      "y": 1,
      "z": -6,
      "name": "Soil_Dirt"
    },
    {
      "x": -23,
      "y": 2,
      "z": -6,
      "name": "Soil_Grass"
    },
    {
      "x": -23,
      "y": 0,
      "z": -5,
      "name": "Soil_Dirt"
    },
    {
      "x": -23,
      "y": 1,
      "z": -5,
      "name": "Soil_Dirt"
    },
    {
      "x": -23,
      "y": 2,
      "z": -5,
      "name": "Soil_Grass"
    },
    {
      "x": -23,
      "y": 0,
      "z": -4,
      "name": "Soil_Dirt"
    },
    {
      "x": -23,
      "y": 1,
      "z": -4,
      "name": "Soil_Dirt"
    },
    {
      "x": -23,
      "y": 2,
      "z": -4,
      "name": "Soil_Grass"
    },
    {
      "x": -23,
      "y": 3,
      "z": -4,
      "name": "Plant_Grass_Sharp",
      "support": 15
    },
    {
      "x": -23,
      "y": 0,
      "z": -3,
      "name": "Soil_Dirt"
    },
    {
      "x": -23,
      "y": 1,
      "z": -3,
      "name": "Soil_Dirt"
    },
    {
      "x": -23,
      "y": 2,
      "z": -3,
      "name": "Soil_Grass"
    },
    {
      "x": -23,
      "y": 0,
      "z": -2,
      "name": "Rock_Stone"
    },
    {
      "x": -23,
      "y": 1,
      "z": -2,
      "name": "Soil_Dirt"
    },
    {
      "x": -23,
      "y": 2,
      "z": -2,
      "name": "Soil_Dirt"
    },
    {
      "x": -23,
      "y": 3,
      "z": -2,
      "name": "Soil_Grass"
    },
    {
      "x": -23,
      "y": 0,
      "z": -1,
      "name": "Rock_Stone"
    },
    {
      "x": -23,
      "y": 1,
      "z": -1,
      "name": "Soil_Dirt"
    },
    {
      "x": -23,
      "y": 2,
      "z": -1,
      "name": "Soil_Dirt"
    },
    {
      "x": -23,
      "y": 3,
      "z": -1,
      "name": "Soil_Grass"
    },
    {
      "x": -23,
      "y": 0,
      "z": 0,
      "name": "Rock_Stone"
    },
    {
      "x": -23,
      "y": 1,
      "z": 0,
      "name": "Soil_Dirt"
    },
    {
      "x": -23,
      "y": 2,
      "z": 0,
      "name": "Soil_Dirt"
    },
    {
      "x": -23,
      "y": 3,
      "z": 0,
      "name": "Soil_Grass"
    },
    {
      "x": -23,
      "y": 0,
      "z": 1,
      "name": "Rock_Stone"
    },
    {
      "x": -23,
      "y": 1,
      "z": 1,
      "name": "Soil_Dirt"
    },
    {
      "x": -23,
      "y": 2,
      "z": 1,
      "name": "Soil_Dirt"
    },
    {
      "x": -23,
      "y": 3,
      "z": 1,
      "name": "Soil_Grass"
    },
    {
      "x": -23,
      "y": 0,
      "z": 2,
      "name": "Rock_Stone"
    },
    {
      "x": -23,
      "y": 1,
      "z": 2,
      "name": "Soil_Dirt"
    },
    {
      "x": -23,
      "y": 2,
      "z": 2,
      "name": "Soil_Dirt"
    },
    {
      "x": -23,
      "y": 3,
      "z": 2,
      "name": "Soil_Grass"
    },
    {
      "x": -23,
      "y": 4,
      "z": 2,
      "name": "Plant_Grass_Sharp",
      "support": 15
    },
    {
      "x": -23,
      "y": 0,
      "z": 3,
      "name": "Rock_Stone"
    },
    {
      "x": -23,
      "y": 1,
      "z": 3,
      "name": "Soil_Dirt"
    },
    {
      "x": -23,
      "y": 2,
      "z": 3,
      "name": "Soil_Dirt"
    },
    {
      "x": -23,
      "y": 3,
      "z": 3,
      "name": "Soil_Grass"
    },
    {
      "x": -23,
      "y": 0,
      "z": 4,
      "name": "Soil_Dirt"
    },
    {
      "x": -23,
      "y": 1,
      "z": 4,
      "name": "Soil_Dirt"
    },
    {
      "x": -23,
      "y": 2,
      "z": 4,
      "name": "Soil_Grass"
    },
    {
      "x": -23,
      "y": 3,
      "z": 4,
      "name": "Plant_Grass_Sharp",
      "support": 15
    },
    {
      "x": -23,
      "y": 0,
      "z": 5,
      "name": "Soil_Dirt"
    },
    {
      "x": -23,
      "y": 1,
      "z": 5,
      "name": "Soil_Dirt"
    },
    {
      "x": -23,
      "y": 2,
      "z": 5,
      "name": "Soil_Grass"
    },
    {
      "x": -23,
      "y": 0,
      "z": 6,
      "name": "Soil_Dirt"
    },
    {
      "x": -23,
      "y": 1,
      "z": 6,
      "name": "Soil_Dirt"
    },
    {
      "x": -23,
      "y": 2,
      "z": 6,
      "name": "Soil_Grass"
    },
    {
      "x": -23,
      "y": 0,
      "z": 7,
      "name": "Soil_Dirt"
    },
    {
      "x": -23,
      "y": 1,
      "z": 7,
      "name": "Soil_Grass"
    },
    {
      "x": -23,
      "y": 2,
      "z": 7,
      "name": "Plant_Bush_Green",
      "support": 15
    },
    {
      "x": -23,
      "y": 3,
      "z": 7,
      "name": "Plant_Bush_Green",
      "filler": 1024
    },
    {
      "x": -23,
      "y": 0,
      "z": 8,
      "name": "Soil_Grass"
    },
    {
      "x": -23,
      "y": 0,
      "z": 9,
      "name": "Soil_Grass"
    },
    {
      "x": -23,
      "y": 0,
      "z": 10,
      "name": "Soil_Grass"
    },
    {
      "x": -23,
      "y": 0,
      "z": 11,
      "name": "Soil_Grass"
    },
    {
      "x": -23,
      "y": 0,
      "z": 12,
      "name": "Soil_Grass"
    },
    {
      "x": -23,
      "y": 0,
      "z": 13,
      "name": "Soil_Grass"
    },
    {
      "x": -23,
      "y": 0,
      "z": 14,
      "name": "Soil_Grass"
    },
    {
      "x": -23,
      "y": 0,
      "z": 15,
      "name": "Soil_Grass"
    },
    {
      "x": -23,
      "y": 0,
      "z": 16,
      "name": "Soil_Grass"
    },
    {
      "x": -23,
      "y": 0,
      "z": 17,
      "name": "Soil_Grass"
    },
    {
      "x": -23,
      "y": 0,
      "z": 18,
      "name": "Soil_Grass"
    },
    {
      "x": -23,
      "y": 0,
      "z": 19,
      "name": "Soil_Grass"
    },
    {
      "x": -23,
      "y": 0,
      "z": 20,
      "name": "Soil_Grass"
    },
    {
      "x": -22,
      "y": 0,
      "z": -20,
      "name": "Soil_Grass"
    },
    {
      "x": -22,
      "y": 0,
      "z": -19,
      "name": "Soil_Dirt"
    },
    {
      "x": -22,
      "y": 1,
      "z": -19,
      "name": "Soil_Grass"
    },
    {
      "x": -22,
      "y": 0,
      "z": -18,
      "name": "Soil_Dirt"
    },
    {
      "x": -22,
      "y": 1,
      "z": -18,
      "name": "Soil_Grass"
    },
    {
      "x": -22,
      "y": 2,
      "z": -18,
      "name": "Plant_Grass_Sharp",
      "support": 15
    },
    {
      "x": -22,
      "y": 0,
      "z": -17,
      "name": "Soil_Dirt"
    },
    {
      "x": -22,
      "y": 1,
      "z": -17,
      "name": "Soil_Grass"
    },
    {
      "x": -22,
      "y": 0,
      "z": -16,
      "name": "Soil_Dirt"
    },
    {
      "x": -22,
      "y": 1,
      "z": -16,
      "name": "Soil_Dirt"
    },
    {
      "x": -22,
      "y": 2,
      "z": -16,
      "name": "Soil_Grass"
    },
    {
      "x": -22,
      "y": 0,
      "z": -15,
      "name": "Soil_Dirt"
    },
    {
      "x": -22,
      "y": 1,
      "z": -15,
      "name": "Soil_Dirt"
    },
    {
      "x": -22,
      "y": 2,
      "z": -15,
      "name": "Soil_Grass"
    },
    {
      "x": -22,
      "y": 0,
      "z": -14,
      "name": "Soil_Dirt"
    },
    {
      "x": -22,
      "y": 1,
      "z": -14,
      "name": "Soil_Dirt"
    },
    {
      "x": -22,
      "y": 2,
      "z": -14,
      "name": "Soil_Grass"
    },
    {
      "x": -22,
      "y": 0,
      "z": -13,
      "name": "Rock_Stone"
    },
    {
      "x": -22,
      "y": 1,
      "z": -13,
      "name": "Soil_Dirt"
    },
    {
      "x": -22,
      "y": 2,
      "z": -13,
      "name": "Soil_Dirt"
    },
    {
      "x": -22,
      "y": 3,
      "z": -13,
      "name": "Soil_Grass"
    },
    {
      "x": -22,
      "y": 0,
      "z": -12,
      "name": "Rock_Stone"
    },
    {
      "x": -22,
      "y": 1,
      "z": -12,
      "name": "Soil_Dirt"
    },
    {
      "x": -22,
      "y": 2,
      "z": -12,
      "name": "Soil_Dirt"
    },
    {
      "x": -22,
      "y": 3,
      "z": -12,
      "name": "Soil_Grass"
    },
    {
      "x": -22,
      "y": 0,
      "z": -11,
      "name": "Rock_Stone"
    },
    {
      "x": -22,
      "y": 1,
      "z": -11,
      "name": "Soil_Dirt"
    },
    {
      "x": -22,
      "y": 2,
      "z": -11,
      "name": "Soil_Dirt"
    },
    {
      "x": -22,
      "y": 3,
      "z": -11,
      "name": "Soil_Grass"
    },
    {
      "x": -22,
      "y": 4,
      "z": -11,
      "name": "Plant_Flower_Tall_Yellow"
    },
    {
      "x": -22,
      "y": 0,
      "z": -10,
      "name": "Rock_Stone"
    },
    {
      "x": -22,
      "y": 1,
      "z": -10,
      "name": "Soil_Dirt"
    },
    {
      "x": -22,
      "y": 2,
      "z": -10,
      "name": "Soil_Dirt"
    },
    {
      "x": -22,
      "y": 3,
      "z": -10,
      "name": "Soil_Grass"
    },
    {
      "x": -22,
      "y": 0,
      "z": -9,
      "name": "Soil_Dirt"
    },
    {
      "x": -22,
      "y": 1,
      "z": -9,
      "name": "Soil_Dirt"
    },
    {
      "x": -22,
      "y": 2,
      "z": -9,
      "name": "Soil_Grass"
    },
    {
      "x": -22,
      "y": 0,
      "z": -8,
      "name": "Soil_Dirt"
    },
    {
      "x": -22,
      "y": 1,
      "z": -8,
      "name": "Soil_Dirt"
    },
    {
      "x": -22,
      "y": 2,
      "z": -8,
      "name": "Soil_Grass"
    },
    {
      "x": -22,
      "y": 0,
      "z": -7,
      "name": "Rock_Stone"
    },
    {
      "x": -22,
      "y": 1,
      "z": -7,
      "name": "Soil_Dirt"
    },
    {
      "x": -22,
      "y": 2,
      "z": -7,
      "name": "Soil_Dirt"
    },
    {
      "x": -22,
      "y": 3,
      "z": -7,
      "name": "Soil_Grass"
    },
    {
      "x": -22,
      "y": 0,
      "z": -6,
      "name": "Rock_Stone"
    },
    {
      "x": -22,
      "y": 1,
      "z": -6,
      "name": "Soil_Dirt"
    },
    {
      "x": -22,
      "y": 2,
      "z": -6,
      "name": "Soil_Dirt"
    },
    {
      "x": -22,
      "y": 3,
      "z": -6,
      "name": "Soil_Grass"
    },
    {
      "x": -22,
      "y": 0,
      "z": -5,
      "name": "Soil_Dirt"
    },
    {
      "x": -22,
      "y": 1,
      "z": -5,
      "name": "Soil_Dirt"
    },
    {
      "x": -22,
      "y": 2,
      "z": -5,
      "name": "Soil_Grass"
    },
    {
      "x": -22,
      "y": 0,
      "z": -4,
      "name": "Rock_Stone"
    },
    {
      "x": -22,
      "y": 1,
      "z": -4,
      "name": "Soil_Dirt"
    },
    {
      "x": -22,
      "y": 2,
      "z": -4,
      "name": "Soil_Dirt"
    },
    {
      "x": -22,
      "y": 3,
      "z": -4,
      "name": "Soil_Grass"
    },
    {
      "x": -22,
      "y": 0,
      "z": -3,
      "name": "Rock_Stone"
    },
    {
      "x": -22,
      "y": 1,
      "z": -3,
      "name": "Soil_Dirt"
    },
    {
      "x": -22,
      "y": 2,
      "z": -3,
      "name": "Soil_Dirt"
    },
    {
      "x": -22,
      "y": 3,
      "z": -3,
      "name": "Soil_Grass"
    },
    {
      "x": -22,
      "y": 4,
      "z": -3,
      "name": "Plant_Flower_Common_Pink"
    },
    {
      "x": -22,
      "y": 5,
      "z": -3,
      "name": "Plant_Flower_Common_Pink",
      "filler": 1024
    },
    {
      "x": -22,
      "y": 0,
      "z": -2,
      "name": "Rock_Stone"
    },
    {
      "x": -22,
      "y": 1,
      "z": -2,
      "name": "Soil_Dirt"
    },
    {
      "x": -22,
      "y": 2,
      "z": -2,
      "name": "Soil_Dirt"
    },
    {
      "x": -22,
      "y": 3,
      "z": -2,
      "name": "Soil_Grass"
    },
    {
      "x": -22,
      "y": 4,
      "z": -2,
      "name": "Plant_Grass_Sharp",
      "support": 15
    },
    {
      "x": -22,
      "y": 0,
      "z": -1,
      "name": "Rock_Stone"
    },
    {
      "x": -22,
      "y": 1,
      "z": -1,
      "name": "Soil_Dirt"
    },
    {
      "x": -22,
      "y": 2,
      "z": -1,
      "name": "Soil_Dirt"
    },
    {
      "x": -22,
      "y": 3,
      "z": -1,
      "name": "Soil_Grass"
    },
    {
      "x": -22,
      "y": 0,
      "z": 0,
      "name": "Rock_Stone"
    },
    {
      "x": -22,
      "y": 1,
      "z": 0,
      "name": "Soil_Dirt"
    },
    {
      "x": -22,
      "y": 2,
      "z": 0,
      "name": "Soil_Dirt"
    },
    {
      "x": -22,
      "y": 3,
      "z": 0,
      "name": "Soil_Grass"
    },
    {
      "x": -22,
      "y": 0,
      "z": 1,
      "name": "Rock_Stone"
    },
    {
      "x": -22,
      "y": 1,
      "z": 1,
      "name": "Soil_Dirt"
    },
    {
      "x": -22,
      "y": 2,
      "z": 1,
      "name": "Soil_Dirt"
    },
    {
      "x": -22,
      "y": 3,
      "z": 1,
      "name": "Soil_Grass"
    },
    {
      "x": -22,
      "y": 0,
      "z": 2,
      "name": "Rock_Stone"
    },
    {
      "x": -22,
      "y": 1,
      "z": 2,
      "name": "Soil_Dirt"
    },
    {
      "x": -22,
      "y": 2,
      "z": 2,
      "name": "Soil_Dirt"
    },
    {
      "x": -22,
      "y": 3,
      "z": 2,
      "name": "Soil_Grass"
    },
    {
      "x": -22,
      "y": 4,
      "z": 2,
      "name": "Plant_Flower_Common_Yellow"
    },
    {
      "x": -22,
      "y": 0,
      "z": 3,
      "name": "Rock_Stone"
    },
    {
      "x": -22,
      "y": 1,
      "z": 3,
      "name": "Soil_Dirt"
    },
    {
      "x": -22,
      "y": 2,
      "z": 3,
      "name": "Soil_Dirt"
    },
    {
      "x": -22,
      "y": 3,
      "z": 3,
      "name": "Soil_Grass"
    },
    {
      "x": -22,
      "y": 0,
      "z": 4,
      "name": "Rock_Stone"
    },
    {
      "x": -22,
      "y": 1,
      "z": 4,
      "name": "Soil_Dirt"
    },
    {
      "x": -22,
      "y": 2,
      "z": 4,
      "name": "Soil_Dirt"
    },
    {
      "x": -22,
      "y": 3,
      "z": 4,
      "name": "Soil_Grass"
    },
    {
      "x": -22,
      "y": 0,
      "z": 5,
      "name": "Rock_Stone"
    },
    {
      "x": -22,
      "y": 1,
      "z": 5,
      "name": "Soil_Dirt"
    },
    {
      "x": -22,
      "y": 2,
      "z": 5,
      "name": "Soil_Dirt"
    },
    {
      "x": -22,
      "y": 3,
      "z": 5,
      "name": "Soil_Grass"
    },
    {
      "x": -22,
      "y": 0,
      "z": 6,
      "name": "Soil_Dirt"
    },
    {
      "x": -22,
      "y": 1,
      "z": 6,
      "name": "Soil_Dirt"
    },
    {
      "x": -22,
      "y": 2,
      "z": 6,
      "name": "Soil_Grass"
    },
    {
      "x": -22,
      "y": 0,
      "z": 7,
      "name": "Soil_Dirt"
    },
    {
      "x": -22,
      "y": 1,
      "z": 7,
      "name": "Soil_Grass"
    },
    {
      "x": -22,
      "y": 0,
      "z": 8,
      "name": "Soil_Dirt"
    },
    {
      "x": -22,
      "y": 1,
      "z": 8,
      "name": "Soil_Grass"
    },
    {
      "x": -22,
      "y": 0,
      "z": 9,
      "name": "Soil_Grass"
    },
    {
      "x": -22,
      "y": 0,
      "z": 10,
      "name": "Soil_Grass"
    },
    {
      "x": -22,
      "y": 0,
      "z": 11,
      "name": "Soil_Grass"
    },
    {
      "x": -22,
      "y": 0,
      "z": 12,
      "name": "Soil_Grass"
    },
    {
      "x": -22,
      "y": 0,
      "z": 13,
      "name": "Soil_Grass"
    },
    {
      "x": -22,
      "y": 0,
      "z": 14,
      "name": "Soil_Grass"
    },
    {
      "x": -22,
      "y": 0,
      "z": 15,
      "name": "Soil_Grass"
    },
    {
      "x": -22,
      "y": 0,
      "z": 16,
      "name": "Soil_Grass"
    },
    {
      "x": -22,
      "y": 0,
      "z": 17,
      "name": "Soil_Grass"
    },
    {
      "x": -22,
      "y": 0,
      "z": 18,
      "name": "Soil_Grass"
    },
    {
      "x": -22,
      "y": 0,
      "z": 19,
      "name": "Soil_Grass"
    },
    {
      "x": -22,
      "y": 0,
      "z": 20,
      "name": "Soil_Grass"
    },
    {
      "x": -21,
      "y": 0,
      "z": -20,
      "name": "Soil_Grass"
    },
    {
      "x": -21,
      "y": 0,
      "z": -19,
      "name": "Soil_Dirt"
    },
    {
      "x": -21,
      "y": 1,
      "z": -19,
      "name": "Soil_Grass"
    },
    {
      "x": -21,
      "y": 2,
      "z": -19,
      "name": "Plant_Flower_Bushy_Green"
    },
    {
      "x": -21,
      "y": 0,
      "z": -18,
      "name": "Soil_Dirt"
    },
    {
      "x": -21,
      "y": 1,
      "z": -18,
      "name": "Soil_Grass"
    },
    {
      "x": -21,
      "y": 0,
      "z": -17,
      "name": "Soil_Dirt"
    },
    {
      "x": -21,
      "y": 1,
      "z": -17,
      "name": "Soil_Grass"
    },
    {
      "x": -21,
      "y": 0,
      "z": -16,
      "name": "Soil_Dirt"
    },
    {
      "x": -21,
      "y": 1,
      "z": -16,
      "name": "Soil_Dirt"
    },
    {
      "x": -21,
      "y": 2,
      "z": -16,
      "name": "Soil_Grass"
    },
    {
      "x": -21,
      "y": 0,
      "z": -15,
      "name": "Soil_Dirt"
    },
    {
      "x": -21,
      "y": 1,
      "z": -15,
      "name": "Soil_Dirt"
    },
    {
      "x": -21,
      "y": 2,
      "z": -15,
      "name": "Soil_Grass"
    },
    {
      "x": -21,
      "y": 0,
      "z": -14,
      "name": "Rock_Stone"
    },
    {
      "x": -21,
      "y": 1,
      "z": -14,
      "name": "Soil_Dirt"
    },
    {
      "x": -21,
      "y": 2,
      "z": -14,
      "name": "Soil_Dirt"
    },
    {
      "x": -21,
      "y": 3,
      "z": -14,
      "name": "Soil_Grass"
    },
    {
      "x": -21,
      "y": 4,
      "z": -14,
      "name": "Plant_Grass_Sharp",
      "support": 15
    },
    {
      "x": -21,
      "y": 0,
      "z": -13,
      "name": "Rock_Stone"
    },
    {
      "x": -21,
      "y": 1,
      "z": -13,
      "name": "Soil_Dirt"
    },
    {
      "x": -21,
      "y": 2,
      "z": -13,
      "name": "Soil_Dirt"
    },
    {
      "x": -21,
      "y": 3,
      "z": -13,
      "name": "Soil_Grass"
    },
    {
      "x": -21,
      "y": 0,
      "z": -12,
      "name": "Rock_Stone"
    },
    {
      "x": -21,
      "y": 1,
      "z": -12,
      "name": "Soil_Dirt"
    },
    {
      "x": -21,
      "y": 2,
      "z": -12,
      "name": "Soil_Dirt"
    },
    {
      "x": -21,
      "y": 3,
      "z": -12,
      "name": "Soil_Grass"
    },
    {
      "x": -21,
      "y": 4,
      "z": -12,
      "name": "Plant_Grass_Sharp",
      "support": 15
    },
    {
      "x": -21,
      "y": 0,
      "z": -11,
      "name": "Rock_Stone"
    },
    {
      "x": -21,
      "y": 1,
      "z": -11,
      "name": "Soil_Dirt"
    },
    {
      "x": -21,
      "y": 2,
      "z": -11,
      "name": "Soil_Dirt"
    },
    {
      "x": -21,
      "y": 3,
      "z": -11,
      "name": "Soil_Grass"
    },
    {
      "x": -21,
      "y": 0,
      "z": -10,
      "name": "Rock_Stone"
    },
    {
      "x": -21,
      "y": 1,
      "z": -10,
      "name": "Soil_Dirt"
    },
    {
      "x": -21,
      "y": 2,
      "z": -10,
      "name": "Soil_Dirt"
    },
    {
      "x": -21,
      "y": 3,
      "z": -10,
      "name": "Soil_Grass"
    },
    {
      "x": -21,
      "y": 4,
      "z": -10,
      "name": "Plant_Grass_Dry_Tall",
      "support": 15
    },
    {
      "x": -21,
      "y": 5,
      "z": -10,
      "name": "Plant_Grass_Dry_Tall",
      "filler": 1024
    },
    {
      "x": -21,
      "y": 0,
      "z": -9,
      "name": "Soil_Dirt"
    },
    {
      "x": -21,
      "y": 1,
      "z": -9,
      "name": "Soil_Dirt"
    },
    {
      "x": -21,
      "y": 2,
      "z": -9,
      "name": "Soil_Grass"
    },
    {
      "x": -21,
      "y": 0,
      "z": -8,
      "name": "Rock_Stone"
    },
    {
      "x": -21,
      "y": 1,
      "z": -8,
      "name": "Soil_Dirt"
    },
    {
      "x": -21,
      "y": 2,
      "z": -8,
      "name": "Soil_Dirt"
    },
    {
      "x": -21,
      "y": 3,
      "z": -8,
      "name": "Soil_Grass"
    },
    {
      "x": -21,
      "y": 4,
      "z": -8,
      "name": "Plant_Bush",
      "support": 15
    },
    {
      "x": -21,
      "y": 5,
      "z": -8,
      "name": "Plant_Bush",
      "support": 15
    },
    {
      "x": -21,
      "y": 0,
      "z": -7,
      "name": "Rock_Stone"
    },
    {
      "x": -21,
      "y": 1,
      "z": -7,
      "name": "Soil_Dirt"
    },
    {
      "x": -21,
      "y": 2,
      "z": -7,
      "name": "Soil_Dirt"
    },
    {
      "x": -21,
      "y": 3,
      "z": -7,
      "name": "Soil_Grass"
    },
    {
      "x": -21,
      "y": 4,
      "z": -7,
      "name": "Plant_Grass_Sharp",
      "support": 15
    },
    {
      "x": -21,
      "y": 0,
      "z": -6,
      "name": "Rock_Stone"
    },
    {
      "x": -21,
      "y": 1,
      "z": -6,
      "name": "Soil_Dirt"
    },
    {
      "x": -21,
      "y": 2,
      "z": -6,
      "name": "Soil_Dirt"
    },
    {
      "x": -21,
      "y": 3,
      "z": -6,
      "name": "Soil_Grass"
    },
    {
      "x": -21,
      "y": 0,
      "z": -5,
      "name": "Rock_Stone"
    },
    {
      "x": -21,
      "y": 1,
      "z": -5,
      "name": "Soil_Dirt"
    },
    {
      "x": -21,
      "y": 2,
      "z": -5,
      "name": "Soil_Dirt"
    },
    {
      "x": -21,
      "y": 3,
      "z": -5,
      "name": "Soil_Grass"
    },
    {
      "x": -21,
      "y": 0,
      "z": -4,
      "name": "Soil_Dirt"
    },
    {
      "x": -21,
      "y": 1,
      "z": -4,
      "name": "Soil_Dirt"
    },
    {
      "x": -21,
      "y": 2,
      "z": -4,
      "name": "Soil_Grass"
    },
    {
      "x": -21,
      "y": 3,
      "z": -4,
      "name": "Soil_Grass"
    },
    {
      "x": -21,
      "y": 0,
      "z": -3,
      "name": "Rock_Stone"
    },
    {
      "x": -21,
      "y": 1,
      "z": -3,
      "name": "Soil_Dirt"
    },
    {
      "x": -21,
      "y": 2,
      "z": -3,
      "name": "Soil_Dirt"
    },
    {
      "x": -21,
      "y": 3,
      "z": -3,
      "name": "Soil_Grass"
    },
    {
      "x": -21,
      "y": 0,
      "z": -2,
      "name": "Rock_Stone"
    },
    {
      "x": -21,
      "y": 1,
      "z": -2,
      "name": "Soil_Dirt"
    },
    {
      "x": -21,
      "y": 2,
      "z": -2,
      "name": "Soil_Dirt"
    },
    {
      "x": -21,
      "y": 3,
      "z": -2,
      "name": "Soil_Grass"
    },
    {
      "x": -21,
      "y": 4,
      "z": -2,
      "name": "Plant_Grass_Sharp",
      "support": 15
    },
    {
      "x": -21,
      "y": 0,
      "z": -1,
      "name": "Rock_Stone"
    },
    {
      "x": -21,
      "y": 1,
      "z": -1,
      "name": "Rock_Stone"
    },
    {
      "x": -21,
      "y": 2,
      "z": -1,
      "name": "Soil_Dirt"
    },
    {
      "x": -21,
      "y": 3,
      "z": -1,
      "name": "Soil_Dirt"
    },
    {
      "x": -21,
      "y": 4,
      "z": -1,
      "name": "Soil_Grass"
    },
    {
      "x": -21,
      "y": 5,
      "z": -1,
      "name": "Plant_Grass_Sharp",
      "support": 15
    },
    {
      "x": -21,
      "y": 0,
      "z": 0,
      "name": "Rock_Stone"
    },
    {
      "x": -21,
      "y": 1,
      "z": 0,
      "name": "Rock_Stone"
    },
    {
      "x": -21,
      "y": 2,
      "z": 0,
      "name": "Soil_Dirt"
    },
    {
      "x": -21,
      "y": 3,
      "z": 0,
      "name": "Soil_Dirt"
    },
    {
      "x": -21,
      "y": 4,
      "z": 0,
      "name": "Soil_Grass"
    },
    {
      "x": -21,
      "y": 0,
      "z": 1,
      "name": "Rock_Stone"
    },
    {
      "x": -21,
      "y": 1,
      "z": 1,
      "name": "Rock_Stone"
    },
    {
      "x": -21,
      "y": 2,
      "z": 1,
      "name": "Soil_Dirt"
    },
    {
      "x": -21,
      "y": 3,
      "z": 1,
      "name": "Soil_Dirt"
    },
    {
      "x": -21,
      "y": 4,
      "z": 1,
      "name": "Soil_Grass"
    },
    {
      "x": -21,
      "y": 5,
      "z": 1,
      "name": "Plant_Grass_Sharp",
      "support": 15
    },
    {
      "x": -21,
      "y": 0,
      "z": 2,
      "name": "Rock_Stone"
    },
    {
      "x": -21,
      "y": 1,
      "z": 2,
      "name": "Rock_Stone"
    },
    {
      "x": -21,
      "y": 2,
      "z": 2,
      "name": "Soil_Dirt"
    },
    {
      "x": -21,
      "y": 3,
      "z": 2,
      "name": "Soil_Dirt"
    },
    {
      "x": -21,
      "y": 4,
      "z": 2,
      "name": "Soil_Grass"
    },
    {
      "x": -21,
      "y": 0,
      "z": 3,
      "name": "Rock_Stone"
    },
    {
      "x": -21,
      "y": 1,
      "z": 3,
      "name": "Rock_Stone"
    },
    {
      "x": -21,
      "y": 2,
      "z": 3,
      "name": "Soil_Dirt"
    },
    {
      "x": -21,
      "y": 3,
      "z": 3,
      "name": "Soil_Dirt"
    },
    {
      "x": -21,
      "y": 4,
      "z": 3,
      "name": "Soil_Grass"
    },
    {
      "x": -21,
      "y": 0,
      "z": 4,
      "name": "Rock_Stone"
    },
    {
      "x": -21,
      "y": 1,
      "z": 4,
      "name": "Soil_Dirt"
    },
    {
      "x": -21,
      "y": 2,
      "z": 4,
      "name": "Soil_Dirt"
    },
    {
      "x": -21,
      "y": 3,
      "z": 4,
      "name": "Soil_Grass"
    },
    {
      "x": -21,
      "y": 0,
      "z": 5,
      "name": "Rock_Stone"
    },
    {
      "x": -21,
      "y": 1,
      "z": 5,
      "name": "Soil_Dirt"
    },
    {
      "x": -21,
      "y": 2,
      "z": 5,
      "name": "Soil_Dirt"
    },
    {
      "x": -21,
      "y": 3,
      "z": 5,
      "name": "Soil_Grass"
    },
    {
      "x": -21,
      "y": 0,
      "z": 6,
      "name": "Soil_Dirt"
    },
    {
      "x": -21,
      "y": 1,
      "z": 6,
      "name": "Soil_Dirt"
    },
    {
      "x": -21,
      "y": 2,
      "z": 6,
      "name": "Soil_Grass"
    },
    {
      "x": -21,
      "y": 3,
      "z": 6,
      "name": "Plant_Grass_Sharp",
      "support": 15
    },
    {
      "x": -21,
      "y": 0,
      "z": 7,
      "name": "Soil_Dirt"
    },
    {
      "x": -21,
      "y": 1,
      "z": 7,
      "name": "Soil_Grass"
    },
    {
      "x": -21,
      "y": 2,
      "z": 7,
      "name": "Plant_Grass_Sharp",
      "support": 15
    },
    {
      "x": -21,
      "y": 0,
      "z": 8,
      "name": "Soil_Dirt"
    },
    {
      "x": -21,
      "y": 1,
      "z": 8,
      "name": "Soil_Grass"
    },
    {
      "x": -21,
      "y": 0,
      "z": 9,
      "name": "Soil_Grass"
    },
    {
      "x": -21,
      "y": 0,
      "z": 10,
      "name": "Soil_Grass"
    },
    {
      "x": -21,
      "y": 0,
      "z": 11,
      "name": "Soil_Grass"
    },
    {
      "x": -21,
      "y": 0,
      "z": 12,
      "name": "Soil_Grass"
    },
    {
      "x": -21,
      "y": 0,
      "z": 13,
      "name": "Soil_Grass"
    },
    {
      "x": -21,
      "y": 0,
      "z": 14,
      "name": "Soil_Grass"
    },
    {
      "x": -21,
      "y": 0,
      "z": 15,
      "name": "Soil_Grass"
    },
    {
      "x": -21,
      "y": 0,
      "z": 16,
      "name": "Soil_Grass"
    },
    {
      "x": -21,
      "y": 0,
      "z": 17,
      "name": "Soil_Grass"
    },
    {
      "x": -21,
      "y": 0,
      "z": 18,
      "name": "Soil_Grass"
    },
    {
      "x": -21,
      "y": 0,
      "z": 19,
      "name": "Soil_Grass"
    },
    {
      "x": -21,
      "y": 0,
      "z": 20,
      "name": "Soil_Grass"
    },
    {
      "x": -20,
      "y": 0,
      "z": -20,
      "name": "Soil_Grass"
    },
    {
      "x": -20,
      "y": 0,
      "z": -19,
      "name": "Soil_Dirt"
    },
    {
      "x": -20,
      "y": 1,
      "z": -19,
      "name": "Soil_Grass"
    },
    {
      "x": -20,
      "y": 0,
      "z": -18,
      "name": "Soil_Dirt"
    },
    {
      "x": -20,
      "y": 1,
      "z": -18,
      "name": "Soil_Grass"
    },
    {
      "x": -20,
      "y": 0,
      "z": -17,
      "name": "Soil_Dirt"
    },
    {
      "x": -20,
      "y": 1,
      "z": -17,
      "name": "Soil_Dirt"
    },
    {
      "x": -20,
      "y": 2,
      "z": -17,
      "name": "Soil_Grass"
    },
    {
      "x": -20,
      "y": 0,
      "z": -16,
      "name": "Soil_Dirt"
    },
    {
      "x": -20,
      "y": 1,
      "z": -16,
      "name": "Soil_Dirt"
    },
    {
      "x": -20,
      "y": 2,
      "z": -16,
      "name": "Soil_Grass"
    },
    {
      "x": -20,
      "y": 0,
      "z": -15,
      "name": "Rock_Stone"
    },
    {
      "x": -20,
      "y": 1,
      "z": -15,
      "name": "Soil_Dirt"
    },
    {
      "x": -20,
      "y": 2,
      "z": -15,
      "name": "Soil_Dirt"
    },
    {
      "x": -20,
      "y": 3,
      "z": -15,
      "name": "Soil_Grass"
    },
    {
      "x": -20,
      "y": 4,
      "z": -15,
      "name": "Plant_Grass_Sharp",
      "support": 15
    },
    {
      "x": -20,
      "y": 0,
      "z": -14,
      "name": "Rock_Stone"
    },
    {
      "x": -20,
      "y": 1,
      "z": -14,
      "name": "Soil_Dirt"
    },
    {
      "x": -20,
      "y": 2,
      "z": -14,
      "name": "Soil_Dirt"
    },
    {
      "x": -20,
      "y": 3,
      "z": -14,
      "name": "Soil_Grass"
    },
    {
      "x": -20,
      "y": 0,
      "z": -13,
      "name": "Rock_Stone"
    },
    {
      "x": -20,
      "y": 1,
      "z": -13,
      "name": "Soil_Dirt"
    },
    {
      "x": -20,
      "y": 2,
      "z": -13,
      "name": "Soil_Dirt"
    },
    {
      "x": -20,
      "y": 3,
      "z": -13,
      "name": "Soil_Grass"
    },
    {
      "x": -20,
      "y": 4,
      "z": -13,
      "name": "Plant_Flower_Bushy_Green"
    },
    {
      "x": -20,
      "y": 0,
      "z": -12,
      "name": "Rock_Stone"
    },
    {
      "x": -20,
      "y": 1,
      "z": -12,
      "name": "Soil_Dirt"
    },
    {
      "x": -20,
      "y": 2,
      "z": -12,
      "name": "Soil_Dirt"
    },
    {
      "x": -20,
      "y": 3,
      "z": -12,
      "name": "Soil_Grass"
    },
    {
      "x": -20,
      "y": 0,
      "z": -11,
      "name": "Rock_Stone"
    },
    {
      "x": -20,
      "y": 1,
      "z": -11,
      "name": "Soil_Dirt"
    },
    {
      "x": -20,
      "y": 2,
      "z": -11,
      "name": "Soil_Dirt"
    },
    {
      "x": -20,
      "y": 3,
      "z": -11,
      "name": "Soil_Grass"
    },
    {
      "x": -20,
      "y": 0,
      "z": -10,
      "name": "Rock_Stone"
    },
    {
      "x": -20,
      "y": 1,
      "z": -10,
      "name": "Soil_Dirt"
    },
    {
      "x": -20,
      "y": 2,
      "z": -10,
      "name": "Soil_Dirt"
    },
    {
      "x": -20,
      "y": 3,
      "z": -10,
      "name": "Soil_Grass"
    },
    {
      "x": -20,
      "y": 4,
      "z": -10,
      "name": "Plant_Grass_Sharp",
      "support": 15
    },
    {
      "x": -20,
      "y": 0,
      "z": -9,
      "name": "Rock_Stone"
    },
    {
      "x": -20,
      "y": 1,
      "z": -9,
      "name": "Soil_Dirt"
    },
    {
      "x": -20,
      "y": 2,
      "z": -9,
      "name": "Soil_Dirt"
    },
    {
      "x": -20,
      "y": 3,
      "z": -9,
      "name": "Soil_Grass"
    },
    {
      "x": -20,
      "y": 4,
      "z": -9,
      "name": "Plant_Grass_Sharp",
      "support": 15
    },
    {
      "x": -20,
      "y": 0,
      "z": -8,
      "name": "Rock_Stone"
    },
    {
      "x": -20,
      "y": 1,
      "z": -8,
      "name": "Soil_Dirt"
    },
    {
      "x": -20,
      "y": 2,
      "z": -8,
      "name": "Soil_Dirt"
    },
    {
      "x": -20,
      "y": 3,
      "z": -8,
      "name": "Soil_Grass"
    },
    {
      "x": -20,
      "y": 0,
      "z": -7,
      "name": "Rock_Stone"
    },
    {
      "x": -20,
      "y": 1,
      "z": -7,
      "name": "Soil_Dirt"
    },
    {
      "x": -20,
      "y": 2,
      "z": -7,
      "name": "Soil_Dirt"
    },
    {
      "x": -20,
      "y": 3,
      "z": -7,
      "name": "Soil_Grass"
    },
    {
      "x": -20,
      "y": 0,
      "z": -6,
      "name": "Rock_Stone"
    },
    {
      "x": -20,
      "y": 1,
      "z": -6,
      "name": "Soil_Dirt"
    },
    {
      "x": -20,
      "y": 2,
      "z": -6,
      "name": "Soil_Dirt"
    },
    {
      "x": -20,
      "y": 3,
      "z": -6,
      "name": "Soil_Grass"
    },
    {
      "x": -20,
      "y": 0,
      "z": -5,
      "name": "Rock_Stone"
    },
    {
      "x": -20,
      "y": 1,
      "z": -5,
      "name": "Rock_Stone"
    },
    {
      "x": -20,
      "y": 2,
      "z": -5,
      "name": "Soil_Dirt"
    },
    {
      "x": -20,
      "y": 3,
      "z": -5,
      "name": "Soil_Dirt"
    },
    {
      "x": -20,
      "y": 4,
      "z": -5,
      "name": "Soil_Grass"
    },
    {
      "x": -20,
      "y": 0,
      "z": -4,
      "name": "Rock_Stone"
    },
    {
      "x": -20,
      "y": 1,
      "z": -4,
      "name": "Rock_Stone"
    },
    {
      "x": -20,
      "y": 2,
      "z": -4,
      "name": "Soil_Dirt"
    },
    {
      "x": -20,
      "y": 3,
      "z": -4,
      "name": "Soil_Dirt"
    },
    {
      "x": -20,
      "y": 4,
      "z": -4,
      "name": "Soil_Grass"
    },
    {
      "x": -20,
      "y": 0,
      "z": -3,
      "name": "Rock_Stone"
    },
    {
      "x": -20,
      "y": 1,
      "z": -3,
      "name": "Rock_Stone"
    },
    {
      "x": -20,
      "y": 2,
      "z": -3,
      "name": "Soil_Dirt"
    },
    {
      "x": -20,
      "y": 3,
      "z": -3,
      "name": "Soil_Dirt"
    },
    {
      "x": -20,
      "y": 4,
      "z": -3,
      "name": "Soil_Grass"
    },
    {
      "x": -20,
      "y": 0,
      "z": -2,
      "name": "Rock_Stone"
    },
    {
      "x": -20,
      "y": 1,
      "z": -2,
      "name": "Rock_Stone"
    },
    {
      "x": -20,
      "y": 2,
      "z": -2,
      "name": "Soil_Dirt"
    },
    {
      "x": -20,
      "y": 3,
      "z": -2,
      "name": "Soil_Dirt"
    },
    {
      "x": -20,
      "y": 4,
      "z": -2,
      "name": "Soil_Grass"
    },
    {
      "x": -20,
      "y": 5,
      "z": -2,
      "name": "Plant_Grass_Sharp",
      "support": 15
    },
    {
      "x": -20,
      "y": 0,
      "z": -1,
      "name": "Rock_Stone"
    },
    {
      "x": -20,
      "y": 1,
      "z": -1,
      "name": "Rock_Stone"
    },
    {
      "x": -20,
      "y": 2,
      "z": -1,
      "name": "Soil_Dirt"
    },
    {
      "x": -20,
      "y": 3,
      "z": -1,
      "name": "Soil_Dirt"
    },
    {
      "x": -20,
      "y": 4,
      "z": -1,
      "name": "Soil_Grass"
    },
    {
      "x": -20,
      "y": 0,
      "z": 0,
      "name": "Rock_Stone"
    },
    {
      "x": -20,
      "y": 1,
      "z": 0,
      "name": "Rock_Stone"
    },
    {
      "x": -20,
      "y": 2,
      "z": 0,
      "name": "Soil_Dirt"
    },
    {
      "x": -20,
      "y": 3,
      "z": 0,
      "name": "Soil_Dirt"
    },
    {
      "x": -20,
      "y": 4,
      "z": 0,
      "name": "Soil_Grass"
    },
    {
      "x": -20,
      "y": 0,
      "z": 1,
      "name": "Rock_Stone"
    },
    {
      "x": -20,
      "y": 1,
      "z": 1,
      "name": "Rock_Stone"
    },
    {
      "x": -20,
      "y": 2,
      "z": 1,
      "name": "Soil_Dirt"
    },
    {
      "x": -20,
      "y": 3,
      "z": 1,
      "name": "Soil_Dirt"
    },
    {
      "x": -20,
      "y": 4,
      "z": 1,
      "name": "Soil_Grass"
    },
    {
      "x": -20,
      "y": 0,
      "z": 2,
      "name": "Rock_Stone"
    },
    {
      "x": -20,
      "y": 1,
      "z": 2,
      "name": "Rock_Stone"
    },
    {
      "x": -20,
      "y": 2,
      "z": 2,
      "name": "Soil_Dirt"
    },
    {
      "x": -20,
      "y": 3,
      "z": 2,
      "name": "Soil_Dirt"
    },
    {
      "x": -20,
      "y": 4,
      "z": 2,
      "name": "Soil_Grass"
    },
    {
      "x": -20,
      "y": 5,
      "z": 2,
      "name": "Plant_Bush",
      "support": 15
    },
    {
      "x": -20,
      "y": 0,
      "z": 3,
      "name": "Rock_Stone"
    },
    {
      "x": -20,
      "y": 1,
      "z": 3,
      "name": "Rock_Stone"
    },
    {
      "x": -20,
      "y": 2,
      "z": 3,
      "name": "Soil_Dirt"
    },
    {
      "x": -20,
      "y": 3,
      "z": 3,
      "name": "Soil_Dirt"
    },
    {
      "x": -20,
      "y": 4,
      "z": 3,
      "name": "Soil_Grass"
    },
    {
      "x": -20,
      "y": 0,
      "z": 4,
      "name": "Rock_Stone"
    },
    {
      "x": -20,
      "y": 1,
      "z": 4,
      "name": "Rock_Stone"
    },
    {
      "x": -20,
      "y": 2,
      "z": 4,
      "name": "Soil_Dirt"
    },
    {
      "x": -20,
      "y": 3,
      "z": 4,
      "name": "Soil_Dirt"
    },
    {
      "x": -20,
      "y": 4,
      "z": 4,
      "name": "Soil_Grass"
    },
    {
      "x": -20,
      "y": 0,
      "z": 5,
      "name": "Rock_Stone"
    },
    {
      "x": -20,
      "y": 1,
      "z": 5,
      "name": "Soil_Dirt"
    },
    {
      "x": -20,
      "y": 2,
      "z": 5,
      "name": "Soil_Dirt"
    },
    {
      "x": -20,
      "y": 3,
      "z": 5,
      "name": "Soil_Grass"
    },
    {
      "x": -20,
      "y": 4,
      "z": 5,
      "name": "Plant_Grass_Sharp",
      "support": 15
    },
    {
      "x": -20,
      "y": 0,
      "z": 6,
      "name": "Rock_Stone"
    },
    {
      "x": -20,
      "y": 1,
      "z": 6,
      "name": "Soil_Dirt"
    },
    {
      "x": -20,
      "y": 2,
      "z": 6,
      "name": "Soil_Dirt"
    },
    {
      "x": -20,
      "y": 3,
      "z": 6,
      "name": "Soil_Grass"
    },
    {
      "x": -20,
      "y": 0,
      "z": 7,
      "name": "Soil_Dirt"
    },
    {
      "x": -20,
      "y": 1,
      "z": 7,
      "name": "Soil_Dirt"
    },
    {
      "x": -20,
      "y": 2,
      "z": 7,
      "name": "Soil_Grass"
    },
    {
      "x": -20,
      "y": 3,
      "z": 7,
      "name": "Plant_Grass_Sharp",
      "support": 15
    },
    {
      "x": -20,
      "y": 0,
      "z": 8,
      "name": "Soil_Dirt"
    },
    {
      "x": -20,
      "y": 1,
      "z": 8,
      "name": "Soil_Dirt"
    },
    {
      "x": -20,
      "y": 2,
      "z": 8,
      "name": "Soil_Grass"
    },
    {
      "x": -20,
      "y": 0,
      "z": 9,
      "name": "Soil_Dirt"
    },
    {
      "x": -20,
      "y": 1,
      "z": 9,
      "name": "Soil_Grass"
    },
    {
      "x": -20,
      "y": 0,
      "z": 10,
      "name": "Soil_Grass"
    },
    {
      "x": -20,
      "y": 0,
      "z": 11,
      "name": "Soil_Grass"
    },
    {
      "x": -20,
      "y": 0,
      "z": 12,
      "name": "Soil_Grass"
    },
    {
      "x": -20,
      "y": 0,
      "z": 13,
      "name": "Soil_Grass"
    },
    {
      "x": -20,
      "y": 0,
      "z": 14,
      "name": "Soil_Grass"
    },
    {
      "x": -20,
      "y": 0,
      "z": 15,
      "name": "Soil_Grass"
    },
    {
      "x": -20,
      "y": 0,
      "z": 16,
      "name": "Soil_Grass"
    },
    {
      "x": -20,
      "y": 0,
      "z": 17,
      "name": "Soil_Grass"
    },
    {
      "x": -20,
      "y": 0,
      "z": 18,
      "name": "Soil_Grass"
    },
    {
      "x": -20,
      "y": 0,
      "z": 19,
      "name": "Soil_Grass"
    },
    {
      "x": -20,
      "y": 0,
      "z": 20,
      "name": "Soil_Grass"
    },
    {
      "x": -19,
      "y": 0,
      "z": -20,
      "name": "Soil_Grass"
    },
    {
      "x": -19,
      "y": 0,
      "z": -19,
      "name": "Soil_Dirt"
    },
    {
      "x": -19,
      "y": 1,
      "z": -19,
      "name": "Soil_Grass"
    },
    {
      "x": -19,
      "y": 0,
      "z": -18,
      "name": "Soil_Dirt"
    },
    {
      "x": -19,
      "y": 1,
      "z": -18,
      "name": "Soil_Dirt"
    },
    {
      "x": -19,
      "y": 2,
      "z": -18,
      "name": "Soil_Grass"
    },
    {
      "x": -19,
      "y": 0,
      "z": -17,
      "name": "Soil_Dirt"
    },
    {
      "x": -19,
      "y": 1,
      "z": -17,
      "name": "Soil_Dirt"
    },
    {
      "x": -19,
      "y": 2,
      "z": -17,
      "name": "Soil_Grass"
    },
    {
      "x": -19,
      "y": 0,
      "z": -16,
      "name": "Rock_Stone"
    },
    {
      "x": -19,
      "y": 1,
      "z": -16,
      "name": "Soil_Dirt"
    },
    {
      "x": -19,
      "y": 2,
      "z": -16,
      "name": "Soil_Dirt"
    },
    {
      "x": -19,
      "y": 3,
      "z": -16,
      "name": "Soil_Grass"
    },
    {
      "x": -19,
      "y": 0,
      "z": -15,
      "name": "Rock_Stone"
    },
    {
      "x": -19,
      "y": 1,
      "z": -15,
      "name": "Soil_Dirt"
    },
    {
      "x": -19,
      "y": 2,
      "z": -15,
      "name": "Soil_Dirt"
    },
    {
      "x": -19,
      "y": 3,
      "z": -15,
      "name": "Soil_Grass"
    },
    {
      "x": -19,
      "y": 0,
      "z": -14,
      "name": "Rock_Stone"
    },
    {
      "x": -19,
      "y": 1,
      "z": -14,
      "name": "Rock_Stone"
    },
    {
      "x": -19,
      "y": 2,
      "z": -14,
      "name": "Soil_Dirt"
    },
    {
      "x": -19,
      "y": 3,
      "z": -14,
      "name": "Soil_Dirt"
    },
    {
      "x": -19,
      "y": 4,
      "z": -14,
      "name": "Soil_Grass"
    },
    {
      "x": -19,
      "y": 5,
      "z": -14,
      "name": "Plant_Grass_Sharp",
      "support": 15
    },
    {
      "x": -19,
      "y": 0,
      "z": -13,
      "name": "Rock_Stone"
    },
    {
      "x": -19,
      "y": 1,
      "z": -13,
      "name": "Rock_Stone"
    },
    {
      "x": -19,
      "y": 2,
      "z": -13,
      "name": "Soil_Dirt"
    },
    {
      "x": -19,
      "y": 3,
      "z": -13,
      "name": "Soil_Dirt"
    },
    {
      "x": -19,
      "y": 4,
      "z": -13,
      "name": "Soil_Grass"
    },
    {
      "x": -19,
      "y": 0,
      "z": -12,
      "name": "Rock_Stone"
    },
    {
      "x": -19,
      "y": 1,
      "z": -12,
      "name": "Rock_Stone"
    },
    {
      "x": -19,
      "y": 2,
      "z": -12,
      "name": "Soil_Dirt"
    },
    {
      "x": -19,
      "y": 3,
      "z": -12,
      "name": "Soil_Dirt"
    },
    {
      "x": -19,
      "y": 4,
      "z": -12,
      "name": "Soil_Grass"
    },
    {
      "x": -19,
      "y": 0,
      "z": -11,
      "name": "Rock_Stone"
    },
    {
      "x": -19,
      "y": 1,
      "z": -11,
      "name": "Soil_Dirt"
    },
    {
      "x": -19,
      "y": 2,
      "z": -11,
      "name": "Soil_Dirt"
    },
    {
      "x": -19,
      "y": 3,
      "z": -11,
      "name": "Soil_Grass"
    },
    {
      "x": -19,
      "y": 0,
      "z": -10,
      "name": "Rock_Stone"
    },
    {
      "x": -19,
      "y": 1,
      "z": -10,
      "name": "Soil_Dirt"
    },
    {
      "x": -19,
      "y": 2,
      "z": -10,
      "name": "Soil_Dirt"
    },
    {
      "x": -19,
      "y": 3,
      "z": -10,
      "name": "Soil_Grass"
    },
    {
      "x": -19,
      "y": 0,
      "z": -9,
      "name": "Soil_Dirt"
    },
    {
      "x": -19,
      "y": 1,
      "z": -9,
      "name": "Soil_Dirt"
    },
    {
      "x": -19,
      "y": 2,
      "z": -9,
      "name": "Soil_Grass"
    },
    {
      "x": -19,
      "y": 3,
      "z": -9,
      "name": "Soil_Grass"
    },
    {
      "x": -19,
      "y": 0,
      "z": -8,
      "name": "Rock_Stone"
    },
    {
      "x": -19,
      "y": 1,
      "z": -8,
      "name": "Soil_Dirt"
    },
    {
      "x": -19,
      "y": 2,
      "z": -8,
      "name": "Soil_Dirt"
    },
    {
      "x": -19,
      "y": 3,
      "z": -8,
      "name": "Soil_Grass"
    },
    {
      "x": -19,
      "y": 0,
      "z": -7,
      "name": "Rock_Stone"
    },
    {
      "x": -19,
      "y": 1,
      "z": -7,
      "name": "Soil_Dirt"
    },
    {
      "x": -19,
      "y": 2,
      "z": -7,
      "name": "Soil_Dirt"
    },
    {
      "x": -19,
      "y": 3,
      "z": -7,
      "name": "Soil_Grass"
    },
    {
      "x": -19,
      "y": 4,
      "z": -7,
      "name": "Plant_Bush_Green",
      "support": 15
    },
    {
      "x": -19,
      "y": 5,
      "z": -7,
      "name": "Plant_Bush_Green",
      "filler": 1024
    },
    {
      "x": -19,
      "y": 0,
      "z": -6,
      "name": "Rock_Stone"
    },
    {
      "x": -19,
      "y": 1,
      "z": -6,
      "name": "Rock_Stone"
    },
    {
      "x": -19,
      "y": 2,
      "z": -6,
      "name": "Soil_Dirt"
    },
    {
      "x": -19,
      "y": 3,
      "z": -6,
      "name": "Soil_Dirt"
    },
    {
      "x": -19,
      "y": 4,
      "z": -6,
      "name": "Soil_Grass"
    },
    {
      "x": -19,
      "y": 0,
      "z": -5,
      "name": "Rock_Stone"
    },
    {
      "x": -19,
      "y": 1,
      "z": -5,
      "name": "Rock_Stone"
    },
    {
      "x": -19,
      "y": 2,
      "z": -5,
      "name": "Soil_Dirt"
    },
    {
      "x": -19,
      "y": 3,
      "z": -5,
      "name": "Soil_Dirt"
    },
    {
      "x": -19,
      "y": 4,
      "z": -5,
      "name": "Soil_Grass"
    },
    {
      "x": -19,
      "y": 5,
      "z": -5,
      "name": "Plant_Flower_Bushy_Green"
    },
    {
      "x": -19,
      "y": 0,
      "z": -4,
      "name": "Rock_Stone"
    },
    {
      "x": -19,
      "y": 1,
      "z": -4,
      "name": "Soil_Dirt"
    },
    {
      "x": -19,
      "y": 2,
      "z": -4,
      "name": "Soil_Dirt"
    },
    {
      "x": -19,
      "y": 3,
      "z": -4,
      "name": "Soil_Grass"
    },
    {
      "x": -19,
      "y": 4,
      "z": -4,
      "name": "Soil_Grass"
    },
    {
      "x": -19,
      "y": 5,
      "z": -4,
      "name": "Soil_Grass"
    },
    {
      "x": -19,
      "y": 0,
      "z": -3,
      "name": "Rock_Stone"
    },
    {
      "x": -19,
      "y": 1,
      "z": -3,
      "name": "Rock_Stone"
    },
    {
      "x": -19,
      "y": 2,
      "z": -3,
      "name": "Soil_Dirt"
    },
    {
      "x": -19,
      "y": 3,
      "z": -3,
      "name": "Soil_Dirt"
    },
    {
      "x": -19,
      "y": 4,
      "z": -3,
      "name": "Soil_Grass"
    },
    {
      "x": -19,
      "y": 5,
      "z": -3,
      "name": "Plant_Grass_Sharp",
      "support": 15
    },
    {
      "x": -19,
      "y": 0,
      "z": -2,
      "name": "Rock_Stone"
    },
    {
      "x": -19,
      "y": 1,
      "z": -2,
      "name": "Rock_Stone"
    },
    {
      "x": -19,
      "y": 2,
      "z": -2,
      "name": "Soil_Dirt"
    },
    {
      "x": -19,
      "y": 3,
      "z": -2,
      "name": "Soil_Dirt"
    },
    {
      "x": -19,
      "y": 4,
      "z": -2,
      "name": "Soil_Grass"
    },
    {
      "x": -19,
      "y": 5,
      "z": -2,
      "name": "Plant_Flower_Bushy_Green"
    },
    {
      "x": -19,
      "y": 0,
      "z": -1,
      "name": "Rock_Stone"
    },
    {
      "x": -19,
      "y": 1,
      "z": -1,
      "name": "Rock_Stone"
    },
    {
      "x": -19,
      "y": 2,
      "z": -1,
      "name": "Soil_Dirt"
    },
    {
      "x": -19,
      "y": 3,
      "z": -1,
      "name": "Soil_Dirt"
    },
    {
      "x": -19,
      "y": 4,
      "z": -1,
      "name": "Soil_Grass"
    },
    {
      "x": -19,
      "y": 5,
      "z": -1,
      "name": "Plant_Grass_Sharp",
      "support": 15
    },
    {
      "x": -19,
      "y": 0,
      "z": 0,
      "name": "Rock_Stone"
    },
    {
      "x": -19,
      "y": 1,
      "z": 0,
      "name": "Rock_Stone"
    },
    {
      "x": -19,
      "y": 2,
      "z": 0,
      "name": "Rock_Stone"
    },
    {
      "x": -19,
      "y": 3,
      "z": 0,
      "name": "Soil_Dirt"
    },
    {
      "x": -19,
      "y": 4,
      "z": 0,
      "name": "Soil_Dirt"
    },
    {
      "x": -19,
      "y": 5,
      "z": 0,
      "name": "Soil_Grass"
    },
    {
      "x": -19,
      "y": 6,
      "z": 0,
      "name": "Plant_Grass_Sharp",
      "support": 15
    },
    {
      "x": -19,
      "y": 0,
      "z": 1,
      "name": "Rock_Stone"
    },
    {
      "x": -19,
      "y": 1,
      "z": 1,
      "name": "Rock_Stone"
    },
    {
      "x": -19,
      "y": 2,
      "z": 1,
      "name": "Rock_Stone"
    },
    {
      "x": -19,
      "y": 3,
      "z": 1,
      "name": "Soil_Dirt"
    },
    {
      "x": -19,
      "y": 4,
      "z": 1,
      "name": "Soil_Dirt"
    },
    {
      "x": -19,
      "y": 5,
      "z": 1,
      "name": "Soil_Grass"
    },
    {
      "x": -19,
      "y": 0,
      "z": 2,
      "name": "Rock_Stone"
    },
    {
      "x": -19,
      "y": 1,
      "z": 2,
      "name": "Rock_Stone"
    },
    {
      "x": -19,
      "y": 2,
      "z": 2,
      "name": "Rock_Stone"
    },
    {
      "x": -19,
      "y": 3,
      "z": 2,
      "name": "Soil_Dirt"
    },
    {
      "x": -19,
      "y": 4,
      "z": 2,
      "name": "Soil_Dirt"
    },
    {
      "x": -19,
      "y": 5,
      "z": 2,
      "name": "Soil_Grass"
    },
    {
      "x": -19,
      "y": 0,
      "z": 3,
      "name": "Rock_Stone"
    },
    {
      "x": -19,
      "y": 1,
      "z": 3,
      "name": "Rock_Stone"
    },
    {
      "x": -19,
      "y": 2,
      "z": 3,
      "name": "Soil_Dirt"
    },
    {
      "x": -19,
      "y": 3,
      "z": 3,
      "name": "Soil_Dirt"
    },
    {
      "x": -19,
      "y": 4,
      "z": 3,
      "name": "Soil_Grass"
    },
    {
      "x": -19,
      "y": 0,
      "z": 4,
      "name": "Rock_Stone"
    },
    {
      "x": -19,
      "y": 1,
      "z": 4,
      "name": "Rock_Stone"
    },
    {
      "x": -19,
      "y": 2,
      "z": 4,
      "name": "Soil_Dirt"
    },
    {
      "x": -19,
      "y": 3,
      "z": 4,
      "name": "Soil_Dirt"
    },
    {
      "x": -19,
      "y": 4,
      "z": 4,
      "name": "Soil_Grass"
    },
    {
      "x": -19,
      "y": 5,
      "z": 4,
      "name": "Plant_Grass_Sharp",
      "support": 15
    },
    {
      "x": -19,
      "y": 0,
      "z": 5,
      "name": "Rock_Stone"
    },
    {
      "x": -19,
      "y": 1,
      "z": 5,
      "name": "Rock_Stone"
    },
    {
      "x": -19,
      "y": 2,
      "z": 5,
      "name": "Soil_Dirt"
    },
    {
      "x": -19,
      "y": 3,
      "z": 5,
      "name": "Soil_Dirt"
    },
    {
      "x": -19,
      "y": 4,
      "z": 5,
      "name": "Soil_Grass"
    },
    {
      "x": -19,
      "y": 0,
      "z": 6,
      "name": "Rock_Stone"
    },
    {
      "x": -19,
      "y": 1,
      "z": 6,
      "name": "Soil_Dirt"
    },
    {
      "x": -19,
      "y": 2,
      "z": 6,
      "name": "Soil_Dirt"
    },
    {
      "x": -19,
      "y": 3,
      "z": 6,
      "name": "Soil_Grass"
    },
    {
      "x": -19,
      "y": 0,
      "z": 7,
      "name": "Rock_Stone"
    },
    {
      "x": -19,
      "y": 1,
      "z": 7,
      "name": "Soil_Dirt"
    },
    {
      "x": -19,
      "y": 2,
      "z": 7,
      "name": "Soil_Dirt"
    },
    {
      "x": -19,
      "y": 3,
      "z": 7,
      "name": "Soil_Grass"
    },
    {
      "x": -19,
      "y": 4,
      "z": 7,
      "name": "Plant_Grass_Sharp",
      "support": 15
    },
    {
      "x": -19,
      "y": 0,
      "z": 8,
      "name": "Soil_Dirt"
    },
    {
      "x": -19,
      "y": 1,
      "z": 8,
      "name": "Soil_Dirt"
    },
    {
      "x": -19,
      "y": 2,
      "z": 8,
      "name": "Soil_Grass"
    },
    {
      "x": -19,
      "y": 3,
      "z": 8,
      "name": "Plant_Bush",
      "support": 15
    },
    {
      "x": -19,
      "y": 0,
      "z": 9,
      "name": "Soil_Dirt"
    },
    {
      "x": -19,
      "y": 1,
      "z": 9,
      "name": "Soil_Dirt"
    },
    {
      "x": -19,
      "y": 2,
      "z": 9,
      "name": "Soil_Grass"
    },
    {
      "x": -19,
      "y": 3,
      "z": 9,
      "name": "Plant_Grass_Sharp",
      "support": 15
    },
    {
      "x": -19,
      "y": 0,
      "z": 10,
      "name": "Soil_Dirt"
    },
    {
      "x": -19,
      "y": 1,
      "z": 10,
      "name": "Soil_Grass"
    },
    {
      "x": -19,
      "y": 0,
      "z": 11,
      "name": "Soil_Dirt"
    },
    {
      "x": -19,
      "y": 1,
      "z": 11,
      "name": "Soil_Grass"
    },
    {
      "x": -19,
      "y": 0,
      "z": 12,
      "name": "Soil_Grass"
    },
    {
      "x": -19,
      "y": 0,
      "z": 13,
      "name": "Soil_Grass"
    },
    {
      "x": -19,
      "y": 0,
      "z": 14,
      "name": "Soil_Grass"
    },
    {
      "x": -19,
      "y": 0,
      "z": 15,
      "name": "Soil_Grass"
    },
    {
      "x": -19,
      "y": 0,
      "z": 16,
      "name": "Soil_Grass"
    },
    {
      "x": -19,
      "y": 0,
      "z": 17,
      "name": "Soil_Grass"
    },
    {
      "x": -19,
      "y": 0,
      "z": 18,
      "name": "Soil_Grass"
    },
    {
      "x": -19,
      "y": 0,
      "z": 19,
      "name": "Soil_Grass"
    },
    {
      "x": -19,
      "y": 0,
      "z": 20,
      "name": "Soil_Grass"
    },
    {
      "x": -18,
      "y": 0,
      "z": -20,
      "name": "Soil_Grass"
    },
    {
      "x": -18,
      "y": 0,
      "z": -19,
      "name": "Soil_Dirt"
    },
    {
      "x": -18,
      "y": 1,
      "z": -19,
      "name": "Soil_Grass"
    },
    {
      "x": -18,
      "y": 0,
      "z": -18,
      "name": "Soil_Dirt"
    },
    {
      "x": -18,
      "y": 1,
      "z": -18,
      "name": "Soil_Dirt"
    },
    {
      "x": -18,
      "y": 2,
      "z": -18,
      "name": "Soil_Grass"
    },
    {
      "x": -18,
      "y": 3,
      "z": -18,
      "name": "Plant_Grass_Sharp",
      "support": 15
    },
    {
      "x": -18,
      "y": 0,
      "z": -17,
      "name": "Soil_Dirt"
    },
    {
      "x": -18,
      "y": 1,
      "z": -17,
      "name": "Soil_Dirt"
    },
    {
      "x": -18,
      "y": 2,
      "z": -17,
      "name": "Soil_Grass"
    },
    {
      "x": -18,
      "y": 3,
      "z": -17,
      "name": "Plant_Flower_Common_White2"
    },
    {
      "x": -18,
      "y": 0,
      "z": -16,
      "name": "Rock_Stone"
    },
    {
      "x": -18,
      "y": 1,
      "z": -16,
      "name": "Soil_Dirt"
    },
    {
      "x": -18,
      "y": 2,
      "z": -16,
      "name": "Soil_Dirt"
    },
    {
      "x": -18,
      "y": 3,
      "z": -16,
      "name": "Soil_Grass"
    },
    {
      "x": -18,
      "y": 4,
      "z": -16,
      "name": "Plant_Flower_Bushy_Green"
    },
    {
      "x": -18,
      "y": 0,
      "z": -15,
      "name": "Rock_Stone"
    },
    {
      "x": -18,
      "y": 1,
      "z": -15,
      "name": "Soil_Dirt"
    },
    {
      "x": -18,
      "y": 2,
      "z": -15,
      "name": "Soil_Dirt"
    },
    {
      "x": -18,
      "y": 3,
      "z": -15,
      "name": "Soil_Grass"
    },
    {
      "x": -18,
      "y": 0,
      "z": -14,
      "name": "Rock_Stone"
    },
    {
      "x": -18,
      "y": 1,
      "z": -14,
      "name": "Rock_Stone"
    },
    {
      "x": -18,
      "y": 2,
      "z": -14,
      "name": "Soil_Dirt"
    },
    {
      "x": -18,
      "y": 3,
      "z": -14,
      "name": "Soil_Dirt"
    },
    {
      "x": -18,
      "y": 4,
      "z": -14,
      "name": "Soil_Grass"
    },
    {
      "x": -18,
      "y": 0,
      "z": -13,
      "name": "Rock_Stone"
    },
    {
      "x": -18,
      "y": 1,
      "z": -13,
      "name": "Rock_Stone"
    },
    {
      "x": -18,
      "y": 2,
      "z": -13,
      "name": "Soil_Dirt"
    },
    {
      "x": -18,
      "y": 3,
      "z": -13,
      "name": "Soil_Dirt"
    },
    {
      "x": -18,
      "y": 4,
      "z": -13,
      "name": "Soil_Grass"
    },
    {
      "x": -18,
      "y": 0,
      "z": -12,
      "name": "Rock_Stone"
    },
    {
      "x": -18,
      "y": 1,
      "z": -12,
      "name": "Rock_Stone"
    },
    {
      "x": -18,
      "y": 2,
      "z": -12,
      "name": "Soil_Dirt"
    },
    {
      "x": -18,
      "y": 3,
      "z": -12,
      "name": "Soil_Dirt"
    },
    {
      "x": -18,
      "y": 4,
      "z": -12,
      "name": "Soil_Grass"
    },
    {
      "x": -18,
      "y": 5,
      "z": -12,
      "name": "Plant_Bush_Green",
      "support": 15
    },
    {
      "x": -18,
      "y": 6,
      "z": -12,
      "name": "Plant_Bush_Green",
      "filler": 1024
    },
    {
      "x": -18,
      "y": 0,
      "z": -11,
      "name": "Rock_Stone"
    },
    {
      "x": -18,
      "y": 1,
      "z": -11,
      "name": "Rock_Stone"
    },
    {
      "x": -18,
      "y": 2,
      "z": -11,
      "name": "Soil_Dirt"
    },
    {
      "x": -18,
      "y": 3,
      "z": -11,
      "name": "Soil_Dirt"
    },
    {
      "x": -18,
      "y": 4,
      "z": -11,
      "name": "Soil_Grass"
    },
    {
      "x": -18,
      "y": 0,
      "z": -10,
      "name": "Rock_Stone"
    },
    {
      "x": -18,
      "y": 1,
      "z": -10,
      "name": "Soil_Dirt"
    },
    {
      "x": -18,
      "y": 2,
      "z": -10,
      "name": "Soil_Dirt"
    },
    {
      "x": -18,
      "y": 3,
      "z": -10,
      "name": "Soil_Grass"
    },
    {
      "x": -18,
      "y": 0,
      "z": -9,
      "name": "Rock_Stone"
    },
    {
      "x": -18,
      "y": 1,
      "z": -9,
      "name": "Soil_Dirt"
    },
    {
      "x": -18,
      "y": 2,
      "z": -9,
      "name": "Soil_Dirt"
    },
    {
      "x": -18,
      "y": 3,
      "z": -9,
      "name": "Soil_Grass"
    },
    {
      "x": -18,
      "y": 4,
      "z": -9,
      "name": "Plant_Flower_Common_White2"
    },
    {
      "x": -18,
      "y": 0,
      "z": -8,
      "name": "Rock_Stone"
    },
    {
      "x": -18,
      "y": 1,
      "z": -8,
      "name": "Soil_Dirt"
    },
    {
      "x": -18,
      "y": 2,
      "z": -8,
      "name": "Soil_Dirt"
    },
    {
      "x": -18,
      "y": 3,
      "z": -8,
      "name": "Soil_Grass"
    },
    {
      "x": -18,
      "y": 0,
      "z": -7,
      "name": "Rock_Stone"
    },
    {
      "x": -18,
      "y": 1,
      "z": -7,
      "name": "Rock_Stone"
    },
    {
      "x": -18,
      "y": 2,
      "z": -7,
      "name": "Soil_Dirt"
    },
    {
      "x": -18,
      "y": 3,
      "z": -7,
      "name": "Soil_Dirt"
    },
    {
      "x": -18,
      "y": 4,
      "z": -7,
      "name": "Soil_Grass"
    },
    {
      "x": -18,
      "y": 0,
      "z": -6,
      "name": "Rock_Stone"
    },
    {
      "x": -18,
      "y": 1,
      "z": -6,
      "name": "Rock_Stone"
    },
    {
      "x": -18,
      "y": 2,
      "z": -6,
      "name": "Soil_Dirt"
    },
    {
      "x": -18,
      "y": 3,
      "z": -6,
      "name": "Soil_Dirt"
    },
    {
      "x": -18,
      "y": 4,
      "z": -6,
      "name": "Soil_Grass"
    },
    {
      "x": -18,
      "y": 0,
      "z": -5,
      "name": "Rock_Stone"
    },
    {
      "x": -18,
      "y": 1,
      "z": -5,
      "name": "Rock_Stone"
    },
    {
      "x": -18,
      "y": 2,
      "z": -5,
      "name": "Soil_Dirt"
    },
    {
      "x": -18,
      "y": 3,
      "z": -5,
      "name": "Soil_Dirt"
    },
    {
      "x": -18,
      "y": 4,
      "z": -5,
      "name": "Soil_Grass"
    },
    {
      "x": -18,
      "y": 5,
      "z": -5,
      "name": "Plant_Grass_Sharp",
      "support": 15
    },
    {
      "x": -18,
      "y": 0,
      "z": -4,
      "name": "Rock_Stone"
    },
    {
      "x": -18,
      "y": 1,
      "z": -4,
      "name": "Rock_Stone"
    },
    {
      "x": -18,
      "y": 2,
      "z": -4,
      "name": "Rock_Stone"
    },
    {
      "x": -18,
      "y": 3,
      "z": -4,
      "name": "Soil_Dirt"
    },
    {
      "x": -18,
      "y": 4,
      "z": -4,
      "name": "Soil_Dirt"
    },
    {
      "x": -18,
      "y": 5,
      "z": -4,
      "name": "Soil_Grass"
    },
    {
      "x": -18,
      "y": 6,
      "z": -4,
      "name": "Plant_Grass_Dry_Tall",
      "support": 15
    },
    {
      "x": -18,
      "y": 7,
      "z": -4,
      "name": "Plant_Grass_Dry_Tall",
      "filler": 1024
    },
    {
      "x": -18,
      "y": 0,
      "z": -3,
      "name": "Rock_Stone"
    },
    {
      "x": -18,
      "y": 1,
      "z": -3,
      "name": "Rock_Stone"
    },
    {
      "x": -18,
      "y": 2,
      "z": -3,
      "name": "Rock_Stone"
    },
    {
      "x": -18,
      "y": 3,
      "z": -3,
      "name": "Soil_Dirt"
    },
    {
      "x": -18,
      "y": 4,
      "z": -3,
      "name": "Soil_Dirt"
    },
    {
      "x": -18,
      "y": 5,
      "z": -3,
      "name": "Soil_Grass"
    },
    {
      "x": -18,
      "y": 0,
      "z": -2,
      "name": "Rock_Stone"
    },
    {
      "x": -18,
      "y": 1,
      "z": -2,
      "name": "Rock_Stone"
    },
    {
      "x": -18,
      "y": 2,
      "z": -2,
      "name": "Rock_Stone"
    },
    {
      "x": -18,
      "y": 3,
      "z": -2,
      "name": "Soil_Dirt"
    },
    {
      "x": -18,
      "y": 4,
      "z": -2,
      "name": "Soil_Dirt"
    },
    {
      "x": -18,
      "y": 5,
      "z": -2,
      "name": "Soil_Grass"
    },
    {
      "x": -18,
      "y": 0,
      "z": -1,
      "name": "Rock_Stone"
    },
    {
      "x": -18,
      "y": 1,
      "z": -1,
      "name": "Rock_Stone"
    },
    {
      "x": -18,
      "y": 2,
      "z": -1,
      "name": "Rock_Stone"
    },
    {
      "x": -18,
      "y": 3,
      "z": -1,
      "name": "Soil_Dirt"
    },
    {
      "x": -18,
      "y": 4,
      "z": -1,
      "name": "Soil_Dirt"
    },
    {
      "x": -18,
      "y": 5,
      "z": -1,
      "name": "Soil_Grass"
    },
    {
      "x": -18,
      "y": 0,
      "z": 0,
      "name": "Rock_Stone"
    },
    {
      "x": -18,
      "y": 1,
      "z": 0,
      "name": "Rock_Stone"
    },
    {
      "x": -18,
      "y": 2,
      "z": 0,
      "name": "Rock_Stone"
    },
    {
      "x": -18,
      "y": 3,
      "z": 0,
      "name": "Soil_Dirt"
    },
    {
      "x": -18,
      "y": 4,
      "z": 0,
      "name": "Soil_Dirt"
    },
    {
      "x": -18,
      "y": 5,
      "z": 0,
      "name": "Soil_Grass"
    },
    {
      "x": -18,
      "y": 0,
      "z": 1,
      "name": "Rock_Stone"
    },
    {
      "x": -18,
      "y": 1,
      "z": 1,
      "name": "Rock_Stone"
    },
    {
      "x": -18,
      "y": 2,
      "z": 1,
      "name": "Rock_Stone"
    },
    {
      "x": -18,
      "y": 3,
      "z": 1,
      "name": "Soil_Dirt"
    },
    {
      "x": -18,
      "y": 4,
      "z": 1,
      "name": "Soil_Dirt"
    },
    {
      "x": -18,
      "y": 5,
      "z": 1,
      "name": "Soil_Grass"
    },
    {
      "x": -18,
      "y": 6,
      "z": 1,
      "name": "Plant_Bush",
      "support": 15
    },
    {
      "x": -18,
      "y": 0,
      "z": 2,
      "name": "Rock_Stone"
    },
    {
      "x": -18,
      "y": 1,
      "z": 2,
      "name": "Rock_Stone"
    },
    {
      "x": -18,
      "y": 2,
      "z": 2,
      "name": "Rock_Stone"
    },
    {
      "x": -18,
      "y": 3,
      "z": 2,
      "name": "Soil_Dirt"
    },
    {
      "x": -18,
      "y": 4,
      "z": 2,
      "name": "Soil_Dirt"
    },
    {
      "x": -18,
      "y": 5,
      "z": 2,
      "name": "Soil_Grass"
    },
    {
      "x": -18,
      "y": 0,
      "z": 3,
      "name": "Rock_Stone"
    },
    {
      "x": -18,
      "y": 1,
      "z": 3,
      "name": "Rock_Stone"
    },
    {
      "x": -18,
      "y": 2,
      "z": 3,
      "name": "Soil_Dirt"
    },
    {
      "x": -18,
      "y": 3,
      "z": 3,
      "name": "Soil_Dirt"
    },
    {
      "x": -18,
      "y": 4,
      "z": 3,
      "name": "Soil_Grass"
    },
    {
      "x": -18,
      "y": 5,
      "z": 3,
      "name": "Plant_Grass_Sharp",
      "support": 15
    },
    {
      "x": -18,
      "y": 0,
      "z": 4,
      "name": "Rock_Stone"
    },
    {
      "x": -18,
      "y": 1,
      "z": 4,
      "name": "Rock_Stone"
    },
    {
      "x": -18,
      "y": 2,
      "z": 4,
      "name": "Soil_Dirt"
    },
    {
      "x": -18,
      "y": 3,
      "z": 4,
      "name": "Soil_Dirt"
    },
    {
      "x": -18,
      "y": 4,
      "z": 4,
      "name": "Soil_Grass"
    },
    {
      "x": -18,
      "y": 0,
      "z": 5,
      "name": "Rock_Stone"
    },
    {
      "x": -18,
      "y": 1,
      "z": 5,
      "name": "Rock_Stone"
    },
    {
      "x": -18,
      "y": 2,
      "z": 5,
      "name": "Soil_Dirt"
    },
    {
      "x": -18,
      "y": 3,
      "z": 5,
      "name": "Soil_Dirt"
    },
    {
      "x": -18,
      "y": 4,
      "z": 5,
      "name": "Soil_Grass"
    },
    {
      "x": -18,
      "y": 0,
      "z": 6,
      "name": "Rock_Stone"
    },
    {
      "x": -18,
      "y": 1,
      "z": 6,
      "name": "Rock_Stone"
    },
    {
      "x": -18,
      "y": 2,
      "z": 6,
      "name": "Soil_Dirt"
    },
    {
      "x": -18,
      "y": 3,
      "z": 6,
      "name": "Soil_Dirt"
    },
    {
      "x": -18,
      "y": 4,
      "z": 6,
      "name": "Soil_Grass"
    },
    {
      "x": -18,
      "y": 0,
      "z": 7,
      "name": "Rock_Stone"
    },
    {
      "x": -18,
      "y": 1,
      "z": 7,
      "name": "Rock_Stone"
    },
    {
      "x": -18,
      "y": 2,
      "z": 7,
      "name": "Soil_Dirt"
    },
    {
      "x": -18,
      "y": 3,
      "z": 7,
      "name": "Soil_Dirt"
    },
    {
      "x": -18,
      "y": 4,
      "z": 7,
      "name": "Soil_Grass"
    },
    {
      "x": -18,
      "y": 5,
      "z": 7,
      "name": "Plant_Flower_Common_Pink"
    },
    {
      "x": -18,
      "y": 6,
      "z": 7,
      "name": "Plant_Flower_Common_Pink",
      "filler": 1024
    },
    {
      "x": -18,
      "y": 0,
      "z": 8,
      "name": "Rock_Stone"
    },
    {
      "x": -18,
      "y": 1,
      "z": 8,
      "name": "Soil_Dirt"
    },
    {
      "x": -18,
      "y": 2,
      "z": 8,
      "name": "Soil_Dirt"
    },
    {
      "x": -18,
      "y": 3,
      "z": 8,
      "name": "Soil_Grass"
    },
    {
      "x": -18,
      "y": 0,
      "z": 9,
      "name": "Rock_Stone"
    },
    {
      "x": -18,
      "y": 1,
      "z": 9,
      "name": "Soil_Dirt"
    },
    {
      "x": -18,
      "y": 2,
      "z": 9,
      "name": "Soil_Dirt"
    },
    {
      "x": -18,
      "y": 3,
      "z": 9,
      "name": "Soil_Grass"
    },
    {
      "x": -18,
      "y": 0,
      "z": 10,
      "name": "Soil_Dirt"
    },
    {
      "x": -18,
      "y": 1,
      "z": 10,
      "name": "Soil_Grass"
    },
    {
      "x": -18,
      "y": 2,
      "z": 10,
      "name": "Plant_Grass_Sharp",
      "support": 15
    },
    {
      "x": -18,
      "y": 0,
      "z": 11,
      "name": "Soil_Dirt"
    },
    {
      "x": -18,
      "y": 1,
      "z": 11,
      "name": "Soil_Dirt"
    },
    {
      "x": -18,
      "y": 2,
      "z": 11,
      "name": "Soil_Grass"
    },
    {
      "x": -18,
      "y": 3,
      "z": 11,
      "name": "Plant_Bush",
      "support": 15
    },
    {
      "x": -18,
      "y": 0,
      "z": 12,
      "name": "Soil_Dirt"
    },
    {
      "x": -18,
      "y": 1,
      "z": 12,
      "name": "Soil_Grass"
    },
    {
      "x": -18,
      "y": 0,
      "z": 13,
      "name": "Soil_Dirt"
    },
    {
      "x": -18,
      "y": 1,
      "z": 13,
      "name": "Soil_Grass"
    },
    {
      "x": -18,
      "y": 0,
      "z": 14,
      "name": "Soil_Grass"
    },
    {
      "x": -18,
      "y": 0,
      "z": 15,
      "name": "Soil_Grass"
    },
    {
      "x": -18,
      "y": 0,
      "z": 16,
      "name": "Soil_Grass"
    },
    {
      "x": -18,
      "y": 0,
      "z": 17,
      "name": "Soil_Grass"
    },
    {
      "x": -18,
      "y": 0,
      "z": 18,
      "name": "Soil_Grass"
    },
    {
      "x": -18,
      "y": 0,
      "z": 19,
      "name": "Soil_Grass"
    },
    {
      "x": -18,
      "y": 0,
      "z": 20,
      "name": "Soil_Grass"
    },
    {
      "x": -17,
      "y": 0,
      "z": -20,
      "name": "Soil_Grass"
    },
    {
      "x": -17,
      "y": 0,
      "z": -19,
      "name": "Soil_Dirt"
    },
    {
      "x": -17,
      "y": 1,
      "z": -19,
      "name": "Soil_Grass"
    },
    {
      "x": -17,
      "y": 0,
      "z": -18,
      "name": "Soil_Dirt"
    },
    {
      "x": -17,
      "y": 1,
      "z": -18,
      "name": "Soil_Dirt"
    },
    {
      "x": -17,
      "y": 2,
      "z": -18,
      "name": "Soil_Grass"
    },
    {
      "x": -17,
      "y": 0,
      "z": -17,
      "name": "Soil_Dirt"
    },
    {
      "x": -17,
      "y": 1,
      "z": -17,
      "name": "Soil_Dirt"
    },
    {
      "x": -17,
      "y": 2,
      "z": -17,
      "name": "Soil_Grass"
    },
    {
      "x": -17,
      "y": 0,
      "z": -16,
      "name": "Rock_Stone"
    },
    {
      "x": -17,
      "y": 1,
      "z": -16,
      "name": "Soil_Dirt"
    },
    {
      "x": -17,
      "y": 2,
      "z": -16,
      "name": "Soil_Dirt"
    },
    {
      "x": -17,
      "y": 3,
      "z": -16,
      "name": "Soil_Grass"
    },
    {
      "x": -17,
      "y": 4,
      "z": -16,
      "name": "Plant_Grass_Sharp",
      "support": 15
    },
    {
      "x": -17,
      "y": 0,
      "z": -15,
      "name": "Rock_Stone"
    },
    {
      "x": -17,
      "y": 1,
      "z": -15,
      "name": "Rock_Stone"
    },
    {
      "x": -17,
      "y": 2,
      "z": -15,
      "name": "Soil_Dirt"
    },
    {
      "x": -17,
      "y": 3,
      "z": -15,
      "name": "Soil_Dirt"
    },
    {
      "x": -17,
      "y": 4,
      "z": -15,
      "name": "Soil_Grass"
    },
    {
      "x": -17,
      "y": 0,
      "z": -14,
      "name": "Rock_Stone"
    },
    {
      "x": -17,
      "y": 1,
      "z": -14,
      "name": "Rock_Stone"
    },
    {
      "x": -17,
      "y": 2,
      "z": -14,
      "name": "Soil_Dirt"
    },
    {
      "x": -17,
      "y": 3,
      "z": -14,
      "name": "Soil_Dirt"
    },
    {
      "x": -17,
      "y": 4,
      "z": -14,
      "name": "Soil_Grass"
    },
    {
      "x": -17,
      "y": 5,
      "z": -14,
      "name": "Plant_Grass_Sharp",
      "support": 15
    },
    {
      "x": -17,
      "y": 0,
      "z": -13,
      "name": "Rock_Stone"
    },
    {
      "x": -17,
      "y": 1,
      "z": -13,
      "name": "Rock_Stone"
    },
    {
      "x": -17,
      "y": 2,
      "z": -13,
      "name": "Soil_Dirt"
    },
    {
      "x": -17,
      "y": 3,
      "z": -13,
      "name": "Soil_Dirt"
    },
    {
      "x": -17,
      "y": 4,
      "z": -13,
      "name": "Soil_Grass"
    },
    {
      "x": -17,
      "y": 5,
      "z": -13,
      "name": "Plant_Crop_Mushroom_Cap_Red",
      "components": {
        "Components": {
          "FarmingBlock": {
            "LastTickGameTime": "0001-01-01T07:00:00Z"
          },
          "PlacedByInteraction": {
            "WhoPlacedUuid": {
              "$binary": "Shql8I17RtKAFQvVehUiIg==",
              "$type": "04"
            }
          }
        }
      }
    },
    {
      "x": -17,
      "y": 0,
      "z": -12,
      "name": "Rock_Stone"
    },
    {
      "x": -17,
      "y": 1,
      "z": -12,
      "name": "Rock_Stone"
    },
    {
      "x": -17,
      "y": 2,
      "z": -12,
      "name": "Soil_Dirt"
    },
    {
      "x": -17,
      "y": 3,
      "z": -12,
      "name": "Soil_Dirt"
    },
    {
      "x": -17,
      "y": 4,
      "z": -12,
      "name": "Soil_Grass"
    },
    {
      "x": -17,
      "y": 5,
      "z": -12,
      "name": "Plant_Grass_Sharp",
      "support": 15
    },
    {
      "x": -17,
      "y": 0,
      "z": -11,
      "name": "Rock_Stone"
    },
    {
      "x": -17,
      "y": 1,
      "z": -11,
      "name": "Rock_Stone"
    },
    {
      "x": -17,
      "y": 2,
      "z": -11,
      "name": "Soil_Dirt"
    },
    {
      "x": -17,
      "y": 3,
      "z": -11,
      "name": "Soil_Dirt"
    },
    {
      "x": -17,
      "y": 4,
      "z": -11,
      "name": "Soil_Grass"
    },
    {
      "x": -17,
      "y": 0,
      "z": -10,
      "name": "Rock_Stone"
    },
    {
      "x": -17,
      "y": 1,
      "z": -10,
      "name": "Soil_Dirt"
    },
    {
      "x": -17,
      "y": 2,
      "z": -10,
      "name": "Soil_Dirt"
    },
    {
      "x": -17,
      "y": 3,
      "z": -10,
      "name": "Soil_Grass"
    },
    {
      "x": -17,
      "y": 0,
      "z": -9,
      "name": "Rock_Stone"
    },
    {
      "x": -17,
      "y": 1,
      "z": -9,
      "name": "Soil_Dirt"
    },
    {
      "x": -17,
      "y": 2,
      "z": -9,
      "name": "Soil_Dirt"
    },
    {
      "x": -17,
      "y": 3,
      "z": -9,
      "name": "Soil_Grass"
    },
    {
      "x": -17,
      "y": 0,
      "z": -8,
      "name": "Rock_Stone"
    },
    {
      "x": -17,
      "y": 1,
      "z": -8,
      "name": "Rock_Stone"
    },
    {
      "x": -17,
      "y": 2,
      "z": -8,
      "name": "Soil_Dirt"
    },
    {
      "x": -17,
      "y": 3,
      "z": -8,
      "name": "Soil_Dirt"
    },
    {
      "x": -17,
      "y": 4,
      "z": -8,
      "name": "Soil_Grass"
    },
    {
      "x": -17,
      "y": 5,
      "z": -8,
      "name": "Plant_Flower_Common_Yellow"
    },
    {
      "x": -17,
      "y": 0,
      "z": -7,
      "name": "Rock_Stone"
    },
    {
      "x": -17,
      "y": 1,
      "z": -7,
      "name": "Rock_Stone"
    },
    {
      "x": -17,
      "y": 2,
      "z": -7,
      "name": "Soil_Dirt"
    },
    {
      "x": -17,
      "y": 3,
      "z": -7,
      "name": "Soil_Dirt"
    },
    {
      "x": -17,
      "y": 4,
      "z": -7,
      "name": "Soil_Grass"
    },
    {
      "x": -17,
      "y": 0,
      "z": -6,
      "name": "Rock_Stone"
    },
    {
      "x": -17,
      "y": 1,
      "z": -6,
      "name": "Rock_Stone"
    },
    {
      "x": -17,
      "y": 2,
      "z": -6,
      "name": "Soil_Dirt"
    },
    {
      "x": -17,
      "y": 3,
      "z": -6,
      "name": "Soil_Dirt"
    },
    {
      "x": -17,
      "y": 4,
      "z": -6,
      "name": "Soil_Grass"
    },
    {
      "x": -17,
      "y": 0,
      "z": -5,
      "name": "Rock_Stone"
    },
    {
      "x": -17,
      "y": 1,
      "z": -5,
      "name": "Rock_Stone"
    },
    {
      "x": -17,
      "y": 2,
      "z": -5,
      "name": "Rock_Stone"
    },
    {
      "x": -17,
      "y": 3,
      "z": -5,
      "name": "Soil_Dirt"
    },
    {
      "x": -17,
      "y": 4,
      "z": -5,
      "name": "Soil_Dirt"
    },
    {
      "x": -17,
      "y": 5,
      "z": -5,
      "name": "Soil_Grass"
    },
    {
      "x": -17,
      "y": 0,
      "z": -4,
      "name": "Rock_Stone"
    },
    {
      "x": -17,
      "y": 1,
      "z": -4,
      "name": "Rock_Stone"
    },
    {
      "x": -17,
      "y": 2,
      "z": -4,
      "name": "Rock_Stone"
    },
    {
      "x": -17,
      "y": 3,
      "z": -4,
      "name": "Soil_Dirt"
    },
    {
      "x": -17,
      "y": 4,
      "z": -4,
      "name": "Soil_Dirt"
    },
    {
      "x": -17,
      "y": 5,
      "z": -4,
      "name": "Soil_Grass"
    },
    {
      "x": -17,
      "y": 6,
      "z": -4,
      "name": "Plant_Grass_Dry_Tall",
      "support": 15
    },
    {
      "x": -17,
      "y": 7,
      "z": -4,
      "name": "Plant_Grass_Dry_Tall",
      "filler": 1024
    },
    {
      "x": -17,
      "y": 0,
      "z": -3,
      "name": "Rock_Stone"
    },
    {
      "x": -17,
      "y": 1,
      "z": -3,
      "name": "Rock_Stone"
    },
    {
      "x": -17,
      "y": 2,
      "z": -3,
      "name": "Rock_Stone"
    },
    {
      "x": -17,
      "y": 3,
      "z": -3,
      "name": "Soil_Dirt"
    },
    {
      "x": -17,
      "y": 4,
      "z": -3,
      "name": "Soil_Dirt"
