{
  "version": 8,
  "blockIdVersion": 11,
  "anchorX": 0,
  "anchorY": 0,
  "anchorZ": 0,
  "blocks": [
    {
      "x": -27,
      "y": 0,
      "z": -5,
      "name": "Soil_Grass_Cold",
      "rotation": 2
    },
    {
      "x": -27,
      "y": 1,
      "z": -5,
      "name": "Rock_Shale_Brick",
      "rotation": 2
    },
    {
      "x": -27,
      "y": 2,
      "z": -5,
      "name": "Rock_Shale_Brick",
      "rotation": 2
    },
    {
      "x": -27,
      "y": 3,
      "z": -5,
      "name": "Rock_Shale_Brick",
      "rotation": 2
    },
    {
      "x": -27,
      "y": 4,
      "z": -5,
      "name": "*Rock_Shale_Brick_Wall_State_Definitions_Corner",
      "rotation": 1
    },
    {
      "x": -27,
      "y": 5,
      "z": -5,
      "name": "Furniture_Crude_Torch",
      "rotation": 3
    },
    {
      "x": -27,
      "y": 0,
      "z": -4,
      "name": "Soil_Grass_Cold",
      "rotation": 2
    },
    {
      "x": -27,
      "y": 1,
      "z": -4,
      "name": "Rock_Shale_Brick",
      "rotation": 2
    },
    {
      "x": -27,
      "y": 2,
      "z": -4,
      "name": "Rock_Shale_Brick",
      "rotation": 2
    },
    {
      "x": -27,
      "y": 3,
      "z": -4,
      "name": "Rock_Shale_Brick",
      "rotation": 2
    },
    {
      "x": -27,
      "y": 4,
      "z": -4,
      "name": "Rock_Shale_Brick_Wall",
      "rotation": 3
    },
    {
      "x": -27,
      "y": 0,
      "z": -3,
      "name": "Soil_Grass_Cold",
      "rotation": 2
    },
    {
      "x": -27,
      "y": 1,
      "z": -3,
      "name": "Rock_Shale_Brick",
      "rotation": 2
    },
    {
      "x": -27,
      "y": 2,
      "z": -3,
      "name": "Rock_Shale_Brick",
      "rotation": 2
    },
    {
      "x": -27,
      "y": 3,
      "z": -3,
      "name": "Rock_Shale_Brick",
      "rotation": 2
    },
    {
      "x": -27,
      "y": 4,
      "z": -3,
      "name": "Rock_Shale_Brick_Wall",
      "rotation": 3
    },
    {
      "x": -27,
      "y": 0,
      "z": -2,
      "name": "Soil_Grass_Cold",
      "rotation": 2
    },
    {
      "x": -27,
      "y": 1,
      "z": -2,
      "name": "Rock_Shale_Brick",
      "rotation": 2
    },
    {
      "x": -27,
      "y": 2,
      "z": -2,
      "name": "Rock_Shale_Brick",
      "rotation": 2
    },
    {
      "x": -27,
      "y": 3,
      "z": -2,
      "name": "Rock_Shale_Brick",
      "rotation": 2
    },
    {
      "x": -27,
      "y": 4,
      "z": -2,
      "name": "Rock_Shale_Brick_Wall",
      "rotation": 3
    },
    {
      "x": -27,
      "y": 0,
      "z": -1,
      "name": "Soil_Grass_Cold",
      "rotation": 2
    },
    {
      "x": -27,
      "y": 1,
      "z": -1,
      "name": "Rock_Shale_Brick",
      "rotation": 2
    },
    {
      "x": -27,
      "y": 2,
      "z": -1,
      "name": "Rock_Shale_Brick",
      "rotation": 2
    },
    {
      "x": -27,
      "y": 3,
      "z": -1,
      "name": "Rock_Shale_Brick",
      "rotation": 2
    },
    {
      "x": -27,
      "y": 4,
      "z": -1,
      "name": "Rock_Shale_Brick_Wall",
      "rotation": 3
    },
    {
      "x": -27,
      "y": 0,
      "z": 0,
      "name": "Soil_Grass_Cold",
      "rotation": 2
    },
    {
      "x": -27,
      "y": 1,
      "z": 0,
      "name": "Rock_Shale_Brick",
      "rotation": 2
    },
    {
      "x": -27,
      "y": 2,
      "z": 0,
      "name": "Rock_Shale_Brick",
      "rotation": 2
    },
    {
      "x": -27,
      "y": 3,
      "z": 0,
      "name": "Rock_Shale_Brick",
      "rotation": 2
    },
    {
      "x": -27,
      "y": 4,
      "z": 0,
      "name": "Rock_Shale_Brick_Wall",
      "rotation": 3
    },
    {
      "x": -27,
      "y": 0,
      "z": 1,
      "name": "Soil_Grass_Cold",
      "rotation": 2
    },
    {
      "x": -27,
      "y": 1,
      "z": 1,
      "name": "Rock_Shale_Brick",
      "rotation": 2
    },
    {
      "x": -27,
      "y": 2,
      "z": 1,
      "name": "Rock_Shale_Brick",
      "rotation": 2
    },
    {
      "x": -27,
      "y": 3,
      "z": 1,
      "name": "Rock_Shale_Brick",
      "rotation": 2
    },
    {
      "x": -27,
      "y": 4,
      "z": 1,
      "name": "Rock_Shale_Brick_Wall",
      "rotation": 3
    },
    {
      "x": -27,
      "y": 0,
      "z": 2,
      "name": "Soil_Grass_Cold",
      "rotation": 2
    },
    {
      "x": -27,
      "y": 1,
      "z": 2,
      "name": "Rock_Shale_Brick",
      "rotation": 2
    },
    {
      "x": -27,
      "y": 2,
      "z": 2,
      "name": "Rock_Shale_Brick",
      "rotation": 2
    },
    {
      "x": -27,
      "y": 3,
      "z": 2,
      "name": "Rock_Shale_Brick",
      "rotation": 2
    },
    {
      "x": -27,
      "y": 4,
      "z": 2,
      "name": "Rock_Shale_Brick_Wall",
      "rotation": 3
    },
    {
      "x": -27,
      "y": 0,
      "z": 3,
      "name": "Soil_Grass_Cold",
      "rotation": 2
    },
    {
      "x": -27,
      "y": 1,
      "z": 3,
      "name": "Rock_Shale_Brick",
      "rotation": 2
    },
    {
      "x": -27,
      "y": 2,
      "z": 3,
      "name": "Rock_Shale_Brick",
      "rotation": 2
    },
    {
      "x": -27,
      "y": 3,
      "z": 3,
      "name": "Rock_Shale_Brick",
      "rotation": 2
    },
    {
      "x": -27,
      "y": 4,
      "z": 3,
      "name": "Rock_Shale_Brick_Wall",
      "rotation": 3
    },
    {
      "x": -27,
      "y": 0,
      "z": 4,
      "name": "Soil_Grass_Cold",
      "rotation": 2
    },
    {
      "x": -27,
      "y": 1,
      "z": 4,
      "name": "Rock_Shale_Brick",
      "rotation": 2
    },
    {
      "x": -27,
      "y": 2,
      "z": 4,
      "name": "Rock_Shale_Brick",
      "rotation": 2
    },
    {
      "x": -27,
      "y": 3,
      "z": 4,
      "name": "Rock_Shale_Brick",
      "rotation": 2
    },
    {
      "x": -27,
      "y": 4,
      "z": 4,
      "name": "Rock_Shale_Brick_Wall",
      "rotation": 3
    },
    {
      "x": -27,
      "y": 0,
      "z": 5,
      "name": "Soil_Grass_Cold",
      "rotation": 2
    },
    {
      "x": -27,
      "y": 1,
      "z": 5,
      "name": "Rock_Shale_Brick",
      "rotation": 2
    },
    {
      "x": -27,
      "y": 2,
      "z": 5,
      "name": "Rock_Shale_Brick",
      "rotation": 2
    },
    {
      "x": -27,
      "y": 3,
      "z": 5,
      "name": "Rock_Shale_Brick",
      "rotation": 2
    },
    {
      "x": -27,
      "y": 4,
      "z": 5,
      "name": "*Rock_Shale_Brick_Wall_State_Definitions_Corner",
      "rotation": 2
    },
    {
      "x": -27,
      "y": 5,
      "z": 5,
      "name": "Furniture_Crude_Torch",
      "rotation": 3
    },
    {
      "x": -26,
      "y": 0,
      "z": -9,
      "name": "Soil_Grass_Cold",
      "rotation": 2
    },
    {
      "x": -26,
      "y": 1,
      "z": -9,
      "name": "Rock_Shale_Brick",
      "rotation": 2
    },
    {
      "x": -26,
      "y": 2,
      "z": -9,
      "name": "Rock_Shale_Brick",
      "rotation": 2
    },
    {
      "x": -26,
      "y": 3,
      "z": -9,
      "name": "Rock_Shale_Brick",
      "rotation": 2
    },
    {
      "x": -26,
      "y": 4,
      "z": -9,
      "name": "*Rock_Shale_Brick_Wall_State_Definitions_Corner",
      "rotation": 1
    },
    {
      "x": -26,
      "y": 0,
      "z": -8,
      "name": "Soil_Grass_Cold",
      "rotation": 2
    },
    {
      "x": -26,
      "y": 1,
      "z": -8,
      "name": "Rock_Shale_Brick",
      "rotation": 2
    },
    {
      "x": -26,
      "y": 2,
      "z": -8,
      "name": "Rock_Shale_Brick",
      "rotation": 2
    },
    {
      "x": -26,
      "y": 3,
      "z": -8,
      "name": "Rock_Shale_Brick",
      "rotation": 2
    },
    {
      "x": -26,
      "y": 4,
      "z": -8,
      "name": "Rock_Shale_Brick_Wall",
      "rotation": 3
    },
    {
      "x": -26,
      "y": 0,
      "z": -7,
      "name": "Soil_Grass_Cold",
      "rotation": 2
    },
    {
      "x": -26,
      "y": 1,
      "z": -7,
      "name": "Rock_Shale_Brick",
      "rotation": 2
    },
    {
      "x": -26,
      "y": 2,
      "z": -7,
      "name": "Rock_Shale_Brick",
      "rotation": 2
    },
    {
      "x": -26,
      "y": 3,
      "z": -7,
      "name": "Rock_Shale_Brick",
      "rotation": 2
    },
    {
      "x": -26,
      "y": 4,
      "z": -7,
      "name": "Rock_Shale_Brick_Wall",
      "rotation": 3
    },
    {
      "x": -26,
      "y": 0,
      "z": -6,
      "name": "Soil_Grass_Cold",
      "rotation": 2
    },
    {
      "x": -26,
      "y": 1,
      "z": -6,
      "name": "Rock_Shale_Brick",
      "rotation": 2
    },
    {
      "x": -26,
      "y": 2,
      "z": -6,
      "name": "Rock_Shale_Brick",
      "rotation": 2
    },
    {
      "x": -26,
      "y": 3,
      "z": -6,
      "name": "Rock_Shale_Brick",
      "rotation": 2
    },
    {
      "x": -26,
      "y": 4,
      "z": -6,
      "name": "Rock_Shale_Brick_Wall",
      "rotation": 3
    },
    {
      "x": -26,
      "y": 0,
      "z": -5,
      "name": "Soil_Grass_Cold",
      "rotation": 2
    },
    {
      "x": -26,
      "y": 1,
      "z": -5,
      "name": "Rock_Shale_Brick",
      "rotation": 2
    },
    {
      "x": -26,
      "y": 2,
      "z": -5,
      "name": "Rock_Shale_Brick",
      "rotation": 2
    },
    {
      "x": -26,
      "y": 3,
      "z": -5,
      "name": "Rock_Shale_Brick",
      "rotation": 2
    },
    {
      "x": -26,
      "y": 4,
      "z": -5,
      "name": "*Rock_Shale_Brick_Wall_State_Definitions_Corner",
      "rotation": 3
    },
    {
      "x": -26,
      "y": 0,
      "z": -4,
      "name": "Soil_Grass_Cold",
      "rotation": 2
    },
    {
      "x": -26,
      "y": 0,
      "z": -3,
      "name": "Soil_Grass_Cold",
      "rotation": 2
    },
    {
      "x": -26,
      "y": 0,
      "z": -2,
      "name": "Soil_Grass_Cold",
      "rotation": 2
    },
    {
      "x": -26,
      "y": 0,
      "z": -1,
      "name": "Soil_Grass_Cold",
      "rotation": 2
    },
    {
      "x": -26,
      "y": 0,
      "z": 0,
      "name": "Soil_Grass_Cold",
      "rotation": 2
    },
    {
      "x": -26,
      "y": 0,
      "z": 1,
      "name": "Soil_Grass_Cold",
      "rotation": 2
    },
    {
      "x": -26,
      "y": 0,
      "z": 2,
      "name": "Soil_Grass_Cold",
      "rotation": 2
    },
    {
      "x": -26,
      "y": 0,
      "z": 3,
      "name": "Soil_Grass_Cold",
      "rotation": 2
    },
    {
      "x": -26,
      "y": 0,
      "z": 4,
      "name": "Soil_Grass_Cold",
      "rotation": 2
    },
    {
      "x": -26,
      "y": 0,
      "z": 5,
      "name": "Soil_Grass_Cold",
      "rotation": 2
    },
    {
      "x": -26,
      "y": 1,
      "z": 5,
      "name": "Rock_Shale_Brick",
      "rotation": 2
    },
    {
      "x": -26,
      "y": 2,
      "z": 5,
      "name": "Rock_Shale_Brick",
      "rotation": 2
    },
    {
      "x": -26,
      "y": 3,
      "z": 5,
      "name": "Rock_Shale_Brick",
      "rotation": 2
    },
    {
      "x": -26,
      "y": 4,
      "z": 5,
      "name": "*Rock_Shale_Brick_Wall_State_Definitions_Corner"
    },
    {
      "x": -26,
      "y": 0,
      "z": 6,
      "name": "Soil_Grass_Cold",
      "rotation": 2
    },
    {
      "x": -26,
      "y": 1,
      "z": 6,
      "name": "Rock_Shale_Brick",
      "rotation": 2
    },
    {
      "x": -26,
      "y": 2,
      "z": 6,
      "name": "Rock_Shale_Brick",
      "rotation": 2
    },
    {
      "x": -26,
      "y": 3,
      "z": 6,
      "name": "Rock_Shale_Brick",
      "rotation": 2
    },
    {
      "x": -26,
      "y": 4,
      "z": 6,
      "name": "Rock_Shale_Brick_Wall",
      "rotation": 3
    },
    {
      "x": -26,
      "y": 0,
      "z": 7,
      "name": "Soil_Grass_Cold",
      "rotation": 2
    },
    {
      "x": -26,
      "y": 1,
      "z": 7,
      "name": "Rock_Shale_Brick",
      "rotation": 2
    },
    {
      "x": -26,
      "y": 2,
      "z": 7,
      "name": "Rock_Shale_Brick",
      "rotation": 2
    },
    {
      "x": -26,
      "y": 3,
      "z": 7,
      "name": "Rock_Shale_Brick",
      "rotation": 2
    },
    {
      "x": -26,
      "y": 4,
      "z": 7,
      "name": "Rock_Shale_Brick_Wall",
      "rotation": 3
    },
    {
      "x": -26,
      "y": 0,
      "z": 8,
      "name": "Soil_Grass_Cold",
      "rotation": 2
    },
    {
      "x": -26,
      "y": 1,
      "z": 8,
      "name": "Rock_Shale_Brick",
      "rotation": 2
    },
    {
      "x": -26,
      "y": 2,
      "z": 8,
      "name": "Rock_Shale_Brick",
      "rotation": 2
    },
    {
      "x": -26,
      "y": 3,
      "z": 8,
      "name": "Rock_Shale_Brick",
      "rotation": 2
    },
    {
      "x": -26,
      "y": 4,
      "z": 8,
      "name": "Rock_Shale_Brick_Wall",
      "rotation": 3
    },
    {
      "x": -26,
      "y": 0,
      "z": 9,
      "name": "Soil_Grass_Cold",
      "rotation": 2
    },
    {
      "x": -26,
      "y": 1,
      "z": 9,
      "name": "Rock_Shale_Brick",
      "rotation": 2
    },
    {
      "x": -26,
      "y": 2,
      "z": 9,
      "name": "Rock_Shale_Brick",
      "rotation": 2
    },
    {
      "x": -26,
      "y": 3,
      "z": 9,
      "name": "Rock_Shale_Brick",
      "rotation": 2
    },
    {
      "x": -26,
      "y": 4,
      "z": 9,
      "name": "*Rock_Shale_Brick_Wall_State_Definitions_Corner",
      "rotation": 2
    },
    {
      "x": -25,
      "y": 0,
      "z": -12,
      "name": "Soil_Grass_Cold",
      "rotation": 2
    },
    {
      "x": -25,
      "y": 1,
      "z": -12,
      "name": "Rock_Shale_Brick",
      "rotation": 2
    },
    {
      "x": -25,
      "y": 2,
      "z": -12,
      "name": "Rock_Shale_Brick",
      "rotation": 2
    },
    {
      "x": -25,
      "y": 3,
      "z": -12,
      "name": "Rock_Shale_Brick",
      "rotation": 2
    },
    {
      "x": -25,
      "y": 4,
      "z": -12,
      "name": "*Rock_Shale_Brick_Wall_State_Definitions_Corner",
      "rotation": 1
    },
    {
      "x": -25,
      "y": 0,
      "z": -11,
      "name": "Soil_Grass_Cold",
      "rotation": 2
    },
    {
      "x": -25,
      "y": 1,
      "z": -11,
      "name": "Rock_Shale_Brick",
      "rotation": 2
    },
    {
      "x": -25,
      "y": 2,
      "z": -11,
      "name": "Rock_Shale_Brick",
      "rotation": 2
    },
    {
      "x": -25,
      "y": 3,
      "z": -11,
      "name": "Rock_Shale_Brick",
      "rotation": 2
    },
    {
      "x": -25,
      "y": 4,
      "z": -11,
      "name": "Rock_Shale_Brick_Wall",
      "rotation": 3
    },
    {
      "x": -25,
      "y": 0,
      "z": -10,
      "name": "Soil_Grass_Cold",
      "rotation": 2
    },
    {
      "x": -25,
      "y": 1,
      "z": -10,
      "name": "Rock_Shale_Brick",
      "rotation": 2
    },
    {
      "x": -25,
      "y": 2,
      "z": -10,
      "name": "Rock_Shale_Brick",
      "rotation": 2
    },
    {
      "x": -25,
      "y": 3,
      "z": -10,
      "name": "Rock_Shale_Brick",
      "rotation": 2
    },
    {
      "x": -25,
      "y": 4,
      "z": -10,
      "name": "Rock_Shale_Brick_Wall",
      "rotation": 3
    },
    {
      "x": -25,
      "y": 0,
      "z": -9,
      "name": "Soil_Grass_Cold",
      "rotation": 2
    },
    {
      "x": -25,
      "y": 1,
      "z": -9,
      "name": "Rock_Shale_Brick",
      "rotation": 2
    },
    {
      "x": -25,
      "y": 2,
      "z": -9,
      "name": "Rock_Shale_Brick",
      "rotation": 2
    },
    {
      "x": -25,
      "y": 3,
      "z": -9,
      "name": "Rock_Shale_Brick",
      "rotation": 2
    },
    {
      "x": -25,
      "y": 4,
      "z": -9,
      "name": "*Rock_Shale_Brick_Wall_State_Definitions_Corner",
      "rotation": 3
    },
    {
      "x": -25,
      "y": 0,
      "z": -8,
      "name": "Soil_Grass_Cold",
      "rotation": 2
    },
    {
      "x": -25,
      "y": 0,
      "z": -7,
      "name": "Soil_Grass_Cold",
      "rotation": 2
    },
    {
      "x": -25,
      "y": 0,
      "z": -6,
      "name": "Soil_Grass_Cold",
      "rotation": 2
    },
    {
      "x": -25,
      "y": 0,
      "z": -5,
      "name": "Soil_Grass_Cold",
      "rotation": 2
    },
    {
      "x": -25,
      "y": 1,
      "z": -5,
      "name": "Wood_Darkwood_Fence",
      "rotation": 2
    },
    {
      "x": -25,
      "y": 0,
      "z": -4,
      "name": "Soil_Grass_Cold",
      "rotation": 2
    },
    {
      "x": -25,
      "y": 0,
      "z": -3,
      "name": "Soil_Grass_Cold",
      "rotation": 2
    },
    {
      "x": -25,
      "y": 0,
      "z": -2,
      "name": "Soil_Grass_Cold",
      "rotation": 2
    },
    {
      "x": -25,
      "y": 0,
      "z": -1,
      "name": "Soil_Grass_Cold",
      "rotation": 2
    },
    {
      "x": -25,
      "y": 0,
      "z": 0,
      "name": "Soil_Grass_Cold",
      "rotation": 2
    },
    {
      "x": -25,
      "y": 0,
      "z": 1,
      "name": "Soil_Grass_Cold",
      "rotation": 2
    },
    {
      "x": -25,
      "y": 0,
      "z": 2,
      "name": "Soil_Grass_Cold",
      "rotation": 2
    },
    {
      "x": -25,
      "y": 0,
      "z": 3,
      "name": "Soil_Grass_Cold",
      "rotation": 2
    },
    {
      "x": -25,
      "y": 0,
      "z": 4,
      "name": "Soil_Grass_Cold",
      "rotation": 2
    },
    {
      "x": -25,
      "y": 0,
      "z": 5,
      "name": "Soil_Grass_Cold",
      "rotation": 2
    },
    {
      "x": -25,
      "y": 1,
      "z": 5,
      "name": "Wood_Darkwood_Fence",
      "rotation": 2
    },
    {
      "x": -25,
      "y": 0,
      "z": 6,
      "name": "Soil_Grass_Cold",
      "rotation": 2
    },
    {
      "x": -25,
      "y": 0,
      "z": 7,
      "name": "Soil_Grass_Cold",
      "rotation": 2
    },
    {
      "x": -25,
      "y": 0,
      "z": 8,
      "name": "Soil_Grass_Cold",
      "rotation": 2
    },
    {
      "x": -25,
      "y": 0,
      "z": 9,
      "name": "Soil_Grass_Cold",
      "rotation": 2
    },
    {
      "x": -25,
      "y": 1,
      "z": 9,
      "name": "Rock_Shale_Brick",
      "rotation": 2
    },
    {
      "x": -25,
      "y": 2,
      "z": 9,
      "name": "Rock_Shale_Brick",
      "rotation": 2
    },
    {
      "x": -25,
      "y": 3,
      "z": 9,
      "name": "Rock_Shale_Brick",
      "rotation": 2
    },
    {
      "x": -25,
      "y": 4,
      "z": 9,
      "name": "*Rock_Shale_Brick_Wall_State_Definitions_Corner"
    },
    {
      "x": -25,
      "y": 0,
      "z": 10,
      "name": "Soil_Grass_Cold",
      "rotation": 2
    },
    {
      "x": -25,
      "y": 1,
      "z": 10,
      "name": "Rock_Shale_Brick",
      "rotation": 2
    },
    {
      "x": -25,
      "y": 2,
      "z": 10,
      "name": "Rock_Shale_Brick",
      "rotation": 2
    },
    {
      "x": -25,
      "y": 3,
      "z": 10,
      "name": "Rock_Shale_Brick",
      "rotation": 2
    },
    {
      "x": -25,
      "y": 4,
      "z": 10,
      "name": "Rock_Shale_Brick_Wall",
      "rotation": 3
    },
    {
      "x": -25,
      "y": 0,
      "z": 11,
      "name": "Soil_Grass_Cold",
      "rotation": 2
    },
    {
      "x": -25,
      "y": 1,
      "z": 11,
      "name": "Rock_Shale_Brick",
      "rotation": 2
    },
    {
      "x": -25,
      "y": 2,
      "z": 11,
      "name": "Rock_Shale_Brick",
      "rotation": 2
    },
    {
      "x": -25,
      "y": 3,
      "z": 11,
      "name": "Rock_Shale_Brick",
      "rotation": 2
    },
    {
      "x": -25,
      "y": 4,
      "z": 11,
      "name": "Rock_Shale_Brick_Wall",
      "rotation": 3
    },
    {
      "x": -25,
      "y": 0,
      "z": 12,
      "name": "Soil_Grass_Cold",
      "rotation": 2
    },
    {
      "x": -25,
      "y": 1,
      "z": 12,
      "name": "Rock_Shale_Brick",
      "rotation": 2
    },
    {
      "x": -25,
      "y": 2,
      "z": 12,
      "name": "Rock_Shale_Brick",
      "rotation": 2
    },
    {
      "x": -25,
      "y": 3,
      "z": 12,
      "name": "Rock_Shale_Brick",
      "rotation": 2
    },
    {
      "x": -25,
      "y": 4,
      "z": 12,
      "name": "*Rock_Shale_Brick_Wall_State_Definitions_Corner",
      "rotation": 2
    },
    {
      "x": -24,
      "y": 0,
      "z": -13,
      "name": "Soil_Grass_Cold",
      "rotation": 2
    },
    {
      "x": -24,
      "y": 1,
      "z": -13,
      "name": "Rock_Shale_Brick",
      "rotation": 2
    },
    {
      "x": -24,
      "y": 2,
      "z": -13,
      "name": "Rock_Shale_Brick",
      "rotation": 2
    },
    {
      "x": -24,
      "y": 3,
      "z": -13,
      "name": "Rock_Shale_Brick",
      "rotation": 2
    },
    {
      "x": -24,
      "y": 4,
      "z": -13,
      "name": "*Rock_Shale_Brick_Wall_State_Definitions_Corner",
      "rotation": 1
    },
    {
      "x": -24,
      "y": 0,
      "z": -12,
      "name": "Soil_Grass_Cold",
      "rotation": 2
    },
    {
      "x": -24,
      "y": 1,
      "z": -12,
      "name": "Rock_Shale_Brick",
      "rotation": 2
    },
    {
      "x": -24,
      "y": 2,
      "z": -12,
      "name": "Rock_Shale_Brick",
      "rotation": 2
    },
    {
      "x": -24,
      "y": 3,
      "z": -12,
      "name": "Rock_Shale_Brick",
      "rotation": 2
    },
    {
      "x": -24,
      "y": 4,
      "z": -12,
      "name": "*Rock_Shale_Brick_Wall_State_Definitions_Corner",
      "rotation": 3
    },
    {
      "x": -24,
      "y": 0,
      "z": -11,
      "name": "Soil_Grass_Cold",
      "rotation": 2
    },
    {
      "x": -24,
      "y": 0,
      "z": -10,
      "name": "Soil_Grass_Cold",
      "rotation": 2
    },
    {
      "x": -24,
      "y": 0,
      "z": -9,
      "name": "Soil_Grass_Cold",
      "rotation": 2
    },
    {
      "x": -24,
      "y": 0,
      "z": -8,
      "name": "Soil_Grass_Cold",
      "rotation": 2
    },
    {
      "x": -24,
      "y": 0,
      "z": -7,
      "name": "Soil_Grass_Cold",
      "rotation": 2
    },
    {
      "x": -24,
      "y": 0,
      "z": -6,
      "name": "Soil_Grass_Cold",
      "rotation": 2
    },
    {
      "x": -24,
      "y": 0,
      "z": -5,
      "name": "Soil_Grass_Cold",
      "rotation": 2
    },
    {
      "x": -24,
      "y": 1,
      "z": -5,
      "name": "Wood_Darkwood_Fence",
      "rotation": 2
    },
    {
      "x": -24,
      "y": 0,
      "z": -4,
      "name": "Soil_Grass_Cold",
      "rotation": 2
    },
    {
      "x": -24,
      "y": 0,
      "z": -3,
      "name": "Soil_Grass_Cold",
      "rotation": 2
    },
    {
      "x": -24,
      "y": 0,
      "z": -2,
      "name": "Soil_Grass_Cold",
      "rotation": 2
    },
    {
      "x": -24,
      "y": 0,
      "z": -1,
      "name": "Soil_Grass_Cold",
      "rotation": 2
    },
    {
      "x": -24,
      "y": 1,
      "z": -1,
      "name": "Coop_Chicken",
      "filler": 1023,
      "rotation": 1
    },
    {
      "x": -24,
      "y": 2,
      "z": -1,
      "name": "Coop_Chicken",
      "filler": 2047,
      "rotation": 1
    },
    {
      "x": -24,
      "y": 3,
      "z": -1,
      "name": "Coop_Chicken",
      "filler": 3071,
      "rotation": 1
    },
    {
      "x": -24,
      "y": 0,
      "z": 0,
      "name": "Soil_Grass_Cold",
      "rotation": 2
    },
    {
      "x": -24,
      "y": 1,
      "z": 0,
      "name": "Coop_Chicken",
      "filler": 31,
      "rotation": 1
    },
    {
      "x": -24,
      "y": 2,
      "z": 0,
      "name": "Coop_Chicken",
      "filler": 1055,
      "rotation": 1
    },
    {
      "x": -24,
      "y": 3,
      "z": 0,
      "name": "Coop_Chicken",
      "filler": 2079,
      "rotation": 1
    },
    {
      "x": -24,
      "y": 0,
      "z": 1,
      "name": "Soil_Grass_Cold",
      "rotation": 2
    },
    {
      "x": -24,
      "y": 1,
      "z": 1,
      "name": "Coop_Chicken",
      "filler": 63,
      "rotation": 1
    },
    {
      "x": -24,
      "y": 2,
      "z": 1,
      "name": "Coop_Chicken",
      "filler": 1087,
      "rotation": 1
    },
    {
      "x": -24,
      "y": 3,
      "z": 1,
      "name": "Coop_Chicken",
      "filler": 2111,
      "rotation": 1
    },
    {
      "x": -24,
      "y": 0,
      "z": 2,
      "name": "Soil_Grass_Cold",
      "rotation": 2
    },
    {
      "x": -24,
      "y": 0,
      "z": 3,
      "name": "Soil_Grass_Cold",
      "rotation": 2
    },
    {
      "x": -24,
      "y": 0,
      "z": 4,
      "name": "Soil_Grass_Cold",
      "rotation": 2
    },
    {
      "x": -24,
      "y": 0,
      "z": 5,
      "name": "Soil_Grass_Cold",
      "rotation": 2
    },
    {
      "x": -24,
      "y": 1,
      "z": 5,
      "name": "Wood_Darkwood_Fence",
      "rotation": 2
    },
    {
      "x": -24,
      "y": 0,
      "z": 6,
      "name": "Soil_Grass_Cold",
      "rotation": 2
    },
    {
      "x": -24,
      "y": 0,
      "z": 7,
      "name": "Soil_Grass_Cold",
      "rotation": 2
    },
    {
      "x": -24,
      "y": 0,
      "z": 8,
      "name": "Soil_Grass_Cold",
      "rotation": 2
    },
    {
      "x": -24,
      "y": 0,
      "z": 9,
      "name": "Soil_Grass_Cold",
      "rotation": 2
    },
    {
      "x": -24,
      "y": 0,
      "z": 10,
      "name": "Soil_Grass_Cold",
      "rotation": 2
    },
    {
      "x": -24,
      "y": 0,
      "z": 11,
      "name": "Soil_Grass_Cold",
      "rotation": 2
    },
    {
      "x": -24,
      "y": 0,
      "z": 12,
      "name": "Soil_Grass_Cold",
      "rotation": 2
    },
    {
      "x": -24,
      "y": 1,
      "z": 12,
      "name": "Rock_Shale_Brick",
      "rotation": 2
    },
    {
      "x": -24,
      "y": 2,
      "z": 12,
      "name": "Rock_Shale_Brick",
      "rotation": 2
    },
    {
      "x": -24,
      "y": 3,
      "z": 12,
      "name": "Rock_Shale_Brick",
      "rotation": 2
    },
    {
      "x": -24,
      "y": 4,
      "z": 12,
      "name": "*Rock_Shale_Brick_Wall_State_Definitions_Corner"
    },
    {
      "x": -24,
      "y": 0,
      "z": 13,
      "name": "Soil_Grass_Cold",
      "rotation": 2
    },
    {
      "x": -24,
      "y": 1,
      "z": 13,
      "name": "Rock_Shale_Brick",
      "rotation": 2
    },
    {
      "x": -24,
      "y": 2,
      "z": 13,
      "name": "Rock_Shale_Brick",
      "rotation": 2
    },
    {
      "x": -24,
      "y": 3,
      "z": 13,
      "name": "Rock_Shale_Brick",
      "rotation": 2
    },
    {
      "x": -24,
      "y": 4,
      "z": 13,
      "name": "*Rock_Shale_Brick_Wall_State_Definitions_Corner",
      "rotation": 2
    },
    {
      "x": -23,
      "y": 0,
      "z": -15,
      "name": "Soil_Grass_Cold",
      "rotation": 2
    },
    {
      "x": -23,
      "y": 1,
      "z": -15,
      "name": "Rock_Shale_Brick",
      "rotation": 2
    },
    {
      "x": -23,
      "y": 2,
      "z": -15,
      "name": "Rock_Shale_Brick",
      "rotation": 2
    },
    {
      "x": -23,
      "y": 3,
      "z": -15,
      "name": "Rock_Shale_Brick",
      "rotation": 2
    },
    {
      "x": -23,
      "y": 4,
      "z": -15,
      "name": "*Rock_Shale_Brick_Wall_State_Definitions_Corner",
      "rotation": 1
    },
    {
      "x": -23,
      "y": 0,
      "z": -14,
      "name": "Soil_Grass_Cold",
      "rotation": 2
    },
    {
      "x": -23,
      "y": 1,
      "z": -14,
      "name": "Rock_Shale_Brick",
      "rotation": 2
    },
    {
      "x": -23,
      "y": 2,
      "z": -14,
      "name": "Rock_Shale_Brick",
      "rotation": 2
    },
    {
      "x": -23,
      "y": 3,
      "z": -14,
      "name": "Rock_Shale_Brick",
      "rotation": 2
    },
    {
      "x": -23,
      "y": 4,
      "z": -14,
      "name": "Rock_Shale_Brick_Wall",
      "rotation": 3
    },
    {
      "x": -23,
      "y": 0,
      "z": -13,
      "name": "Soil_Grass_Cold",
      "rotation": 2
    },
    {
      "x": -23,
      "y": 1,
      "z": -13,
      "name": "Rock_Shale_Brick",
      "rotation": 2
    },
    {
      "x": -23,
      "y": 2,
      "z": -13,
      "name": "Rock_Shale_Brick",
      "rotation": 2
    },
    {
      "x": -23,
      "y": 3,
      "z": -13,
      "name": "Rock_Shale_Brick",
      "rotation": 2
    },
    {
      "x": -23,
      "y": 4,
      "z": -13,
      "name": "*Rock_Shale_Brick_Wall_State_Definitions_Corner",
      "rotation": 3
    },
    {
      "x": -23,
      "y": 0,
      "z": -12,
      "name": "Soil_Grass_Cold",
      "rotation": 2
    },
    {
      "x": -23,
      "y": 0,
      "z": -11,
      "name": "Soil_Grass_Cold",
      "rotation": 2
    },
    {
      "x": -23,
      "y": 0,
      "z": -10,
      "name": "Soil_Grass_Cold",
      "rotation": 2
    },
    {
      "x": -23,
      "y": 0,
      "z": -9,
      "name": "Soil_Grass_Cold",
      "rotation": 2
    },
    {
      "x": -23,
      "y": 0,
      "z": -8,
      "name": "Soil_Grass_Cold",
      "rotation": 2
    },
    {
      "x": -23,
      "y": 0,
      "z": -7,
      "name": "Soil_Grass_Cold",
      "rotation": 2
    },
    {
      "x": -23,
      "y": 0,
      "z": -6,
      "name": "Soil_Grass_Cold",
      "rotation": 2
    },
    {
      "x": -23,
      "y": 0,
      "z": -5,
      "name": "Soil_Grass_Cold",
      "rotation": 2
    },
    {
      "x": -23,
      "y": 1,
      "z": -5,
      "name": "Wood_Darkwood_Fence",
      "rotation": 2
    },
    {
      "x": -23,
      "y": 0,
      "z": -4,
      "name": "Soil_Grass_Cold",
      "rotation": 2
    },
    {
      "x": -23,
      "y": 0,
      "z": -3,
      "name": "Soil_Grass_Cold",
      "rotation": 2
    },
    {
      "x": -23,
      "y": 0,
      "z": -2,
      "name": "Soil_Grass_Cold",
      "rotation": 2
    },
    {
      "x": -23,
      "y": 0,
      "z": -1,
      "name": "Soil_Grass_Cold",
      "rotation": 2
    },
    {
      "x": -23,
      "y": 1,
      "z": -1,
      "name": "Coop_Chicken",
      "filler": 992,
      "rotation": 1
    },
    {
      "x": -23,
      "y": 2,
      "z": -1,
      "name": "Coop_Chicken",
      "filler": 2016,
      "rotation": 1
    },
    {
      "x": -23,
      "y": 3,
      "z": -1,
      "name": "Coop_Chicken",
      "filler": 3040,
      "rotation": 1
    },
    {
      "x": -23,
      "y": 0,
      "z": 0,
      "name": "Soil_Grass_Cold",
      "rotation": 2
    },
    {
      "x": -23,
      "y": 1,
      "z": 0,
      "name": "Coop_Chicken",
      "components": {
        "Components": {
          "Coop": {
            "FarmingCoopId": "Coop_Chicken",
            "Residents": [],
            "Storage": {
              "Id": "Simple",
              "Capacity": 5,
              "Items": {}
            }
          },
          "PlacedByInteraction": {
            "WhoPlacedUuid": {
              "$binary": "4r3uXrk6TtaZ4OXLTDGs2w==",
              "$type": "04"
            }
          }
        }
      },
      "rotation": 1
    },
    {
      "x": -23,
      "y": 2,
      "z": 0,
      "name": "Coop_Chicken",
      "filler": 1024,
      "rotation": 1
    },
    {
      "x": -23,
      "y": 3,
      "z": 0,
      "name": "Coop_Chicken",
      "filler": 2048,
      "rotation": 1
    },
    {
      "x": -23,
      "y": 0,
      "z": 1,
      "name": "Soil_Grass_Cold",
      "rotation": 2
    },
    {
      "x": -23,
      "y": 1,
      "z": 1,
      "name": "Coop_Chicken",
      "filler": 32,
      "rotation": 1
    },
    {
      "x": -23,
      "y": 2,
      "z": 1,
      "name": "Coop_Chicken",
      "filler": 1056,
      "rotation": 1
    },
    {
      "x": -23,
      "y": 3,
      "z": 1,
      "name": "Coop_Chicken",
      "filler": 2080,
      "rotation": 1
    },
    {
      "x": -23,
      "y": 0,
      "z": 2,
      "name": "Soil_Grass_Cold",
      "rotation": 2
    },
    {
      "x": -23,
      "y": 0,
      "z": 3,
      "name": "Soil_Grass_Cold",
      "rotation": 2
    },
    {
      "x": -23,
      "y": 0,
      "z": 4,
      "name": "Soil_Grass_Cold",
      "rotation": 2
    },
    {
      "x": -23,
      "y": 0,
      "z": 5,
      "name": "Soil_Grass_Cold",
      "rotation": 2
    },
    {
      "x": -23,
      "y": 1,
      "z": 5,
      "name": "Wood_Darkwood_Fence",
      "rotation": 2
    },
    {
      "x": -23,
      "y": 0,
      "z": 6,
      "name": "Soil_Grass_Cold",
      "rotation": 2
    },
    {
      "x": -23,
      "y": 0,
      "z": 7,
      "name": "Soil_Grass_Cold",
      "rotation": 2
    },
    {
      "x": -23,
      "y": 0,
      "z": 8,
      "name": "Soil_Grass_Cold",
      "rotation": 2
    },
    {
      "x": -23,
      "y": 0,
      "z": 9,
      "name": "Soil_Grass_Cold",
      "rotation": 2
    },
    {
      "x": -23,
      "y": 0,
      "z": 10,
      "name": "Soil_Grass_Cold",
      "rotation": 2
    },
    {
      "x": -23,
      "y": 0,
      "z": 11,
      "name": "Soil_Grass_Cold",
      "rotation": 2
    },
    {
      "x": -23,
      "y": 0,
      "z": 12,
      "name": "Soil_Grass_Cold",
      "rotation": 2
    },
    {
      "x": -23,
      "y": 0,
      "z": 13,
      "name": "Soil_Grass_Cold",
      "rotation": 2
    },
    {
      "x": -23,
      "y": 1,
      "z": 13,
      "name": "Rock_Shale_Brick",
      "rotation": 2
    },
    {
      "x": -23,
      "y": 2,
      "z": 13,
      "name": "Rock_Shale_Brick",
      "rotation": 2
    },
    {
      "x": -23,
      "y": 3,
      "z": 13,
      "name": "Rock_Shale_Brick",
      "rotation": 2
    },
    {
      "x": -23,
      "y": 4,
      "z": 13,
      "name": "*Rock_Shale_Brick_Wall_State_Definitions_Corner"
    },
    {
      "x": -23,
      "y": 0,
      "z": 14,
      "name": "Soil_Grass_Cold",
      "rotation": 2
    },
    {
      "x": -23,
      "y": 1,
      "z": 14,
      "name": "Rock_Shale_Brick",
      "rotation": 2
    },
    {
      "x": -23,
      "y": 2,
      "z": 14,
      "name": "Rock_Shale_Brick",
      "rotation": 2
    },
    {
      "x": -23,
      "y": 3,
      "z": 14,
      "name": "Rock_Shale_Brick",
      "rotation": 2
    },
    {
      "x": -23,
      "y": 4,
      "z": 14,
      "name": "Rock_Shale_Brick_Wall",
      "rotation": 3
    },
    {
      "x": -23,
      "y": 0,
      "z": 15,
      "name": "Soil_Grass_Cold",
      "rotation": 2
    },
    {
      "x": -23,
      "y": 1,
      "z": 15,
      "name": "Rock_Shale_Brick",
      "rotation": 2
    },
    {
      "x": -23,
      "y": 2,
      "z": 15,
      "name": "Rock_Shale_Brick",
      "rotation": 2
    },
    {
      "x": -23,
      "y": 3,
      "z": 15,
      "name": "Rock_Shale_Brick",
      "rotation": 2
    },
    {
      "x": -23,
      "y": 4,
      "z": 15,
      "name": "*Rock_Shale_Brick_Wall_State_Definitions_Corner",
      "rotation": 2
    },
    {
      "x": -22,
      "y": 0,
      "z": -17,
      "name": "Soil_Grass_Cold",
      "rotation": 2
    },
    {
      "x": -22,
      "y": 1,
      "z": -17,
      "name": "Rock_Shale_Brick",
      "rotation": 2
    },
    {
      "x": -22,
      "y": 2,
      "z": -17,
      "name": "Rock_Shale_Brick",
      "rotation": 2
    },
    {
      "x": -22,
      "y": 3,
      "z": -17,
      "name": "Rock_Shale_Brick",
      "rotation": 2
    },
    {
      "x": -22,
      "y": 4,
      "z": -17,
      "name": "*Rock_Shale_Brick_Wall_State_Definitions_Corner",
      "rotation": 1
    },
    {
      "x": -22,
      "y": 0,
      "z": -16,
      "name": "Soil_Grass_Cold",
      "rotation": 2
    },
    {
      "x": -22,
      "y": 1,
      "z": -16,
      "name": "Rock_Shale_Brick",
      "rotation": 2
    },
    {
      "x": -22,
      "y": 2,
      "z": -16,
      "name": "Rock_Shale_Brick",
      "rotation": 2
    },
    {
      "x": -22,
      "y": 3,
      "z": -16,
      "name": "Rock_Shale_Brick",
      "rotation": 2
    },
    {
      "x": -22,
      "y": 4,
      "z": -16,
      "name": "Rock_Shale_Brick_Wall",
      "rotation": 3
    },
    {
      "x": -22,
      "y": 0,
      "z": -15,
      "name": "Soil_Grass_Cold",
      "rotation": 2
    },
    {
      "x": -22,
      "y": 1,
      "z": -15,
      "name": "Rock_Shale_Brick",
      "rotation": 2
    },
    {
      "x": -22,
      "y": 2,
      "z": -15,
      "name": "Rock_Shale_Brick",
      "rotation": 2
    },
    {
      "x": -22,
      "y": 3,
      "z": -15,
      "name": "Rock_Shale_Brick",
      "rotation": 2
    },
    {
      "x": -22,
      "y": 4,
      "z": -15,
      "name": "*Rock_Shale_Brick_Wall_State_Definitions_Corner",
      "rotation": 3
    },
    {
      "x": -22,
      "y": 0,
      "z": -14,
      "name": "Soil_Grass_Cold",
      "rotation": 2
    },
    {
      "x": -22,
      "y": 0,
      "z": -13,
      "name": "Soil_Grass_Cold",
      "rotation": 2
    },
    {
      "x": -22,
      "y": 0,
      "z": -12,
      "name": "Soil_Grass_Cold",
      "rotation": 2
    },
    {
      "x": -22,
      "y": 0,
      "z": -11,
      "name": "Soil_Grass_Cold",
      "rotation": 2
    },
    {
      "x": -22,
      "y": 0,
      "z": -10,
      "name": "Soil_Grass_Cold",
      "rotation": 2
    },
    {
      "x": -22,
      "y": 0,
      "z": -9,
      "name": "Soil_Grass_Cold",
      "rotation": 2
    },
    {
      "x": -22,
      "y": 0,
      "z": -8,
      "name": "Soil_Grass_Cold",
      "rotation": 2
    },
    {
      "x": -22,
      "y": 0,
      "z": -7,
      "name": "Soil_Grass_Cold",
      "rotation": 2
    },
    {
      "x": -22,
      "y": 0,
      "z": -6,
      "name": "Soil_Grass_Cold",
      "rotation": 2
    },
    {
      "x": -22,
      "y": 0,
      "z": -5,
      "name": "Soil_Grass_Cold",
      "rotation": 2
    },
    {
      "x": -22,
      "y": 1,
      "z": -5,
      "name": "Wood_Darkwood_Fence",
      "rotation": 2
    },
    {
      "x": -22,
      "y": 0,
      "z": -4,
      "name": "Soil_Grass_Cold",
      "rotation": 2
    },
    {
      "x": -22,
      "y": 0,
      "z": -3,
      "name": "Soil_Grass_Cold",
      "rotation": 2
    },
    {
      "x": -22,
      "y": 0,
      "z": -2,
      "name": "Soil_Grass_Cold",
      "rotation": 2
    },
    {
      "x": -22,
      "y": 0,
      "z": -1,
      "name": "Soil_Grass_Cold",
      "rotation": 2
    },
    {
      "x": -22,
      "y": 0,
      "z": 0,
      "name": "Soil_Grass_Cold",
      "rotation": 2
    },
    {
      "x": -22,
      "y": 0,
      "z": 1,
      "name": "Soil_Grass_Cold",
      "rotation": 2
    },
    {
      "x": -22,
      "y": 0,
      "z": 2,
      "name": "Soil_Grass_Cold",
      "rotation": 2
    },
    {
      "x": -22,
      "y": 0,
      "z": 3,
      "name": "Soil_Grass_Cold",
      "rotation": 2
    },
    {
      "x": -22,
      "y": 0,
      "z": 4,
      "name": "Soil_Grass_Cold",
      "rotation": 2
    },
    {
      "x": -22,
      "y": 0,
      "z": 5,
      "name": "Soil_Grass_Cold",
      "rotation": 2
    },
    {
      "x": -22,
      "y": 1,
      "z": 5,
      "name": "Wood_Darkwood_Fence",
      "rotation": 2
    },
    {
      "x": -22,
      "y": 0,
      "z": 6,
      "name": "Soil_Grass_Cold",
      "rotation": 2
    },
    {
      "x": -22,
      "y": 0,
      "z": 7,
      "name": "Soil_Grass_Cold",
      "rotation": 2
    },
    {
      "x": -22,
      "y": 0,
      "z": 8,
      "name": "Soil_Grass_Cold",
      "rotation": 2
    },
    {
      "x": -22,
      "y": 0,
      "z": 9,
      "name": "Soil_Grass_Cold",
      "rotation": 2
    },
    {
      "x": -22,
      "y": 0,
      "z": 10,
      "name": "Soil_Grass_Cold",
      "rotation": 2
    },
    {
      "x": -22,
      "y": 0,
      "z": 11,
      "name": "Soil_Grass_Cold",
      "rotation": 2
    },
    {
      "x": -22,
      "y": 0,
      "z": 12,
      "name": "Soil_Grass_Cold",
      "rotation": 2
    },
    {
      "x": -22,
      "y": 0,
      "z": 13,
      "name": "Soil_Grass_Cold",
      "rotation": 2
    },
    {
      "x": -22,
      "y": 0,
      "z": 14,
      "name": "Soil_Grass_Cold",
      "rotation": 2
    },
    {
      "x": -22,
      "y": 0,
      "z": 15,
      "name": "Soil_Grass_Cold",
      "rotation": 2
    },
    {
      "x": -22,
      "y": 1,
      "z": 15,
      "name": "Rock_Shale_Brick",
      "rotation": 2
    },
    {
      "x": -22,
      "y": 2,
      "z": 15,
      "name": "Rock_Shale_Brick",
      "rotation": 2
    },
    {
      "x": -22,
      "y": 3,
      "z": 15,
      "name": "Rock_Shale_Brick",
      "rotation": 2
    },
    {
      "x": -22,
      "y": 4,
      "z": 15,
      "name": "*Rock_Shale_Brick_Wall_State_Definitions_Corner"
    },
    {
      "x": -22,
      "y": 0,
      "z": 16,
      "name": "Soil_Grass_Cold",
      "rotation": 2
    },
    {
      "x": -22,
      "y": 1,
      "z": 16,
      "name": "Rock_Shale_Brick",
      "rotation": 2
    },
    {
      "x": -22,
      "y": 2,
      "z": 16,
      "name": "Rock_Shale_Brick",
      "rotation": 2
    },
    {
      "x": -22,
      "y": 3,
      "z": 16,
      "name": "Rock_Shale_Brick",
      "rotation": 2
    },
    {
      "x": -22,
      "y": 4,
      "z": 16,
      "name": "Rock_Shale_Brick_Wall",
      "rotation": 3
    },
    {
      "x": -22,
      "y": 0,
      "z": 17,
      "name": "Soil_Grass_Cold",
      "rotation": 2
    },
    {
      "x": -22,
      "y": 1,
      "z": 17,
      "name": "Rock_Shale_Brick",
      "rotation": 2
    },
    {
      "x": -22,
      "y": 2,
      "z": 17,
      "name": "Rock_Shale_Brick",
      "rotation": 2
    },
    {
      "x": -22,
      "y": 3,
      "z": 17,
      "name": "Rock_Shale_Brick",
      "rotation": 2
    },
    {
      "x": -22,
      "y": 4,
      "z": 17,
      "name": "*Rock_Shale_Brick_Wall_State_Definitions_Corner",
      "rotation": 2
    },
    {
      "x": -21,
      "y": 0,
      "z": -18,
      "name": "Soil_Grass_Cold",
      "rotation": 2
    },
    {
      "x": -21,
      "y": 1,
      "z": -18,
      "name": "Rock_Shale_Brick",
      "rotation": 2
    },
    {
      "x": -21,
      "y": 2,
      "z": -18,
      "name": "Rock_Shale_Brick",
      "rotation": 2
    },
    {
      "x": -21,
      "y": 3,
      "z": -18,
      "name": "Rock_Shale_Brick",
      "rotation": 2
    },
    {
      "x": -21,
      "y": 4,
      "z": -18,
      "name": "*Rock_Shale_Brick_Wall_State_Definitions_Corner",
      "rotation": 1
    },
    {
      "x": -21,
      "y": 0,
      "z": -17,
      "name": "Soil_Grass_Cold",
      "rotation": 2
    },
    {
      "x": -21,
      "y": 1,
      "z": -17,
      "name": "Rock_Shale_Brick",
      "rotation": 2
    },
    {
      "x": -21,
      "y": 2,
      "z": -17,
      "name": "Rock_Shale_Brick",
      "rotation": 2
    },
    {
      "x": -21,
      "y": 3,
      "z": -17,
      "name": "Rock_Shale_Brick",
      "rotation": 2
    },
    {
      "x": -21,
      "y": 4,
      "z": -17,
      "name": "*Rock_Shale_Brick_Wall_State_Definitions_Corner",
      "rotation": 3
    },
    {
      "x": -21,
      "y": 0,
      "z": -16,
      "name": "Soil_Grass_Cold",
      "rotation": 2
    },
    {
      "x": -21,
      "y": 0,
      "z": -15,
      "name": "Soil_Grass_Cold",
      "rotation": 2
    },
    {
      "x": -21,
      "y": 0,
      "z": -14,
      "name": "Soil_Grass_Cold",
      "rotation": 2
    },
    {
      "x": -21,
      "y": 0,
      "z": -13,
      "name": "Soil_Grass_Cold",
      "rotation": 2
    },
    {
      "x": -21,
      "y": 0,
      "z": -12,
      "name": "Soil_Grass_Cold",
      "rotation": 2
    },
    {
      "x": -21,
      "y": 0,
      "z": -11,
      "name": "Soil_Grass_Cold",
      "rotation": 2
    },
    {
      "x": -21,
      "y": 0,
      "z": -10,
      "name": "Soil_Grass_Cold",
      "rotation": 2
    },
    {
      "x": -21,
      "y": 0,
      "z": -9,
      "name": "Soil_Grass_Cold",
      "rotation": 2
    },
    {
      "x": -21,
      "y": 0,
      "z": -8,
      "name": "Soil_Grass_Cold",
      "rotation": 2
    },
    {
      "x": -21,
      "y": 0,
      "z": -7,
      "name": "Soil_Grass_Cold",
      "rotation": 2
    },
    {
      "x": -21,
      "y": 0,
      "z": -6,
      "name": "Soil_Grass_Cold",
      "rotation": 2
    },
    {
      "x": -21,
      "y": 0,
      "z": -5,
      "name": "Soil_Grass_Cold",
      "rotation": 2
    },
    {
      "x": -21,
      "y": 1,
      "z": -5,
      "name": "Wood_Darkwood_Fence",
      "rotation": 2
    },
    {
      "x": -21,
      "y": 0,
      "z": -4,
      "name": "Soil_Grass_Cold",
      "rotation": 2
    },
    {
      "x": -21,
      "y": 0,
      "z": -3,
      "name": "Soil_Grass_Cold",
      "rotation": 2
    },
    {
      "x": -21,
      "y": 0,
      "z": -2,
      "name": "Soil_Grass_Cold",
      "rotation": 2
    },
    {
      "x": -21,
      "y": 0,
      "z": -1,
      "name": "Soil_Grass_Cold",
      "rotation": 2
    },
    {
      "x": -21,
      "y": 0,
      "z": 0,
      "name": "Soil_Grass_Cold",
      "rotation": 2
    },
    {
      "x": -21,
      "y": 0,
      "z": 1,
      "name": "Soil_Grass_Cold",
      "rotation": 2
    },
    {
      "x": -21,
      "y": 0,
      "z": 2,
      "name": "Soil_Grass_Cold",
      "rotation": 2
    },
    {
      "x": -21,
      "y": 0,
      "z": 3,
      "name": "Soil_Grass_Cold",
      "rotation": 2
    },
    {
      "x": -21,
      "y": 0,
      "z": 4,
      "name": "Soil_Grass_Cold",
      "rotation": 2
    },
    {
      "x": -21,
      "y": 0,
      "z": 5,
      "name": "Soil_Grass_Cold",
      "rotation": 2
    },
    {
      "x": -21,
      "y": 1,
      "z": 5,
      "name": "Wood_Darkwood_Fence",
      "rotation": 2
    },
    {
      "x": -21,
      "y": 0,
      "z": 6,
      "name": "Soil_Grass_Cold",
      "rotation": 2
    },
    {
      "x": -21,
      "y": 0,
      "z": 7,
      "name": "Soil_Grass_Cold",
      "rotation": 2
    },
    {
      "x": -21,
      "y": 0,
      "z": 8,
      "name": "Soil_Grass_Cold",
      "rotation": 2
    },
    {
      "x": -21,
      "y": 0,
      "z": 9,
      "name": "Soil_Grass_Cold",
      "rotation": 2
    },
    {
      "x": -21,
      "y": 0,
      "z": 10,
      "name": "Soil_Grass_Cold",
      "rotation": 2
    },
    {
      "x": -21,
      "y": 0,
      "z": 11,
      "name": "Soil_Grass_Cold",
      "rotation": 2
    },
    {
      "x": -21,
      "y": 0,
      "z": 12,
      "name": "Soil_Grass_Cold",
      "rotation": 2
    },
    {
      "x": -21,
      "y": 0,
      "z": 13,
      "name": "Soil_Grass_Cold",
      "rotation": 2
    },
    {
      "x": -21,
      "y": 0,
      "z": 14,
      "name": "Soil_Grass_Cold",
      "rotation": 2
    },
    {
      "x": -21,
      "y": 0,
      "z": 15,
      "name": "Soil_Grass_Cold",
      "rotation": 2
    },
    {
      "x": -21,
      "y": 0,
      "z": 16,
      "name": "Soil_Grass_Cold",
      "rotation": 2
    },
    {
      "x": -21,
      "y": 0,
      "z": 17,
      "name": "Soil_Grass_Cold",
      "rotation": 2
    },
    {
      "x": -21,
      "y": 1,
      "z": 17,
      "name": "Rock_Shale_Brick",
      "rotation": 2
    },
    {
      "x": -21,
      "y": 2,
      "z": 17,
      "name": "Rock_Shale_Brick",
      "rotation": 2
    },
    {
      "x": -21,
      "y": 3,
      "z": 17,
      "name": "Rock_Shale_Brick",
      "rotation": 2
    },
    {
      "x": -21,
      "y": 4,
      "z": 17,
      "name": "*Rock_Shale_Brick_Wall_State_Definitions_Corner"
    },
    {
      "x": -21,
      "y": 0,
      "z": 18,
      "name": "Soil_Grass_Cold",
      "rotation": 2
    },
    {
      "x": -21,
      "y": 1,
      "z": 18,
      "name": "Rock_Shale_Brick",
      "rotation": 2
    },
    {
      "x": -21,
      "y": 2,
      "z": 18,
      "name": "Rock_Shale_Brick",
      "rotation": 2
    },
    {
      "x": -21,
      "y": 3,
      "z": 18,
      "name": "Rock_Shale_Brick",
      "rotation": 2
    },
    {
      "x": -21,
      "y": 4,
      "z": 18,
      "name": "*Rock_Shale_Brick_Wall_State_Definitions_Corner",
      "rotation": 2
    },
    {
      "x": -20,
      "y": 0,
      "z": -19,
      "name": "Soil_Grass_Cold",
      "rotation": 2
    },
    {
      "x": -20,
      "y": 1,
      "z": -19,
      "name": "Rock_Shale_Brick",
      "rotation": 2
    },
    {
      "x": -20,
      "y": 2,
      "z": -19,
      "name": "Rock_Shale_Brick",
      "rotation": 2
    },
    {
      "x": -20,
      "y": 3,
      "z": -19,
      "name": "Rock_Shale_Brick",
      "rotation": 2
    },
    {
      "x": -20,
      "y": 4,
      "z": -19,
      "name": "*Rock_Shale_Brick_Wall_State_Definitions_Corner",
      "rotation": 1
    },
    {
      "x": -20,
      "y": 0,
      "z": -18,
      "name": "Soil_Grass_Cold",
      "rotation": 2
    },
    {
      "x": -20,
      "y": 1,
      "z": -18,
      "name": "Rock_Shale_Brick",
      "rotation": 2
    },
    {
      "x": -20,
      "y": 2,
      "z": -18,
      "name": "Rock_Shale_Brick",
      "rotation": 2
    },
    {
      "x": -20,
      "y": 3,
      "z": -18,
      "name": "Rock_Shale_Brick",
      "rotation": 2
    },
    {
      "x": -20,
      "y": 4,
      "z": -18,
      "name": "*Rock_Shale_Brick_Wall_State_Definitions_Corner",
      "rotation": 3
    },
    {
      "x": -20,
      "y": 0,
      "z": -17,
      "name": "Soil_Grass_Cold",
      "rotation": 2
    },
    {
      "x": -20,
      "y": 0,
      "z": -16,
      "name": "Soil_Grass_Cold",
      "rotation": 2
    },
    {
      "x": -20,
      "y": 0,
      "z": -15,
      "name": "Soil_Grass_Cold",
      "rotation": 2
    },
    {
      "x": -20,
      "y": 0,
      "z": -14,
      "name": "Soil_Grass_Cold",
      "rotation": 2
    },
    {
      "x": -20,
      "y": 0,
      "z": -13,
      "name": "Soil_Grass_Cold",
      "rotation": 2
    },
    {
      "x": -20,
      "y": 0,
      "z": -12,
      "name": "Soil_Grass_Cold",
      "rotation": 2
    },
    {
      "x": -20,
      "y": 0,
      "z": -11,
      "name": "Soil_Grass_Cold",
      "rotation": 2
    },
    {
      "x": -20,
      "y": 0,
      "z": -10,
      "name": "Soil_Grass_Cold",
      "rotation": 2
    },
    {
      "x": -20,
      "y": 0,
      "z": -9,
      "name": "Soil_Grass_Cold",
      "rotation": 2
    },
    {
      "x": -20,
      "y": 0,
      "z": -8,
      "name": "Soil_Grass_Cold",
      "rotation": 2
    },
    {
      "x": -20,
      "y": 0,
      "z": -7,
      "name": "Soil_Grass_Cold",
      "rotation": 2
    },
    {
      "x": -20,
      "y": 0,
      "z": -6,
      "name": "Soil_Dirt_Cold",
      "rotation": 2
    },
    {
      "x": -20,
      "y": 0,
      "z": -5,
      "name": "Soil_Dirt_Cold",
      "rotation": 2
    },
    {
      "x": -20,
      "y": 1,
      "z": -5,
      "name": "Wood_Darkwood_Fence",
      "rotation": 2
    },
    {
      "x": -20,
      "y": 0,
      "z": -4,
      "name": "Soil_Dirt_Cold",
      "rotation": 2
    },
    {
      "x": -20,
      "y": 0,
      "z": -3,
      "name": "Soil_Dirt_Cold",
      "rotation": 2
    },
    {
      "x": -20,
      "y": 0,
      "z": -2,
      "name": "Soil_Dirt_Cold",
      "rotation": 2
    },
    {
      "x": -20,
      "y": 0,
      "z": -1,
      "name": "Soil_Grass_Cold",
      "rotation": 2
    },
    {
      "x": -20,
      "y": 0,
      "z": 0,
      "name": "Soil_Grass_Cold",
      "rotation": 2
    },
    {
      "x": -20,
      "y": 0,
      "z": 1,
      "name": "Soil_Grass_Cold",
      "rotation": 2
    },
    {
      "x": -20,
      "y": 0,
      "z": 2,
      "name": "Soil_Grass_Cold",
      "rotation": 2
    },
    {
      "x": -20,
      "y": 0,
      "z": 3,
      "name": "Soil_Grass_Cold",
      "rotation": 2
    },
    {
      "x": -20,
      "y": 0,
      "z": 4,
      "name": "Soil_Grass_Cold",
      "rotation": 2
    },
    {
      "x": -20,
      "y": 0,
      "z": 5,
      "name": "Soil_Grass_Cold",
      "rotation": 2
    },
    {
      "x": -20,
      "y": 1,
      "z": 5,
      "name": "Wood_Darkwood_Fence",
      "rotation": 2
    },
    {
      "x": -20,
      "y": 0,
      "z": 6,
      "name": "Soil_Grass_Cold",
      "rotation": 2
    },
    {
      "x": -20,
      "y": 0,
      "z": 7,
      "name": "Soil_Grass_Cold",
      "rotation": 2
    },
    {
      "x": -20,
      "y": 0,
      "z": 8,
      "name": "Soil_Grass_Cold",
      "rotation": 2
    },
    {
      "x": -20,
      "y": 0,
      "z": 9,
      "name": "Soil_Grass_Cold",
      "rotation": 2
    },
    {
      "x": -20,
      "y": 0,
      "z": 10,
      "name": "Soil_Grass_Cold",
      "rotation": 2
    },
    {
      "x": -20,
      "y": 0,
      "z": 11,
      "name": "Soil_Grass_Cold",
      "rotation": 2
    },
    {
      "x": -20,
      "y": 0,
      "z": 12,
      "name": "Soil_Grass_Cold",
      "rotation": 2
    },
    {
      "x": -20,
      "y": 0,
      "z": 13,
      "name": "Soil_Grass_Cold",
      "rotation": 2
    },
    {
      "x": -20,
      "y": 0,
      "z": 14,
      "name": "Soil_Grass_Cold",
      "rotation": 2
    },
    {
      "x": -20,
      "y": 0,
      "z": 15,
      "name": "Soil_Grass_Cold",
      "rotation": 2
    },
    {
      "x": -20,
      "y": 0,
      "z": 16,
      "name": "Soil_Grass_Cold",
      "rotation": 2
    },
    {
      "x": -20,
      "y": 0,
      "z": 17,
      "name": "Soil_Grass_Cold",
      "rotation": 2
    },
    {
      "x": -20,
      "y": 0,
      "z": 18,
      "name": "Soil_Grass_Cold",
      "rotation": 2
    },
    {
      "x": -20,
      "y": 1,
      "z": 18,
      "name": "Rock_Shale_Brick",
      "rotation": 2
    },
    {
      "x": -20,
      "y": 2,
      "z": 18,
      "name": "Rock_Shale_Brick",
      "rotation": 2
    },
    {
      "x": -20,
      "y": 3,
      "z": 18,
      "name": "Rock_Shale_Brick",
      "rotation": 2
    },
    {
      "x": -20,
      "y": 4,
      "z": 18,
      "name": "*Rock_Shale_Brick_Wall_State_Definitions_Corner"
    },
    {
      "x": -20,
      "y": 0,
      "z": 19,
      "name": "Soil_Grass_Cold",
      "rotation": 2
    },
    {
      "x": -20,
      "y": 1,
      "z": 19,
      "name": "Rock_Shale_Brick",
      "rotation": 2
    },
    {
      "x": -20,
      "y": 2,
      "z": 19,
      "name": "Rock_Shale_Brick",
      "rotation": 2
    },
    {
      "x": -20,
      "y": 3,
      "z": 19,
      "name": "Rock_Shale_Brick",
      "rotation": 2
    },
    {
      "x": -20,
      "y": 4,
      "z": 19,
      "name": "*Rock_Shale_Brick_Wall_State_Definitions_Corner",
      "rotation": 2
    },
    {
      "x": -19,
      "y": 0,
      "z": -20,
      "name": "Soil_Grass_Cold",
      "rotation": 2
    },
    {
      "x": -19,
      "y": 1,
      "z": -20,
      "name": "Rock_Shale_Brick",
      "rotation": 2
    },
    {
      "x": -19,
      "y": 2,
      "z": -20,
      "name": "Rock_Shale_Brick",
      "rotation": 2
    },
    {
      "x": -19,
      "y": 3,
      "z": -20,
      "name": "Rock_Shale_Brick",
      "rotation": 2
    },
    {
      "x": -19,
      "y": 4,
      "z": -20,
      "name": "*Rock_Shale_Brick_Wall_State_Definitions_Corner",
      "rotation": 1
    },
    {
      "x": -19,
      "y": 0,
      "z": -19,
      "name": "Soil_Grass_Cold",
      "rotation": 2
    },
    {
      "x": -19,
      "y": 1,
      "z": -19,
      "name": "Rock_Shale_Brick",
      "rotation": 2
    },
    {
      "x": -19,
      "y": 2,
      "z": -19,
      "name": "Rock_Shale_Brick",
      "rotation": 2
    },
    {
      "x": -19,
      "y": 3,
      "z": -19,
      "name": "Rock_Shale_Brick",
      "rotation": 2
    },
    {
      "x": -19,
      "y": 4,
      "z": -19,
      "name": "*Rock_Shale_Brick_Wall_State_Definitions_Corner",
      "rotation": 3
    },
    {
      "x": -19,
      "y": 5,
      "z": -19,
      "name": "Furniture_Crude_Torch",
      "rotation": 2
    },
    {
      "x": -19,
      "y": 0,
      "z": -18,
      "name": "Soil_Grass_Cold",
      "rotation": 2
    },
    {
      "x": -19,
      "y": 0,
      "z": -17,
      "name": "Soil_Grass_Cold",
      "rotation": 2
    },
    {
      "x": -19,
      "y": 0,
      "z": -16,
      "name": "Soil_Grass_Cold",
      "rotation": 2
    },
    {
      "x": -19,
      "y": 0,
      "z": -15,
      "name": "Soil_Grass_Cold",
      "rotation": 2
    },
    {
      "x": -19,
      "y": 0,
      "z": -14,
      "name": "Soil_Grass_Cold",
      "rotation": 2
    },
    {
      "x": -19,
      "y": 0,
      "z": -13,
      "name": "Soil_Grass_Cold",
      "rotation": 2
    },
    {
      "x": -19,
      "y": 0,
      "z": -12,
      "name": "Soil_Grass_Cold",
      "rotation": 2
    },
    {
      "x": -19,
      "y": 0,
      "z": -11,
      "name": "Soil_Grass_Cold",
      "rotation": 2
    },
    {
      "x": -19,
      "y": 0,
      "z": -10,
      "name": "Soil_Grass_Cold",
      "rotation": 2
    },
    {
      "x": -19,
      "y": 0,
      "z": -9,
      "name": "Soil_Grass_Cold",
      "rotation": 2
    },
    {
      "x": -19,
      "y": 0,
      "z": -8,
      "name": "Soil_Grass_Cold",
      "rotation": 2
    },
    {
      "x": -19,
      "y": 0,
      "z": -7,
      "name": "Soil_Dirt_Cold",
      "rotation": 2
    },
    {
      "x": -19,
      "y": 0,
      "z": -6,
      "name": "Soil_Dirt_Cold",
      "rotation": 2
    },
    {
      "x": -19,
      "y": 0,
      "z": -5,
      "name": "Soil_Dirt_Cold",
      "rotation": 2
    },
    {
      "x": -19,
      "y": 1,
      "z": -5,
      "name": "*Wood_Darkwood_Fence_State_Definitions_Corner"
    },
    {
      "x": -19,
      "y": 0,
      "z": -4,
      "name": "Soil_Dirt_Cold",
      "rotation": 2
    },
    {
      "x": -19,
      "y": 1,
      "z": -4,
      "name": "Wood_Darkwood_Fence",
      "rotation": 3
    },
    {
      "x": -19,
      "y": 0,
      "z": -3,
      "name": "Soil_Dirt_Cold",
      "rotation": 2
    },
    {
      "x": -19,
      "y": 1,
      "z": -3,
      "name": "Wood_Darkwood_Fence",
      "rotation": 3
    },
    {
      "x": -19,
      "y": 0,
      "z": -2,
      "name": "Soil_Dirt_Cold",
      "rotation": 2
    },
    {
      "x": -19,
      "y": 1,
      "z": -2,
      "name": "Wood_Darkwood_Fence_Gate",
      "rotation": 1
    },
    {
      "x": -19,
      "y": 0,
      "z": -1,
      "name": "Soil_Dirt_Cold",
      "rotation": 2
    },
    {
      "x": -19,
      "y": 1,
      "z": -1,
      "name": "Wood_Darkwood_Fence",
      "rotation": 3
    },
    {
      "x": -19,
      "y": 0,
      "z": 0,
      "name": "Soil_Dirt_Cold",
      "rotation": 2
    },
    {
      "x": -19,
      "y": 1,
      "z": 0,
      "name": "Wood_Darkwood_Fence",
      "rotation": 3
    },
    {
      "x": -19,
      "y": 0,
      "z": 1,
      "name": "Soil_Dirt_Cold",
      "rotation": 2
    },
    {
      "x": -19,
      "y": 1,
      "z": 1,
      "name": "Wood_Darkwood_Fence",
      "rotation": 3
    },
    {
      "x": -19,
      "y": 0,
      "z": 2,
      "name": "Soil_Dirt_Cold",
      "rotation": 2
    },
    {
      "x": -19,
      "y": 1,
      "z": 2,
      "name": "Wood_Darkwood_Fence",
      "rotation": 3
    },
    {
      "x": -19,
      "y": 0,
      "z": 3,
      "name": "Soil_Dirt_Cold",
      "rotation": 2
    },
    {
      "x": -19,
      "y": 1,
      "z": 3,
      "name": "Wood_Darkwood_Fence",
      "rotation": 3
    },
    {
      "x": -19,
      "y": 0,
      "z": 4,
      "name": "Soil_Dirt_Cold",
      "rotation": 2
    },
    {
      "x": -19,
      "y": 1,
      "z": 4,
      "name": "Wood_Darkwood_Fence",
      "rotation": 3
    },
    {
      "x": -19,
      "y": 0,
      "z": 5,
      "name": "Soil_Dirt_Cold",
      "rotation": 2
    },
    {
      "x": -19,
      "y": 1,
      "z": 5,
      "name": "*Wood_Darkwood_Fence_State_Definitions_Corner",
      "rotation": 3
    },
    {
      "x": -19,
      "y": 0,
      "z": 6,
      "name": "Soil_Dirt_Cold",
      "rotation": 2
    },
    {
      "x": -19,
      "y": 0,
      "z": 7,
      "name": "Soil_Dirt_Cold",
      "rotation": 2
    },
    {
      "x": -19,
      "y": 0,
      "z": 8,
      "name": "Soil_Dirt_Cold",
      "rotation": 2
    },
    {
      "x": -19,
      "y": 0,
      "z": 9,
      "name": "Soil_Grass_Cold",
      "rotation": 2
    },
    {
      "x": -19,
      "y": 0,
      "z": 10,
      "name": "Soil_Grass_Cold",
      "rotation": 2
    },
    {
      "x": -19,
      "y": 0,
      "z": 11,
      "name": "Soil_Grass_Cold",
      "rotation": 2
    },
    {
      "x": -19,
      "y": 0,
      "z": 12,
      "name": "Soil_Grass_Cold",
      "rotation": 2
    },
    {
      "x": -19,
      "y": 0,
      "z": 13,
      "name": "Soil_Grass_Cold",
      "rotation": 2
    },
    {
      "x": -19,
      "y": 0,
      "z": 14,
      "name": "Soil_Grass_Cold",
      "rotation": 2
    },
    {
      "x": -19,
      "y": 0,
      "z": 15,
      "name": "Soil_Grass_Cold",
      "rotation": 2
    },
    {
      "x": -19,
      "y": 0,
      "z": 16,
      "name": "Soil_Grass_Cold",
      "rotation": 2
    },
    {
      "x": -19,
      "y": 0,
      "z": 17,
      "name": "Soil_Grass_Cold",
      "rotation": 2
    },
    {
      "x": -19,
      "y": 0,
      "z": 18,
      "name": "Soil_Grass_Cold",
      "rotation": 2
    },
    {
      "x": -19,
      "y": 0,
      "z": 19,
      "name": "Soil_Grass_Cold",
      "rotation": 2
    },
    {
      "x": -19,
      "y": 1,
      "z": 19,
      "name": "Rock_Shale_Brick",
      "rotation": 2
    },
    {
      "x": -19,
      "y": 2,
      "z": 19,
      "name": "Rock_Shale_Brick",
      "rotation": 2
    },
    {
      "x": -19,
      "y": 3,
      "z": 19,
      "name": "Rock_Shale_Brick",
      "rotation": 2
    },
    {
      "x": -19,
      "y": 4,
      "z": 19,
      "name": "*Rock_Shale_Brick_Wall_State_Definitions_Corner"
    },
    {
      "x": -19,
      "y": 5,
      "z": 19,
      "name": "Furniture_Crude_Torch"
    },
    {
      "x": -19,
      "y": 0,
      "z": 20,
      "name": "Soil_Grass_Cold",
      "rotation": 2
    },
    {
      "x": -19,
      "y": 1,
      "z": 20,
      "name": "Rock_Shale_Brick",
      "rotation": 2
    },
    {
      "x": -19,
      "y": 2,
      "z": 20,
      "name": "Rock_Shale_Brick",
      "rotation": 2
    },
    {
      "x": -19,
      "y": 3,
      "z": 20,
      "name": "Rock_Shale_Brick",
      "rotation": 2
    },
    {
      "x": -19,
      "y": 4,
      "z": 20,
      "name": "*Rock_Shale_Brick_Wall_State_Definitions_Corner",
      "rotation": 2
    },
    {
      "x": -18,
      "y": 0,
      "z": -21,
      "name": "Soil_Grass_Cold",
      "rotation": 2
    },
    {
      "x": -18,
      "y": 1,
      "z": -21,
      "name": "Rock_Shale_Brick",
      "rotation": 2
    },
    {
      "x": -18,
      "y": 2,
      "z": -21,
      "name": "Rock_Shale_Brick",
      "rotation": 2
    },
    {
      "x": -18,
      "y": 3,
      "z": -21,
      "name": "Rock_Shale_Brick",
      "rotation": 2
    },
    {
      "x": -18,
      "y": 4,
      "z": -21,
      "name": "*Rock_Shale_Brick_Wall_State_Definitions_Corner",
      "rotation": 1
    },
    {
      "x": -18,
      "y": 0,
      "z": -20,
      "name": "Soil_Grass_Cold",
      "rotation": 2
    },
    {
      "x": -18,
      "y": 1,
      "z": -20,
      "name": "Rock_Shale_Brick",
      "rotation": 2
    },
    {
      "x": -18,
      "y": 2,
      "z": -20,
      "name": "Rock_Shale_Brick",
      "rotation": 2
    },
    {
      "x": -18,
      "y": 3,
      "z": -20,
      "name": "Rock_Shale_Brick",
      "rotation": 2
    },
    {
      "x": -18,
      "y": 4,
      "z": -20,
      "name": "*Rock_Shale_Brick_Wall_State_Definitions_Corner",
      "rotation": 3
    },
    {
      "x": -18,
      "y": 0,
      "z": -19,
      "name": "Soil_Grass_Cold",
      "rotation": 2
    },
    {
      "x": -18,
      "y": 0,
      "z": -18,
      "name": "Soil_Grass_Cold",
      "rotation": 2
    },
    {
      "x": -18,
      "y": 0,
      "z": -17,
      "name": "Soil_Grass_Cold",
      "rotation": 2
    },
    {
      "x": -18,
      "y": 0,
      "z": -16,
      "name": "Soil_Grass_Cold",
      "rotation": 2
    },
    {
      "x": -18,
      "y": 0,
      "z": -15,
      "name": "Soil_Grass_Cold",
      "rotation": 2
    },
    {
      "x": -18,
      "y": 0,
      "z": -14,
      "name": "Soil_Grass_Cold",
      "rotation": 2
    },
    {
      "x": -18,
      "y": 0,
      "z": -13,
      "name": "Soil_Grass_Cold",
      "rotation": 2
    },
    {
      "x": -18,
      "y": 0,
      "z": -12,
      "name": "Soil_Grass_Cold",
      "rotation": 2
    },
    {
      "x": -18,
      "y": 0,
      "z": -11,
      "name": "Soil_Grass_Cold",
      "rotation": 2
    },
    {
      "x": -18,
      "y": 0,
      "z": -10,
      "name": "Soil_Grass_Cold",
      "rotation": 2
    },
    {
      "x": -18,
      "y": 0,
      "z": -9,
      "name": "Soil_Grass_Cold",
      "rotation": 2
    },
    {
      "x": -18,
      "y": 0,
      "z": -8,
      "name": "Soil_Dirt_Cold",
      "rotation": 2
    },
    {
      "x": -18,
      "y": 0,
      "z": -7,
      "name": "Soil_Dirt_Cold",
      "rotation": 2
    },
    {
      "x": -18,
      "y": 0,
      "z": -6,
      "name": "Soil_Dirt_Cold",
      "rotation": 2
    },
    {
      "x": -18,
      "y": 0,
      "z": -5,
      "name": "Soil_Dirt_Cold",
      "rotation": 2
    },
    {
      "x": -18,
      "y": 0,
      "z": -4,
      "name": "Soil_Dirt_Cold",
      "rotation": 2
    },
    {
      "x": -18,
      "y": 0,
      "z": -3,
      "name": "Soil_Dirt_Cold",
      "rotation": 2
    },
    {
      "x": -18,
      "y": 0,
      "z": -2,
      "name": "Soil_Dirt_Cold",
      "rotation": 2
    },
    {
      "x": -18,
      "y": 0,
      "z": -1,
      "name": "Soil_Dirt_Cold",
      "rotation": 2
    },
    {
      "x": -18,
      "y": 0,
      "z": 0,
      "name": "Soil_Dirt_Cold",
      "rotation": 2
    },
    {
      "x": -18,
      "y": 0,
      "z": 1,
      "name": "Soil_Dirt_Cold",
      "rotation": 2
    },
    {
      "x": -18,
      "y": 0,
      "z": 2,
      "name": "Soil_Dirt_Cold",
      "rotation": 2
    },
    {
      "x": -18,
      "y": 0,
      "z": 3,
      "name": "Soil_Dirt_Cold",
      "rotation": 2
    },
    {
      "x": -18,
      "y": 0,
      "z": 4,
      "name": "Soil_Dirt_Cold",
      "rotation": 2
    },
    {
      "x": -18,
      "y": 0,
      "z": 5,
      "name": "Soil_Dirt_Cold",
      "rotation": 2
    },
    {
      "x": -18,
      "y": 0,
      "z": 6,
      "name": "Soil_Dirt_Cold",
      "rotation": 2
    },
    {
      "x": -18,
      "y": 0,
      "z": 7,
      "name": "Soil_Dirt_Cold",
      "rotation": 2
    },
    {
      "x": -18,
      "y": 0,
      "z": 8,
      "name": "Soil_Dirt_Cold",
      "rotation": 2
    },
    {
      "x": -18,
      "y": 0,
      "z": 9,
      "name": "Soil_Dirt_Cold",
      "rotation": 2
    },
    {
      "x": -18,
      "y": 0,
      "z": 10,
      "name": "Soil_Dirt_Cold",
      "rotation": 2
    },
    {
      "x": -18,
      "y": 0,
      "z": 11,
      "name": "Soil_Grass_Cold",
      "rotation": 2
    },
    {
      "x": -18,
      "y": 0,
      "z": 12,
      "name": "Soil_Grass_Cold",
      "rotation": 2
    },
    {
      "x": -18,
      "y": 0,
      "z": 13,
      "name": "Soil_Grass_Cold",
      "rotation": 2
    },
    {
      "x": -18,
      "y": 0,
      "z": 14,
      "name": "Soil_Grass_Cold",
      "rotation": 2
    },
    {
      "x": -18,
      "y": 0,
      "z": 15,
      "name": "Soil_Grass_Cold",
      "rotation": 2
    },
    {
      "x": -18,
      "y": 0,
      "z": 16,
      "name": "Soil_Grass_Cold",
      "rotation": 2
    },
    {
      "x": -18,
      "y": 0,
      "z": 17,
      "name": "Soil_Grass_Cold",
      "rotation": 2
    },
    {
      "x": -18,
      "y": 0,
      "z": 18,
      "name": "Soil_Grass_Cold",
      "rotation": 2
    },
    {
      "x": -18,
      "y": 0,
      "z": 19,
      "name": "Soil_Grass_Cold",
      "rotation": 2
    },
    {
      "x": -18,
      "y": 0,
      "z": 20,
      "name": "Soil_Grass_Cold",
      "rotation": 2
    },
    {
      "x": -18,
      "y": 1,
      "z": 20,
      "name": "Rock_Shale_Brick",
      "rotation": 2
    },
    {
      "x": -18,
      "y": 2,
      "z": 20,
      "name": "Rock_Shale_Brick",
      "rotation": 2
    },
    {
      "x": -18,
      "y": 3,
      "z": 20,
      "name": "Rock_Shale_Brick",
      "rotation": 2
    },
    {
      "x": -18,
      "y": 4,
      "z": 20,
      "name": "*Rock_Shale_Brick_Wall_State_Definitions_Corner"
    },
    {
      "x": -18,
      "y": 0,
      "z": 21,
      "name": "Soil_Grass_Cold",
      "rotation": 2
    },
    {
      "x": -18,
      "y": 1,
      "z": 21,
      "name": "Rock_Shale_Brick",
      "rotation": 2
    },
    {
      "x": -18,
      "y": 2,
      "z": 21,
      "name": "Rock_Shale_Brick",
      "rotation": 2
    },
    {
      "x": -18,
      "y": 3,
      "z": 21,
      "name": "Rock_Shale_Brick",
      "rotation": 2
    },
    {
      "x": -18,
      "y": 4,
      "z": 21,
      "name": "*Rock_Shale_Brick_Wall_State_Definitions_Corner",
      "rotation": 2
    },
    {
      "x": -17,
      "y": 0,
      "z": -22,
      "name": "Soil_Grass_Cold",
      "rotation": 2
    },
    {
      "x": -17,
      "y": 1,
      "z": -22,
      "name": "Rock_Shale_Brick",
      "rotation": 2
    },
    {
      "x": -17,
      "y": 2,
      "z": -22,
      "name": "Rock_Shale_Brick",
      "rotation": 2
    },
    {
      "x": -17,
      "y": 3,
      "z": -22,
      "name": "Rock_Shale_Brick",
      "rotation": 2
    },
    {
      "x": -17,
      "y": 4,
      "z": -22,
      "name": "*Rock_Shale_Brick_Wall_State_Definitions_Corner",
      "rotation": 1
    },
    {
      "x": -17,
      "y": 0,
      "z": -21,
      "name": "Soil_Grass_Cold",
      "rotation": 2
    },
    {
      "x": -17,
      "y": 1,
      "z": -21,
      "name": "Rock_Shale_Brick",
      "rotation": 2
    },
    {
      "x": -17,
      "y": 2,
      "z": -21,
      "name": "Rock_Shale_Brick",
      "rotation": 2
    },
    {
      "x": -17,
      "y": 3,
      "z": -21,
      "name": "Rock_Shale_Brick",
      "rotation": 2
    },
    {
      "x": -17,
      "y": 4,
      "z": -21,
      "name": "*Rock_Shale_Brick_Wall_State_Definitions_Corner",
      "rotation": 3
    },
    {
      "x": -17,
      "y": 0,
      "z": -20,
      "name": "Soil_Grass_Cold",
      "rotation": 2
    },
    {
      "x": -17,
      "y": 0,
      "z": -19,
      "name": "Soil_Grass_Cold",
      "rotation": 2
    },
    {
      "x": -17,
      "y": 0,
      "z": -18,
      "name": "Soil_Grass_Cold",
      "rotation": 2
    },
    {
      "x": -17,
      "y": 0,
      "z": -17,
      "name": "Soil_Grass_Cold",
      "rotation": 2
    },
    {
      "x": -17,
      "y": 0,
      "z": -16,
      "name": "Soil_Grass_Cold",
      "rotation": 2
    },
    {
      "x": -17,
      "y": 0,
      "z": -15,
      "name": "Soil_Grass_Cold",
      "rotation": 2
    },
    {
      "x": -17,
      "y": 0,
      "z": -14,
      "name": "Soil_Grass_Cold",
      "rotation": 2
    },
    {
      "x": -17,
      "y": 0,
      "z": -13,
      "name": "Soil_Grass_Cold",
      "rotation": 2
    },
    {
      "x": -17,
      "y": 0,
      "z": -12,
      "name": "Soil_Grass_Cold",
      "rotation": 2
    },
    {
      "x": -17,
      "y": 0,
      "z": -11,
      "name": "Soil_Dirt_Cold",
      "rotation": 2
    },
    {
      "x": -17,
      "y": 0,
      "z": -10,
      "name": "Soil_Dirt_Cold",
      "rotation": 2
    },
    {
      "x": -17,
      "y": 0,
      "z": -9,
      "name": "Soil_Dirt_Cold",
      "rotation": 2
    },
    {
      "x": -17,
      "y": 0,
      "z": -8,
      "name": "Soil_Dirt_Cold",
      "rotation": 2
    },
    {
      "x": -17,
      "y": 0,
      "z": -7,
      "name": "Soil_Dirt_Cold",
      "rotation": 2
    },
    {
      "x": -17,
      "y": 0,
      "z": -6,
      "name": "Soil_Dirt_Cold",
      "rotation": 2
    },
    {
      "x": -17,
      "y": 0,
      "z": -5,
      "name": "Soil_Grass_Cold",
      "rotation": 2
    },
    {
      "x": -17,
      "y": 0,
      "z": -4,
      "name": "Soil_Grass_Cold",
      "rotation": 2
    },
    {
      "x": -17,
      "y": 0,
      "z": -3,
      "name": "Soil_Grass_Cold",
      "rotation": 2
    },
    {
      "x": -17,
      "y": 0,
      "z": -2,
      "name": "Soil_Grass_Cold",
      "rotation": 2
    },
    {
      "x": -17,
      "y": 0,
      "z": -1,
      "name": "Soil_Dirt_Cold",
      "rotation": 2
    },
    {
      "x": -17,
      "y": 0,
      "z": 0,
      "name": "Soil_Dirt_Cold",
      "rotation": 2
    },
    {
      "x": -17,
      "y": 0,
      "z": 1,
      "name": "Soil_Dirt_Cold",
      "rotation": 2
    },
    {
      "x": -17,
      "y": 0,
      "z": 2,
      "name": "Soil_Dirt_Cold",
      "rotation": 2
    },
    {
      "x": -17,
      "y": 0,
      "z": 3,
      "name": "Soil_Dirt_Cold",
      "rotation": 2
    },
    {
      "x": -17,
      "y": 0,
      "z": 4,
      "name": "Soil_Dirt_Cold",
      "rotation": 2
    },
    {
      "x": -17,
      "y": 0,
      "z": 5,
      "name": "Soil_Dirt_Cold",
      "rotation": 2
    },
    {
      "x": -17,
      "y": 0,
      "z": 6,
      "name": "Soil_Dirt_Cold",
      "rotation": 2
    },
    {
      "x": -17,
      "y": 0,
      "z": 7,
      "name": "Soil_Dirt_Cold",
      "rotation": 2
    },
    {
      "x": -17,
      "y": 0,
      "z": 8,
      "name": "Soil_Dirt_Cold",
      "rotation": 2
    },
    {
      "x": -17,
      "y": 0,
      "z": 9,
      "name": "Soil_Dirt_Cold",
      "rotation": 2
    },
    {
      "x": -17,
      "y": 0,
      "z": 10,
      "name": "Soil_Dirt_Cold",
      "rotation": 2
    },
    {
      "x": -17,
      "y": 0,
      "z": 11,
      "name": "Soil_Dirt_Cold",
      "rotation": 2
    },
    {
      "x": -17,
      "y": 0,
      "z": 12,
      "name": "Soil_Grass_Cold",
      "rotation": 2
    },
    {
      "x": -17,
      "y": 0,
      "z": 13,
      "name": "Soil_Grass_Cold",
      "rotation": 2
    },
    {
      "x": -17,
      "y": 0,
      "z": 14,
      "name": "Soil_Grass_Cold",
      "rotation": 2
    },
    {
      "x": -17,
      "y": 0,
      "z": 15,
      "name": "Soil_Grass_Cold",
      "rotation": 2
    },
    {
      "x": -17,
      "y": 0,
      "z": 16,
      "name": "Soil_Grass_Cold",
      "rotation": 2
    },
    {
      "x": -17,
      "y": 0,
      "z": 17,
      "name": "Soil_Grass_Cold",
      "rotation": 2
    },
    {
      "x": -17,
      "y": 0,
      "z": 18,
      "name": "Soil_Grass_Cold",
      "rotation": 2
    },
    {
      "x": -17,
      "y": 0,
      "z": 19,
      "name": "Soil_Grass_Cold",
      "rotation": 2
    },
    {
      "x": -17,
      "y": 0,
      "z": 20,
      "name": "Soil_Grass_Cold",
      "rotation": 2
    },
    {
      "x": -17,
      "y": 0,
      "z": 21,
      "name": "Soil_Grass_Cold",
      "rotation": 2
    },
    {
      "x": -17,
      "y": 1,
      "z": 21,
      "name": "Rock_Shale_Brick",
      "rotation": 2
    },
    {
      "x": -17,
      "y": 2,
      "z": 21,
      "name": "Rock_Shale_Brick",
      "rotation": 2
    },
    {
      "x": -17,
      "y": 3,
      "z": 21,
      "name": "Rock_Shale_Brick",
      "rotation": 2
    },
    {
      "x": -17,
      "y": 4,
      "z": 21,
      "name": "*Rock_Shale_Brick_Wall_State_Definitions_Corner"
    },
    {
      "x": -17,
      "y": 0,
      "z": 22,
      "name": "Soil_Grass_Cold",
      "rotation": 2
    },
    {
      "x": -17,
      "y": 1,
      "z": 22,
      "name": "Rock_Shale_Brick",
      "rotation": 2
    },
    {
      "x": -17,
      "y": 2,
      "z": 22,
      "name": "Rock_Shale_Brick",
      "rotation": 2
    },
    {
      "x": -17,
      "y": 3,
      "z": 22,
      "name": "Rock_Shale_Brick",
      "rotation": 2
    },
    {
      "x": -17,
      "y": 4,
      "z": 22,
      "name": "*Rock_Shale_Brick_Wall_State_Definitions_Corner",
      "rotation": 2
    },
    {
      "x": -16,
      "y": 0,
      "z": -22,
      "name": "Soil_Grass_Cold",
      "rotation": 2
    },
    {
      "x": -16,
      "y": 1,
      "z": -22,
      "name": "Rock_Shale_Brick",
      "rotation": 2
    },
    {
      "x": -16,
      "y": 2,
      "z": -22,
      "name": "Rock_Shale_Brick",
      "rotation": 2
    },
    {
      "x": -16,
      "y": 3,
      "z": -22,
      "name": "Rock_Shale_Brick",
      "rotation": 2
    },
    {
      "x": -16,
      "y": 4,
      "z": -22,
      "name": "Rock_Shale_Brick_Wall",
      "rotation": 2
    },
    {
      "x": -16,
      "y": 0,
      "z": -21,
      "name": "Soil_Grass_Cold",
      "rotation": 2
    },
    {
      "x": -16,
      "y": 0,
      "z": -20,
      "name": "Soil_Grass_Cold",
      "rotation": 2
    },
    {
      "x": -16,
      "y": 0,
      "z": -19,
      "name": "Soil_Grass_Cold",
      "rotation": 2
    },
    {
      "x": -16,
      "y": 0,
      "z": -18,
      "name": "Soil_Grass_Cold",
      "rotation": 2
    },
    {
      "x": -16,
      "y": 0,
      "z": -17,
      "name": "Soil_Grass_Cold",
      "rotation": 2
    },
    {
      "x": -16,
      "y": 0,
      "z": -16,
      "name": "Soil_Grass_Cold",
      "rotation": 2
    },
    {
      "x": -16,
      "y": 1,
      "z": -16,
      "name": "Rock_Shale_Brick"
    },
    {
      "x": -16,
      "y": 2,
      "z": -16,
      "name": "Rock_Shale_Brick_Beam"
    },
    {
      "x": -16,
      "y": 3,
      "z": -16,
      "name": "Rock_Shale_Brick_Beam"
    },
    {
      "x": -16,
      "y": 4,
      "z": -16,
      "name": "*Rock_Slate_Cobble_Roof_Hollow_State_Definitions_Corner_Right",
      "rotation": 3
    },
    {
      "x": -16,
      "y": 0,
      "z": -15,
      "name": "Soil_Grass_Cold",
      "rotation": 2
    },
    {
      "x": -16,
      "y": 4,
      "z": -15,
      "name": "Rock_Slate_Cobble_Roof_Hollow",
      "rotation": 3
    },
    {
      "x": -16,
      "y": 0,
      "z": -14,
      "name": "Soil_Grass_Cold",
      "rotation": 2
    },
    {
      "x": -16,
      "y": 1,
      "z": -14,
      "name": "Rock_Shale_Brick"
    },
    {
      "x": -16,
      "y": 2,
      "z": -14,
      "name": "Rock_Shale_Brick_Beam"
    },
    {
      "x": -16,
      "y": 3,
      "z": -14,
      "name": "Rock_Shale_Brick_Beam"
    },
    {
      "x": -16,
      "y": 4,
      "z": -14,
      "name": "*Rock_Slate_Cobble_Roof_Hollow_State_Definitions_Corner_Left",
      "rotation": 3
    },
    {
      "x": -16,
      "y": 0,
      "z": -13,
      "name": "Soil_Dirt_Cold",
      "rotation": 2
    },
    {
      "x": -16,
      "y": 0,
      "z": -12,
      "name": "Soil_Dirt_Cold",
      "rotation": 2
    },
    {
      "x": -16,
      "y": 42,
      "z": -12,
      "name": "Wood_Fir_Trunk",
      "support": 15,
      "rotation": 5
    },
    {
      "x": -16,
      "y": 43,
      "z": -12,
      "name": "Rock_Slate_Cobble_Roof_Shallow",
      "rotation": 3
    },
    {
      "x": -16,
      "y": 0,
      "z": -11,
      "name": "Soil_Dirt_Cold",
      "rotation": 2
    },
    {
      "x": -16,
      "y": 43,
      "z": -11,
      "name": "Rock_Slate_Cobble_Roof_Shallow",
      "rotation": 3
    },
    {
      "x": -16,
      "y": 0,
      "z": -10,
      "name": "Soil_Dirt_Cold",
      "rotation": 2
    },
    {
      "x": -16,
      "y": 43,
      "z": -10,
      "name": "Rock_Slate_Cobble_Roof_Shallow",
      "rotation": 3
    },
    {
      "x": -16,
      "y": 0,
      "z": -9,
      "name": "Soil_Dirt_Cold",
      "rotation": 2
    },
    {
      "x": -16,
      "y": 43,
      "z": -9,
      "name": "Rock_Slate_Cobble_Roof_Shallow",
      "rotation": 3
    },
    {
      "x": -16,
      "y": 0,
      "z": -8,
      "name": "Soil_Dirt_Cold",
      "rotation": 2
    },
    {
      "x": -16,
      "y": 42,
      "z": -8,
      "name": "Wood_Fir_Trunk",
      "support": 15,
      "rotation": 5
    },
    {
      "x": -16,
      "y": 43,
      "z": -8,
      "name": "Rock_Slate_Cobble_Roof_Shallow",
      "rotation": 3
    },
    {
      "x": -16,
      "y": 0,
      "z": -7,
      "name": "Soil_Dirt_Cold",
      "rotation": 2
    },
    {
      "x": -16,
      "y": 0,
      "z": -6,
      "name": "Soil_Grass_Cold",
      "rotation": 2
    },
    {
      "x": -16,
      "y": 0,
      "z": -5,
      "name": "Soil_Grass_Cold",
      "rotation": 2
    },
    {
      "x": -16,
      "y": 0,
      "z": -4,
      "name": "Soil_Grass_Cold",
      "rotation": 2
    },
    {
      "x": -16,
      "y": 0,
      "z": -3,
      "name": "Soil_Grass_Cold",
      "rotation": 2
    },
    {
      "x": -16,
      "y": 0,
      "z": -2,
      "name": "Soil_Grass_Cold",
      "rotation": 2
    },
    {
      "x": -16,
      "y": 0,
      "z": -1,
      "name": "Soil_Grass_Cold",
      "rotation": 2
    },
    {
      "x": -16,
      "y": 0,
      "z": 0,
      "name": "Soil_Grass_Cold",
      "rotation": 2
    },
    {
      "x": -16,
      "y": 0,
      "z": 1,
      "name": "Soil_Grass_Cold",
      "rotation": 2
    },
    {
      "x": -16,
      "y": 0,
      "z": 2,
      "name": "Soil_Grass_Cold",
      "rotation": 2
    },
    {
      "x": -16,
      "y": 0,
      "z": 3,
      "name": "Soil_Grass_Cold",
      "rotation": 2
    },
    {
      "x": -16,
      "y": 0,
      "z": 4,
      "name": "Soil_Grass_Cold",
      "rotation": 2
    },
    {
      "x": -16,
      "y": 0,
      "z": 5,
      "name": "Soil_Grass_Cold",
      "rotation": 2
    },
    {
      "x": -16,
      "y": 0,
      "z": 6,
      "name": "Soil_Dirt_Cold",
      "rotation": 2
    },
    {
      "x": -16,
      "y": 0,
      "z": 7,
      "name": "Soil_Dirt_Cold",
      "rotation": 2
    },
    {
      "x": -16,
      "y": 0,
      "z": 8,
      "name": "Soil_Dirt_Cold",
      "rotation": 2
    },
    {
      "x": -16,
      "y": 0,
      "z": 9,
      "name": "Soil_Dirt_Cold",
      "rotation": 2
    },
    {
      "x": -16,
      "y": 0,
      "z": 10,
      "name": "Soil_Dirt_Cold",
      "rotation": 2
    },
    {
      "x": -16,
      "y": 0,
      "z": 11,
      "name": "Soil_Dirt_Cold",
      "rotation": 2
    },
    {
      "x": -16,
      "y": 0,
      "z": 12,
      "name": "Soil_Dirt_Cold",
      "rotation": 2
    },
    {
      "x": -16,
      "y": 0,
      "z": 13,
      "name": "Soil_Grass_Cold",
      "rotation": 2
    },
    {
      "x": -16,
      "y": 0,
      "z": 14,
      "name": "Soil_Grass_Cold",
      "rotation": 2
    },
    {
      "x": -16,
      "y": 0,
      "z": 15,
      "name": "Soil_Grass_Cold",
      "rotation": 2
    },
    {
      "x": -16,
      "y": 0,
      "z": 16,
      "name": "Soil_Grass_Cold",
      "rotation": 2
    },
    {
      "x": -16,
      "y": 0,
      "z": 17,
      "name": "Soil_Grass_Cold",
      "rotation": 2
    },
    {
      "x": -16,
      "y": 0,
      "z": 18,
      "name": "Soil_Grass_Cold",
      "rotation": 2
    },
    {
      "x": -16,
      "y": 0,
      "z": 19,
      "name": "Soil_Grass_Cold",
      "rotation": 2
    },
    {
      "x": -16,
      "y": 0,
      "z": 20,
      "name": "Soil_Grass_Cold",
      "rotation": 2
    },
    {
      "x": -16,
      "y": 0,
      "z": 21,
      "name": "Soil_Grass_Cold",
      "rotation": 2
    },
    {
      "x": -16,
      "y": 0,
      "z": 22,
      "name": "Soil_Grass_Cold",
      "rotation": 2
    },
    {
      "x": -16,
      "y": 1,
      "z": 22,
      "name": "Rock_Shale_Brick",
      "rotation": 2
    },
    {
      "x": -16,
      "y": 2,
      "z": 22,
      "name": "Rock_Shale_Brick",
      "rotation": 2
    },
    {
      "x": -16,
      "y": 3,
      "z": 22,
      "name": "Rock_Shale_Brick",
      "rotation": 2
    },
    {
      "x": -16,
      "y": 4,
      "z": 22,
      "name": "Rock_Shale_Brick_Wall",
      "rotation": 2
    },
    {
      "x": -15,
      "y": 0,
      "z": -23,
      "name": "Soil_Grass_Cold",
      "rotation": 2
    },
    {
      "x": -15,
      "y": 1,
      "z": -23,
      "name": "Rock_Shale_Brick",
      "rotation": 2
    },
    {
      "x": -15,
      "y": 2,
      "z": -23,
      "name": "Rock_Shale_Brick",
      "rotation": 2
    },
    {
      "x": -15,
      "y": 3,
      "z": -23,
      "name": "Rock_Shale_Brick",
      "rotation": 2
    },
    {
      "x": -15,
      "y": 4,
      "z": -23,
      "name": "*Rock_Shale_Brick_Wall_State_Definitions_Corner",
      "rotation": 1
    },
    {
      "x": -15,
      "y": 0,
      "z": -22,
      "name": "Soil_Grass_Cold",
      "rotation": 2
    },
    {
      "x": -15,
      "y": 1,
      "z": -22,
      "name": "Rock_Shale_Brick",
      "rotation": 2
    },
    {
      "x": -15,
      "y": 2,
      "z": -22,
      "name": "Rock_Shale_Brick",
      "rotation": 2
    },
    {
      "x": -15,
      "y": 3,
      "z": -22,
      "name": "Rock_Shale_Brick",
      "rotation": 2
    },
    {
      "x": -15,
      "y": 4,
      "z": -22,
      "name": "*Rock_Shale_Brick_Wall_State_Definitions_Corner",
      "rotation": 3
    },
    {
      "x": -15,
      "y": 0,
      "z": -21,
      "name": "Soil_Grass_Cold",
      "rotation": 2
    },
    {
      "x": -15,
      "y": 0,
      "z": -20,
      "name": "Soil_Grass_Cold",
      "rotation": 2
    },
    {
      "x": -15,
      "y": 0,
      "z": -19,
      "name": "Soil_Grass_Cold",
      "rotation": 2
    },
    {
      "x": -15,
      "y": 0,
      "z": -18,
      "name": "Soil_Grass_Cold",
      "rotation": 2
    },
    {
      "x": -15,
      "y": 0,
      "z": -17,
      "name": "Soil_Grass_Cold",
      "rotation": 2
    },
    {
      "x": -15,
      "y": 0,
      "z": -16,
      "name": "Soil_Grass_Cold",
      "rotation": 2
    },
    {
      "x": -15,
      "y": 4,
      "z": -16,
      "name": "Rock_Slate_Cobble_Roof_Hollow",
      "rotation": 2
    },
    {
      "x": -15,
      "y": 0,
      "z": -15,
      "name": "Soil_Grass_Cold",
      "rotation": 2
    },
    {
      "x": -15,
      "y": 3,
      "z": -15,
      "name": "Deco_Lantern_Ceiling"
    },
    {
      "x": -15,
      "y": 4,
      "z": -15,
      "name": "Deco_Iron_Chain_Small"
    },
    {
      "x": -15,
      "y": 5,
      "z": -15,
      "name": "*Rock_Slate_Cobble_Roof_State_Definitions_Topper"
    },
    {
      "x": -15,
      "y": 43,
      "z": -15,
      "name": "*Rock_Slate_Cobble_Roof_Hollow_State_Definitions_Corner_Right",
      "rotation": 3
    },
    {
      "x": -15,
      "y": 0,
      "z": -14,
      "name": "Soil_Dirt_Cold",
      "rotation": 2
    },
    {
      "x": -15,
      "y": 4,
      "z": -14,
      "name": "Rock_Slate_Cobble_Roof_Hollow"
    },
    {
      "x": -15,
      "y": 43,
      "z": -14,
      "name": "Rock_Slate_Cobble_Roof_Hollow",
      "rotation": 3
    },
    {
      "x": -15,
      "y": 0,
      "z": -13,
      "name": "Soil_Dirt_Cold",
      "rotation": 2
    },
    {
      "x": -15,
      "y": 43,
      "z": -13,
      "name": "Rock_Slate_Cobble_Roof_Hollow",
      "rotation": 3
    },
    {
      "x": -15,
      "y": 0,
      "z": -12,
      "name": "Soil_Dirt_Cold",
      "rotation": 2
    },
    {
      "x": -15,
      "y": 37,
      "z": -12,
      "name": "Rock_Shale_Brick"
    },
    {
      "x": -15,
      "y": 38,
      "z": -12,
      "name": "Rock_Shale_Brick_Pillar_Base"
    },
    {
      "x": -15,
      "y": 39,
      "z": -12,
      "name": "Rock_Shale_Brick_Pillar_Middle"
    },
    {
      "x": -15,
      "y": 40,
      "z": -12,
      "name": "Rock_Shale_Brick_Pillar_Middle"
    },
    {
      "x": -15,
      "y": 41,
      "z": -12,
      "name": "Rock_Shale_Brick_Pillar_Middle"
    },
    {
      "x": -15,
      "y": 42,
      "z": -12,
      "name": "Wood_Fir_Trunk",
      "support": 15,
      "rotation": 5
    },
    {
      "x": -15,
      "y": 43,
      "z": -12,
      "name": "Rock_Slate_Cobble_Roof_Shallow",
      "filler": 1,
      "rotation": 3
    },
    {
      "x": -15,
      "y": 0,
      "z": -11,
      "name": "Soil_Dirt_Cold",
      "rotation": 2
    },
    {
      "x": -15,
      "y": 36,
      "z": -11,
      "name": "Rock_Shale_Brick"
    },
    {
      "x": -15,
      "y": 37,
      "z": -11,
      "name": "Rock_Shale_Brick"
    },
    {
      "x": -15,
      "y": 38,
      "z": -11,
      "name": "Rock_Shale_Brick_Wall",
      "rotation": 1
    },
    {
      "x": -15,
      "y": 43,
      "z": -11,
      "name": "Rock_Slate_Cobble_Roof_Shallow",
      "filler": 1,
      "rotation": 3
    },
    {
      "x": -15,
      "y": 0,
      "z": -10,
      "name": "Soil_Dirt_Cold",
      "rotation": 2
    },
    {
      "x": -15,
      "y": 35,
      "z": -10,
      "name": "Rock_Shale_Brick"
    },
    {
      "x": -15,
      "y": 36,
      "z": -10,
      "name": "Rock_Shale_Brick"
    },
    {
      "x": -15,
      "y": 37,
      "z": -10,
      "name": "Rock_Shale_Brick"
    },
    {
      "x": -15,
      "y": 38,
      "z": -10,
      "name": "Rock_Shale_Brick_Wall",
      "rotation": 1
    },
    {
      "x": -15,
      "y": 43,
      "z": -10,
      "name": "Rock_Slate_Cobble_Roof_Shallow",
      "filler": 1,
      "rotation": 3
    },
    {
      "x": -15,
      "y": 0,
      "z": -9,
      "name": "Soil_Dirt_Cold",
      "rotation": 2
    },
    {
      "x": -15,
      "y": 36,
      "z": -9,
      "name": "Rock_Shale_Brick"
    },
    {
      "x": -15,
      "y": 37,
      "z": -9,
      "name": "Rock_Shale_Brick"
    },
    {
      "x": -15,
      "y": 38,
      "z": -9,
      "name": "Rock_Shale_Brick_Wall",
      "rotation": 1
    },
    {
      "x": -15,
      "y": 43,
      "z": -9,
      "name": "Rock_Slate_Cobble_Roof_Shallow",
      "filler": 1,
      "rotation": 3
    },
    {
      "x": -15,
      "y": 0,
      "z": -8,
      "name": "Soil_Dirt_Cold",
      "rotation": 2
    },
    {
      "x": -15,
      "y": 37,
      "z": -8,
      "name": "Rock_Shale_Brick"
    },
    {
      "x": -15,
      "y": 38,
      "z": -8,
      "name": "Rock_Shale_Brick_Pillar_Base"
    },
    {
      "x": -15,
      "y": 39,
      "z": -8,
      "name": "Rock_Shale_Brick_Pillar_Middle"
    },
    {
      "x": -15,
      "y": 40,
      "z": -8,
      "name": "Rock_Shale_Brick_Pillar_Middle"
    },
    {
      "x": -15,
      "y": 41,
      "z": -8,
      "name": "Rock_Shale_Brick_Pillar_Middle"
    },
    {
      "x": -15,
      "y": 42,
      "z": -8,
      "name": "Wood_Fir_Trunk",
      "support": 15,
      "rotation": 5
    },
    {
      "x": -15,
      "y": 43,
      "z": -8,
      "name": "Rock_Slate_Cobble_Roof_Shallow",
      "filler": 1,
      "rotation": 3
    },
    {
      "x": -15,
      "y": 0,
      "z": -7,
      "name": "Soil_Grass_Cold",
      "rotation": 2
    },
    {
      "x": -15,
      "y": 43,
      "z": -7,
      "name": "Rock_Slate_Cobble_Roof_Hollow",
      "rotation": 3
    },
    {
      "x": -15,
      "y": 0,
      "z": -6,
      "name": "Soil_Grass_Cold",
      "rotation": 2
    },
    {
      "x": -15,
      "y": 43,
      "z": -6,
      "name": "Rock_Slate_Cobble_Roof_Hollow",
      "rotation": 3
    },
    {
      "x": -15,
      "y": 0,
      "z": -5,
      "name": "Soil_Grass_Cold",
      "rotation": 2
    },
    {
      "x": -15,
      "y": 43,
      "z": -5,
      "name": "*Rock_Slate_Cobble_Roof_Hollow_State_Definitions_Corner_Right"
    },
    {
      "x": -15,
      "y": 0,
      "z": -4,
      "name": "Soil_Grass_Cold",
      "rotation": 2
    },
    {
      "x": -15,
      "y": 0,
      "z": -3,
      "name": "Soil_Grass_Cold",
      "rotation": 2
    },
    {
      "x": -15,
      "y": 0,
      "z": -2,
      "name": "Soil_Grass_Cold",
      "rotation": 2
    },
    {
      "x": -15,
      "y": 0,
      "z": -1,
      "name": "Soil_Grass_Cold",
      "rotation": 2
    },
    {
      "x": -15,
      "y": 0,
      "z": 0,
      "name": "Soil_Grass_Cold",
      "rotation": 2
    },
    {
      "x": -15,
      "y": 0,
      "z": 1,
      "name": "Soil_Grass_Cold",
      "rotation": 2
    },
    {
      "x": -15,
      "y": 0,
      "z": 2,
      "name": "Soil_Grass_Cold",
      "rotation": 2
    },
    {
      "x": -15,
      "y": 0,
      "z": 3,
      "name": "Soil_Grass_Cold",
      "rotation": 2
    },
    {
      "x": -15,
      "y": 0,
      "z": 4,
      "name": "Soil_Grass_Cold",
      "rotation": 2
    },
    {
      "x": -15,
      "y": 0,
      "z": 5,
      "name": "Soil_Grass_Cold",
      "rotation": 2
    },
    {
      "x": -15,
      "y": 0,
      "z": 6,
      "name": "Soil_Grass_Cold",
      "rotation": 2
    },
    {
      "x": -15,
      "y": 0,
      "z": 7,
      "name": "Soil_Dirt_Cold",
      "rotation": 2
    },
    {
      "x": -15,
      "y": 0,
      "z": 8,
      "name": "Soil_Dirt_Cold",
      "rotation": 2
    },
    {
      "x": -15,
      "y": 0,
      "z": 9,
      "name": "Soil_Dirt_Cold",
      "rotation": 2
    },
    {
      "x": -15,
      "y": 0,
      "z": 10,
      "name": "Soil_Dirt_Cold",
      "rotation": 2
    },
    {
      "x": -15,
      "y": 0,
      "z": 11,
      "name": "Soil_Dirt_Cold",
      "rotation": 2
    },
    {
      "x": -15,
      "y": 0,
      "z": 12,
      "name": "Soil_Dirt_Cold",
      "rotation": 2
    },
    {
      "x": -15,
      "y": 0,
      "z": 13,
      "name": "Soil_Dirt_Cold",
      "rotation": 2
    },
    {
      "x": -15,
      "y": 0,
      "z": 14,
      "name": "Soil_Grass_Cold",
      "rotation": 2
    },
    {
      "x": -15,
      "y": 0,
      "z": 15,
      "name": "Soil_Grass_Cold",
      "rotation": 2
    },
    {
      "x": -15,
      "y": 0,
      "z": 16,
      "name": "Soil_Grass_Cold",
      "rotation": 2
    },
    {
      "x": -15,
      "y": 0,
      "z": 17,
      "name": "Soil_Grass_Cold",
      "rotation": 2
    },
    {
      "x": -15,
      "y": 0,
      "z": 18,
      "name": "Soil_Grass_Cold",
      "rotation": 2
    },
    {
      "x": -15,
      "y": 0,
      "z": 19,
      "name": "Soil_Grass_Cold",
      "rotation": 2
    },
    {
      "x": -15,
      "y": 0,
      "z": 20,
      "name": "Soil_Grass_Cold",
      "rotation": 2
    },
    {
      "x": -15,
      "y": 0,
      "z": 21,
      "name": "Soil_Grass_Cold",
      "rotation": 2
    },
    {
      "x": -15,
      "y": 0,
      "z": 22,
      "name": "Soil_Grass_Cold",
      "rotation": 2
    },
    {
      "x": -15,
      "y": 1,
      "z": 22,
      "name": "Rock_Shale_Brick",
      "rotation": 2
    },
    {
      "x": -15,
      "y": 2,
      "z": 22,
      "name": "Rock_Shale_Brick",
      "rotation": 2
    },
    {
      "x": -15,
      "y": 3,
      "z": 22,
      "name": "Rock_Shale_Brick",
      "rotation": 2
    },
    {
      "x": -15,
      "y": 4,
      "z": 22,
      "name": "*Rock_Shale_Brick_Wall_State_Definitions_Corner"
    },
    {
      "x": -15,
      "y": 0,
      "z": 23,
      "name": "Soil_Grass_Cold",
      "rotation": 2
    },
    {
      "x": -15,
      "y": 1,
      "z": 23,
      "name": "Rock_Shale_Brick",
      "rotation": 2
    },
    {
      "x": -15,
      "y": 2,
      "z": 23,
      "name": "Rock_Shale_Brick",
      "rotation": 2
    },
    {
      "x": -15,
      "y": 3,
      "z": 23,
      "name": "Rock_Shale_Brick",
      "rotation": 2
    },
    {
      "x": -15,
      "y": 4,
      "z": 23,
      "name": "*Rock_Shale_Brick_Wall_State_Definitions_Corner",
      "rotation": 2
    },
    {
      "x": -14,
      "y": 0,
      "z": -23,
      "name": "Soil_Grass_Cold",
      "rotation": 2
    },
    {
      "x": -14,
      "y": 1,
      "z": -23,
      "name": "Rock_Shale_Brick",
      "rotation": 2
    },
    {
      "x": -14,
      "y": 2,
      "z": -23,
      "name": "Rock_Shale_Brick",
      "rotation": 2
    },
    {
      "x": -14,
      "y": 3,
      "z": -23,
      "name": "Rock_Shale_Brick",
      "rotation": 2
    },
    {
      "x": -14,
      "y": 4,
      "z": -23,
      "name": "Rock_Shale_Brick_Wall",
      "rotation": 2
    },
    {
      "x": -14,
      "y": 0,
      "z": -22,
      "name": "Soil_Grass_Cold",
      "rotation": 2
    },
    {
      "x": -14,
      "y": 0,
      "z": -21,
      "name": "Soil_Grass_Cold",
      "rotation": 2
    },
    {
      "x": -14,
      "y": 0,
      "z": -20,
      "name": "Soil_Grass_Cold",
      "rotation": 2
    },
    {
      "x": -14,
      "y": 0,
      "z": -19,
      "name": "Soil_Grass_Cold",
      "rotation": 2
    },
    {
      "x": -14,
      "y": 0,
      "z": -18,
      "name": "Soil_Grass_Cold",
      "rotation": 2
    },
    {
      "x": -14,
      "y": 0,
      "z": -17,
      "name": "Soil_Grass_Cold",
      "rotation": 2
    },
    {
      "x": -14,
      "y": 0,
      "z": -16,
      "name": "Soil_Grass_Cold",
      "rotation": 2
    },
    {
      "x": -14,
      "y": 1,
      "z": -16,
      "name": "Rock_Shale_Brick"
    },
    {
      "x": -14,
      "y": 2,
      "z": -16,
      "name": "Rock_Shale_Brick_Beam"
    },
    {
      "x": -14,
      "y": 3,
      "z": -16,
      "name": "Rock_Shale_Brick_Beam"
    },
    {
      "x": -14,
      "y": 4,
      "z": -16,
      "name": "*Rock_Slate_Cobble_Roof_Hollow_State_Definitions_Corner_Right",
      "rotation": 2
    },
    {
      "x": -14,
      "y": 0,
      "z": -15,
      "name": "Soil_Dirt_Cold",
      "rotation": 2
    },
    {
      "x": -14,
      "y": 4,
      "z": -15,
      "name": "Rock_Slate_Cobble_Roof_Hollow",
      "rotation": 1
    },
    {
      "x": -14,
      "y": 43,
      "z": -15,
      "name": "Rock_Slate_Cobble_Roof_Hollow",
      "rotation": 2
    },
    {
      "x": -14,
      "y": 0,
      "z": -14,
      "name": "Soil_Dirt_Cold",
      "rotation": 2
    },
    {
      "x": -14,
      "y": 1,
      "z": -14,
      "name": "Rock_Shale_Brick"
    },
    {
      "x": -14,
      "y": 2,
      "z": -14,
      "name": "Rock_Shale_Brick_Beam"
    },
    {
      "x": -14,
      "y": 3,
      "z": -14,
      "name": "Rock_Shale_Brick_Beam"
    },
    {
      "x": -14,
      "y": 4,
      "z": -14,
      "name": "*Rock_Slate_Cobble_Roof_Hollow_State_Definitions_Corner_Left"
    },
    {
      "x": -14,
      "y": 44,
      "z": -14,
      "name": "*Rock_Slate_Cobble_Roof_Hollow_State_Definitions_Corner_Right",
      "rotation": 3
    },
    {
      "x": -14,
      "y": 0,
      "z": -13,
      "name": "Soil_Dirt_Cold",
      "rotation": 2
    },
    {
      "x": -14,
      "y": 35,
      "z": -13,
      "name": "Rock_Shale_Brick"
    },
    {
      "x": -14,
      "y": 36,
      "z": -13,
      "name": "Rock_Shale_Brick"
    },
    {
      "x": -14,
      "y": 37,
      "z": -13,
      "name": "Rock_Shale_Brick"
    },
    {
      "x": -14,
      "y": 38,
      "z": -13,
      "name": "Rock_Shale_Brick_Wall"
    },
    {
      "x": -14,
      "y": 44,
      "z": -13,
      "name": "Rock_Slate_Cobble_Roof_Hollow",
      "rotation": 3
    },
    {
      "x": -14,
      "y": 0,
      "z": -12,
      "name": "Soil_Dirt_Cold",
      "rotation": 2
    },
    {
      "x": -14,
      "y": 34,
      "z": -12,
      "name": "Rock_Shale_Brick"
    },
    {
      "x": -14,
      "y": 35,
      "z": -12,
      "name": "Rock_Shale_Brick"
    },
    {
      "x": -14,
      "y": 36,
      "z": -12,
      "name": "Rock_Shale_Brick"
    },
    {
      "x": -14,
      "y": 37,
      "z": -12,
      "name": "Rock_Shale_Brick"
    },
    {
      "x": -14,
      "y": 42,
      "z": -12,
      "name": "Wood_Fir_Trunk",
      "support": 15,
      "rotation": 5
    },
    {
      "x": -14,
      "y": 43,
      "z": -12,
      "name": "Rock_Slate"
    },
    {
      "x": -14,
      "y": 44,
      "z": -12,
      "name": "Rock_Slate_Cobble_Roof",
      "rotation": 3
    },
    {
      "x": -14,
      "y": 0,
      "z": -11,
      "name": "Soil_Dirt_Cold",
      "rotation": 2
    },
    {
      "x": -14,
      "y": 34,
      "z": -11,
      "name": "Rock_Shale_Brick"
    },
    {
      "x": -14,
      "y": 35,
      "z": -11,
      "name": "Rock_Shale_Brick"
    },
    {
      "x": -14,
      "y": 36,
      "z": -11,
      "name": "Rock_Shale_Brick"
    },
    {
      "x": -14,
      "y": 37,
      "z": -11,
      "name": "Rock_Shale_Brick"
    },
    {
      "x": -14,
      "y": 43,
      "z": -11,
      "name": "Rock_Slate"
    },
    {
      "x": -14,
      "y": 44,
      "z": -11,
      "name": "Rock_Slate_Cobble_Roof",
      "rotation": 3
    },
    {
      "x": -14,
      "y": 0,
      "z": -10,
      "name": "Soil_Grass_Cold",
      "rotation": 2
    },
    {
      "x": -14,
      "y": 34,
      "z": -10,
      "name": "Rock_Shale_Brick"
    },
    {
      "x": -14,
      "y": 35,
      "z": -10,
